Workbook

Sheet 92107
A1: ZURU Babycorns Surprise - S1 #92107 | BI1: 中东客 | BT1: 蝴蝶 | BU1: 瓢虫 | BV1: 长颈鹿 | BW1: 大象
AI2: 收缩膜 | AO2: 收藏指南 | AT2: 阅读卡 MA 5L | AX2: 阅读卡 MA 5L B版 | BB2: 阅读卡 中文 | BG2: 展示架F | BI2: 134696 | BJ2: 口水胶 | BL2: 布标 | BS2: 总MA | BT2: =生产MA!D19 -> 245000 | BU2: =生产MA!E19 -> 245000 | BV2: =生产MA!F19 -> 242000 | BW2: =生产MA!G19 -> 241000 | BX2: =SUM(BT2:BW2) -> 973000
A3: 接单日期 | B3: 第三方客户名称 | C3: 国家 | D3: PO号 | E3: 客PO号 | F3: SKU | G3: ITEM# | H3: 中文名 | I3: PO数量 (pcs) | J3: 内箱装箱数量(pcs) | K3: 外箱装箱数量(pcs) | L3: 总箱数 | M3: ZURU订单走货日期 | N3: ZURU验货 日期 | O3: 第三方验货 | P3: 驗貨結果 | Q3: 送货情况 | R3: 欠数 | S3: 贴纸 | T3: 出单情况 | U3: 船期SO | V3: 车间回复完成时间 | W3: 箱唛资料 | X3: 是否有外箱贴 | Y3: 贴纸资料 | Z3: 客供物料 | AA3: 日期码 | AB3: 备注 | AC3: ZURU跟单 | AD3: 单价USD | AE3: 金额USD | AF3: 發票號 | AG3: 系统货号 | AH3: 是否入系统 | AI3: MA 1L | AJ3: MA 1L B版 | AK3: MA 3L | AL3: MA 3L B版 | AM3: 134696中东客 客版 | AN3: 客版 | AO3: MA 5L | AP3: MA 5L B版 | AQ3: 134696中东客 客版 | AR3: 中文 | AS3: 客版 | AT3: Butterfly 蝴蝶 D | AU3: Ladybug瓢虫 E | AV3: Giraffe长颈鹿 B | AW3: Elephant大象 A | AX3: Butterfly 蝴蝶 D | AY3: Ladybug瓢虫 E | AZ3: Giraffe长颈鹿 B | BA3: Elephant大象 A | BB3: Butterfly 蝴蝶 | BC3: Ladybug瓢虫 | BD3: Giraffe长颈鹿 | BE3: Elephant大象 | BF3: 相差 | BG3: MA 1L | BH3: MA 3L | BI3: #9283中的两款沙子代替slime | BJ3: 有硼 | BK3: 无硼 | BL3: MA/客版 | BN3: Butterfly 蝴蝶 D | BO3: Ladybug 瓢虫 E | BP3: Giraffe 长颈鹿 B | BQ3: Elephant 大象 A | BS3: 合计 | BT3: MA剩余 | BU3: MA剩余 | BV3: MA剩余 | BW3: MA剩余
A4: 45289 | B4: ZURU | C4: 库有 | D4: ZPO2312005 | E4: PP订单 | G4: 92107-S001 | H4: 摇篮公子 | I4: 284 | J4: 0 | K4: 8 | L4: =I4/K4 -> 35.5 | M4: 45313 | N4: 45309 | W4: 无 | X4: 无 | Y4: 无 | AB4: 1.OA Testing Samples (BULK)：数量 16；地址 深圳市罗湖区东门南路106号口岸大楼17B ，Angus 2 CTN 2.QA Testing samples (FSDU)：数量 30；地址 深圳市罗湖区东门南路106号口岸大楼17B ，Angus 1FSDU 3.Signed Sample (6套签+1套用于拆办)：数量 28；地址 深圳市罗湖区东门南路1006号口岸大楼A栋3楼，Jessy Zhang 13421384408 ，7套*4款=28 4.Show room：数量 80；地址 清溪镇光朗村易京街25号《库有样板房) 收件人:李志强电话: 18328402533 ，20套 注：开PP时候帮忙额外准备3套散件邮寄到深圳办公室 5.Sample room samples：数量 280；地址 清溪镇光朗村易京街25号《库有样板房) 收件人:李志强电话: 18328402533 ，70套 注：开PP时候帮忙额外准备3套散件邮寄到深圳办公室 6.散件：数量 12；地址 深圳市罗湖区东门南路1006号口岸大楼A栋16楼，Max Mlai 13632761211 2 CTN 3套散件（除蛋壳外的所有内含物），每套单独装好 合计数量434；PP订单数量合计 500PCS 注:PP PO数量含buffer，请按PP PO数量准备物料 | AG4: # | AH4: # | BF4: =SUM(AT4:BE4)-I4 -> -284 | BN4: 0 | BO4: 0 | BP4: 0 | BQ4: 0 | BR4: =BN4+BO4+BP4+BQ4-I4 -> -284 | BS4: =BN4+BO4+BP4+BQ4+$BS$290 -> 512480 | BT4: =$BT$2-$BT$290-BN4 -> 131789.33 | BU4: =$BT$2-$BT$290-BO4 -> 131789.33 | BV4: =$BT$2-$BT$290-BP4 -> 131789.33 | BW4: =$BT$2-$BT$290-BQ4 -> 131789.33
A5: 45561 | B5: WAL-MART CANADA CORP. | C5: 加拿大 | D5: 4500146212 | F5: 4500146212-20 | G5: 92107-S003-NB | H5: 摇篮公子 | I5: 1707 | J5: 0 | K5: 1 | L5: =I5/K5 -> 1707 | M5: 45621 | N5: 45617 | O5: 11/25抽办 12/18第三方 | P5: PASS | U5: 1/6出 | W5: 10/31收到 | X5: 无 | Y5: UPC条码贴纸9/26 | AB5: 日期码格式：ZURU INC(BVI) 标准格式 日期：按实际生产日期 Packaging Info: #92107: MA3L收缩膜+UPC条码贴纸(UPC: 193052064738)+MA5L收藏指南+MA5L资料卡+MA5L胶袋+MA配件袋+MA2L布标 -产品配比: 4 Assortment Ratio (Ladybug: Giraffe: Butterfly: Elephant)=1:1:1:1 Remark: 1. 92107 须使用无硼slime; 3. 此单有箱唛； 4. 此单有第三方验货，烦请多备包装物料； 5. 此单#92108/92107/92105/9296/9554/15714 需签办；签办数量：大货样各3套; 6. 此单#92108/92107/92105/9296/9554 需于2024/11/25 抽办做测试；抽办数量：大货各5套; ********************* a. 请确保产品符合1999年版本的加拿大环境保护法(CEPA)和2012年禁止某些有毒物质法规的要求。该产品不含任何在加拿大禁用的化学物质，包括但不限于有毒物 质清单中列出的化学物质，并且在为加拿大沃尔玛生产产品期间没有使用任何禁用化学物质。 Supplier certify that the products comply with the requirements of Canadian Environmental Protection Act, 1999 (CEPA), Prohibition of Certain To xic Substances Regulations, 2012. The products do not contain any chemicals that are banned in Canada, including but not limited to those listed in the Toxic Substances List and no banned chemicals were used during the manufacturing of product for Walmart Canada. 附件列表： (1) Letter of Guarantee for Canada banned chemicals - (1-5CA) b. 请确保产品在均质材料中的汞浓度不超过0.1%（按重量计）。 Supplier certify that the WAL-MART vendor products does not have a mercury concentration of more than 0.1% by weight in homogeneous material. 附件列表： (1) Letter of Guarantee for Mercury COC c. 请确保产品的塑料材料不含以下物质（SOR 2011-17 27B): Supplier certify that the plastic materials do not contain the following substances(SOR 2011-17 27B): (a) carbon tetrachloride or any substance that contains it; (b) methyl alcohol or any substance thay contains >1.0%; (c) petroleum distillates or any substance that contains >10% weight to volume of petroleum distillates; (d) benzene; (e) turpentine or any substance that contains >10% weight to volume of turpentine; (f) boric acid or salts of boric acid; or (g) ethyl ether. 附件列表： (1) Letter of Guarantee for WM CA-Other prohibited substances in plastic(less than 3 years) | AC5: Monica Zhou | AD5: 4.3993 | AE5: =AD5*I5 -> 7509.6051 | AF5: 94003-1.13 | AG5: 92107-S003-NB-3L | AH5: 已入 | AL5: =I5 -> 1707 | AP5: =I5 -> 1707 | AT5: =I5/4 -> 426.75 | AU5: =AT5 -> 426.75 | AV5: =AU5 -> 426.75 | AW5: =AV5 -> 426.75 | BF5: =SUM(AT5:BE5)-I5 -> 0 | BK5: =I5 -> 1707 | BL5: MA | BN5: =I5/4 -> 426.75 | BO5: =I5/4 -> 426.75 | BP5: =I5/4 -> 426.75 | BQ5: =I5/4 -> 426.75 | BR5: =BN5+BO5+BP5+BQ5-I5 -> 0 | BS5: =BN5+BO5+BP5+BQ5+$BS$290 -> 514187 | BT5: =BT4-BN5 -> 131362.58 | BU5: =BU4-BO5 -> 131362.58 | BV5: =BV4-BP5 -> 131362.58 | BW5: =BW4-BQ5 -> 131362.58
A6: 45523 | B6: DM LLC | C6: 俄罗斯 | D6: 4500143263 | E6: 出Bekasovo 2 | F6: 4500143263-30 | G6: 92107-S001 | H6: 摇篮公子 | I6: 2320 | J6: 0 | K6: 8 | L6: =I6/K6 -> 290 | M6: 45667 | N6: 45663 | P6: PASS | U6: 2/10出 | W6: 10/28收到 | X6: 无 | Y6: 进口商贴纸（翻4500143236）+EAN条码贴纸（翻4500143236） | Z6: 客版收缩膜翻4500143236 | AA6: 外包装(指: 收缩膜/彩卡/吊牌/PDQ)/外箱不要打ZURU标准日期码！ | AB6: 日期码格式：注意:外包装(指: 收缩膜/彩卡/吊牌/PDQ)/外箱不要打ZURU标准日期码！ 日期： Packaging Info: 出Bekasovo 2 和Ural 2 个港口； LC 货期不可延期有罚款 ； 92107 : 客版收缩膜翻4500143236 ， MA 指南 。 注意 ：外包装 (指: 收缩膜/彩卡/吊牌/PDQ) /外箱不要打ZURU标准日期码！ Remark: 标准配比 | AC6: Ann Zhang | AD6: 4.2362 | AE6: =AD6*I6 -> 9827.984 | AF6: 94200-2.10 | AG6: 92107-S001-2 | AH6: 已入 | AN6: =I6 -> 2320 | AO6: =I6 -> 2320 | AT6: =I6/4 -> 580 | AU6: =AT6 -> 580 | AV6: =AU6 -> 580 | AW6: =AV6 -> 580 | BF6: =SUM(AT6:BE6)-I6 -> 0 | BJ6: =I6 -> 2320 | BL6: MA | BN6: =I6/4 -> 580 | BO6: =I6/4 -> 580 | BP6: =I6/4 -> 580 | BQ6: =I6/4 -> 580 | BR6: =BN6+BO6+BP6+BQ6-I6 -> 0 | BS6: =BN6+BO6+BP6+BQ6+$BS$290 -> 514800 | BT6: =BT5-BN6 -> 130782.58 | BU6: =BU5-BO6 -> 130782.58 | BV6: =BV5-BP6 -> 130782.58 | BW6: =BW5-BQ6 -> 130782.58
A7: 45523 | B7: DM LLC | C7: 俄罗斯 | D7: 4500143263 | E7: 出Ural | F7: 4500143263-60 | G7: 92107-S001 | H7: 摇篮公子 | I7: 1160 | J7: 0 | K7: 8 | L7: =I7/K7 -> 145 | M7: 45667 | N7: 45663 | P7: PASS | U7: 2/10出 | W7: 10/28收到 | X7: 无 | Y7: 进口商贴纸（翻4500143236）+EAN条码贴纸（翻4500143236） | Z7: 客版收缩膜翻4500143236 | AA7: 外包装(指: 收缩膜/彩卡/吊牌/PDQ)/外箱不要打ZURU标准日期码！ | AB7: 日期码格式：注意:外包装(指: 收缩膜/彩卡/吊牌/PDQ)/外箱不要打ZURU标准日期码！ 日期： Packaging Info: 出Bekasovo 2 和Ural 2 个港口； LC 货期不可延期有罚款 ； 92107 : 客版收缩膜翻4500143236 ， MA 指南 。 注意 ：外包装 (指: 收缩膜/彩卡/吊牌/PDQ) /外箱不要打ZURU标准日期码！ Remark: 标准配比 | AC7: Ann Zhang | AD7: 4.2362 | AE7: =AD7*I7 -> 4913.992 | AF7: 94200-2.10 | AG7: 92107-S001-2 | AH7: 已入 | AN7: =I7 -> 1160 | AO7: =I7 -> 1160 | AT7: =I7/4 -> 290 | AU7: =AT7 -> 290 | AV7: =AU7 -> 290 | AW7: =AV7 -> 290 | BF7: =SUM(AT7:BE7)-I7 -> 0 | BJ7: =I7 -> 1160 | BL7: MA | BN7: =I7/4 -> 290 | BO7: =I7/4 -> 290 | BP7: =I7/4 -> 290 | BQ7: =I7/4 -> 290 | BR7: =BN7+BO7+BP7+BQ7-I7 -> 0 | BS7: =BN7+BO7+BP7+BQ7+$BS$290 -> 513640 | BT7: =BT6-BN7 -> 130492.58 | BU7: =BU6-BO7 -> 130492.58 | BV7: =BV6-BP7 -> 130492.58 | BW7: =BW6-BQ7 -> 130492.58
A8: 45601 | B8: DD’S DISCOUNTS | C8: 美国 | D8: 4500150187 | E8: 70054066 | F8: 4500150187-40 | G8: 92107-S001 | H8: 摇篮公子 | I8: 600 | J8: 0 | K8: 8 | L8: =I8/K8 -> 75 | M8: 45653 | N8: 45649 | P8: PASS | U8: 1/7出 | W8: ROSS指定箱唛格式 | Y8: 11/19收到价格贴纸客供 | AB8: 日期码格式：ZURU INC(BVI) 标准格式 日期：按实际生产日期 Packaging Info: 1.ZURU MA UPC 现有版本包装 + 客供价格贴纸，出口美国 , 优先使用MA 1L 最新版本 。 Remark: 1.ZURU MA UPC 现有版本包装 + 客供价格贴纸，出口美国 , 优先使用MA 1L 最新版本 。 2.价格贴纸位于包装正面右下角，不挡住重要信息即可，可适当调整 ，价格贴纸由跟单提供。 3.标准日期码格式，产品和包装必须有日期码 。 4.同个产品同个货期不可出现不同的包装。 5. 跟单提供ROSS通用的箱唛模版，工厂按实际45 PO上客户PO/Item号/装箱数 提供箱唛排版来确认。 | AC8: Taylor Liao | AD8: 4.0921 | AE8: =AD8*I8 -> 2455.26 | AF8: 88917-1.7 | AG8: 92107-S001 | AH8: 已入 | AI8: =I8 -> 600 | AO8: =I8 -> 600 | AT8: =I8/4 -> 150 | AU8: =AT8 -> 150 | AV8: =AU8 -> 150 | AW8: =AV8 -> 150 | BF8: =SUM(AT8:BE8)-I8 -> 0 | BJ8: =I8 -> 600 | BL8: MA | BN8: =I8/4 -> 150 | BO8: =I8/4 -> 150 | BP8: =I8/4 -> 150 | BQ8: =I8/4 -> 150 | BR8: =BN8+BO8+BP8+BQ8-I8 -> 0 | BS8: =BN8+BO8+BP8+BQ8+$BS$290 -> 513080 | BT8: =BT7-BN8 -> 130342.58 | BU8: =BU7-BO8 -> 130342.58 | BV8: =BV7-BP8 -> 130342.58 | BW8: =BW7-BQ8 -> 130342.58
A9: 45621 | B9: TOYS "R" US – JAPAN, LTD | C9: 日本 | D9: 4500152217 | E9: 47:0003108131 | F9: 4500152217-10 | G9: 92107-S008 | H9: 摇篮公子 (三款公仔） | I9: 552 | J9: 0 | K9: 8 | L9: =I9/K9 -> 69 | M9: 45656 | N9: 45652 | P9: PASS | U9: 1/5出 | W9: 11/25收到 | Y9: 日语贴纸翻4500135847）+6+贴纸 | AB9: 日期码格式：ZURU INC(BVI) 标准格式 日期：按实际生产日期 Tracking Code: Packaging Info: MA 1L UPC PKG A版收缩膜+MA 5L+23L Warning A版收藏指南 +日语贴纸(贴纸AW翻单4500135847）+1张6+贴纸覆盖3+。 Remark: 出日本， 大货品质/包装必须严格跟到PO#4500135847。 请特别留意此单仅出以下3款， 按以下的数量分配。 Ladybug: 184pcs Giraffe: 184pcs Butterfly: 184pcs 装箱按以下配比。 3 Assortment Ratio (Ladybug: Giraffe: Butterfly)=1:1:1, 2pcs of each+2pcs random=8pcs/CTN | AC9: Doris Shou | AD9: 4.0839 | AE9: =AD9*I9 -> 2254.3128 | AF9: 88889-1.6 | AG9: 92107-S001 | AH9: 已入 | AI9: =I9 -> 552 | AO9: =I9 -> 552 | AT9: =I9/3 -> 184 | AU9: =AT9 -> 184 | AV9: =AU9 -> 184 | BF9: =SUM(AT9:BE9)-I9 -> 0 | BJ9: =I9 -> 552 | BL9: MA | BN9: =I9/3 -> 184 | BO9: =I9/3 -> 184 | BP9: =I9/3 -> 184 | BR9: =BN9+BO9+BP9+BQ9-I9 -> 0 | BS9: =BN9+BO9+BP9+BQ9+$BS$290 -> 513032 | BT9: =BT8-BN9 -> 130158.58 | BU9: =BU8-BO9 -> 130158.58 | BV9: =BV8-BP9 -> 130158.58 | BW9: =BW8-BQ9 -> 130342.58
A10: 45621 | B10: TOYS "R" US – JAPAN, LTD | C10: 日本 | D10: 4500152215 | E10: 46:0003108129 | F10: 4500152215-10 | G10: 92107-S008 | H10: 摇篮公子 (三款公仔） | I10: 448 | J10: 0 | K10: 8 | L10: =I10/K10 -> 56 | M10: 45656 | N10: 45652 | P10: PASS | U10: 1/5出 | W10: 11/25收到 | Y10: 日语贴纸翻4500135847）+6+贴纸 | AB10: 日期码格式：ZURU INC(BVI) 标准格式 日期：按实际生产日期 Packaging Info: MA 1L UPC PKG A版收缩膜+MA 5L+23L Warning A版收藏指南 +日语贴纸(贴纸AW翻单4500135847）+1张6+贴纸覆盖3+。 Remark: 出日本， 大货品质/包装必须严格跟到PO#4500135847。 请特别留意此单仅出以下3款， 按以下的数量分配。 Ladybug: 149pcs Giraffe: 149pcs Butterfly: 150pcs 装箱按以下配比。 3 Assortment Ratio (Ladybug: Giraffe: Butterfly)=1:1:1, 2pcs of each+2pcs random=8pcs/CTN | AC10: Doris Shou | AD10: 4.0953 | AE10: =AD10*I10 -> 1834.6944 | AF10: 88888-1.6 | AG10: 92107-S001 | AH10: 已入 | AI10: =I10 -> 448 | AO10: =I10 -> 448 | AT10: =I10/3 -> 149.33333 | AU10: =AT10 -> 149.33333 | AV10: =AU10 -> 149.33333 | BF10: =SUM(AT10:BE10)-I10 -> 0 | BJ10: =I10 -> 448 | BL10: MA | BN10: =I10/3 -> 149.33333 | BO10: =I10/3 -> 149.33333 | BP10: =I10/3 -> 149.33333 | BR10: =BN10+BO10+BP10+BQ10-I10 -> 0 | BS10: =BN10+BO10+BP10+BQ10+$BS$290 -> 512928 | BT10: =BT9-BN10 -> 130009.25 | BU10: =BU9-BO10 -> 130009.25 | BV10: =BV9-BP10 -> 130009.25 | BW10: =BW9-BQ10 -> 130342.58
A11: 45586 | B11: TJX COMPANIES, INC | C11: 美国 | D11: 4500147789 | E11: Marshalls DC#881-128PCS , DC#884-96PCS, DC#886-136PCS , DC#887-120PCS , DC#888-120PCS | F11: 4500147789-70 | G11: 92107-S001 | H11: 摇篮公子 | I11: 600 | J11: 0 | K11: 8 | L11: =I11/K11 -> 75 | M11: 45649 | N11: 45645 | P11: PASS | U11: 1/2出 | W11: 11/4收到 | X11: 无 | Y11: 11/19收到价格贴纸客供 | AB11: 日期码格式：ZURU INC(BVI) 标准格式 日期：按实际生产日期 Packaging Info: MA UPC包装+价格贴纸，价格贴纸客供。 Remark: 1. 产品和包装上印刷tracking code信息，格式为ZURU常规格式。 2. 分5个DC出货，每款产品每个DC的箱唛资料不同。具体分DC数量，请参考后面行项目备注。 3. ZURU QC验货。 | AC11: Emily Wu | AD11: 4.2475 | AE11: =AD11*I11 -> 2548.5 | AF11: 94169-1.23 | AG11: 92107-S001 | AH11: 已入 | AI11: =I11 -> 600 | AO11: =I11 -> 600 | AT11: =I11/4 -> 150 | AU11: =AT11 -> 150 | AV11: =AU11 -> 150 | AW11: =AV11 -> 150 | BF11: =SUM(AT11:BE11)-I11 -> 0 | BJ11: =I11 -> 600 | BL11: MA | BN11: =I11/4 -> 150 | BO11: =I11/4 -> 150 | BP11: =I11/4 -> 150 | BQ11: =I11/4 -> 150 | BR11: =BN11+BO11+BP11+BQ11-I11 -> 0 | BS11: =BN11+BO11+BP11+BQ11+$BS$290 -> 513080 | BT11: =BT10-BN11 -> 129859.25 | BU11: =BU10-BO11 -> 129859.25 | BV11: =BV10-BP11 -> 129859.25 | BW11: =BW10-BQ11 -> 130192.58
A12: 45608 | B12: Amazon CA (Vendor Center) | C12: 加拿大 | D12: 4500150978 | E12: 5R6F4YLI | F12: 4500150978-10 | G12: 92107E-S001-NB | H12: 瓢虫 | I12: 8 | J12: 0 | K12: 8 | L12: =I12/K12 -> 1 | M12: 45653 | N12: 45649 | P12: PASS | U12: 1/1-1/7出 | W12: 11/12收到 | Y12: UPC贴纸翻4500134367 | AB12: 日期码格式：ZURU INC(BVI) 标准格式 日期：按实际生产日期 Packaging Info: 出口加拿大，包装需要至少2/3L UPC版，无硼版本 #92107 MA 1L UPC版本+ UPC贴纸跟返单4500134367；92107A:193052066817, 92107B:193052066824, 92107D:193052066831, 92107E:193052066848; Remark: 1. Amazon FOB订单，出口CA。外箱最长边不能超过25" （超过了，case pack只能为1），不符合要求的大货，一律不接受。 2. 外箱正面印ZURU Logo + SSCC LABEL（客供贴纸)，侧面印item#（订单上显示的SKU#) + carton size(以工厂实际尺寸为准，单位: inch) + MADE IN CHINA， 日期使用ZURU 标准版本 SSCC Label 显示的是客人自己的item#，SSCC Label 贴在外箱正面的正中间，贴一面即可，跟单订购，贴纸离外箱距必须至少3cm，每一 张SSCC label 都是唯一且有不同流水及条码的，没有损耗，绝对不可贴错 ，否则贴错或损坏一张会导致全部都错，千万要注意: SSCC 贴纸务必要在正中间(可以覆 盖Logo <(>&<)> 箱唛)，否则会影响到仓库扫描识别。 3. 日期码使用ZURU标准版本。 4. 如果大货有要求入邮包盒，则对应的邮包盒上面要打上日期码。 5. 按照客户PO# 装柜/箱号顺序装柜，跟单会提前给到装柜计划。在大货生产/仓库存放时，请留意该装柜要求，以便装柜时不混乱（避免装错/装漏/找不到货号等 ）。 6. 出口加拿大，包装需要至少2/3L UPC版，无硼版本。 7.邮包盒上要印刷日期码 | AC12: Kelly/Mia | AD12: 4.1036 | AE12: =AD12*I12 -> 32.8288 | AF12: 88919-1.7 | AG12: 92107E-S001-3L-NB | AH12: 已入 | AL12: =I12 -> 8 | AP12: =I12 -> 8 | AT12: =I12/4 -> 2 | AU12: =AT12 -> 2 | AV12: =AU12 -> 2 | AW12: =AV12 -> 2 | BF12: =SUM(AT12:BE12)-I12 -> 0 | BK12: =I12 -> 8 | BL12: MA | BO12: =I12 -> 8 | BR12: =BN12+BO12+BP12+BQ12-I12 -> 0 | BS12: =BN12+BO12+BP12+BQ12+$BS$290 -> 512488 | BT12: =BT11-BN12 -> 129859.25 | BU12: =BU11-BO12 -> 129851.25 | BV12: =BV11-BP12 -> 129859.25 | BW12: =BW11-BQ12 -> 130192.58
A13: 45608 | B13: Amazon CA (Vendor Center) | C13: 加拿大 | D13: 4500150978 | E13: 5GDMN3WZ | F13: 4500150978-20 | G13: 92107D-S001-NB | H13: 蝴蝶 | I13: 8 | J13: 0 | K13: 8 | L13: =I13/K13 -> 1 | M13: 45653 | N13: 45649 | P13: PASS | U13: 1/1-1/7出 | W13: 11/12收到 | Y13: UPC贴纸翻4500134367 | AB13: 日期码格式：ZURU INC(BVI) 标准格式 日期：按实际生产日期 Packaging Info: 出口加拿大，包装需要至少2/3L UPC版，无硼版本 #92107 MA 1L UPC版本+ UPC贴纸跟返单4500134367；92107A:193052066817, 92107B:193052066824, 92107D:193052066831, 92107E:193052066848; Remark: 1. Amazon FOB订单，出口CA。外箱最长边不能超过25" （超过了，case pack只能为1），不符合要求的大货，一律不接受。 2. 外箱正面印ZURU Logo + SSCC LABEL（客供贴纸)，侧面印item#（订单上显示的SKU#) + carton size(以工厂实际尺寸为准，单位: inch) + MADE IN CHINA， 日期使用ZURU 标准版本 SSCC Label 显示的是客人自己的item#，SSCC Label 贴在外箱正面的正中间，贴一面即可，跟单订购，贴纸离外箱距必须至少3cm，每一 张SSCC label 都是唯一且有不同流水及条码的，没有损耗，绝对不可贴错 ，否则贴错或损坏一张会导致全部都错，千万要注意: SSCC 贴纸务必要在正中间(可以覆 盖Logo <(>&<)> 箱唛)，否则会影响到仓库扫描识别。 3. 日期码使用ZURU标准版本。 4. 如果大货有要求入邮包盒，则对应的邮包盒上面要打上日期码。 5. 按照客户PO# 装柜/箱号顺序装柜，跟单会提前给到装柜计划。在大货生产/仓库存放时，请留意该装柜要求，以便装柜时不混乱（避免装错/装漏/找不到货号等 ）。 6. 出口加拿大，包装需要至少2/3L UPC版，无硼版本。 7.邮包盒上要印刷日期码 | AC13: Kelly/Mia | AD13: 4.1036 | AE13: =AD13*I13 -> 32.8288 | AF13: 88919-1.7 | AG13: 92107D-S001-3L-NB | AH13: 已入 | AL13: =I13 -> 8 | AP13: =I13 -> 8 | AT13: =I13/4 -> 2 | AU13: =AT13 -> 2 | AV13: =AU13 -> 2 | AW13: =AV13 -> 2 | BF13: =SUM(AT13:BE13)-I13 -> 0 | BK13: =I13 -> 8 | BL13: MA | BN13: =I13 -> 8 | BR13: =BN13+BO13+BP13+BQ13-I13 -> 0 | BS13: =BN13+BO13+BP13+BQ13+$BS$290 -> 512488 | BT13: =BT12-BN13 -> 129851.25 | BU13: =BU12-BO13 -> 129851.25 | BV13: =BV12-BP13 -> 129859.25 | BW13: =BW12-BQ13 -> 130192.58
A14: 45586 | B14: TJX COMPANIES, INC | C14: 美国 | D14: 4500147792 | E14: Marshalls DC#881-128PCS , DC#884-96PCS, DC#886-136PCS , DC#887-120PCS , DC#888-120PCS | F14: 4500147792-70 | G14: 92107-S001 | H14: 摇篮公子 | I14: 600 | J14: 0 | K14: 8 | L14: =I14/K14 -> 75 | M14: 45656 | N14: 45652 | P14: PASS | U14: 1/9出 | W14: 11/4收到 | X14: 无 | Y14: 无 | Z14: 12/6-价格贴纸客供 | AB14: 日期码格式：ZURU INC(BVI) 标准格式 日期：按实际生产日期 Packaging Info: MA UPC包装+价格贴纸，价格贴纸客供。 Remark: 1. 产品和包装上印刷tracking code信息，格式为ZURU常规格式。 2. 分5个DC出货，每款产品每个DC的箱唛资料不同。具体分DC数量，请参考后面行项目备注。 3. ZURU QC验货。 | AC14: Emily Wu | AD14: 4.2475 | AE14: =AD14*I14 -> 2548.5 | AF14: 94166-1.23 | AG14: 92107-S001 | AH14: 已入 | AI14: =I14 -> 600 | AO14: =I14 -> 600 | AT14: =I14/4 -> 150 | AU14: =AT14 -> 150 | AV14: =AU14 -> 150 | AW14: =AV14 -> 150 | BF14: =SUM(AT14:BE14)-I14 -> 0 | BJ14: =I14 -> 600 | BL14: MA | BN14: =I14/4 -> 150 | BO14: =I14/4 -> 150 | BP14: =I14/4 -> 150 | BQ14: =I14/4 -> 150 | BR14: =BN14+BO14+BP14+BQ14-I14 -> 0 | BS14: =BN14+BO14+BP14+BQ14+$BS$290 -> 513080 | BT14: =BT13-BN14 -> 129701.25 | BU14: =BU13-BO14 -> 129701.25 | BV14: =BV13-BP14 -> 129709.25 | BW14: =BW13-BQ14 -> 130042.58
A15: 45586 | B15: TJX COMPANIES, INC | C15: 美国 | D15: 4500147795 | E15: TJ MAXX DC#891-160PCS , DC#894-136PCS , DC#896-128PCS , DC#897-248PCS , DC#898-128PCS | F15: 4500147795-70 | G15: 92107-S001 | H15: 摇篮公子 | I15: 800 | J15: 0 | K15: 8 | L15: =I15/K15 -> 100 | M15: 45656 | N15: 45652 | P15: PASS | U15: 1/8出 | W15: 11/4收到 | X15: 无 | Y15: 无 | Z15: 12/6-价格贴纸客供 | AB15: 日期码格式：ZURU INC(BVI) 标准格式 日期：按实际生产日期 Packaging Info: MA UPC包装+价格贴纸，价格贴纸客供。 Remark: 1. 产品和包装上印刷tracking code信息，格式为ZURU常规格式。 2. 分5个DC出货，每款产品每个DC的箱唛资料不同。具体分DC数量，请参考后面行项目备注。 3. ZURU QC验货。 | AC15: Emily Wu | AD15: 4.2475 | AE15: =AD15*I15 -> 3398 | AF15: 94175-1.23 | AG15: 92107-S001 | AH15: 已入 | AI15: =I15 -> 800 | AO15: =I15 -> 800 | AT15: =I15/4 -> 200 | AU15: =AT15 -> 200 | AV15: =AU15 -> 200 | AW15: =AV15 -> 200 | BF15: =SUM(AT15:BE15)-I15 -> 0 | BJ15: =I15 -> 800 | BL15: MA | BN15: =I15/4 -> 200 | BO15: =I15/4 -> 200 | BP15: =I15/4 -> 200 | BQ15: =I15/4 -> 200 | BR15: =BN15+BO15+BP15+BQ15-I15 -> 0 | BS15: =BN15+BO15+BP15+BQ15+$BS$290 -> 513280 | BT15: =BT14-BN15 -> 129501.25 | BU15: =BU14-BO15 -> 129501.25 | BV15: =BV14-BP15 -> 129509.25 | BW15: =BW14-BQ15 -> 129842.58
A16: 45586 | B16: TJX COMPANIES, INC | C16: 美国 | D16: 4500147793 | E16: Marshalls DC#881-168PCS , DC#884-128PCS , DC#886-184PCS , DC#887-152PCS , DC#888-168PCS | F16: 4500147793-90 | G16: 92107-S001 | H16: 摇篮公子 | I16: 800 | J16: 0 | K16: 8 | L16: =I16/K16 -> 100 | M16: 45656 | N16: 45652 | P16: PASS | U16: 1/10出 | W16: 11/4收到 | X16: 无 | Y16: 无 | Z16: 12/6-价格贴纸客供 | AB16: 日期码格式：ZURU INC(BVI) 标准格式 日期：按实际生产日期 Packaging Info: MA UPC包装+价格贴纸，价格贴纸客供。 Remark: 1. 产品和包装上印刷tracking code信息，格式为ZURU常规格式。 2. 分5个DC出货，每款产品每个DC的箱唛资料不同。具体分DC数量，请参考后面行项目备注。 3. ZURU QC验货。 | AC16: Emily Wu | AD16: 4.2475 | AE16: =AD16*I16 -> 3398 | AF16: 94171-1.23 | AG16: 92107-S001 | AH16: 已入 | AI16: =I16 -> 800 | AO16: =I16 -> 800 | AT16: =I16/4 -> 200 | AU16: =AT16 -> 200 | AV16: =AU16 -> 200 | AW16: =AV16 -> 200 | BF16: =SUM(AT16:BE16)-I16 -> 0 | BJ16: =I16 -> 800 | BL16: MA | BN16: =I16/4 -> 200 | BO16: =I16/4 -> 200 | BP16: =I16/4 -> 200 | BQ16: =I16/4 -> 200 | BR16: =BN16+BO16+BP16+BQ16-I16 -> 0 | BS16: =BN16+BO16+BP16+BQ16+$BS$290 -> 513280 | BT16: =BT15-BN16 -> 129301.25 | BU16: =BU15-BO16 -> 129301.25 | BV16: =BV15-BP16 -> 129309.25 | BW16: =BW15-BQ16 -> 129642.58
A17: 45586 | B17: TJX COMPANIES, INC | C17: 美国 | D17: 4500147796 | E17: TJ MAXX DC#891-200PCS , DC#894-168PCS , DC#896-160PCS , DC#897-312PCS , DC#898-160PCS | F17: 4500147796-90 | G17: 92107-S001 | H17: 摇篮公子 | I17: 1000 | J17: 0 | K17: 8 | L17: =I17/K17 -> 125 | M17: 45656 | N17: 45652 | P17: PASS | U17: 1/8出 | W17: 11/4收到 | X17: 无 | Y17: 无 | Z17: 12/6-价格贴纸客供 | AB17: 日期码格式：ZURU INC(BVI) 标准格式 日期：按实际生产日期 Packaging Info: MA UPC包装+价格贴纸，价格贴纸客供。 Remark: 1. 产品和包装上印刷tracking code信息，格式为ZURU常规格式。 2. 分5个DC出货，每款产品每个DC的箱唛资料不同。具体分DC数量，请参考后面行项目备注。 3. ZURU QC验货。 | AC17: Emily Wu | AD17: 4.2475 | AE17: =AD17*I17 -> 4247.5 | AF17: 94170-1.23 | AG17: 92107-S001 | AH17: 已入 | AI17: =I17 -> 1000 | AO17: =I17 -> 1000 | AT17: =I17/4 -> 250 | AU17: =AT17 -> 250 | AV17: =AU17 -> 250 | AW17: =AV17 -> 250 | BF17: =SUM(AT17:BE17)-I17 -> 0 | BJ17: =I17 -> 1000 | BL17: MA | BN17: =I17/4 -> 250 | BO17: =I17/4 -> 250 | BP17: =I17/4 -> 250 | BQ17: =I17/4 -> 250 | BR17: =BN17+BO17+BP17+BQ17-I17 -> 0 | BS17: =BN17+BO17+BP17+BQ17+$BS$290 -> 513480 | BT17: =BT16-BN17 -> 129051.25 | BU17: =BU16-BO17 -> 129051.25 | BV17: =BV16-BP17 -> 129059.25 | BW17: =BW16-BQ17 -> 129392.58
A18: 45604 | B18: ASDA STORES LTD | C18: 英国 | D18: 4500150696 | E18: 2950866103 | F18: 4500150696-70 | G18: 92107SLB-S001 | H18: 摇篮公子88PCS/ctn/卡板 | I18: 968 | J18: 0 | K18: 88 | L18: =I18/K18 -> 11 | M18: 45656 | N18: 45652 | P18: PASS | U18: 1/8出 | W18: 11/29收到 | Y18: 11/29-卡板贴纸 | AB18: 日期码格式：ZURU INC(BVI) 标准格式 日期：按实际生产日期 Packaging Info: 5.92107SLB 92107-S003：MA最新1L UPC包装 UPC#193052064738, 请先检查条码是否正确再安排做货； 4 Assortment Ratio (Ladybug: Giraffe: Butterfly: Elephant)=1:1:1:1 Slip Sheet: 1 PCS/CTN, 22*4=88ctn=88pcs/slip sheet, 一共需要11套slip sheet; Slip Sheet打包好后，需要在正唛、侧唛右下角各贴一张slip sheet贴纸，直接用A4纸打印出来即可，贴纸尺寸160mm width x 140mm high； Slip Sheet尺寸限制为100*115*130CM，一旦实际SLIP SHEET尺寸超过这个尺寸，请提前通知ZURU跟单，需同客人确认才能量产和出货; Remark: 1. 产品及包装需要印UKCA图标，包装需要有ZURU UK LTD/ZURU France地址信息，QC同事请核查，如有问题与跟单确认 2. 产品/包装/外箱都需要打ZURU格式日期码，日期必须为法定工作日。 3. 需要符合欧洲标准不能含有闪粉和微塑料，否则不合法规会有客诉产生 | AC18: Amy Ding | AD18: 392.7986 | AE18: =AD18*I18 -> 380229.04 | AF18: 88944-1.8 | AG18: 92107SLB-S001 | AH18: 已入 | AI18: =I18 -> 968 | AO18: =I18 -> 968 | AT18: =I18/4 -> 242 | AU18: =AT18 -> 242 | AV18: =AU18 -> 242 | AW18: =AV18 -> 242 | BF18: =SUM(AT18:BE18)-I18 -> 0 | BJ18: =I18 -> 968 | BL18: MA | BN18: =I18/4 -> 242 | BO18: =I18/4 -> 242 | BP18: =I18/4 -> 242 | BQ18: =I18/4 -> 242 | BR18: =BN18+BO18+BP18+BQ18-I18 -> 0 | BS18: =BN18+BO18+BP18+BQ18+$BS$290 -> 513448 | BT18: =BT17-BN18 -> 128809.25 | BU18: =BU17-BO18 -> 128809.25 | BV18: =BV17-BP18 -> 128817.25 | BW18: =BW17-BQ18 -> 129150.58
A19: 45586 | B19: TJX COMPANIES, INC | C19: 美国 | D19: 4500147794 | E19: Marshalls DC#881-168PCS , DC#884-128PCS , DC#886-184PCS , DC#887-160PCS , DC#888-160PCS | F19: 4500147794-100 | G19: 92107-S001 | H19: 摇篮公子 | I19: 800 | J19: 0 | K19: 8 | L19: =I19/K19 -> 100 | M19: 45657 | N19: 45653 | P19: PASS | U19: 1/9出 | W19: 11/4收到 | X19: 无 | Y19: 无 | Z19: 12/6-价格贴纸客供 | AB19: 日期码格式：ZURU INC(BVI) 标准格式 日期：按实际生产日期 Packaging Info: MA UPC包装+价格贴纸，价格贴纸客供。 Remark: 1. 产品和包装上印刷tracking code信息，格式为ZURU常规格式。 2. 分5个DC出货，每款产品每个DC的箱唛资料不同。具体分DC数量，请参考后面行项目备注。 3. ZURU QC验货。 | AC19: Emily Wu | AD19: 4.2475 | AE19: =AD19*I19 -> 3398 | AF19: 94176-1.23 | AG19: 92107-S001 | AH19: 已入 | AI19: =I19 -> 800 | AO19: =I19 -> 800 | AT19: =I19/4 -> 200 | AU19: =AT19 -> 200 | AV19: =AU19 -> 200 | AW19: =AV19 -> 200 | BF19: =SUM(AT19:BE19)-I19 -> 0 | BJ19: =I19 -> 800 | BL19: MA | BN19: =I19/4 -> 200 | BO19: =I19/4 -> 200 | BP19: =I19/4 -> 200 | BQ19: =I19/4 -> 200 | BR19: =BN19+BO19+BP19+BQ19-I19 -> 0 | BS19: =BN19+BO19+BP19+BQ19+$BS$290 -> 513280 | BT19: =BT18-BN19 -> 128609.25 | BU19: =BU18-BO19 -> 128609.25 | BV19: =BV18-BP19 -> 128617.25 | BW19: =BW18-BQ19 -> 128950.58
A20: 45586 | B20: TJX COMPANIES, INC | C20: 美国 | D20: 4500147798 | E20: TJ MAXX DC#891-200PCS , DC#894-168PCS , DC#896-160PCS , DC#897-312PCS , DC#898-160PCS | F20: 4500147798-100 | G20: 92107-S001 | H20: 摇篮公子 | I20: 1000 | J20: 0 | K20: 8 | L20: =I20/K20 -> 125 | M20: 45657 | N20: 45653 | P20: PASS | U20: 1/8出 | W20: 11/4收到 | X20: 无 | Y20: 无 | Z20: 12/6-价格贴纸客供 | AB20: 日期码格式：ZURU INC(BVI) 标准格式 日期：按实际生产日期 Packaging Info: MA UPC包装+价格贴纸，价格贴纸客供。 Remark: 1. 产品和包装上印刷tracking code信息，格式为ZURU常规格式。 2. 分5个DC出货，每款产品每个DC的箱唛资料不同。具体分DC数量，请参考后面行项目备注。 3. ZURU QC验货。 | AC20: Emily Wu | AD20: 4.2475 | AE20: =AD20*I20 -> 4247.5 | AF20: 94174-1.23 | AG20: 92107-S001 | AH20: 已入 | AI20: =I20 -> 1000 | AO20: =I20 -> 1000 | AT20: =I20/4 -> 250 | AU20: =AT20 -> 250 | AV20: =AU20 -> 250 | AW20: =AV20 -> 250 | BF20: =SUM(AT20:BE20)-I20 -> 0 | BJ20: =I20 -> 1000 | BL20: MA | BN20: =I20/4 -> 250 | BO20: =I20/4 -> 250 | BP20: =I20/4 -> 250 | BQ20: =I20/4 -> 250 | BR20: =BN20+BO20+BP20+BQ20-I20 -> 0 | BS20: =BN20+BO20+BP20+BQ20+$BS$290 -> 513480 | BT20: =BT19-BN20 -> 128359.25 | BU20: =BU19-BO20 -> 128359.25 | BV20: =BV19-BP20 -> 128367.25 | BW20: =BW19-BQ20 -> 128700.58
A21: 45624 | B21: BIG W | C21: 澳大利亚 | D21: 4500152763 | E21: CUS PO#47779210 SYD | F21: 4500152763-20 | G21: 92107-S001 | H21: 摇篮公子 | I21: 656 | J21: 0 | K21: 8 | L21: =I21/K21 -> 82 | M21: 45657 | N21: 45653 | P21: PASS | U21: 1/3出 | W21: 11/28收到 | Y21: 进口商贴纸翻4500129569 | AB21: 日期码格式：ZURU INC(BVI) 标准格式 日期：按实际生产日期 Tracking Code: Packaging Info: 1. 包装 92107：英文MA包装 (UPC版本，首选1L，无1L可用多L含英语)+1张进口商贴纸，贴纸翻单4500129569 2. 产品和包装上的日期码一致，请按要求在包装上打日期码（进口商贴纸不覆盖日期码） 3. 使用ZURU标准日期码 Remark: 1. 共出4港口(SYD, BNE, MEL, FRE), 不同港口数量信息请见订单行项目，并请参考箱唛资料，港口不同，箱唛资料也不同； 2. 箱唛不可出现任何手写内容（箱数除外），重量与实际一致且不可手写; 3. 此单出澳大利亚，请按澳洲标准生产并满足当地法规要求; 4. 出无闪粉版本，需符合欧洲微塑料法规 | AC21: Christine Liao | AD21: 4.5774 | AE21: =AD21*I21 -> 3002.7744 | AF21: 88832-1.2 | AG21: 92107-S001 | AH21: 已入 | AI21: =I21 -> 656 | AO21: =I21 -> 656 | AT21: =I21/4 -> 164 | AU21: =I21/4 -> 164 | AV21: =I21/4 -> 164 | AW21: =I21/4 -> 164 | BF21: =SUM(AT21:BE21)-I21 -> 0 | BJ21: =I21 -> 656 | BL21: MA | BN21: =I21/4 -> 164 | BO21: =I21/4 -> 164 | BP21: =I21/4 -> 164 | BQ21: =I21/4 -> 164 | BR21: =BN21+BO21+BP21+BQ21-I21 -> 0 | BS21: =BN21+BO21+BP21+BQ21+$BS$290 -> 513136 | BT21: =BT20-BN21 -> 128195.25 | BU21: =BU20-BO21 -> 128195.25 | BV21: =BV20-BP21 -> 128203.25 | BW21: =BW20-BQ21 -> 128536.58
A22: 45624 | B22: BIG W | C22: 澳大利亚 | D22: 4500152763 | E22: CUS PO#47779211 BNE | F22: 4500152763-40 | G22: 92107-S001 | H22: 摇篮公子 | I22: 504 | J22: 0 | K22: 8 | L22: =I22/K22 -> 63 | M22: 45657 | N22: 45653 | P22: PASS | W22: 11/28收到 | Y22: 进口商贴纸翻4500129569 | AB22: 日期码格式：ZURU INC(BVI) 标准格式 日期：按实际生产日期 Tracking Code: Packaging Info: 1. 包装 92107：英文MA包装 (UPC版本，首选1L，无1L可用多L含英语)+1张进口商贴纸，贴纸翻单4500129569 2. 产品和包装上的日期码一致，请按要求在包装上打日期码（进口商贴纸不覆盖日期码） 3. 使用ZURU标准日期码 Remark: 1. 共出4港口(SYD, BNE, MEL, FRE), 不同港口数量信息请见订单行项目，并请参考箱唛资料，港口不同，箱唛资料也不同； 2. 箱唛不可出现任何手写内容（箱数除外），重量与实际一致且不可手写; 3. 此单出澳大利亚，请按澳洲标准生产并满足当地法规要求; 4. 出无闪粉版本，需符合欧洲微塑料法规 | AC22: Christine Liao | AD22: 4.5774 | AE22: =AD22*I22 -> 2307.0096 | AF22: 88853-1.3 | AG22: 92107-S001 | AH22: 已入 | AI22: =I22 -> 504 | AO22: =I22 -> 504 | AT22: =I22/4 -> 126 | AU22: =I22/4 -> 126 | AV22: =I22/4 -> 126 | AW22: =I22/4 -> 126 | BF22: =SUM(AT22:BE22)-I22 -> 0 | BJ22: =I22 -> 504 | BL22: MA | BN22: =I22/4 -> 126 | BO22: =I22/4 -> 126 | BP22: =I22/4 -> 126 | BQ22: =I22/4 -> 126 | BR22: =BN22+BO22+BP22+BQ22-I22 -> 0 | BS22: =BN22+BO22+BP22+BQ22+$BS$290 -> 512984 | BT22: =BT21-BN22 -> 128069.25 | BU22: =BU21-BO22 -> 128069.25 | BV22: =BV21-BP22 -> 128077.25 | BW22: =BW21-BQ22 -> 128410.58
A23: 45624 | B23: BIG W | C23: 澳大利亚 | D23: 4500152763 | E23: CUS PO#47779212 MEL | F23: 4500152763-60 | G23: 92107-S001 | H23: 摇篮公子 | I23: 504 | J23: 0 | K23: 8 | L23: =I23/K23 -> 63 | M23: 45657 | N23: 45653 | P23: PASS | U23: 1/4出 | W23: 11/28收到 | Y23: 进口商贴纸翻4500129569 | AB23: 日期码格式：ZURU INC(BVI) 标准格式 日期：按实际生产日期 Tracking Code: Packaging Info: 1. 包装 92107：英文MA包装 (UPC版本，首选1L，无1L可用多L含英语)+1张进口商贴纸，贴纸翻单4500129569 2. 产品和包装上的日期码一致，请按要求在包装上打日期码（进口商贴纸不覆盖日期码） 3. 使用ZURU标准日期码 Remark: 1. 共出4港口(SYD, BNE, MEL, FRE), 不同港口数量信息请见订单行项目，并请参考箱唛资料，港口不同，箱唛资料也不同； 2. 箱唛不可出现任何手写内容（箱数除外），重量与实际一致且不可手写; 3. 此单出澳大利亚，请按澳洲标准生产并满足当地法规要求; 4. 出无闪粉版本，需符合欧洲微塑料法规 | AC23: Christine Liao | AD23: 4.5774 | AE23: =AD23*I23 -> 2307.0096 | AF23: 88887-1.6 | AG23: 92107-S001 | AH23: 已入 | AI23: =I23 -> 504 | AO23: =I23 -> 504 | AT23: =I23/4 -> 126 | AU23: =I23/4 -> 126 | AV23: =I23/4 -> 126 | AW23: =I23/4 -> 126 | BF23: =SUM(AT23:BE23)-I23 -> 0 | BJ23: =I23 -> 504 | BL23: MA | BN23: =I23/4 -> 126 | BO23: =I23/4 -> 126 | BP23: =I23/4 -> 126 | BQ23: =I23/4 -> 126 | BR23: =BN23+BO23+BP23+BQ23-I23 -> 0 | BS23: =BN23+BO23+BP23+BQ23+$BS$290 -> 512984 | BT23: =BT22-BN23 -> 127943.25 | BU23: =BU22-BO23 -> 127943.25 | BV23: =BV22-BP23 -> 127951.25 | BW23: =BW22-BQ23 -> 128284.58
A24: 45624 | B24: BIG W | C24: 澳大利亚 | D24: 4500152763 | E24: CUS PO#47779213 FRE | F24: 4500152763-80 | G24: 92107-S001 | H24: 摇篮公子 | I24: 176 | J24: 0 | K24: 8 | L24: =I24/K24 -> 22 | M24: 45657 | N24: 45653 | P24: PASS | U24: 1/4出 | W24: 11/28收到 | Y24: 进口商贴纸翻4500129569 | AB24: 日期码格式：ZURU INC(BVI) 标准格式 日期：按实际生产日期 Tracking Code: Packaging Info: 1. 包装 92107：英文MA包装 (UPC版本，首选1L，无1L可用多L含英语)+1张进口商贴纸，贴纸翻单4500129569 2. 产品和包装上的日期码一致，请按要求在包装上打日期码（进口商贴纸不覆盖日期码） 3. 使用ZURU标准日期码 Remark: 1. 共出4港口(SYD, BNE, MEL, FRE), 不同港口数量信息请见订单行项目，并请参考箱唛资料，港口不同，箱唛资料也不同； 2. 箱唛不可出现任何手写内容（箱数除外），重量与实际一致且不可手写; 3. 此单出澳大利亚，请按澳洲标准生产并满足当地法规要求; 4. 出无闪粉版本，需符合欧洲微塑料法规 | AC24: Christine Liao | AD24: 4.5774 | AE24: =AD24*I24 -> 805.6224 | AF24: 88867-1.4 | AG24: 92107-S001 | AH24: 已入 | AI24: =I24 -> 176 | AO24: =I24 -> 176 | AT24: =I24/4 -> 44 | AU24: =I24/4 -> 44 | AV24: =I24/4 -> 44 | AW24: =I24/4 -> 44 | BF24: =SUM(AT24:BE24)-I24 -> 0 | BJ24: =I24 -> 176 | BL24: MA | BN24: =I24/4 -> 44 | BO24: =I24/4 -> 44 | BP24: =I24/4 -> 44 | BQ24: =I24/4 -> 44 | BR24: =BN24+BO24+BP24+BQ24-I24 -> 0 | BS24: =BN24+BO24+BP24+BQ24+$BS$290 -> 512656 | BT24: =BT23-BN24 -> 127899.25 | BU24: =BU23-BO24 -> 127899.25 | BV24: =BV23-BP24 -> 127907.25 | BW24: =BW23-BQ24 -> 128240.58
A25: 45604 | B25: THE ENTERTAINER | C25: 英国 | D25: 4500150141 | E25: 4500150141-1 | F25: 4500150141-20 | G25: 92107-S001 | H25: 摇篮公子 | I25: 2800 | J25: 0 | K25: 8 | L25: =I25/K25 -> 350 | M25: 45657 | N25: 45653 | P25: PASS | U25: 1/4出 | W25: 11/14收到 | Y25: 客户EAN条码贴翻4500148687 | AB25: 日期码格式：ZURU INC(BVI) 标准格式 日期：按实际生产日期 Packaging Info: 92107：MA最新1L-UPC配套包装+客户EAN条码贴一张覆盖ZURU 原条码，条码贴翻订单4500148687 4 Assortment Ratio (Ladybug: Giraffe: Butterfly: Elephant)=1:1:1:1 Remark: *MA版本按工厂现有最新库存即可，订单出英国，请注意检查产品及包装应带UKCA图标，包装显示ZURU UK LTD信息，QC同事请查核，如有问题与跟单确认。 *生产日期按实际（法定工作日），按ZURU标准格式即可 ，但是请知悉包装日期码需要早于或者等于外箱日期码 ，不能晚于外箱日期码 *请注意所有订单都需要经过ZURU QC验货并且通过后方可出货 *条码以订单显示为准 ，请安排生产前先核对 ，有问题请提出。 *所有产品按符合欧洲标准走货，需要是不含微塑料版本 。 *涉及到硼的，如可选择情况下应使用低硼版本 （slime 类别低硼一般低于300ppm)，无选择的应与跟单复核再安排 。 | AC25: Sherry Lu | AD25: 4.0808 | AE25: =AD25*I25 -> 11426.24 | AF25: 88877-1.4 | AG25: 92107-S001 | AH25: 已入 | AI25: =I25 -> 2800 | AP25: =I25 -> 2800 | AT25: =I25/4 -> 700 | AU25: =I25/4 -> 700 | AV25: =I25/4 -> 700 | AW25: =I25/4 -> 700 | BF25: =SUM(AT25:BE25)-I25 -> 0 | BJ25: =I25 -> 2800 | BL25: MA | BN25: =I25/4 -> 700 | BO25: =I25/4 -> 700 | BP25: =I25/4 -> 700 | BQ25: =I25/4 -> 700 | BR25: =BN25+BO25+BP25+BQ25-I25 -> 0 | BS25: =BN25+BO25+BP25+BQ25+$BS$290 -> 515280 | BT25: =BT24-BN25 -> 127199.25 | BU25: =BU24-BO25 -> 127199.25 | BV25: =BV24-BP25 -> 127207.25 | BW25: =BW24-BQ25 -> 127540.58
A26: 45618 | B26: CRG | C26: 哥斯达黎加 | D26: 4500152087 | E26: ZU01-25 | F26: 4500152087-120 | G26: 92107-S001 | H26: 摇篮公子 | I26: 504 | J26: 0 | K26: 8 | L26: =I26/K26 -> 63 | M26: 45660 | N26: 45656 | P26: PASS | U26: 1/8出 | W26: 11/27收到 | Y26: 12/10-进口商贴纸 | AB26: 日期码格式：ZURU INC(BVI) 标准格式 日期：按实际生产日期 Packaging Info: 92107:MA 1L包装+进口商贴纸+箱唛 Remark: | AC26: Ava Liang | AD26: 4.2475 | AE26: =AD26*I26 -> 2140.74 | AF26: 88961-1.9 | AG26: 92107-S001 | AH26: 已入 | AI26: =I26 -> 504 | AP26: =I26 -> 504 | AT26: =I26/4 -> 126 | AU26: =I26/4 -> 126 | AV26: =I26/4 -> 126 | AW26: =I26/4 -> 126 | BF26: =SUM(AT26:BE26)-I26 -> 0 | BJ26: =I26 -> 504 | BL26: MA | BN26: =I26/4 -> 126 | BO26: =I26/4 -> 126 | BP26: =I26/4 -> 126 | BQ26: =I26/4 -> 126 | BR26: =BN26+BO26+BP26+BQ26-I26 -> 0 | BS26: =BN26+BO26+BP26+BQ26+$BS$290 -> 512984 | BT26: =BT25-BN26 -> 127073.25 | BU26: =BU25-BO26 -> 127073.25 | BV26: =BV25-BP26 -> 127081.25 | BW26: =BW25-BQ26 -> 127414.58
A27: 45625 | B27: TJX UK | C27: 英国 | D27: 4500152937 | E27: PO#50343349 | F27: 4500152937-60 | G27: 92107-S001 | H27: 摇篮公子 | I27: 600 | J27: 0 | K27: 8 | L27: =I27/K27 -> 75 | M27: 45660 | N27: 45656 | P27: PASS | U27: 1/10出 | W27: 12/5收到 | Y27: 12/6-客供价格贴纸 | AB27: 日期码格式：ZURU INC(BVI) 标准格式 日期：按实际生产日期 Packaging Info: TJX UK: PO#50343294(9283) <(>&<)> PO#50343296(9258) <(>&<)> PO#50343296(9281) <(>&<)> PO#50343305(9298) <(>&<)> PO#50343349(7132) <(>&<)> PO#503 43349(92107) <(>&<)> PO#50343392(9279) <(>&<)> PO#50343399(9279) 6) 92107: MA3L (9Lwanrning) B版收缩膜+其他最新MA配套包装+1张客供价格贴纸 8) 最迟验货时间不得晚于1/4 Remark: 1. 出往UK的产品+包装务必打上UKCA logo ，否则客人会退货且当地会有罚款； 2. 订单必须经过ZURU QC验货并且通过后方可出货； 3. 订单每行对应客人不同的PO， 箱唛也有不同，做货的时候请分开堆放； 4. 订单每行对应客人不同的PO，即同款item的价格贴纸都不相同，请注意收到贴纸后不要弄混!（客人PO号请参考PO最后一栏remark）； 5. 价格贴纸位置为产品正面右上角，不能遮住产品信息，大货生产前，请把贴纸位置先发给跟单确认 6. 涉及到相关款式会有闪粉的或 者微塑料的，请统一默认出无闪粉或者不含微塑料 版本; 7. 外箱封箱必须是工字型封箱方式； | AC27: Zoe Chen | AD27: 4.2475 | AE27: =AD27*I27 -> 2548.5 | AF27: 88937-1.8 | AG27: 92107-S001-3L | AH27: 已入 | AL27: =I27 -> 600 | AP27: =I27 -> 600 | AT27: =I27/4 -> 150 | AU27: =I27/4 -> 150 | AV27: =I27/4 -> 150 | AW27: =I27/4 -> 150 | BF27: =SUM(AT27:BE27)-I27 -> 0 | BJ27: =I27 -> 600 | BL27: MA | BN27: =I27/4 -> 150 | BO27: =I27/4 -> 150 | BP27: =I27/4 -> 150 | BQ27: =I27/4 -> 150 | BR27: =BN27+BO27+BP27+BQ27-I27 -> 0 | BS27: =BN27+BO27+BP27+BQ27+$BS$290 -> 513080 | BT27: =BT26-BN27 -> 126923.25 | BU27: =BU26-BO27 -> 126923.25 | BV27: =BV26-BP27 -> 126931.25 | BW27: =BW26-BQ27 -> 127264.58
A28: 45625 | B28: TJX UK c/o TJX Distribution Ltd & C | C28: 德国 | D28: 4500152906 | E28: TJX Europe(DE): PO#55343920 | F28: 4500152906-90 | G28: 92107-S001 | H28: 摇篮公子 | I28: 704 | J28: 0 | K28: 8 | L28: =I28/K28 -> 88 | M28: 45660 | N28: 45656 | P28: PASS | U28: 1/9出 | W28: 12/5收到 | Y28: 12/6-客供价格贴纸+含波兰语警告语翻4500150830 | AB28: 日期码格式：ZURU INC(BVI) 标准格式 日期：按实际生产日期 Packaging Info: TJX Europe(DE): PO#55343895(9283) <(>&<)> PO#55343898(9258) <(>&<)> PO#55343898(9281) <(>&<)> PO#55343901(9281) <(>&<)> PO#55343906(9298) <(>& <)> PO#55343909(9298) <(>&<)> PO#55343918(7132) <(>&<)> PO#55343920(7132) <(>&<)> PO#55343920(92107) <(>&<)> PO#55343844(9279) <(>&<)> PO#553438 77(9279) 6) 92107: MA3L (9Lwanrning) B版收缩膜+其他最新MA配套包装+1张客供价格贴纸+1张贴纸（含波兰语警告语) 8) 最迟验货时间不得晚于1/4 Remark: 1. 出往UK的产品+包装务必打上UKCA logo ，否则客人会退货且当地会有罚款； 2.订单必须经过ZURU QC验货并且通过后方可出货； 3. 订单每行对应客人不同的PO， 箱唛也有不同，做货的时候请分开堆放； 4. 订单每行对应客人不同的PO，即同款item的价格贴纸都不相同，请注意收到贴纸后不要弄混!（客人PO号请参考PO最后一栏remark）； 5. 价格贴纸位置为产品正面右上角，不能遮住产品信息，大货生产前，请把贴纸位置先发给跟单确认 6. 涉及到相关款式会有闪粉的或者微塑料的，请统一默认出无闪粉或者不含微塑料版本; 7. 外箱封箱必须是工字型封箱方式； | AC28: Zoe Chen | AD28: 4.2475 | AE28: =AD28*I28 -> 2990.24 | AF28: 88936-1.8 | AG28: 92107-S001-3L | AH28: 已入 | AL28: =I28 -> 704 | AP28: =I28 -> 704 | AT28: =I28/4 -> 176 | AU28: =I28/4 -> 176 | AV28: =I28/4 -> 176 | AW28: =I28/4 -> 176 | BF28: =SUM(AT28:BE28)-I28 -> 0 | BJ28: =I28 -> 704 | BL28: MA | BN28: =I28/4 -> 176 | BO28: =I28/4 -> 176 | BP28: =I28/4 -> 176 | BQ28: =I28/4 -> 176 | BR28: =BN28+BO28+BP28+BQ28-I28 -> 0 | BS28: =BN28+BO28+BP28+BQ28+$BS$290 -> 513184 | BT28: =BT27-BN28 -> 126747.25 | BU28: =BU27-BO28 -> 126747.25 | BV28: =BV27-BP28 -> 126755.25 | BW28: =BW27-BQ28 -> 127088.58
A29: 45623 | B29: MEIJER | C29: 美国 | D29: 4500152685 | E29: 216641089 | F29: 4500152685-10 | G29: 92107-S005 | H29: 摇篮公子 | I29: 852 | J29: 0 | K29: 2 | L29: =I29/K29 -> 426 | M29: 45662 | N29: 45658 | P29: PASS | U29: 收到SO | W29: 11/28收到 | Y29: 无 | AB29: 日期码格式：ZURU INC(BVI) 标准格式 日期：按实际生产日期 Packaging Info: 1. MA 1L 包装 2. 客人指定箱唛排版 Remark: 出货前 Zuru QC 验货 | AC29: Sophia Zhou | AD29: 4.7334 | AE29: =AD29*I29 -> 4032.8568 | AF29: 88932-1.8 | AG29: 92107-S005 | AH29: 已入 | AI29: =I29 -> 852 | AP29: =I29 -> 852 | AT29: =I29/4 -> 213 | AU29: =I29/4 -> 213 | AV29: =I29/4 -> 213 | AW29: =I29/4 -> 213 | BF29: =SUM(AT29:BE29)-I29 -> 0 | BJ29: =I29 -> 852 | BL29: MA | BN29: =I29/4 -> 213 | BO29: =I29/4 -> 213 | BP29: =I29/4 -> 213 | BQ29: =I29/4 -> 213 | BR29: =BN29+BO29+BP29+BQ29-I29 -> 0 | BS29: =BN29+BO29+BP29+BQ29+$BS$290 -> 513332 | BT29: =BT28-BN29 -> 126534.25 | BU29: =BU28-BO29 -> 126534.25 | BV29: =BV28-BP29 -> 126542.25 | BW29: =BW28-BQ29 -> 126875.58
A30: 45623 | B30: MEIJER | C30: 美国 | D30: 4500152678 | E30: 216641085 | F30: 4500152678-10 | G30: 92107-S005 | H30: 摇篮公子 | I30: 1548 | J30: 0 | K30: 2 | L30: =I30/K30 -> 774 | M30: 45662 | N30: 45658 | P30: PASS | U30: 收到SO | W30: 11/28收到 | Y30: 无 | AB30: 日期码格式：ZURU INC(BVI) 标准格式 日期：按实际生产日期 Packaging Info: 1. MA 1L 包装 2. 客人指定箱唛排版 Remark: 出货前 Zuru QC 验货 | AC30: Sophia Zhou | AD30: 4.7221 | AE30: =AD30*I30 -> 7309.8108 | AF30: 88931-1.8 | AG30: 92107-S005 | AH30: 已入 | AI30: =I30 -> 1548 | AP30: =I30 -> 1548 | AT30: =I30/4 -> 387 | AU30: =I30/4 -> 387 | AV30: =I30/4 -> 387 | AW30: =I30/4 -> 387 | BF30: =SUM(AT30:BE30)-I30 -> 0 | BJ30: =I30 -> 1548 | BL30: MA | BN30: =I30/4 -> 387 | BO30: =I30/4 -> 387 | BP30: =I30/4 -> 387 | BQ30: =I30/4 -> 387 | BR30: =BN30+BO30+BP30+BQ30-I30 -> 0 | BS30: =BN30+BO30+BP30+BQ30+$BS$290 -> 514028 | BT30: =BT29-BN30 -> 126147.25 | BU30: =BU29-BO30 -> 126147.25 | BV30: =BV29-BP30 -> 126155.25 | BW30: =BW29-BQ30 -> 126488.58
A31: 45604 | B31: AEON TOPVALU (HONG KONG) CO.,LTD | C31: 柬埔寨 | D31: 4500150770 | E31: SDN24-0024 | F31: 4500150770-10 | G31: 92107-S001 | H31: 摇篮公子 | I31: 256 | J31: 0 | K31: 8 | L31: =I31/K31 -> 32 | M31: 45663 | N31: 45659 | P31: PASS | U31: 1/15出 | W31: 11/11收到 | Y31: 无 | AB31: 日期码格式：ZURU INC(BVI) 标准格式 日期：按实际生产日期 Packaging Info: MA PKG, 优先1L Remark: 出柬埔寨 | AC31: Doris Shou | AD31: 4.3169 | AE31: =AD31*I31 -> 1105.1264 | AF31: 94063-1.16 | AG31: 92107-S001 | AH31: 已入 | AI31: =I31 -> 256 | AP31: =I31 -> 256 | AT31: =I31/4 -> 64 | AU31: =AT31 -> 64 | AV31: =AU31 -> 64 | AW31: =AV31 -> 64 | BF31: =SUM(AT31:BE31)-I31 -> 0 | BJ31: =I31 -> 256 | BL31: MA | BN31: =I31/4 -> 64 | BO31: =I31/4 -> 64 | BP31: =I31/4 -> 64 | BQ31: =I31/4 -> 64 | BR31: =BN31+BO31+BP31+BQ31-I31 -> 0 | BS31: =BN31+BO31+BP31+BQ31+$BS$290 -> 512736 | BT31: =BT30-BN31 -> 126083.25 | BU31: =BU30-BO31 -> 126083.25 | BV31: =BV30-BP31 -> 126091.25 | BW31: =BW30-BQ31 -> 126424.58
A32: 45623 | B32: AMAZON.COM.DEDC,LLC | C32: 美国 | D32: 4500152379 | E32: 5NFG96GC | F32: 4500152379-230 | G32: 92107D-S001 | H32: 蝴蝶 | I32: 240 | J32: 0 | K32: 8 | L32: =I32/K32 -> 30 | M32: 45664 | N32: 45660 | P32: PASS | U32: 2/7出 | W32: 11/27收到 | Y32: UPC贴纸翻450013436 | Z32: 12/20-外箱贴纸 | AB32: 日期码格式： 标准格式 日期：按实际生产日期 Packaging Info: #92107 MA 1L UPC版本+ UPC贴纸跟返单4500134367；92107A:193052066817, 92107D:193052066831, 92107E:193052066848; Remark: 1. Amazon FOB订单，出口US。 2. 日期码使用ZURU标准版本。 3. 如果大货有要求入邮包盒，则对应的邮包盒上面要打上日期码。 4. 箱尺寸要求：外箱最长边不能超过25" （超过了，case pack只能为1），不符合要求的大货，一律不接受。 5. 外箱箱唛要求： ①外箱正面印ZURU Logo+SSCC Label（客供贴纸，由跟单订购)。关于 SSCC Label 请注意： SSCC Label 显示的是客人自己的item#。每一张SSCC label 都是唯一且有不同流水及条码的，没有损耗，绝对不可贴错 。如果贴错或损坏任何一张，都会导致全 部都错，千万要注意！ SSCC Label 必须贴在外箱正面的正中间位置（贴一面即可），并且贴纸离外箱边距必须至少3cm(可以覆盖Logo<(>&<)>箱唛)，否则会影响到客户那边仓库的扫描识 别。 ②外箱侧面印item#（订单上显示的SKU#)+carton size(以工厂实际尺寸为准,单位: inch) +MADE IN CHINA,日期使用ZURU 标准版本。 6. 装柜要求：按照客户PO# 装柜/箱号顺序装柜，跟单会提前给到装柜计划。 在大货生产/仓库存放时，请留意该装柜要求，以便装柜时不混乱（避免装错/装漏/找不到货号等）。 | AC32: Kelly Shen | AD32: 4.2589 | AE32: =AD32*I32 -> 1022.136 | AF32: 94201-2.10 | AG32: 92107D-S001 | AH32: 已入 | AI32: =I32 -> 240 | AP32: =I32 -> 240 | AX32: =I32 -> 240 | BF32: =SUM(AT32:BE32)-I32 -> 0 | BJ32: =I32 -> 240 | BL32: MA | BN32: =I32 -> 240 | BR32: =BN32+BO32+BP32+BQ32-I32 -> 0 | BS32: =BN32+BO32+BP32+BQ32+$BS$290 -> 512720 | BT32: =BT31-BN32 -> 125843.25 | BU32: =BU31-BO32 -> 126083.25 | BV32: =BV31-BP32 -> 126091.25 | BW32: =BW31-BQ32 -> 126424.58
A33: 45623 | B33: AMAZON.COM.DEDC,LLC | C33: 美国 | D33: 4500152379 | E33: 2LWM8QCA | F33: 4500152379-240 | G33: 92107D-S001 | H33: 蝴蝶 | I33: 208 | J33: 0 | K33: 8 | L33: =I33/K33 -> 26 | M33: 45664 | N33: 45660 | P33: PASS | U33: 2/7出 | W33: 11/27收到 | Y33: UPC贴纸翻450013436 | Z33: 12/20-外箱贴纸 | AB33: 日期码格式： 标准格式 日期：按实际生产日期 Packaging Info: #92107 MA 1L UPC版本+ UPC贴纸跟返单4500134367；92107A:193052066817, 92107D:193052066831, 92107E:193052066848; Remark: 1. Amazon FOB订单，出口US。 2. 日期码使用ZURU标准版本。 3. 如果大货有要求入邮包盒，则对应的邮包盒上面要打上日期码。 4. 箱尺寸要求：外箱最长边不能超过25" （超过了，case pack只能为1），不符合要求的大货，一律不接受。 5. 外箱箱唛要求： ①外箱正面印ZURU Logo+SSCC Label（客供贴纸，由跟单订购)。关于 SSCC Label 请注意： SSCC Label 显示的是客人自己的item#。每一张SSCC label 都是唯一且有不同流水及条码的，没有损耗，绝对不可贴错 。如果贴错或损坏任何一张，都会导致全 部都错，千万要注意！ SSCC Label 必须贴在外箱正面的正中间位置（贴一面即可），并且贴纸离外箱边距必须至少3cm(可以覆盖Logo<(>&<)>箱唛)，否则会影响到客户那边仓库的扫描识 别。 ②外箱侧面印item#（订单上显示的SKU#)+carton size(以工厂实际尺寸为准,单位: inch) +MADE IN CHINA,日期使用ZURU 标准版本。 6. 装柜要求：按照客户PO# 装柜/箱号顺序装柜，跟单会提前给到装柜计划。 在大货生产/仓库存放时，请留意该装柜要求，以便装柜时不混乱（避免装错/装漏/找不到货号等）。 | AC33: Kelly Shen | AD33: 4.2589 | AE33: =AD33*I33 -> 885.8512 | AF33: 94201-2.10 | AG33: 92107D-S001 | AH33: 已入 | AI33: =I33 -> 208 | AP33: =I33 -> 208 | AX33: =I33 -> 208 | BF33: =SUM(AT33:BE33)-I33 -> 0 | BJ33: =I33 -> 208 | BL33: MA | BN33: =I33 -> 208 | BR33: =BN33+BO33+BP33+BQ33-I33 -> 0 | BS33: =BN33+BO33+BP33+BQ33+$BS$290 -> 512688 | BT33: =BT32-BN33 -> 125635.25 | BU33: =BU32-BO33 -> 126083.25 | BV33: =BV32-BP33 -> 126091.25 | BW33: =BW32-BQ33 -> 126424.58
A34: 45623 | B34: AMAZON.COM.DEDC,LLC | C34: 美国 | D34: 4500152657 | E34: 5WZ1EI7C | F34: 4500152657-60 | G34: 92107D-S001 | H34: 蝴蝶 | I34: 760 | J34: 0 | K34: 8 | L34: =I34/K34 -> 95 | M34: 45664 | N34: 45660 | P34: PASS | U34: 1/15-1/20出 | W34: 11/27收到 | Y34: UPC贴纸翻450013436 | Z34: 12/20-外箱贴纸 | AB34: 日期码格式： 标准格式 日期：按实际生产日期 Packaging Info: #92107 MA 1L UPC版本+ UPC贴纸跟返单4500134367；92107A:193052066817, 92107D:193052066831, 92107E:193052066848; Remark: 1. Amazon FOB订单，出口US。 2. 日期码使用ZURU标准版本。 3. 如果大货有要求入邮包盒，则对应的邮包盒上面要打上日期码。 4. 箱尺寸要求：外箱最长边不能超过25" （超过了，case pack只能为1），不符合要求的大货，一律不接受。 5. 外箱箱唛要求： ①外箱正面印ZURU Logo+SSCC Label（客供贴纸，由跟单订购)。关于 SSCC Label 请注意： SSCC Label 显示的是客人自己的item#。每一张SSCC label 都是唯一且有不同流水及条码的，没有损耗，绝对不可贴错 。如果贴错或损坏任何一张，都会导致全 部都错，千万要注意！ SSCC Label 必须贴在外箱正面的正中间位置（贴一面即可），并且贴纸离外箱边距必须至少3cm(可以覆盖Logo<(>&<)>箱唛)，否则会影响到客户那边仓库的扫描识 别。 ②外箱侧面印item#（订单上显示的SKU#)+carton size(以工厂实际尺寸为准,单位: inch) +MADE IN CHINA,日期使用ZURU 标准版本。 6. 装柜要求：按照客户PO# 装柜/箱号顺序装柜，跟单会提前给到装柜计划。 在大货生产/仓库存放时，请留意该装柜要求，以便装柜时不混乱（避免装错/装漏/找不到货号等）。 | AC34: Kelly Shen | AD34: 4.2475 | AE34: =AD34*I34 -> 3228.1 | AF34: 94229-2.12 | AG34: 92107D-S001 | AH34: 已入 | AI34: =I34 -> 760 | AP34: =I34 -> 760 | AX34: =I34 -> 760 | BF34: =SUM(AT34:BE34)-I34 -> 0 | BJ34: =I34 -> 760 | BL34: MA | BN34: =I34 -> 760 | BR34: =BN34+BO34+BP34+BQ34-I34 -> 0 | BS34: =BN34+BO34+BP34+BQ34+$BS$290 -> 513240 | BT34: =BT33-BN34 -> 124875.25 | BU34: =BU33-BO34 -> 126083.25 | BV34: =BV33-BP34 -> 126091.25 | BW34: =BW33-BQ34 -> 126424.58
A35: 45623 | B35: HEB GROCERY COMPANY, LP | C35: 美国 | D35: 4500152429 | E35: PO#60X356498 | F35: 4500152429-60 | G35: 92107-S005 | H35: 摇篮公子 | I35: 590 | J35: 0 | K35: 2 | L35: =I35/K35 -> 295 | M35: 45665 | N35: 45661 | O35: 1/9第三方 | P35: PASS | U35: 1/16出 | W35: 11/27收到 | Y35: 无 | AB35: 日期码格式：ZURU INC(BVI) 标准格式 日期：按实际生产日期 Packaging Info: 1. ZURU MA UPC版本，出口美国. Remark: 2. 日期跟踪码：ZURU标准格式日期码，产品包装及产品本身都必须有ZURU标准格式日期码，并且确保两者信息保持一致(请自行调整具体年月日生产期，但不能为周末）。 针对你们目前没办法保持日期码一致的做法是： * 大货：可以按照实际生产的日期码打，毛绒布标和蛋壳上的日期码格式和时间这次特例可以不保持一致出货；但到时需手动贴一套公仔的布标贴纸，使布标跟蛋壳 日期码格式和时间一样，拍照给我们发给实验室review 日期码，让实验室知道订单大货出的日期码格式和时间是跟抽板指定款的保持一样。 * 指定款抽板：需手动贴布标贴纸，保证布标跟蛋壳上的日期码格式和时间都一样，且这个时间要跟大货的时间一样。 3. 大货样 4. 验货+ 抽板 （同一天进行） 预约1月9日第三方（利丰）到工厂做100%大货现场验货和抽板，验货需打印EPM出来跟客户回签样板供第三方验货参考。 PS:EPM是跟单提供。 抽板： 因#92107的ZURU测试报告上被客户指定实验室发现产品和产品包装上的日期码不一致，所以这款寄样给实验室的是按照 利丰验货员现场针对指定款随机抽板6PCS（须带包装）;其他利丰验货员现场针对指定款随机抽板6PCS。 工厂需把抽板寄到以下MTS 地址做测试，测试通过后才能出货；如产品有油漆的工厂需额外准备5G/色的油漆涂在同材质胶件上(面积类似A4纸大小)一并寄出； 实验室收件地址： 东莞现代产品整理服务有限公司（MTS） 广东省东莞市寮步镇新旧围村良平路76号 收件人：Cherry Wang （汪单） Tel: +86 769- 8112 0818 ext.893 抽板有随样文件TRF（跟单提供），工厂在寄样时打印出来放纸箱内随样寄走。 5. 出货配比：ZURU 标版配比 6. ZURU QA 验货时需拍齐每款角色的产品和产品包装上的日期码照片（供实验室review） | AC35: Elsa Zheng | AD35: 4.3446 | AE35: =AD35*I35 -> 2563.314 | AF35: 94152-1.22 | AG35: 92107-S005 | AH35: 已入 | AJ35: =I35 -> 590 | AP35: =I35 -> 590 | AX35: =I35/4 -> 147.5 | AY35: =I35/4 -> 147.5 | AZ35: =AY35 -> 147.5 | BA35: =I35/4 -> 147.5 | BF35: =SUM(AT35:BE35)-I35 -> 0 | BJ35: =I35 -> 590 | BL35: MA | BN35: =I35/4 -> 147.5 | BO35: =I35/4 -> 147.5 | BP35: =I35/4 -> 147.5 | BQ35: =I35/4 -> 147.5 | BR35: =BN35+BO35+BP35+BQ35-I35 -> 0 | BS35: =BN35+BO35+BP35+BQ35+$BS$290 -> 513070 | BT35: =BT34-BN35 -> 124727.75 | BU35: =BU34-BO35 -> 125935.75 | BV35: =BV34-BP35 -> 125943.75 | BW35: =BW34-BQ35 -> 126277.08
A36: 45645 | D36: ZMPO24972 | G36: 92107-S001 | H36: 摇篮公子 | I36: 120 | J36: 0 | K36: 8 | L36: =I36/K36 -> 15 | M36: 45665 | N36: 45661 | P36: PASS | W36: 周转箱 | Y36: 无 | AB36: Remark：大货最新版本/请用大货标准箱装箱/箱唛请参照邮件附件 备注： 收到样品订单后尽快安排 ，注意样板品质质量要求要高于大货品质要求 ，送货时必须要附带送货单(没有送货单和QC检验合格报告的仓库一律拒绝收货)，请知悉，谢谢！ | AC36: Angus | AG36: 92107-S001 | AH36: 已入 | AJ36: =I36 -> 120 | AP36: =I36 -> 120 | AX36: =I36/4 -> 30 | AY36: =AX36 -> 30 | AZ36: =AX36 -> 30 | BA36: =AX36 -> 30 | BJ36: =I36 -> 120 | BL36: MA | BN36: =I36/4 -> 30 | BO36: =I36/4 -> 30 | BP36: =I36/4 -> 30 | BQ36: =I36/4 -> 30 | BR36: =BN36+BO36+BP36+BQ36-I36 -> 0 | BS36: =BN36+BO36+BP36+BQ36+$BS$290 -> 512600 | BT36: =BT35-BN36 -> 124697.75 | BU36: =BU35-BO36 -> 125905.75 | BV36: =BV35-BP36 -> 125913.75 | BW36: =BW35-BQ36 -> 126247.08
A37: 45615 | B37: VM INTERNATIONAL | C37: 美国 | D37: 4500151779 | F37: 4500151779-30 | G37: 92107-S001 | H37: 摇篮公子 | I37: 640 | J37: 0 | K37: 8 | L37: 80 | M37: 45666 | N37: 45663 | P37: PASS | U37: 1/13出 | W37: 12/11收到 | Y37: 无 | AB37: 日期码格式：ZURU INC(BVI) 标准格式 日期：按实际生产日期 Packaging Info: 1.ZURU 标准日期码格式， 2.无第三方测试和验货，ZURU 内部QC验货即可出货 Remark: 3. 优先 MA 1L UPC包装; 4. 纸箱印ZURU LOGO，出口美国； | AC37: Iris Yuan | AD37: 4.2475 | AE37: 2718.4 | AF37: 94112-1.18 | AG37: 92107-S001 | AH37: 已入 | AI37: =I37 -> 640 | AO37: =I37 -> 640 | AT37: =I37/4 -> 160 | AU37: =AT37 -> 160 | AV37: =AU37 -> 160 | AW37: =AV37 -> 160 | BF37: =SUM(AT37:BE37)-I37 -> 0 | BJ37: =I37 -> 640 | BL37: MA | BM37: 160 | BN37: =I37/4 -> 160 | BO37: =I37/4 -> 160 | BP37: =I37/4 -> 160 | BQ37: =I37/4 -> 160 | BR37: =BN37+BO37+BP37+BQ37-I37 -> 0 | BS37: =BN37+BO37+BP37+BQ37+$BS$290 -> 513120 | BT37: =BT36-BN37 -> 124537.75 | BU37: =BU36-BO37 -> 125745.75 | BV37: =BV36-BP37 -> 125753.75 | BW37: =BW36-BQ37 -> 126087.08
A38: 45629 | B38: FREDMEYER INC | C38: 美国 | D38: 4500153169 | E38: PO#0000373341 06 | F38: 4500153169-40 | G38: 92107-S002 | H38: 摇篮公子 | I38: 300 | J38: 0 | K38: 4 | L38: =I38/K38 -> 75 | M38: 45670 | N38: 45666 | P38: PASS | U38: 1/16出 | W38: 12/3收到 | Y38: 无 | AB38: 日期码格式：ZURU INC(BVI) 标准格式 日期：按实际生产日期 Packaging Info: 1、包装方式: MA UPC优先1L最新版本，出口美国 Remark: 2、无测试无第三方验货要求。 3、纸箱4面印ZURU LOGO + 箱唛 4、日期码请按ZURU标准版执行即可。 5、ZURU QC验货。 6、Ratio: #92107: 4 Assortment Ratio (Ladybug: Giraffe: Butterfly: Elephant)=1:1:1:1 | AC38: Vicky Wu | AD38: 4.1317 | AE38: =AD38*I38 -> 1239.51 | AF38: 94067-1.16 | AG38: 92107-S002 | AH38: 已入 | AJ38: =I38 -> 300 | AP38: =I38 -> 300 | AX38: =I38/4 -> 75 | AY38: =I38/4 -> 75 | AZ38: =I38/4 -> 75 | BA38: =I38/4 -> 75 | BF38: =SUM(AT38:BE38)-I38 -> 0 | BJ38: =I38 -> 300 | BL38: MA | BN38: =I38/4 -> 75 | BO38: =I38/4 -> 75 | BP38: =I38/4 -> 75 | BQ38: =I38/4 -> 75 | BR38: =BN38+BO38+BP38+BQ38-I38 -> 0 | BS38: =BN38+BO38+BP38+BQ38+$BS$290 -> 512780 | BT38: =BT37-BN38 -> 124462.75 | BU38: =BU37-BO38 -> 125670.75 | BV38: =BV37-BP38 -> 125678.75 | BW38: =BW37-BQ38 -> 126012.08
A39: 45635 | B39: BINGO GLOBAL GROUP FOR TRADING SUPP | C39: 埃及 | D39: 4500153513 | F39: 4500153513-50 | G39: 92107-S001 | H39: 摇篮公子 | I39: 800 | J39: 0 | K39: 8 | L39: =I39/K39 -> 100 | M39: 45672 | N39: 45668 | P39: PASS | U39: 收到SO | W39: 12/12收到 | Y39: 12-12进口商贴纸 | AB39: 日期码格式：ZURU INC(BVI) 标准格式 日期：按实际生产日期 Packaging Info: 92107:3L MA EAN 收缩膜+进口商贴纸;MA指南 Remark: 标准产品标准配比 | AC39: Lena Huang | AD39: 4.2475 | AE39: =AD39*I39 -> 3398 | AF39: 94081-1.17 | AG39: 92107-S001-3L | AH39: 已入 | AL39: =I39 -> 800 | AP39: =I39 -> 800 | AX39: =I39/4 -> 200 | AY39: =AX39 -> 200 | AZ39: =AX39 -> 200 | BA39: =AX39 -> 200 | BF39: =SUM(AT39:BE39)-I39 -> 0 | BJ39: =I39 -> 800 | BL39: MA | BN39: =I39/4 -> 200 | BO39: =I39/4 -> 200 | BP39: =I39/4 -> 200 | BQ39: =I39/4 -> 200 | BR39: =BN39+BO39+BP39+BQ39-I39 -> 0 | BS39: =BN39+BO39+BP39+BQ39+$BS$290 -> 513280 | BT39: =BT38-BN39 -> 124262.75 | BU39: =BU38-BO39 -> 125470.75 | BV39: =BV38-BP39 -> 125478.75 | BW39: =BW38-BQ39 -> 125812.08
A40: 45636 | D40: ZMPO24940 | G40: 92107-S003-NB | H40: 摇篮公子 | I40: 2 | J40: 0 | K40: 1 | L40: =I40/K40 -> 2 | M40: 45649 | N40: 45645 | P40: 已送货 | W40: 周转箱 | Y40: UPC条码贴纸 | AB40: Remark：跟订单4500146212一起安排/MA3L收缩膜+UPC条码贴纸(UPC: 193052064738)+MA5L收藏指南+MA5L资料卡+MA5L胶袋+MA配件袋+MA2L布标 备注： 收到样品订单后尽快安排 ，注意样板品质质量要求要高于大货品质要求 ，送货时必须要附带送货单(没有送货单和QC检验合格报告的仓库一律拒绝收货)，请知悉，谢谢！ | AG40: 92107-S003-NB-3L | AH40: 已入 | AL40: =I40 -> 2 | AP40: =I40 -> 2 | AT40: 1 | AU40: 1 | BF40: =SUM(AT40:BE40)-I40 -> 0 | BK40: =I40 -> 2 | BL40: MA | BN40: 1 | BO40: 1 | BR40: =BN40+BO40+BP40+BQ40-I40 -> 0 | BS40: =BN40+BO40+BP40+BQ40+$BS$290 -> 512482 | BT40: =BT39-BN40 -> 124261.75 | BU40: =BU39-BO40 -> 125469.75 | BV40: =BV39-BP40 -> 125478.75 | BW40: =BW39-BQ40 -> 125812.08
...

Sheet 92108
A1: ZURU Babycorns Surprise - S1生产排期表 #92108 | J1: 不带电出货 | BC1: 中东客 | BF1: ICMA剩余 | BG1: ='IC MA'!S10-'IC MA'!S6-BF111 -> 1035615 | BR1: 兔子（机芯款） | BS1: 兔子（小公仔） | BT1: 独角兽（机芯款） | BU1: 独角兽（小公仔） | BV1: 小猫（机芯款） | BW1: 美国猫（小公仔） | BX1: 斑点狗（机芯款） | BY1: 斑点狗（小公仔）
AD2: 收缩膜 | AJ2: 收藏指南 | AO2: 阅读卡 MA 5L | AS2: 阅读卡 MA 5L B版 | AW2: 阅读卡 中文 | BA2: 92108F | BC2: 134696 | BD2: 口水胶 | BF2: IC | BG2: 布标 | BI2: 兔子（机芯款） | BJ2: 兔子（小公仔） | BK2: 独角兽（机芯款） | BL2: 独角兽（小公仔） | BM2: 小猫（机芯款） | BN2: 美国猫（小公仔） | BO2: 斑点狗（机芯款） | BP2: 斑点狗（小公仔） | BQ2: 总MA | BR2: =生产MA!O19 -> 80000 | BS2: =生产MA!P19 -> 80000 | BT2: =生产MA!Q19 -> 80000 | BU2: =生产MA!R19 -> 80000 | BV2: =生产MA!S19 -> 122000 | BW2: =生产MA!T19 -> 122000 | BX2: =生产MA!U19 -> 80000 | BY2: =生产MA!V19 -> 80000 | BZ2: =SUM(BR2:BY2)/2 -> 362000
A3: 接单日期 | B3: 第三方客户名称 | C3: 国家 | D3: PO号 | E3: 173317 | F3: SKU | G3: ITEM# | H3: 中文名 | I3: PO数量 (pcs) | J3: 内箱装箱数量(pcs) | K3: 外箱装箱数量(pcs) | L3: 总箱数 | M3: ZURU订单走货日期 | N3: ZURU验货 日期 | O3: 第三方验货 | P3: 驗貨結果 | Q3: 船期SO | R3: 箱唛资料 | S3: 是否有外箱贴 | T3: 贴纸资料 | U3: 客供物料 | V3: 日期码 | W3: 备注 | X3: ZURU跟单 | Y3: 单价USD | Z3: 金额USD | AA3: 發票號 | AB3: 系统货号 | AC3: 是否入系统 | AD3: MA 1L | AE3: MA 1L B版 | AF3: MA 3L | AG3: MA 3L B版 | AH3: 134696中东客 客版 | AI3: 客版 | AJ3: MA 5L | AK3: MA 5L B版 | AL3: 134696中东客 客版 | AM3: 中文 | AN3: 客版 | AO3: bunny兔子A | AP3: unicorn独角兽D | AQ3: kitten小猫E | AR3: puppy斑点狗B | AS3: bunny兔子A | AT3: unicorn独角兽D | AU3: kitten小猫E | AV3: puppy斑点狗B | AW3: bunny兔子 | AX3: unicorn独角兽 | AY3: kitten小猫 | AZ3: puppy斑点狗 | BA3: 展示架-1L | BB3: 展示架-3L | BC3: #9283中的两款沙子代替slime | BD3: 有硼 | BE3: 无硼 | BF3: MA | BG3: MA/客版 | BI3: bunny 兔子 A | BK3: unicorn 独角兽 D | BM3: kitten 小猫 E | BO3: puppy 斑点狗 B | BQ3: 公仔合计 | BR3: MA剩余 | BS3: MA剩余 | BT3: MA剩余 | BU3: MA剩余 | BV3: MA剩余 | BW3: MA剩余 | BX3: MA剩余 | BY3: MA剩余
A4: 45289 | B4: ZURU | C4: 库有 | D4: ZPO2312006 | E4: PP订单 | G4: 92108-S001 | H4: 摇篮公子 | I4: 294 | J4: 0 | K4: 4 | L4: =I4/K4 -> 73.5 | M4: 45316 | N4: 45313 | R4: 无 | S4: 无 | T4: 无 | W4: 1.OA Testing Samples (BULK)：数量 8；地址 深圳市罗湖区东门南路106号口岸大楼17B ，Angus 2 CTN 2.QA Testing samples (FSDU)：数量 24；地址 深圳市罗湖区东门南路106号口岸大楼17B ，Angus 1FSDU 3.Signed Sample (6套签+1套用于拆办)：数量 28；地址 深圳市罗湖区东门南路1006号口岸大楼A栋3楼，Jessy Zhang 13421384408 ，7套*4款=28 4.Show room：数量 28；地址 清溪镇光朗村易京街25号《库有样板房) 收件人:李志强电话: 18328402533 ，7套 注：开PP时候帮忙额外准备3套散件邮寄到深圳办公室 5.Sample room samples：数量 292；地址 清溪镇光朗村易京街25号《库有样板房) 收件人:李志强电话: 18328402533 ，73套 注：开PP时候帮忙额外准备3套散件邮寄到深圳办公室 6.散件：数量 12；地址 深圳市罗湖区东门南路1006号口岸大楼A栋16楼，Max Mlai 13632761211 2 CTN 3套散件（除蛋壳外的所有内含物），每套单独装好 合计数量392；PP订单数量合计 500PCS 注:PP PO数量含buffer，请按PP PO数量准备物料 PP 数量包括了:QA 测试办、签样办、板房展厅样板 | AB4: 过渡 | AC4: 过渡 | BG4: MA | BI4: 0 | BJ4: 0 | BK4: 0 | BL4: 0 | BM4: 0 | BN4: 0 | BO4: 0 | BP4: 0 | BQ4: =$BQ$119+BJ4+BL4+BN4+BP4 -> 238025 | BR4: =$BR$2-BR119-BI4 -> 27131.75 | BS4: =$BR$2-BS119-BJ4 -> 27131.75 | BT4: =$BT$2-BT119-BK4 -> 27003.75 | BU4: =$BU$2-BU119-BL4 -> 27003.75 | BV4: =$BV$2-BV119-BM4 -> 42215.75 | BW4: =$BW$2-BW119-BN4 -> 42215.75 | BX4: =$BX$2-BX119-BO4 -> 27623.75 | BY4: =$BY$2-BY119-BP4 -> 27623.75
A5: 45390 | B5: ZURU | C5: 库有 | D5: ZMPO24254 | G5: 92108E-S003 | H5: 小猫 邮包盒装 | I5: 6 | J5: 0 | K5: 2 | L5: =I5/K5 -> 3 | M5: 45399 | N5: 45395 | R5: 无 | S5: 无 | T5: 无 | W5: 大货版本-UPC 193052067111 | AB5: 92108E-S003 | AC5: 已入 | AD5: =I5 -> 6 | AJ5: =AD5 -> 6 | AQ5: =AJ5 -> 6 | BD5: =I5 -> 6 | BF5: =I5 -> 6 | BG5: MA | BM5: =I5 -> 6 | BN5: =BM5 -> 6 | BQ5: =$BQ$119+BJ5+BL5+BN5+BP5 -> 238031 | BR5: =BR4-BI5 -> 27131.75 | BS5: =BS4-BJ5 -> 27131.75 | BT5: =BT4-BK5 -> 27003.75 | BU5: =BU4-BL5 -> 27003.75 | BV5: =BV4-BM5 -> 42209.75 | BW5: =BW4-BN5 -> 42209.75 | BX5: =BX4-BO5 -> 27623.75 | BY5: =BY4-BP5 -> 27623.75
A6: 45516 | B6: ZURU | C6: 库有 | D6: ZMPO24638 | G6: 92108-S001 | H6: 摇篮公子 | I6: 180 | J6: 0 | K6: 4 | L6: =I6/K6 -> 45 | M6: 45531 | N6: 45527 | P6: PAss | R6: 45516 | W6: 大货最新版本/款号平均/麻烦按款号装箱/并在外箱上注明款款号/请用大货标准箱装箱/箱唛请参照邮件附件;备注： 收到样品订单后尽快安排 ，注意样板品质质量要求要高于大货品质要求 ，送货时必须要附带送货单(没有送货单和QC检验合格报告的仓库一律拒绝收货)，请知悉，谢谢！ | AB6: 92108-S001 | AC6: 已入 | AD6: =I6 -> 180 | AJ6: =I6 -> 180 | AO6: =I6/4 -> 45 | AP6: =AO6 -> 45 | AQ6: =AP6 -> 45 | AR6: =AQ6 -> 45 | BD6: =I6 -> 180 | BF6: =I6 -> 180 | BG6: MA | BI6: =I6/4 -> 45 | BJ6: =BI6 -> 45 | BK6: =I6/4 -> 45 | BL6: =BK6 -> 45 | BM6: =I6/4 -> 45 | BN6: =BM6 -> 45 | BO6: =BN6 -> 45 | BP6: =BO6 -> 45 | BQ6: =$BQ$119+BJ6+BL6+BN6+BP6 -> 238205 | BR6: =BR5-BI6 -> 27086.75 | BS6: =BS5-BJ6 -> 27086.75 | BT6: =BT5-BK6 -> 26958.75 | BU6: =BU5-BL6 -> 26958.75 | BV6: =BV5-BM6 -> 42164.75 | BW6: =BW5-BN6 -> 42164.75 | BX6: =BX5-BO6 -> 27578.75 | BY6: =BY5-BP6 -> 27578.75
A7: 45561 | B7: WAL-MART CANADA CORP. | C7: 加拿大 | D7: 4500146212 | F7: 4500146212-10 | G7: 92108-S002-NB | H7: 摇篮公子 | I7: 1218 | J7: 0 | K7: 1 | L7: =I7/K7 -> 1218 | M7: 45621 | N7: 45617 | O7: 11/25抽办 12/18第三方 | P7: PAss | Q7: 1/6出 | R7: 10/31收到 | S7: 无 | T7: UPC条码贴纸9/26 | W7: 日期码格式：ZURU INC(BVI) 标准格式 日期：按实际生产日期 Packaging Info: #92108: MA3L收缩膜+UPC条码贴纸(UPC: 193052064721)+MA5L收藏指南+MA5L资料卡+MA5L胶袋+MA配件袋+MA2L布标 -产品配比: 4 Assortments (bunny: puppy: unicorn: kitten)=1:1:1:1 Remark: 1. #92108 须使用无硼slime; 3. 此单有箱唛； 4. 此单有第三方验货，烦请多备包装物料； 5. 此单#92108/92107/92105/9296/9554/15714 需签办；签办数量：大货样各3套; 6. 此单#92108/92107/92105/9296/9554 需于2024/11/25 抽办做测试；抽办数量：大货各5套; ********************* a. 请确保产品符合1999年版本的加拿大环境保护法(CEPA)和2012年禁止某些有毒物质法规的要求。该产品不含任何在加拿大禁用的化学物质，包括但不限于有毒物 质清单中列出的化学物质，并且在为加拿大沃尔玛生产产品期间没有使用任何禁用化学物质。 Supplier certify that the products comply with the requirements of Canadian Environmental Protection Act, 1999 (CEPA), Prohibition of Certain To xic Substances Regulations, 2012. The products do not contain any chemicals that are banned in Canada, including but not limited to those listed in the Toxic Substances List and no banned chemicals were used during the manufacturing of product for Walmart Canada. 附件列表： (1) Letter of Guarantee for Canada banned chemicals - (1-5CA) b. 请确保产品在均质材料中的汞浓度不超过0.1%（按重量计）。 Supplier certify that the WAL-MART vendor products does not have a mercury concentration of more than 0.1% by weight in homogeneous material. 附件列表： (1) Letter of Guarantee for Mercury COC c. 请确保产品的塑料材料不含以下物质（SOR 2011-17 27B): Supplier certify that the plastic materials do not contain the following substances(SOR 2011-17 27B): (a) carbon tetrachloride or any substance that contains it; (b) methyl alcohol or any substance thay contains >1.0%; (c) petroleum distillates or any substance that contains >10% weight to volume of petroleum distillates; (d) benzene; (e) turpentine or any substance that contains >10% weight to volume of turpentine; (f) boric acid or salts of boric acid; or (g) ethyl ether. 附件列表： (1) Letter of Guarantee for WM CA-Other prohibited substances in plastic(less than 3 years) | X7: Monica Zhou | Y7: 7.4679 | Z7: =Y7*I7 -> 9095.9022 | AA7: 94003-1.13 | AB7: 92108-S002-NB-3L | AC7: 已入 | AF7: =I7 -> 1218 | AJ7: =I7 -> 1218 | AO7: =I7/4 -> 304.5 | AP7: =AO7 -> 304.5 | AQ7: =AP7 -> 304.5 | AR7: =AQ7 -> 304.5 | BE7: =I7 -> 1218 | BF7: =I7 -> 1218 | BG7: MA | BI7: =I7/4 -> 304.5 | BJ7: =BI7 -> 304.5 | BK7: =BJ7 -> 304.5 | BL7: =BK7 -> 304.5 | BM7: =BL7 -> 304.5 | BN7: =BM7 -> 304.5 | BO7: =BN7 -> 304.5 | BP7: =BO7 -> 304.5 | BQ7: =$BQ$119+BJ7+BL7+BN7+BP7 -> 239243 | BR7: =BR6-BI7 -> 26782.25 | BS7: =BS6-BJ7 -> 26782.25 | BT7: =BT6-BK7 -> 26654.25 | BU7: =BU6-BL7 -> 26654.25 | BV7: =BV6-BM7 -> 41860.25 | BW7: =BW6-BN7 -> 41860.25 | BX7: =BX6-BO7 -> 27274.25 | BY7: =BY6-BP7 -> 27274.25
A8: 45602 | B8: DM LLC | C8: 俄罗斯联邦 | D8: 4500150264 | E8: 出Bekasovo 2 | F8: 4500150264-20 | G8: 92108-S001 | H8: 摇篮公子 | I8: 472 | J8: 0 | K8: 4 | L8: =I8/K8 -> 118 | M8: 45652 | N8: 45638 | P8: PAss | Q8: 12/28出 | R8: 11/14收到 | T8: 11/26-进口商贴纸+ EAN条码贴纸 | V8: 外包装 (指: 收缩膜/彩卡/铝箔袋/挂卡/PDQ) /外箱不要打ZURU标准日期码！胶件可以打日期码 | W8: 日期码格式：外包装/外箱不要打ZURU标准日期码 日期： Packaging Info: 注意 ：外包装 (指: 收缩膜/彩卡/铝箔袋/挂卡/PDQ) /外箱不要打ZURU标准日期码！胶件可以打日期码 . 92108 ： 1L MA 收缩膜+ 进口商贴纸+ EAN条码贴纸， MA 说明书or 指南（如有） ： Remark: 标准配比 ； 请按期完货， 会有罚金。 出港口Bekasovo 2. | X8: Ann Zhang | Y8: 7.3277 | Z8: =Y8*I8 -> 3458.6744 | AA8: 94035-1.15 | AB8: 92108-S001 | AC8: 已入 | AD8: =I8 -> 472 | AJ8: =I8 -> 472 | AQ8: =I8/4 -> 118 | AR8: =I8/4 -> 118 | AS8: =I8/4 -> 118 | AT8: =AS8 -> 118 | BD8: =I8 -> 472 | BF8: =I8 -> 472 | BG8: MA | BI8: =I8/4 -> 118 | BJ8: =BI8 -> 118 | BK8: =BJ8 -> 118 | BL8: =BK8 -> 118 | BM8: =BL8 -> 118 | BN8: =BM8 -> 118 | BO8: =BN8 -> 118 | BP8: =BO8 -> 118 | BQ8: =$BQ$119+BJ8+BL8+BN8+BP8 -> 238497 | BR8: =BR7-BI8 -> 26664.25 | BS8: =BS7-BJ8 -> 26664.25 | BT8: =BT7-BK8 -> 26536.25 | BU8: =BU7-BL8 -> 26536.25 | BV8: =BV7-BM8 -> 41742.25 | BW8: =BW7-BN8 -> 41742.25 | BX8: =BX7-BO8 -> 27156.25 | BY8: =BY7-BP8 -> 27156.25
A9: 45601 | B9: DD’S DISCOUNTS | C9: 美国 | D9: 4500150187 | E9: 70054066 | F9: 4500150187-50 | G9: 92108-S001 | H9: 摇篮公子 | I9: 360 | J9: 0 | K9: 4 | L9: =I9/K9 -> 90 | M9: 45653 | N9: 45649 | P9: PAss | Q9: 1/7出 | R9: ROSS指定箱唛格式 | T9: 11/19收到价格贴纸客供 | W9: 日期码格式：ZURU INC(BVI) 标准格式 日期：按实际生产日期 Packaging Info: 1.ZURU MA UPC 现有版本包装 + 客供价格贴纸，出口美国 , 优先使用MA 1L 最新版本 。 Remark: 1.ZURU MA UPC 现有版本包装 + 客供价格贴纸，出口美国 , 优先使用MA 1L 最新版本 。 2.价格贴纸位于包装正面右下角，不挡住重要信息即可，可适当调整 ，价格贴纸由跟单提供。 3.标准日期码格式，产品和包装必须有日期码 。 4.同个产品同个货期不可出现不同的包装。 5. 跟单提供ROSS通用的箱唛模版，工厂按实际45 PO上客户PO/Item号/装箱数 提供箱唛排版来确认。 | X9: Taylor Liao | Y9: 7.3277 | Z9: =Y9*I9 -> 2637.972 | AA9: 88917-1.7 | AB9: 92108-S001 | AC9: 已入 | AD9: =I9 -> 360 | AJ9: =I9 -> 360 | AQ9: =I9/4 -> 90 | AR9: =I9/4 -> 90 | AS9: =I9/4 -> 90 | AT9: =AS9 -> 90 | BD9: =I9 -> 360 | BF9: =I9 -> 360 | BG9: MA | BI9: =I9/4 -> 90 | BJ9: =BI9 -> 90 | BK9: =BJ9 -> 90 | BL9: =BK9 -> 90 | BM9: =BL9 -> 90 | BN9: =BM9 -> 90 | BO9: =BN9 -> 90 | BP9: =BO9 -> 90 | BQ9: =$BQ$119+BJ9+BL9+BN9+BP9 -> 238385 | BR9: =BR8-BI9 -> 26574.25 | BS9: =BS8-BJ9 -> 26574.25 | BT9: =BT8-BK9 -> 26446.25 | BU9: =BU8-BL9 -> 26446.25 | BV9: =BV8-BM9 -> 41652.25 | BW9: =BW8-BN9 -> 41652.25 | BX9: =BX8-BO9 -> 27066.25 | BY9: =BY8-BP9 -> 27066.25
A10: 45614 | B10: BURLINGTON COAT FACTORY | C10: 美国 | D10: 4500151479 | E10: 383017704 | F10: 4500151479 | G10: 92108-S001 | H10: 摇篮公子 | I10: 1800 | J10: 0 | K10: 4 | L10: =I10/K10 -> 450 | M10: 45663 | N10: 45659 | P10: PAss | Q10: 收到SO | R10: 11/18收到 | T10: 12/13-客供价格贴纸+12/11-外箱贴纸 | W10: 日期码格式：ZURU INC(BVI) 标准格式 日期：按实际生产日期 Packaging Info: 1. ZURU MA （首选1L）UPC版本+客供价格贴纸+外箱贴纸，出口美国 有PVC桶的价格贴纸贴在PVC桶上面 Remark: 2. 产品和包装上印刷ZURU 标准日期码； 3. 纸箱中间靠上沿印刷ZURU LOGO，见箱唛资料 4. 外箱UCC 条码贴纸，尺寸: 4*6inch，贴在其中一面正唛右下角，贴纸距离外箱底部3.5cm, 侧边距离3.5cm。外箱贴纸由跟单提供电子版, 工厂自行安排，不可用 封箱胶覆盖贴纸条码，贴纸需要可以扫描且无损坏. 5. 每个产品有一个价格贴纸，价格贴纸覆盖UPC条码上 （若UPC 条码太大，可以露出ITEM#, 覆盖条码即可）贴的时候要是会覆盖包装上重要的信息和图案，需要 告知跟单。 | X10: Jessi Xu | Y10: 7.0129 | Z10: =Y10*I10 -> 12623.22 | AA10: 94086-1.17 | AB10: 92108-S001 | AC10: 已入 | AD10: =I10 -> 1800 | AJ10: =I10 -> 1800 | AQ10: =I10/4 -> 450 | AS10: =I10/4 -> 450 | AT10: =AS10 -> 450 | AV10: =AS10 -> 450 | BD10: =I10 -> 1800 | BF10: =I10 -> 1800 | BG10: MA | BI10: =I10/4 -> 450 | BJ10: =BI10 -> 450 | BK10: =BJ10 -> 450 | BL10: =BK10 -> 450 | BM10: =BL10 -> 450 | BN10: =BM10 -> 450 | BO10: =BN10 -> 450 | BP10: =BO10 -> 450 | BQ10: =$BQ$119+BJ10+BL10+BN10+BP10 -> 239825 | BR10: =BR9-BI10 -> 26124.25 | BS10: =BS9-BJ10 -> 26124.25 | BT10: =BT9-BK10 -> 25996.25 | BU10: =BU9-BL10 -> 25996.25 | BV10: =BV9-BM10 -> 41202.25 | BW10: =BW9-BN10 -> 41202.25 | BX10: =BX9-BO10 -> 26616.25 | BY10: =BY9-BP10 -> 26616.25
