Workbook

Sheet 樣板單
A1: ZURU Rainbocorn 樣板訂單 | V1: 1代珠片公仔#9201 | AE1: 2代珠片公仔#9202 | AN1: #9204 | AW1: #9214 | BE1: #9209 | BV1: #9202 | CI1: #9204 | CO1: #9214（第二代） | CU1: #9209 | CX1: #9215 | DE1: #9212 | DK1: #9213 | DN1: #9207 | DO1: #9208
V2: 收縮膜 | Y2: 說明書 | AE2: 收縮膜 | AH2: 說明書 | AN2: A版本 | AP2: B版本 | BJ2: 3 | BL2: 4 | BN2: 5 | BP2: 5 | BR2: 4 | BT2: 3
A3: 香港接单日期 | B3: ZURU 跟单 | C3: ZURU PO NO# | D3: 第三方客户 PO NO# | E3: 第三方客户名称 | F3: ITEM# | G3: 中文名 | H3: PO数量 (pcs) | I3: 内箱装箱数量(pcs) | J3: 外箱装箱数量(pcs) | K3: 总箱数 | L3: 单价USD | M3: 金额USD | N3: ZURU验货 日期 | O3: 驗貨結果 | P3: 第三方客户公证行验货 | Q3: ZURU订单走货日期 | R3: ZURU确认走货日期 | S3: 箱唛资料(收到日期) | T3: 箱唛资料(确认日期) | U3: 客供贴纸AI(收到日期) | V3: MA 1語收縮膜 | W3: MA 3語收縮膜 | X3: 客版收縮膜 | Y3: MA 1語说明书 A版本 | Z3: MA 1語说明书 B版本 | AA3: MA 3語說明書 A版本 | AB3: MA 3語說明書 B版本 | AC3: 客版說明書 | AD3: 布標 | AE3: MA 1語收縮膜 | AF3: MA 3語收縮膜 | AG3: 客版收縮膜 | AH3: MA 1語说明书 A版本 | AI3: MA 1語说明书 B版本 | AJ3: MA 3語說明書 A版本 | AK3: MA 3語說明書 B版本 | AL3: 客版說明書 | AM3: 布標 | AN3: MA 1語收縮膜 | AO3: MA 1語說明書 | AP3: MA 1語收縮膜 | AQ3: MA 1語說明書 | AR3: MA 2語收縮膜（加拿大版本） | AS3: MA 2語說明書（加拿大版本） | AT3: 落加拿大 棉花泥 | AU3: 9201SQ1 | AV3: 9204UQ1 | AW3: MA 1語收縮膜 A | AX3: MA 1語收縮膜 B | AY3: MA 1語說明書 A | AZ3: MA 1語收縮膜 B | BA3: MA 1語說明書 B | BB3: MA领养卡 | BC3: 9214SQ1 MA PDQ盒 | BD3: 9214UQ1 客办PDQ盒 | BE3: MA 1語收縮膜 | BF3: MA 1語說明書 | BG3: MA 3語收縮膜 | BH3: MA 3語說明書 | BI3: 發票號 | BJ3: 玫紅猴子 Monkey（A） | BK3: 黃色猴子 Monkey（B） | BL3: 粉紅貓 Kitty （A） | BM3: 玫紅貓 Kitty （B） | BN3: 白色兔子 Rabbit （A） | BO3: 玫紅兔子 Rabbit （B） | BP3: 白色獨角獸 Unicorn （A） | BQ3: 玫紅獨角獸 Unicorn （B） | BR3: 紫色小狗 Puppy （A） | BS3: 藍色小狗 Puppy （B） | BT3: 粉色倉鼠 Hamster （A） | BU3: 橙色倉鼠 Hamster （B） | BV3: 羊駝 Llama（白色） | BW3: 羊駝 Llama（紫色） | BX3: 火烈鳥 Flamingo （玫紅色） | BY3: 火烈鳥 Flamingo （彩虹色） | BZ3: 火烈鳥 Flamingo （金色） | CA3: 熊貓 Panda （黑白色） | CB3: 熊貓 Panda （粉紅色） | CC3: 貓頭鷹 OWL （紫色） | CD3: 貓頭鷹 OWL （白色） | CE3: 獨角獸 Unicorn （白色） | CF3: 獨角獸 Unicorn （紫色） | CG3: 獅子 Lion （粉紅色） | CH3: 獅子 Lion （黃色） | CI3: 白色獨角獸 Unicorn | CJ3: 枚红色火烈鸟 Flamingo | CK3: 白色羊驼 Llama | CL3: 粉红色猫 Kitty | CM3: 紫色兔子 Bunny | CN3: 蓝色小狗 Puppy | CO3: 白色猫头鹰 White Owl | CP3: 粉色狮子 Pink Lion | CQ3: 黄色猴子 Yellow Monkey | CR3: 紫色独角兽 Purple Unicorn | CS3: 白色熊猫 White Panda | CT3: 彩色火烈鸟 Colour Flamingo | CU3: 獨角獸 Unicorn | CV3: 白色羊驼 Llama | CW3: 枚红色火烈鸟 Flamingo | CX3: 孔雀 Peacock | CY3: 火烈鸟 Toucan | CZ3: 树懒 Sloth | DA3: 大象 Elephant | DB3: 老虎 Tiger | DC3: 梅花鹿 Giraffe | DD3: 斑马 Zebra | DE3: 兔子 Bunny 含海绵 | DF3: 小狗 Puppy | DG3: 羊驼 Llama | DH3: 小猫 Kitty 含海绵 | DI3: 独角兽 Unicorn | DJ3: 猴子 Monkey | DK3: 小猫 Kitten | DL3: 独角兽 Unicorn | DM3: 大嘴鸟 Toucan | DN3: 2PK超小蛋殼公仔 | DO3: 4PK超小蛋殼公仔
A4: 43243 | B4: Binnie | C4: ZMPO18068 | F4: 9201-S001 | G4: 珠片公仔 | H4: 360 | V4: =H4 -> 360 | Y4: =H4 -> 360 | AD4: MA布標 | BI4: 19573 | BJ4: =H4/12 -> 30 | BK4: =H4/12 -> 30 | BL4: =H4/12 -> 30 | BM4: =H4/12 -> 30 | BN4: =H4/12 -> 30 | BO4: =H4/12 -> 30 | BP4: =H4/12 -> 30 | BQ4: =H4/12 -> 30 | BR4: =H4/12 -> 30 | BS4: =H4/12 -> 30 | BT4: =H4/12 -> 30 | BU4: =H4/12 -> 30
A5: 43265 | B5: Amanda | C5: ZMPO18078 | F5: 9201-S001 | G5: 珠片公仔 | H5: 480 | V5: =H5 -> 480 | Y5: =H5 -> 480 | AD5: MA布標 | BI5: 19654 | BJ5: =H5/12 -> 40 | BK5: =H5/12 -> 40 | BL5: =H5/12 -> 40 | BM5: =H5/12 -> 40 | BN5: =H5/12 -> 40 | BO5: =H5/12 -> 40 | BP5: =H5/12 -> 40 | BQ5: =H5/12 -> 40 | BR5: =H5/12 -> 40 | BS5: =H5/12 -> 40 | BT5: =H5/12 -> 40 | BU5: =H5/12 -> 40
A6: 43265 | B6: Angela | C6: 4500010393 | E6: 簽板 | F6: 9201-S001 | G6: 珠片公仔 | H6: 36 | V6: =H6 -> 36 | Y6: =H6 -> 36 | AD6: MA布標 | BJ6: =H6/12 -> 3 | BK6: =H6/12 -> 3 | BL6: =H6/12 -> 3 | BM6: =H6/12 -> 3 | BN6: =H6/12 -> 3 | BO6: =H6/12 -> 3 | BP6: =H6/12 -> 3 | BQ6: =H6/12 -> 3 | BR6: =H6/12 -> 3 | BS6: =H6/12 -> 3 | BT6: =H6/12 -> 3 | BU6: =H6/12 -> 3
A7: 43265 | B7: Lingly | C7: 4500010570 | E7: GP測試版 | F7: 9201-S001 | G7: 珠片公仔 | H7: 12 | V7: =H7 -> 12 | Y7: =H7 -> 12 | AD7: MA布標 | BJ7: =H7/12 -> 1 | BK7: =H7/12 -> 1 | BL7: =H7/12 -> 1 | BM7: =H7/12 -> 1 | BN7: =H7/12 -> 1 | BO7: =H7/12 -> 1 | BP7: =H7/12 -> 1 | BQ7: =H7/12 -> 1 | BR7: =H7/12 -> 1 | BS7: =H7/12 -> 1 | BT7: =H7/12 -> 1 | BU7: =H7/12 -> 1
A8: 43265 | B8: Holly | C8: 4500009837 | E8: 寄客版 | F8: 9201-S001 | G8: 珠片公仔 | H8: 12 | V8: =H8 -> 12 | Y8: =H8 -> 12 | AD8: MA布標 | BJ8: =H8/12 -> 1 | BK8: =H8/12 -> 1 | BL8: =H8/12 -> 1 | BM8: =H8/12 -> 1 | BN8: =H8/12 -> 1 | BO8: =H8/12 -> 1 | BP8: =H8/12 -> 1 | BQ8: =H8/12 -> 1 | BR8: =H8/12 -> 1 | BS8: =H8/12 -> 1 | BT8: =H8/12 -> 1 | BU8: =H8/12 -> 1
A9: 43270 | B9: Sara | C9: 郵件 | E9: Candide客户样品 | F9: 9201-S001 | G9: 珠片公仔 | H9: 6 | V9: =H9 -> 6 | Y9: =H9 -> 6 | AD9: MA布標 | BJ9: 1 | BL9: 1 | BN9: 1 | BP9: 1 | BR9: 1 | BT9: 1
A10: 43270 | B10: Sara | C10: 4500010598 | E10: WABRO | F10: 9201-S001 | G10: 珠片公仔 | H10: 24 | V10: =H10 -> 24 | Y10: =H10 -> 24 | AD10: MA布標 | BJ10: =H10/12 -> 2 | BK10: =H10/12 -> 2 | BL10: =H10/12 -> 2 | BM10: =H10/12 -> 2 | BN10: =H10/12 -> 2 | BO10: =H10/12 -> 2 | BP10: =H10/12 -> 2 | BQ10: =H10/12 -> 2 | BR10: =H10/12 -> 2 | BS10: =H10/12 -> 2 | BT10: =H10/12 -> 2 | BU10: =H10/12 -> 2
A11: 43277 | B11: Tiffany | C11: 4500010957 | D11: 大貨簽板 | E11: EURO TOYS EUROPE BV | F11: 9201-S001 | G11: 珠片公仔 | H11: 36 | X11: 36 | AC11: 36 | AD11: MA布標 | BJ11: =H11/12 -> 3 | BK11: =H11/12 -> 3 | BL11: =H11/12 -> 3 | BM11: =H11/12 -> 3 | BN11: =H11/12 -> 3 | BO11: =H11/12 -> 3 | BP11: =H11/12 -> 3 | BQ11: =H11/12 -> 3 | BR11: =H11/12 -> 3 | BS11: =H11/12 -> 3 | BT11: =H11/12 -> 3 | BU11: =H11/12 -> 3
A12: 43277 | B12: Lucky | C12: 450012096 | D12: 產前測試 | E12: CENCOSUD CHILE | F12: 9201-S001 | G12: 珠片公仔 | H12: 12 | V12: 12 | Y12: 12 | AD12: MA布標 | BJ12: =H12/12 -> 1 | BK12: =H12/12 -> 1 | BL12: =H12/12 -> 1 | BM12: =H12/12 -> 1 | BN12: =H12/12 -> 1 | BO12: =H12/12 -> 1 | BP12: =H12/12 -> 1 | BQ12: =H12/12 -> 1 | BR12: =H12/12 -> 1 | BS12: =H12/12 -> 1 | BT12: =H12/12 -> 1 | BU12: =H12/12 -> 1
A13: 43265 | B13: Lingly | C13: 4500010570 | E13: 年齡評估樣品 | F13: 9201-S001 | G13: 珠片公仔 | H13: 2 | V13: 12 | Y13: 12 | AD13: MA布標 | BN13: 1 | BO13: 1
A14: 43284 | C14: ZMPO18086 | F14: 9201-S001 | G14: 珠片公仔 | H14: 480 | V14: 480 | Y14: 480 | AD14: MA布標 | BI14: 19655 | BJ14: =H14/12 -> 40 | BK14: =H14/12 -> 40 | BL14: =H14/12 -> 40 | BM14: =H14/12 -> 40 | BN14: =H14/12 -> 40 | BO14: =H14/12 -> 40 | BP14: =H14/12 -> 40 | BQ14: =H14/12 -> 40 | BR14: =H14/12 -> 40 | BS14: =H14/12 -> 40 | BT14: =H14/12 -> 40 | BU14: =H14/12 -> 40
A15: 43286 | C15: 4500010467 | F15: 9201-S001 | G15: 珠片公仔 | H15: 10 | V15: 10 | Y15: 10 | AD15: MA布標 | BL15: 1 | BM15: 1 | BN15: 1 | BO15: 1 | BP15: 1 | BQ15: 1 | BR15: 1 | BS15: 1 | BT15: 1 | BU15: 1
A16: 43287 | C16: 4500010333 | F16: 9201-S001 | G16: 珠片公仔 | H16: 10 | V16: 10 | Y16: 10 | AD16: MA布標 | BL16: 1 | BM16: 1 | BN16: 1 | BO16: 1 | BP16: 1 | BQ16: 1 | BR16: 1 | BS16: 1 | BT16: 1 | BU16: 1
A17: 43302 | C17: 4500012533 | F17: 9201-S001 | G17: 珠片公仔 | H17: 12 | V17: 12 | Y17: 12 | AD17: MA布標 | BJ17: 1 | BK17: 1 | BL17: 1 | BM17: 1 | BN17: 1 | BO17: 1 | BP17: 1 | BQ17: 1 | BR17: 1 | BS17: 1 | BT17: 1 | BU17: 1
A18: 43302 | C18: 4500010568 | F18: 9201-S001 | G18: 珠片公仔 | H18: 4 | V18: 4 | AC18: 4 | AD18: 丹麥布標 | BJ18: 1 | BL18: 1 | BN18: 1 | BP18: 1
A19: 43306 | C19: 4500010570 | E19: GP FRANCE | F19: 9201-S001 | G19: 珠片公仔 | H19: 28 | X19: 28 | Y19: 28 | AD19: 法國布標 | BJ19: 3 | BK19: 2 | BL19: 3 | BM19: 2 | BN19: 3 | BO19: 2 | BP19: 3 | BQ19: 2 | BR19: 2 | BS19: 2 | BT19: 2 | BU19: 2
A20: 43306 | C20: 4500010574 | E20: GP ITALY | F20: 9201-S001 | G20: 珠片公仔 | H20: 25 | X20: 25 | Y20: 25 | AD20: 意大利布標 | BJ20: 2 | BK20: 2 | BL20: 2 | BM20: 2 | BN20: 2 | BO20: 2 | BP20: 3 | BQ20: 2 | BR20: 2 | BS20: 2 | BT20: 2 | BU20: 2
A21: 43313 | C21: 4500009768 | E21: TOY TRIANGLE CO.W.L.L | F21: 9201-S001 | G21: 珠片公仔 | H21: 2 | V21: 2 | Y21: 2 | AD21: MA布標 | BN21: 1 | BP21: 1
A22: 43313 | C22: 4500012277 | E22: Express Gifts Ltd | F22: 9201-S006 | G22: 珠片公仔 | H22: 10 | V22: 10 | Y22: 10 | AD22: MA布標 | BL22: 1 | BM22: 1 | BN22: 1 | BO22: 1 | BP22: 1 | BQ22: 1 | BR22: 1 | BS22: 1 | BT22: 1 | BU22: 1
A23: 43316 | C23: 4500009878 | E23: P.M.I TRADING & ENTERPRISE LTS34 | F23: 9201-S001 | G23: 珠片公仔 | H23: 2 | V23: 2 | Y23: 2 | AD23: MA布標
A24: 43318 | C24: 4500012769 | E24: TOYS kingdom | F24: 9201-S001 | G24: 珠片公仔 | H24: 2 | AD24: MA布標 | BT24: 2
A25: 43321 | C25: 4500012192 | D25: 簽板 | E25: CANDIDE IND E COM LTDA | F25: 9201-S001 | G25: 珠片公仔 | H25: 25 | X25: 25 | AC25: 25 | AD25: 巴西布標 | BJ25: 2 | BK25: 2 | BL25: 2 | BM25: 2 | BN25: 2 | BO25: 2 | BP25: 3 | BQ25: 2 | BR25: 2 | BS25: 2 | BT25: 2 | BU25: 2
A26: 43323 | C26: 4500012835 | D26: 產前測試 | E26: WAL-MART.COM | F26: 9201-S001 | G26: 珠片公仔 | H26: 18 | V26: 18 | Y26: 18 | AD26: MA布標 | BJ26: 3 | BL26: 3 | BN26: 3 | BP26: 3 | BR26: 3 | BT26: 3
A27: 43332 | C27: 4500010580 | D27: 大貨版、簽板 | E27: GP SPAIN | F27: 9201-S001 | G27: 珠片公仔 | H27: 12 | X27: 12 | Y27: 12 | AD27: 西班牙布標 | BJ27: 2 | BK27: 2 | BL27: 2 | BM27: 2 | BN27: 2 | BO27: 2 | BP27: 3 | BQ27: 2 | BR27: 2 | BS27: 2 | BT27: 2 | BU27: 2
A28: 43332 | C28: 4500011417 | D28: 大貨版、簽板 | E28: GP TURKEY | F28: 9201-S001 | G28: 珠片公仔 | H28: 12 | X28: 12 | Y28: 12 | AD28: 土耳其布標 | BJ28: 2 | BK28: 2 | BL28: 2 | BM28: 2 | BN28: 2 | BO28: 2 | BP28: 3 | BQ28: 2 | BR28: 2 | BS28: 2 | BT28: 2 | BU28: 2
A29: 43335 | C29: 4500012306 | D29: MA 3語簽板 | E29: 360 SALES SOLUTIONS INC | F29: 9201-S001 | G29: 珠片公仔 | H29: 24 | W29: 24 | AA29: 24 | AD29: MA布標 | BJ29: 2 | BK29: 2 | BL29: 2 | BM29: 2 | BN29: 2 | BO29: 2 | BP29: 2 | BQ29: 2 | BR29: 2 | BS29: 2 | BT29: 2 | BU29: 2
A30: 43336 | C30: 4500009673 | D30: 大貨樣板 | E30: B&M RETAIL LIMITED | F30: 9201-S003 | G30: 珠片公仔 | H30: 10 | V30: 10 | Y30: 10 | AD30: MA布標 | BL30: 1 | BM30: 1 | BN30: 1 | BO30: 1 | BP30: 1 | BQ30: 1 | BR30: 1 | BS30: 1 | BT30: 1 | BU30: 1
A31: 43336 | C31: 郵件 | D31: Intek 客户样品 | E31: Lucky | F31: 9201-S001 | G31: 珠片公仔 | H31: 24 | V31: 24 | Y31: 24 | AD31: MA布標 | BJ31: 2 | BK31: 2 | BL31: 2 | BM31: 2 | BN31: 2 | BO31: 2 | BP31: 2 | BQ31: 2 | BR31: 2 | BS31: 2 | BT31: 2 | BU31: 2
A32: 43342 | C32: ZMPO18108 | F32: 9201-S001 | G32: 珠片公仔 | H32: 360 | V32: 24 | Y32: 24 | BI32: 19952 | BJ32: =H32/24*3/2 -> 22.5 | BK32: =H32/24*3/2 -> 22.5 | BL32: =H32/24*4/2 -> 30 | BM32: =H32/24*4/2 -> 30 | BN32: =H32/24*5/2 -> 37.5 | BO32: =H32/24*5/2 -> 37.5 | BP32: =H32/24*5/2 -> 37.5 | BQ32: =H32/24*5/2 -> 37.5 | BR32: =H32/24*4/2 -> 30 | BS32: =H32/24*4/2 -> 30 | BT32: =H32/24*3/2 -> 22.5 | BU32: =H32/24*3/2 -> 22.5
A33: 43364 | C33: 4500011712 | D33: 大貨樣板 | E33: TARGET US | F33: 9201-S001 | G33: 珠片公仔 | H33: 9 | V33: 9 | Y33: 9 | AD33: MA布標 | BJ33: 1 | BK33: 1 | BL33: 1 | BM33: 1 | BQ33: 1 | BR33: 1 | BS33: 1 | BT33: 1 | BU33: 1
A34: 43364 | C34: 4500013372 | D34: 大貨樣板 | E34: DISTRIBUIDORA JUGUETRON S.A DE C.V | F34: 9201-S001 | G34: 珠片公仔 | H34: 2 | W34: 2 | AA34: 2 | AD34: MA布標 | BN34: 1 | BP34: 1
A35: 43369 | C35: 4500013085 | D35: 抽版 | F35: 9201-S001 | G35: 粉紅色獨角獸 | H35: 8 | V35: 8 | Y35: 8 | AD35: MA布標 | BQ35: 8
A36: 43382 | C36: 4500013648 | D36: 簽板 | F36: 9201-S001 | G36: 珠片公仔 | H36: 24 | V36: 24 | Y36: 24 | AD36: MA布標 | BJ36: 2 | BK36: 2 | BL36: 2 | BM36: 2 | BN36: 2 | BO36: 2 | BP36: 2 | BQ36: 2 | BR36: 2 | BS36: 2 | BT36: 2 | BU36: 2
A37: 43384 | C37: 4500013155 | D37: 大貨版 | F37: 9201-S001 | G37: 珠片公仔 | H37: 12 | V37: 12 | Y37: 12 | AD37: MA布標 | BJ37: 1 | BK37: 1 | BL37: 1 | BM37: 1 | BN37: 1 | BO37: 1 | BP37: 1 | BQ37: 1 | BR37: 1 | BS37: 1 | BT37: 1 | BU37: 1
A38: 43392 | C38: 4500013641 | D38: 大貨版 | F38: 9201-S001 | G38: 珠片公仔 | H38: 12 | X38: 12 | AC38: 12 | AD38: GP法國 | BJ38: 1 | BK38: 1 | BL38: 1 | BM38: 1 | BN38: 1 | BO38: 1 | BP38: 1 | BQ38: 1 | BR38: 1 | BS38: 1 | BT38: 1 | BU38: 1
A39: 43392 | C39: ZMPO18123 | D39: 樣品訂單 | F39: 9201-S001 | G39: 珠片公仔 | H39: 204 | V39: 204 | Y39: 204 | AD39: MA布標 | BJ39: 17 | BK39: 17 | BL39: 17 | BM39: 17 | BN39: 17 | BO39: 17 | BP39: 17 | BQ39: 17 | BR39: 17 | BS39: 17 | BT39: 17 | BU39: 17
A40: 43392 | C40: ZMPO18131 | D40: 樣品訂單 | F40: 9201-S001 | G40: 珠片公仔 | H40: 480 | V40: 480 | Y40: 480 | AD40: MA布標 | BJ40: 40 | BK40: 40 | BL40: 40 | BM40: 40 | BN40: 40 | BO40: 40 | BP40: 40 | BQ40: 40 | BR40: 40 | BS40: 40 | BT40: 40 | BU40: 40
...

Sheet 92119
A1: ZURU Rainbocorn 冰雪蛋系列排期#92119
A2: 45660 | I2: （黃色表示更改或增加） | L2: （蓝色表示已完货） | P2: （綠色表示調整貨期） | AH2: 收缩膜 | AM2: 收藏指南 | AP2: 口水胶 | AU2: 吊卡 | AW2: FROZENMANIA
A3: 接单日期 | B3: 第三方客户名称 | C3: 国家 | D3: PO号 | E3: 客PO号 | F3: SKU | G3: 系统货号 | H3: ITEM# | I3: 中文名 | J3: PO数量 (pcs) | K3: 内箱装箱数量(pcs) | L3: 外箱装箱数量(pcs) | M3: 总箱数 | N3: 客PO期 | O3: 验货期 | P3: 第三方验货期 | Q3: 驗貨結果 | R3: 船期SO | S3: 箱唛资料 | T3: 外箱贴纸 | U3: 客贴纸资料 | V3: 客供物料 | W3: 日期码 | X3: 备注 | Y3: ZURU 跟单 | Z3: 单价USD | AA3: 金额USD | AB3: 送货情况 | AC3: 欠数 | AD3: 贴纸情况 | AE3: 下单情况 | AF3: 發票號 | AG3: 是否入系统 | AH3: MA 1語收縮膜 A版本 | AI3: MA 1語收縮膜 B版本 | AJ3: MA 3語收縮膜 A版本 | AK3: MA 3語收縮膜 B版本 | AL3: 客版收縮膜 | AM3: MA 5語收藏指南 | AN3: MA 5語收藏指南-B版本 | AO3: 客版收藏指南 | AP3: 有硼 | AQ3: 有硼-B版本 | AR3: 无硼 | AS3: 无硼-B版本 | AT3: 客办蓬松泥 | AU3: 客版吊卡 | AV3: 布標 | AW3: 北极熊 A Polar Bear（10） | AX3: 企鹅 B Penguin（10） | AY3: 海豹 H Seal（8） | AZ3: 雪人 Snow man（2） | BA3: 海象 D Walrus（10） | BB3: 猛犸象 E Mammoth（10） | BC3: 猫头鹰 G Owl（10） | BD3: 总数 | BE3: 相差 | BG3: 包装更替 | BH3: 客户回复
A4: 46079 | B4: TJX CANADA | C4: 加拿大 | D4: 4500194379 | E4: 40320901 | F4: 4500194379-40 | H4: 92119-S001-NB | I4: S001-NB-RAINBOCORNS-EG GZANIA-SERIES 1-FROZEN MANIA-SHRINK WRAP,12PCS/CTN | J4: 720 | L4: 12 | M4: 46135 | O4: 46129 | X4: 日期码格式：标准格式 日期：按实际生产日期 92125 MA 多语EAN版本+UPC贴纸193052083951 77731 英法客版铜版纸，upc 193052085115, MA 2L 收缩膜 多语多明书 25251 英法客版包装 UPC 845218016418 翻单4500166055 25252 客版英法彩盒和说明书。UPC号码845218016425 25253 英法客版 UPC 845218016432，彩盒翻单4500158924，说明书翻单4500166055 7153 英法客版包装 翻单4500131680， 7149 UPC193052033499 7150UPC 193052033406 MA 多语说明书 92119 无硼版本 MA 3L B 版收缩膜 +UPC 贴纸 UPC 193052078391， B 版5L 收藏指南 9258 无硼版本 MA 3L B 版收缩膜 UPC 5L多语言收藏指南193052037640 9296 无硼版本 MA 3L 收缩膜+ 多语说明书 ， UPC 193052057129 9298 无硼版本 MA C 版3L 收缩膜 +UPC 贴纸 UPC 193052057426， B 版5L 收藏指南 9548 无硼版本 MA D 版本 5L 包装+D 版本 5L 收藏指南 +UPC 贴纸 UPC 193052064196 出加拿大 有客供价格贴 每行对应不同的客户PO，唛头要一一对应， 放唛头时跟单会提供清单 Zuru验货.日期跟踪码：产品外包装及产品本身都必须有日期跟踪码，ZURU标准格式 日期码 | Y4: Katrina Xie | Z4: 3.5671 | AA4: =Z4*J4 -> 2568.312 | AK4: =J4 -> 720 | AN4: =J4 -> 720 | AQ4: =J4 -> 720 | AW4: =J4/60*10 -> 120 | AX4: =J4/60*10 -> 120
D5: ZPO2411007 | G5: 过渡 | H5: 92119-S001 | I5: 冰雪蛋 | J5: 550 | K5: 0 | L5: 12 | M5: =J5/L5 -> 45.833333 | N5: 45667 | O5: 45667 | AG5: 过渡 | AH5: =J5 -> 550 | AV5: MA布标 | AW5: =J5/60*10 -> 91.666667 | AX5: =J5/60*10 -> 91.666667 | AY5: =J5/60*8 -> 73.333333 | AZ5: =J5/60*2 -> 18.333333 | BA5: =J5/60*10 -> 91.666667 | BB5: =J5/60*10 -> 91.666667 | BC5: =J5/60*10 -> 91.666667 | BD5: =SUM(AW5:BC5) -> 550 | BE5: =J5-BD5 -> 0
A6: 46079 | B6: TJX CANADA | C6: 加拿大 | D6: 4500194379 | F6: 4500194379-150 | H6: 92119-S001-NB | I6: S001-NB-RAINBOCORNS-EG GZANIA-SERIES 1-FROZEN MANIA-SHRINK WRAP,12PCS/CTN | J6: 180 | L6: 12 | M6: 46135 | O6: 46129 | X6: 日期码格式：标准格式 日期：按实际生产日期 92125 MA 多语EAN版本+UPC贴纸193052083951 77731 英法客版铜版纸，upc 193052085115, MA 2L 收缩膜 多语多明书 25251 英法客版包装 UPC 845218016418 翻单4500166055 25252 客版英法彩盒和说明书。UPC号码845218016425 25253 英法客版 UPC 845218016432，彩盒翻单4500158924，说明书翻单4500166055 7153 英法客版包装 翻单4500131680， 7149 UPC193052033499 7150UPC 193052033406 MA 多语说明书 92119 无硼版本 MA 3L B 版收缩膜 +UPC 贴纸 UPC 193052078391， B 版5L 收藏指南 9258 无硼版本 MA 3L B 版收缩膜 UPC 5L多语言收藏指南193052037640 9296 无硼版本 MA 3L 收缩膜+ 多语说明书 ， UPC 193052057129 9298 无硼版本 MA C 版3L 收缩膜 +UPC 贴纸 UPC 193052057426， B 版5L 收藏指南 9548 无硼版本 MA D 版本 5L 包装+D 版本 5L 收藏指南 +UPC 贴纸 UPC 193052064196 出加拿大 有客供价格贴 每行对应不同的客户PO，唛头要一一对应， 放唛头时跟单会提供清单 Zuru验货.日期跟踪码：产品外包装及产品本身都必须有日期跟踪码，ZURU标准格式 日期码 | Y6: Katrina Xie | Z6: 3.5671 | AA6: =Z6*J6 -> 642.078
A7: 45657 | B7: THE WAREHOUSE LIMITED | C7: 新西兰 | D7: 4500155047 | F7: 4500155047-10 | G7: 92119-S001 | H7: 92119-S001 | I7: 冰雪蛋 | J7: 120 | K7: 0 | L7: 12 | M7: =J7/L7 -> 10 | N7: 45674 | O7: 45670 | Q7: PASS | R7: 1/19出 | S7: 1/13收到 | U7: 无 | X7: 日期码格式：ZURU INC(BVI) 标准格式 日期：按实际生产日期 Packaging Info: MA UPC 英语包装（优先1L英语版本，或者3L/5L含英语都可） 此客人不接受易掉落或者剥落或者可直接触碰的闪粉，可降解也不行，但可以接受符合欧洲微塑料标准的珠光粉或者闪片。 Remark: 7 Assortment, Polar bear: Penguin: Walrus: Mammoth: Owl: Seal: Snow man=10:10:10:10:10:8:2. Snow man is the rare item. | Y7: Abby Liang | Z7: 3.4 | AA7: =Z7*J7 -> 408 | AE7: 车间生产 | AF7: 94791-4.18 | AG7: 已入 | AH7: =J7 -> 120 | AM7: =J7 -> 120 | AP7: =J7 -> 120 | AV7: MA布标 | AW7: =J7/60*10 -> 20 | AX7: =J7/60*10 -> 20 | AY7: =J7/60*8 -> 16 | AZ7: =J7/60*2 -> 4 | BA7: =J7/60*10 -> 20 | BB7: =J7/60*10 -> 20 | BC7: =J7/60*10 -> 20 | BD7: =SUM(AW7:BC7) -> 120 | BE7: =J7-BD7 -> 0
A8: 45636 | B8: THE WAREHOUSE LIMITED | C8: 新西兰 | D8: 4500153598 | E8: 28797909 | F8: 4500153598-20 | G8: 92119-S001 | H8: 92119-S001 | I8: 冰雪蛋 | J8: 444 | K8: 0 | L8: 12 | M8: =J8/L8 -> 37 | N8: 45726 | O8: 45722 | Q8: PASS | R8: 3/20出 | S8: 12/10收到 | U8: 无 | X8: 日期码格式：ZURU INC(BVI) 标准格式 日期：按实际生产日期 Packaging Info: MA UPC 英语包装（优先1L英语版本，或者3L/5L含英语都可） 此客人不接受易掉落或者剥落或者可直接触碰的闪粉，可降解也不行，但可以接受符合欧洲微塑料标准的珠光粉或者闪片。 Remark: 92119: 7 Assortment, Polar bear: Penguin: Walrus: Mammoth: Owl: Seal: Snow man=10:10:10:10:10:8:2. Snow man is the rare item. | Y8: Abby Liang | Z8: 3.4 | AA8: =Z8*J8 -> 1509.6 | AD8: 无 | AE8: 车间生产 | AF8: 94793-4.18 | AG8: 已入 | AH8: =J8 -> 444 | AM8: =J8 -> 444 | AR8: =J8 -> 444 | AV8: MA布标 | AW8: =J8/60*10 -> 74 | AX8: =J8/60*10 -> 74 | AY8: =J8/60*8 -> 59.2 | AZ8: =J8/60*2 -> 14.8 | BA8: =J8/60*10 -> 74 | BB8: =J8/60*10 -> 74 | BC8: =J8/60*10 -> 74 | BD8: =SUM(AW8:BC8) -> 444 | BE8: =J8-BD8 -> 0
A9: 45636 | B9: THE WAREHOUSE LIMITED | C9: 新西兰 | D9: 4500153593 | E9: 28797907 | F9: 4500153593-20 | G9: 92119-S001 | H9: 92119-S001 | I9: 冰雪蛋 | J9: 1356 | K9: 0 | L9: 12 | M9: =J9/L9 -> 113 | N9: 45726 | O9: 45722 | Q9: PASS | R9: 3/20出 | S9: 12/10收到 | U9: 无 | X9: 日期码格式：ZURU INC(BVI) 标准格式 日期：按实际生产日期 Packaging Info: MA UPC 英语包装（优先1L英语版本，或者3L/5L含英语都可） 此客人不接受易掉落或者剥落或者可直接触碰的闪粉，可降解也不行，但可以接受符合欧洲微塑料标准的珠光粉或者闪片。 Remark: 92119: 7 Assortment, Polar bear: Penguin: Walrus: Mammoth: Owl: Seal: Snow man=10:10:10:10:10:8:2. Snow man is the rare item. | Y9: Abby Liang | Z9: 3.4 | AA9: =Z9*J9 -> 4610.4 | AD9: 无 | AE9: 车间生产 | AF9: 94792-4.18 | AG9: 已入 | AH9: =J9 -> 1356 | AM9: =J9 -> 1356 | AR9: =J9 -> 1356 | AV9: MA布标 | AW9: =J9/60*10 -> 226 | AX9: =J9/60*10 -> 226 | AY9: =J9/60*8 -> 180.8 | AZ9: =J9/60*2 -> 45.2 | BA9: =J9/60*10 -> 226 | BB9: =J9/60*10 -> 226 | BC9: =J9/60*10 -> 226 | BD9: =SUM(AW9:BC9) -> 1356 | BE9: =J9-BD9 -> 0
A10: 45663 | B10: DOLGENCORP, LLC | C10: 美国 | D10: 4500155298 | E10: PO#2475S8 | F10: 4500155298-10 | G10: 92119-S004-PKC | H10: 92119-S004-PKC | I10: 冰雪蛋 | J10: 76464 | K10: 0 | L10: 2 | M10: =J10/L10 -> 38232 | N10: 45733 | O10: 45729 | P10: 3/18第三方-正常出货 | Q10: PASS | S10: 1/9收到 | U10: 2/12-可移动价格贴纸 | W10: 2/12-客办收缩膜文档 + 日期码：DOLGEN41199801E25 | X10: 日期码格式：DOLLAR GENERAL 格式日期码 日期： Packaging Info: 客版1L包装 +可移动价格贴纸$15,(客AW单稍后提供) + 如果有说明书或者收藏指南优先使用ZURU MA 1L的，如没有1L请邮件告知。 Remark: 1.包装： 客版1L收缩膜 +可移动价格贴纸$18（客AW单稍后提供) + 如果有说明书或者收藏指南优先使用ZURU MA 1L的，如没有1L请邮件告知。 客户要求： "产品和包装不能含有PFAS 物质以及1,4 dioxane" 客户指定TUV来厂抽样+验货，会做实际测试。请确保产品符合美国测试标准，可以pass测试。 外箱必须是双坑的。 2.日期码：产品和包装上必须有客版格式日期码。 （1）产品上需打客版日期码 内容： DOLGEN41199801D25 D代表ETD 4月。打在蛋壳底部。 （2）包装日期码41199801D25（已印在客版包装UPC条码旁竖排文字了，无需额外做日期码在包装上）。 （3）UPC#193052078391 3. 产品包装正面右上角需要贴客版可移动价贴$18，留意蓝色圆点的色号(Blue #279C)，材质必须是可移动的，贴上不能翘起，撕下不能留胶 。 4.客户指定TUV做100%大货验货+抽样： 3月18日早上进行客人指定TUV的100%大货验货+CT抽测试样（成品12pcs带包装产品+工厂提前准备好的5套光身板，即包装里面所有的随机toys + 足量干漆或油墨涂 在同底材A4大小）。请在3月17日前完成ZURU QC验货，并当天13点前提供验货报告+大货图片给跟单。 5.样板需求，需2月17左右寄出每款每色各6套样板给ZURU跟单转寄客人。 6.箱唛：此客人要求严格，外箱不接受水贴纸，材积以及重量必须按照以下要求，否则不符会导致验货fail从而影响货期而产生罚款。 大货外箱材积绝对不可大于下述数据，材积只接受3%的变小；重量正负不得超过以下列出数据的5%，接受外箱以印章方式印上实际毛重。 大货外箱材积必须不能大于0.75CubeFeet（0.0213CBM);外箱毛重4.6LBS（2.11KGS）。 如有尺寸变小，请提前通知Cora/Minny。 重要提醒：外箱材质必须是双层瓦楞纸，不接受单层，会导致第三方验货fail以及返工和罚款。 7.此客人不接受任何理由的延期，会有高额罚金产生. 8.如散货入仓需在货车上加防护网. 9.出货配比：ZURU MA配比 。 #92119-S004-PKC-RAINBOCORNS-EGGZANIA-SERIES 1-FROZEN MANIA-SHRINK WRAP,2pcs/CTN双坑外箱 7 Assortment, Polar bear: Penguin: Walrus: Mammoth: Owl: Seal: Snow man=10:10:10:10:10:8:2. Snow man is the rare item. | Y10: Hailey Yu | Z10: 3.6812 | AA10: =Z10*J10 -> 281479.28 | AB10: =50000+5320+7280+6914+6880+9008+3440 -> 88842 | AC10: =AB10-J10 -> 12378 | AD10: OK | AE10: 系统出单 | AF10: ZB00118-4.9 ZB00119-4.10 | AG10: 已入 | AL10: =J10 -> 76464 | AM10: =J10 -> 76464 | AP10: =J10 -> 76464 | AV10: MA布标 | AW10: =J10/60*10 -> 12744 | AX10: =J10/60*10 -> 12744 | AY10: =J10/60*8 -> 10195.2 | AZ10: =J10/60*2 -> 2548.8 | BA10: =J10/60*10 -> 12744 | BB10: =J10/60*10 -> 12744 | BC10: =J10/60*10 -> 12744 | BD10: =SUM(AW10:BC10) -> 76464 | BE10: =J10-BD10 -> 0
A11: 45741 | B11: DOLGENCORP, LLC | C11: 美国 | D11: 4500155298 | E11: PO#2475S8 | F11: 4500155298-20 | G11: 92119-S004-PKC | H11: 92119-S004-PKC | I11: 冰雪蛋 | J11: 12378 | K11: 0 | L11: 2 | M11: =J11/L11 -> 6189 | N11: 45733 | O11: 45729 | P11: 3/18第三方-正常出货 | Q11: PASS | S11: 1/9收到 | U11: 2/12-可移动价格贴纸 | W11: 2/12-客办收缩膜文档 + 日期码：DOLGEN41199801E25 | X11: 日期码格式：DOLLAR GENERAL 格式日期码 日期： Packaging Info: 客版1L包装 +可移动价格贴纸$15,(客AW单稍后提供) + 如果有说明书或者收藏指南优先使用ZURU MA 1L的，如没有1L请邮件告知。 Remark: 1.包装： 客版1L收缩膜 +可移动价格贴纸$18（客AW单稍后提供) + 如果有说明书或者收藏指南优先使用ZURU MA 1L的，如没有1L请邮件告知。 客户要求： "产品和包装不能含有PFAS 物质以及1,4 dioxane" 客户指定TUV来厂抽样+验货，会做实际测试。请确保产品符合美国测试标准，可以pass测试。 外箱必须是双坑的。 2.日期码：产品和包装上必须有客版格式日期码。 （1）产品上需打客版日期码 内容： DOLGEN41199801D25 D代表ETD 4月。打在蛋壳底部。 （2）包装日期码41199801D25（已印在客版包装UPC条码旁竖排文字了，无需额外做日期码在包装上）。 （3）UPC#193052078391 3. 产品包装正面右上角需要贴客版可移动价贴$18，留意蓝色圆点的色号(Blue #279C)，材质必须是可移动的，贴上不能翘起，撕下不能留胶 。 4.客户指定TUV做100%大货验货+抽样： 3月18日早上进行客人指定TUV的100%大货验货+CT抽测试样（成品12pcs带包装产品+工厂提前准备好的5套光身板，即包装里面所有的随机toys + 足量干漆或油墨涂 在同底材A4大小）。请在3月17日前完成ZURU QC验货，并当天13点前提供验货报告+大货图片给跟单。 5.样板需求，需2月17左右寄出每款每色各6套样板给ZURU跟单转寄客人。 6.箱唛：此客人要求严格，外箱不接受水贴纸，材积以及重量必须按照以下要求，否则不符会导致验货fail从而影响货期而产生罚款。 大货外箱材积绝对不可大于下述数据，材积只接受3%的变小；重量正负不得超过以下列出数据的5%，接受外箱以印章方式印上实际毛重。 大货外箱材积必须不能大于0.75CubeFeet（0.0213CBM);外箱毛重4.6LBS（2.11KGS）。 如有尺寸变小，请提前通知Cora/Minny。 重要提醒：外箱材质必须是双层瓦楞纸，不接受单层，会导致第三方验货fail以及返工和罚款。 7.此客人不接受任何理由的延期，会有高额罚金产生. 8.如散货入仓需在货车上加防护网. 9.出货配比：ZURU MA配比 。 #92119-S004-PKC-RAINBOCORNS-EGGZANIA-SERIES 1-FROZEN MANIA-SHRINK WRAP,2pcs/CTN双坑外箱 7 Assortment, Polar bear: Penguin: Walrus: Mammoth: Owl: Seal: Snow man=10:10:10:10:10:8:2. Snow man is the rare item. | Y11: Hailey Yu | Z11: 3.5512 | AA11: =Z11*J11 -> 43956.754 | AE11: 分单 | AG11: 已入 | AL11: =J11 -> 12378 | AM11: =J11 -> 12378 | AP11: =J11 -> 12378 | AV11: MA布标 | AW11: =J11/60*10 -> 2063 | AX11: =J11/60*10 -> 2063 | AY11: =J11/60*8 -> 1650.4 | AZ11: =J11/60*2 -> 412.6 | BA11: =J11/60*10 -> 2063 | BB11: =J11/60*10 -> 2063 | BC11: =J11/60*10 -> 2063 | BD11: =SUM(AW11:BC11) -> 12378 | BE11: =J11-BD11 -> 0
A12: 45722 | D12: ZMPO250187 | F12: 92119-S001 | G12: 92119-S001 | H12: 92119-S001 | I12: 冰雪蛋 | J12: 216 | K12: 0 | L12: 12 | M12: =J12/L12 -> 18 | N12: 45736 | O12: 45733 | Q12: PASS | S12: 周转箱 | U12: 无 | X12: Remark:大货最新版本/7款平均/请按款号装箱，并在外箱上注明款号/大货标准箱装箱/箱唛请参照邮件附件;备注：收到样品订单后尽快安排 ，注意样板品质质量要求要高于大货品质要求 ，送货时必须要附带送货单(没有送货单和QC检验合格报告的仓库一律拒绝收货)，请知悉，谢谢！ | Y12: Angus | AB12: 216 | AC12: =AB12-J12 -> 0 | AE12: 系统出单 | AG12: 已入 | AH12: =J12 -> 216 | AM12: =J12 -> 216 | AP12: =J12 -> 216 | AV12: MA布标 | AW12: =J12/7 -> 30.857143 | AX12: =J12/7 -> 30.857143 | AY12: =J12/7 -> 30.857143 | AZ12: =J12/7 -> 30.857143 | BA12: =J12/7 -> 30.857143 | BB12: =J12/7 -> 30.857143 | BC12: =J12/7 -> 30.857143 | BD12: =SUM(AW12:BC12) -> 216 | BE12: 0
A13: 45716 | B13: PRO & PACIFIC CO.,LTD | C13: 台湾 | D13: 4500158781 | E13: ZU25021702 | F13: 4500158781-10 | G13: 92119-S001 | H13: 92119-S001 | I13: 冰雪蛋 | J13: 2004 | K13: 0 | L13: 12 | M13: =J13/L13 -> 167 | N13: 45741 | O13: 45737 | Q13: PASS | R13: 4/24出 | S13: 3/3收到 | U13: 3/3-进口商贴纸 | X13: 日期码格式：ZURU INC(BVI) 标准格式 日期：按实际生产日期 Packaging Info: MA 1L UPC包装+1张进口商贴纸,贴纸资料待提供 Remark: 92119-7 Assortment, Polar bear: Penguin: Walrus: Mammoth: Owl: Seal: Snow man=10:10:10:10:10:8:2. Snow man is the rare item. | Y13: Emma Wu | Z13: 3.4 | AA13: =Z13*J13 -> 6813.6 | AB13: =1968+36 -> 2004 | AC13: =AB13-J13 -> 0 | AD13: OK | AE13: 系统出单 | AF13: 94827-4.22 | AG13: 已入 | AH13: =J13 -> 2004 | AM13: =J13 -> 2004 | AP13: =J13 -> 2004 | AV13: MA布标 | AW13: =J13/60*10 -> 334 | AX13: =J13/60*10 -> 334 | AY13: =J13/60*8 -> 267.2 | AZ13: =J13/60*2 -> 66.8 | BA13: =J13/60*10 -> 334 | BB13: =J13/60*10 -> 334 | BC13: =J13/60*10 -> 334 | BD13: =SUM(AW13:BC13) -> 2004 | BE13: =J13-BD13 -> 0
A14: 45707 | B14: ZURU Germany GMBH | C14: 德国 | D14: 4500157858 | E14: 5200006149 | F14: 4500157858-100 | G14: 92119-S006-NB-3L | H14: 92119-S006-NB-MTS | I14: 冰雪蛋 | J14: 600 | K14: 0 | L14: 4 | M14: =J14/L14 -> 150 | N14: 45747 | O14: 45743 | Q14: PASS | R14: 4/3出 | S14: 2/19收到 | U14: 无 | X14: 日期码格式：ZURU INC(BVI) 标准格式 日期：按实际生产日期 Packaging Info: 92119：MA最新版3L EAN收缩膜+MA 1L+23L warning收藏指南+MA 2L布标+MA 5L复合袋 Remark: "1.德国内销单，需要通过ZURU 验货结果后才能出货 (工厂需要主动提前同ZURU QC预约验货避免延期出货造成不必要麻烦)； 2. 若有特定款有特殊外箱条码要求时,需要明确列出产品款对应的具体外箱条码号码/条码类型 (若无,可以忽略此需求) 3.所有出口欧洲的产品, 法规规定禁止在包装和共公众用的印刷品中使用矿物油中含有的物质, 包装印刷油墨中含有的MOAH/MOSH的质量浓度不能超过1%, 否则出货 到法国被抽检出现问题, 供应商需要对此负责; 4. date code: 外箱日期码要晚于或等于产品日期码，不能早于产品的日期码 5. 所有电子产品身上需要加字唛，为ZURU FRANCE 地址 (如无电子产品，或者产品布标有此地址，可忽略此信息) ZURU France 1/3, Rue d'Argenteuil 95210 SAINT-GRATIEN, FRANCE 6. 装柜时需要按照款式号码从小到大一款款依次装,避免终端仓库卸货混乱.若一个柜子涉及到几个不同国家内销单,装柜时需要一个国家装完后再装另一个国家的 产品,依次装柜,避免终端仓库因不同国家不同库位位置卸货混乱. (此点需要同工厂装柜人员强调)" | Y14: SD82 | Z14: 3.6 | AA14: =Z14*J14 -> 2160 | AB14: =596+4 -> 600 | AC14: =AB14-J14 -> 0 | AD14: 无 | AE14: 系统出单 | AF14: 94875-4.29 | AG14: 已入 | AJ14: =J14 -> 600 | AM14: =J14 -> 600 | AR14: =J14 -> 600 | AV14: MA布标 | AW14: =J14/60*10 -> 100 | AX14: =J14/60*10 -> 100 | AY14: =J14/60*8 -> 80 | AZ14: =J14/60*2 -> 20 | BA14: =J14/60*10 -> 100 | BB14: =J14/60*10 -> 100 | BC14: =J14/60*10 -> 100 | BD14: =SUM(AW14:BC14) -> 600 | BE14: =J14-BD14 -> 0
A15: 45716 | B15: ZURU Germany GMBH | C15: 德国 | D15: 4500158832 | E15: 5200006286 | F15: 4500158832-10 | G15: 92119-S006-NB-3L | H15: 92119-S006-NB-MTS | I15: 冰雪蛋 | J15: 600 | K15: 0 | L15: 4 | M15: =J15/L15 -> 150 | N15: 45754 | O15: 45750 | Q15: PASS | R15: 4/11出 | S15: 2/28收到 | U15: 无 | X15: 日期码格式：ZURU INC(BVI) 标准格式 日期：按实际生产日期 Packaging Info: 92119:MA最新版3L EAN收缩膜+MA 1L+23L warning收藏指南+MA 2L布标+MA 5L复合袋 Remark: "1.德国内销单，需要通过ZURU 验货结果后才能出货 (工厂需要主动提前同ZURU QC预约验货避免延期出货造成不必要麻烦)； 2. 若有特定款有特殊外箱条码要求时,需要明确列出产品款对应的具体外箱条码号码/条码类型 (若无,可以忽略此需求) 3.所有出口欧洲的产品, 法规规定禁止在包装和共公众用的印刷品中使用矿物油中含有的物质, 包装印刷油墨中含有的MOAH/MOSH的质量浓度不能超过1%, 否则出货 到法国被抽检出现问题, 供应商需要对此负责; 4. date code: 外箱/产品/包装 保持一致，完货后提供date code 信息以便我们保存记录做批次管理 35. 装柜时需要按照款式号码从小到大一款款依次装,避免终端仓库卸货混乱.若一个柜子涉及到几个不同国家内销单,装柜时需要一个国家装完后再装另一个国家的 产品,依次装柜,避免终端仓库因不同国家不同库位位置卸货混乱. (此点需要同工厂装柜人员强调)" | Y15: SD82 | Z15: 3.6 | AA15: =Z15*J15 -> 2160 | AB15: 600 | AC15: =AB15-J15 -> 0 | AD15: 无 | AE15: 系统出单 | AF15: 94876-4.29 | AG15: 已入 | AJ15: =J15 -> 600 | AM15: =J15 -> 600 | AR15: =J15 -> 600 | AV15: MA布标 | AW15: =J15/60*10 -> 100 | AX15: =J15/60*10 -> 100 | AY15: =J15/60*8 -> 80 | AZ15: =J15/60*2 -> 20 | BA15: =J15/60*10 -> 100 | BB15: =J15/60*10 -> 100 | BC15: =J15/60*10 -> 100 | BD15: =SUM(AW15:BC15) -> 600 | BE15: =J15-BD15 -> 0
A16: 45723 | B16: ZURU LLC | C16: 美国 | D16: 4500159464 | E16: 5200006340 | F16: 4500159464-130 | G16: 92119E-S002 | H16: 92119E-S002-MTS | I16: 猛犸象 | J16: 492 | K16: 0 | L16: 12 | M16: =J16/L16 -> 41 | N16: 45758 | O16: 45754 | Q16: PASS | R16: 4/16出 | S16: 3/10收到 | U16: UPC贴纸翻4500158580 | X16: 日期码格式：ZURU INC(BVI) 标准格式 日期：按实际生产日期 Packaging Info: #92119 MA UPC版 (1L或3L都可)+UPC贴纸, 贴纸资料翻EU单4500158580 (但不需要印刷IT环保标贴纸)A:193052083821 B:193052083838 D:193052083845 E:19305208 3852 G:193052083869 H:193052083876 Remark: 1.Amazon domestic 订单。出口美国。外箱最长边不能超过25" （超过了，case pack只能为1），不符合要求的大货，一律不接受。 2.无第三方验货/测试要求。 3.日期码使用ZURU标准版本。 | Y16: Kelly Shen/Mia Pan/P | Z16: 3.4 | AA16: =Z16*J16 -> 1672.8 | AB16: =24+468 -> 492 | AC16: =AB16-J16 -> 0 | AD16: OK | AE16: 系统出单 | AF16: ZB00145-4.16 | AG16: 已入 | AH16: =J16 -> 492 | AM16: =J16 -> 492 | AP16: =J16 -> 492 | AV16: MA布标 | BB16: =J16 -> 492 | BD16: =SUM(AW16:BC16) -> 492 | BE16: =J16-BD16 -> 0
A17: 45723 | B17: ZURU LLC | C17: 美国 | D17: 4500159464 | E17: 5200006340 | F17: 4500159464-140 | G17: 92119G-S002 | H17: 92119G-S002-MTS | I17: 猫头鹰 | J17: 492 | K17: 0 | L17: 12 | M17: =J17/L17 -> 41 | N17: 45758 | O17: 45754 | Q17: PASS | R17: 4/16出 | S17: 3/10收到 | U17: UPC贴纸翻4500158580 | X17: 日期码格式：ZURU INC(BVI) 标准格式 日期：按实际生产日期 Packaging Info: #92119 MA UPC版 (1L或3L都可)+UPC贴纸, 贴纸资料翻EU单4500158580 (但不需要印刷IT环保标贴纸)A:193052083821 B:193052083838 D:193052083845 E:19305208 3852 G:193052083869 H:193052083876 Remark: 1.Amazon domestic 订单。出口美国。外箱最长边不能超过25" （超过了，case pack只能为1），不符合要求的大货，一律不接受。 2.无第三方验货/测试要求。 3.日期码使用ZURU标准版本。 | Y17: Kelly Shen/Mia Pan/P | Z17: 3.4 | AA17: =Z17*J17 -> 1672.8 | AB17: =24+468 -> 492 | AC17: =AB17-J17 -> 0 | AD17: OK | AE17: 系统出单 | AF17: ZB00145-4.16 | AG17: 已入 | AH17: =J17 -> 492 | AM17: =J17 -> 492 | AP17: =J17 -> 492 | AV17: MA布标 | BC17: =J17 -> 492 | BD17: =SUM(AW17:BC17) -> 492 | BE17: =J17-BD17 -> 0
A18: 45723 | B18: ZURU LLC | C18: 美国 | D18: 4500159464 | E18: 5200006340 | F18: 4500159464-150 | G18: 92119B-S002 | H18: 92119B-S002-MTS | I18: 企鹅 | J18: 492 | K18: 0 | L18: 12 | M18: =J18/L18 -> 41 | N18: 45758 | O18: 45754 | Q18: PASS | R18: 4/16出 | S18: 3/10收到 | U18: UPC贴纸翻4500158580 | X18: 日期码格式：ZURU INC(BVI) 标准格式 日期：按实际生产日期 Packaging Info: #92119 MA UPC版 (1L或3L都可)+UPC贴纸, 贴纸资料翻EU单4500158580 (但不需要印刷IT环保标贴纸)A:193052083821 B:193052083838 D:193052083845 E:19305208 3852 G:193052083869 H:193052083876 Remark: 1.Amazon domestic 订单。出口美国。外箱最长边不能超过25" （超过了，case pack只能为1），不符合要求的大货，一律不接受。 2.无第三方验货/测试要求。 3.日期码使用ZURU标准版本。 | Y18: Kelly Shen/Mia Pan/P | Z18: 3.4 | AA18: =Z18*J18 -> 1672.8 | AB18: =24+468 -> 492 | AC18: =AB18-J18 -> 0 | AD18: OK | AE18: 系统出单 | AF18: ZB00145-4.16 | AG18: 已入 | AH18: =J18 -> 492 | AM18: =J18 -> 492 | AP18: =J18 -> 492 | AV18: MA布标 | AX18: =J18 -> 492 | BD18: =SUM(AW18:BC18) -> 492 | BE18: =J18-BD18 -> 0
A19: 45723 | B19: ZURU LLC | C19: 美国 | D19: 4500159464 | E19: 5200006340 | F19: 4500159464-160 | G19: 92119A-S002 | H19: 92119A-S002-MTS | I19: 北极熊 | J19: 492 | K19: 0 | L19: 12 | M19: =J19/L19 -> 41 | N19: 45758 | O19: 45754 | Q19: PASS | R19: 4/16出 | S19: 3/10收到 | U19: UPC贴纸翻4500158580 | X19: 日期码格式：ZURU INC(BVI) 标准格式 日期：按实际生产日期 Packaging Info: #92119 MA UPC版 (1L或3L都可)+UPC贴纸, 贴纸资料翻EU单4500158580 (但不需要印刷IT环保标贴纸)A:193052083821 B:193052083838 D:193052083845 E:19305208 3852 G:193052083869 H:193052083876 Remark: 1.Amazon domestic 订单。出口美国。外箱最长边不能超过25" （超过了，case pack只能为1），不符合要求的大货，一律不接受。 2.无第三方验货/测试要求。 3.日期码使用ZURU标准版本。 | Y19: Kelly Shen/Mia Pan/P | Z19: 3.4 | AA19: =Z19*J19 -> 1672.8 | AB19: =24+468 -> 492 | AC19: =AB19-J19 -> 0 | AD19: OK | AE19: 系统出单 | AF19: ZB00145-4.16 | AG19: 已入 | AH19: =J19 -> 492 | AM19: =J19 -> 492 | AP19: =J19 -> 492 | AV19: MA布标 | AW19: =J19 -> 492 | BD19: =SUM(AW19:BC19) -> 492 | BE19: =J19-BD19 -> 0
A20: 45723 | B20: ZURU LLC | C20: 美国 | D20: 4500159464 | E20: 5200006340 | F20: 4500159464-170 | G20: 92119H-S002 | H20: 92119H-S002-MTS | I20: 海豹 | J20: 492 | K20: 0 | L20: 12 | M20: =J20/L20 -> 41 | N20: 45758 | O20: 45754 | Q20: PASS | R20: 4/16出 | S20: 3/10收到 | U20: UPC贴纸翻4500158580 | X20: 日期码格式：ZURU INC(BVI) 标准格式 日期：按实际生产日期 Packaging Info: #92119 MA UPC版 (1L或3L都可)+UPC贴纸, 贴纸资料翻EU单4500158580 (但不需要印刷IT环保标贴纸)A:193052083821 B:193052083838 D:193052083845 E:19305208 3852 G:193052083869 H:193052083876 Remark: 1.Amazon domestic 订单。出口美国。外箱最长边不能超过25" （超过了，case pack只能为1），不符合要求的大货，一律不接受。 2.无第三方验货/测试要求。 3.日期码使用ZURU标准版本。 | Y20: Kelly Shen/Mia Pan/P | Z20: 3.4 | AA20: =Z20*J20 -> 1672.8 | AB20: =24+468 -> 492 | AC20: =AB20-J20 -> 0 | AD20: OK | AE20: 系统出单 | AF20: ZB00145-4.16 | AG20: 已入 | AH20: =J20 -> 492 | AM20: =J20 -> 492 | AP20: =J20 -> 492 | AV20: MA布标 | AY20: =J20 -> 492 | BD20: =SUM(AW20:BC20) -> 492 | BE20: =J20-BD20 -> 0
A21: 45723 | B21: ZURU LLC | C21: 美国 | D21: 4500159464 | E21: 5200006340 | F21: 4500159464-180 | G21: 92119D-S002 | H21: 92119D-S002-MTS | I21: 海象 | J21: 492 | K21: 0 | L21: 12 | M21: =J21/L21 -> 41 | N21: 45758 | O21: 45754 | Q21: PASS | R21: 4/16出 | S21: 3/10收到 | U21: UPC贴纸翻4500158580 | X21: 日期码格式：ZURU INC(BVI) 标准格式 日期：按实际生产日期 Packaging Info: #92119 MA UPC版 (1L或3L都可)+UPC贴纸, 贴纸资料翻EU单4500158580 (但不需要印刷IT环保标贴纸)A:193052083821 B:193052083838 D:193052083845 E:19305208 3852 G:193052083869 H:193052083876 Remark: 1.Amazon domestic 订单。出口美国。外箱最长边不能超过25" （超过了，case pack只能为1），不符合要求的大货，一律不接受。 2.无第三方验货/测试要求。 3.日期码使用ZURU标准版本。 | Y21: Kelly Shen/Mia Pan/P | Z21: 3.4 | AA21: =Z21*J21 -> 1672.8 | AB21: =24+468 -> 492 | AC21: =AB21-J21 -> 0 | AD21: OK | AE21: 系统出单 | AF21: ZB00145-4.16 | AG21: 已入 | AH21: =J21 -> 492 | AM21: =J21 -> 492 | AP21: =J21 -> 492 | AV21: MA布标 | BA21: =J21 -> 492 | BD21: =SUM(AW21:BC21) -> 492 | BE21: =J21-BD21 -> 0
A22: 45705 | B22: DIAMANT TOYS LTD | C22: 以色列 | D22: 4500153742 | E22: 56053 | F22: 4500153742-10 | G22: 92119-S001 | H22: 92119-S001 | I22: 冰雪蛋 | J22: 3480 | K22: 0 | L22: 12 | M22: =J22/L22 -> 290 | N22: 45761 | O22: 45757 | Q22: PASS | R22: 4/18出 | S22: 2/20收到 | U22: 2/17-进口商贴纸+彩色贴纸 | X22: 日期码格式：ZURU INC(BVI) 标准格式 日期：按实际生产日期 Packaging Info: 92119:1L MA收缩膜+进口商贴纸+彩色贴纸; MA指南 Remark: 92119:7 Assortment, Polar bear: Penguin: Walrus: Mammoth: Owl: Seal: Snow man=10:10:10:10:10:8:2. Snow man is the rare item. | Y22: Lena Huang | Z22: 3.4 | AA22: =Z22*J22 -> 11832 | AB22: =3444+36 -> 3480 | AC22: =AB22-J22 -> 0 | AD22: OK | AE22: 系统出单 | AF22: 94787-4.17 | AG22: 已入 | AH22: =J22 -> 3480 | AM22: =J22 -> 3480 | AP22: =J22 -> 3480 | AV22: MA布标 | AW22: =J22/60*10 -> 580 | AX22: =J22/60*10 -> 580 | AY22: =J22/60*8 -> 464 | AZ22: =J22/60*2 -> 116 | BA22: =J22/60*10 -> 580 | BB22: =J22/60*10 -> 580 | BC22: =J22/60*10 -> 580 | BD22: =SUM(AW22:BC22) -> 3480 | BE22: =J22-BD22 -> 0
A23: 45716 | B23: TARGET US | C23: 美国 | D23: 4500158830 | E23: 10001240713-3890 | F23: 4500158830-10 | G23: 92119-S003 | H23: 92119-S003 | I23: 冰雪蛋 | J23: 18152 | K23: 0 | L23: 8 | M23: =J23/L23 -> 2269 | N23: 45761 | O23: 45757 | P23: 正常出货 | Q23: PASS | R23: 5/21出 | S23: 3/11收到 | U23: 无 | V23: 3/24-外箱贴纸 | X23: 日期码格式：ZURU INC(BVI) 标准格式 日期：按实际生产日期 Packaging Info: 92119：产品MA包装, MA 1L收缩膜(UPC版)； Remark: 92119: 1. 92119-S003-RAINBOCORNS-EGGZANIA-SERIES 1-FROZEN MANIA-SHRINK WRAP,8pcs/CTN 2. 产品MA包装, MA 1L收缩膜(UPC版)；收缩膜上的UPC显示193052078391； 7 Assortment, Polar bear: Penguin: Walrus: Mammoth: Owl: Seal: Snow man=10:10:10:10:10:8:2. Snow man is the rare item. 3. 外箱正唛左上角位置粘贴条码箱贴纸，每箱只贴一张，由ZURU订购。来料贴纸上显示的客户DPCI#086-08-4925, UPC显示10193052078398; 此订单所有item： 1. 外箱正唛箱唛内容右侧需贴一张Event label，内容显示Toys Set Date：7/20/2025，工厂自行订购； 2. 产品和包装上印刷 tracking code信息，格式为ZURU常规格式; 3. 出货方式：货代自提 | Y23: Holly Zheng | Z23: 3.35 | AA23: =Z23*J23 -> 60809.2 | AB23: =10080+672+2696+4704 -> 18152 | AC23: =AB23-J23 -> 0 | AD23: OK | AE23: 系统出单 | AG23: 已入 | AH23: =J23 -> 18152 | AM23: =J23 -> 18152 | AR23: =J23 -> 18152 | AV23: MA布标 | AW23: =J23/60*10 -> 3025.3333 | AX23: =J23/60*10 -> 3025.3333 | AY23: =J23/60*8 -> 2420.2667 | AZ23: =J23/60*2 -> 605.06667 | BA23: =J23/60*10 -> 3025.3333 | BB23: =J23/60*10 -> 3025.3333 | BC23: =J23/60*10 -> 3025.3333 | BD23: =SUM(AW23:BC23) -> 18152 | BE23: =J23-BD23 -> 0
A24: 45726 | B24: DM LLC | C24: 俄罗斯联邦 | D24: 4500159461 | E24: 出Bekasovo 2 | F24: 4500159461-40 | G24: 92119-S001 | H24: 92124-S001-92119 | I24: 冰雪蛋（92119+9298+92104） | J24: 4318 | K24: 0 | L24: 1 | M24: =J24/L24 -> 4318 | N24: 45756 | O24: 45752 | Q24: PASS | S24: 3/13收到 | U24: 空白贴纸 | W24: 外包装 (指: 收缩膜/彩卡/铝箔袋/挂卡/PDQ) /外箱不要打ZURU标准日期码！胶件可以打日期码-DG20250401 | X24: 日期码格式：外包装/外箱不要打ZURU标准日期码 日期： Packaging Info: 注意 ：外包装 (指: 收缩膜/彩卡/铝箔袋/挂卡/PDQ) /外箱不要打ZURU标准日期码！胶件可以打日期码。 92124/92123 ： 里面combo 产品1L MA 收缩膜（不含任何条码）+ 空白贴纸覆盖条码， 客版托盘 ， MA指南/说明书（如有）； Remark: 标准配比 ； 请按期完货， 会有罚金。 出2个港口Bekasovo 2 和Ural | Y24: Ann | Z24: 8.499 | AA24: =J24*Z24 -> 36698.682 | AB24: 4318 | AC24: =AB24-J24 -> 0 | AD24: OK | AE24: 系统出单 | AG24: 已入 | AH24: =J24 -> 4318 | AM24: =J24 -> 4318 | AP24: =J24 -> 4318 | AV24: MA布标 | AW24: =J24/60*10 -> 719.66667 | AX24: =J24/60*10 -> 719.66667 | AY24: =J24/60*8 -> 575.73333 | AZ24: =J24/60*2 -> 143.93333 | BA24: =J24/60*10 -> 719.66667 | BB24: =J24/60*10 -> 719.66667 | BC24: =J24/60*10 -> 719.66667 | BD24: =SUM(AW24:BC24) -> 4318 | BE24: =J24-BD24 -> 0
A25: 45726 | B25: DM LLC | C25: 俄罗斯联邦 | D25: 4500159461 | E25: 出Ural | F25: 4500159461-90 | G25: 92119-S001 | H25: 92124-S001-92119 | I25: 冰雪蛋（92119+9298+92104） | J25: 1679 | K25: 0 | L25: 1 | M25: =J25/L25 -> 1679 | N25: 45756 | O25: 45752 | Q25: PASS | S25: 3/13收到 | U25: 空白贴纸 | W25: 外包装 (指: 收缩膜/彩卡/铝箔袋/挂卡/PDQ) /外箱不要打ZURU标准日期码！胶件可以打日期码-DG20250401 | X25: 日期码格式：外包装/外箱不要打ZURU标准日期码 日期： Packaging Info: 注意 ：外包装 (指: 收缩膜/彩卡/铝箔袋/挂卡/PDQ) /外箱不要打ZURU标准日期码！胶件可以打日期码。 92124 ： 里面combo 产品1L MA 收缩膜（不含任何条码）， 客版托盘 ， MA指南/说明书（如有）； Remark: 标准配比 ； 请按期完货， 会有罚金。 出2个港口Bekasovo 2 和Ural | Y25: Ann | Z25: 8.499 | AA25: =J25*Z25 -> 14269.821 | AB25: 1679 | AC25: =AB25-J25 -> 0 | AD25: OK | AE25: 系统出单 | AG25: 已入 | AH25: =J25 -> 1679 | AM25: =J25 -> 1679 | AP25: =J25 -> 1679 | AV25: MA布标 | AW25: =J25/60*10 -> 279.83333 | AX25: =J25/60*10 -> 279.83333 | AY25: =J25/60*8 -> 223.86667 | AZ25: =J25/60*2 -> 55.966667 | BA25: =J25/60*10 -> 279.83333 | BB25: =J25/60*10 -> 279.83333 | BC25: =J25/60*10 -> 279.83333 | BD25: =SUM(AW25:BC25) -> 1679 | BE25: =J25-BD25 -> 0
A26: 45729 | B26: Smyths Toys HQ UC IE | C26: 爱尔兰 | D26: 4500160022 | E26: 4400471618 | F26: 4500160022-10 | G26: 92119A-S003-3L | H26: 92119A-S003 | I26: 北极熊 | J26: 288 | K26: 0 | L26: 6 | M26: =J26/L26 -> 48 | N26: 45759 | O26: 45755 | Q26: PASS | R26: 4/25出 | S26: 3/17收到 | U26: 4/1-EAN条码贴（含德语Callout+挂牌的德意荷警语）+配件袋荷兰语警告语贴纸 | X26: 日期码格式：ZURU INC(BVI) 标准格式 日期：按实际生产日期 Packaging Info: 92119A：MA 3-23L EAN包装+EAN条码贴（含德语Callout+挂牌的德意荷警语）+MA 3L挂牌+MA 3L配件袋+荷兰语警告语贴纸+MA 5L Slime bag+MA 5L-23L收藏指南+M A布标 Remark: 1) 包装日期码按ZURU格式即可，请确保不迟于外箱日期码，可等于或者早于外箱日期码，必须为法定工作日，印刷前请先检查外箱日期码。 2) 订单出英国，请注意检查产品及包装应带UKCA图标（14+产品除外），包装显示ZURU UK LTD/ZURU France地址信息，QC部门请查核，如有问题与跟单确认 3) 需要完全符合欧洲标准(符合微塑料法规)，否则不合法规会有客诉产生 | Y26: May Wu | Z26: 3.58 | AA26: =Z26*J26 -> 1031.04 | AB26: 288 | AC26: =AB26-J26 -> 0 | AD26: OK | AE26: 系统出单 | AF26: 94824-4.24 | AG26: 已入 | AJ26: =J26 -> 288 | AM26: =J26 -> 288 | AP26: =J26 -> 288 | AV26: MA布标 | AW26: =J26 -> 288 | BD26: =SUM(AW26:BC26) -> 288 | BE26: =J26-BD26 -> 0
A27: 45729 | B27: Smyths Toys HQ UC IE | C27: 爱尔兰 | D27: 4500160022 | E27: 4400471618 | F27: 4500160022-20 | G27: 92119B-S003-3L | H27: 92119B-S003 | I27: 企鹅 | J27: 288 | K27: 0 | L27: 6 | M27: =J27/L27 -> 48 | N27: 45759 | O27: 45755 | Q27: PASS | R27: 4/25出 | S27: 3/17收到 | U27: 4/1-EAN条码贴（含德语Callout+挂牌的德意荷警语）+配件袋荷兰语警告语贴纸 | X27: 日期码格式：ZURU INC(BVI) 标准格式 日期：按实际生产日期 Packaging Info: 92119B: MA 3-23L EAN包装+EAN条码贴（含德语Callout+挂牌的德意荷警语）+MA 3L挂牌+MA 3L配件袋+荷兰语警告语贴纸+MA 5L Slime bag+MA 5L-23L收藏指南+M A布标 Remark: 1) 包装日期码按ZURU格式即可，请确保不迟于外箱日期码，可等于或者早于外箱日期码，必须为法定工作日，印刷前请先检查外箱日期码。 2) 订单出英国，请注意检查产品及包装应带UKCA图标（14+产品除外），包装显示ZURU UK LTD/ZURU France地址信息，QC部门请查核，如有问题与跟单确认 3) 需要完全符合欧洲标准(符合微塑料法规)，否则不合法规会有客诉产生 | Y27: May Wu | Z27: 3.5 | AA27: =Z27*J27 -> 1008 | AB27: 288 | AC27: =AB27-J27 -> 0 | AD27: OK | AE27: 系统出单 | AF27: 94824-4.24 | AG27: 已入 | AJ27: =J27 -> 288 | AM27: =J27 -> 288 | AP27: =J27 -> 288 | AV27: MA布标 | AX27: =J27 -> 288 | BD27: =SUM(AW27:BC27) -> 288 | BE27: =J27-BD27 -> 0
A28: 45726 | B28: PPTOYS PTE LTD (SG) | C28: 新加坡 | D28: 4500159608 | E28: ZU25022002SG | F28: 4500159608-10 | G28: 92119-S001 | H28: 92119-S001 | I28: 冰雪蛋 | J28: 840 | K28: 0 | L28: 12 | M28: =J28/L28 -> 70 | N28: 45759 | O28: 45755 | Q28: PASS | R28: 收到SO | S28: 3/10收到 | U28: 3/13-进口商贴纸 | X28: 日期码格式：ZURU INC(BVI) 标准格式 日期：按实际生产日期 Packaging Info: MA UPC包装（优先1L)+1张进口商贴纸 其他item贴纸AW、位置图待提供 此客人用的贴纸内容都是一样的，个别item可能存在尺寸差别，如果发现贴纸尺寸没差别，就请都统一订购节省成本 Remark: 92119-7 Assortment, Polar bear: Penguin: Walrus: Mammoth: Owl: Seal: Snow man=10:10:10:10:10:8:2. Snow man is the rare item. | Y28: Emma Wu | Z28: 3.6923 | AA28: =Z28*J28 -> 3101.532 | AB28: 840 | AC28: =AB28-J28 -> 0 | AD28: OK | AE28: 系统出单 | AF28: 94794-4.18 | AG28: 已入 | AH28: =J28 -> 840 | AM28: =J28 -> 840 | AP28: =J28 -> 840 | AV28: MA布标 | AW28: =J28/60*10 -> 140 | AX28: =J28/60*10 -> 140 | AY28: =J28/60*8 -> 112 | AZ28: =J28/60*2 -> 28 | BA28: =J28/60*10 -> 140 | BB28: =J28/60*10 -> 140 | BC28: =J28/60*10 -> 140 | BD28: =SUM(AW28:BC28) -> 840 | BE28: =J28-BD28 -> 0
A29: 45714 | B29: Walmart Central America-CR | C29: 哥斯达黎加 | D29: 4500158535 | F29: 4500158535-90 | G29: 92119-S001-3L | H29: 92119-S001 | I29: 冰雪蛋 | J29: 816 | K29: 0 | L29: 12 | M29: =J29/L29 -> 68 | N29: 45763 | O29: 45759 | Q29: PASS | R29: 4/29出 | S29: 3/24收到-双坑纸箱 | U29: 3/21-UPC贴纸+进口商贴纸 | X29: 日期码格式：ZURU INC(BVI) 标准格式 日期：按实际生产日期 Packaging Info: 6. 92119: MA 3L EAN包装+UPC贴纸+MA 多语收藏指南+进口商贴纸+箱唛 以上贴纸翻单PO 4500158302 Remark: 1.使用双坑外箱 2.请注意产品包装条形码必须是UPC 3.无第三方验货 92119：7 Assortment, Polar bear: Penguin: Walrus: Mammoth: Owl: Seal: Snow man=10:10:10:10:10:8:2. Snow man is the rare item. | Y29: Ever Li | Z29: 3.4 | AA29: =Z29*J29 -> 2774.4 | AB29: 816 | AC29: =AB29-J29 -> 0 | AD29: OK | AE29: 系统出单 | AF29: 94882-4.29 | AG29: 已入 | AJ29: =J29 -> 816 | AM29: =J29 -> 816 | AP29: =J29 -> 816 | AV29: MA布标 | AW29: =J29/60*10 -> 136 | AX29: =J29/60*10 -> 136 | AY29: =J29/60*8 -> 108.8 | AZ29: =J29/60*2 -> 27.2 | BA29: =J29/60*10 -> 136 | BB29: =J29/60*10 -> 136 | BC29: =J29/60*10 -> 136 | BD29: =SUM(AW29:BC29) -> 816 | BE29: =J29-BD29 -> 0
A30: 45712 | B30: Walmart Central America | C30: 萨尔瓦多 | D30: 4500158302 | F30: 4500158302-90 | G30: 92119-S001-3L | H30: 92119-S001 | I30: 冰雪蛋 | J30: 348 | K30: 0 | L30: 12 | M30: =J30/L30 -> 29 | N30: 45763 | O30: 45759 | Q30: PASS | R30: 4/28出 | S30: 3/24收到-双坑纸箱 | U30: 3/21-UPC贴纸+进口商贴纸 | X30: 日期码格式：ZURU INC(BVI) 标准格式 日期：按实际生产日期 Packaging Info: 6. 92119: MA 3L EAN包装+UPC贴纸+MA 多语收藏指南+进口商贴纸+箱唛 Remark: 1.使用双坑外箱 2.请注意产品包装条形码必须是UPC 3.无第三方验货 6. 92119：7 Assortment, Polar bear: Penguin: Walrus: Mammoth: Owl: Seal: Snow man=10:10:10:10:10:8:2. Snow man is the rare item. | Y30: Ever Li | Z30: 3.4 | AA30: =Z30*J30 -> 1183.2 | AB30: 348 | AC30: =AB30-J30 -> 0 | AE30: 系统出单 | AF30: 94865-4.28 | AG30: 已入 | AJ30: =J30 -> 348 | AM30: =J30 -> 348 | AP30: =J30 -> 348 | AV30: MA布标 | AW30: =J30/60*10 -> 58 | AX30: =J30/60*10 -> 58 | AY30: =J30/60*8 -> 46.4 | AZ30: =J30/60*2 -> 11.6 | BA30: =J30/60*10 -> 58 | BB30: =J30/60*10 -> 58 | BC30: =J30/60*10 -> 58 | BD30: =SUM(AW30:BC30) -> 348 | BE30: =J30-BD30 -> 0
A31: 45730 | B31: KMART AUSTRALIA LTD | C31: 澳大利亚 | D31: 4500160268 | F31: 4500160268-10 | G31: 92119-S001 | H31: 92119-S001 | I31: 冰雪蛋 | J31: 3240 | K31: 0 | L31: 12 | M31: =J31/L31 -> 270 | N31: 45768 | O31: 45764 | Q31: PASS | R31: 4/22-4/25出 | S31: 3/20收到 | U31: 3/31-防盗贴纸+外箱贴纸 | X31: 日期码格式：ZURU INC(BVI) 标准格式 日期：按实际生产日期 Packaging Info: 92119-S001 : MA英语UPC版本包装（收缩膜和说明书, MA首选1L，如无1L可用多语且含英语的配套多语包装) + 1张防盗贴纸+ 箱唛 + 外箱SSCC Label 配比信息：7 Assortment, Polar bear: Penguin: Walrus: Mammoth: Owl: Seal: Snow man=10:10:10:10:10:8:2. Snow man is the rare item." Remark: 1.请务必按时完货，验货。并且按期送货入货代指定仓库，如果晚了导致船期Delay将会有罚金产生或者客户要求空运，所产生的罚金和空运费由工厂承担。 2.SSCC 外箱贴纸请同纸箱瓦楞纸方向（竖纹向）垂直，即外箱贴纸横着贴(注意条码不要被胶带粘住），贴1pc，贴1面正唛，封箱胶纸不能挡住贴纸内容。外箱贴纸 离外箱边距离不少于2cm。 3.外箱材质为ZURU标准； 4.此单需使用KMART封箱胶上下工字型封箱;从2019年6月开始，要用KMART 新版封箱胶带，此单要用"ANKO"封箱胶带 5.此单出口澳大利亚，请按相应的澳新标准生产； 6.产品和包装上生产批号的显示格式ZURU标准日期码格式 7.外箱信息不可手写，重量和体积需要与实际的一致(不可手写） 8. 每款item装箱后的G.W.超过10KG或者CBM超过0.13,(9.5KG或者以上，四舍五入后也属于10KG) 需在外箱上加印超 重或者Bulky LOGO，若发现我们资料没有，请 帮忙提醒 1)重量超过10kg但不超过16kg且CBM不超过0.13,10-16kg 超重logo 2）CBM超过0.13且重量少于17kg，bulky logo 3）不属于以上两种情况，需要使用相应重量范围内的超重logo 4）超重logo需要在外箱四面都印刷(箱唛右上角，两面侧唛超重logo需要尽量靠近毛重)，尺寸为:110mm height* 95mm width 9. 实际外箱重量跟印在箱唛上的数据差异不能超3%，尺寸按实际数据印刷 92119实际为LCL出货 | Y31: Lydia Wu | Z31: 3.4 | AA31: =Z31*J31 -> 11016 | AB31: =888+2352 -> 3240 | AC31: =AB31-J31 -> 0 | AD31: OK | AE31: 系统出单 | AF31: 94836-4.24 | AG31: 已入 | AH31: =J31 -> 3240 | AM31: =J31 -> 3240 | AP31: =J31 -> 3240 | AV31: MA布标 | AW31: =J31/60*10 -> 540 | AX31: =J31/60*10 -> 540 | AY31: =J31/60*8 -> 432 | AZ31: =J31/60*2 -> 108 | BA31: =J31/60*10 -> 540 | BB31: =J31/60*10 -> 540 | BC31: =J31/60*10 -> 540 | BD31: =SUM(AW31:BC31) -> 3240 | BE31: =J31-BD31 -> 0
A32: 45730 | B32: KMART AUSTRALIA LTD(NEW ZEALAND) | C32: 新西兰 | D32: 4500160271 | E32: 20676971 | F32: 4500160271-10 | G32: 92119-S001 | H32: 92119-S001 | I32: 冰雪蛋 | J32: 360 | K32: 0 | L32: 12 | M32: =J32/L32 -> 30 | N32: 45768 | O32: 45764 | Q32: PASS | R32: 4/22-4/25出 | S32: 3/20收到 | U32: 3/31-防盗贴纸+外箱贴纸 | X32: 日期码格式：ZURU INC(BVI) 标准格式 日期：按实际生产日期 Packaging Info: 92119-S001 : MA英语UPC版本包装（收缩膜和说明书, MA首选1L，如无1L可用多语且含英语的配套多语包装) + 1张防盗贴纸 (贴纸以及位置图翻单PO#4500160268） + 箱唛 + 外箱SSCC Label 配比信息：7 Assortment, Polar bear: Penguin: Walrus: Mammoth: Owl: Seal: Snow man=10:10:10:10:10:8:2. Snow man is the rare item. Remark: 1.请务必按时完货，验货。并且按期送货入货代指定仓库，如果晚了导致船期Delay将会有罚金产生或者客户要求空运，所产生的罚金和空运费由工厂承担。 2.SSCC 外箱贴纸请同纸箱瓦楞纸方向（竖纹向）垂直，即外箱贴纸横着贴(注意条码不要被胶带粘住），贴1pc，贴1面正唛，封箱胶纸不能挡住贴纸内容。外箱贴纸 离外箱边距离不少于2cm。 3.外箱材质为ZURU标准； 4.此单需使用KMART封箱胶上下工字型封箱;从2019年6月开始，要用KMART 新版封箱胶带，此单要用"ANKO"封箱胶带 5.此单出口新西兰，请按相应的澳新标准生产； 6.产品和包装上生产批号的显示格式ZURU标准日期码格式 7.外箱信息不可手写，重量和体积需要与实际的一致(不可手写） 8. 每款item装箱后的G.W.超过10KG或者CBM超过0.13,(9.5KG或者以上，四舍五入后也属于10KG) 需在外箱上加印超 重或者Bulky LOGO，若发现我们资料没有，请 帮忙提醒 1)重量超过10kg但不超过16kg且CBM不超过0.13,10-16kg 超重logo 2）CBM超过0.13且重量少于17kg，bulky logo 3）不属于以上两种情况，需要使用相应重量范围内的超重logo 4）超重logo需要在外箱四面都印刷(箱唛右上角，两面侧唛超重logo需要尽量靠近毛重)，尺寸为:110mm height* 95mm width 9. 实际外箱重量跟印在箱唛上的数据差异不能超3%，尺寸按实际数据印刷 92119实际为LCL出货 | Y32: Lydia Wu | Z32: 3.4 | AA32: =Z32*J32 -> 1224 | AB32: 360 | AC32: =AB32-J32 -> 0 | AD32: OK | AE32: 系统出单 | AF32: 94825-4.24 | AG32: 已入 | AH32: =J32 -> 360 | AM32: =J32 -> 360 | AP32: =J32 -> 360 | AV32: MA布标 | AW32: =J32/60*10 -> 60 | AX32: =J32/60*10 -> 60 | AY32: =J32/60*8 -> 48 | AZ32: =J32/60*2 -> 12 | BA32: =J32/60*10 -> 60 | BB32: =J32/60*10 -> 60 | BC32: =J32/60*10 -> 60 | BD32: =SUM(AW32:BC32) -> 360 | BE32: =J32-BD32 -> 0
A33: 45729 | B33: Smyths Toys HQ UC UK | C33: 英国 | D33: 4500160023 | E33: 客户PO4400471 627 | F33: 4500160023-10 | G33: 92119A-S003-3L | H33: 92119A-S003 | I33: 北极熊 | J33: 600 | K33: 0 | L33: 6 | M33: =J33/L33 -> 100 | N33: 45768 | O33: 45764 | Q33: PASS | R33: 4/28出 | S33: 3/17收到 | U33: 4/1-EAN条码贴（含德语Callout+挂牌的德意荷警语）+配件袋荷兰语警告语贴纸翻4500160022 | X33: 日期码格式：ZURU INC(BVI) 标准格式 日期：按实际生产日期 Packaging Info: 92119A：MA 3-23L EAN包装+EAN条码贴（含德语Callout+挂牌的德意荷警语）+MA 3L挂牌+MA 3L配件袋+荷兰语警告语贴纸+MA 5L Slime bag+MA 5L-23L收藏指南+M A布标（贴纸翻4500160022） Remark: 1) 包装日期码按ZURU格式即可，请确保不迟于外箱日期码，可等于或者早于外箱日期码，必须为法定工作日，印刷前请先检查外箱日期码。 2) 订单出英国，请注意检查产品及包装应带UKCA图标（14+产品除外），包装显示ZURU UK LTD/ZURU France地址信息，QC部门请查核，如有问题与跟单确认 3) 需要完全符合欧洲标准(符合微塑料法规)，否则不合法规会有客诉产生 | Y33: May Wu | Z33: 3.58 | AA33: =Z33*J33 -> 2148 | AB33: 600 | AC33: =AB33-J33 -> 0 | AD33: OK | AE33: 系统出单 | AF33: 94849-4.28 | AG33: 已入 | AJ33: =J33 -> 600 | AM33: =J33 -> 600 | AP33: =J33 -> 600 | AV33: MA布标 | AW33: =J33 -> 600 | BD33: =SUM(AW33:BC33) -> 600 | BE33: =J33-BD33 -> 0
A34: 45732 | B34: Smyths Toys HQ UC UK | C34: 英国 | D34: 4500160023 | E34: 客户PO4400471 628 | F34: 4500160023-30 | G34: 92119A-S003-3L | H34: 92119A-S003 | I34: 北极熊 | J34: 600 | K34: 0 | L34: 6 | M34: =J34/L34 -> 100 | N34: 45768 | O34: 45764 | Q34: PASS | R34: 4/28出 | S34: 3/17收到 | U34: 4/1-EAN条码贴（含德语Callout+挂牌的德意荷警语）+配件袋荷兰语警告语贴纸翻4500160022 | X34: 日期码格式：ZURU INC(BVI) 标准格式 日期：按实际生产日期 Packaging Info: 92119A：MA 3-23L EAN包装+EAN条码贴（含德语Callout+挂牌的德意荷警语）+MA 3L挂牌+MA 3L配件袋+荷兰语警告语贴纸+MA 5L Slime bag+MA 5L-23L收藏指南+M A布标（贴纸翻4500160022） Remark: 1) 包装日期码按ZURU格式即可，请确保不迟于外箱日期码，可等于或者早于外箱日期码，必须为法定工作日，印刷前请先检查外箱日期码。 2) 订单出英国，请注意检查产品及包装应带UKCA图标（14+产品除外），包装显示ZURU UK LTD/ZURU France地址信息，QC部门请查核，如有问题与跟单确认 3) 需要完全符合欧洲标准(符合微塑料法规)，否则不合法规会有客诉产生 | Y34: May Wu | Z34: 3.58 | AA34: =Z34*J34 -> 2148 | AB34: 600 | AC34: =AB34-J34 -> 0 | AD34: OK | AE34: 系统出单 | AF34: 94849-4.28 | AG34: 已入 | AJ34: =J34 -> 600 | AM34: =J34 -> 600 | AP34: =J34 -> 600 | AV34: MA布标 | AW34: =J34 -> 600 | BD34: =SUM(AW34:BC34) -> 600 | BE34: =J34-BD34 -> 0
A35: 45733 | B35: SMYTHS TOYS HQ UC | C35: 法国 | D35: 4500160446 | E35: 4400472143 | F35: 4500160446-20 | G35: 92119A-S003-3L | H35: 92119A-S003 | I35: 北极熊 | J35: 408 | K35: 0 | L35: 6 | M35: =J35/L35 -> 68 | N35: 45768 | O35: 45764 | Q35: PASS | S35: 3/17收到 | U35: 德语Callout贴纸+荷兰语警告语贴纸翻4500160022 | X35: 日期码格式：ZURU INC(BVI) 标准格式 日期：按实际生产日期 Packaging Info: 2.92119A:MA 3-23L EAN包装+1张德语Callout贴纸+MA 3L挂牌+MA 5L Slime bag+荷兰语警告语贴纸+MA 5L-23L收藏指南+MA布标 （贴纸都翻4500160022） Remark: 1. 此单出法国，所有包装都需要含有法语，需要满足Zuru Standard欧洲标准测试要求； 2. 请准时出货，推期会有罚款； 3. 所有出口法国的产品, 法规规定禁止在包装和共公众用的印刷品中使用矿物油中含有的物质, 包装印刷油墨中含有的MOAH/MOSH的质量浓度不能超过1%, 否则出 货到法国被抽检出现问题, 供应商需要对此负责; | Y35: Ula Zhao | Z35: 3.58 | AA35: =Z35*J35 -> 1460.64 | AB35: 408 | AC35: =AB35-J35 -> 0 | AD35: OK | AE35: 系统出单 | AF35: 94812-4.22 | AG35: 已入 | AJ35: =J35 -> 408 | AM35: =J35 -> 408 | AP35: =J35 -> 408 | AV35: MA布标 | AW35: =J35 -> 408 | BD35: =SUM(AW35:BC35) -> 408 | BE35: =J35-BD35 -> 0
A36: 45729 | B36: Babyhouse | C36: 乌兹别克斯坦 | D36: 4500159866 | F36: 4500159866-70 | G36: 92119-S001 | H36: 92119-S001 | I36: 冰雪蛋 | J36: 240 | K36: 0 | L36: 12 | M36: =J36/L36 -> 20 | N36: 45769 | O36: 45765 | Q36: PASS | R36: 4/24出 | S36: 3/13收到 | U36: 3/14-进口商贴纸 | X36: 日期码格式：ZURU INC(BVI) 标准格式 日期：按实际生产日期 Packaging Info: 92119 : 1L MA 收缩膜 + 进口商贴纸 ; MA 说明书/指南（如有）; Remark: 标准配比 | Y36: Ann Zhang | Z36: 3.4 | AA36: =Z36*J36 -> 816 | AB36: 240 | AC36: =AB36-J36 -> 0 | AD36: OK | AE36: 系统出单 | AF36: 94879-4.29 | AG36: 已入 | AH36: =J36 -> 240 | AM36: =J36 -> 240 | AP36: =J36 -> 240 | AV36: MA布标 | AW36: =J36/60*10 -> 40 | AX36: =J36/60*10 -> 40 | AY36: =J36/60*8 -> 32 | AZ36: =J36/60*2 -> 8 | BA36: =J36/60*10 -> 40 | BB36: =J36/60*10 -> 40 | BC36: =J36/60*10 -> 40 | BD36: =SUM(AW36:BC36) -> 240 | BE36: =J36-BD36 -> 0
A37: 45732 | B37: Smyths Toys HQ UC UK | C37: 英国 | D37: 4500160023 | E37: 客户PO4400471 628 | F37: 4500160023-40 | G37: 92119B-S003-3L | H37: 92119B-S003 | I37: 企鹅 | J37: 600 | K37: 0 | L37: 6 | M37: =J37/L37 -> 100 | N37: 45764 | O37: 45761 | Q37: PASS | R37: 4/28出 | S37: 3/17收到 | U37: 4/1-EAN条码贴（含德语Callout+挂牌的德意荷警语）+配件袋荷兰语警告语贴纸翻4500160022 | X37: 日期码格式：ZURU INC(BVI) 标准格式 日期：按实际生产日期 Packaging Info: 92119B: MA 3-23L EAN包装+EAN条码贴（含德语Callout+挂牌的德意荷警语）+MA 3L挂牌+MA 3L配件袋+荷兰语警告语贴纸+MA 5L Slime bag+MA 5L-23L收藏指南+M A布标（贴纸翻4500160022） Remark: 1) 包装日期码按ZURU格式即可，请确保不迟于外箱日期码，可等于或者早于外箱日期码，必须为法定工作日，印刷前请先检查外箱日期码。 2) 订单出英国，请注意检查产品及包装应带UKCA图标（14+产品除外），包装显示ZURU UK LTD/ZURU France地址信息，QC部门请查核，如有问题与跟单确认 3) 需要完全符合欧洲标准(符合微塑料法规)，否则不合法规会有客诉产生 | Y37: May Wu | Z37: 3.5 | AA37: =Z37*J37 -> 2100 | AB37: 600 | AC37: =AB37-J37 -> 0 | AD37: OK | AE37: 系统出单 | AF37: 94849-4.28 | AG37: 已入 | AJ37: =J37 -> 600 | AM37: =J37 -> 600 | AP37: =J37 -> 600 | AV37: MA布标 | AX37: =J37 -> 600 | BD37: =SUM(AW37:BC37) -> 600 | BE37: =J37-BD37 -> 0
A38: 45729 | B38: Smyths Toys HQ UC UK | C38: 英国 | D38: 4500160023 | E38: 客户PO4400471 627 | F38: 4500160023-20 | G38: 92119B-S003-3L | H38: 92119B-S003 | I38: 企鹅 | J38: 600 | K38: 0 | L38: 6 | M38: =J38/L38 -> 100 | N38: 45768 | O38: 45764 | Q38: PASS | R38: 4/28出 | S38: 3/17收到 | U38: 4/1-EAN条码贴（含德语Callout+挂牌的德意荷警语）+配件袋荷兰语警告语贴纸翻4500160022 | X38: 日期码格式：ZURU INC(BVI) 标准格式 日期：按实际生产日期 Packaging Info: 92119B: MA 3-23L EAN包装+EAN条码贴（含德语Callout+挂牌的德意荷警语）+MA 3L挂牌+MA 3L配件袋+荷兰语警告语贴纸+MA 5L Slime bag+MA 5L-23L收藏指南+M A布标（贴纸翻4500160022） Remark: 1) 包装日期码按ZURU格式即可，请确保不迟于外箱日期码，可等于或者早于外箱日期码，必须为法定工作日，印刷前请先检查外箱日期码。 2) 订单出英国，请注意检查产品及包装应带UKCA图标（14+产品除外），包装显示ZURU UK LTD/ZURU France地址信息，QC部门请查核，如有问题与跟单确认 3) 需要完全符合欧洲标准(符合微塑料法规)，否则不合法规会有客诉产生 | Y38: May Wu | Z38: 3.5 | AA38: =Z38*J38 -> 2100 | AB38: 600 | AC38: =AB38-J38 -> 0 | AD38: OK | AE38: 系统出单 | AF38: 94849-4.28 | AG38: 已入 | AJ38: =J38 -> 600 | AM38: =J38 -> 600 | AP38: =J38 -> 600 | AV38: MA布标 | AX38: =J38 -> 600 | BD38: =SUM(AW38:BC38) -> 600 | BE38: =J38-BD38 -> 0
A39: 45733 | B39: SMYTHS TOYS HQ UC | C39: 法国 | D39: 4500160446 | E39: 4400472143 | F39: 4500160446-30 | G39: 92119B-S003-3L | H39: 92119B-S003 | I39: 企鹅 | J39: 408 | K39: 0 | L39: 6 | M39: =J39/L39 -> 68 | N39: 45768 | O39: 45764 | Q39: PASS | S39: 3/17收到 | U39: 德语Callout贴纸+荷兰语警告语贴纸翻4500160022 | X39: 日期码格式：ZURU INC(BVI) 标准格式 日期：按实际生产日期 Packaging Info: 3.92119B:MA 3-23L EAN包装+1张德语Callout贴纸+MA 3L挂牌+MA 5L Slime bag+荷兰语警告语贴纸+MA 5L-23L收藏指南+MA布标 （贴纸都翻4500160022） Remark: 1. 此单出法国，所有包装都需要含有法语，需要满足Zuru Standard欧洲标准测试要求； 2. 请准时出货，推期会有罚款； 3. 所有出口法国的产品, 法规规定禁止在包装和共公众用的印刷品中使用矿物油中含有的物质, 包装印刷油墨中含有的MOAH/MOSH的质量浓度不能超过1%, 否则出 货到法国被抽检出现问题, 供应商需要对此负责; | Y39: Ula Zhao | Z39: 3.5 | AA39: =Z39*J39 -> 1428 | AB39: 408 | AC39: =AB39-J39 -> 0 | AD39: OK | AE39: 系统出单 | AF39: 94812-4.22 | AG39: 已入 | AJ39: =J39 -> 408 | AM39: =J39 -> 408 | AP39: =J39 -> 408 | AV39: MA布标 | AX39: =J39 -> 408 | BD39: =SUM(AW39:BC39) -> 408 | BE39: =J39-BD39 -> 0
A40: 45714 | B40: ALL BRANDS TOYS PTY LTD | C40: 澳大利亚 | D40: 4500158680 | E40: 83715 | F40: 4500158680-10 | G40: 92119-S001 | H40: 92119-S001 | I40: 冰雪蛋 | J40: 1440 | K40: 0 | L40: 12 | M40: =J40/L40 -> 120 | N40: 45771 | O40: 45768 | Q40: PASS | R40: 4/24出 | S40: 2/26收到 | U40: 2/26-客人通用进口商贴纸 | X40: 日期码格式：ZURU INC(BVI) 标准格式 日期：按实际生产日期 Packaging Info: 92119：MA_UPC版本包装（MA首选1L，如无1L可用多语且含英语的配套多语UPC包装）+ 1张客人通用进口商贴纸 (请提供贴纸位置图供确认) Remark: 1.按实际生产日期; 2.出澳大利亚，请按照相应标准生产; | Y40: Lydia Wu | Z40: 3.4 | AA40: =Z40*J40 -> 4896 | AB40: 1440 | AC40: =AB40-J40 -> 0 | AD40: OK | AE40: 系统出单 | AF40: 94811-4.22 | AG40: 已入 | AH40: =J40 -> 1440 | AM40: =J40 -> 1440 | AR40: =J40 -> 1440 | AV40: MA布标 | AW40: =J40/60*10 -> 240 | AX40: =J40/60*10 -> 240 | AY40: =J40/60*8 -> 192 | AZ40: =J40/60*2 -> 48 | BA40: =J40/60*10 -> 240 | BB40: =J40/60*10 -> 240 | BC40: =J40/60*10 -> 240 | BD40: =SUM(AW40:BC40) -> 1440 | BE40: =J40-BD40 -> 0
...

Sheet 92125
A1: ZURU Rainbocorn 大猫蛋系列排期#92125 | AW1: 剩余MA | AX1: =半成品MA!S18-AX2 -> 59671 | AY1: =半成品MA!T18-AY2 -> 58837 | AZ1: =半成品MA!U18-AZ2 -> 59211 | BA1: =半成品MA!V18-BA2 -> 58014 | BB1: =半成品MA!W18-BB2 -> 53800 | BC1: =半成品MA!X18-BC2 -> 55495 | BD1: =SUM(AX1:BC1) -> 345028
A2: 45660 | I2: （黃色表示更改或增加） | L2: （蓝色表示已完货） | P2: （綠色表示調整貨期） | AD2: 收缩膜 | AG2: 收藏指南 | AI2: 太空沙 | AJ2: PDQ | AM2: 吊卡 | AO2: 1 | AP2: 1 | AQ2: 1 | AR2: 1 | AS2: 1 | AT2: 1 | AW2: 毛绒交货数 | AX2: 50329 | AY2: 51163 | AZ2: 50789 | BA2: 51986 | BB2: 56200 | BC2: 59505 | BD2: =SUM(AX2:BC2) -> 319972
A3: 接单日期 | B3: 第三方客户名称 | C3: 国家 | D3: PO号 | E3: 客PO号 | F3: SKU | G3: 系统货号 | H3: ITEM# | I3: 中文名 | J3: PO数量 (pcs) | K3: 内箱装箱数量(pcs) | L3: 外箱装箱数量(pcs) | M3: 总箱数 | N3: 客PO期 | O3: 验货期 | P3: 第三方验货期 | Q3: 驗貨結果 | R3: 船期SO | S3: 箱唛资料 | T3: 外箱贴纸 | U3: 客贴纸资料 | V3: 客供物料 | W3: 日期码 | X3: 备注 | Y3: ZURU 跟单 | Z3: 单价USD | AA3: 金额USD | AB3: 發票號 | AC3: 是否入系统 | AD3: MA 1語收縮膜 A版本 | AE3: MA 3語收縮膜 A版本 | AF3: 客版收縮膜 | AG3: MA 5語收藏指南 | AH3: 客版收藏指南 | AI3: 无硼 | AJ3: UQ1 | AK3: SLD展示架 | AL3: 客版领养卡 | AM3: 客版吊卡 | AN3: 布標 | AO3: 暹罗猫-A | AP3: 黑猫-E | AQ3: 粉白猫-B | AR3: 紫猫-D | AS3: 棕黄猫-G | AT3: 橘猫-H | AU3: 总数 | AV3: 相差 | AX3: 暹罗猫-A | AY3: 黑猫-E | AZ3: 粉白猫-B | BA3: 紫猫-D | BB3: 棕黄猫-G | BC3: 橘猫-H
A4: 45805 | B4: PP-订单 | D4: ZPO2505005 | G4: 过渡 | H4: 92125-S001 | J4: 576 | K4: 0 | L4: 6 | M4: =J4/L4 -> 96 | N4: 45811 | O4: =N4-4 -> 45807 | S4: 周转箱 | U4: 无 | Y4: Nicole Yu | AD4: =J4 -> 576 | AG4: =J4 -> 576 | AI4: =J4 -> 576 | AN4: MA布标 | AX4: =AX2-AO4 -> 50329 | AY4: =AY2-AP4 -> 51163 | AZ4: =AZ2-AQ4 -> 50789 | BA4: =BA2-AR4 -> 51986 | BB4: =BB2-AS4 -> 56200 | BC4: =BC2-AT4 -> 59505
A5: 46079 | B5: TJX CANADA | C5: 加拿大 | D5: 4500194379 | E5: 40320901 | F5: 4500194379-60 | H5: 92125-S001 | I5: S001-RAINBOCORNS-EGGZA NIA-SERIES 2-PLUSH SOFT MEDIUM-SHRINK WRAP,6PCS/CTN | J5: 720 | L5: 6 | M5: 46135 | O5: 46129 | X5: 日期码格式：标准格式 日期：按实际生产日期 92125 MA 多语EAN版本+UPC贴纸193052083951 77731 英法客版铜版纸，upc 193052085115, MA 2L 收缩膜 多语多明书 25251 英法客版包装 UPC 845218016418 翻单4500166055 25252 客版英法彩盒和说明书。UPC号码845218016425 25253 英法客版 UPC 845218016432，彩盒翻单4500158924，说明书翻单4500166055 7153 英法客版包装 翻单4500131680， 7149 UPC193052033499 7150UPC 193052033406 MA 多语说明书 92119 无硼版本 MA 3L B 版收缩膜 +UPC 贴纸 UPC 193052078391， B 版5L 收藏指南 9258 无硼版本 MA 3L B 版收缩膜 UPC 5L多语言收藏指南193052037640 9296 无硼版本 MA 3L 收缩膜+ 多语说明书 ， UPC 193052057129 9298 无硼版本 MA C 版3L 收缩膜 +UPC 贴纸 UPC 193052057426， B 版5L 收藏指南 9548 无硼版本 MA D 版本 5L 包装+D 版本 5L 收藏指南 +UPC 贴纸 UPC 193052064196 出加拿大 有客供价格贴 每行对应不同的客户PO，唛头要一一对应， 放唛头时跟单会提供清单 Zuru验货.日期跟踪码：产品外包装及产品本身都必须有日期跟踪码，ZURU标准格式 日期码 | Y5: Katrina Xie | Z5: 5.2547 | AX5: =AX1048509-AO5 -> 0
A6: 45805 | B6: PP-订单 | D6: ZPO2505005 | G6: 过渡 | H6: 92125SLD-S001 | J6: 36 | K6: 0 | L6: 36 | M6: =J6/L6 -> 1 | N6: 45811 | O6: =N6-4 -> 45807 | S6: 周转箱 | U6: 无 | Y6: Nicole Yu | AN6: MA布标 | AX6: =AX4-AO6 -> 50329 | AY6: =AY4-AP6 -> 51163 | AZ6: =AZ4-AQ6 -> 50789 | BA6: =BA4-AR6 -> 51986 | BB6: =BB4-AS6 -> 56200 | BC6: =BC4-AT6 -> 59505
A7: 46079 | B7: TJX CANADA | C7: 加拿大 | D7: 4500194379 | F7: 4500194379-170 | H7: 92125-S001 | I7: S001-RAINBOCORNS-EGGZA NIA-SERIES 2-PLUSH SOFT MEDIUM-SHRINK WRAP,6PCS/CTN | J7: 180 | L7: 6 | M7: 46135 | O7: 46129 | X7: 日期码格式：标准格式 日期：按实际生产日期 92125 MA 多语EAN版本+UPC贴纸193052083951 77731 英法客版铜版纸，upc 193052085115, MA 2L 收缩膜 多语多明书 25251 英法客版包装 UPC 845218016418 翻单4500166055 25252 客版英法彩盒和说明书。UPC号码845218016425 25253 英法客版 UPC 845218016432，彩盒翻单4500158924，说明书翻单4500166055 7153 英法客版包装 翻单4500131680， 7149 UPC193052033499 7150UPC 193052033406 MA 多语说明书 92119 无硼版本 MA 3L B 版收缩膜 +UPC 贴纸 UPC 193052078391， B 版5L 收藏指南 9258 无硼版本 MA 3L B 版收缩膜 UPC 5L多语言收藏指南193052037640 9296 无硼版本 MA 3L 收缩膜+ 多语说明书 ， UPC 193052057129 9298 无硼版本 MA C 版3L 收缩膜 +UPC 贴纸 UPC 193052057426， B 版5L 收藏指南 9548 无硼版本 MA D 版本 5L 包装+D 版本 5L 收藏指南 +UPC 贴纸 UPC 193052064196 出加拿大 有客供价格贴 每行对应不同的客户PO，唛头要一一对应， 放唛头时跟单会提供清单 Zuru验货.日期跟踪码：产品外包装及产品本身都必须有日期跟踪码，ZURU标准格式 日期码 | Y7: Katrina Xie | Z7: 5.2547 | AX7: =AX6-AO7 -> 50329
A8: 45790 | B8: KMART AUSTRALIA LTD | C8: 澳大利亚 | D8: 4500166286 | E8: 20846869 | F8: 4500166286-10 | G8: 92125-S001 | H8: 92125-S001 | I8: 一窝猫蛋 | J8: 954 | K8: 0 | L8: 6 | M8: =J8/L8 -> 159 | N8: 45843 | O8: 45841 | Q8: PASS | R8: 7/2-7/4出 | S8: 5/13收到 | U8: 5/19防盗贴纸+6/9-外箱SSCC | X8: 日期码格式：ZURU INC(BVI) 标准格式 日期：按实际生产日期 Packaging Info: 92125:MA英语UPC版本包装（收缩膜和说明书, MA首选1L，如无1L可用多语且含英语的配套多语包装) + 1张防盗贴纸 + 箱唛 + 外箱SSCC Label 配比信息：6 Assortments,siamese cat:pink-white cat:purple cat:black cat:brown-white cat:orange cat=1:1:1:1:1:1 此订单有分两种装运类型，请注意外箱贴纸需要按贴纸文件顺序安排贴纸顺序，先贴整柜的数量，剩下的贴散货的数量。 如：柜货+散货： 以此类推，如不按此安排，此次出货请自行记录好外箱对应贴纸的相关信息。如客户收到后有贴纸重复或贴纸顺序记录错误等问题产生的相关费用需由工厂自己承担 。 Remark: 1.请务必按时完货，验货。并且按期送货入货代指定仓库，如果晚了导致船期Delay将会有罚金产生或者客户要求空运，所产生的罚金和空运费由工厂承担。 2.SSCC 外箱贴纸请同纸箱瓦楞纸方向（竖纹向）垂直，即外箱贴纸横着贴(注意条码不要被胶带粘住），贴1pc，贴1面正唛，封箱胶纸不能挡住贴纸内容。外箱贴纸 离外箱边距离不少于2cm。 3.外箱材质为ZURU标准； 4.此单需使用KMART封箱胶上下工字型封箱;从2019年6月开始，要用KMART 新版封箱胶带，此单要用"ANKO"封箱胶带 5.此单出口澳大利亚，请按相应的澳新标准生产； 6.产品和包装上生产批号的显示格式ZURU标准日期码格式 7.外箱信息不可手写，重量和体积需要与实际的一致(不可手写） 8. 每款item装箱后的G.W.超过10KG或者CBM超过0.13,(9.5KG或者以上，四舍五入后也属于10KG) 需在外箱上加印超 重或者Bulky LOGO，若发现我们资料没有，请 帮忙提醒 1)重量超过10kg但不超过16kg且CBM不超过0.13,10-16kg 超重logo 2）CBM超过0.13且重量少于17kg，bulky logo 3）不属于以上两种情况，需要使用相应重量范围内的超重logo 4）超重logo需要在外箱四面都印刷(箱唛右上角，两面侧唛超重logo需要尽量靠近毛重)，尺寸为:110mm height* 95mm width 9. 实际外箱重量跟印在箱唛上的数据差异不能超3%，尺寸按实际数据印刷 | Y8: Lydia Wu | Z8: 5.2 | AA8: =Z8*J8 -> 4960.8 | AB8: 95855-7.31 | AC8: 已入 | AD8: =J8 -> 954 | AG8: =J8 -> 954 | AI8: =J8 -> 954 | AN8: MA布标 | AO8: =J8/6 -> 159 | AP8: =J8/6 -> 159 | AQ8: =J8/6 -> 159 | AR8: =J8/6 -> 159 | AS8: =J8/6 -> 159 | AT8: =J8/6 -> 159 | AU8: =SUM(AO8:AT8) -> 954 | AV8: =J8-AU8 -> 0 | AX8: =AX6-AO8 -> 50170 | AY8: =AY6-AP8 -> 51004 | AZ8: =AZ6-AQ8 -> 50630 | BA8: =BA6-AR8 -> 51827 | BB8: =BB6-AS8 -> 56041 | BC8: =BC6-AT8 -> 59346
A9: 45790 | B9: Salling Group A/S | C9: 丹麦 | D9: 4500166233 | E9: 4041588208 | F9: 4500166233-30 | G9: 92125-S001-3L | H9: 92125-S001 | I9: 一窝猫蛋 | J9: 1962 | K9: 0 | L9: 6 | M9: =J9/L9 -> 327 | N9: 45840 | O9: 45841 | Q9: PASS | R9: 7/4出 | S9: 5/23收到 | U9: 5/23-挪威瑞典丹麦芬兰爱沙尼亚警告语贴纸贴 | X9: 日期码格式：ZURU INC(BVI) 标准格式 日期：按实际生产日期 Packaging Info: 3. 92125: MA A 3L(23L warning) EAN版收缩膜+MA KITTY LITTER BAG_MA_A_5L(Warning 9L)+挪威瑞典丹麦芬兰爱沙尼亚警告语贴纸贴在袋子上+MA_A Version_5L( WARNING 23L)收藏指南+MA布标+MA ACCESSORIES BAGS_MA_A_5L(23L warning) Remark: 92125是新品，请在6/25各寄两套大货样给客人留底 1. 包装如含PVC,请改为PET 2. 产品/包装要求无硼无香； 3. 出欧洲，微塑料需合规。 4.带电池出货的产品所用到的电池需要符合欧洲电池新规(EU) 2023-1542 5.关于贴纸，如果贴纸位置图的包装版本与大货不一致，请工厂提前提出。跟单会重新调整确认是否更新贴纸或调整位置图 6.产品/包装不含PFAS成分 7. 产品条码如下: 请先检查条码是否正确再安排做货，如有问题请告知: 92125-S001:4894680046306 | Y9: Sheba | Z9: 4.4 | AA9: =Z9*J9 -> 8632.8 | AB9: 95854-7.31 | AC9: 已入 | AE9: =J9 -> 1962 | AG9: =J9 -> 1962 | AI9: =J9 -> 1962 | AN9: MA布标 | AO9: =J9/6 -> 327 | AP9: =J9/6 -> 327 | AQ9: =J9/6 -> 327 | AR9: =J9/6 -> 327 | AS9: =J9/6 -> 327 | AT9: =J9/6 -> 327 | AU9: =SUM(AO9:AT9) -> 1962 | AV9: =J9-AU9 -> 0 | AX9: =AX8-AO9 -> 49843 | AY9: =AY8-AP9 -> 50677 | AZ9: =AZ8-AQ9 -> 50303 | BA9: =BA8-AR9 -> 51500 | BB9: =BB8-AS9 -> 55714 | BC9: =BC8-AT9 -> 59019
