Workbook

Sheet 9548明细
AJ1: 彩盒 | AR1: 说明书 | AV1: 展示架 | BF1: MA-RR-1088 | BG1: MA-RR-1124 | BH1: MA-RR-1143 | BI1: MA-RR-1179 | BJ1: MA-RR-1201 | BK1: MA-RR-1226 | BL1: MA-RR-1261 | BM1: MA-RR-1315 | BN1: MA-RR-1332
A2: 接单期 | B2: 第三方客户名称 | C2: 走货国家 | D2: ZURU PO NO# | E2: 第三方客户 PO NO# | F2: SKU | G2: ITEM# | H2: 货品名称 | I2: PO数量(只) | J2: 内箱装箱数量(只) | K2: 外箱装箱数量(只) | L2: 总箱数 | M2: 计划出货期 | N2: 计划验货期 | O2: 第三方客户公证行验货 | P2: 验货结果 | Q2: ZURU确认走货日期 | R2: 箱唛(收到日期) | S2: 外箱贴纸 | T2: 客供贴纸资料(收到日期及订购日期) | U2: 布标 | V2: 客版资料 | W2: 日期码 | X2: 备注 | Y2: ZURU跟单组员 | Z2: 单价USD | AA2: 金额USD | AB2: 发票号 | AC2: 系统货号 | AD2: 是否入系统 | AE2: 需求数 有硼 | AF2: 需求数 无硼 | AG2: 送货情况 | AH2: 贴纸情况 | AI2: 纸箱情况 | AJ2: MA1语彩盒A版 | AK2: MA1语彩盒B版 | AL2: MA5语彩盒 A版 | AM2: MA5语彩盒 B版 | AN2: MA1语彩盒C版 | AO2: MA5语彩盒 C版 | AP2: MA5语彩盒D版 | AQ2: 客版彩盒 | AR2: 5L 说明书 A版 | AS2: 5L 说明书 B版 | AT2: 5L 说明书 C版 | AU2: 客版说明书 | AV2: 9548SLD-S001 | AW2: 9548EC-S001B版 | AX2: 9548UQ1 客版PDQ | AY2: 9548SLB-S001(66pcs) | AZ2: 9548SLB-S002 | BA2: 合计数量 | BB2: 累计数量 | BC2: 新配比（口水胶） | BD2: 新旧压片 | BE2: MA数量 | BF2: 30000 | BG2: 60000 | BH2: 60000 | BI2: 80000 | BJ2: 100000 | BK2: 120000 | BL2: 40000 | BM2: 40000 | BN2: 40000
A3: 45370 | B3: BJ'S WHOLESALE CLUB, INC. | C3: 美国 | D3: 4500127362 | E3: 115380735 | F3: 4500127362-10 | G3: 9548UQ1-S001 | H3: 鸭妈妈 | I3: 2864 | J3: 0 | K3: 4 | L3: =I3/K3 -> 716 | M3: 45432 | N3: 45428 | P3: PASS | Q3: 6/19出货 | R3: 45370 | S3: 无 | T3: 无 | U3: MA | V3: 客版PDQ | X3: 日期码格式：ZURU INC(BVI) 标准格式 日期：按实际生产日期 Packaging Info: MA UPC版本包装+客版PDQ（PDQ AW翻单PO#4500127386） Remark: 1. 箱唛上体积数和实际要相符，如体积数和PO上有不一致，客人会有罚款。 2. 产品和包装上的日期按照ZURU标准格式。 3. 产品不含以下物质： a. 不含任何的美国优先化学品priority chemicals； b. 不含或者不超过美国缅因州的高度关注化学品Chemicals of High Concern清单中的最低水平(100mg/kg)； c. 不含化学阻燃剂：TDCPP，TCEP，Antimony trioxide，HBCD，TBPH，TBB，SCCP，TCPP，Penta-BDE，Octa-BDE，TBBPA等。 | Y3: Emily Wu | Z3: 7.65 | AA3: =Z3*I3 -> 21909.6 | AB3: 已出货 | AC3: 9548UQ1-S001 | AD3: 已入 | AE3: =I3*0.2 -> 572.8 | AJ3: =I3 -> 2864 | AR3: =I3 -> 2864 | AX3: =I3/4 -> 716 | BA3: =I3 -> 2864 | BB3: =652688+BA3+80332 -> 735884 | BD3: 旧 | BF3: =#REF!+$BF$2+$BG$2-BB3 -> #REF!
A4: 45558 | B4: WAL-MART STORES INC. USA | C4: 美国 | D4: 4500145927 | E4: 0863715001 | F4: 4500145927-30 | G4: 9548SLB-S002 | H4: 鸭妈妈 （卡板装） | I4: 2304 | J4: 1 | K4: 72 | L4: =I4/K4 -> 32 | M4: 45596 | N4: 45593 | O4: 10/31完成自检 | P4: PASS | R4: 45373 | S4: 有 | T4: 客版布标贴纸，10/12客供RFID贴纸 | U4: MA | X4: 日期码格式：ZURU DGYYYYMMDD CHINA（日期避开周末和法定节假日即可） 日期：按实际生产日期 Packaging Info: 1.包装信息：MA A版 UPC版 1L收缩膜，MA 5L A版说明书，MA 5L A版口水胶袋，MA 2L C版车缝布标，客版布标贴纸，客供RFID贴纸（标贴位置严格按照我们签板的 位置图，不可擅自调整位置，贴纸不能有任何破损或折坏，不可淋湿）。 Remark: 2.外箱四面印刷RFID箱唛，正唛左前下角印刷ITF-14格式条码的艾利替代标箱唛，只印刷正唛一面，整个内容尺寸最小10*10cm，加印时需确保条形码能扫描出来，Z URU logo跟MADE IN CHINA四面右下角印刷，外箱印刷日期码，每个slip sheet上面贴一张10*10cm艾利替代标（工厂自行用不干胶打印）和一张普通贴纸（可A4纸 打印），slip sheet打印的普通贴纸的尺寸不能比艾利替代标小。 3.在产品上和包装上要有日期码（避开周末和节假日），以及要有MADE IN CHINA和ZURU字样。 4.产品如有扎带口要剪平，不能刮手。 5.此单以打卡板出货（18*4H=72cartons/72pcs/Slip Sheet） 6.此单需要第三方验货，请自行多备物料。 7.其它信息：3pcs*AAA battery not include。 | Y4: Sandy Xu | Z4: 531.55 | AA4: =Z4*L4 -> 17009.6 | AB4: 已出货 | AC4: 9548SLB-S002 | AD4: 已入 | AE4: =I4*0.2 -> 460.8 | AJ4: =I4 -> 2304 | AR4: =I4 -> 2304 | AZ4: =I4/72 -> 32 | BA4: =I4 -> 2304 | BB4: =BB3+BA4 -> 738188
A5: 45558 | B5: WAL-MART STORES INC. USA | C5: 美国 | D5: 4500145927 | E5: 0863715002 | F5: 4500145927-40 | G5: 9548SLB-S002 | H5: 鸭妈妈 （卡板装） | I5: 504 | J5: 1 | K5: 72 | L5: =I5/K5 -> 7 | M5: 45596 | N5: 45593 | O5: 10/31完成自检 | P5: PASS | R5: 45373 | S5: 有 | T5: 客版布标贴纸，10/12客供RFID贴纸 | U5: MA | X5: 日期码格式：ZURU DGYYYYMMDD CHINA（日期避开周末和法定节假日即可） 日期：按实际生产日期 Packaging Info: 1.包装信息：MA A版 UPC版 1L收缩膜，MA 5L A版说明书，MA 5L A版口水胶袋，MA 2L C版车缝布标，客版布标贴纸，客供RFID贴纸（标贴位置严格按照我们签板的 位置图，不可擅自调整位置，贴纸不能有任何破损或折坏，不可淋湿）。 Remark: 2.外箱四面印刷RFID箱唛，正唛左前下角印刷ITF-14格式条码的艾利替代标箱唛，只印刷正唛一面，整个内容尺寸最小10*10cm，加印时需确保条形码能扫描出来，Z URU logo跟MADE IN CHINA四面右下角印刷，外箱印刷日期码，每个slip sheet上面贴一张10*10cm艾利替代标（工厂自行用不干胶打印）和一张普通贴纸（可A4纸 打印），slip sheet打印的普通贴纸的尺寸不能比艾利替代标小。 3.在产品上和包装上要有日期码（避开周末和节假日），以及要有MADE IN CHINA和ZURU字样。 4.产品如有扎带口要剪平，不能刮手。 5.此单以打卡板出货（18*4H=72cartons/72pcs/Slip Sheet） 6.此单需要第三方验货，请自行多备物料。 7.其它信息：3pcs*AAA battery not include。 | Y5: Sandy Xu | Z5: 533.1556 | AA5: =Z5*L5 -> 3732.0892 | AB5: 已出货 | AC5: 9548SLB-S002 | AD5: 已入 | AE5: =I5*0.2 -> 100.8 | AJ5: =I5 -> 504 | AR5: =I5 -> 504 | AZ5: =I5/72 -> 7 | BA5: =I5 -> 504 | BB5: =BB4+BA5 -> 738692
A6: 45593 | B6: Tesco CE | D6: MPO02967 | G6: 9548-S001 | H6: 鸭妈妈 | I6: 2080 | J6: 0 | K6: 4 | L6: =I6/K6 -> 520 | M6: 45630 | N6: 45626 | P6: PASS | R6: 可用空白周转箱 | S6: 无 | T6: 无 | U6: MA | X6: Remark: ① 2% 损耗；②送货前必需通知我司安排验货. 1. 此单出EU，需满足EU测试标准要求，不含微塑料。 2. 产品及包装需要印UKCA图标，包装需要有ZURU UK LTD/ZURU France地址信息，QC同事请核查，如有问题与跟单确认。 3.可用空白周转箱 4. 如含硼的话， 需用低硼版本(小于300ppm),硼含量需要符合欧洲标准,否则客人会退货有罚款产生 5. 子件送华康组装 9548：最新版MA 1L+23L UPC收缩膜包装 | Y6: Eddie Huang | Z6: 7.069 | AA6: =Z6*I6 -> 14703.52 | AB6: 94398-2.27 | AC6: 9548-S001 | AD6: 已入 | AE6: =I6*0.2 -> 416 | AK6: =I6 -> 2080 | AS6: =I6 -> 2080 | BA6: =I6 -> 2080 | BB6: =BB5+BA6 -> 740772
A7: 45586 | B7: TJX COMPANIES, INC | C7: 美国 | D7: 4500147789 | E7: Marshalls DC#881-124PCS , DC#884-96PCS, DC#886-140PCS , DC#887-116PCS , DC#888-124PCS | F7: 4500147789-30 | G7: 9548-S001 | H7: 鸭妈妈 | I7: 600 | J7: 0 | K7: 4 | L7: =I7/K7 -> 150 | M7: 45649 | N7: 45645 | P7: PASS | R7: 45600 | S7: 无 | T7: 11/19价格贴纸客供 | U7: MA | X7: 日期码格式：ZURU INC(BVI) 标准格式 日期：按实际生产日期 Packaging Info: MA UPC包装+价格贴纸，价格贴纸客供。 Remark: 1. 产品和包装上印刷tracking code信息，格式为ZURU常规格式。 2. 分5个DC出货，每款产品每个DC的箱唛资料不同。具体分DC数量，请参考后面行项目备注。 3. ZURU QC验货。 | Y7: Emily Wu | Z7: 7.6175 | AA7: =Z7*I7 -> 4570.5 | AB7: 94169-1.23 | AC7: 9548-S001 | AD7: 已入 | AE7: =I7*0.2 -> 120 | AK7: =I7 -> 600 | AS7: =I7 -> 600 | BA7: =I7 -> 600 | BB7: =BB6+BA7 -> 741372
A8: 45635 | D8: ZMPO24927 | G8: 9548-S001 | H8: 鸭妈妈 | I8: 120 | J8: 0 | K8: 4 | L8: =I8/K8 -> 30 | M8: 45649 | N8: 45645 | P8: PASS | R8: 45636 | S8: 无 | T8: 无 | U8: MA | X8: Remark：大货最新版本/大货标准箱装箱/箱唛请参照邮件附件；备注： 收到样品订单后尽快安排 ，注意样板品质质量要求要高于大货品质要求 ，送货时必须要附带送货单(没有送货单和QC检验合格报告的仓库一律拒绝收货)，请知悉，谢谢！ | Y8: Angus | Z8: 7.3292 | AA8: =Z8*I8 -> 879.504 | AB8: 94396-2.27 | AC8: 9548-S001 | AD8: 已入 | AE8: =I8*0.2 -> 24 | AK8: =I8 -> 120 | AS8: =I8 -> 120 | BA8: =I8 -> 120 | BB8: =BB7+BA8 -> 741492
A9: 45608 | B9: Amazon CA (Vendor Center) | C9: 加拿大 | D9: 4500150978 | E9: 6B6E7U7Q | F9: 4500150978-60 | G9: 9548-S001-NB | H9: 鸭妈妈 | I9: 16 | J9: 0 | K9: 4 | L9: =I9/K9 -> 4 | M9: 45653 | N9: 45639 | P9: PASS | R9: 45622 | S9: 有 | T9: 11/2外箱客供贴纸+贴纸资料跟翻单#4500146603 | U9: MA | X9: 日期码格式：ZURU INC(BVI) 标准格式 日期：按实际生产日期 Packaging Info: 出口加拿大，包装需要至少2/3L UPC版，无硼版本 #9548: MA 5L 加UPC贴纸，贴纸资料跟翻单#4500146603，UPC：193052064196。 Remark: 1. Amazon FOB订单，出口CA。外箱最长边不能超过25" （超过了，case pack只能为1），不符合要求的大货，一律不接受。 2. 外箱正面印ZURU Logo + SSCC LABEL（客供贴纸)，侧面印item#（订单上显示的SKU#) + carton size(以工厂实际尺寸为准，单位: inch) + MADE IN CHINA， 日期使用ZURU 标准版本 SSCC Label 显示的是客人自己的item#，SSCC Label 贴在外箱正面的正中间，贴一面即可，跟单订购，贴纸离外箱距必须至少3cm，每一 张SSCC label 都是唯一且有不同流水及条码的，没有损耗，绝对不可贴错 ，否则贴错或损坏一张会导致全部都错，千万要注意: SSCC 贴纸务必要在正中间(可以覆 盖Logo <(>&<)> 箱唛)，否则会影响到仓库扫描识别。 3. 日期码使用ZURU标准版本。 4. 如果大货有要求入邮包盒，则对应的邮包盒上面要打上日期码。 5. 按照客户PO# 装柜/箱号顺序装柜，跟单会提前给到装柜计划。在大货生产/仓库存放时，请留意该装柜要求，以便装柜时不混乱（避免装错/装漏/找不到货号等 ）。 6. 出口加拿大，包装需要至少2/3L UPC版，无硼版本。 7.邮包盒上要印刷日期码 | Y9: Kelly/Mia | Z9: 7.3292 | AA9: =Z9*I9 -> 117.2672 | AB9: 未出货 | AC9: 9548-S001-NB-5L | AD9: 已入 | AF9: =I9*0.2 -> 3.2 | AO9: =I9 -> 16 | AS9: =I9 -> 16 | BA9: =I9 -> 16 | BB9: =BB8+BA9 -> 741508
A10: 45617 | B10: TARGET US | C10: 美国 | D10: 4500151904 | E10: 10001053761-3891 | F10: 4500151904-20 | G10: 9548-S001 | H10: 鸭妈妈 | I10: 848 | J10: 0 | K10: 4 | L10: =I10/K10 -> 212 | M10: 45653 | N10: 45649 | R10: 45625 | S10: 有 | T10: 12/6客供外箱贴纸 | U10: MA | X10: 日期码格式：ZURU INC(BVI) 标准格式 日期：按实际生产日期 Packaging Info: 9548：MA 1L包装(UPC版) Remark: 9548： 1. 9548-S001-PETS ALIVE - MAMA <(>&<)> BABY SURPRISE - SERIES 1 - MAMA DUCK -WINDOW BOX-4 PCS/CTN 2. MA 1L包装(UPC版), 产品彩盒上的UPC显示193052064196; 3. 外箱正唛左上角位置粘贴条码箱贴纸，每箱只贴一张，由ZURU订购。来料贴纸上显示的客户DPCI# 086-08-0304， UPC显示10193052064193; 4. 产品和包装上印刷 tracking code信息，格式为ZURU常规格式; 5. 出货方式：货代自提 | Y10: Holly Zheng | Z10: 7.3075 | AA10: =Z10*I10 -> 6196.76 | AC10: 9548-S001 | AD10: 已入 | AE10: =I10*0.2 -> 169.6 | AK10: =I10 -> 848 | AS10: =I10 -> 848 | BA10: =I10 -> 848 | BB10: =BB4+BA10 -> 739036
A11: 45607 | B11: TARGET US | C11: 美国 | D11: 4500150859 | E11: 10001053805-3891 | F11: 4500150859-20 | G11: 9548-S001 | H11: 鸭妈妈 | I11: 848 | J11: 0 | K11: 4 | L11: =I11/K11 -> 212 | M11: 45653 | N11: 45649 | R11: 45622 | S11: 有 | T11: 12/6客供外箱贴纸 | U11: MA | X11: 日期码格式：ZURU INC(BVI) 标准格式 日期：按实际生产日期 Packaging Info: 9548:MA 1L包装(UPC版) Remark: 9548: 1. 9548-S001-PETS ALIVE - MAMA <(>&<)> BABY SURPRISE - SERIES 1 - MAMA DUCK -WINDOW BOX-4 PCS/CTN 2. MA 1L包装(UPC版), 产品彩盒上的UPC显示193052064196; 3. 外箱正唛左上角位置粘贴条码箱贴纸，每箱只贴一张，由ZURU订购。来料贴纸上显示的客户DPCI# 086-08-0304， UPC显示10193052064193; 4. 产品和包装上印刷 tracking code信息，格式为ZURU常规格式; 5. 出货方式：货代自提 | Y11: Holly Zheng | Z11: 7.3075 | AA11: =Z11*I11 -> 6196.76 | AC11: 9548-S001 | AD11: 已入 | AE11: =I11*0.2 -> 169.6 | AK11: =I11 -> 848 | AS11: =I11 -> 848 | BA11: =I11 -> 848 | BB11: =BB10+BA11 -> 739884
A12: 45607 | B12: TARGET US | C12: 美国 | D12: 4500150863 | E12: 10001053812-3890 | F12: 4500150859-20 | G12: 9548-S001 | H12: 鸭妈妈 | I12: 1168 | J12: 0 | K12: 4 | L12: =I12/K12 -> 292 | M12: 45653 | N12: 45639 | R12: 45622 | S12: 有 | T12: 12/6客供外箱贴纸 | U12: MA | X12: 日期码格式：ZURU INC(BVI) 标准格式 日期：按实际生产日期 Packaging Info: 9548: MA 1L包装(UPC版) Remark: 9548: 1. 9548-S001-PETS ALIVE - MAMA <(>&<)> BABY SURPRISE - SERIES 1 - MAMA DUCK -WINDOW BOX-4 PCS/CTN 2. MA 1L包装(UPC版), 产品彩盒上的UPC显示193052064196; 3. 外箱正唛左上角位置粘贴条码箱贴纸，每箱只贴一张，由ZURU订购。来料贴纸上显示的客户DPCI# 086-08-0304， UPC显示10193052064193; 4. 产品和包装上印刷 tracking code信息，格式为ZURU常规格式; 5. 出货方式：货代自提 | Y12: Holly Zheng | Z12: 7.3075 | AA12: =Z12*I12 -> 8535.16 | AC12: 9548-S001 | AD12: 已入 | AE12: =I12*0.2 -> 233.6 | AK12: =I12 -> 1168 | AS12: =I12 -> 1168 | BA12: =I12 -> 1168 | BB12: =BB11+BA12 -> 741052
A13: 45586 | B13: TJX COMPANIES, INC | C13: 美国 | D13: 4500147796 | E13: TJ MAXX DC#891-160PCS , DC#894-136PCS , DC#896-128PCS , DC#897-248PCS , DC#898-128PCS | F13: 4500147796-40 | G13: 9548-S001 | H13: 鸭妈妈 | I13: 800 | J13: 0 | K13: 4 | L13: =I13/K13 -> 200 | M13: 45656 | N13: 45652 | R13: 45600 | S13: 无 | T13: 12/6价格贴纸客供 | U13: MA | X13: 日期码格式：ZURU INC(BVI) 标准格式 日期：按实际生产日期 Packaging Info: MA UPC包装+价格贴纸，价格贴纸客供。 Remark: 1. 产品和包装上印刷tracking code信息，格式为ZURU常规格式。 2. 分5个DC出货，每款产品每个DC的箱唛资料不同。具体分DC数量，请参考后面行项目备注。 3. ZURU QC验货。 | Y13: Emily Wu | Z13: 7.6175 | AA13: =Z13*I13 -> 6094 | AB13: 94170-1.23 | AC13: 9548-S001 | AD13: 已入 | AE13: =I13*0.2 -> 160 | AK13: =I13 -> 800 | AS13: =I13 -> 800 | BA13: =I13 -> 800 | BB13: =BB12+BA13 -> 741852
A14: 45586 | B14: TJX COMPANIES, INC | C14: 美国 | D14: 4500147793 | E14: Marshalls DC#881-124PCS , DC#884-96PCS, DC#886-140PCS , DC#887-116PCS , DC#888-124PCS | F14: 4500147793-40 | G14: 9548-S001 | H14: 鸭妈妈 | I14: 600 | J14: 0 | K14: 4 | L14: =I14/K14 -> 150 | M14: 45656 | N14: 45652 | R14: 45600 | S14: 无 | T14: 12/6价格贴纸客供 | U14: MA | X14: 日期码格式：ZURU INC(BVI) 标准格式 日期：按实际生产日期 Packaging Info: MA UPC包装+价格贴纸，价格贴纸客供。 Remark: 1. 产品和包装上印刷tracking code信息，格式为ZURU常规格式。 2. 分5个DC出货，每款产品每个DC的箱唛资料不同。具体分DC数量，请参考后面行项目备注。 3. ZURU QC验货。 | Y14: Emily Wu | Z14: 7.6175 | AA14: =Z14*I14 -> 4570.5 | AB14: 94171-1.23 | AC14: 9548-S001 | AD14: 已入 | AE14: =I14*0.2 -> 120 | AK14: =I14 -> 600 | AS14: =I14 -> 600 | BA14: =I14 -> 600 | BB14: =BB13+BA14 -> 742452
A15: 45622 | B15: ALL BRANDS TOYS PTY LTD | C15: 澳大利亚 | D15: 4500152355 | E15: 83235 | F15: 4500152355-10 | G15: 9548-S001 | H15: 鸭妈妈 | I15: 1040 | J15: 0 | K15: 4 | L15: =I15/K15 -> 260 | M15: 45656 | N15: 45652 | R15: 45624 | S15: 无 | T15: 进口商贴纸+贴纸翻单4500125432 | U15: MA | X15: 日期码格式：ZURU INC(BVI) 标准格式 日期：按实际生产日期 Packaging Info: 9548:英文MA包装UPC版本（首选1L, 如无1L可选多语含英语）+客人通用进口商贴纸+箱唛，贴纸翻单4500125432 Remark: 1.按实际生产日期; 2.出澳大利亚，请按照相应标准生产; | Y15: Lydia Wu | Z15: 7.6175 | AA15: =Z15*I15 -> 7922.2 | AC15: 9548-S001 | AD15: 已入 | AE15: =I15*0.2 -> 208 | AK15: =I15 -> 1040 | AS15: =I15 -> 1040 | BA15: =I15 -> 1040 | BB15: =BB14+BA15 -> 743492
A16: 45621 | B16: TARGET US | C16: 美国 | D16: 4500152243 | E16: 10001144214-3891 | F16: 4500152243-10 | G16: 9548-S001 | H16: 鸭妈妈 | I16: 6312 | J16: 0 | K16: 4 | L16: =I16/K16 -> 1578 | M16: 45656 | N16: 45652 | R16: 45625 | S16: 有 | T16: 12/6客供外箱贴纸 | U16: MA | X16: 日期码格式：ZURU INC(BVI) 标准格式 日期：按实际生产日期 Packaging Info: MA 1L包装(UPC版) Remark: 1. 9548-S001-PETS ALIVE - MAMA <(>&<)> BABY SURPRISE - SERIES 1 - MAMA DUCK -WINDOW BOX-4 PCS/CTN 2. MA 1L包装(UPC版), 产品彩盒上的UPC显示193052064196; 3. 外箱正唛左上角位置粘贴条码箱贴纸，每箱只贴一张，由ZURU订购。来料贴纸上显示的客户DPCI# 086-08-0304， UPC显示10193052064193; 4. 产品和包装上印刷 tracking code信息，格式为ZURU常规格式; 5. 出货方式：货代自提 | Y16: Holly Zheng | Z16: 7.2151 | AA16: =Z16*I16 -> 45541.711 | AC16: 9548-S001 | AD16: 已入 | AE16: 300 | AK16: =I16 -> 6312 | AS16: =I16 -> 6312 | BA16: =I16 -> 6312 | BB16: =BB15+BA16 -> 749804
A17: 45604 | B17: THE ENTERTAINER | C17: 英国 | D17: 4500150141 | E17: 4500150141-1 | F17: 4500150141-30 | G17: 9548-S001 | H17: 鸭妈妈 | I17: 1272 | J17: 0 | K17: 4 | L17: =I17/K17 -> 318 | M17: 45657 | N17: 45653 | P17: PASS | R17: 45610 | S17: 无 | T17: 条码贴和两国语言说明书翻订单4500148687 | U17: MA | V17: 产品内包装再加多一张2国语言电池说明书 | X17: 日期码格式：ZURU INC(BVI) 标准格式 日期：按实际生产日期 Packaging Info: 9548：MA-1L（含23L warning）包装配套 ,额外加一张条码贴覆盖ZURU条码 ，另外产品内包装再加多一张2国语言电池说明书 ，即产品内含2张说明书 （ZURU标准 说明书1张+2国语言电池说明书）；条码贴和两国语言说明书翻订单4500148687 1 assortment Remark: *MA版本按工厂现有最新库存即可，订单出英国，请注意检查产品及包装应带UKCA图标，包装显示ZURU UK LTD信息，QC同事请查核，如有问题与跟单确认。 *生产日期按实际（法定工作日），按ZURU标准格式即可 ，但是请知悉包装日期码需要早于或者等于外箱日期码 ，不能晚于外箱日期码 *请注意所有订单都需要经过ZURU QC验货并且通过后方可出货 *条码以订单显示为准 ，请安排生产前先核对 ，有问题请提出。 *所有产品按符合欧洲标准走货，需要是不含微塑料版本 。 *涉及到硼的，如可选择情况下应使用低硼版本 （slime 类别低硼一般低于300ppm)，无选择的应与跟单复核再安排 。 | Y17: Sherry Lu | Z17: 7.6175 | AA17: =Z17*I17 -> 9689.46 | AB17: 未出货 | AC17: 9548-S001 | AD17: 已入 | AE17: =I17*0.2 -> 254.4 | AK17: =I17 -> 1272 | AR17: =I17 -> 1272 | BA17: =I17 -> 1272 | BB17: =BB16+BA17 -> 751076
A18: 45614 | B18: TARGET US | C18: 美国 | D18: 4500151467 | E18: 10001064833-3890 | F18: 4500151467-10 | G18: 9548-S001 | H18: 鸭妈妈 | I18: 2016 | J18: 0 | K18: 4 | L18: =I18/K18 -> 504 | M18: 45657 | N18: 45653 | R18: 45625 | S18: 有 | T18: 12/6客供外箱贴纸 | U18: MA | X18: 日期码格式：ZURU INC(BVI) 标准格式 日期：按实际生产日期 Packaging Info: MA 1L包装(UPC版) Remark: 1. 9548-S001-PETS ALIVE - MAMA <(>&<)> BABY SURPRISE - SERIES 1 - MAMA DUCK -WINDOW BOX-4 PCS/CTN 2. MA 1L包装(UPC版), 产品彩盒上的UPC显示193052064196; 3. 外箱正唛左上角位置粘贴条码箱贴纸，每箱只贴一张，由ZURU订购。来料贴纸上显示的客户DPCI# 086-08-0304， UPC显示10193052064193; 4. 产品和包装上印刷 tracking code信息，格式为ZURU常规格式; 5. 出货方式：货代自提 | Y18: Holly Zheng | Z18: 7.2852 | AA18: =Z18*I18 -> 14686.963 | AC18: 9548-S001 | AD18: 已入 | AE18: =I18*0.2 -> 403.2 | AK18: =I18 -> 2016 | AS18: =I18 -> 2016 | BA18: =I18 -> 2016 | BB18: =BB17+BA18 -> 753092
A19: 45625 | B19: Smyths Toys HQ UC IE | C19: 爱尔兰 | D19: 4500153056 | E19: 4400452588 | F19: 4500153056-10 | G19: 9548-S001 | H19: 鸭妈妈 | I19: 1200 | J19: 0 | K19: 4 | L19: =I19/K19 -> 300 | M19: 45659 | N19: 45656 | R19: 45630 | S19: 无 | T19: 无 | U19: MA | X19: 日期码格式：ZURU INC(BVI) 标准格式 日期：按实际生产日期 Packaging Info: 1.9548: MA A 5L EAN版彩盒（23L warning） +MA 5L（9L Warning ）收藏指南+MA 2L 布标+MA5L（9L Warning）_A 胶袋 EAN#4894680033351请先检查条码是否正确再安排做货如有问题请告知 Remark: 1）包装日期码按ZURU格式即可，请确保不迟于外箱日期码，可等于或者早于外箱日期码，必须为法定工作日，印刷前请先检查外箱日期码。 2）订单出英国，请注意检查产品及包装应带UKCA图标（14+产品除外），包装显示ZURU UK LTD/ZURU France地址信息，QC部门请查核，如有问题与跟单确认 3) 需要符合欧洲标准不能含有闪粉和微塑料，否则不和法规会有客诉产生 | Y19: Amy Ding | Z19: 7.3075 | AA19: =Z19*I19 -> 8769 | AC19: 9548-S001-5L | AD19: 已入 | AE19: =I19*0.2 -> 240 | AO19: =I19 -> 1200 | AR19: =I19 -> 1200 | BA19: =I19 -> 1200 | BB19: =BB18+BA19 -> 754292
A20: 45604 | B20: Inventive Toys | C20: 俄罗斯联邦 | D20: 4500150836 | F20: 4500150836-30 | G20: 9548-S001 | H20: 鸭妈妈 | I20: 2108 | J20: 0 | K20: 4 | L20: =I20/K20 -> 527 | M20: 45660 | N20: 45656 | P20: PASS | R20: 45622 | S20: 无 | T20: 12/10进口商贴纸+EAN条码贴纸 | U20: MA | W20: 胶件/收缩膜/彩盒和外箱不需要ZURU 标准日期码 | X20: 日期码格式：外包装/外箱不要打ZURU标准日期码 日期： Packaging Info: 注意 ：外包装 (指: 收缩膜/彩卡/铝箔袋/挂卡/PDQ) /外箱不要打ZURU标准日期码！胶件可以打日期码。 外包装（包括收缩膜/彩卡/PDQ）都不能含Instagram and facebook logo等社交logo; 1L MA 收缩膜 或者彩卡+ 进口商贴纸； MA PDQ + EAN条码贴纸 ， MA指南/说明书（如有）; Remark: 标准配比 ；整单货期2025年1月3 | Y20: Ann Zhang | Z20: 7.5952 | AA20: =Z20*I20 -> 16010.682 | AB20: 94071-1.16 | AC20: 9548-S001 | AD20: 已入 | AE20: =I20*0.2 -> 421.6 | AK20: =I20 -> 2108 | AR20: =I20 -> 2108 | BA20: =I20 -> 2108 | BB20: =BB19+BA20 -> 756400
A21: 45621 | B21: FREDMEYER INC | C21: 美国 | D21: 4500152281 | E21: 000035894679 | F21: 4500152281-10 | G21: 9548-S001 | H21: 鸭妈妈 | I21: 1548 | J21: 0 | K21: 4 | L21: =I21/K21 -> 387 | M21: 45660 | N21: 45656 | P21: PASS | R21: 45621 | S21: 无 | T21: 无 | U21: MA | X21: 日期码格式：ZURU INC(BVI) 标准格式 日期：按实际生产日期 Packaging Info: 1、包装方式：MA UPC优先1L,出口美国 Remark: 2、无测试无验货要求。 3、纸箱4面印ZURU LOGO + 箱唛。 4、日期码请按ZURU标准版执行即可。 5、ZURU OQC验货 | Y21: Vicky Wu | Z21: 7.6175 | AA21: =Z21*I21 -> 11791.89 | AB21: 未出货 | AC21: 9548-S001 | AD21: 已入 | AE21: =I21*0.2 -> 309.6 | AK21: =I21 -> 1548 | AS21: =I21 -> 1548 | BA21: =I21 -> 1548 | BB21: =BB20+BA21 -> 757948
A22: 45632 | B22: KMART AUSTRALIA LTD | C22: 澳大利亚 | D22: 4500153425 | E22: 20549112 | F22: 4500153425-10 | G22: 9548-S001 | H22: 鸭妈妈 | I22: 2000 | J22: 0 | K22: 4 | L22: =I22/K22 -> 500 | M22: 45660 | N22: 45656 | P22: PASS | R22: 45602 | S22: 有 | T22: 外箱SSCC Label+1张防盗贴纸 (贴纸以及位置图翻单PO#4500126567） | U22: MA | X22: 日期码格式：ZURU INC(BVI) 标准格式 日期：按实际生产日期 Packaging Info: 9548: MA英语UPC版本包装（收缩膜和说明书, MA首选1L，如无1L可用多语且含英语的配套多语包装) + 1张防盗贴纸 (贴纸以及位置图翻单PO#4500126567）+ 箱唛 + 外箱SSCC Label Remark: 1.请务必按时完货，验货。并且按期送货入货代指定仓库，如果晚了导致船期Delay将会有罚金产生或者客户要求空运，所产生的罚金和空运费由工厂承担。 2.SSCC 外箱贴纸请同纸箱瓦楞纸方向（竖纹向）垂直，即外箱贴纸横着贴(注意条码不要被胶带粘住），贴1pc，贴1面正唛，封箱胶纸不能挡住贴纸内容。外箱贴纸 离外箱边距离不少于2cm。 3.外箱材质为ZURU标准； 4.此单需使用KMART封箱胶上下工字型封箱;从2019年6月开始，要用KMART 新版封箱胶带，此单要用"ANKO"封箱胶带 5.此单出口澳大利亚，请按相应的澳新标准生产； 6.产品和包装上生产批号的显示格式ZURU标准日期码格式 7.外箱信息不可手写，重量和体积需要与实际的一致(不可手写） 8. 每款item装箱后的G.W.超过10KG或者CBM超过0.13,(9.5KG或者以上，四舍五入后也属于10KG) 需在外箱上加印超 重或者Bulky LOGO，若发现我们资料没有，请 帮忙提醒 1)重量超过10kg但不超过16kg且CBM不超过0.13,10-16kg 超重logo 2）CBM超过0.13且重量少于17kg，bulky logo 3）不属于以上两种情况，需要使用相应重量范围内的超重logo 4）超重logo需要在外箱四面都印刷(箱唛右上角，两面侧唛超重logo需要尽量靠近毛重)，尺寸为:110mm height* 95mm width 9. 实际外箱重量跟印在箱唛上的数据差异不能超3%，尺寸按实际数据印刷 | Y22: Lydia Wu | Z22: 8.2534 | AA22: =Z22*I22 -> 16506.8 | AB22: 未出货 | AC22: 9548-S001 | AD22: 已入 | AE22: =I22*0.2 -> 400 | AK22: =I22 -> 2000 | AS22: =I22 -> 2000 | BA22: =I22 -> 2000 | BB22: =BB21+BA22 -> 759948
A23: 45616 | B23: COOLSHOP(ENTERTAINMENT TRADINGS APS | C23: 丹麦 | D23: 4500151829 | E23: 257441 | F23: 4500151829-50 | G23: 9548-S001-NB | H23: 鸭妈妈 | I23: 368 | J23: 0 | K23: 4 | L23: =I23/K23 -> 92 | M23: 45660 | N23: 45656 | R23: 45626 | S23: 无 | T23: 进口商贴纸+黑白电池说明书(瑞典/挪威/芬兰语翻译) | U23: MA | X23: 日期码格式：ZURU INC(BVI) 标准格式 日期：按实际生产日期 Packaging Info: 5.9548: MA EAN C 5L-23L warning 包装+进口商贴纸+MA B 5L-9L warning说明书+黑白电池说明书(瑞典/挪威/芬兰语翻译) Remark: 1. 包装如含PVC,请改为PET 2. 产品/包装要求无硼无香； 3. 出欧洲，微塑料需合规。 4.带电池出货的产品所用到的电池需要符合欧洲电池新规(EU) 2023-1542 5.关于贴纸，如果贴纸位置图的包装版本与大货不一致，请工厂提前提出。跟单会重新调整确认是否更新贴纸或调整位置图 6.产品/包装不含PFAS成分 7. 产品信息： 9548:3pcs AAA batteries(not included); Boron free Slime ;magnet(inside in the body of baby duck) 8.SKU-客户款号-条码 9548-1254070-4894680033351 | Y23: Sheba Ye | Z23: 7.6392 | AA23: =Z23*I23 -> 2811.2256 | AC23: 9548-S001-NB-5L | AD23: 已入 | AF23: =I23*0.2 -> 73.6 | AO23: =I23 -> 368 | AS23: =I23 -> 368 | BA23: =I23 -> 368 | BB23: =BB22+BA23 -> 760316
A24: 45624 | B24: WABRO | C24: 阿根廷 | D24: 4500152720 | F24: 4500152720-200 | G24: 9548-S001 | H24: 鸭妈妈 | I24: 600 | J24: 0 | K24: 4 | L24: =I24/K24 -> 150 | M24: 45663 | N24: 45659 | P24: PASS | R24: 45629 | S24: 无 | T24: 12/11进口商贴纸 | U24: MA | X24: 日期码格式：ZURU INC(BVI) 标准格式 日期：按实际生产日期 Packaging Info: 9548:MA 5L包装+MA 5L说明书+进口商贴纸+箱唛 | Y24: Ava Liang | Z24: 7.6175 | AA24: =I24*Z24 -> 4570.5 | AC24: 9548-S001-5L | AD24: 已入 | AE24: 300 | AO24: =I24 -> 600 | AS24: =I24 -> 600 | BA24: =I24 -> 600 | BB24: =BB23+BA24 -> 760916
A25: 45617 | B25: TARGET US | C25: 美国 | D25: 4500151907 | E25: 10001053759-3890 | F25: 4500151907-20 | G25: 9548-S001 | H25: 鸭妈妈 | I25: 1168 | J25: 0 | K25: 4 | L25: =I25/K25 -> 292 | M25: 45663 | N25: 45659 | P25: PASS | R25: 45628 | S25: 有 | T25: 12/25客供外箱贴纸 | U25: MA | X25: 日期码格式：ZURU INC(BVI) 标准格式 日期：按实际生产日期 Packaging Info: 9548：MA 1L包装(UPC版) Remark: 9548： 1. 9548-S001-PETS ALIVE - MAMA <(>&<)> BABY SURPRISE - SERIES 1 - MAMA DUCK -WINDOW BOX-4 PCS/CTN 2. MA 1L包装(UPC版), 产品彩盒上的UPC显示193052064196; 3. 外箱正唛左上角位置粘贴条码箱贴纸，每箱只贴一张，由ZURU订购。来料贴纸上显示的客户DPCI# 086-08-0304， UPC显示10193052064193; 4. 产品和包装上印刷 tracking code信息，格式为ZURU常规格式; 5. 出货方式：货代自提 | Y25: Holly Zheng | Z25: 7.3075 | AA25: =Z25*I25 -> 8535.16 | AC25: 9548-S001 | AD25: 已入 | AE25: =I25*0.2 -> 233.6 | AK25: =I25 -> 1168 | AS25: =I25 -> 1168 | BA25: =I25 -> 1168 | BB25: =BB24+BA25 -> 762084
A26: 45617 | B26: TARGET US | C26: 美国 | D26: 4500151906 | E26: 10001053693-3891 | F26: 4500151906-20 | G26: 9548-S001 | H26: 鸭妈妈 | I26: 848 | J26: 0 | K26: 4 | L26: =I26/K26 -> 212 | M26: 45663 | N26: 45659 | P26: PASS | R26: 45628 | S26: 有 | T26: 12/25客供外箱贴纸 | U26: MA | X26: 日期码格式：ZURU INC(BVI) 标准格式 日期：按实际生产日期 Packaging Info: 9548：MA 1L包装(UPC版) Remark: 9548： 1. 9548-S001-PETS ALIVE - MAMA <(>&<)> BABY SURPRISE - SERIES 1 - MAMA DUCK -WINDOW BOX-4 PCS/CTN 2. MA 1L包装(UPC版), 产品彩盒上的UPC显示193052064196; 3. 外箱正唛左上角位置粘贴条码箱贴纸，每箱只贴一张，由ZURU订购。来料贴纸上显示的客户DPCI# 086-08-0304， UPC显示10193052064193; 4. 产品和包装上印刷 tracking code信息，格式为ZURU常规格式; 5. 出货方式：货代自提 | Y26: Holly Zheng | Z26: 7.3075 | AA26: 10961.25 | AB26: 94061-1.16 | AC26: 9548-S001 | AD26: 已入 | AE26: 300 | AK26: =I26 -> 848 | AS26: =I26 -> 848 | BA26: =I26 -> 848 | BB26: =BB25+BA26 -> 762932
A27: 45609 | B27: ROSS PROCUREMENT.INC | C27: 美国 | D27: 4500151215 | E27: 60194304 | F27: 4500151215-10 | G27: 9548-S001 | H27: 鸭妈妈 | I27: 1500 | J27: 0 | K27: 4 | L27: =I27/K27 -> 375 | M27: 45664 | N27: 45660 | P27: PASS | R27: 45610 | S27: 无 | T27: 12/2客供价格贴纸 | U27: MA | X27: 日期码格式： 标准格式 日期：按实际生产日期 Packaging Info: 1.ZURU MA UPC 现有版本包装 + 客供价格贴纸，出口美国 , 优先使用MA 1L 最新版本 。 Remark: 1.ZURU MA UPC 现有版本包装 + 客供价格贴纸，出口美国 , 优先使用MA 1L 最新版本 。 2.价格贴纸位于包装正面右下角，不挡住重要信息即可，可适当调整 ，价格贴纸由跟单提供。 3.标准日期码格式，产品和包装必须有日期码 。 4.同个产品同个货期不可出现不同的包装。 5. 跟单提供ROSS通用的箱唛模版，工厂按实际45 PO上客户PO/Item号/装箱数 提供箱唛排版来确认 | Y27: Minny Peng | Z27: 7.3075 | AA27: 10961.25 | AB27: 94103-1.18 | AC27: 9548-S001 | AD27: 已入 | AE27: 300 | AK27: =I27 -> 1500 | AS27: =I27 -> 1500 | BA27: =I27 -> 1500 | BB27: =BB26+BA27 -> 764432
A28: 45615 | B28: WAL-MART STORES INC. USA | C28: 美国 | D28: 4500151682 | E28: 0876497060 | F28: 4500151682-10 | G28: 9548SLB-S002 | H28: 鸭妈妈 （卡板装） | I28: 504 | J28: 1 | K28: 72 | L28: =I28/K28 -> 7 | M28: 45664 | N28: 45660 | P28: PASS | R28: 45373 | S28: 有 | T28: 客版布标贴纸+11/11客供RFID贴纸 | U28: MA | X28: 日期码格式：ZURU DGYYYYMMDD CHINA（日期避开周末和法定节假日即可） 日期：按实际生产日期 Packaging Info: 9548 1.包装信息：MA B版 UPC版 1L包装，MA 5L B版说明书，MA 5L B版口水胶袋，MA 2L C版车缝布标，客版布标贴纸，客供RFID贴纸（标贴位置严格按照我们签板的 位置图，不可擅自调整位置，贴纸不能有任何破损或折坏，不可淋湿）。 Remark: 2.外箱四面印刷RFID箱唛，正唛左前下角印刷ITF-14格式条码的艾利替代标箱唛，只印刷正唛一面，整个内容尺寸最小10*10cm，加印时需确保条形码能扫描出来，Z URU logo跟MADE IN CHINA四面右下角印刷，外箱印刷日期码，每个slip sheet上面贴一张10*10cm艾利替代标（工厂自行用不干胶打印）和一张普通贴纸（可A4纸 打印），slip sheet打印的普通贴纸的尺寸不能比艾利替代标小。 3.在产品上和包装上要有日期码（避开周末和节假日），以及要有MADE IN CHINA和ZURU字样。 4.产品如有扎带口要剪平，不能刮手。 5.此单以打卡板出货（18*4H=72cartons/72pcs/Slip Sheet） 6.此单需要第三方验货，请自行多备物料。 7.其它信息：3pcs*AAA battery not include。 | Y28: Sandy Xu | Z28: 23.842 | AA28: =Z28*L28 -> 166.894 | AB28: 94095-1.18 | AC28: 9548SLB-S002 | AD28: 已入 | AE28: =I28*0.2 -> 100.8 | AK28: =I28 -> 504 | AS28: =I28 -> 504 | AZ28: =I28/72 -> 7 | BA28: =I28 -> 504 | BB28: =BB27+BA28 -> 764936
A29: 45615 | B29: WAL-MART STORES INC. USA | C29: 美国 | D29: 4500151682 | E29: 0876497079 | F29: 4500151682-20 | G29: 9548SLB-S002 | H29: 鸭妈妈 （卡板装） | I29: 1152 | J29: 1 | K29: 72 | L29: =I29/K29 -> 16 | M29: 45664 | N29: 45660 | P29: PASS | R29: 45373 | S29: 有 | T29: 客版布标贴纸+11/11客供RFID贴纸 | U29: MA | X29: 日期码格式：ZURU DGYYYYMMDD CHINA（日期避开周末和法定节假日即可） 日期：按实际生产日期 Packaging Info: 9548 1.包装信息：MA B版 UPC版 1L包装，MA 5L B版说明书，MA 5L B版口水胶袋，MA 2L C版车缝布标，客版布标贴纸，客供RFID贴纸（标贴位置严格按照我们签板的 位置图，不可擅自调整位置，贴纸不能有任何破损或折坏，不可淋湿）。 Remark: 2.外箱四面印刷RFID箱唛，正唛左前下角印刷ITF-14格式条码的艾利替代标箱唛，只印刷正唛一面，整个内容尺寸最小10*10cm，加印时需确保条形码能扫描出来，Z URU logo跟MADE IN CHINA四面右下角印刷，外箱印刷日期码，每个slip sheet上面贴一张10*10cm艾利替代标（工厂自行用不干胶打印）和一张普通贴纸（可A4纸 打印），slip sheet打印的普通贴纸的尺寸不能比艾利替代标小。 3.在产品上和包装上要有日期码（避开周末和节假日），以及要有MADE IN CHINA和ZURU字样。 4.产品如有扎带口要剪平，不能刮手。 5.此单以打卡板出货（18*4H=72cartons/72pcs/Slip Sheet） 6.此单需要第三方验货，请自行多备物料。 7.其它信息：3pcs*AAA battery not include。 | Y29: Sandy Xu | Z29: 44.6867 | AA29: =Z29*L29 -> 714.9872 | AB29: 94138-1.21 | AC29: 9548SLB-S002 | AD29: 已入 | AE29: =I29*0.2 -> 230.4 | AK29: =I29 -> 1152 | AS29: =I29 -> 1152 | AZ29: =I29/72 -> 16 | BA29: =I29 -> 1152 | BB29: =BB28+BA29 -> 766088
A30: 45625 | B30: Smyths Toys HQ UC UK | C30: 英国 | D30: 4500153057 | E30: 4400452593 | F30: 4500153057-20 | G30: 9548-S001 | H30: 鸭妈妈 | I30: 1160 | J30: 0 | K30: 4 | L30: =I30/K30 -> 290 | M30: 45666 | N30: 45663 | P30: PASS | R30: 45630 | S30: 无 | T30: 无 | U30: MA | X30: 日期码格式：ZURU INC(BVI) 标准格式 日期：按实际生产日期 Packaging Info: 1.9548: MA A 5L EAN版彩盒（23L warning） +MA 5L（9L Warning ）收藏指南+MA 2L 布标+MA5L（9L Warning）_A 胶袋 EAN#4894680033351请先检查条码是否正确再安排做货如有问题请告知 | Y30: Amy Ding | Z30: 7.6175 | AA30: 10961.25 | AB30: 94098-1.18 | AC30: 9548-S001-5L | AD30: 已入 | AE30: 300 | AO30: =I30 -> 1160 | AS30: =I30 -> 1160 | BA30: =I30 -> 1160 | BB30: =BB29+BA30 -> 767248
A31: 45630 | B31: Smyths Toys HQ UC UK | C31: 爱尔兰英国 | D31: 4500153276 | E31: 4400453582 | F31: 4500153276-10 | G31: 9548-S001 | H31: 鸭妈妈 | I31: 4000 | J31: 0 | K31: 4 | L31: =I31/K31 -> 1000 | M31: 45666 | N31: 45663 | P31: PASS | R31: 45636 | S31: 无 | T31: 无 | U31: MA | X31: 日期码格式：ZURU INC(BVI) 标准格式 日期：按实际生产日期 Packaging Info: 9548: MA A 5L EAN版彩盒（23L warning） +MA 5L（9L Warning ）收藏指南+MA 2L 布标+MA5L（9L Warning）_A 胶袋 EAN#4894680033351请先检查条码是否正确再安排做货如有问题请告知 Remark: 1）包装日期码按ZURU格式即可，请确保不迟于外箱日期码，可等于或者早于外箱日期码，必须为法定工作日，印刷前请先检查外箱日期码。 2）订单出英国，请注意检查产品及包装应带UKCA图标（14+产品除外），包装显示ZURU UK LTD/ZURU France地址信息，QC部门请查核，如有问题与跟单确认 3) 需要符合欧洲标准不能含有闪粉和微塑料，否则不和法规会有客诉产生 | Y31: Amy Ding | Z31: 7.5952 | AA31: 10961.25 | AB31: 94117-1.20 | AC31: 9548-S001-5L | AD31: 已入 | AE31: 300 | AO31: =I31 -> 4000 | AS31: =I31 -> 4000 | BA31: =I31 -> 4000 | BB31: =BB30+BA31 -> 771248
A32: 45630 | B32: Smyths Toys HQ UC UK | C32: 爱尔兰英国 | D32: 4500153276 | E32: 4400453584 | F32: 4500153276-20 | G32: 9548-S001 | H32: 鸭妈妈 | I32: 1000 | J32: 0 | K32: 4 | L32: =I32/K32 -> 250 | M32: 45666 | N32: 45663 | P32: PASS | R32: 45636 | S32: 无 | T32: 无 | U32: MA | X32: 日期码格式：ZURU INC(BVI) 标准格式 日期：按实际生产日期 Packaging Info: 9548: MA A 5L EAN版彩盒（23L warning） +MA 5L（9L Warning ）收藏指南+MA 2L 布标+MA5L（9L Warning）_A 胶袋 EAN#4894680033351请先检查条码是否正确再安排做货如有问题请告知 Remark: 1）包装日期码按ZURU格式即可，请确保不迟于外箱日期码，可等于或者早于外箱日期码，必须为法定工作日，印刷前请先检查外箱日期码。 2）订单出英国，请注意检查产品及包装应带UKCA图标（14+产品除外），包装显示ZURU UK LTD/ZURU France地址信息，QC部门请查核，如有问题与跟单确认 3) 需要符合欧洲标准不能含有闪粉和微塑料，否则不和法规会有客诉产生 | Y32: Amy Ding | Z32: 7.6175 | AA32: 10961.25 | AC32: 9548-S001-5L | AD32: 已入 | AE32: 300 | AO32: =I32 -> 1000 | AS32: =I32 -> 1000 | BA32: =I32 -> 1000 | BB32: =BB31+BA32 -> 772248
A33: 45631 | B33: Ambiental Paraguay | C33: 巴拉圭 | D33: 4500153347 | F33: 4500153347-60 | G33: 9548-S001 | H33: 鸭妈妈 | I33: 300 | J33: 0 | K33: 4 | L33: =I33/K33 -> 75 | M33: 45667 | N33: 45663 | P33: PASS | R33: 45631 | S33: 无 | U33: MA | X33: 日期码格式：ZURU INC(BVI) 标准格式 日期：按实际生产日期 Packaging Info: 9548:MA 1L包装+MA5L 说明书+客户贴纸+箱唛,进口商贴于位置"A" | Y33: Ava Liang | Z33: 7.6392 | AA33: =Z33*I33 -> 2291.76 | AB33: 94049-1.15 | AC33: 9548-S001 | AD33: 已入 | AE33: =I33*0.2 -> 60 | AK33: =I33 -> 300 | AR33: =I33 -> 300 | BA33: =I33 -> 300 | BB33: =BB32+BA33 -> 772548
A34: 45632 | B34: KMART AUSTRALIA LTD | C34: 澳大利亚 | D34: 4500153426 | E34: 20549113 | F34: 4500153426-10 | G34: 9548-S001 | H34: 鸭妈妈 | I34: 2000 | J34: 0 | K34: 4 | L34: =I34/K34 -> 500 | M34: 45667 | N34: 45663 | P34: PASS | R34: 45632 | S34: 有 | T34: 外箱SSCC Label+1张防盗贴纸 (贴纸以及位置图翻单PO#4500126567） | U34: MA | X34: 日期码格式：ZURU INC(BVI) 标准格式 日期：按实际生产日期 Packaging Info: 9548: MA英语UPC版本包装（收缩膜和说明书, MA首选1L，如无1L可用多语且含英语的配套多语包装) + 1张防盗贴纸 (贴纸以及位置图翻单PO#4500126567）+ 箱唛 + 外箱SSCC Label Remark: 1.请务必按时完货，验货。并且按期送货入货代指定仓库，如果晚了导致船期Delay将会有罚金产生或者客户要求空运，所产生的罚金和空运费由工厂承担。 2.SSCC 外箱贴纸请同纸箱瓦楞纸方向（竖纹向）垂直，即外箱贴纸横着贴(注意条码不要被胶带粘住），贴1pc，贴1面正唛，封箱胶纸不能挡住贴纸内容。外箱贴纸 离外箱边距离不少于2cm。 3.外箱材质为ZURU标准； 4.此单需使用KMART封箱胶上下工字型封箱;从2019年6月开始，要用KMART 新版封箱胶带，此单要用"ANKO"封箱胶带 5.此单出口澳大利亚，请按相应的澳新标准生产； 6.产品和包装上生产批号的显示格式ZURU标准日期码格式 7.外箱信息不可手写，重量和体积需要与实际的一致(不可手写） 8. 每款item装箱后的G.W.超过10KG或者CBM超过0.13,(9.5KG或者以上，四舍五入后也属于10KG) 需在外箱上加印超 重或者Bulky LOGO，若发现我们资料没有，请 帮忙提醒 1)重量超过10kg但不超过16kg且CBM不超过0.13,10-16kg 超重logo 2）CBM超过0.13且重量少于17kg，bulky logo 3）不属于以上两种情况，需要使用相应重量范围内的超重logo 4）超重logo需要在外箱四面都印刷(箱唛右上角，两面侧唛超重logo需要尽量靠近毛重)，尺寸为:110mm height* 95mm width 9. 实际外箱重量跟印在箱唛上的数据差异不能超3%，尺寸按实际数据印刷 | Y34: Lydia Wu | Z34: 8.2534 | AA34: =Z34*I34 -> 16506.8 | AC34: 9548-S001 | AD34: 已入 | AE34: =I34*0.2 -> 400 | AK34: =I34 -> 2000 | AS34: =I34 -> 2000 | BA34: =I34 -> 2000 | BB34: =BB33+BA34 -> 774548
A35: 45631 | B35: ALL BRANDS TOYS PTY LTD | C35: 澳大利亚 | D35: 4500153356 | E35: 83275 | F35: 4500153356-10 | G35: 9548-S001 | H35: 鸭妈妈 | I35: 720 | J35: 0 | K35: 4 | L35: =I35/K35 -> 180 | M35: 45667 | N35: 45663 | P35: PASS | R35: 45631 | S35: 无 | T35: 客人通用进口商贴纸+贴纸翻单4500125432 | U35: MA | X35: 日期码格式：ZURU INC(BVI) 标准格式 日期：按实际生产日期 Packaging Info: 9548:英文MA包装UPC版本（首选1L, 如无1L可选多语含英语）+客人通用进口商贴纸+箱唛，贴纸翻单4500125432 Remark: 1.按实际生产日期; 2.出澳大利亚，请按照相应标准生产; | Y35: Lydia Wu | Z35: 7.6175 | AA35: =Z35*I35 -> 5484.6 | AB35: 94039-1.15 | AC35: 9548-S001 | AD35: 已入 | AE35: =I35*0.2 -> 144 | AK35: =I35 -> 720 | AS35: =I35 -> 720 | BA35: =I35 -> 720 | BB35: =BB34+BA35 -> 775268
A36: 45629 | B36: APOLLO D.O.O. | C36: 斯洛文尼亚 | D36: 4500153179 | F36: 4500153179-20 | G36: 9548-S001 | H36: 鸭妈妈 | I36: 440 | J36: 0 | K36: 4 | L36: =I36/K36 -> 110 | M36: 45667 | N36: 45663 | R36: 45629 | S36: 无 | T36: 12/11UPC条码+进口商贴纸+客版说明书资料 | U36: MA | V36: 客版指南(翻4500126983) | X36: 日期码格式：ZURU INC(BVI) 标准格式 日期：按实际生产日期 Packaging Info: 9548: MA最新包装含UPC条码; 进口商贴纸+客版指南(翻4500126983) Remark: 此单出欧洲斯洛文尼亚， 需满足EU测试标准要求，不能含微塑料，需出无闪粉版本 9548:3pcs AAA batteries(not included) | Y36: Sharon | Z36: 7.6392 | AA36: =Z36*I36 -> 3361.248 | AB36: 94148-1.22 | AC36: 9548-S001-客版斯洛文尼亚 | AD36: 已入 | AE36: 300 | AK36: =I36 -> 440 | AU36: =I36 -> 440 | BA36: =I36 -> 440 | BB36: =BB46+BA36 -> 753840
A37: 45523 | B37: DM LLC | C37: 俄罗斯 | D37: 4500143263 | E37: 出Bekasovo 2 | F37: 4500143263-20 | G37: 9548-S001 | H37: 鸭妈妈 | I37: 460 | J37: 0 | K37: 4 | L37: =I37/K37 -> 115 | M37: 45667 | N37: 45663 | P37: PASS | R37: 45594 | S37: 无 | T37: 进口商贴纸（翻4500143236）+EAN条码贴纸（翻4500143236） | U37: MA | W37: 外包装(指: 收缩膜/彩卡/吊牌/PDQ)/外箱不要打ZURU标准日期码！ | X37: 日期码格式：注意:外包装(指: 收缩膜/彩卡/吊牌/PDQ)/外箱不要打ZURU标准日期码！ 日期： Packaging Info: 出Bekasovo 2 和Ural 2 个港口； LC 货期不可延期有罚款 ； 1.9548： 1L MA 收缩膜 or 彩卡+进口商贴纸（翻4500143236）+EAN条码贴纸（翻4500143236）; MA 说明书/指南（如有）; 注意 ：外包装 (指: 收缩膜/彩卡/吊牌/PDQ) /外箱不要打ZURU标准日期码！ Remark: 标准配比 | Y37: Ann Zhang | Z37: 7.6175 | AA37: =Z37*I37 -> 3504.05 | AB37: 94706-4.7 | AC37: 9548-S001 | AD37: 已入 | AE37: =I37*0.2 -> 92 | AK37: =I37 -> 460 | AS37: =I37 -> 460 | BA37: =I37 -> 460 | BB37: =BB13+BA37 -> 742312
A38: 45523 | B38: DM LLC | C38: 俄罗斯 | D38: 4500143263 | E38: 出Ural | F38: 4500143263-50 | G38: 9548-S001 | H38: 鸭妈妈 | I38: 224 | J38: 0 | K38: 4 | L38: =I38/K38 -> 56 | M38: 45667 | N38: 45663 | P38: PASS | R38: 45594 | S38: 无 | T38: 进口商贴纸（翻4500143236）+EAN条码贴纸（翻4500143236） | U38: MA | W38: 外包装(指: 收缩膜/彩卡/吊牌/PDQ)/外箱不要打ZURU标准日期码！ | X38: 日期码格式：注意:外包装(指: 收缩膜/彩卡/吊牌/PDQ)/外箱不要打ZURU标准日期码！ 日期： Packaging Info: 出Bekasovo 2 和Ural 2 个港口； LC 货期不可延期有罚款 ； 1.9548： 1L MA 收缩膜 or 彩卡+进口商贴纸（翻4500143236）+EAN条码贴纸（翻4500143236）; MA 说明书/指南（如有）; 注意 ：外包装 (指: 收缩膜/彩卡/吊牌/PDQ) /外箱不要打ZURU标准日期码！ Remark: 标准配比 | Y38: Ann Zhang | Z38: 7.6175 | AA38: =Z38*I38 -> 1706.32 | AB38: 94706-4.7 | AC38: 9548-S001 | AD38: 已入 | AE38: =I38*0.2 -> 44.8 | AK38: =I38 -> 224 | AS38: =I38 -> 224 | BA38: =I38 -> 224 | BB38: =BB37+BA38 -> 742536
A39: 45607 | B39: ZURU France | C39: 法国 | D39: 4500149708 | E39: 5200005612 | F39: 4500149708-40 | G39: 9548-S005-NB-MTS | H39: 鸭妈妈 | I39: 552 | J39: 0 | K39: 3 | L39: =I39/K39 -> 184 | M39: 45670 | N39: 45666 | P39: PASS | R39: 45635 | S39: 无 | T39: 无 | U39: MA | X39: 日期码格式：ZURU INC(BVI) 标准格式 日期：按实际生产日期 Packaging Info: 3.9548:最新MA 5L EAN彩卡+最新MA5L说明书+MA5L袋子+MA2L布标 Remark: 1.法国国家内销单，需要通过ZURU 验货结果后才能出货 (工厂需要主动提前同ZURU QC预约验货避免延期出货造成不必要麻烦)； 2.本订单所有 具有 baby items / assorted items 的款式，零售包装上都要用 母 EAN; 3. 若有特定款有特殊外箱条码要求时,需要明确列出产品款对应的具体外箱条码号码/条码类型 (若无,可以忽略此需求) 4. 所有出口欧洲的产品, 法规规定禁止在包装和共公众用的印刷品中使用矿物油中含有的物质, 包装印刷油墨中含有的MOAH/MOSH的质量浓度不能超过1%, 否则出 货到法国被抽检出现问题, 供应商需要对此负责; 5. date code: 外箱/产品/包装 保持一致，完货后提供date code 信息以便我们保存记录做批次管理; 6. 装柜时需要按照款式号码从小到大一款款依次装,避免终端仓库卸货混乱.若一个柜子涉及到几个不同国家内销单,装柜时需要一个国家装完后再装另一个国家的 产品,依次装柜,避免终端仓库因不同国家不同库位位置卸货混乱. (此点需要同工厂装柜人员强调) | Y39: Jade Wang | Z39: 7.5194 | AA39: =Z39*I39 -> 4150.7088 | AB39: 94099-1.18 | AC39: 9548-S005-NB-MTS | AD39: 已入 | AE39: =I39*0.2 -> 110.4 | AF39: =I39 -> 552 | AO39: =I39 -> 552 | AS39: =I39 -> 552 | BA39: =I39 -> 552 | BB39: =BB38+BA39 -> 743088
A40: 45637 | B40: MTA Trade | C40: 哈萨克斯坦 | D40: 4500153567 | F40: 4500153567-10 | G40: 9548-S001 | H40: 鸭妈妈 | I40: 280 | J40: 0 | K40: 4 | L40: =I40/K40 -> 70 | M40: 45670 | N40: 45666 | P40: PASS | R40: 45639 | S40: 无 | T40: 12/13进口商贴纸 | U40: MA | X40: 日期码格式：ZURU INC(BVI) 标准格式 日期：按实际生产日期 Packaging Info: 9548：1L MA UPC 彩卡+进口商贴纸, MA说明书/指南（如有） Remark: 标准配比 | Y40: Ann Zhang | Z40: 7.3292 | AA40: =Z40*I40 -> 2052.176 | AC40: 9548-S001 | AD40: 已入 | AE40: =I40*0.2 -> 56 | AK40: =I40 -> 280 | AS40: =I40 -> 280 | BA40: =I40 -> 280 | BB40: =BB39+BA40 -> 743368
...

Sheet MA
B2: 9548鸭妈妈 IC MA
B3: 日期 | C3: MA订单号码 | D3: ITEM | E3: 名称 | F3: MA数量 | G3: 要求交货日期 | H3: IC 供应商 | I3: IC编号 | J3: 备注
A4: 46079 | B4: TJX CANADA | C4: 加拿大 | D4: 9548-S001-NB | E4: 40320898 | F4: 720 | G4: 新布标格式 | H4: 30000 | I4: 46052 | J4: 日期码格式：标准格式 日期：按实际生产日期 92125 MA 多语EAN版本+UPC贴纸193052083951 77731 英法客版铜版纸，upc 193052085115, MA 2L 收缩膜 多语多明书 25251 英法客版包装 UPC 845218016418 翻单4500166055 25252 客版英法彩盒和说明书。UPC号码845218016425 25253 英法客版 UPC 845218016432，彩盒翻单4500158924，说明书翻单4500166055 7153 英法客版包装 翻单4500131680， 7149 UPC193052033499 7150UPC 193052033406 MA 多语说明书 92119 无硼版本 MA 3L B 版收缩膜 +UPC 贴纸 UPC 193052078391， B 版5L 收藏指南 9258 无硼版本 MA 3L B 版收缩膜 UPC 5L多语言收藏指南193052037640 9296 无硼版本 MA 3L 收缩膜+ 多语说明书 ， UPC 193052057129 9298 无硼版本 MA C 版3L 收缩膜 +UPC 贴纸 UPC 193052057426， B 版5L 收藏指南 9548 无硼版本 MA D 版本 5L 包装+D 版本 5L 收藏指南 +UPC 贴纸 UPC 193052064196 出加拿大 有客供价格贴 每行对应不同的客户PO，唛头要一一对应， 放唛头时跟单会提供清单 Zuru验货.日期跟踪码：产品外包装及产品本身都必须有日期跟踪码，ZURU标准格式 日期码 | M4: 46135
A5: 46079 | B5: TJX CANADA | C5: 加拿大 | D5: 9548-S001-NB | E5: 布料MA | F5: 180 | G5: 新布标格式 | H5: 30000 | I5: 46052 | J5: 日期码格式：标准格式 日期：按实际生产日期 92125 MA 多语EAN版本+UPC贴纸193052083951 77731 英法客版铜版纸，upc 193052085115, MA 2L 收缩膜 多语多明书 25251 英法客版包装 UPC 845218016418 翻单4500166055 25252 客版英法彩盒和说明书。UPC号码845218016425 25253 英法客版 UPC 845218016432，彩盒翻单4500158924，说明书翻单4500166055 7153 英法客版包装 翻单4500131680， 7149 UPC193052033499 7150UPC 193052033406 MA 多语说明书 92119 无硼版本 MA 3L B 版收缩膜 +UPC 贴纸 UPC 193052078391， B 版5L 收藏指南 9258 无硼版本 MA 3L B 版收缩膜 UPC 5L多语言收藏指南193052037640 9296 无硼版本 MA 3L 收缩膜+ 多语说明书 ， UPC 193052057129 9298 无硼版本 MA C 版3L 收缩膜 +UPC 贴纸 UPC 193052057426， B 版5L 收藏指南 9548 无硼版本 MA D 版本 5L 包装+D 版本 5L 收藏指南 +UPC 贴纸 UPC 193052064196 出加拿大 有客供价格贴 每行对应不同的客户PO，唛头要一一对应， 放唛头时跟单会提供清单 Zuru验货.日期跟踪码：产品外包装及产品本身都必须有日期跟踪码，ZURU标准格式 日期码 | M5: 46135
A6: 46079 | B6: TJX CANADA | C6: 加拿大 | D6: 9548-S001 | E6: 布料MA | F6: 296 | G6: 新布标格式 | H6: 30000 | I6: 46052 | J6: 日期码格式：标准格式 日期：按实际生产日期 92125 MA 多语EAN版本+UPC贴纸193052083951 77731 英法客版铜版纸，upc 193052085115, MA 2L 收缩膜 多语多明书 25251 英法客版包装 UPC 845218016418 翻单4500166055 25252 客版英法彩盒和说明书。UPC号码845218016425 25253 英法客版 UPC 845218016432，彩盒翻单4500158924，说明书翻单4500166055 7153 英法客版包装 翻单4500131680， 7149 UPC193052033499 7150UPC 193052033406 MA 多语说明书 92119 无硼版本 MA 3L B 版收缩膜 +UPC 贴纸 UPC 193052078391， B 版5L 收藏指南 9258 无硼版本 MA 3L B 版收缩膜 UPC 5L多语言收藏指南193052037640 9296 无硼版本 MA 3L 收缩膜+ 多语说明书 ， UPC 193052057129 9298 无硼版本 MA C 版3L 收缩膜 +UPC 贴纸 UPC 193052057426， B 版5L 收藏指南 9548 无硼版本 MA D 版本 5L 包装+D 版本 5L 收藏指南 +UPC 贴纸 UPC 193052064196 出加拿大 有客供价格贴 每行对应不同的客户PO，唛头要一一对应， 放唛头时跟单会提供清单 Zuru验货.日期跟踪码：产品外包装及产品本身都必须有日期跟踪码，ZURU标准格式 日期码 | M6: 46135
B7: 45229 | C7: MA_RR_988 | D7: 9548 | E7: IC | F7: 3000 | G7: 45239 | H7: 矽源特 | I7: CST2307019-6
B8: 45280 | C8: MA_RR_1039 | D8: 9548 | E8: IC | F8: 27000 | G8: 45290 | H8: 矽源特 | I8: CST2307019-6B
B9: 45286 | C9: MA_RR_1051 | D9: 9548 | E9: IC | F9: 30000 | G9: 45301 | H9: 矽源特 | I9: CST2307019-6B
B10: 45315 | C10: MA_RR_1074 | D10: 9548 | E10: IC | F10: 15000 | G10: 45350 | H10: 矽源特 | I10: CST2307019-6B
B11: 45350 | C11: MA_RR_1104 | D11: 9548 | E11: IC | F11: 25000 | G11: 45365 | H11: 矽源特 | I11: CST2307019-6B
B12: 45371 | C12: MA_RR_1126 | D12: 9548 | E12: IC | F12: 80000 | G12: 45385 | H12: 矽源特 | I12: CST2307019-6B
B13: 45385 | C13: MA_RR_1155 | D13: 9548 | E13: IC | F13: 80000 | G13: 45400 | H13: 矽源特 | I13: CST2307019-6B
B14: 45420 | C14: MA_RR_1199 | D14: 9548 | E14: IC | F14: 100000 | G14: 45435 | H14: 矽源特 | I14: CST2307019-6B
B15: 45427 | C15: MA_RR_1224 | D15: 9548 | E15: IC | F15: 160000 | G15: 45442 | H15: 矽源特 | I15: CST2307019-6B
B16: 45455 | C16: MA_RR_1259 | D16: 9548 | E16: IC | F16: 40000 | G16: 45485 | H16: 矽源特 | I16: CST2307019-6B
B17: 45483 | C17: MA_RR_1317 | D17: 9548 | E17: IC | F17: 40000 | G17: 45513 | H17: 矽源特 | I17: CST2307019-6B
B18: 45504 | C18: MA_RR_1339 | D18: 9548 | E18: IC | F18: 50000 | G18: 45534 | H18: 矽源特 | I18: CST2307019-6B
... B23: 45625 | C23: MA_RR_1464 | D23: 9548 | E23: IC | F23: 30000 | G23: 45635 | H23: 矽源特 | I23: CST2307019-6B
C24: MA_RR_1497 | D24: 9548 | E24: IC | F24: 50000 | G24: 45660 | H24: 矽源特 | I24: CST2307019-6B
B25: 45677 | C25: MA_RR_1526 | D25: 9548 | E25: IC | F25: 30000 | G25: 45701 | H25: 矽源特 | I25: CST2307019-6B
B26: 45714 | C26: MA_RR_1568 | D26: 9548 | E26: IC | F26: 50000 | G26: 45724 | H26: 矽源特 | I26: CST2307019-6B
B27: 45719 | C27: MA_RR_1581 | D27: 9548 | E27: IC | F27: 80000 | G27: 45729 | H27: 矽源特 | I27: CST2307019-6B
B28: 45742 | C28: MA_RR_1605 | D28: 9548 | E28: IC | F28: 40000 | G28: 45754 | H28: 矽源特 | I28: CST2307019-6B
B29: 45804 | C29: MA_RR_1699 | D29: 9548 | E29: IC | F29: 20000 | G29: 45816 | H29: 矽源特 | I29: CST2307019-6B
B30: 45835 | C30: MA_RR_1757 | D30: 9548 | E30: IC | F30: 60000 | G30: 45847 | H30: 矽源特 | I30: CST2307019-6B
B31: 45866 | C31: MA_RR_1812 | D31: 9548 | E31: IC | F31: 30000 | G31: 45878 | H31: 矽源特 | I31: CST2307019-6B
B32: 46031 | C32: MA_RR_2052 | D32: 9548 | E32: IC | F32: 60000 | G32: 46043 | H32: 矽源特 | I32: CST2307019-6B
E33: 合计 | F33: =SUM(F7:F32) -> 1330000
E34: 半成品MA数 | F34: =H68 -> 1240000
E35: 接单总数 | F35: ='9548明细'!AE427+I35 -> 217094.27 | H35: 2024年剩余数 | I35: 143286.27
E36: 按实单扣数的IC MA剩余 | F36: =F33-F35 -> 1112905.7
E37: 按半成品MA扣数的IC MA剩余 | F37: =F33-F34 -> 90000
B42: 9548鸭妈妈 半成品生产MA | K42: 口水胶 | L42: 无硼口水胶 | M42: 布料MA剩余： | N42: =H99-H68 -> 30000
B43: 日期 | C43: MA订单号码 | D43: ITEM | E43: 名称 | H43: 合计 | I43: 要求完成日期 | J43: 备注
B44: 45294 | C44: MA-RR-1054 | D44: 9548 | E44: MAMA & BABY SURPRISE - SERIES 1 - MAMA DUCK | H44: 30000 | I44: 45361 | K44: =21428*0.34286+8572*0.2 -> 9061.2041 | N44: 口水胶日期码4/18
B45: 45344 | C45: MA-RR-1088 | D45: 9548 | E45: MAMA & BABY SURPRISE - SERIES 1 - MAMA DUCK | H45: 30000 | I45: 45402 | J45: 新布标 | K45: =H45*0.2 -> 6000 | N45: 口水胶日期码4/26
B46: 45365 | D46: 9548 | L46: 10000 | M46: （300kg） | N46: 无硼 口水胶日期码4/30
B47: 45371 | C47: MA-RR-1124 | D47: 9548 | E47: MAMA & BABY SURPRISE - SERIES 1 - MAMA DUCK | H47: 60000 | I47: 45448 | J47: 新布标 | K47: =H47*0.2 -> 12000 | N47: 口水胶日期码5/6
B48: 45389 | C48: MA-RR-1143 | D48: 9548 | E48: MAMA & BABY SURPRISE - SERIES 1 - MAMA DUCK | H48: 60000 | I48: 45485 | J48: 生产5/2新日期码格式布标 | K48: =H48*0.2 -> 12000 | N48: 口水胶日期码5/30
B49: 45405 | C49: MA-RR-1179 | D49: 9548 | E49: MAMA & BABY SURPRISE - SERIES 1 - MAMA DUCK | H49: 80000 | I49: 45485 | J49: 生产5/25新日期码格式布标 | K49: =H49*0.2 -> 16000 | N49: 口水胶日期码5/30
...

Sheet 彩盒MA
B2: 9548 彩盒/说明书 MA
B3: 放MA日期 | C3: 名称 | D3: MA订单号码 | E3: 货号 | F3: 数量 | G3: 语言 | H3: 版本号 | I3: 1L 标准版彩盒A版 | J3: 1L 标准版彩盒B版 | K3: 5L 标准版彩盒A版 | L3: 5L 标准版彩盒B版 | M3: 1L标准版彩盒C版 | N3: 5L 标准版彩盒C版 | O3: 5L 标准版彩盒D版 | P3: 5L 说明书 | Q3: 5L 说明书 B版 | R3: 5L说明书 C版 | S3: 客版彩盒 | T3: 客版说明书 | U3: Endcap EC展架 | V3: SLD展示架
B4: 45359 | C4: Window Box+PET box 彩盒+透明盒 | D4: 1000018820 | E4: 9548 | F4: 30000 | G4: 1L+23L | H4: A | I4: 30000
B5: 45359 | C5: Instruction+Warning 说明书 | D5: 1000018821 | E5: 9548 | F5: 30000 | G5: 5L | H5: A | P5: 30000
B6: 45370 | C6: Window Box+PET box 彩盒+透明盒 | D6: 1000018994 | E6: 9548 | F6: 30000 | G6: 5L | H6: A | K6: 30000
B7: 45370 | C7: Window Box+PET box 彩盒+透明盒 | D7: 1000018995 | E7: 9548 | F7: 50000 | G7: 1L+23L | H7: A | I7: 50000
B8: 45370 | C8: Instruction+Warning 说明书 | D8: 1000018996 | E8: 9548 | F8: 100000 | G8: 5L | H8: A | P8: 100000
B9: 45384 | C9: BJ's new order PDQ | D9: 1000019290 | E9: 9548 | F9: 5728 | G9: 1L | H9: N/A | S9: 5728
B10: 45394 | C10: Endcap EC展架 | D10: 1000019556 | E10: 9548 | F10: 400 | G10: 3L | H10: A | U10: 400
B11: 45394 | C11: （4500125999）Instruction Sheet | D11: 1000019545 | E11: 9548 | F11: 3000 | G11: 芬兰 | H11: 客版 | T11: 3000 | W11: Luna用于4500126092-120pcs; 4500130794-700pcs; 4500131147-2256pcs;
B12: 45405 | C12: Window Box+PET box 彩盒+透明盒 | D12: 1000019769 | E12: 9548 | F12: 100000 | G12: 1L+23L | H12: A | I12: =F12 -> 100000
B13: 45405 | C13: Instruction+Warning 说明书 | D13: 1000019770 | E13: 9548 | F13: 80000 | G13: 5L | H13: A | P13: =F13 -> 80000
B14: 45425 | C14: Window Box+PET box 彩盒+透明盒 | D14: 1000020238 | E14: 9548 | F14: 60000 | G14: 1L+23L | H14: A | I14: =F14 -> 60000
B15: 45425 | C15: Window Box+PET box 彩盒+透明盒 | D15: 1000020239 | E15: 9548 | F15: 30000 | G15: 5L | H15: A | K15: =F15 -> 30000
B16: 45425 | C16: Instruction+Warning 说明书 | D16: 1000020240 | E16: 9548 | F16: 50000 | G16: 5L | H16: A | P16: =F16 -> 50000
B17: 45443 | C17: Window Box+PET box 彩盒+透明盒 | D17: 1000020666 | E17: 9548 | F17: 80000 | G17: 1L+23L | H17: A | I17: =F17 -> 80000
B18: 45443 | C18: Instruction+Warning 说明书 | D18: 1000020659 | E18: 9548 | F18: 80000 | G18: 5L | H18: A | P18: =F18 -> 80000
B19: 45447 | C19: （4500125999）Instruction Sheet | D19: 1000020745 | E19: 9548 | F19: 3460 | G19: 芬兰 | H19: 客版 | T19: =F19 -> 3460 | W19: Luna用于4500131331-360pcs; 4500131352-500pcs;4500131615-684pcs；4500129328-300pcs；4500132947-360pcs; 4500129340-556pcs;4500125999-300pcs 4500135130-120pcs 4500137072-120pcs 剩余用于后续订单：1100022520-84pcs
B20: 45467 | C20: Window Box+PET box 彩盒+透明盒 | D20: 1000021275 | E20: 9548 | F20: 50000 | G20: 1L+23L | H20: A | I20: =F20 -> 50000 | W20: 剩余700客版说明书125999
B21: 45467 | C21: Window Box+PET box 彩盒+透明盒 | D21: 1000021276 | E21: 9548 | F21: 30000 | G21: 5L | H21: B | L21: =F21 -> 30000
B22: 45467 | C22: Instruction+Warning 说明书 | D22: 1000021277 | E22: 9548 | F22: 80000 | G22: 5L | H22: A | P22: =F22 -> 80000
B23: 45496 | C23: （4500125999）Instruction Sheet | D23: 1000022060 | E23: 9548 | F23: 3000 | G23: 芬兰 | H23: 客版 | T23: =F23 -> 3000 | W23: Luna用于PO 4500140612(200PCS)+SOK PO4500139712(300pcs)，剩余数量后续订单消耗
B24: 45502 | C24: 中文版说明书 | D24: 1000022144 | E24: 9548 | F24: 3000 | G24: 中文 | H24: 客版 | T24: 3000 | W24: Dona用于订单4500140818
B25: 45503 | C25: Window Box+PET box 彩盒+透明盒 | D25: 1000022167 | E25: 9548 | F25: 100000 | G25: 1L+23L | H25: A | I25: =F25 -> 100000
B26: 45503 | C26: Window Box+PET box 彩盒+透明盒 | D26: 1000022168 | E26: 9548 | F26: 30000 | G26: 5L | H26: B | L26: =F26 -> 30000
B27: 45503 | C27: Instruction+Warning 说明书 | D27: 1000022169 | E27: 9548 | F27: 100000 | G27: 5L | H27: A | P27: =F27 -> 100000
B28: 45517 | C28: Window Box+PET box 彩盒+透明盒 | D28: 1000022482 | E28: 9548 | F28: 50000 | G28: 1L+23L | H28: A | I28: =F28 -> 50000
B29: 45517 | C29: Instruction+Warning 说明书 | D29: 1000022483 | E29: 9548 | F29: 100000 | G29: 5L | H29: A | P29: =F29 -> 100000
B30: 45558 | C30: Window Box+PET box 彩盒+透明盒 | D30: 1000023317 | E30: 9548 | F30: 20000 | G30: 1L+23L | H30: B | J30: =F30 -> 20000
B31: 45558 | C31: Window Box+PET box 彩盒+透明盒 | D31: 1000023318 | E31: 9548 | F31: 20000 | G31: 5L | H31: C | N31: =F31 -> 20000
B32: 45580 | C32: Window Box+PET box 彩盒+透明盒 | D32: 1000023697 | E32: 9548 | F32: 50000 | G32: 1L+23L | H32: B | I32: 10000 | J32: =F32-I32 -> 40000
B33: 45580 | C33: Instruction+Warning 说明书 | D33: 1000023698 | E33: 9548 | F33: 50000 | G33: 5L | H33: B | Q33: =F33 -> 50000
B34: 45604 | C34: Window Box+PET box 彩盒+透明盒 | D34: 1000024299 | E34: 9548 | F34: 50000 | G34: 1L+23L | H34: B | J34: 50000
B35: 45604 | C35: Instruction+Warning 说明书 | D35: 1000024300 | E35: 9548 | F35: 80000 | G35: 5L | H35: B | Q35: 80000
B36: 45631 | C36: Window Box+PET box 彩盒+透明盒 | D36: 1000024919 | E36: 9548 | F36: 60000 | G36: 1L+23L | H36: B | J36: 60000
B37: 45631 | C37: Window Box+PET box 彩盒+透明盒 | D37: 1000024920 | E37: 9548 | F37: 20000 | G37: 5L | H37: C | N37: 20000
B38: 45631 | C38: Instruction+Warning 说明书 | D38: 1000024922 | E38: 9548 | F38: 60000 | G38: 5L | H38: B | Q38: 60000
B39: 45673 | C39: Window Box+PET box彩盒+透明盒 | D39: 1000025575 | E39: 9548 | F39: 20000 | G39: 1L+23L | H39: B | J39: 20000
B40: 45673 | C40: Instruction+Warning说明书 | D40: 1000025576 | E40: 9548 | F40: 30000 | G40: 5L | H40: C | Q40: 30000
B41: 45734 | C41: Window Box+PET box 彩盒+透明盒 | D41: 1000026364 | E41: 9548 | F41: 30000 | G41: 5L | H41: C | N41: 30000
...

Sheet 取消单
A1: 接单期 | B1: 第三方客户名称 | C1: 走货国家 | D1: ZURU PO NO# | E1: 第三方客户 PO NO# | F1: SKU | G1: ITEM# | H1: 货品名称 | I1: PO数量(只) | J1: 内箱装箱数量(只) | K1: 外箱装箱数量(只) | L1: 总箱数 | M1: 计划出货期 | N1: 计划验货期 | O1: 第三方客户公证行验货 | P1: 验货结果 | Q1: ZURU确认走货日期 | R1: 箱唛(收到日期) | S1: 外箱贴纸 | T1: 客供贴纸资料(收到日期及订购日期) | U1: 客版资料 | V1: 备注 | W1: ZURU跟单组员 | X1: 单价USD | Y1: 金额USD | Z1: 发票号 | AA1: 系统货号 | AB1: 是否入系统 | AC1: 需求数 有硼 | AD1: 需求数 无硼 | AE1: 送货情况 | AF1: 贴纸情况 | AG1: 纸箱情况 | AH1: MA1语彩盒 | AI1: MA5语彩盒 | AJ1: 客版彩盒 | AK1: 5L 说明书 | AL1: 客版说明书 | AM1: 9548EC-S001 | AN1: 9548UQ1 客版PDQ | AO1: 9548SLB-S001 | AP1: 9548SLB-S002 | AQ1: 布标 | AR1: 合计数量 | AS1: 累计数量 | AT1: 新配比（口水胶） | AU1: MA数量 | AV1: 30000 | AW1: 30000 | AX1: 60000
A2: 45721 | B2: KMART AUSTRALIA LTD | C2: 澳大利亚 | D2: 4500159287 | E2: 20672972 | F2: 4500159287-20 | G2: 9548-S001 | H2: 鸭妈妈 | I2: 1500 | J2: 0 | K2: 4 | L2: 375 | M2: 3/13取消订单 | N2: 3/13取消订单 | R2: 45733 | S2: 有 | T2: 1张防盗贴纸 (贴纸以及位置图翻单PO#4500157612）+外箱SSCC Label | U2: MA | X2: 日期码格式：ZURU INC(BVI) 标准格式 日期：按实际生产日期 Packaging Info: 9561: MA英语UPC版本包装（收缩膜和说明书, MA首选1L，如无1L可用多语且含英语的配套多语包装) + 1张包装纽扣电池警告语贴纸 + 1张说明书纽扣电池警告语 贴纸 （贴纸及位置图翻单: PO#4500157612）+ 1张防盗贴纸+ 箱唛 + 外箱SSCC Label 配比信息：3pcs mini turtles: 4pcs mini tutles: 5pcs mini turtles= 87:10:3 9548: MA英语UPC版本包装（收缩膜和说明书, MA首选1L，如无1L可用多语且含英语的配套多语包装) + 1张防盗贴纸 (贴纸以及位置图翻单PO#4500126567）+ 箱唛 + 外箱SSCC Label Remark: 1.请务必按时完货，验货。并且按期送货入货代指定仓库，如果晚了导致船期Delay将会有罚金产生或者客户要求空运，所产生的罚金和空运费由工厂承担。 2.SSCC 外箱贴纸请同纸箱瓦楞纸方向（竖纹向）垂直，即外箱贴纸横着贴(注意条码不要被胶带粘住），贴1pc，贴1面正唛，封箱胶纸不能挡住贴纸内容。外箱贴纸 离外箱边距离不少于2cm。 3.外箱材质为ZURU标准； 4.此单需使用KMART封箱胶上下工字型封箱;从2019年6月开始，要用KMART 新版封箱胶带，此单要用"ANKO"封箱胶带 5.此单出口澳大利亚，请按相应的澳新标准生产； 6.产品和包装上生产批号的显示格式ZURU标准日期码格式 7.外箱信息不可手写，重量和体积需要与实际的一致(不可手写） 8. 每款item装箱后的G.W.超过10KG或者CBM超过0.13,(9.5KG或者以上，四舍五入后也属于10KG) 需在外箱上加印超 重或者Bulky LOGO，若发现我们资料没有，请 帮忙提醒 1)重量超过10kg但不超过16kg且CBM不超过0.13,10-16kg 超重logo 2）CBM超过0.13且重量少于17kg，bulky logo 3）不属于以上两种情况，需要使用相应重量范围内的超重logo 4）超重logo需要在外箱四面都印刷(箱唛右上角，两面侧唛超重logo需要尽量靠近毛重)，尺寸为:110mm height* 95mm width 9. 实际外箱重量跟印在箱唛上的数据差异不能超3%，尺寸按实际数据印刷 | Y2: Lydia Wu | Z2: 8.2757 | AA2: 12413.55 | AC2: 9548-S001 | AD2: 已入 | AE2: 300 | AF2: 1500 | AL2: 1500 | AS2: 1500 | AT2: 834976
A3: 45747 | B3: Mid-States Distributing, LLC | C3: 美国 | D3: 4500161570 | E3: Murdoch's Southern DC PO 671605134 | F3: 4500161570-190 | G3: 9548-S001 | H3: 鸭妈妈 | I3: 100 | J3: 0 | K3: 4 | L3: =I3/K3 -> 25 | M3: 45818 | N3: 45814 | O3: 暂停生产 | R3: 欠 | S3: 无 | T3: 无 | U3: MA | X3: 日期码格式：ZURU INC(BVI) 标准格式 日期：按实际生产日期 Packaging Info: 1.使用 MA UPC版本包装，优先1L，出口美国。 Remark: 1.产品和包装上印刷tracking code信息，格式为ZURU常规。 2.ZURU QC验货 | Y3: Cara Li | Z3: 8.1258 | AA3: =Z3*I3 -> 812.58 | AC3: 9548-S001 | AD3: 已入 | AE3: =I3*0.2 -> 20 | AK3: =I3 -> 100 | AQ3: =I3 -> 100 | AX3: =I3 -> 100 | AY3: ='9548明细'!BB90+AX3 -> 779952
A4: 45747 | B4: Mid-States Distributing, LLC | C4: 美国 | D4: 4500161570 | E4: Murdoch's TX DC PO 671605136 | F4: 4500161570-210 | G4: 9548-S001 | H4: 鸭妈妈 | I4: 40 | J4: 0 | K4: 4 | L4: =I4/K4 -> 10 | M4: 45818 | N4: 45814 | O4: 暂停生产 | R4: 欠 | S4: 无 | T4: 无 | U4: MA | X4: 日期码格式：ZURU INC(BVI) 标准格式 日期：按实际生产日期 Packaging Info: 1.使用 MA UPC版本包装，优先1L，出口美国。 Remark: 1.产品和包装上印刷tracking code信息，格式为ZURU常规。 2.ZURU QC验货 | Y4: Cara Li | Z4: 8.1258 | AA4: =Z4*I4 -> 325.032 | AC4: 9548-S001 | AD4: 已入 | AE4: =I4*0.2 -> 8 | AK4: =I4 -> 40 | AQ4: =I4 -> 40 | AX4: =I4 -> 40 | AY4: ='9548明细'!BB98+AX4 -> 783356
A5: 45747 | B5: Mid-States Distributing, LLC | C5: 美国 | D5: 4500161570 | E5: Murdoch's Norther DC PO 671605135 | F5: 4500161570-200 | G5: 9548-S001 | H5: 鸭妈妈 | I5: 76 | J5: 0 | K5: 4 | L5: =I5/K5 -> 19 | M5: 45818 | N5: 45814 | O5: 暂停生产 | R5: 欠 | S5: 无 | T5: 无 | U5: MA | X5: 日期码格式：ZURU INC(BVI) 标准格式 日期：按实际生产日期 Packaging Info: 1.使用 MA UPC版本包装，优先1L，出口美国。 Remark: 1.产品和包装上印刷tracking code信息，格式为ZURU常规。 2.ZURU QC验货 | Y5: Cara Li | Z5: 8.1258 | AA5: =Z5*I5 -> 617.5608 | AC5: 9548-S001 | AD5: 已入 | AE5: =I5*0.2 -> 15.2 | AK5: =I5 -> 76 | AQ5: =I5 -> 76 | AX5: =I5 -> 76 | AY5: ='9548明细'!BB97+AX5 -> 778592
A6: 45771 | B6: ZURU Germany GMBH | C6: 德国 | D6: 4500164783 | E6: 5200006663 | F6: 4500164783-100 | G6: 9548-S005-NB-MTS | H6: 鸭妈妈 | I6: 600 | J6: 0 | K6: 3 | L6: =I6/K6 -> 200 | M6: 45804 | N6: 45800 | R6: 45772 | S6: 无 | T6: WEEE 30L 带电说明书+1张意大利回 收贴纸（翻4500133324） | U6: MA | X6: 日期码格式：ZURU INC(BVI) 标准格式 日期：按实际生产日期 Packaging Info: 10.9548：MA 3L（23L warning）EAN彩盒+MA 5L（9L Warning ）收藏指南+黑白5L（PL+HU+CZ+SK+RO)说明书（翻4500133324）+WEEE 30L 带电说明书+1张意大利回 收贴纸（翻4500133324）+MA5L（9L Warning）胶袋+1*5L 黑白slime 说明书； Remark: 1.波兰内销单，需要通过ZURU 验货结果后才能出货 (工厂需要主动提前同ZURU QC预约验货避免延期出货造成不必要麻烦)； 2. 若有特定款有特殊外箱条码要求时,需要明确列出产品款对应的具体外箱条码号码/条码类型 (若无,可以忽略此需求) 3.所有出口欧洲的产品, 法规规定禁止在包装和共公众用的印刷品中使用矿物油中含有的物质, 包装印刷油墨中含有的MOAH/MOSH的质量浓度不能超过1%, 否则出货 到法国被抽检出现问题, 供应商需要对此负责; 4. date code: 外箱日期码要晚于或等于产品日期码，不能早于产品的日期码 5. 所有电子产品身上需要加字唛，为ZURU FRANCE 地址 (如无电子产品，或者产品布标有此地址，可忽略此信息) ZURU France 1/3, Rue d'Argenteuil 95210 SAINT-GRATIEN, FRANCE 6. 装柜时需要按照款式号码从小到大一款款依次装,避免终端仓库卸货混乱.若一个柜子涉及到几个不同国家内销单,装柜时需要一个国家装完后再装另一个国家的 产品,依次装柜,避免终端仓库因不同国家不同库位位置卸货混乱. (此点需要同工厂装柜人员强调) | Y6: Amy Xiao | Z6: 7.5194 | AA6: =Z6*I6 -> 4511.64 | AC6: 9548-S005-NB-MTS | AD6: 已入 | AN6: =I6 -> 600 | AQ6: =I6 -> 600 | AX6: =I6 -> 600 | AY6: ='9548明细'!BB137+AX6 -> 1784
A7: 45803 | B7: KMART AUSTRALIA LTD(NEW ZEALAND) | C7: 新西兰 | D7: 4500166290 | E7: 20858536 | F7: 4500166290-60 | G7: 9548-S001 | H7: 鸭妈妈 | I7: 44 | J7: 0 | K7: 4 | L7: =I7/K7 -> 11 | M7: 45845 | N7: 45841 | O7: 6.5取消 | U7: MA | X7: 日期码格式：ZURU INC(BVI) 标准格式 日期：按实际生产日期 Packaging Info: 9548: MA英语UPC版本包装（收缩膜和说明书, MA首选1L，如无1L可用多语且含英语的配套多语包装) + 1张防盗贴纸 (贴纸以及位置图翻单PO#4500126567）+ 箱唛 + 外箱SSCC Label Remark: 1.请务必按时完货，验货。并且按期送货入货代指定仓库，如果晚了导致船期Delay将会有罚金产生或者客户要求空运，所产生的罚金和空运费由工厂承担。 2.SSCC 外箱贴纸请同纸箱瓦楞纸方向（竖纹向）垂直，即外箱贴纸横着贴(注意条码不要被胶带粘住），贴1pc，贴1面正唛，封箱胶纸不能挡住贴纸内容。外箱贴纸 离外箱边距离不少于2cm。 3.外箱材质为ZURU标准； 4.此单需使用KMART封箱胶上下工字型封箱;从2019年6月开始，要用KMART 新版封箱胶带，此单要用"ANKO"封箱胶带 5.此单出口新西兰，请按相应的澳新标准生产； 6.产品和包装上生产批号的显示格式ZURU标准日期码格式 7.外箱信息不可手写，重量和体积需要与实际的一致(不可手写） 8. 每款item装箱后的G.W.超过10KG或者CBM超过0.13,(9.5KG或者以上，四舍五入后也属于10KG) 需在外箱上加印超 重或者Bulky LOGO，若发现我们资料没有，请 帮忙提醒 1)重量超过10kg但不超过16kg且CBM不超过0.13,10-16kg 超重logo 2）CBM超过0.13且重量少于17kg，bulky logo 3）不属于以上两种情况，需要使用相应重量范围内的超重logo 4）超重logo需要在外箱四面都印刷(箱唛右上角，两面侧唛超重logo需要尽量靠近毛重)，尺寸为:110mm height* 95mm width 9. 实际外箱重量跟印在箱唛上的数据差异不能超3%，尺寸按实际数据印刷 | Y7: Lydia Wu | Z7: 8.1258 | AA7: =Z7*I7 -> 357.5352 | AE7: =I7*0.2 -> 8.8 | AZ7: =I7 -> 44 | BA7: ='9548明细'!BB182+AZ7 -> 795764
A8: 45803 | B8: KMART AUSTRALIA LTD | C8: 澳大利亚 | D8: 4500166289 | E8: 20858535 | F8: 4500166289-70 | G8: 9548-S001 | H8: 鸭妈妈 | I8: 1456 | J8: 0 | K8: 4 | L8: =I8/K8 -> 364 | M8: 45845 | N8: 45841 | O8: 取消 | U8: MA | X8: 日期码格式：ZURU INC(BVI) 标准格式 日期：按实际生产日期 Packaging Info: 9548: MA英语UPC版本包装（收缩膜和说明书, MA首选1L，如无1L可用多语且含英语的配套多语包装) + 1张防盗贴纸 (贴纸以及位置图翻单PO#4500126567）+ 箱唛 + 外箱SSCC Label Remark: 1.请务必按时完货，验货。并且按期送货入货代指定仓库，如果晚了导致船期Delay将会有罚金产生或者客户要求空运，所产生的罚金和空运费由工厂承担。 2.SSCC 外箱贴纸请同纸箱瓦楞纸方向（竖纹向）垂直，即外箱贴纸横着贴(注意条码不要被胶带粘住），贴1pc，贴1面正唛，封箱胶纸不能挡住贴纸内容。外箱贴纸 离外箱边距离不少于2cm。 3.外箱材质为ZURU标准； 4.此单需使用KMART封箱胶上下工字型封箱;从2019年6月开始，要用KMART 新版封箱胶带，此单要用"ANKO"封箱胶带 5.此单出口澳大利亚，请按相应的澳新标准生产； 6.产品和包装上生产批号的显示格式ZURU标准日期码格式 7.外箱信息不可手写，重量和体积需要与实际的一致(不可手写） 8. 每款item装箱后的G.W.超过10KG或者CBM超过0.13,(9.5KG或者以上，四舍五入后也属于10KG) 需在外箱上加印超 重或者Bulky LOGO，若发现我们资料没有，请 帮忙提醒 1)重量超过10kg但不超过16kg且CBM不超过0.13,10-16kg 超重logo 2）CBM超过0.13且重量少于17kg，bulky logo 3）不属于以上两种情况，需要使用相应重量范围内的超重logo 4）超重logo需要在外箱四面都印刷(箱唛右上角，两面侧唛超重logo需要尽量靠近毛重)，尺寸为:110mm height* 95mm width 9. 实际外箱重量跟印在箱唛上的数据差异不能超3%，尺寸按实际数据印刷 | Y8: Lydia Wu | Z8: 8.1045 | AA8: =Z8*I8 -> 11800.152 | AE8: =I8*0.2 -> 291.2 | AZ8: =I8 -> 1456 | BA8: ='9548明细'!BB145+AZ8 -> 787600
A9: 45912 | B9: KMART AUSTRALIA LTD(NEW ZEALAND) | C9: 新西兰 | D9: 4500179341 | E9: 21105434 | F9: 4500179341-70 | G9: 9548-S001 | H9: 鸭妈妈 | I9: 48 | J9: 0 | K9: 4 | L9: =I9/K9 -> 12 | M9: 45957 | N9: 45953 | U9: MA | X9: 日期码格式：ZURU INC(BVI) 标准格式 日期：按实际生产日期 Packaging Info: 9548: MA英语UPC版本包装（收缩膜和说明书, MA首选1L，如无1L可用多语且含英语的配套多语包装) + 1张防盗贴纸 (贴纸以及位置图翻单PO#4500126567）+ 箱唛 + 外箱SSCC Label Remark: 1.请务必按时完货，验货。并且按期送货入货代指定仓库，如果晚了导致船期Delay将会有罚金产生或者客户要求空运，所产生的罚金和空运费由工厂承担。 2.SSCC 外箱贴纸请同纸箱瓦楞纸方向（竖纹向）垂直，即外箱贴纸横着贴(注意条码不要被胶带粘住），贴1pc，贴1面正唛，封箱胶纸不能挡住贴纸内容。外箱贴纸 离外箱边距离不少于2cm。 3.外箱材质为ZURU标准； 4.此单需使用KMART封箱胶上下工字型封箱;从2019年6月开始，要用KMART 新版封箱胶带，此单要用"ANKO"封箱胶带 5.此单出口新西兰，请按相应的澳新标准生产； 6.产品和包装上生产批号的显示格式ZURU标准日期码格式 7.外箱信息不可手写，重量和体积需要与实际的一致(不可手写） 8. 每款item装箱后的G.W.超过10KG或者CBM超过0.13,(9.5KG或者以上，四舍五入后也属于10KG) 需在外箱上加印超 重或者Bulky LOGO，若发现我们资料没有，请 帮忙提醒 1)重量超过10kg但不超过16kg且CBM不超过0.13,10-16kg 超重logo 2）CBM超过0.13且重量少于17kg，bulky logo 3）不属于以上两种情况，需要使用相应重量范围内的超重logo 4）超重logo需要在外箱四面都印刷(箱唛右上角，两面侧唛超重logo需要尽量靠近毛重)，尺寸为:110mm height* 95mm width 9. 实际外箱重量跟印在箱唛上的数据差异不能超3%，尺寸按实际数据印刷 | Y9: Lydia Wu | Z9: 8.1258 | AA9: =Z9*I9 -> 390.0384 | BA9: =I9 -> 48 | BB9: ='9548明细'!BB177+BA9 -> 788480
A10: 45912 | B10: KMART AUSTRALIA LTD | C10: 澳大利亚 | D10: 4500179340 | E10: 21105432 | F10: 4500179340-70 | G10: 9548-S001 | H10: 鸭妈妈 | I10: 1452 | J10: 0 | K10: 4 | L10: =I10/K10 -> 363 | M10: 45957 | N10: 45953 | U10: MA | X10: 日期码格式：ZURU INC(BVI) 标准格式 日期：按实际生产日期 Packaging Info: 9548: MA英语UPC版本包装（收缩膜和说明书, MA首选1L，如无1L可用多语且含英语的配套多语包装) + 1张防盗贴纸 (贴纸以及位置图翻单PO#4500126567）+ 箱唛 + 外箱SSCC Label Remark: 1.请务必按时完货，验货。并且按期送货入货代指定仓库，如果晚了导致船期Delay将会有罚金产生或者客户要求空运，所产生的罚金和空运费由工厂承担。 2.SSCC 外箱贴纸请同纸箱瓦楞纸方向（竖纹向）垂直，即外箱贴纸横着贴(注意条码不要被胶带粘住），贴1pc，贴1面正唛，封箱胶纸不能挡住贴纸内容。外箱贴纸 离外箱边距离不少于2cm。 3.外箱材质为ZURU标准； 4.此单需使用KMART封箱胶上下工字型封箱;从2019年6月开始，要用KMART 新版封箱胶带，此单要用"ANKO"封箱胶带 5.此单出口澳大利亚，请按相应的澳新标准生产； 6.产品和包装上生产批号的显示格式ZURU标准日期码格式 7.外箱信息不可手写，重量和体积需要与实际的一致(不可手写） 8. 每款item装箱后的G.W.超过10KG或者CBM超过0.13,(9.5KG或者以上，四舍五入后也属于10KG) 需在外箱上加印超 重或者Bulky LOGO，若发现我们资料没有，请 帮忙提醒 1)重量超过10kg但不超过16kg且CBM不超过0.13,10-16kg 超重logo 2）CBM超过0.13且重量少于17kg，bulky logo 3）不属于以上两种情况，需要使用相应重量范围内的超重logo 4）超重logo需要在外箱四面都印刷(箱唛右上角，两面侧唛超重logo需要尽量靠近毛重)，尺寸为:110mm height* 95mm width 9. 实际外箱重量跟印在箱唛上的数据差异不能超3%，尺寸按实际数据印刷 | Y10: Lydia Wu | Z10: 8.1045 | AA10: =Z10*I10 -> 11767.734 | BA10: =I10 -> 1452 | BB10: ='9548明细'!BB178+BA10 -> 783364
A12: 45774 | B12: WALMART INC. | C12: 美国 | D12: 4500165176 | E12: 0923153980 | F12: 4500165176-20 | G12: 9548-S002 | H12: 鸭妈妈 | I12: 110 | J12: 0 | K12: 1 | L12: =I12/K12 -> 110 | M12: 45854 | N12: =M12-4 -> 45850 | O12: 客人取消 | P12: PASS | R12: 45738 | S12: 无 | T12: 客版布标贴纸，5/12客供RFID贴纸（标贴位置严格按照我们签板的 位置图，不可擅自调整位置，贴纸不能有任何破损或折坏，不可淋湿）。 | U12: MA | X12: 日期码格式：ZURU DGYYYYMMDD CHINA(日期避开周末和法定节假日即可） 日期：按实际生产日期 Packaging Info: 9548 1.包装信息：MA B版 UPC版 1L包装，MA 5L B版说明书，MA 5L B版口水胶袋，MA 2L C版车缝布标，客版布标贴纸，客供RFID贴纸（标贴位置严格按照我们签板的 位置图，不可擅自调整位置，贴纸不能有任何破损或折坏，不可淋湿）。 Remark: 9548 1.包装信息：MA B版 UPC版 1L包装，MA 5L B版说明书，MA 5L B版口水胶袋，MA 2L C版车缝布标，客版布标贴纸，客供RFID贴纸（标贴位置严格按照我们签板的 位置图，不可擅自调整位置，贴纸不能有任何破损或折坏，不可淋湿）。 2. 外箱印刷带条码的RFID箱唛：RFID紫色色带+WM Dept.图标+RFID图标+ITF-14条码+粉色艾利贴纸（不干胶打印），四面右下角印刷ZURU logo, ITFF条码只印刷在 正唛一面，在加印的时候确保条形码能扫描出来，1张粉红色贴纸贴在正唛对角线，外箱侧面任一角落加印："MADE IN CHINA" 字样； 3.在产品上和包装上要有日期码（避开周末和节假日），以及要有MADE IN CHINA和ZURU字样。 4.产品如有扎带口要剪平，不能刮手。 5. 此单以散箱出货，9548：1pcs/CTN 6.此单需要第三方验货，请自行多备物料。 7.其它信息：3pcs*AAA battery not include。 | Y12: Maggie Xie | Z12: 4.5054 | AA12: =Z12*I12 -> 495.594 | AC12: 9548-S002 | AD12: 已入 | AE12: =I12*0.2 -> 22 | AK12: =I12 -> 110 | AS12: =I12 -> 110 | BA12: =I12 -> 110 | BB12: =取消单!BB16+BA12 -> 778942
A13: 45774 | B13: WALMART INC. | C13: 美国 | D13: 4500165176 | E13: 0923153985 | F13: 4500165176-10 | G13: 9548-S002 | H13: 鸭妈妈 | I13: 88 | J13: 0 | K13: 1 | L13: =I13/K13 -> 88 | M13: 45859 | N13: =M13-4 -> 45855 | O13: 客人取消 | P13: PASS | R13: 45738 | S13: 无 | T13: 客版布标贴纸，5/12客供RFID贴纸（标贴位置严格按照我们签板的 位置图，不可擅自调整位置，贴纸不能有任何破损或折坏，不可淋湿）。 | U13: MA | X13: 日期码格式：ZURU DGYYYYMMDD CHINA(日期避开周末和法定节假日即可） 日期：按实际生产日期 Packaging Info: 9548 1.包装信息：MA B版 UPC版 1L包装，MA 5L B版说明书，MA 5L B版口水胶袋，MA 2L C版车缝布标，客版布标贴纸，客供RFID贴纸（标贴位置严格按照我们签板的 位置图，不可擅自调整位置，贴纸不能有任何破损或折坏，不可淋湿）。 Remark: 9548 1.包装信息：MA B版 UPC版 1L包装，MA 5L B版说明书，MA 5L B版口水胶袋，MA 2L C版车缝布标，客版布标贴纸，客供RFID贴纸（标贴位置严格按照我们签板的 位置图，不可擅自调整位置，贴纸不能有任何破损或折坏，不可淋湿）。 2. 外箱印刷带条码的RFID箱唛：RFID紫色色带+WM Dept.图标+RFID图标+ITF-14条码+粉色艾利贴纸（不干胶打印），四面右下角印刷ZURU logo, ITFF条码只印刷在 正唛一面，在加印的时候确保条形码能扫描出来，1张粉红色贴纸贴在正唛对角线，外箱侧面任一角落加印："MADE IN CHINA" 字样； 3.在产品上和包装上要有日期码（避开周末和节假日），以及要有MADE IN CHINA和ZURU字样。 4.产品如有扎带口要剪平，不能刮手。 5. 此单以散箱出货，9548：1pcs/CTN 6.此单需要第三方验货，请自行多备物料。 7.其它信息：3pcs*AAA battery not include。 | Y13: Maggie Xie | Z13: 4.5054 | AA13: =Z13*I13 -> 396.4752 | AC13: 9548-S002 | AD13: 已入 | AE13: =I13*0.2 -> 17.6 | AK13: =I13 -> 88 | AS13: =I13 -> 88 | BA13: =I13 -> 88 | BB13: ='9548明细'!BB135+BA13 -> 88
A14: 45611 | B14: DM LLC | C14: 俄罗斯联邦 | D14: 4500151414 | E14: 出Bekasovo 2 | F14: 4500151414-80 | G14: 9548-S001 | H14: 鸭妈妈 | I14: 340 | J14: 0 | K14: 4 | L14: =I14/K14 -> 85 | M14: 45847 | N14: 45843 | P14: PASS | R14: 45615 | S14: 无 | T14: 进口商贴纸翻4500151398+ EAN条码贴纸翻4500151398 | U14: MA | W14: 外包装(指: 收缩膜/彩卡/吊牌/PDQ)/外箱不要打ZURU标准日期码！ | X14: 日期码格式：外包装/外箱不要打ZURU标准日期码 日期： Packaging Info: 注意 ：外包装 (指: 收缩膜/彩卡/铝箔袋/挂卡/PDQ) /外箱不要打ZURU标准日期码！胶件可以打日期码。 9548 : 1L MA 收缩膜 or 彩卡 + 进口商贴纸翻4500151398+ EAN条码贴纸翻4500151398，MA 指南 /说明书（如有）； Remark: | Y14: Ann Zhang | Z14: 7.6392 | AA14: =Z14*I14 -> 2597.328 | AC14: 9548-S001 | AD14: 已入 | AE14: =I14*0.2 -> 68 | AK14: =I14 -> 340 | AS14: =I14 -> 340 | BA14: =I14 -> 340 | BB14: ='9548明细'!BB152+BA14 -> 786320
A15: 45611 | B15: DM LLC | C15: 俄罗斯联邦 | D15: 4500151414 | E15: 出Ural | F15: 4500151414-170 | G15: 9548-S001 | H15: 鸭妈妈 | I15: 148 | J15: 0 | K15: 4 | L15: =I15/K15 -> 37 | M15: 45847 | N15: 45843 | P15: PASS | R15: 45615 | S15: 无 | T15: 进口商贴纸翻4500151398+ EAN条码贴纸翻4500151398 | U15: MA | W15: 外包装(指: 收缩膜/彩卡/吊牌/PDQ)/外箱不要打ZURU标准日期码！ | X15: 日期码格式：外包装/外箱不要打ZURU标准日期码 日期： Packaging Info: 注意 ：外包装 (指: 收缩膜/彩卡/铝箔袋/挂卡/PDQ) /外箱不要打ZURU标准日期码！胶件可以打日期码。 9548 : 1L MA 收缩膜 or 彩卡 + 进口商贴纸翻4500151398+ EAN条码贴纸翻4500151398，MA 指南 /说明书（如有）； Remark: | Y15: Ann Zhang | Z15: 7.3292 | AA15: =Z15*I15 -> 1084.7216 | AC15: 9548-S001 | AD15: 已入 | AE15: =I15*0.2 -> 29.6 | AK15: =I15 -> 148 | AS15: =I15 -> 148 | BA15: =I15 -> 148 | BB15: ='9548明细'!BB153+BA15 -> 787352
A16: 45611 | B16: DM LLC | C16: 俄罗斯联邦 | D16: 4500151404 | E16: 出Bekasovo 2 | F16: 4500151404-70 | G16: 9548-S001 | H16: 鸭妈妈 | I16: 340 | J16: 0 | K16: 4 | L16: =I16/K16 -> 85 | M16: 45817 | N16: 45813 | P16: PASS | R16: 45615 | S16: 无 | T16: 进口商贴纸翻4500151398+ EAN条码贴纸翻4500151398 | U16: MA | W16: 外包装(指: 收缩膜/彩卡/吊牌/PDQ)/外箱不要打ZURU标准日期码！ | X16: 日期码格式：外包装/外箱不要打ZURU标准日期码 日期： Packaging Info: 注意 ：外包装 (指: 收缩膜/彩卡/铝箔袋/挂卡/PDQ) /外箱不要打ZURU标准日期码！胶件可以打日期码。 9548 : 1L MA 收缩膜 or 彩卡 + 进口商贴纸翻4500151398+ EAN条码贴纸翻4500151398，MA 指南 /说明书（如有）； Remark: 标准配比 出BEKASOVO 2 和Ural 2 个港口； 货期不可延， 有罚金 。 | Y16: Ann Zhang | Z16: 7.3075 | AA16: =Z16*I16 -> 2484.55 | AC16: 9548-S001 | AD16: 已入 | AE16: =I16*0.2 -> 68 | AK16: =I16 -> 340 | AS16: =I16 -> 340 | BA16: =I16 -> 340 | BB16: ='9548明细'!BB95+BA16 -> 778832
