Workbook

Sheet 樣板單
A1: ZURU Rainbocorn 樣板訂單 | V1: 1代珠片公仔#9201 | AE1: 2代珠片公仔#9202 | AN1: #9204 | AW1: #9214 | BE1: #9209 | BV1: #9202 | CI1: #9204 | CO1: #9214（第二代） | CU1: #9209 | CX1: #9215 | DE1: #9212 | DK1: #9213 | DN1: #9207 | DO1: #9208
V2: 收縮膜 | Y2: 說明書 | AE2: 收縮膜 | AH2: 說明書 | AN2: A版本 | AP2: B版本 | BJ2: 3 | BL2: 4 | BN2: 5 | BP2: 5 | BR2: 4 | BT2: 3
A3: 香港接单日期 | B3: ZURU 跟单 | C3: ZURU PO NO# | D3: 第三方客户 PO NO# | E3: 第三方客户名称 | F3: ITEM# | G3: 中文名 | H3: PO数量 (pcs) | I3: 内箱装箱数量(pcs) | J3: 外箱装箱数量(pcs) | K3: 总箱数 | L3: 单价USD | M3: 金额USD | N3: ZURU验货 日期 | O3: 驗貨結果 | P3: 第三方客户公证行验货 | Q3: ZURU订单走货日期 | R3: ZURU确认走货日期 | S3: 箱唛资料(收到日期) | T3: 箱唛资料(确认日期) | U3: 客供贴纸AI(收到日期) | V3: MA 1語收縮膜 | W3: MA 3語收縮膜 | X3: 客版收縮膜 | Y3: MA 1語说明书 A版本 | Z3: MA 1語说明书 B版本 | AA3: MA 3語說明書 A版本 | AB3: MA 3語說明書 B版本 | AC3: 客版說明書 | AD3: 布標 | AE3: MA 1語收縮膜 | AF3: MA 3語收縮膜 | AG3: 客版收縮膜 | AH3: MA 1語说明书 A版本 | AI3: MA 1語说明书 B版本 | AJ3: MA 3語說明書 A版本 | AK3: MA 3語說明書 B版本 | AL3: 客版說明書 | AM3: 布標 | AN3: MA 1語收縮膜 | AO3: MA 1語說明書 | AP3: MA 1語收縮膜 | AQ3: MA 1語說明書 | AR3: MA 2語收縮膜（加拿大版本） | AS3: MA 2語說明書（加拿大版本） | AT3: 落加拿大 棉花泥 | AU3: 9201SQ1 | AV3: 9204UQ1 | AW3: MA 1語收縮膜 A | AX3: MA 1語收縮膜 B | AY3: MA 1語說明書 A | AZ3: MA 1語收縮膜 B | BA3: MA 1語說明書 B | BB3: MA领养卡 | BC3: 9214SQ1 MA PDQ盒 | BD3: 9214UQ1 客办PDQ盒 | BE3: MA 1語收縮膜 | BF3: MA 1語說明書 | BG3: MA 3語收縮膜 | BH3: MA 3語說明書 | BI3: 發票號 | BJ3: 玫紅猴子 Monkey（A） | BK3: 黃色猴子 Monkey（B） | BL3: 粉紅貓 Kitty （A） | BM3: 玫紅貓 Kitty （B） | BN3: 白色兔子 Rabbit （A） | BO3: 玫紅兔子 Rabbit （B） | BP3: 白色獨角獸 Unicorn （A） | BQ3: 玫紅獨角獸 Unicorn （B） | BR3: 紫色小狗 Puppy （A） | BS3: 藍色小狗 Puppy （B） | BT3: 粉色倉鼠 Hamster （A） | BU3: 橙色倉鼠 Hamster （B） | BV3: 羊駝 Llama（白色） | BW3: 羊駝 Llama（紫色） | BX3: 火烈鳥 Flamingo （玫紅色） | BY3: 火烈鳥 Flamingo （彩虹色） | BZ3: 火烈鳥 Flamingo （金色） | CA3: 熊貓 Panda （黑白色） | CB3: 熊貓 Panda （粉紅色） | CC3: 貓頭鷹 OWL （紫色） | CD3: 貓頭鷹 OWL （白色） | CE3: 獨角獸 Unicorn （白色） | CF3: 獨角獸 Unicorn （紫色） | CG3: 獅子 Lion （粉紅色） | CH3: 獅子 Lion （黃色） | CI3: 白色獨角獸 Unicorn | CJ3: 枚红色火烈鸟 Flamingo | CK3: 白色羊驼 Llama | CL3: 粉红色猫 Kitty | CM3: 紫色兔子 Bunny | CN3: 蓝色小狗 Puppy | CO3: 白色猫头鹰 White Owl | CP3: 粉色狮子 Pink Lion | CQ3: 黄色猴子 Yellow Monkey | CR3: 紫色独角兽 Purple Unicorn | CS3: 白色熊猫 White Panda | CT3: 彩色火烈鸟 Colour Flamingo | CU3: 獨角獸 Unicorn | CV3: 白色羊驼 Llama | CW3: 枚红色火烈鸟 Flamingo | CX3: 孔雀 Peacock | CY3: 火烈鸟 Toucan | CZ3: 树懒 Sloth | DA3: 大象 Elephant | DB3: 老虎 Tiger | DC3: 梅花鹿 Giraffe | DD3: 斑马 Zebra | DE3: 兔子 Bunny 含海绵 | DF3: 小狗 Puppy | DG3: 羊驼 Llama | DH3: 小猫 Kitty 含海绵 | DI3: 独角兽 Unicorn | DJ3: 猴子 Monkey | DK3: 小猫 Kitten | DL3: 独角兽 Unicorn | DM3: 大嘴鸟 Toucan | DN3: 2PK超小蛋殼公仔 | DO3: 4PK超小蛋殼公仔
A4: 43243 | B4: Binnie | C4: ZMPO18068 | F4: 9201-S001 | G4: 珠片公仔 | H4: 360 | V4: =H4 -> 360 | Y4: =H4 -> 360 | AD4: MA布標 | BI4: 19573 | BJ4: =H4/12 -> 30 | BK4: =H4/12 -> 30 | BL4: =H4/12 -> 30 | BM4: =H4/12 -> 30 | BN4: =H4/12 -> 30 | BO4: =H4/12 -> 30 | BP4: =H4/12 -> 30 | BQ4: =H4/12 -> 30 | BR4: =H4/12 -> 30 | BS4: =H4/12 -> 30 | BT4: =H4/12 -> 30 | BU4: =H4/12 -> 30
A5: 43265 | B5: Amanda | C5: ZMPO18078 | F5: 9201-S001 | G5: 珠片公仔 | H5: 480 | V5: =H5 -> 480 | Y5: =H5 -> 480 | AD5: MA布標 | BI5: 19654 | BJ5: =H5/12 -> 40 | BK5: =H5/12 -> 40 | BL5: =H5/12 -> 40 | BM5: =H5/12 -> 40 | BN5: =H5/12 -> 40 | BO5: =H5/12 -> 40 | BP5: =H5/12 -> 40 | BQ5: =H5/12 -> 40 | BR5: =H5/12 -> 40 | BS5: =H5/12 -> 40 | BT5: =H5/12 -> 40 | BU5: =H5/12 -> 40
A6: 43265 | B6: Angela | C6: 4500010393 | E6: 簽板 | F6: 9201-S001 | G6: 珠片公仔 | H6: 36 | V6: =H6 -> 36 | Y6: =H6 -> 36 | AD6: MA布標 | BJ6: =H6/12 -> 3 | BK6: =H6/12 -> 3 | BL6: =H6/12 -> 3 | BM6: =H6/12 -> 3 | BN6: =H6/12 -> 3 | BO6: =H6/12 -> 3 | BP6: =H6/12 -> 3 | BQ6: =H6/12 -> 3 | BR6: =H6/12 -> 3 | BS6: =H6/12 -> 3 | BT6: =H6/12 -> 3 | BU6: =H6/12 -> 3
A7: 43265 | B7: Lingly | C7: 4500010570 | E7: GP測試版 | F7: 9201-S001 | G7: 珠片公仔 | H7: 12 | V7: =H7 -> 12 | Y7: =H7 -> 12 | AD7: MA布標 | BJ7: =H7/12 -> 1 | BK7: =H7/12 -> 1 | BL7: =H7/12 -> 1 | BM7: =H7/12 -> 1 | BN7: =H7/12 -> 1 | BO7: =H7/12 -> 1 | BP7: =H7/12 -> 1 | BQ7: =H7/12 -> 1 | BR7: =H7/12 -> 1 | BS7: =H7/12 -> 1 | BT7: =H7/12 -> 1 | BU7: =H7/12 -> 1
A8: 43265 | B8: Holly | C8: 4500009837 | E8: 寄客版 | F8: 9201-S001 | G8: 珠片公仔 | H8: 12 | V8: =H8 -> 12 | Y8: =H8 -> 12 | AD8: MA布標 | BJ8: =H8/12 -> 1 | BK8: =H8/12 -> 1 | BL8: =H8/12 -> 1 | BM8: =H8/12 -> 1 | BN8: =H8/12 -> 1 | BO8: =H8/12 -> 1 | BP8: =H8/12 -> 1 | BQ8: =H8/12 -> 1 | BR8: =H8/12 -> 1 | BS8: =H8/12 -> 1 | BT8: =H8/12 -> 1 | BU8: =H8/12 -> 1
A9: 43270 | B9: Sara | C9: 郵件 | E9: Candide客户样品 | F9: 9201-S001 | G9: 珠片公仔 | H9: 6 | V9: =H9 -> 6 | Y9: =H9 -> 6 | AD9: MA布標 | BJ9: 1 | BL9: 1 | BN9: 1 | BP9: 1 | BR9: 1 | BT9: 1
A10: 43270 | B10: Sara | C10: 4500010598 | E10: WABRO | F10: 9201-S001 | G10: 珠片公仔 | H10: 24 | V10: =H10 -> 24 | Y10: =H10 -> 24 | AD10: MA布標 | BJ10: =H10/12 -> 2 | BK10: =H10/12 -> 2 | BL10: =H10/12 -> 2 | BM10: =H10/12 -> 2 | BN10: =H10/12 -> 2 | BO10: =H10/12 -> 2 | BP10: =H10/12 -> 2 | BQ10: =H10/12 -> 2 | BR10: =H10/12 -> 2 | BS10: =H10/12 -> 2 | BT10: =H10/12 -> 2 | BU10: =H10/12 -> 2
A11: 43277 | B11: Tiffany | C11: 4500010957 | D11: 大貨簽板 | E11: EURO TOYS EUROPE BV | F11: 9201-S001 | G11: 珠片公仔 | H11: 36 | X11: 36 | AC11: 36 | AD11: MA布標 | BJ11: =H11/12 -> 3 | BK11: =H11/12 -> 3 | BL11: =H11/12 -> 3 | BM11: =H11/12 -> 3 | BN11: =H11/12 -> 3 | BO11: =H11/12 -> 3 | BP11: =H11/12 -> 3 | BQ11: =H11/12 -> 3 | BR11: =H11/12 -> 3 | BS11: =H11/12 -> 3 | BT11: =H11/12 -> 3 | BU11: =H11/12 -> 3
A12: 43277 | B12: Lucky | C12: 450012096 | D12: 產前測試 | E12: CENCOSUD CHILE | F12: 9201-S001 | G12: 珠片公仔 | H12: 12 | V12: 12 | Y12: 12 | AD12: MA布標 | BJ12: =H12/12 -> 1 | BK12: =H12/12 -> 1 | BL12: =H12/12 -> 1 | BM12: =H12/12 -> 1 | BN12: =H12/12 -> 1 | BO12: =H12/12 -> 1 | BP12: =H12/12 -> 1 | BQ12: =H12/12 -> 1 | BR12: =H12/12 -> 1 | BS12: =H12/12 -> 1 | BT12: =H12/12 -> 1 | BU12: =H12/12 -> 1
A13: 43265 | B13: Lingly | C13: 4500010570 | E13: 年齡評估樣品 | F13: 9201-S001 | G13: 珠片公仔 | H13: 2 | V13: 12 | Y13: 12 | AD13: MA布標 | BN13: 1 | BO13: 1
A14: 43284 | C14: ZMPO18086 | F14: 9201-S001 | G14: 珠片公仔 | H14: 480 | V14: 480 | Y14: 480 | AD14: MA布標 | BI14: 19655 | BJ14: =H14/12 -> 40 | BK14: =H14/12 -> 40 | BL14: =H14/12 -> 40 | BM14: =H14/12 -> 40 | BN14: =H14/12 -> 40 | BO14: =H14/12 -> 40 | BP14: =H14/12 -> 40 | BQ14: =H14/12 -> 40 | BR14: =H14/12 -> 40 | BS14: =H14/12 -> 40 | BT14: =H14/12 -> 40 | BU14: =H14/12 -> 40
A15: 43286 | C15: 4500010467 | F15: 9201-S001 | G15: 珠片公仔 | H15: 10 | V15: 10 | Y15: 10 | AD15: MA布標 | BL15: 1 | BM15: 1 | BN15: 1 | BO15: 1 | BP15: 1 | BQ15: 1 | BR15: 1 | BS15: 1 | BT15: 1 | BU15: 1
A16: 43287 | C16: 4500010333 | F16: 9201-S001 | G16: 珠片公仔 | H16: 10 | V16: 10 | Y16: 10 | AD16: MA布標 | BL16: 1 | BM16: 1 | BN16: 1 | BO16: 1 | BP16: 1 | BQ16: 1 | BR16: 1 | BS16: 1 | BT16: 1 | BU16: 1
A17: 43302 | C17: 4500012533 | F17: 9201-S001 | G17: 珠片公仔 | H17: 12 | V17: 12 | Y17: 12 | AD17: MA布標 | BJ17: 1 | BK17: 1 | BL17: 1 | BM17: 1 | BN17: 1 | BO17: 1 | BP17: 1 | BQ17: 1 | BR17: 1 | BS17: 1 | BT17: 1 | BU17: 1
A18: 43302 | C18: 4500010568 | F18: 9201-S001 | G18: 珠片公仔 | H18: 4 | V18: 4 | AC18: 4 | AD18: 丹麥布標 | BJ18: 1 | BL18: 1 | BN18: 1 | BP18: 1
A19: 43306 | C19: 4500010570 | E19: GP FRANCE | F19: 9201-S001 | G19: 珠片公仔 | H19: 28 | X19: 28 | Y19: 28 | AD19: 法國布標 | BJ19: 3 | BK19: 2 | BL19: 3 | BM19: 2 | BN19: 3 | BO19: 2 | BP19: 3 | BQ19: 2 | BR19: 2 | BS19: 2 | BT19: 2 | BU19: 2
A20: 43306 | C20: 4500010574 | E20: GP ITALY | F20: 9201-S001 | G20: 珠片公仔 | H20: 25 | X20: 25 | Y20: 25 | AD20: 意大利布標 | BJ20: 2 | BK20: 2 | BL20: 2 | BM20: 2 | BN20: 2 | BO20: 2 | BP20: 3 | BQ20: 2 | BR20: 2 | BS20: 2 | BT20: 2 | BU20: 2
A21: 43313 | C21: 4500009768 | E21: TOY TRIANGLE CO.W.L.L | F21: 9201-S001 | G21: 珠片公仔 | H21: 2 | V21: 2 | Y21: 2 | AD21: MA布標 | BN21: 1 | BP21: 1
A22: 43313 | C22: 4500012277 | E22: Express Gifts Ltd | F22: 9201-S006 | G22: 珠片公仔 | H22: 10 | V22: 10 | Y22: 10 | AD22: MA布標 | BL22: 1 | BM22: 1 | BN22: 1 | BO22: 1 | BP22: 1 | BQ22: 1 | BR22: 1 | BS22: 1 | BT22: 1 | BU22: 1
A23: 43316 | C23: 4500009878 | E23: P.M.I TRADING & ENTERPRISE LTS34 | F23: 9201-S001 | G23: 珠片公仔 | H23: 2 | V23: 2 | Y23: 2 | AD23: MA布標
A24: 43318 | C24: 4500012769 | E24: TOYS kingdom | F24: 9201-S001 | G24: 珠片公仔 | H24: 2 | AD24: MA布標 | BT24: 2
A25: 43321 | C25: 4500012192 | D25: 簽板 | E25: CANDIDE IND E COM LTDA | F25: 9201-S001 | G25: 珠片公仔 | H25: 25 | X25: 25 | AC25: 25 | AD25: 巴西布標 | BJ25: 2 | BK25: 2 | BL25: 2 | BM25: 2 | BN25: 2 | BO25: 2 | BP25: 3 | BQ25: 2 | BR25: 2 | BS25: 2 | BT25: 2 | BU25: 2
A26: 43323 | C26: 4500012835 | D26: 產前測試 | E26: WAL-MART.COM | F26: 9201-S001 | G26: 珠片公仔 | H26: 18 | V26: 18 | Y26: 18 | AD26: MA布標 | BJ26: 3 | BL26: 3 | BN26: 3 | BP26: 3 | BR26: 3 | BT26: 3
A27: 43332 | C27: 4500010580 | D27: 大貨版、簽板 | E27: GP SPAIN | F27: 9201-S001 | G27: 珠片公仔 | H27: 12 | X27: 12 | Y27: 12 | AD27: 西班牙布標 | BJ27: 2 | BK27: 2 | BL27: 2 | BM27: 2 | BN27: 2 | BO27: 2 | BP27: 3 | BQ27: 2 | BR27: 2 | BS27: 2 | BT27: 2 | BU27: 2
A28: 43332 | C28: 4500011417 | D28: 大貨版、簽板 | E28: GP TURKEY | F28: 9201-S001 | G28: 珠片公仔 | H28: 12 | X28: 12 | Y28: 12 | AD28: 土耳其布標 | BJ28: 2 | BK28: 2 | BL28: 2 | BM28: 2 | BN28: 2 | BO28: 2 | BP28: 3 | BQ28: 2 | BR28: 2 | BS28: 2 | BT28: 2 | BU28: 2
A29: 43335 | C29: 4500012306 | D29: MA 3語簽板 | E29: 360 SALES SOLUTIONS INC | F29: 9201-S001 | G29: 珠片公仔 | H29: 24 | W29: 24 | AA29: 24 | AD29: MA布標 | BJ29: 2 | BK29: 2 | BL29: 2 | BM29: 2 | BN29: 2 | BO29: 2 | BP29: 2 | BQ29: 2 | BR29: 2 | BS29: 2 | BT29: 2 | BU29: 2
A30: 43336 | C30: 4500009673 | D30: 大貨樣板 | E30: B&M RETAIL LIMITED | F30: 9201-S003 | G30: 珠片公仔 | H30: 10 | V30: 10 | Y30: 10 | AD30: MA布標 | BL30: 1 | BM30: 1 | BN30: 1 | BO30: 1 | BP30: 1 | BQ30: 1 | BR30: 1 | BS30: 1 | BT30: 1 | BU30: 1
A31: 43336 | C31: 郵件 | D31: Intek 客户样品 | E31: Lucky | F31: 9201-S001 | G31: 珠片公仔 | H31: 24 | V31: 24 | Y31: 24 | AD31: MA布標 | BJ31: 2 | BK31: 2 | BL31: 2 | BM31: 2 | BN31: 2 | BO31: 2 | BP31: 2 | BQ31: 2 | BR31: 2 | BS31: 2 | BT31: 2 | BU31: 2
A32: 43342 | C32: ZMPO18108 | F32: 9201-S001 | G32: 珠片公仔 | H32: 360 | V32: 24 | Y32: 24 | BI32: 19952 | BJ32: =H32/24*3/2 -> 22.5 | BK32: =H32/24*3/2 -> 22.5 | BL32: =H32/24*4/2 -> 30 | BM32: =H32/24*4/2 -> 30 | BN32: =H32/24*5/2 -> 37.5 | BO32: =H32/24*5/2 -> 37.5 | BP32: =H32/24*5/2 -> 37.5 | BQ32: =H32/24*5/2 -> 37.5 | BR32: =H32/24*4/2 -> 30 | BS32: =H32/24*4/2 -> 30 | BT32: =H32/24*3/2 -> 22.5 | BU32: =H32/24*3/2 -> 22.5
A33: 43364 | C33: 4500011712 | D33: 大貨樣板 | E33: TARGET US | F33: 9201-S001 | G33: 珠片公仔 | H33: 9 | V33: 9 | Y33: 9 | AD33: MA布標 | BJ33: 1 | BK33: 1 | BL33: 1 | BM33: 1 | BQ33: 1 | BR33: 1 | BS33: 1 | BT33: 1 | BU33: 1
A34: 43364 | C34: 4500013372 | D34: 大貨樣板 | E34: DISTRIBUIDORA JUGUETRON S.A DE C.V | F34: 9201-S001 | G34: 珠片公仔 | H34: 2 | W34: 2 | AA34: 2 | AD34: MA布標 | BN34: 1 | BP34: 1
A35: 43369 | C35: 4500013085 | D35: 抽版 | F35: 9201-S001 | G35: 粉紅色獨角獸 | H35: 8 | V35: 8 | Y35: 8 | AD35: MA布標 | BQ35: 8
A36: 43382 | C36: 4500013648 | D36: 簽板 | F36: 9201-S001 | G36: 珠片公仔 | H36: 24 | V36: 24 | Y36: 24 | AD36: MA布標 | BJ36: 2 | BK36: 2 | BL36: 2 | BM36: 2 | BN36: 2 | BO36: 2 | BP36: 2 | BQ36: 2 | BR36: 2 | BS36: 2 | BT36: 2 | BU36: 2
A37: 43384 | C37: 4500013155 | D37: 大貨版 | F37: 9201-S001 | G37: 珠片公仔 | H37: 12 | V37: 12 | Y37: 12 | AD37: MA布標 | BJ37: 1 | BK37: 1 | BL37: 1 | BM37: 1 | BN37: 1 | BO37: 1 | BP37: 1 | BQ37: 1 | BR37: 1 | BS37: 1 | BT37: 1 | BU37: 1
A38: 43392 | C38: 4500013641 | D38: 大貨版 | F38: 9201-S001 | G38: 珠片公仔 | H38: 12 | X38: 12 | AC38: 12 | AD38: GP法國 | BJ38: 1 | BK38: 1 | BL38: 1 | BM38: 1 | BN38: 1 | BO38: 1 | BP38: 1 | BQ38: 1 | BR38: 1 | BS38: 1 | BT38: 1 | BU38: 1
A39: 43392 | C39: ZMPO18123 | D39: 樣品訂單 | F39: 9201-S001 | G39: 珠片公仔 | H39: 204 | V39: 204 | Y39: 204 | AD39: MA布標 | BJ39: 17 | BK39: 17 | BL39: 17 | BM39: 17 | BN39: 17 | BO39: 17 | BP39: 17 | BQ39: 17 | BR39: 17 | BS39: 17 | BT39: 17 | BU39: 17
A40: 43392 | C40: ZMPO18131 | D40: 樣品訂單 | F40: 9201-S001 | G40: 珠片公仔 | H40: 480 | V40: 480 | Y40: 480 | AD40: MA布標 | BJ40: 40 | BK40: 40 | BL40: 40 | BM40: 40 | BN40: 40 | BO40: 40 | BP40: 40 | BQ40: 40 | BR40: 40 | BS40: 40 | BT40: 40 | BU40: 40
...

Sheet 71152
A2: =#REF! -> #REF! | I2: （黃色表示更改或增加） | L2: （蓝色表示已完货） | P2: （綠色表示調整貨期） | T2: 是否需要样板 | AJ2: 彩盒 | AN2: 收藏指南 | AQ2: 展示架
A3: 接单日期 | B3: 第三方客户名称 | C3: 国家 | D3: PO号 | E3: 客PO号 | F3: SKU | G3: 系统货号 | H3: ITEM# | I3: 中文名 | J3: PO数量 (pcs) | K3: 内箱装箱数量(pcs) | L3: 外箱装箱数量(pcs) | M3: 总箱数 | N3: 客PO期 | O3: 验货期 | P3: 第三方验货期 | Q3: 驗貨結果 | R3: 船期SO | S3: 贴纸情况 | T3: 蓝色表示已寄 黄色表示出单 | U3: 箱唛资料（收到箱唛日期） | V3: 外箱贴纸 | W3: 客贴纸资料 | X3: 客版资料 | Y3: 日期码 | Z3: 备注 | AA3: ZURU 跟单 | AB3: 单价USD | AC3: 金额USD | AD3: 發票號 | AE3: 是否入系统 | AF3: 装配采购单 | AG3: 已送数量 | AH3: 欠数 | AI3: 贴纸信息 | AJ3: MA 1语彩盒 A版本 | AK3: MA 1L 彩盒B版本 | AL3: MA 3L彩盒 A版本 | AM3: 客版彩盒 | AN3: MA 5说明书 | AO3: MA 5L 说明书B版 | AP3: 客版说明书 | AQ3: EC展示架 | AR3: 合计数量 | AS3: 累计数量
A4: 45623 | D4: ZPO2411014 | G4: * | H4: 71152-S001 | I4: 机械速龙 | J4: 600 | M4: 100 | Q4: PASS | Z4: STD PP 产品 500 件金印测试样品 2x 主箱开发实验室外测试-10套(如果FEP中未提供)商品团队:1套(Phoenix/Selina)客户化团队:1套(Sharon) 生产计划:1套(Tracy)设计/品牌团队:1套(Gretta/Amy)销售团队:4箱至4SR办公室。签署样品:4套。(5套用于I/H) 产用(用于QA/QC)个用于包装设计用于营销 个用于新产品开发和产品设计(用于 I/H 研发 剩余数量:营销样品 准:PP产品500件散装和250件套装。PP工艺中将包含A11标准SKU。 PD团队将协调PP支持卡材料的交货时间以及付款。 请注意，其中200pcs需在PP后空运至新西兰进行上架测试，务必保证功能外观都没问题 | AB4: 2.7 | AC4: =AB4*J4 -> 1620 | AE4: * | AN4: =J4 -> 600 | AR4: =J4 -> 600 | AS4: =AR4 -> 600
A5: 45701 | B5: THE WAREHOUSE LIMITED | C5: 新西兰 | D5: 4500157534 | F5: 4500157534-20 | G5: 71152-S001 | H5: 71152-S001 | I5: 机械速龙 | J5: 96 | K5: 0 | L5: 6 | M5: =J5/L5 -> 16 | N5: 45723 | O5: 45719 | Q5: PASS | R5: 4/3入仓 | U5: 加水贴纸 | Y5: 日期码格式：ZURU INC(BVI) 标准格式 日期：按实际生产日期 | Z5: 日期码格式：ZURU INC(BVI) 标准格式 日期：按实际生产日期 Packaging Info: MA UPC 英语包装（优先1L英语版本，或者3L/5L含英语都可） 此客人不接受易掉落或者剥落或者可直接触碰的闪粉，可降解也不行，但可以接受符合欧洲微塑料标准的珠光粉或者闪片。 77685GQ1: 要加UPC贴纸 77673：包装正面和说明书都需要加电池警告语贴纸（法规要求） 所有外箱上都要贴一张大黄贴："ZURU Product for NZ test " Remark: 71152：2PCS AAA BATTERIES(NOT INCLUDED) | AA5: Abby Liang | AB5: 2.767 | AC5: =AB5*J5 -> 265.632 | AD5: 94695-4.3 | AE5: 已入 | AG5: =J5 -> 96 | AH5: =AG5-J5 -> 0 | AJ5: =J5 -> 96 | AN5: =J5 -> 96 | AR5: =J5 -> 96 | AS5: =AS4+AR5 -> 696
A6: 45666 | B6: PT.MAP Aktif Adiperkasa, Tbk | C6: 印度尼西亚 | D6: 4500155574 | E6: 241227-2MAAJKTQ225-ZURU | F6: 4500155574-50 | G6: 71152-S001 | H6: 71152-S001 | I6: 机械速龙 | J6: 504 | K6: 0 | L6: 6 | M6: =J6/L6 -> 84 | N6: 45733 | O6: 45729 | Q6: PASS | U6: 45667 | V6: 无 | W6: 2/6 进口商贴纸 | Y6: 日期码格式：ZURU INC(BVI) 标准格式 日期：按实际生产日期 | Z6: 日期码格式：ZURU INC(BVI) 标准格式 日期：按实际生产日期 Packaging Info: MA UPC包装（优先1L)+1张进口商贴纸, 所有item使用含电池信息的进口商贴纸，贴纸待提供 1.可能会被抽大货样做测试，请多备料，CRD前半个月会通知是否有抽到该订单中的item。 2.此订单送普通仓，送仓后会有第三方验货，所以需要按CRD准时完货。 Remark: 9561-3pcs LR41 Batteries（included） | AA6: Emma Wu | AB6: 2.7 | AC6: =AB6*J6 -> 1360.8 | AD6: 94672-3.29 | AE6: 已入 | AG6: =J6 -> 504 | AH6: =AG6-J6 -> 0 | AJ6: =J6 -> 504 | AN6: =J6 -> 504 | AR6: =J6 -> 504 | AS6: =AS5+AR6 -> 1200
A7: 45681 | B7: ALL BRANDS TOYS PTY LTD | C7: 澳大利亚 | D7: 4500156597 | E7: 83575 | F7: 4500156597-10 | G7: 71152-S001 | H7: 71152-S001 | I7: 机械速龙 | J7: 2400 | K7: 0 | L7: 6 | M7: =J7/L7 -> 400 | N7: 45737 | O7: =N7-4 -> 45733 | Q7: PASS | U7: 45694 | V7: 无 | W7: 通用进口商贴纸 | Y7: 日期码格式：ZURU INC(BVI) 标准格式 日期：按实际生产日期 | Z7: 日期码格式：ZURU INC(BVI) 标准格式 日期：按实际生产日期 Packaging Info: 71152： MA_UPC版本包装（收缩膜/彩卡和说明书, MA首选1L，如无1L可用多语且含英语的配套多语UPC包装）+ 1张客人通用进口商贴纸 Remark: 1.按实际生产日期; 2.出澳大利亚，请按照相应标准生产; | AA7: Lydia Wu | AB7: 2.7 | AC7: =AB7*J7 -> 6480 | AD7: 94724-4.8 | AE7: 已入 | AG7: =J7 -> 2400 | AH7: =AG7-J7 -> 0 | AJ7: =J7 -> 2400 | AN7: =J7 -> 2400 | AR7: =J7 -> 2400 | AS7: =AS6+AR7 -> 3600
A8: 45698 | B8: Smyths Toys EU HQ UC | C8: 德国 | D8: 4500157159 | E8: 4400464033 | F8: 4500157159-10 | G8: 71152-S001-1 | H8: 71152-S001 | I8: 机械速龙 | J8: 2004 | K8: 0 | L8: 6 | M8: =J8/L8 -> 334 | N8: 45737 | O8: =N8-4 -> 45733 | Q8: PASS | U8: 45699 | V8: 无 | W8: 客版WEEE声明说明书纸(不带电池)+产品贴纸（翻450 0064042 ） | X8: 客版彩盒翻4500156690 | Y8: 日期码格式：ZURU INC(BVI) 标准格式 日期：按实际生产日期 | Z8: 日期码格式：ZURU INC(BVI) 标准格式 日期：按实际生产日期 Packaging Info: 71152: 客版彩盒(3L 英法德callout+EAN条码+法国回收logo) 翻UK单#4500156690 + MA 5L-9L Warning说明书+客版WEEE声明说明书纸(不带电池)+产品贴纸（翻450 0064042 ） Remark: 1. 此单出德国，需要满足Zuru Standard欧洲标准测试要求； 2. 请准时出货，推期会有罚款； 3. 出口欧洲，微塑料需符合法规； 4. 所有电子产品身上需要加字唛，为ZURU FRANCE 地址 (如无电子产品，或者产品布标有此地址，可忽略此信息) ZURU France 1/3, Rue d'Argenteuil 95210 SAINT-GRATIEN, FRANCE 5. 所有出往德国订单的电子产品需增加一张客版WEEE声明说明书纸，区分带电池和不带电池版本, 如已做客版说明书可忽略此要求。 6. 标准配比 | AA8: Shirley Zhou | AB8: 2.7 | AC8: =AB8*J8 -> 5410.8 | AD8: 94725-4.8 | AE8: 已入 | AG8: =J8 -> 2004 | AH8: =AG8-J8 -> 0 | AM8: =J8 -> 2004 | AN8: =J8 -> 2004 | AR8: =J8 -> 2004 | AS8: =AS7+AR8 -> 5604
A9: 45701 | B9: ZURU LLC | C9: 美国 | D9: 4500157378 | E9: 5200006139 | F9: 4500157378-10 | G9: 71152-S001 | H9: 71152-S001-MTS | I9: 机械速龙 | J9: 594 | K9: 0 | L9: 6 | M9: =J9/L9 -> 99 | N9: 45737 | O9: =N9-4 -> 45733 | Q9: PASS | U9: 45701 | V9: 无 | Y9: 日期码格式：ZURU INC(BVI) 标准格式 日期：按实际生产日期 | Z9: 日期码格式：ZURU INC(BVI) 标准格式 日期：按实际生产日期 Packaging Info: #71152 MA UPC版 (1L或3L都可) Remark: 1.Amazon domestic 订单。出口美国。外箱最长边不能超过25" （超过了，case pack只能为1），不符合要求的大货，一律不接受。 2.无第三方验货/测试要求。 3.日期码使用ZURU标准版本。 | AA9: SD24 | AB9: 2.7 | AC9: =AB9*J9 -> 1603.8 | AD9: ZB00056 | AE9: 已入 | AG9: =J9 -> 594 | AH9: =AG9-J9 -> 0 | AJ9: =J9 -> 594 | AN9: =J9 -> 594 | AR9: =J9 -> 594 | AS9: =AS8+AR9 -> 6198
A10: 45712 | B10: Multihexa Sdn Bhd | C10: 马来西亚 | D10: 4500158287 | F10: 4500158287-10 | G10: 71152-S001 | H10: 71152-S001 | I10: 机械速龙 | J10: 252 | K10: 0 | L10: 6 | M10: =J10/L10 -> 42 | N10: 45740 | O10: =N10-4 -> 45736 | Q10: PASS | R10: 3/23送货到新益豪 | U10: 45715 | V10: 无 | W10: 2/281张进口商贴纸 | Y10: 日期码格式：ZURU INC(BVI) 标准格式 日期：按实际生产日期 | Z10: 日期码格式：ZURU INC(BVI) 标准格式 日期：按实际生产日期 Packaging Info: 1.此单走20GP，因系统未维护暂时开15706UQ2的装运类型为40GP，后续会更改过来 2.MA UPC包装（优先1L)+1张进口商贴纸 Remark: 71152-2PCS AAA BATTERIES(NOT INCLUDED) | AA10: Emma Wu | AB10: 2.7 | AC10: =AB10*J10 -> 680.4 | AD10: 94658-3.28 | AE10: 已入 | AG10: =J10 -> 252 | AH10: =AG10-J10 -> 0 | AJ10: =J10 -> 252 | AN10: =J10 -> 252 | AR10: =J10 -> 252 | AS10: =AS9+AR10 -> 6450
A11: 45702 | B11: PPTOYS PTE LTD (SG) | C11: 新加坡 | D11: 4500157618 | E11: ZU25012002SG | F11: 4500157618-10 | G11: 71152-S001 | H11: 71152-S001 | I11: 机械速龙 | J11: 720 | K11: 0 | L11: 6 | M11: =J11/L11 -> 120 | N11: 45735 | O11: 45735 | Q11: PASS | U11: 45703 | V11: 无 | W11: 2/27进口商贴纸 | Y11: 日期码格式：ZURU INC(BVI) 标准格式 日期：按实际生产日期 | Z11: 日期码格式：ZURU INC(BVI) 标准格式 日期：按实际生产日期 Packaging Info: MA UPC包装（优先1L)+1张进口商贴纸 71152-贴纸AW、位置图待提供 此客人用的贴纸内容都是一样的，个别item可能存在尺寸差别，收到贴纸后如果尺寸没差别，请都统一订购节省成本 Remark: 71152-2PCS AAA BATTERIES(NOT INCLUDED) | AA11: Emma Wu | AB11: 2.7 | AC11: =AB11*J11 -> 1944 | AD11: 94603-3.21 | AE11: 已入 | AG11: =J11 -> 720 | AH11: =AG11-J11 -> 0 | AJ11: =J11 -> 720 | AN11: =J11 -> 720 | AR11: =J11 -> 720 | AS11: =AS10+AR11 -> 7170
A12: 45674 | B12: FYE | C12: 美国 | D12: 4500155999 | E12: 86466 | F12: 4500155999-10 | G12: 71152-S001 | H12: 71152-S001 | I12: 机械速龙 | J12: 474 | K12: 0 | L12: 6 | M12: =J12/L12 -> 79 | N12: 45742 | O12: 45738 | Q12: PASS | U12: 45674 | V12: 无 | W12: 1/26客版可移动价格贴纸(贴纸AWS 跟单提供) | Y12: 日期码格式：ZURU INC(BVI) 标准格式 日期：按实际生产日期 | Z12: 日期码格式：ZURU INC(BVI) 标准格式 日期：按实际生产日期 Packaging Info: 1.ZURU MA UPC 包装(优先使用最新版本1L) + 客版可移动价格贴纸(贴纸AWS 跟单提供), 工厂自行订购, 出口美国。 2.ZURU标准日期码格式,所有产品及包装都必须带有日期码，日期码必须一致(但日期不可为周末)。 Remark: 1.ZURU MA UPC 包装(优先使用最新版本1L) +客版可移动价格贴纸(贴纸AWS 跟单提供), 工厂自行订购, 出口美国。 2.ZURU标准日期码格式,所有产品及包装都必须带有日期码，日期码必须一致(但日期不可为周末)。 3.此单外箱不可有水贴纸。 4.可移价贴需贴在产品包装背面右下角的位置（位置图跟单提供）。 All Pre Price Tickets should be placed on the back of the product located in the lower right hand corner of the package #71152-S001 $14.99 5.出货配比： #71152-S001-ROBO ALIVE-DINOSAUR-SERIES 1-RAPTOR-WINDOW BOX,6PCS/CTN 6. 外箱packing slip: 按客户最新要求， 每款产品的尾箱上或者内，需要附上packing slip (文件有跟单提供，工厂帮打印)。 若附在外箱上，需要用信封透明袋装住packing slip， 并贴在外箱一面正唛上。 若附在尾箱箱内，外箱正唛上需要贴有"packing slip enclosed" 标识。 工厂可以选择以上任意一种方式。 | AA12: Hailey Yu | AB12: 2.7 | AC12: =AB12*J12 -> 1279.8 | AD12: ZB00042 | AE12: 已入 | AG12: =J12 -> 474 | AH12: =AG12-J12 -> 0 | AJ12: =J12 -> 474 | AN12: =J12 -> 474 | AR12: =J12 -> 474 | AS12: =AS11+AR12 -> 7644
A13: 45709 | B13: BRICKLAND LLC | C13: 蒙古 | D13: 4500158223 | E13: Zuru2025Q1(addon) | F13: 4500158223-10 | G13: 71152-S001 | H13: 71152-S001 | I13: 机械速龙 | J13: 360 | K13: 0 | L13: 6 | M13: =J13/L13 -> 60 | N13: 45742 | O13: 45738 | Q13: PASS | U13: 45713 | V13: 无 | W13: 2/28 1张进口商贴纸 | Y13: 日期码格式：ZURU INC(BVI) 标准格式 日期：按实际生产日期 | Z13: 日期码格式：ZURU INC(BVI) 标准格式 日期：按实际生产日期 Packaging Info: MA UPC包装(优先1L)+1张进口商贴纸,贴纸图稿及位置图待提供; Remark: | AA13: Emma Wu | AB13: 2.7 | AC13: =AB13*J13 -> 972 | AD13: 94746-4.10 | AE13: 已入 | AG13: =J13 -> 360 | AH13: =AG13-J13 -> 0 | AJ13: =J13 -> 360 | AN13: =J13 -> 360 | AR13: =J13 -> 360 | AS13: =AS12+AR13 -> 8004
A14: 45694 | B14: Smyths Toys HQ UC UK | C14: 英国 | D14: 4500156690 | E14: 4400462625 | F14: 4500156690-10 | G14: 71152-S001-1 | H14: 71152-S001 | I14: 机械速龙 | J14: 3000 | K14: 0 | L14: 6 | M14: =J14/L14 -> 500 | N14: 45740 | O14: =N14-4 -> 45736 | Q14: PASS | U14: 45699 | V14: 无 | X14: 客版彩盒 | Y14: 日期码格式：ZURU INC(BVI) 标准格式 日期：按实际生产日期 | Z14: 日期码格式：ZURU INC(BVI) 标准格式 日期：按实际生产日期 Packaging Info: 71152：客版彩卡(3L callout+EAN条码+法国回收logo)+MA 5L-9L Warning说明书 Remark: 1）包装日期码按ZURU格式即可，请确保不迟于外箱日期码，可等于或者早于外箱日期码，必须为法定工作日，印刷前请先检查外箱日期码。 2）订单出英国，请注意检查产品及包装应带UKCA图标（14+产品除外），包装显示ZURU UK LTD/ZURU France地址信息，QC部门请查核，如有问题与跟单确认 3）订单必须经过ZURU QC验货并且通过后方可出货 4) 需要完全符合欧洲标准(符合微塑料法规)，否则不合法规会有客诉产生 | AA14: May Wu | AB14: 2.7 | AC14: =AB14*J14 -> 8100 | AD14: 94641-3.26 | AE14: 已入 | AG14: =J14 -> 3000 | AH14: =AG14-J14 -> 0 | AM14: =J14 -> 3000 | AN14: =J14 -> 3000 | AR14: =J14 -> 3000 | AS14: =AS13+AR14 -> 11004
A15: 45694 | B15: Smyths Toys HQ UC IE | C15: 爱尔兰 | D15: 4500156692 | E15: PO4400465271 | F15: 4500156692-10 | G15: 71152-S001-1 | H15: 71152-S001 | I15: 机械速龙 | J15: 900 | K15: 0 | L15: 6 | M15: =J15/L15 -> 150 | N15: 45740 | O15: =N15-4 -> 45736 | Q15: PASS | R15: 3/29出盐田 | U15: 45699 | V15: 无 | X15: 客版彩盒翻4500156690 | Y15: 日期码格式：ZURU INC(BVI) 标准格式 日期：按实际生产日期 | Z15: 日期码格式：ZURU INC(BVI) 标准格式 日期：按实际生产日期 Packaging Info: 71152：客版彩卡(英法德3L callout+EAN条码+法国回收logo，翻4500156690)+MA 5L-9L Warning说明书 Remark: 1）包装日期码按ZURU格式即可，请确保不迟于外箱日期码，可等于或者早于外箱日期码，必须为法定工作日，印刷前请先检查外箱日期码。 2）订单出英国，请注意检查产品及包装应带UKCA图标（14+产品除外），包装显示ZURU UK LTD/ZURU France地址信息，QC部门请查核，如有问题与跟单确认 3）订单必须经过ZURU QC验货并且通过后方可出货 4) 需要完全符合欧洲标准(符合微塑料法规)，否则不合法规会有客诉产生 | AA15: May Wu | AB15: 2.7 | AC15: =AB15*J15 -> 2430 | AD15: 94666-3.29 | AE15: 已入 | AG15: =J15 -> 900 | AH15: =AG15-J15 -> 0 | AM15: =J15 -> 900 | AN15: =J15 -> 900 | AR15: =J15 -> 900 | AS15: =AS14+AR15 -> 11904
A16: 45696 | B16: SMYTHS TOYS HQ UC | C16: 法国 | D16: 4500156997 | F16: 4500156997-10 | G16: 71152-S001-1 | H16: 71152-S001 | I16: 机械速龙 | J16: 1002 | K16: 0 | L16: 6 | M16: =J16/L16 -> 167 | N16: 45748 | O16: 45744 | Q16: PASS | U16: 45701 | V16: 无 | X16: 客版彩盒翻4500156690 | Y16: 日期码格式：ZURU INC(BVI) 标准格式 日期：按实际生产日期 | Z16: 日期码格式：ZURU INC(BVI) 标准格式 日期：按实际生产日期 Packaging Info: 71152:客版彩卡翻4500156690+MA 5L(9L Warning)说明书 Remark: 1. 此单出法国，所有包装都需要含有法语，需要满足Zuru Standard欧洲标准测试要求； 2. 请准时出货，推期会有罚款； 3. 所有出口法国的产品, 法规规定禁止在包装和共公众用的印刷品中使用矿物油中含有的物质, 包装印刷油墨中含有的MOAH/MOSH的质量浓度不能超过1%, 否则出 货到法国被抽检出现问题, 供应商需要对此负责; | AA16: Ula Zhao | AB16: 2.7 | AC16: =AB16*J16 -> 2705.4 | AD16: 94661-3.28 | AE16: 已入 | AG16: =J16 -> 1002 | AH16: =AG16-J16 -> 0 | AM16: =J16 -> 1002 | AN16: =J16 -> 1002 | AR16: =J16 -> 1002 | AS16: =AS15+AR16 -> 12906
A17: 45709 | B17: MTA Trade | C17: 哈萨克斯坦 | D17: 4500158182 | F17: 4500158182-30 | G17: 71152-S001 | H17: 71152-S001 | I17: 机械速龙 | J17: 120 | K17: 0 | L17: 6 | M17: =J17/L17 -> 20 | N17: 45748 | O17: 45743 | Q17: PASS | U17: 45709 | V17: 无 | W17: 3/10进口商贴纸 | Y17: 日期码格式：ZURU INC(BVI) 标准格式 日期：按实际生产日期 | Z17: 日期码格式：ZURU INC(BVI) 标准格式 日期：按实际生产日期 Packaging Info: 71152 ： 1L MA 包装 + 进口商贴纸， MA 指南 /说明书（如有）； Remark: 整单货期4月1 标准配比 | AA17: Ann Zhang | AB17: 2.7 | AC17: =AB17*J17 -> 324 | AD17: 94763-4.14 | AE17: 已入 | AG17: =J17 -> 120 | AH17: =AG17-J17 -> 0 | AJ17: =J17 -> 120 | AN17: =J17 -> 120 | AR17: =J17 -> 120 | AS17: =AS16+AR17 -> 13026
A18: 45705 | B18: DIAMANT TOYS LTD | C18: 以色列 | D18: 4500153742 | E18: 56053 | F18: 4500153742-20 | G18: 71152-S001 | H18: 71152-S001 | I18: 机械速龙 | J18: 780 | K18: 0 | L18: 6 | M18: =J18/L18 -> 130 | N18: 45761 | O18: =N18-4 -> 45757 | Q18: PASS | U18: 45707 | V18: 无 | W18: 3/17进口商贴纸+彩色贴纸 | Y18: 日期码格式：ZURU INC(BVI) 标准格式 日期：按实际生产日期 | Z18: 日期码格式：ZURU INC(BVI) 标准格式 日期：按实际生产日期 Packaging Info: 71152:1L MA 彩卡+进口商贴纸+彩色贴纸; MA说明书 Remark: | AA18: Lena Huang | AB18: 2.7 | AC18: =AB18*J18 -> 2106 | AD18: 94787-4.17 | AE18: 已入 | AG18: 780 | AH18: =AG18-J18 -> 0 | AJ18: =J18 -> 780 | AN18: =J18 -> 780 | AR18: =J18 -> 780 | AS18: =AS17+AR18 -> 13806
A19: 45723 | B19: Amazon ES | C19: 西班牙 | D19: 4500159389 | E19: Amazon ES: 2ZNG9OOD | F19: 4500159389-10 | G19: 71152-S001-3L | H19: 71152-S001 | I19: 机械速龙 | J19: 750 | K19: 0 | L19: 6 | M19: =J19/L19 -> 125 | N19: 45757 | O19: 45754 | Q19: PASS | U19: 空白外箱 | V19: 有3/17 | W19: 3/10贴纸(UPC#+IT环保标) | Y19: 日期码格式：ZURU INC(BVI) 标准格式 日期：按实际生产日期 | Z19: 日期码格式：ZURU INC(BVI) 标准格式 日期：按实际生产日期 Packaging Info: Amazon ES(71152) 1. 71152：6PCS WINDOW BOX/CTN; MA 3L(23L warning EAN#)A window box+1张贴纸(UPC#+IT环保标)+MA 5L(9L warning)A 说明书 2. 最迟验货不得晚于2025/4/11; Remark: 1.空白外箱（加印带Zuru字样的最新logo，除了邮包盒直接做外箱的产品） + SSCC LABEL一张, 无箱唛，MADE IN CHINA 外箱只印一正一侧。箱唛资料按照给定的 标准去做即可，无需发回我方再行审批(新标准将另行通知)。 (SSCC LABEL竖贴在外箱正面的正中间，贴一面即可,贴纸离外箱边距必须至少3.2CM。如竖贴无法满足要求，则横贴。如横贴也无法满足要求，则竖贴，遮到ZURU lo go无影响), SSCC贴纸由工厂直接跟勤得采购或者工厂自行采购，每一张SSCC Label都是唯一且有不同流水及条码，且需要检查条码是否能正常扫描，另外，此贴纸 印刷不可出现模糊，溢出及粘胶不牢易脱落等现象，如工厂不按此要求导致贴纸有任何问题产生的罚款将由工厂承担一切责任 。 2.出往UK的产品+包装务必打上UKCA logo ，否则客人会退货且当地会有罚款。 3.订单必须经过ZURU QC验货并且通过后方可出货。 4.法国订单要求包装不使用矿物油，请按要求提供以下其中一份文件再出货 ，产品出到法国被相关部门抽检出现包装不符合此要求的，供应商需要为此承担责任， 故此请严格把关。 -油墨物质""由1 ~ 7个芳香环组成的MOAH""的包装检测报告，要求限值≤1.0%； -包装材料清单，包括包装油墨或物质的信息； -油墨制造商的证书； 5.每一批次出货只能有一个生产日期，不可多个生产日期混在同一批次出货；且邮包盒上必须统一加上日期码；外箱对于日期码没有硬性规定； 6.涉及到相关款式会有闪粉的或者微塑料的，请统一默认出无闪粉或者不含微塑料版本； 7.邮包盒及外箱封箱必须是工字型封箱方式； 8.5 Surprise or Mini Brands涉及包装是2个及2个以上的球入PVC桶包装时，单个球上若有UPC#或者EAN#，请用白色贴纸覆盖住； | AA19: Mandy Hu | AB19: 2.7663 | AC19: =AB19*J19 -> 2074.725 | AD19: 94831-4.24 | AE19: 已入 | AG19: 750 | AH19: =AG19-J19 -> 0 | AL19: =J19 -> 750 | AN19: =J19 -> 750 | AR19: =J19 -> 750 | AS19: =AS18+AR19 -> 14556
A20: 45723 | B20: AMAZON UK | C20: 英国 | D20: 4500159544 | E20: Amazon UK:4H6I8RZN | F20: 4500159544-10 | G20: 71152-S001-3L | H20: 71152-S001 | I20: 机械速龙 | J20: 630 | K20: 0 | L20: 6 | M20: =J20/L20 -> 105 | N20: 45757 | O20: 45754 | Q20: PASS | U20: 空白外箱（加印带Zuru字样的最新logo，除了邮包盒直接做外箱的产品） + SSCC LABEL一张, 无箱唛，MADE IN CHINA 外箱只印一正一侧 | V20: 有 | W20: 1张贴纸(UPC#+IT环保标，参考翻单PO#4500159389) | Y20: 日期码格式：ZURU INC(BVI) 标准格式 日期：按实际生产日期 | Z20: 日期码格式：ZURU INC(BVI) 标准格式 日期：按实际生产日期 Packaging Info: Amazon UK(71152)/FR(71152)/DE(71152) 1. 71152：6PCS WINDOW BOX/CTN; MA 3L(23L warning EAN#)A window box+1张贴纸(UPC#+IT环保标，参考翻单PO#4500159389)+MA 5L(9L warning)A 说明书 2.最迟验货不得晚于2025/4/11; Remark: 1.空白外箱（加印带Zuru字样的最新logo，除了邮包盒直接做外箱的产品） + SSCC LABEL一张, 无箱唛，MADE IN CHINA 外箱只印一正一侧。箱唛资料按照给定的 标准去做即可，无需发回我方再行审批(新标准将另行通知)。 (SSCC LABEL竖贴在外箱正面的正中间，贴一面即可,贴纸离外箱边距必须至少3.2CM。如竖贴无法满足要求，则横贴。如横贴也无法满足要求，则竖贴，遮到ZURU lo go无影响), SSCC贴纸由工厂直接跟勤得采购或者工厂自行采购，每一张SSCC Label都是唯一且有不同流水及条码，且需要检查条码是否能正常扫描，另外，此贴纸 印刷不可出现模糊，溢出及粘胶不牢易脱落等现象，如工厂不按此要求导致贴纸有任何问题产生的罚款将由工厂承担一切责任 。 2.出往UK的产品+包装务必打上UKCA logo ，否则客人会退货且当地会有罚款。 3.订单必须经过ZURU QC验货并且通过后方可出货。 4.法国订单要求包装不使用矿物油，请按要求提供以下其中一份文件再出货 ，产品出到法国被相关部门抽检出现包装不符合此要求的，供应商需要为此承担责任， 故此请严格把关。 -油墨物质""由1 ~ 7个芳香环组成的MOAH""的包装检测报告，要求限值≤1.0%； -包装材料清单，包括包装油墨或物质的信息； -油墨制造商的证书； 5.每一批次出货只能有一个生产日期，不可多个生产日期混在同一批次出货；且邮包盒上必须统一加上日期码；外箱对于日期码没有硬性规定； 6.涉及到相关款式会有闪粉的或者微塑料的，请统一默认出无闪粉或者不含微塑料版本； 7.邮包盒及外箱封箱必须是工字型封箱方式； 8.5 Surprise or Mini Brands涉及包装是2个及2个以上的球入PVC桶包装时，单个球上若有UPC#或者EAN#，请用白色贴纸覆盖住； | AA20: Crystal Chen | AB20: 2.6352 | AC20: =AB20*J20 -> 1660.176 | AD20: 94832-4.24 | AE20: 已入 | AG20: 630 | AH20: =AG20-J20 -> 0 | AL20: =J20 -> 630 | AN20: =J20 -> 630 | AR20: =J20 -> 630 | AS20: =AS19+AR20 -> 15186
A21: 45723 | B21: AMAZON UK | C21: 德国 | D21: 4500159544 | E21: Amazon DE:5AMWB58X | F21: 4500159544-20 | G21: 71152-S001-3L | H21: 71152-S001 | I21: 机械速龙 | J21: 498 | K21: 0 | L21: 6 | M21: =J21/L21 -> 83 | N21: 45757 | O21: 45754 | Q21: PASS | U21: 空白外箱（加印带Zuru字样的最新logo，除了邮包盒直接做外箱的产品） + SSCC LABEL一张, 无箱唛，MADE IN CHINA 外箱只印一正一侧 | V21: 有 | W21: 1张贴纸(UPC#+IT环保标，参考翻单PO#4500159389) | Y21: 日期码格式：ZURU INC(BVI) 标准格式 日期：按实际生产日期 | Z21: 日期码格式：ZURU INC(BVI) 标准格式 日期：按实际生产日期 Packaging Info: Amazon UK(71152)/FR(71152)/DE(71152) 1. 71152：6PCS WINDOW BOX/CTN; MA 3L(23L warning EAN#)A window box+1张贴纸(UPC#+IT环保标，参考翻单PO#4500159389)+MA 5L(9L warning)A 说明书 2.最迟验货不得晚于2025/4/11; Remark: 1.空白外箱（加印带Zuru字样的最新logo，除了邮包盒直接做外箱的产品） + SSCC LABEL一张, 无箱唛，MADE IN CHINA 外箱只印一正一侧。箱唛资料按照给定的 标准去做即可，无需发回我方再行审批(新标准将另行通知)。 (SSCC LABEL竖贴在外箱正面的正中间，贴一面即可,贴纸离外箱边距必须至少3.2CM。如竖贴无法满足要求，则横贴。如横贴也无法满足要求，则竖贴，遮到ZURU lo go无影响), SSCC贴纸由工厂直接跟勤得采购或者工厂自行采购，每一张SSCC Label都是唯一且有不同流水及条码，且需要检查条码是否能正常扫描，另外，此贴纸 印刷不可出现模糊，溢出及粘胶不牢易脱落等现象，如工厂不按此要求导致贴纸有任何问题产生的罚款将由工厂承担一切责任 。 2.出往UK的产品+包装务必打上UKCA logo ，否则客人会退货且当地会有罚款。 3.订单必须经过ZURU QC验货并且通过后方可出货。 4.法国订单要求包装不使用矿物油，请按要求提供以下其中一份文件再出货 ，产品出到法国被相关部门抽检出现包装不符合此要求的，供应商需要为此承担责任， 故此请严格把关。 -油墨物质""由1 ~ 7个芳香环组成的MOAH""的包装检测报告，要求限值≤1.0%； -包装材料清单，包括包装油墨或物质的信息； -油墨制造商的证书； 5.每一批次出货只能有一个生产日期，不可多个生产日期混在同一批次出货；且邮包盒上必须统一加上日期码；外箱对于日期码没有硬性规定； 6.涉及到相关款式会有闪粉的或者微塑料的，请统一默认出无闪粉或者不含微塑料版本； 7.邮包盒及外箱封箱必须是工字型封箱方式； 8.5 Surprise or Mini Brands涉及包装是2个及2个以上的球入PVC桶包装时，单个球上若有UPC#或者EAN#，请用白色贴纸覆盖住； | AA21: Crystal Chen | AB21: 2.6352 | AC21: =AB21*J21 -> 1312.3296 | AD21: 94832-4.24 | AE21: 已入 | AG21: 498 | AH21: =AG21-J21 -> 0 | AL21: =J21 -> 498 | AN21: =J21 -> 498 | AR21: =J21 -> 498 | AS21: =AS20+AR21 -> 15684
A22: 45723 | B22: AMAZON UK | C22: 法国 | D22: 4500159544 | E22: Amazon FR: 8X62JYRM | F22: 4500159544-30 | G22: 71152-S001-3L | H22: 71152-S001 | I22: 机械速龙 | J22: 750 | K22: 0 | L22: 6 | M22: =J22/L22 -> 125 | N22: 45757 | O22: 45754 | Q22: PASS | U22: 空白外箱（加印带Zuru字样的最新logo，除了邮包盒直接做外箱的产品） + SSCC LABEL一张, 无箱唛，MADE IN CHINA 外箱只印一正一侧 | V22: 有 | W22: 1张贴纸(UPC#+IT环保标，参考翻单PO#4500159389) | Y22: 日期码格式：ZURU INC(BVI) 标准格式 日期：按实际生产日期 | Z22: 日期码格式：ZURU INC(BVI) 标准格式 日期：按实际生产日期 Packaging Info: Amazon UK(71152)/FR(71152)/DE(71152) 1. 71152：6PCS WINDOW BOX/CTN; MA 3L(23L warning EAN#)A window box+1张贴纸(UPC#+IT环保标，参考翻单PO#4500159389)+MA 5L(9L warning)A 说明书 2.最迟验货不得晚于2025/4/11; Remark: 1.空白外箱（加印带Zuru字样的最新logo，除了邮包盒直接做外箱的产品） + SSCC LABEL一张, 无箱唛，MADE IN CHINA 外箱只印一正一侧。箱唛资料按照给定的 标准去做即可，无需发回我方再行审批(新标准将另行通知)。 (SSCC LABEL竖贴在外箱正面的正中间，贴一面即可,贴纸离外箱边距必须至少3.2CM。如竖贴无法满足要求，则横贴。如横贴也无法满足要求，则竖贴，遮到ZURU lo go无影响), SSCC贴纸由工厂直接跟勤得采购或者工厂自行采购，每一张SSCC Label都是唯一且有不同流水及条码，且需要检查条码是否能正常扫描，另外，此贴纸 印刷不可出现模糊，溢出及粘胶不牢易脱落等现象，如工厂不按此要求导致贴纸有任何问题产生的罚款将由工厂承担一切责任 。 2.出往UK的产品+包装务必打上UKCA logo ，否则客人会退货且当地会有罚款。 3.订单必须经过ZURU QC验货并且通过后方可出货。 4.法国订单要求包装不使用矿物油，请按要求提供以下其中一份文件再出货 ，产品出到法国被相关部门抽检出现包装不符合此要求的，供应商需要为此承担责任， 故此请严格把关。 -油墨物质""由1 ~ 7个芳香环组成的MOAH""的包装检测报告，要求限值≤1.0%； -包装材料清单，包括包装油墨或物质的信息； -油墨制造商的证书； 5.每一批次出货只能有一个生产日期，不可多个生产日期混在同一批次出货；且邮包盒上必须统一加上日期码；外箱对于日期码没有硬性规定； 6.涉及到相关款式会有闪粉的或者微塑料的，请统一默认出无闪粉或者不含微塑料版本； 7.邮包盒及外箱封箱必须是工字型封箱方式； 8.5 Surprise or Mini Brands涉及包装是2个及2个以上的球入PVC桶包装时，单个球上若有UPC#或者EAN#，请用白色贴纸覆盖住； | AA22: Crystal Chen | AB22: 2.6352 | AC22: =AB22*J22 -> 1976.4 | AD22: 94832-4.24 | AE22: 已入 | AG22: 750 | AH22: =AG22-J22 -> 0 | AL22: =J22 -> 750 | AN22: =J22 -> 750 | AR22: =J22 -> 750 | AS22: =AS21+AR22 -> 16434
A23: 45737 | B23: ASIA GOAL LIMITED | C23: 香港 | D23: 4500160929 | E23: AG240425-HK | F23: 4500160929-10 | G23: 71152-S001 | H23: 71152-S001 | I23: 机械速龙 | J23: 240 | K23: 0 | L23: 6 | M23: =J23/L23 -> 40 | N23: 45761 | O23: 45757 | Q23: PASS | U23: 45737 | V23: 无 | W23: 45749 | Y23: 日期码格式：ZURU INC(BVI) 标准格式 日期：按实际生产日期 | Z23: 日期码格式：ZURU INC(BVI) 标准格式 日期：按实际生产日期 Packaging Info: 71152：MA 1L PKG， MA 说明书+1张客供警语贴纸+1张客供电池警语贴纸+1张客供中文警语书 Remark: 此单出香港 | AA23: Doris Shou | AB23: 2.8165 | AC23: =AB23*J23 -> 675.96 | AD23: 94777-4.16 | AE23: 已入 | AG23: 240 | AH23: =AG23-J23 -> 0 | AJ23: =J23 -> 240 | AO23: =J23 -> 240 | AR23: =J23 -> 240 | AS23: =AS22+AR23 -> 16674
A24: 45761 | D24: ZMPO250315 | G24: 71152-S001 | H24: 71152-S001 | I24: 机械速龙 | J24: 120 | K24: 0 | L24: 6 | M24: =J24/L24 -> 20 | N24: 45771 | O24: 45768 | Q24: PASS | Z24: Remark:大货最新版本/大货标准箱装箱/箱唛参照邮件附件;备注： 收到样品订单后尽快安排 ，此订单麻烦在外箱上备注是海运订单/注意样板品质质量要求要高于大货品质质量 ，送货时必须要附带送货单(没有送货单和QC检验合格报告的仓库一律拒绝收货)，请知悉，谢谢！ | AA24: Angus | AD24: 95176-5.30 | AE24: 已入 | AG24: 120 | AH24: 0 | AK24: =J24 -> 120 | AO24: =J24 -> 120 | AR24: =J24 -> 120 | AS24: =AS23+AR24 -> 16794
A25: 45712 | B25: Walmart Central America-HN | C25: 洪都拉斯 | D25: 4500158415 | F25: 4500158415-120 | G25: 71152-S001 | H25: 71152-S001 | I25: 机械速龙 | J25: 72 | K25: 0 | L25: 6 | M25: =J25/L25 -> 12 | N25: 45763 | O25: 45759 | Q25: PASS | U25: 45740 | V25: 无 | W25: UPC条码贴纸+进口商贴纸所有贴纸翻单PO4500158302 | Y25: 日期码格式：ZURU INC(BVI) 标准格式 日期：按实际生产日期 | Z25: 日期码格式：ZURU INC(BVI) 标准格式 日期：按实际生产日期 Packaging Info: 10.71152：MA 3L EAN包装+UPC条码贴纸+MA 多语说明书+进口商贴纸+箱唛 以上所有贴纸翻单PO4500158302 Remark: 1.使用双坑外箱 2.请注意产品包装条形码必须是UPC 3.无第三方验货 15. 71152：2PCS AAA BATTERIES(NOT INCLUDED) | AA25: Ever Li | AB25: 2.7 | AC25: =AB25*J25 -> 194.4 | AD25: 94891-4.30 | AE25: 已入 | AG25: 72 | AH25: =AG25-J25 -> 0 | AL25: =J25 -> 72 | AN25: =J25 -> 72 | AR25: =J25 -> 72 | AS25: =AS24+AR25 -> 16866
A26: 45712 | B26: Walmart Central America-HN | C26: 萨尔瓦多 | D26: 4500158302 | F26: 4500158302-180 | G26: 71152-S001 | H26: 71152-S001 | I26: 机械速龙 | J26: 108 | K26: 0 | L26: 6 | M26: =J26/L26 -> 18 | N26: 45763 | O26: 45759 | Q26: PASS | U26: 45740 | V26: 无 | W26: 45737 | Y26: 日期码格式：ZURU INC(BVI) 标准格式 日期：按实际生产日期 | Z26: 日期码格式：ZURU INC(BVI) 标准格式 日期：按实际生产日期 Packaging Info: 10.71152：MA 3L EAN包装+UPC条码贴纸+MA 多语说明书+进口商贴纸+箱唛 Remark: 1.使用双坑外箱 2.请注意产品包装条形码必须是UPC 3.无第三方验货 15. 71152：2PCS AAA BATTERIES(NOT INCLUDED) 16. 71152：2PCS AAA BATTERIES(NOT INCLUDED) | AA26: Ever Li | AB26: 2.7 | AC26: =AB26*J26 -> 291.6 | AD26: 94865-4.28 | AE26: 已入 | AG26: 108 | AH26: =AG26-J26 -> 0 | AL26: =J26 -> 108 | AN26: =J26 -> 108 | AR26: =J26 -> 108 | AS26: =AS25+AR26 -> 16974
A27: 45714 | B27: Walmart Central America-GT | C27: 危地马拉 | D27: 4500158447 | F27: 4500158447-150 | G27: 71152-S001 | H27: 71152-S001 | I27: 机械速龙 | J27: 198 | K27: 0 | L27: 6 | M27: =J27/L27 -> 33 | N27: 45763 | O27: 45759 | Q27: PASS | U27: 45740 | V27: 无 | W27: UPC条码贴纸+进口商贴纸所有贴纸翻单PO4500158302 | Y27: 日期码格式：ZURU INC(BVI) 标准格式 日期：按实际生产日期 | Z27: 日期码格式：ZURU INC(BVI) 标准格式 日期：按实际生产日期 Packaging Info: 10.71152：MA 3L EAN包装+UPC条码贴纸+MA 多语说明书+进口商贴纸+箱唛 以上所有贴纸翻单PO4500158302 Remark: 1.使用双坑外箱 2.请注意产品包装条形码必须是UPC 3.无第三方验货 71152：2PCS AAA BATTERIES(NOT INCLUDED) | AA27: Ever Li | AB27: 2.7 | AC27: =AB27*J27 -> 534.6 | AD27: 94923-5.5 | AE27: 已入 | AG27: 198 | AH27: =AG27-J27 -> 0 | AL27: =J27 -> 198 | AN27: =J27 -> 198 | AR27: =J27 -> 198 | AS27: =AS26+AR27 -> 17172
A28: 45714 | B28: Walmart Central America-CR | C28: 哥斯达黎加 | D28: 4500158535 | F28: 4500158535-160 | G28: 71152-S001-3L | H28: 71152-S001 | I28: 机械速龙 | J28: 270 | K28: 0 | L28: 6 | M28: =J28/L28 -> 45 | N28: 45763 | O28: 45759 | Q28: PASS | U28: 45740 | V28: 无 | W28: UPC条码贴纸+进口商贴纸所有贴纸翻单PO4500158302 | Y28: 日期码格式：ZURU INC(BVI) 标准格式 日期：按实际生产日期 | Z28: 日期码格式：ZURU INC(BVI) 标准格式 日期：按实际生产日期 Packaging Info: 10.71152：MA 3L EAN包装+UPC条码贴纸+MA 多语说明书+进口商贴纸+箱唛 以上贴纸翻单PO 4500158302 Remark: 1.使用双坑外箱 2.请注意产品包装条形码必须是UPC 3.无第三方验货 71152：2PCS AAA BATTERIES(NOT INCLUDED) | AA28: Ever Li | AB28: 2.7 | AC28: =AB28*J28 -> 729 | AD28: 94882-4.29 | AE28: 已入 | AG28: 270 | AH28: =AG28-J28 -> 0 | AL28: =J28 -> 270 | AO28: =J28 -> 270 | AR28: =J28 -> 270 | AS28: =AS27+AR28 -> 17442
A29: 45756 | B29: DIAMANT TOYS LTD | C29: 以色列 | D29: 4500163062 | E29: 56053 | F29: 4500163062-20 | G29: 71152-S001 | H29: 71152-S001 | I29: 机械速龙 | J29: 2220 | K29: 0 | L29: 6 | M29: =J29/L29 -> 370 | N29: 45789 | O29: 45785 | Q29: PASS | U29: 45758 | V29: 无 | W29: 进口商贴纸(翻4500153742)+彩色贴纸(翻4500153742) | Z29: 日期码格式：ZURU INC(BVI) 标准格式 日期：按实际生产日期 Packaging Info: 71152：1L MA包装+进口商贴纸(翻4500153742)+彩色贴纸(翻4500153742); MA说明书 Remark: | AA29: Lena Huang | AB29: 2.6214 | AC29: =AB29*J29 -> 5819.508 | AD29: 94890-4.30 | AE29: 已入 | AG29: =1806+30+384 -> 2220 | AH29: =AG29-J29 -> 0 | AK29: =J29 -> 2220 | AO29: =J29 -> 2220 | AR29: =J29 -> 2220 | AS29: =AS28+AR29 -> 19662
A30: 45713 | B30: HEB GROCERY COMPANY, LP | C30: 美国 | D30: 4500158419 | E30: PO#60X273616 | F30: 4500158419-20 | G30: 71152-S003 | H30: 71152-S003 | I30: 机械速龙 | J30: 1272 | K30: 0 | L30: 4 | M30: =J30/L30 -> 318 | N30: 45769 | O30: 45765 | Q30: PASS | U30: 45720 | V30: 无 | W30: 无 | Y30: 日期码格式：ZURU INC(BVI) 标准格式 日期：按实际生产日期 | Z30: 日期码格式：ZURU INC(BVI) 标准格式 日期：按实际生产日期 Packaging Info: 1. 包材：ZURU MA 1L UPC最新版本，出口美国: Remark: 2. 日期跟踪码：ZURU标准格式日期码，产品包装及产品本身都必须有ZURU标准格式日期码，并且确保两者日期码的格式和时间保持一致(请自行调整具体年月日生 产期，但不能为周末） 3. 大货样 需4月15日前需寄出每款每色3套大货样板，样板须跟大货一模一样（含日期码）。 样板一套将给到美国HEB，两套寄到以下深圳利丰地址，到时利丰会回签一套用于第三方100%大货验货。 回签的样板工厂需要长期保存好，只要产品没更新每次的第三方验货都是用这套样板做参考不再走客户签样流程。 * 一套样板寄到以下地址 深圳雨禾伟业实业有限公司 地址：广东省深圳市罗湖区东门南路1006号文锦渡口岸大厦B栋7楼 收件人：Elsa 电话：0755 6688 1988 Ext3337 *2套寄到以下地址（因是签样，样板需寄齐大货会出的所有产品，包括散件/配件）： Li Fung 深圳市福田区绒花路8号深福保大厦附楼3楼。 收件人： Yoland Dai 电话：+0755 8825 3756 4. 验货+ 抽板 （同一天进行） 预约4月23日第三方（利丰）到工厂做100%大货现场验货和抽板，验货需打印EPM出来跟客户回签样板供第三方验货参考。 PS:EPM是跟单提供。 抽板： 利丰验货员现场针对指定款随机抽板6PCS 成品， 工厂需把抽板寄到以下MTS地址做测试，测试通过后才能出货；如产品有油漆的工厂需额外准备5G/色的油漆涂在 同材质胶件上(面积类似A4纸大小)一并寄出； 实验室收件地址： 东莞现代产品整理服务有限公司（MTS） 广东省东莞市寮步镇新旧围村良平路76号 收件人：Cherry Wang （汪单） Tel: +86 769- 8112 0818 ext.893 抽板有随样文件TRF（跟单提供），工厂在寄样时打印出来放纸箱内随样寄走 5. 出货配比： #71152-S003-ROBO ALIVE-DINOSAUR-SERIES 1-RAPTOR-WINDOW BOX,4PCS/CTN 6. ZURU QA验货时需拍齐每款角色的产品和产品包装上的日期码照片（供实验室review） | AA30: Elsa Zheng | AB30: 2.75 | AC30: =AB30*J30 -> 3498 | AD30: ZB00763-7.17 | AE30: 已入 | AG30: =1248+24 -> 1272 | AH30: =AG30-J30 -> 0 | AK30: =J30 -> 1272 | AO30: =J30 -> 1272 | AR30: =J30 -> 1272 | AS30: =AS29+AR30 -> 20934
A31: 45729 | B31: Babyhouse | C31: 乌兹别克斯坦 | D31: 4500159866 | F31: 4500159866-90 | G31: 71152-S001 | H31: 71152-S001 | I31: 机械速龙 | J31: 120 | K31: 0 | L31: 6 | M31: =J31/L31 -> 20 | N31: 45769 | O31: 45765 | Q31: PASS | T31: 否 | U31: 45729 | V31: 无 | W31: 3/14进口商贴纸 | Y31: 日期码格式：ZURU INC(BVI) 标准格式 日期：按实际生产日期 | Z31: 日期码格式：ZURU INC(BVI) 标准格式 日期：按实际生产日期 Packaging Info: 71152 : 1L MA 彩卡+ 进口商贴纸 ; MA 说明书/指南（如有）; Remark: 标准配比 | AA31: Ann Zhang | AB31: 2.7 | AC31: =AB31*J31 -> 324 | AD31: 94879-4.29 | AE31: 已入 | AG31: =J31 -> 120 | AH31: =AG31-J31 -> 0 | AK31: =J31 -> 120 | AO31: =J31 -> 120 | AR31: =J31 -> 120 | AS31: =AS30+AR31 -> 21054
A32: 45735 | B32: MTA Trade | C32: 哈萨克斯坦 | D32: 4500160671 | F32: 4500160671-100 | G32: 71152-S001 | H32: 71152-S001 | I32: 机械速龙 | J32: 276 | K32: 0 | L32: 6 | M32: =J32/L32 -> 46 | N32: 45772 | O32: 45768 | Q32: PASS | T32: 否 | U32: 45735 | V32: 无 | W32: 进口商贴纸(翻PO4500158182) | Y32: 日期码格式：ZURU INC(BVI) 标准格式 日期：按实际生产日期 | Z32: 日期码格式：ZURU INC(BVI) 标准格式 日期：按实际生产日期 Packaging Info: 71152：MA UPC 彩卡+进口商贴纸(翻PO4500158182)；MA说明书 Remark: 标准配比 | AA32: Cora Zhou | AB32: 2.6717 | AC32: =AB32*J32 -> 737.3892 | AD32: 94843-4.25 | AE32: 已入 | AG32: 276 | AH32: =AG32-J32 -> 0 | AK32: =J32 -> 276 | AO32: =J32 -> 276 | AR32: =J32 -> 276 | AS32: =AS31+AR32 -> 21330
A33: 45734 | B33: ZURU Germany GMBH | C33: 德国 | D33: 4500160629 | E33: 5200006404 | F33: 4500160629-10 | G33: 71152-S001-3L | H33: 71152-S001-MTS | I33: 机械速龙 | J33: 1200 | K33: 0 | L33: 6 | M33: =J33/L33 -> 200 | N33: 45772 | O33: 45768 | Q33: PASS | T33: 否 | U33: 45735 | V33: 无 | W33: 45740 | Y33: 日期码格式：ZURU INC(BVI) 标准格式 日期：按实际生产日期 | Z33: 日期码格式：ZURU INC(BVI) 标准格式 日期：按实际生产日期 Packaging Info: 71152: MA 3L_23L EAN 包装+意大利环保标贴纸 + 5L_9L MA说明书 +WEEE不带电池走货黑白说明书 EAN#4894680042742 Remark: 1.德国内销单，需要通过ZURU 验货结果后才能出货 (工厂需要主动提前同ZURU QC预约验货避免延期出货造成不必要麻烦)； 2. 若有特定款有特殊外箱条码要求时,需要明确列出产品款对应的具体外箱条码号码/条码类型 (若无,可以忽略此需求) 3.所有出口欧洲的产品, 法规规定禁止在包装和共公众用的印刷品中使用矿物油中含有的物质, 包装印刷油墨中含有的MOAH/MOSH的质量浓度不能超过1%, 否则出货 到法国被抽检出现问题, 供应商需要对此负责; 4. date code: 外箱日期码要晚于或等于产品日期码，不能早于产品的日期码 5. 所有电子产品身上需要加字唛，为ZURU FRANCE 地址 (如无电子产品，或者产品布标有此地址，可忽略此信息) ZURU France 1/3, Rue d'Argenteuil 95210 SAINT-GRATIEN, FRANCE 6. 装柜时需要按照款式号码从小到大一款款依次装,避免终端仓库卸货混乱.若一个柜子涉及到几个不同国家内销单,装柜时需要一个国家装完后再装另一个国家的 产品,依次装柜,避免终端仓库因不同国家不同库位位置卸货混乱. (此点需要同工厂装柜人员强调)" | AA33: SD04 | AB33: 2.5407 | AC33: =AB33*J33 -> 3048.84 | AD33: 94892-4.30 | AE33: 已入 | AG33: 1200 | AH33: =AG33-J33 -> 0 | AL33: =J33 -> 1200 | AO33: =J33 -> 1200 | AR33: =J33 -> 1200 | AS33: =AS32+AR33 -> 22530
A34: 45736 | B34: THE ENTERTAINER | C34: 英国 | D34: 4500160901 | E34: 4500160901-1: FB12977 | F34: 4500160901-90 | G34: 71152-S001 | H34: 71152-S001 | I34: 机械速龙 | J34: 996 | K34: 0 | L34: 6 | M34: =J34/L34 -> 166 | N34: 45772 | O34: 45768 | Q34: PASS | T34: 是 | U34: 45740 | V34: 无 | W34: 3/24一张2国语言电池说明书(英语+阿拉伯语) | Y34: 日期码格式：ZURU INC(BVI) 标准格式 日期：按实际生产日期 | Z34: 日期码格式：ZURU INC(BVI) 标准格式 日期：按实际生产日期 Packaging Info: 71152-S001: MA 最新1L UPC包装+一张2国语言电池说明书(英语+阿拉伯语); BARCODE: 193052079190 Remark: *MA版本按工厂现有最新库存即可，订单出英国，请注意检查产品及包装应带UKCA图标，包装显示ZURU UK LTD信息，QC同事请查核，如有问题与跟单确认 *生产日期按实际（法定工作日），按ZURU标准格式即可 ，但是请知悉包装日期码需要早于或者等于外箱日期码 ，不能晚于外箱日期码 *请注意所有订单都需要经过ZURU QC验货并且通过后方可出货 *所有产品按符合欧洲标准走货，需要是不含微塑料版本 。 *涉及到硼的，如可选择情况下应使用低硼版本 （slime 类别低硼一般低于300ppm)，无选择的应与跟单复核再安排 。 *条码以订单显示为准 ，请安排生产前先核对 ，有问题请提出。 *订单对应客户3个PO号 ，备注有显示 ，注意分开做货/验货/装柜 ，混装有罚款。 * 大货样： 请在4/10 前寄出每款1整套大货样到罗湖办公室7B Sandy Shao 收。 | AA34: Sandy Shao | AB34: 2.7663 | AC34: =AB34*J34 -> 2755.2348 | AD34: 94866-4.28 | AE34: 已入 | AG34: 996 | AH34: =AG34-J34 -> 0 | AK34: =J34 -> 996 | AO34: =J34 -> 996 | AR34: =J34 -> 996 | AS34: =AS33+AR34 -> 23526
A35: 45736 | B35: THE ENTERTAINER | C35: 英国 | D35: 4500160901 | E35: 4500160901-2: FB12978 | F35: 4500160901-180 | G35: 71152-S001 | H35: 71152-S001 | I35: 机械速龙 | J35: 1002 | K35: 0 | L35: 6 | M35: =J35/L35 -> 167 | N35: 45772 | O35: 45768 | Q35: PASS | T35: 是 | U35: 45740 | V35: 无 | W35: 3/24一张2国语言电池说明书(英语+阿拉伯语) | Y35: 日期码格式：ZURU INC(BVI) 标准格式 日期：按实际生产日期 | Z35: 日期码格式：ZURU INC(BVI) 标准格式 日期：按实际生产日期 Packaging Info: 71152-S001: MA 最新1L UPC包装+一张2国语言电池说明书(英语+阿拉伯语); BARCODE: 193052079190 Remark: *MA版本按工厂现有最新库存即可，订单出英国，请注意检查产品及包装应带UKCA图标，包装显示ZURU UK LTD信息，QC同事请查核，如有问题与跟单确认 *生产日期按实际（法定工作日），按ZURU标准格式即可 ，但是请知悉包装日期码需要早于或者等于外箱日期码 ，不能晚于外箱日期码 *请注意所有订单都需要经过ZURU QC验货并且通过后方可出货 *所有产品按符合欧洲标准走货，需要是不含微塑料版本 。 *涉及到硼的，如可选择情况下应使用低硼版本 （slime 类别低硼一般低于300ppm)，无选择的应与跟单复核再安排 。 *条码以订单显示为准 ，请安排生产前先核对 ，有问题请提出。 *订单对应客户3个PO号 ，备注有显示 ，注意分开做货/验货/装柜 ，混装有罚款。 * 大货样： 请在4/10 前寄出每款1整套大货样到罗湖办公室7B Sandy Shao 收。 | AA35: Sandy Shao | AB35: 2.6352 | AC35: =AB35*J35 -> 2640.4704 | AD35: 94866-4.28 | AE35: 已入 | AG35: 1002 | AH35: =AG35-J35 -> 0 | AK35: =J35 -> 1002 | AO35: =J35 -> 1002 | AR35: =J35 -> 1002 | AS35: =AS34+AR35 -> 24528
A36: 45736 | B36: THE ENTERTAINER | C36: 英国 | D36: 4500160901 | E36: 4500160901-3: FB12979 | F36: 4500160901-270 | G36: 71152-S001 | H36: 71152-S001 | I36: 机械速龙 | J36: 1002 | K36: 0 | L36: 6 | M36: =J36/L36 -> 167 | N36: 45772 | O36: 45768 | Q36: PASS | T36: 是 | U36: 45740 | V36: 无 | W36: 3/24一张2国语言电池说明书(英语+阿拉伯语) | Y36: 日期码格式：ZURU INC(BVI) 标准格式 日期：按实际生产日期 | Z36: 日期码格式：ZURU INC(BVI) 标准格式 日期：按实际生产日期 Packaging Info: 71152-S001: MA 最新1L UPC包装+一张2国语言电池说明书(英语+阿拉伯语); BARCODE: 193052079190 Remark: *MA版本按工厂现有最新库存即可，订单出英国，请注意检查产品及包装应带UKCA图标，包装显示ZURU UK LTD信息，QC同事请查核，如有问题与跟单确认 *生产日期按实际（法定工作日），按ZURU标准格式即可 ，但是请知悉包装日期码需要早于或者等于外箱日期码 ，不能晚于外箱日期码 *请注意所有订单都需要经过ZURU QC验货并且通过后方可出货 *所有产品按符合欧洲标准走货，需要是不含微塑料版本 。 *涉及到硼的，如可选择情况下应使用低硼版本 （slime 类别低硼一般低于300ppm)，无选择的应与跟单复核再安排 。 *条码以订单显示为准 ，请安排生产前先核对 ，有问题请提出。 *订单对应客户3个PO号 ，备注有显示 ，注意分开做货/验货/装柜 ，混装有罚款。 * 大货样： 请在4/10 前寄出每款1整套大货样到罗湖办公室7B Sandy Shao 收。 | AA36: Sandy Shao | AB36: 2.6352 | AC36: =AB36*J36 -> 2640.4704 | AD36: 94866-4.28 | AE36: 已入 | AG36: =996+6 -> 1002 | AH36: =AG36-J36 -> 0 | AK36: =J36 -> 1002 | AO36: =J36 -> 1002 | AR36: =J36 -> 1002 | AS36: =AS35+AR36 -> 25530
A37: 45733 | B37: WAL-MART CANADA CORP. | C37: 加拿大 | D37: 4500160504 | E37: 9900923487 | F37: 4500160504-10 | G37: 71152-S002 | H37: 71152-S002 | I37: 机械速龙 | J37: 2154 | K37: 0 | L37: 3 | M37: =J37/L37 -> 718 | N37: 45776 | O37: 45772 | Q37: PASS | T37: 是 | U37: 45750 | V37: 有 | W37: 3/16UPC贴纸(UPC:193052079190) | Y37: 日期码格式：ZURU INC(BVI) 标准格式 日期：按实际生产日期 | Z37: 日期码格式：ZURU INC(BVI) 标准格式 日期：按实际生产日期 Packaging Info: #71152： MA3L彩盒+UPC贴纸(UPC:193052079190)+MA5L说明书(B版) 产品配比： 7 Assortment, Polar bear: Penguin: Walrus: Mammoth: Owl: Seal: Snow man=10:10:10:10:10:8:2. Snow man is the rare item. Remark: 1. 此单有箱唛； 3. 此单有第三方验货，烦请多备包装物料； 4. #71152需于2025/4/18安排签版, 签样数量：大货样各3PCS； 8. #71152 需于2025/4/28安排抽办测试, 抽办数量：大货各4 pcs 11. UPC贴纸：必须在原来错误的条码上用黑色粗头笔涂黑直至不能扫描，再贴上正确的UPC; ********************* a. 请确保产品符合1999年版本的加拿大环境保护法(CEPA)和2012年禁止某些有毒物质法规的要求。该产品不含任何在加拿大禁用的化学物质，包括但不限于有毒物 质清单中列出的化学物质，并且在为加拿大沃尔玛生产产品期间没有使用任何禁用化学物质。 Supplier certify that the products comply with the requirements of Canadian Environmental Protection Act, 1999 (CEPA), Prohibition of Certain To xic Substances Regulations, 2012. The products do not contain any chemicals that are banned in Canada, including but not limited to those listed in the Toxic Substances List and no banned chemicals were used during the manufacturing of product for Walmart Canada. 附件列表： (1) Letter of Guarantee for Canada banned chemicals - (1-5CA) b. 请确保产品在均质材料中的汞浓度不超过0.1%（按重量计）。 Supplier certify that the WAL-MART vendor products does not have a mercury concentration of more than 0.1% by weight in homogeneous material. 附件列表： (1) Letter of Guarantee for Mercury COC c. 请确保产品的塑料材料不含以下物质（SOR 2011-17 27B): Supplier certify that the plastic materials do not contain the following substances(SOR 2011-17 27B): (a) carbon tetrachloride or any substance that contains it; (b) methyl alcohol or any substance thay contains >1.0%; (c) petroleum distillates or any substance that contains >10% weight to volume of petroleum distillates; (d) benzene; (e) turpentine or any substance that contains >10% weight to volume of turpentine; (f) boric acid or salts of boric acid; or (g) ethyl ether. 附件列表： (1) Letter of Guarantee for WM CA-Other prohibited substances in plastic(less than 3 years) | AA37: Monica Zhou | AB37: 2.75 | AC37: =AB37*J37 -> 5923.5 | AD37: 95077R1-5.27 | AE37: 已入 | AG37: 2154 | AH37: =AG37-J37 -> 0 | AL37: =J37 -> 2154 | AO37: =J37 -> 2154 | AR37: =J37 -> 2154 | AS37: =AS36+AR37 -> 27684
A38: 45744 | B38: AB Gee of Ripley Ltd. | C38: 英国 | D38: 4500161792 | E38: 777 1MAY25 | F38: 4500161792-80 | G38: 71152-S001 | H38: 71152-S001 | I38: 机械速龙 | J38: 504 | K38: 0 | L38: 6 | M38: =J38/L38 -> 84 | N38: 45789 | O38: 45785 | Q38: PASS | T38: 否 | U38: 45761 | V38: 无 | W38: ZURU地址贴纸 | Z38: 日期码格式：ZURU INC(BVI) 标准格式 日期：按实际生产日期 Packaging Info: MA 最新UPC包装，各款的条码如下，请先检查条码是否正确再安排做货，如有问题请告知 71152-S001:193052079190 配比跟MA Remark: 1.产品及包装需要印UKCA图标，包装需要有ZURU UK LTD/ZURU France地址信息，QC同事请核查，如有问题与跟单确认。 2. 需要符合欧洲标准不能含有闪粉和微塑料，否则不和法规会有客诉产生 | AA38: Yoga Huang | AB38: 2.7663 | AC38: =AB38*J38 -> 1394.2152 | AD38: 94978-5.14 | AE38: 已入 | AG38: 504 | AH38: =AG38-J38 -> 0 | AK38: =J38 -> 504 | AN38: =J38 -> 504 | AR38: =J38 -> 504 | AS38: =AS37+AR38 -> 28188
A39: 45748 | B39: T. PLANET SHOPS SL | C39: 西班牙 | D39: 4500162134 | F39: 4500162134-30 | G39: 71152-S001-3L | H39: 71152-S001 | I39: 机械速龙 | J39: 1200 | K39: 0 | L39: 6 | M39: =J39/L39 -> 200 | N39: 45789 | O39: 45785 | Q39: PASS | T39: 是 | U39: 45761 | V39: 无 | W39: 45768 | Z39: 日期码格式：20250202 日期： Packaging Info: 71152:MA A 3L彩盒含EAN条码+进口商贴纸+产品贴纸+MAB版5L+9L说明书 Remark: 1, 此货出西班牙，需满足EU测试标准要求<(>&<)> 微塑料需符合法规。另外请确保所有包装都有西班牙环保标。 2，出货前两周需寄2-3套大货样品，请多备料 3, 此客人推期有罚款，请按时完货 4, 出货前要验货图片给客人确认OK后才出货 6. 其他款，若产品有比例使用ZURU STD 比例 8. 客户指定日期码码20250202，包装/产品/外箱需保持一致 | AA39: Mary Zhong | AB39: 2.6352 | AC39: =AB39*J39 -> 3162.24 | AD39: 95140-5.30 | AE39: 已入 | AG39: 1200 | AH39: =AG39-J39 -> 0 | AL39: =J39 -> 1200 | AO39: =J39 -> 1200 | AR39: =J39 -> 1200 | AS39: =AS38+AR39 -> 29388
A40: 45729 | B40: WM MORRISON SUPERMARKET PLC | C40: 英国 | D40: 4500159816 | E40: 14292169 | F40: 4500159816-40 | G40: 71152-S001 | H40: 71152-S001 | I40: 机械速龙 | J40: 6030 | K40: 0 | L40: 6 | M40: =J40/L40 -> 1005 | N40: 45772 | O40: 45768 | Q40: PASS | T40: 否 | U40: 45740 | V40: 无 | W40: 5/7防盗贴纸 | Y40: 日期码格式：ZURU INC(BVI) 标准格式 日期：按实际生产日期 | Z40: 日期码格式：ZURU INC(BVI) 标准格式 日期：按实际生产日期 Packaging Info: 4.71152-S001:MA 1L 最新UPC包装+1张黄色小圆贴防盗贴纸(贴纸类型9472521: 18MM 18mm yellow EAS label)+1张白色长方形防盗贴（贴纸类型10111887：410 ECO N），请工厂自行跟checkpoint供应商订购贴纸 UPC#193052079190，请先检查包装条码是否正确再安排做货 Remark: 1）外箱有条码要求，排版时请留意并请确保条码清晰可扫描（封箱胶不要黏到条码上), 否则客人会有罚款。 2) 订单出英国，产品及包装需要印UKCA图标，包装需要有ZURU UK LTD/ZURU France地址信息，QC同事请查核，如有问题与跟单确认。 3) 箱唛日期码与包装保持一致 4) 若外箱重量超过16KGS，请提前告知ZURU跟单，需要客人批准才能出货，并且外箱需要印2 man lift标志 | AA40: Yoga Huang | AB40: 2.4786 | AC40: =AB40*J40 -> 14945.958 | AD40: 94975-5.12 | AE40: 已入 | AG40: =4884+1146 -> 6030 | AH40: =AG40-J40 -> 0 | AJ40: =J40 -> 6030 | AO40: =J40 -> 6030 | AR40: =J40 -> 6030 | AS40: =AS39+AR40 -> 35418
A41: 45737 | B41: PT.MAP Aktif Adiperkasa, Tbk | C41: 印度尼西亚 | D41: 4500161027 | E41: 250218-3MAAJKTQ325-ZURU | F41: 4500161027-80 | G41: 71152-S001 | H41: 71152-S001 | I41: 机械速龙 | J41: 252 | K41: 0 | L41: 6 | M41: =J41/L41 -> 42 | N41: 45784 | O41: 45780 | Q41: PASS | T41: 否 | U41: 45747 | V41: 无 | W41: 1张进口商贴纸贴纸AW、位置图翻单如下： 71152-4500155574 | Y41: 日期码格式：ZURU INC(BVI) 标准格式 日期：按实际生产日期 | Z41: 日期码格式：ZURU INC(BVI) 标准格式 日期：按实际生产日期 Packaging Info: MA UPC包装（优先1L)+1张进口商贴纸 所有item使用含电池信息的进口商贴纸 贴纸AW、位置图翻单如下： 71152-4500155574 其他items贴纸AW、位置图待提供 1.可能会被抽大货样做测试，请多备料，CRD前半个月会通知是否有抽到该订单中的item。 2.此订单送仓，送仓后会有第三方验货，所以需要按CRD准时完货。 Remark: 71152-2PCS AAA BATTERIES(NOT INCLUDED) | AA41: Emma Wu | AB41: 2.7663 | AC41: =AB41*J41 -> 697.1076 | AD41: 94972R1-5.12 | AE41: 已入 | AG41: 252 | AH41: =AG41-J41 -> 0 | AK41: =J41 -> 252 | AO41: =J41 -> 252 | AR41: =J41 -> 252 | AS41: =AS40+AR41 -> 35670
...

Sheet 半成品MA
B2: 71152机械龙 半成品生产MA
B3: 日期 | C3: MA订单号码 | D3: ITEM | E3: 名称 | H3: 合计 | I3: 要求完成日期 | J3: 备注
B4: 45678 | C4: MA_RR_1527 | D4: 71152 | E4: 机械龙 | H4: 50000 | I4: 45731
B5: 45729 | C5: MA_RR_1589 | D5: 71152 | E5: 机械龙 | H5: 100000 | I5: 45777
B6: 45764 | C6: MA_RR_1626 | D6: 71152 | E6: 机械龙 | H6: 40000 | I6: 45808
B7: 45785 | C7: MA_RR_1636 | D7: 71152 | E7: 机械龙 | H7: 50000 | I7: 45828
B8: 45804 | C8: MA_RR_1686 | D8: 71152 | E8: 机械龙 | H8: 100000 | I8: 45848
B9: 45827 | C9: MA_RR_1739 | D9: 71152 | E9: 机械龙 | H9: 50000 | I9: 45869
B10: 45847 | C10: MA_RR_1784 | D10: 71152 | E10: 机械龙 | H10: 50000 | I10: 45889
B11: 45896 | C11: MA_RR_1858 | D11: 71152 | E11: 机械龙 | H11: 50000 | I11: 45950
B12: 45923 | C12: MA_RR_1897 | D12: 71152 | E12: 机械龙 | H12: 40000 | I12: 45986
B13: 45951 | C13: MA_RR_1920 | D13: 71152 | E13: 机械龙 | H13: 30000 | I13: 46006
B14: 45992 | C14: MA_RR_1986 | D14: 71152 | E14: 机械龙 | H14: 50000 | I14: 45680
B15: 46017 | C15: MA_RR_2032 | D15: 71152 | E15: 机械龙 | H15: 40000 | I15: 46077
B16: 46051 | C16: MA_RR_2095 | D16: 71152 | E16: 机械龙 | H16: 30000 | I16: 46116
E23: MA合计 | F23: 0 | G23: =SUM(G4:G10) -> 0 | H23: =SUM(H4:H22) -> 680000
G24: 接单总数 | H24: ='71152'!AR557 -> 109073
G25: MA剩余 | H25: =H23-H24 -> 570927
G26: MA剩余占MA数比率 | H26: =H25/H23 -> 0.83959853

Sheet 包装MA
B1: 71152 彩盒/说明书 MA
B2: 放MA日期 | C2: MA订单号 | D2: 名称 | E2: MA订单号码 | F2: 货号 | G2: 数量 | H2: 语言 | I2: 版本号 | J2: 1L 标准版彩盒 | K2: 3L 标准版彩盒 | L2: 5L 说明书 | M2: 客版彩盒 | N2: 客版说明书 | O2: Endcap EC展架
B3: 45705 | D3: Window Box | E3: 1000025812 | F3: 71152 | G3: 20000 | H3: 1L彩盒 | I3: A | J3: 20000
B4: 45705 | D4: Instruction Sheet | E4: 1000025814 | F4: 71152 | G4: 30000 | H4: 说明书 | I4: A | L4: 30000
B5: 45727 | D5: Window Box | E5: 1000026190 | F5: 71152 | G5: 10000 | H5: 彩盒 | I5: A | K5: 10000
B6: 45729 | D6: Window Box | E6: 1000026284 | F6: 71152 | G6: 50000 | H6: 1L B版本彩盒 | I6: B | J6: =G6 -> 50000
B7: 45729 | D7: Instruction Sheet | E7: 1000026285 | F7: 71152 | G7: 60000 | H7: 5L B版本说明书 | I7: B | L7: =G7 -> 60000
B8: 45729 | D8: Window Box | E8: 1000026280 | F8: 71152 | G8: 10000 | H8: 3L 彩盒 | I8: A | K8: 10000
B9: 45749 | C9: 兴富利（B) | D9: Window Box | E9: 1000026874 | F9: 71152 | G9: 30000 | H9: 1L彩盒 | I9: B | J9: 30000
B10: 45749 | D10: Instruction Sheet | E10: 1000026875 | F10: 71152 | G10: 20000 | H10: 5L B版本说明书 | I10: B | L10: 80000
B11: 45749 | C11: 华茂（3L） | D11: Window Box | E11: 1000026875 | F11: 71152 | G11: 50000 | H11: 3L 彩盒 | I11: A | K11: 50000
B12: 45793 | D12: Instruction Sheet | E12: 1000026876 | F12: 71152 | G12: 50000 | H12: 1L B版本彩盒 | I12: B | J12: 50000 | L12: 50000 | P12: 说明书不放MA 自行订购
B13: 45804 | D13: Window Box | E13: 1000028455 | F13: 71152 | G13: 50000 | H13: 1L B版本彩盒 | I13: B | J13: 50000
B14: 45804 | D14: Window Box | E14: 1000028456 | F14: 71152 | G14: 10000 | H14: 3L 彩盒 | I14: A | K14: 10000 | L14: 60000
B15: 45827 | D15: Window Box | E15: 1000029146 | F15: 71152 | G15: 30000 | H15: 1L B版本彩盒 | I15: B | J15: 30000
B16: 45827 | D16: Window Box | E16: 1000029147 | F16: 71152 | G16: 20000 | H16: 3L 彩盒 | I16: A | K16: 20000 | L16: 50000
B17: 45847 | D17: Window Box | E17: 1000029906 | F17: 71152 | G17: 30000 | H17: 1L B版本彩盒 | I17: B | J17: 30000
B18: 45847 | D18: Window Box | E18: 1000029907 | F18: 71152 | G18: 10000 | H18: 3L 彩盒 | I18: A | K18: 10000 | L18: 40000
B19: 45870 | D19: Window Box | E19: 1000030640 | F19: 71152 | G19: 20000 | H19: 1L彩盒 | I19: B | J19: 20000
B20: 45870 | D20: Window Box | E20: 1000030641 | F20: 71152 | G20: 10000 | H20: 3L 彩盒 | I20: A | K20: 10000 | L20: 30000
B21: 45888 | D21: Window Box | E21: 1000031131 | F21: 71152 | G21: 20000 | H21: 1L B版本彩盒 | I21: B | J21: 20000
B22: 45898 | D22: Window Box | E22: 1000031568 | F22: 71152 | G22: 30000 | H22: 1L B版本彩盒 | I22: B | J22: 30000 | L22: 50000
B23: 45929 | D23: Window Box | E23: 1000032536 | F23: 71152 | G23: 30000 | H23: 1L B版本彩盒 | I23: B | J23: 30000
B24: 45929 | D24: Instruction sheet | F24: 71152 | G24: 3000 | H24: 6L客版说明书 | N24: 3000
B25: 45954 | D25: Window Box | E25: 1000033329 | F25: 71152 | G25: 10000 | H25: 1L B版本彩盒 | I25: B | J25: 10000 | L25: 40000
B26: 45954 | D26: Window Box | E26: 1000033330 | F26: 71152 | G26: 10000 | H26: 3L B版本彩盒 | I26: B | K26: 10000
B27: 45995 | D27: Window Box | E27: 1000034704 | F27: 71152 | G27: 50000 | H27: 1L B版本彩盒 | I27: B | J27: 50000 | L27: 50000
B28: 46022 | D28: Window Box | E28: 1000035473 | F28: 71152 | G28: 30000 | H28: 1L | I28: B | J28: 30000 | L28: 30000
I33: 合计 | J33: =SUM(J3:J31) -> 450000 | K33: =SUM(K4:K31) -> 130000 | L33: =SUM(L4:L31) -> 570000 | M33: =22512+SUM(M2:M32) -> 22512 | N33: =SUM(N3:N32) -> 3000
I34: 接单总数 | J34: ='71152'!AJ553+'71152'!AK553 -> 433535 | K34: ='71152'!AL553 -> 124377 | L34: =SUM('71152'!AN553:AO553) -> 538094 | M34: ='71152'!AM553 -> 23112 | N34: ='71152'!AP553 -> 0 | O34: ='71152'!AQ553 -> 0
I36: 剩余数 | J36: =J33-J34 -> 16465 | K36: =K33-K34 -> 5623 | L36: =L33-L34 -> 31906 | M36: =M33-M34 -> -600 | N36: =N33-N34 -> 3000 | O36: =O33-O34 -> 0

Sheet 取消單
A1: 接单日期 | B1: 第三方客户名称 | C1: 国家 | D1: PO号 | E1: 客PO号 | F1: SKU | G1: 系统货号 | H1: ITEM# | I1: 中文名 | J1: PO数量 (pcs) | K1: 内箱装箱数量(pcs) | L1: 外箱装箱数量(pcs) | M1: 总箱数 | N1: 客PO期 | O1: 验货期 | P1: 第三方验货期 | Q1: 驗貨結果 | R1: 船期SO | S1: 贴纸情况 | T1: 箱唛资料（收到箱唛日期） | U1: 外箱贴纸 | V1: 客贴纸资料 | W1: 客版资料 | X1: 日期码 | Y1: 备注 | Z1: ZURU 跟单 | AA1: 单价USD | AB1: 金额USD | AC1: 發票號 | AD1: 是否入系统 | AE1: 已送数量 | AF1: 欠数 | AG1: 贴纸信息 | AH1: MA 1语彩盒 A版本 | AI1: MA 1L 彩盒B版本 | AJ1: MA 3L彩盒 A版本 | AK1: 客版彩盒 | AL1: MA 5说明书 | AM1: MA 5L 说明书B版 | AN1: 客版说明书 | AO1: EC展示架 | AP1: 合计数量 | AQ1: 累计数量
A2: 45723 | B2: DIAMANT TOYS LTD | C2: 以色列 | D2: 4500157806 | E2: 56072 | F2: 4500157806-10 | G2: 71152-S001 | H2: 71152-S001 | I2: 机械速龙 | J2: 2220 | K2: 0 | L2: 6 | M2: 370 | N2: 45765 | O2: 45761 | T2: 45726 | U2: 无 | V2: 进口商贴纸翻4500153742+彩色贴纸翻4500153742 | X2: 日期码格式：ZURU INC(BVI) 标准格式 日期：按实际生产日期 | Y2: 日期码格式：ZURU INC(BVI) 标准格式 日期：按实际生产日期 Packaging Info: 1L MA包装+进口商贴纸翻4500153742+彩色贴纸翻4500153742; MA说明书 Remark: | Z2: Lena Huang | AA2: 2.7 | AB2: 5994 | AD2: 已入 | AF2: -2220 | AH2: 2220 | AL2: 2220 | AP2: 2220 | AQ2: 19302
A3: 45642 | B3: Inventive Toys | C3: 俄罗斯联邦 | D3: 4500153901 | F3: 4500153901-50 | G3: 71152-S001 | H3: 71152-S001 | I3: 机械速龙 | J3: 600 | K3: 0 | L3: 6 | M3: =J3/L3 -> 100 | N3: 45793 | O3: 45789 | T3: 46019 | U3: 无 | V3: 欠进口商贴纸 | X3: 外箱不要打ZURU标准日期码！胶件可以打日期码。 | Y3: 日期码格式：外包装/外箱不要打ZURU标准日期码 日期： Packaging Info: 注意:外包装 (指: 收缩膜/彩卡/铝箔袋/挂卡/PDQ)/外箱不要打ZURU标准日期码!胶件可以打日期码。 外包装(包括收缩膜/彩卡/PDQ)都不能含Instagram and facebook logo等社交logo ; 71152 ： MA 彩卡+ 进口商贴纸 ， MA 说明书/指南（如有）； Remark: 标准配比; | Z3: Ann Zhang | AA3: 2.7 | AB3: =AA3*J3 -> 1620 | AD3: 已入 | AF3: =AE3-J3 -> -600 | AI3: =J3 -> 600 | AM3: =J3 -> 600 | AP3: =J3 -> 600 | AQ3: ='71152'!AS46+AP3 -> 41151
A4: 45775 | B4: ZURU France | C4: 法国 | D4: 4500163394 | E4: 5200006588 | F4: 4500163394-20 | G4: 71152-S001-3L | H4: 71152-S001-MTS | I4: 机械速龙 | J4: 990 | K4: 0 | L4: 6 | M4: =J4/L4 -> 165 | N4: 45824 | O4: 45820 | P4: 5/30取消 | T4: 否 | U4: 45796 | V4: 无 | W4: 一张意大利环保标贴纸+ 多语版WEEE电池垃圾桶的回收声明说明书（not included）（贴纸和WEEE翻 4500162314） | Z4: 日期码格式：ZURU INC(BVI) 标准格式 日期：按实际生产日期 Packaging Info: 71152:最新MA 3L EAN（23L warning）彩盒+最新MA 5L说明书+ 一张意大利环保标贴纸+ 多语版WEEE电池垃圾桶的回收声明说明书（not included）（贴纸和WEEE翻 4500162314） Remark: 1. 法国国家内销单，需要通过ZURU 验货结果后才能出货 (工厂需要主动提前同ZURU QC预约验货避免延期出货造成不必要麻烦)； 2. 本订单所有 具有 baby items / assorted items 的款式，零售包装上都要用 母 EAN; 所有订单出口西班牙都需要有法国环保标。 3. 若有特定款有特殊外箱条码要求时,需要明确列出产品款对应的具体外箱条码号码/条码类型 (若无,可以忽略此需求) 4. 所有出口欧洲的产品, 法规规定禁止在包装和共公众用的印刷品中使用矿物油中含有的物质, 包装印刷油墨中含有的MOAH/MOSH的质量浓度不能超过1%, 否则出 货到法国被抽检出现问题, 供应商需要对此负责; 5. Date code: 外箱/产品/包装 保持一致，完货后提供date code 信息以便我们保存记录做批次管理; 6. 装柜时需要按照款式号码从小到大一款款依次装,避免终端仓库卸货混乱.若一个柜子涉及到几个不同国家内销单,装柜时需要一个国家装完后再装另一个国家的 产品,依次装柜,避免终端仓库因不同国家不同库位位置卸货混乱. (此点需要同工厂装柜人员强调) 7， 带电池产品都需要包含多语WEEE黑白说明书。 8，MTS所有订单，SMASHERS 或含Slime产品，所有化合物使用无硼版本出；如有香味产品，出无香版本; BOB系列要符合欧洲要求不含亚硝酸版本; XShot Hyper系列 ，统一出EN71版本。 | AA4: SD83 | AB4: 2.7663 | AC4: =AB4*J4 -> 2738.637 | AE4: 已入 | AG4: =AF4-J4 -> -990 | AK4: =J4 -> 990 | AN4: =J4 -> 990 | AQ4: =J4 -> 990 | AR4: ='71152'!AS118+AQ4 -> 146119
A5: 45765 | B5: WALMART INC. | C5: 美国 | D5: 4500164205 | E5: WM PO#0905014391 /WM item#67419606 0/GTIN#101930 52079197/STK# 71152 | F5: 4500164205-40 | G5: 71152-S002-2 | H5: 71152-S002 | I5: 机械速龙 | J5: 2268 | K5: 0 | L5: 3 | M5: =J5/L5 -> 756 | N5: 45811 | O5: 45807 | P5: 换单 | T5: 否 | U5: 71152箱唛排版可follow PO#4500163167 | V5: 无 | W5: 无 | X5: 45765 | Z5: 日期码格式：ZURU DGYYMMDD CHINA(日期避开周末和法定节假日） 日期：按实际生产日期 Packaging Info: "1.包装信息： 71152：MA 1L 彩盒+ MA 说明书" Remark: "71152： 2. 此单为散箱出货，外箱印刷RFID箱唛（四面右下角印ZURU logo并要有""""Made in China"""" 字样, 外箱一面正唛直接印刷订单内容（从每行remark处获取）， 不再贴贴纸)。 3. 在产品和包装上要有日期码、以及要有MADE IN CHINA和ZURU字样. 4. 产品如有扎带口要剪平，不能刮手. 5. 3pcs /CTN；not include 2pcs AAA battery. 6. 此单需要验货，烦请多备包装物料 7. 每PCS要加RFID 贴纸，严格按照我们提供的位置图，不可擅自调整位置，贴纸也不可有任何破损或折坏，不可淋湿!!" 8.此单每个运输箱加贴一张粉色贴纸 | AA5: Elena | AB5: 2.75 | AC5: =AB5*J5 -> 6237 | AE5: 已入 | AG5: =AF5-J5 -> -2268 | AH5: 欠 | AJ5: =J5 -> 2268 | AO5: =J5 -> 2268 | AQ5: =J5 -> 2268 | AR5: ='71152'!AS83+AQ5 -> 120651
A6: 45765 | B6: WALMART INC. | C6: 美国 | D6: 4500164205 | E6: WM PO#0905014290 /WM item#67419606 0/GTIN#101930 52079197/STK# 71152 | F6: 4500164205-50 | G6: 71152-S002-2 | H6: 71152-S002 | I6: 机械速龙 | J6: 3132 | K6: 0 | L6: 3 | M6: =J6/L6 -> 1044 | N6: 45811 | O6: 45807 | P6: 换单 | T6: 否 | U6: 71152箱唛排版可follow PO#4500163167 | V6: 无 | W6: 无 | X6: 45765 | Z6: 日期码格式：ZURU DGYYMMDD CHINA(日期避开周末和法定节假日） 日期：按实际生产日期 Packaging Info: "1.包装信息： 71152：MA 1L 彩盒+ MA 说明书" Remark: "71152： 2. 此单为散箱出货，外箱印刷RFID箱唛（四面右下角印ZURU logo并要有""""Made in China"""" 字样, 外箱一面正唛直接印刷订单内容（从每行remark处获取）， 不再贴贴纸)。 3. 在产品和包装上要有日期码、以及要有MADE IN CHINA和ZURU字样. 4. 产品如有扎带口要剪平，不能刮手. 5. 3pcs /CTN；not include 2pcs AAA battery. 6. 此单需要验货，烦请多备包装物料 7. 每PCS要加RFID 贴纸，严格按照我们提供的位置图，不可擅自调整位置，贴纸也不可有任何破损或折坏，不可淋湿!!" 8.此单每个运输箱加贴一张粉色贴纸 | AA6: Elena | AB6: 2.75 | AC6: =AB6*J6 -> 8613 | AE6: 已入 | AG6: =AF6-J6 -> -3132 | AH6: 欠 | AJ6: =J6 -> 3132 | AN6: =J6 -> 3132 | AQ6: =J6 -> 3132 | AR6: =AR5+AQ6 -> 123783
A7: 45765 | B7: WALMART INC. | C7: 美国 | D7: 4500164205 | E7: WM PO#0905014394 /WM item#67419606 0/GTIN#101930 52079197/STK# 71152 | F7: 4500164205-60 | G7: 71152-S002-2 | H7: 71152-S002 | I7: 机械速龙 | J7: 2802 | K7: 0 | L7: 3 | M7: =J7/L7 -> 934 | N7: 45811 | O7: 45807 | P7: 换单 | T7: 否 | U7: 71152箱唛排版可follow PO#4500163167 | V7: 无 | W7: 无 | X7: 45765 | Z7: 日期码格式：ZURU DGYYMMDD CHINA(日期避开周末和法定节假日） 日期：按实际生产日期 Packaging Info: "1.包装信息： 71152：MA 1L 彩盒+ MA 说明书" Remark: "71152： 2. 此单为散箱出货，外箱印刷RFID箱唛（四面右下角印ZURU logo并要有""""Made in China"""" 字样, 外箱一面正唛直接印刷订单内容（从每行remark处获取）， 不再贴贴纸)。 3. 在产品和包装上要有日期码、以及要有MADE IN CHINA和ZURU字样. 4. 产品如有扎带口要剪平，不能刮手. 5. 3pcs /CTN；not include 2pcs AAA battery. 6. 此单需要验货，烦请多备包装物料 7. 每PCS要加RFID 贴纸，严格按照我们提供的位置图，不可擅自调整位置，贴纸也不可有任何破损或折坏，不可淋湿!!" 8.此单每个运输箱加贴一张粉色贴纸 | AA7: Elena | AB7: 2.75 | AC7: =AB7*J7 -> 7705.5 | AE7: 已入 | AG7: =AF7-J7 -> -2802 | AH7: 欠 | AJ7: =J7 -> 2802 | AN7: =J7 -> 2802 | AQ7: =J7 -> 2802 | AR7: =AR6+AQ7 -> 126585
