Workbook

Sheet 77673
A1: 香港接单日期 | B1: 第三方客户名称 | C1: 走货国家 | D1: ZURU PO NO# | E1: 第三方客户 PO NO# | F1: SKU | G1: ITEM# | H1: 货品名称 | I1: PO数量(只) | J1: 内箱装箱数量(只) | K1: 外箱装箱数量(只) | L1: 总箱数 | M1: 计划出货期 | N1: 计划验货期 | O1: 第三方客户公证行验货 | P1: 验货结果 | Q1: S/O(截仓期) | R1: 箱唛 (收到日期) | S1: 外箱贴纸 | T1: 贴纸资料 (收到日期及订购日期) | U1: 客供物料 | V1: 样办 | W1: 备注 | X1: ZURU跟单组员 | Y1: 单价USD | Z1: 金额USD | AA1: 发票号 | AB1: 系统货号 | AC1: 是否入系统 | AD1: 下单情况 | AE1: 生产情况 | AF1: 采购单 | AG1: 已回数量 | AH1: 欠数 | AI1: HN回复完成时间 | AJ1: 贴纸 | AK1: 纸箱 | AL1: 77673标准版本 订单数量 | AM1: 77673COSTCO-NA 客版订单数量 | AN1: 77673 TARGET US 客版 订单数量 | AO1: 77673COSTCO-INT 客版订单数量 | AP1: 收缩膜 1L A版本 | AQ1: 收缩膜 3L A版本 | AR1: 收藏指南 5L A版本 | AS1: 中文收藏指南 | AT1: 黑白说明书 | AU1: 中文黑白说明书 | AV1: BJ'S WHOLESALE CLUB, INC.客版收缩膜.收藏指南 | AW1: COSTCO客版收缩膜 | AX1: COSTCO客版收藏指南 | AY1: COSTCO客版说明书 | AZ1: Smyths客版收缩膜 | BA1: Smyths客版收藏指南 | BB1: TARGET客版收缩膜 | BC1: TARGET客版收藏指南 | BD1: 77637TQ1 1L | BE1: 77637TQ1 3L | BF1: 77637TQ2 3L | BG1: 77721彩盒 | BH1: 77721托盘 | BI1: 77785彩盒 1L | BJ1: 77785彩盒 3L | BK1: MEC305-S001-INT
A2: 45650 | D2: ZPO2412009 | G2: 77673-S001 | H2: 迷你冰箱 | I2: 424 | J2: 0 | K2: 12 | L2: =I2/K2 -> 35.333333 | R2: 45650 | S2: 无 | T2: 无 | X2: Alison Chen | AB2: 77673-S001 | AC2: N/A | AE2: 已完成 | AG2: =I2 -> 424 | AH2: =AG2-I2 -> 0 | AL2: =I2 -> 424 | AP2: =I2 -> 424 | AR2: =I2 -> 424 | AT2: =I2 -> 424
A3: 45701 | B3: THE WAREHOUSE LIMITED | C3: 新西兰 | D3: 4500157534 | F3: 4500157534-50 | G3: 77673-S001 | H3: 迷你冰箱 | I3: 144 | J3: 0 | K3: 12 | L3: =I3/K3 -> 12 | M3: 45731 | N3: 45727 | Q3: 消耗PP订单出货 | R3: 45804 | S3: 无 | T3: 45804 | W3: 日期码格式：ZURU INC(BVI) 标准格式 日期：按实际生产日期 Packaging Info: MA UPC 英语包装（优先1L英语版本，或者3L/5L含英语都可） 此客人不接受易掉落或者剥落或者可直接触碰的闪粉，可降解也不行，但可以接受符合欧洲微塑料标准的珠光粉或者闪片。 77673：包装正面和说明书都需要加电池警告语贴纸（法规要求） 所有外箱上都要贴一张大黄贴："ZURU Product for NZ test " Remark: 77673：3PCS AG13 BATTERIES(INCLUDED) | X3: Abby Liang | Y3: 4.1 | Z3: =Y3*I3 -> 590.4 | AB3: 77673-S001 | AC3: 已入 | AE3: 已完成 | AG3: =I3 -> 144 | AH3: =AG3-I3 -> 0 | AL3: =I3 -> 144 | AP3: =I3 -> 144 | AR3: =I3 -> 144 | AT3: =I3 -> 144
A4: 45722 | D4: ZMPO250187 | G4: 77673-S001 | H4: 迷你冰箱 | I4: 168 | J4: 0 | K4: 12 | L4: =I4/K4 -> 14 | M4: 45736 | N4: 45733 | R4: 45722 | S4: 无 | T4: 无 | W4: Remark:大货最新版本包装/大货标准箱装箱/箱唛请参照邮件附件;备注：收到样品订单后尽快安排 ，注意样板品质质量要求要高于大货品质要求 ，送货时必须要附带送货单(没有送货单和QC检验合格报告的仓库一律拒绝收货)，请知悉，谢谢！ | X4: Angus | AB4: 77673-S001 | AC4: 已入 | AE4: 已完成 | AG4: 东莞安排 | AH4: =AG4-I4 -> #VALUE! | AL4: =I4 -> 168 | AP4: =I4 -> 168 | AR4: =I4 -> 168 | AT4: =I4 -> 168
A5: 45737 | D5: ZMPO250244 | G5: 77673-S001 | H5: 迷你冰箱P39饮料瓶散件 | I5: 1100套 | J5: 0 | K5: 1100 | L5: 1 | M5: 45740 | N5: 45736 | R5: 45737 | S5: 无 | T5: 无 | W5: Remark：大货版本/只需要左图款散件；备注： 收到订单后请尽快安排，谢谢 | X5: Angus | AB5: 77673-S001 | AC5: N/A | AE5: 已完成 | AG5: 东莞安排 | AH5: =AG5-I5 -> #VALUE! | AL5: =I5 -> 1100套 | AP5: =I5 -> 1100套 | AR5: =I5 -> 1100套 | AT5: =I5 -> 1100套
A6: 45749 | D6: ZMPO250283 | G6: 77673-S001 | H6: 迷你冰箱 | I6: 80套散件 | J6: 0 | K6: 12 | L6: =I6/K6 -> #VALUE! | M6: 45757 | N6: 45754 | R6: 45749 | S6: 无 | T6: 无 | W6: Remark:大货最新版本/只需要齐套散件/麻烦用胶袋分装好一套为一袋/箱唛参照邮件附件;备注： 收到订单后请尽快安排，谢谢 | X6: Angus | AB6: N/A | AC6: N/A | AG6: =I6 -> 80套散件
A7: 45726 | B7: WAL-MART STORES INC. USA | C7: 美国 | D7: 4500159641 | E7: 0902763014 | F7: 4500159641-10 | G7: 77673TQ1-S001 | H7: 迷你冰箱4pcs/箱 | I7: 616 | J7: 0 | K7: 4 | L7: =I7/K7 -> 154 | M7: 45770 | N7: 45766 | O7: 4/25 第三方抽办 | R7: 45727 | S7: 有 | T7: 45727 | W7: 日期码格式：ZURU DGYYYYMMDD CHINA(日期避开周末和法定节假日即可） 日期：按实际生产日期 Packaging Info: 77673TQ1-S001 1.包装要求： MA 1L A版收缩膜+MA 5L 收藏指南+MA 说明书+MA playset 每pcs产品上要贴1张RFID贴纸，贴纸由ZURU提供，贴纸位置请严格按照我们签回的签板； Remark: 77673TQ1-S001 1.包装要求： MA 1L A版收缩膜+MA 5L 收藏指南+MA 说明书+MA playset 每pcs产品上要贴1张RFID贴纸，贴纸由ZURU提供，贴纸位置请严格按照我们签回的签板； 2. 外箱印刷带条码的RFID箱唛：RFID紫色色带+WM Dept.图标+RFID图标+ITF-14条码，四面右下角印刷ZURU logo, ITFF条码只印刷在正唛一面，在加印的时候确保 条形码能扫描出来，外箱侧面任一角落加印："MADE IN CHINA" 字样； 3. 在产品上和包装上要有日期码、以及要有MADE IN CHINA和ZURU字样； 4. 产品如有扎带口要剪平，不能刮手。 5. 此单需要抽板和验货，抽板时间预计4/23，请多备料 6. 此单以loose carton出货，4pcs/PDQ/CTN | X7: Maggie Xie | Y7: 5 | Z7: =Y7*I7 -> 3080 | AB7: 77673TQ1-S001 | AC7: 已入 | AE7: 已完成 | AG7: 东莞安排 | AH7: =AG7-I7 -> #VALUE! | AL7: =I7 -> 616 | AP7: =I7 -> 616 | AR7: =I7 -> 616 | AT7: =I7 -> 616 | BD7: =I7/4 -> 154
A8: 45761 | D8: ZMPO250315 | G8: 77673-S001 | H8: 迷你冰箱 | I8: 720 | J8: 0 | K8: 12 | L8: =I8/K8 -> 60 | M8: 45771 | N8: 45768 | R8: 45761 | S8: 无 | T8: 无 | W8: Remark:大货最新版本/大货标准箱装箱/箱唛参照邮件附件;备注： 收到样品订单后尽快安排 ，此订单麻烦在外箱上备注是海运订单/注意样板品质质量要求要高于大货品质质量 ，送货时必须要附带送货单(没有送货单和QC检验合格报告的仓库一律拒绝收货)，请知悉，谢谢！ | X8: Angus | AB8: 77673-S001 | AC8: 已入 | AE8: 已完成 | AG8: 720 | AH8: 0 | AL8: =I8 -> 720 | AP8: =I8 -> 720 | AR8: =I8 -> 720 | AT8: =I8 -> 720
A9: 45728 | B9: THE WAREHOUSE LIMITED | C9: 新西兰 | D9: 4500159882 | F9: 4500159882-20 | G9: 77673TQ1-S002 | H9: 迷你冰箱 | I9: 608 | J9: 0 | K9: 16 | L9: =I9/K9 -> 38 | M9: 45772 | N9: 45768 | P9: PASS | Q9: 4/25 出货 | R9: 45735 | S9: 无 | T9: 45735 | W9: 日期码格式：ZURU INC(BVI) 标准格式 日期：按实际生产日期 Packaging Info: #77673TQ1: 1.3PCS AG13 BATTERIES(INCLUDED)，有纽扣电池，包装正面和说明书都需要加电池警告语贴纸（法规要求） 2.Filxed Collection #77673需要加UPC贴纸 Remark: 1.MA UPC 英语包装（优先1L英语版本，或者3L/5L含英语都可） 2.此客人不接受易掉落或者剥落或者可直接触碰的闪粉，可降解也不行，但可以接受符合欧洲微塑料标准的珠光粉或者闪片。 | X9: Abby Liang | Y9: 4.39 | Z9: =Y9*I9 -> 2669.12 | AB9: 77673TQ1-S002 | AC9: 已入 | AE9: 已完成 | AG9: 东莞安排 | AH9: =AG9-I9 -> #VALUE! | AL9: =I9 -> 608 | AP9: =I9 -> 608 | AR9: =I9 -> 608 | AT9: =I9 -> 608 | BD9: =I9/4 -> 152
A10: 45728 | B10: THE WAREHOUSE LIMITED | C10: 新西兰 | D10: 4500159886 | F10: 4500159886-20 | G10: 77673TQ1-S002 | H10: 迷你冰箱 | I10: 192 | J10: 0 | K10: 16 | L10: =I10/K10 -> 12 | M10: 45772 | N10: 45768 | P10: PASS | R10: 45735 | S10: 无 | T10: 45735 | W10: 日期码格式：ZURU INC(BVI) 标准格式 日期：按实际生产日期 Packaging Info: #77673TQ1: 1.3PCS AG13 BATTERIES(INCLUDED)，有纽扣电池，包装正面和说明书都需要加电池警告语贴纸（法规要求） 2.Filxed Collection #77673需要加UPC贴纸 Remark: 1.MA UPC 英语包装（优先1L英语版本，或者3L/5L含英语都可） 2.此客人不接受易掉落或者剥落或者可直接触碰的闪粉，可降解也不行，但可以接受符合欧洲微塑料标准的珠光粉或者闪片。 | X10: Abby Liang | Y10: 4.39 | Z10: =Y10*I10 -> 842.88 | AB10: 77673TQ1-S002 | AC10: 已入 | AE10: 已完成 | AG10: 东莞安排 | AH10: =AG10-I10 -> #VALUE! | AL10: =I10 -> 192 | AP10: =I10 -> 192 | AR10: =I10 -> 192 | AT10: =I10 -> 192 | BD10: =I10/4 -> 48
A11: 45734 | B11: ZURU LLC | C11: 美国 | D11: 4500160498 | E11: B0DR3VG3YH | F11: 4500160498-30 | G11: 77673-S001-MTS | H11: 迷你冰箱 | I11: 4548 | J11: 0 | K11: 12 | L11: =I11/K11 -> 379 | M11: 45777 | N11: 45773 | P11: PASS | R11: 45734 | S11: 无 | T11: 无 | W11: 日期码格式：ZURU INC(BVI) 标准格式 日期：按实际生产日期 Packaging Info: #77673: MA 1L UPC版包装，出口美国。 Remark: 1.Amazon domestic 订单。出口美国。外箱最长边不能超过25" （超过了，case pack只能为1），不符合要求的大货，一律不接受。 2.无第三方验货/测试要求。 3.日期码使用ZURU标准版本。 4.邮包盒要印刷日期码。 | X11: Kelly Shen/Mia Pan/P | Y11: 4.1 | Z11: =Y11*I11 -> 18646.8 | AB11: 77673-S001 | AC11: 已入 | AE11: OK | AG11: 4548 | AH11: =AG11-I11 -> 0 | AL11: =I11 -> 4548 | AP11: =I11 -> 4548 | AR11: =I11 -> 4548 | AT11: =I11 -> 4548
A12: 45728 | B12: ALL BRANDS TOYS PTY LTD | C12: 澳大利亚 | D12: 4500159576 | E12: 83718 | F12: 4500159576-20 | G12: 77673-S003 | H12: 迷你冰箱6pcs/箱 | I12: 1800 | J12: 0 | K12: 6 | L12: =I12/K12 -> 300 | M12: 45777 | N12: 45773 | P12: PASS | R12: 45728 | S12: 无 | T12: 45728 | W12: 日期码格式：ZURU INC(BVI) 标准格式 日期：按实际生产日期 Packaging Info: 2. 77673: MA_UPC版本包装（MA首选1L，如无1L可用多语且含英语的配套多语UPC包装）+ 1张小纽扣电池警告语贴纸贴于包装正面 + 2张大纽扣电池警告语贴纸附 带进口商信息分别贴于包装背面以及说明书上 Remark: 1.按实际生产日期; 2.出澳大利亚，请按照相应标准生产; | X12: Lydia Wu | Y12: 4.1 | Z12: =Y12*I12 -> 7380 | AB12: 77673-S003 | AC12: 已入 | AE12: OK | AG12: 1800 | AH12: =AG12-I12 -> 0 | AL12: =I12 -> 1800 | AP12: =I12 -> 1800 | AR12: =I12 -> 1800 | AT12: =I12 -> 1800
A13: 45729 | B13: KMART AUSTRALIA LTD | C13: 澳大利亚 | D13: 4500160026 | E13: 20627370 | F13: 4500160026-20 | G13: 77673-S001 | H13: 迷你冰箱 | I13: 3300 | J13: 0 | K13: 12 | L13: =I13/K13 -> 275 | M13: 45786 | N13: 45782 | P13: PASS | R13: 45748 | S13: 有 | T13: 外箱贴纸 | W13: 日期码格式：ZURU INC(BVI) 标准格式 日期：按实际生产日期 Packaging Info: 77673-S001: MA英语UPC版本包装（收缩膜和说明书, MA首选1L，如无1L可用多语且含英语的配套多语包装) + 1张说明书纽扣电池警告语贴纸+ 1张收缩膜纽扣电池 警告语贴纸+ 1张防盗贴纸+箱唛 + 外箱SSCC Label Remark: 1.请务必按时完货，验货。并且按期送货入货代指定仓库，如果晚了导致船期Delay将会有罚金产生或者客户要求空运，所产生的罚金和空运费由工厂承担。 2.SSCC 外箱贴纸请同纸箱瓦楞纸方向（竖纹向）垂直，即外箱贴纸横着贴(注意条码不要被胶带粘住），贴1pc，贴1面正唛，封箱胶纸不能挡住贴纸内容。外箱贴纸 离外箱边距离不少于2cm。 3.外箱材质为ZURU标准； 4.此单需使用KMART封箱胶上下工字型封箱;从2019年6月开始，要用KMART 新版封箱胶带，此单要用"ANKO"封箱胶带 5.此单出口澳大利亚，请按相应的澳新标准生产； 6.产品和包装上生产批号的显示格式ZURU标准日期码格式 7.外箱信息不可手写，重量和体积需要与实际的一致(不可手写） 8. 每款item装箱后的G.W.超过10KG或者CBM超过0.13,(9.5KG或者以上，四舍五入后也属于10KG) 需在外箱上加印超 重或者Bulky LOGO，若发现我们资料没有，请 帮忙提醒 1)重量超过10kg但不超过16kg且CBM不超过0.13,10-16kg 超重logo 2）CBM超过0.13且重量少于17kg，bulky logo 3）不属于以上两种情况，需要使用相应重量范围内的超重logo 4）超重logo需要在外箱四面都印刷(箱唛右上角，两面侧唛超重logo需要尽量靠近毛重)，尺寸为:110mm height* 95mm width 9. 实际外箱重量跟印在箱唛上的数据差异不能超3%，尺寸按实际数据印刷 | X13: Lydia Wu | Y13: 4.19 | Z13: =Y13*I13 -> 13827 | AB13: 77673-S001 | AC13: 已入 | AE13: 已完成 | AG13: 3300 | AH13: =AG13-I13 -> 0 | AL13: =I13 -> 3300 | AP13: =I13 -> 3300 | AR13: =I13 -> 3300 | AT13: =I13 -> 3300
A14: 45729 | B14: KMART AUSTRALIA LTD(NEW ZEALAND) | C14: 新西兰 | D14: 4500160027 | E14: 20627371 | F14: 4500160027-20 | G14: 77673-S001 | H14: 迷你冰箱 | I14: 432 | J14: 0 | K14: 12 | L14: =I14/K14 -> 36 | M14: 45786 | N14: 45782 | P14: PASS | R14: 45748 | S14: 有 | T14: 外箱贴纸 | W14: 日期码格式：ZURU INC(BVI) 标准格式 日期：按实际生产日期 Packaging Info: 77673-S001: MA英语UPC版本包装（收缩膜和说明书, MA首选1L，如无1L可用多语且含英语的配套多语包装) + 1张说明书纽扣电池警告语贴纸+ 1张收缩膜纽扣电池 警告语贴纸+ 1张防盗贴纸+箱唛 + 外箱SSCC Label (贴纸以及位置图翻单PO#4500160026） Remark: 1.请务必按时完货，验货。并且按期送货入货代指定仓库，如果晚了导致船期Delay将会有罚金产生或者客户要求空运，所产生的罚金和空运费由工厂承担。 2.SSCC 外箱贴纸请同纸箱瓦楞纸方向（竖纹向）垂直，即外箱贴纸横着贴(注意条码不要被胶带粘住），贴1pc，贴1面正唛，封箱胶纸不能挡住贴纸内容。外箱贴纸 离外箱边距离不少于2cm。 3.外箱材质为ZURU标准； 4.此单需使用KMART封箱胶上下工字型封箱;从2019年6月开始，要用KMART 新版封箱胶带，此单要用"ANKO"封箱胶带 5.此单出口新西兰，请按相应的澳新标准生产； 6.产品和包装上生产批号的显示格式ZURU标准日期码格式 7.外箱信息不可手写，重量和体积需要与实际的一致(不可手写） 8. 每款item装箱后的G.W.超过10KG或者CBM超过0.13,(9.5KG或者以上，四舍五入后也属于10KG) 需在外箱上加印超 重或者Bulky LOGO，若发现我们资料没有，请 帮忙提醒 1)重量超过10kg但不超过16kg且CBM不超过0.13,10-16kg 超重logo 2）CBM超过0.13且重量少于17kg，bulky logo 3）不属于以上两种情况，需要使用相应重量范围内的超重logo 4）超重logo需要在外箱四面都印刷(箱唛右上角，两面侧唛超重logo需要尽量靠近毛重)，尺寸为:110mm height* 95mm width 9. 实际外箱重量跟印在箱唛上的数据差异不能超3%，尺寸按实际数据印刷 | X14: Lydia Wu | Y14: 4.19 | Z14: =Y14*I14 -> 1810.08 | AB14: 77673-S001 | AC14: 已入 | AE14: 已完成 | AG14: 432 | AH14: =AG14-I14 -> 0 | AL14: =I14 -> 432 | AP14: =I14 -> 432 | AR14: =I14 -> 432 | AT14: =I14 -> 432
A15: 45744 | B15: WALMART INC. | C15: 美国 | D15: 4500161759 | E15: 0904512308 STATESBORO | F15: 4500161759-10 | G15: 77673TQ1-S001 | H15: 迷你冰箱4pcs/箱 | I15: 512 | J15: 0 | K15: 4 | L15: =I15/K15 -> 128 | M15: 45785 | N15: 45782 | O15: 5/9 第三方验货 | P15: PASS | R15: 外箱印刷带条码的RFID箱唛：RFID紫色色带+WM Dept.图标+RFID图标+ITF-14条码，四面右下角印刷ZURU logo, ITFF条码只印刷在正唛一面，在加印的时候确保 条形码能扫描出来，外箱侧面任一角落加印："MADE IN CHINA" 字样； | S15: 无 | T15: RFID贴纸 | U15: RFID贴纸 | W15: 日期码格式：ZURU DGYYYYMMDD CHINA(日期避开周末和法定节假日即可） 日期：按实际生产日期 Packaging Info: 77673TQ1-S001 1.包装要求： MA 1L A版收缩膜+MA 5L 收藏指南+MA 说明书+MA playset，翻单：4500159641 每pcs产品上要贴1张RFID贴纸，贴纸由ZURU提供，贴纸位置请严格按照我们签回的签板； Remark: 77673TQ1-S001 1.包装要求： MA 1L A版收缩膜+MA 5L 收藏指南+MA 说明书+MA playset，翻单：4500159641 每pcs产品上要贴1张RFID贴纸，贴纸由ZURU提供，贴纸位置请严格按照我们签回的签板； 2. 外箱印刷带条码的RFID箱唛：RFID紫色色带+WM Dept.图标+RFID图标+ITF-14条码，四面右下角印刷ZURU logo, ITFF条码只印刷在正唛一面，在加印的时候确保 条形码能扫描出来，外箱侧面任一角落加印："MADE IN CHINA" 字样； 3. 在产品上和包装上要有日期码、以及要有MADE IN CHINA和ZURU字样； 4. 产品如有扎带口要剪平，不能刮手。 5. 此单需要验货，请多备料 6. 此单以loose carton出货，4pcs/PDQ/CTN | X15: Maggie Xie | Y15: 5 | Z15: =Y15*I15 -> 2560 | AB15: 77673TQ1-S001 | AC15: 已入 | AE15: 已完成 | AG15: 512 | AH15: =AG15-I15 -> 0 | AL15: =I15 -> 512 | AP15: =I15 -> 512 | AR15: =I15 -> 512 | AT15: =I15 -> 512 | BD15: =I15/4 -> 128
A16: 45744 | B16: WALMART INC. | C16: 美国 | D16: 4500161759 | E16: 0904512292 SUFFOLK | F16: 4500161759-20 | G16: 77673TQ1-S001 | H16: 迷你冰箱4pcs/箱 | I16: 656 | J16: 0 | K16: 4 | L16: =I16/K16 -> 164 | M16: 45785 | N16: 45782 | O16: 5/9 第三方验货 | P16: PASS | R16: 外箱印刷带条码的RFID箱唛：RFID紫色色带+WM Dept.图标+RFID图标+ITF-14条码，四面右下角印刷ZURU logo, ITFF条码只印刷在正唛一面，在加印的时候确保 条形码能扫描出来，外箱侧面任一角落加印："MADE IN CHINA" 字样； | S16: 无 | T16: RFID贴纸 | U16: RFID贴纸 | W16: 日期码格式：ZURU DGYYYYMMDD CHINA(日期避开周末和法定节假日即可） 日期：按实际生产日期 Packaging Info: 77673TQ1-S001 1.包装要求： MA 1L A版收缩膜+MA 5L 收藏指南+MA 说明书+MA playset，翻单：4500159641 每pcs产品上要贴1张RFID贴纸，贴纸由ZURU提供，贴纸位置请严格按照我们签回的签板； Remark: 77673TQ1-S001 1.包装要求： MA 1L A版收缩膜+MA 5L 收藏指南+MA 说明书+MA playset，翻单：4500159641 每pcs产品上要贴1张RFID贴纸，贴纸由ZURU提供，贴纸位置请严格按照我们签回的签板； 2. 外箱印刷带条码的RFID箱唛：RFID紫色色带+WM Dept.图标+RFID图标+ITF-14条码，四面右下角印刷ZURU logo, ITFF条码只印刷在正唛一面，在加印的时候确保 条形码能扫描出来，外箱侧面任一角落加印："MADE IN CHINA" 字样； 3. 在产品上和包装上要有日期码、以及要有MADE IN CHINA和ZURU字样； 4. 产品如有扎带口要剪平，不能刮手。 5. 此单需要验货，请多备料 6. 此单以loose carton出货，4pcs/PDQ/CTN | X16: Maggie Xie | Y16: 5 | Z16: =Y16*I16 -> 3280 | AA16: ZB00239-5.13 | AB16: 77673TQ1-S001 | AC16: 已入 | AE16: 已完成 | AG16: 656 | AH16: =AG16-I16 -> 0 | AL16: =I16 -> 656 | AP16: =I16 -> 656 | AR16: =I16 -> 656 | AT16: =I16 -> 656 | BD16: =I16/4 -> 164
A17: 45734 | B17: ZURU Germany GMBH | C17: 德国 | D17: 4500160634 | E17: 5200006405 | F17: 4500160634-20 | G17: 77673TQ1-S001-MTS | H17: 迷你冰箱4pcs/箱 | I17: 800 | J17: 0 | K17: 4 | L17: =I17/K17 -> 200 | M17: 45786 | N17: 45782 | P17: PASS | R17: 45735 | S17: 无 | T17: 多语折叠警告语贴纸（翻单4500157858）+WEEE通用黑色书纸带电池走货 | U17: 所有电子产品身上需要加字唛，为ZURU FRANCE 地址 (如无电子产品，或者产品布标有此地址，可忽略此信息) ZURU France 1/3, Rue d'Argenteuil 95210 SAINT-GRATIEN, FRANCE | W17: 日期码格式：ZURU INC(BVI) 标准格式 日期：按实际生产日期 Tracking Code: Packaging Info: 77673TQ1: MA_3L PDQ + MA 3L EAN 收缩膜 + 多语折叠警告语贴纸（翻单4500157858） +MA5L收藏指南+ MA 23L说明书+MA纸袋 + WEEE通用黑色书纸带电池走货 EAN # 4894680042773 Remark: 1.德国内销单，需要通过ZURU 验货结果后才能出货 (工厂需要主动提前同ZURU QC预约验货避免延期出货造成不必要麻烦)； 2. 若有特定款有特殊外箱条码要求时,需要明确列出产品款对应的具体外箱条码号码/条码类型 (若无,可以忽略此需求) 3.所有出口欧洲的产品, 法规规定禁止在包装和共公众用的印刷品中使用矿物油中含有的物质, 包装印刷油墨中含有的MOAH/MOSH的质量浓度不能超过1%, 否则出货 到法国被抽检出现问题, 供应商需要对此负责; 4. date code: 外箱日期码要晚于或等于产品日期码，不能早于产品的日期码 5. 所有电子产品身上需要加字唛，为ZURU FRANCE 地址 (如无电子产品，或者产品布标有此地址，可忽略此信息) ZURU France 1/3, Rue d'Argenteuil 95210 SAINT-GRATIEN, FRANCE 6. 装柜时需要按照款式号码从小到大一款款依次装,避免终端仓库卸货混乱.若一个柜子涉及到几个不同国家内销单,装柜时需要一个国家装完后再装另一个国家的 产品,依次装柜,避免终端仓库因不同国家不同库位位置卸货混乱. (此点需要同工厂装柜人员强调)" | X17: SD04 | Y17: 5.03 | Z17: =Y17*I17 -> 4024 | AB17: 77673TQ1-S001-MTS | AC17: 已入 | AE17: 已完成 | AG17: 800 | AH17: =AG17-I17 -> 0 | AL17: =I17 -> 800 | AQ17: =I17 -> 800 | AR17: =I17 -> 800 | AT17: =I17 -> 800 | BE17: =I17/4 -> 200
A18: 45671 | B18: Smyths Toys EU HQ UC | C18: 德国 | D18: 4500155594 | E18: 4400459913 | F18: 4500155594-10 | G18: 77673TQ1-S003 | H18: 迷你冰箱 | I18: 3008 | J18: 0 | K18: 8 | L18: =I18/K18 -> 376 | M18: 45787 | N18: 45783 | O18: 所有电子产品身上需要加字唛，为ZURU FRANCE 地址 (如无电子产品，或者产品布标有此地址，可忽略此信息) ZURU France 1/3, Rue d'Argenteuil 95210 SAINT-GRATIEN, FRANCE | P18: PASS | R18: 45671 | S18: 无 | T18: WEEE声明(带电池)走货欧洲通用30L-B版说明书 | W18: 日期码格式：ZURU INC(BVI) 标准格式 日期：按实际生产日期 Packaging Info: 最新MA PDQ(优先3L )+ 客版收缩膜(英法德callout/英法德意荷警语/法国环保logo) +23L 说明书+客版收藏指南(英法德意荷) +客版WEEE声明通用说明书(带电池) EAN: 4894680042773 Remark: 1. 此单出德国，需要满足Zuru Standard欧洲标准测试要求； 2. 请准时出货，推期会有罚款； 3. 出口欧洲，微塑料需符合法规； 4. 所有电子产品身上需要加字唛，为ZURU FRANCE 地址 (如无电子产品，或者产品布标有此地址，可忽略此信息) ZURU France 1/3, Rue d'Argenteuil 95210 SAINT-GRATIEN, FRANCE 5. 标准配比 | X18: Shirley Zhou | Y18: 5.1379 | Z18: =Y18*I18 -> 15454.803 | AB18: 77673TQ1-S003 | AC18: 已入 | AE18: 已完成 | AG18: 3008 | AH18: =AG18-I18 -> 0 | AL18: =I18 -> 3008 | AT18: =I18 -> 3008 | AZ18: =I18 -> 3008 | BA18: =I18 -> 3008 | BE18: =I18/4 -> 752
A19: 45733 | B19: WAL-MART CANADA CORP. | C19: 加拿大 | D19: 4500160504 | E19: 9900923471 | F19: 4500160504-40 | G19: 77673-S002 | H19: 迷你冰箱 | I19: 884 | J19: 0 | K19: 2 | L19: =I19/K19 -> 442 | M19: 45776 | N19: 45772 | O19: 5/19 第三方验货，#77673需于2025/4/18安排签版, 签样数量：空PDQ2PCS, 大货样各4PCS+散件3套; #77673 需于2025/4/28安排抽办测试, 抽办数量：大货各4 SETS | P19: PASS | R19: 45748 | S19: 无 | T19: 45734 | W19: 日期码格式：ZURU INC(BVI) 标准格式 日期：按实际生产日期 Packaging Info: #77673： MA3L收缩膜+UPC贴纸(UPC:193052079404)+MA23L说明书+MA5L收藏指南+MA5L,UV胶瓶身贴 产品配比： 7 Assortment, Polar bear: Penguin: Walrus: Mammoth: Owl: Seal: Snow man=10:10:10:10:10:8:2. Snow man is the rare item. Remark: 1. 此单有箱唛； 3. 此单有第三方验货，烦请多备包装物料； 5. #77673需于2025/4/18安排签版, 签样数量：空PDQ2PCS, 大货样各4PCS+齐套散件3套; 9. #77673 需于2025/4/28安排抽办测试, 抽办数量：大货4 pcs+齐套散件4SETS; 11. UPC贴纸：必须在原来错误的条码上用黑色粗头笔涂黑直至不能扫描，再贴上正确的UPC; ********************* a. 请确保产品符合1999年版本的加拿大环境保护法(CEPA)和2012年禁止某些有毒物质法规的要求。该产品不含任何在加拿大禁用的化学物质，包括但不限于有毒物 质清单中列出的化学物质，并且在为加拿大沃尔玛生产产品期间没有使用任何禁用化学物质。 Supplier certify that the products comply with the requirements of Canadian Environmental Protection Act, 1999 (CEPA), Prohibition of Certain To xic Substances Regulations, 2012. The products do not contain any chemicals that are banned in Canada, including but not limited to those listed in the Toxic Substances List and no banned chemicals were used during the manufacturing of product for Walmart Canada. 附件列表： (1) Letter of Guarantee for Canada banned chemicals - (1-5CA) b. 请确保产品在均质材料中的汞浓度不超过0.1%（按重量计）。 Supplier certify that the WAL-MART vendor products does not have a mercury concentration of more than 0.1% by weight in homogeneous material. 附件列表： (1) Letter of Guarantee for Mercury COC c. 请确保产品的塑料材料不含以下物质（SOR 2011-17 27B): Supplier certify that the plastic materials do not contain the following substances(SOR 2011-17 27B): (a) carbon tetrachloride or any substance that contains it; (b) methyl alcohol or any substance thay contains >1.0%; (c) petroleum distillates or any substance that contains >10% weight to volume of petroleum distillates; (d) benzene; (e) turpentine or any substance that contains >10% weight to volume of turpentine; (f) boric acid or salts of boric acid; or (g) ethyl ether. 附件列表： (1) Letter of Guarantee for WM CA-Other prohibited substances in plastic(less than 3 years) | X19: Monica Zhou | Y19: 4.1 | Z19: =Y19*I19 -> 3624.4 | AB19: 77673-S002 | AC19: 已入 | AE19: 已完成 | AG19: 东莞安排 | AH19: =AG19-I19 -> #VALUE! | AL19: =I19 -> 884 | AQ19: =I19 -> 884 | AR19: =I19 -> 884 | AT19: =I19 -> 884
A20: 45726 | B20: 360 SALES SOLUTIONS INC | C20: 加拿大 | D20: 4500159666 | E20: 2025ZURU11 | F20: 4500159666-20 | G20: 77673-S001 | H20: 迷你冰箱 | I20: 15396 | J20: 0 | K20: 12 | L20: =I20/K20 -> 1283 | M20: 45786 | N20: 45782 | P20: PASS | Q20: 5/17 SI | R20: 45727 | S20: 无 | T20: 无 | W20: 日期码格式： 标准格式 日期：按实际生产日期 Packaging Info: 77673 MA 多语（含英法）EAN包装+UPC贴纸， UPC号码193052079404 Remark: 出加拿大 Zuru验货.日期跟踪码：产品外包装及产品本身都必须有日期跟踪码，ZURU标准格式日期码。（箱唛日期码按跟单提供格式） | X20: Summer Mo | Y20: 4.1 | Z20: =Y20*I20 -> 63123.6 | AB20: 77673-S001-3L | AC20: 已入 | AE20: 预计5/14验货 | AG20: 东莞安排 | AH20: =AG20-I20 -> #VALUE! | AL20: =I20 -> 15396 | AQ20: =I20 -> 15396 | AR20: =I20 -> 15396 | AT20: =I20 -> 15396
A21: 45744 | B21: WALMART INC. | C21: 美国 | D21: 4500161760 | E21: 0904512282 | F21: 4500161760-10 | G21: 77673TQ1-S001 | H21: 迷你冰箱4pcs/箱 | I21: 760 | J21: 0 | K21: 4 | L21: =I21/K21 -> 190 | M21: 45789 | N21: 45785 | O21: 5/14 第三方验货 | P21: PASS | R21: 外箱印刷带条码的RFID箱唛：RFID紫色色带+WM Dept.图标+RFID图标+ITF-14条码，四面右下角印刷ZURU logo, ITFF条码只印刷在正唛一面，在加印的时候确保 条形码能扫描出来，外箱侧面任一角落加印："MADE IN CHINA" 字样； | S21: 无 | T21: RFID贴纸 | U21: RFID贴纸 | W21: 日期码格式：ZURU DGYYYYMMDD CHINA(日期避开周末和法定节假日即可） 日期：按实际生产日期 Packaging Info: 77673TQ1-S001 1.包装要求： MA 1L A版收缩膜+MA 5L 收藏指南+MA 说明书+MA playset，翻单：4500159641 每pcs产品上要贴1张RFID贴纸，贴纸由ZURU提供，贴纸位置请严格按照我们签回的签板； Remark: 77673TQ1-S001 1.包装要求： MA 1L A版收缩膜+MA 5L 收藏指南+MA 说明书+MA playset，翻单：4500159641 每pcs产品上要贴1张RFID贴纸，贴纸由ZURU提供，贴纸位置请严格按照我们签回的签板； 2. 外箱印刷带条码的RFID箱唛：RFID紫色色带+WM Dept.图标+RFID图标+ITF-14条码，四面右下角印刷ZURU logo, ITFF条码只印刷在正唛一面，在加印的时候确保 条形码能扫描出来，外箱侧面任一角落加印："MADE IN CHINA" 字样； 3. 在产品上和包装上要有日期码、以及要有MADE IN CHINA和ZURU字样； 4. 产品如有扎带口要剪平，不能刮手。 5. 此单需要验货，请多备料 6. 此单以loose carton出货，4pcs/PDQ/CTN | X21: Maggie Xie | Y21: 5 | Z21: =Y21*I21 -> 3800 | AB21: 77673TQ1-S001 | AC21: 已入 | AE21: 已完成 | AG21: 760 | AH21: =AG21-I21 -> 0 | AL21: =I21 -> 760 | AP21: =I21 -> 760 | AR21: =I21 -> 760 | AT21: =I21 -> 760 | BD21: =I21/4 -> 190
A22: 45726 | B22: WAL-MART STORES INC. USA | C22: 美国 | D22: 4500159654 | E22: 0902421331 SAVANNAH | F22: 4500159654-10 | G22: 77673TQ1-S001 | H22: 迷你冰箱4pcs/箱 | I22: 2768 | J22: 0 | K22: 4 | L22: =I22/K22 -> 692 | M22: 45789 | N22: 45785 | O22: 5/14 第三方验货 | P22: PASS | R22: 45727 | S22: 有 | T22: 45727 | U22: 每pcs产品上要贴1张RFID贴纸，贴纸由ZURU提供，贴纸位置请严格按照我们签回的签板，粉色艾利贴纸（不干胶打印） | W22: 日期码格式：ZURU DGYYYYMMDD CHINA(日期避开周末和法定节假日即可） 日期：按实际生产日期 Packaging Info: 77673TQ1-S001 1.包装要求： MA 1L A版收缩膜+MA 5L 收藏指南+MA 说明书+MA playset 每pcs产品上要贴1张RFID贴纸，贴纸由ZURU提供，贴纸位置请严格按照我们签回的签板； Remark: 77673TQ1-S001 1.包装要求： MA 1L A版收缩膜+MA 5L 收藏指南+MA 说明书+MA playset 每pcs产品上要贴1张RFID贴纸，贴纸由ZURU提供，贴纸位置请严格按照我们签回的签板； 2. 外箱印刷带条码的RFID箱唛：RFID紫色色带+WM Dept.图标+RFID图标+ITF-14条码+粉色艾利贴纸（不干胶打印），四面右下角印刷ZURU logo, ITFF条码只印刷在 正唛一面，在加印的时候确保条形码能扫描出来，1张粉红色贴纸贴在正唛对角线，外箱侧面任一角落加印："MADE IN CHINA" 字样； 3. 在产品上和包装上要有日期码、以及要有MADE IN CHINA和ZURU字样； 4. 产品如有扎带口要剪平，不能刮手。 5. 此单需要验货，请多备料 6. 此单以loose carton出货，4pcs/PDQ/CTN | X22: Maggie Xie | Y22: 5 | Z22: =Y22*I22 -> 13840 | AB22: 77673TQ1-S001 | AC22: 已入 | AE22: 已完成 | AG22: 2768 | AH22: =AG22-I22 -> 0 | AL22: =I22 -> 2768 | AP22: =I22 -> 2768 | AR22: =I22 -> 2768 | AT22: =I22 -> 2768 | BD22: =I22/4 -> 692
A23: 45726 | B23: WAL-MART STORES INC. USA | C23: 美国 | D23: 4500159654 | E23: 0902421341 SUFFOLK | F23: 4500159654-20 | G23: 77673TQ1-S001 | H23: 迷你冰箱4pcs/箱 | I23: 3560 | J23: 0 | K23: 4 | L23: =I23/K23 -> 890 | M23: 45789 | N23: 45785 | O23: 5/14 第三方验货 | P23: PASS | R23: 45727 | S23: 有 | T23: 45727 | U23: 每pcs产品上要贴1张RFID贴纸，贴纸由ZURU提供，贴纸位置请严格按照我们签回的签板，粉色艾利贴纸（不干胶打印） | W23: 日期码格式：ZURU DGYYYYMMDD CHINA(日期避开周末和法定节假日即可） 日期：按实际生产日期 Packaging Info: 77673TQ1-S001 1.包装要求： MA 1L A版收缩膜+MA 5L 收藏指南+MA 说明书+MA playset 每pcs产品上要贴1张RFID贴纸，贴纸由ZURU提供，贴纸位置请严格按照我们签回的签板； Remark: 77673TQ1-S001 1.包装要求： MA 1L A版收缩膜+MA 5L 收藏指南+MA 说明书+MA playset 每pcs产品上要贴1张RFID贴纸，贴纸由ZURU提供，贴纸位置请严格按照我们签回的签板； 2. 外箱印刷带条码的RFID箱唛：RFID紫色色带+WM Dept.图标+RFID图标+ITF-14条码+粉色艾利贴纸（不干胶打印），四面右下角印刷ZURU logo, ITFF条码只印刷在 正唛一面，在加印的时候确保条形码能扫描出来，1张粉红色贴纸贴在正唛对角线，外箱侧面任一角落加印："MADE IN CHINA" 字样； 3. 在产品上和包装上要有日期码、以及要有MADE IN CHINA和ZURU字样； 4. 产品如有扎带口要剪平，不能刮手。 5. 此单需要验货，请多备料 6. 此单以loose carton出货，4pcs/PDQ/CTN | X23: Maggie Xie | Y23: 5 | Z23: =Y23*I23 -> 17800 | AB23: 77673TQ1-S001 | AC23: 已入 | AE23: 已完成 | AG23: 3560 | AH23: =AG23-I23 -> 0 | AL23: =I23 -> 3560 | AP23: =I23 -> 3560 | AR23: =I23 -> 3560 | AT23: =I23 -> 3560 | BD23: =I23/4 -> 890
A24: 45726 | B24: WAL-MART STORES INC. USA | C24: 美国 | D24: 4500159654 | E24: 0902421349 RIDGEVILLE SC | F24: 4500159654-30 | G24: 77673TQ1-S001 | H24: 迷你冰箱4pcs/箱 | I24: 3344 | J24: 0 | K24: 4 | L24: =I24/K24 -> 836 | M24: 45789 | N24: 45785 | O24: 5/14 第三方验货 | P24: PASS | R24: 45727 | S24: 有 | T24: 45727 | U24: 每pcs产品上要贴1张RFID贴纸，贴纸由ZURU提供，贴纸位置请严格按照我们签回的签板，粉色艾利贴纸（不干胶打印） | W24: 日期码格式：ZURU DGYYYYMMDD CHINA(日期避开周末和法定节假日即可） 日期：按实际生产日期 Packaging Info: 77673TQ1-S001 1.包装要求： MA 1L A版收缩膜+MA 5L 收藏指南+MA 说明书+MA playset 每pcs产品上要贴1张RFID贴纸，贴纸由ZURU提供，贴纸位置请严格按照我们签回的签板； Remark: 77673TQ1-S001 1.包装要求： MA 1L A版收缩膜+MA 5L 收藏指南+MA 说明书+MA playset 每pcs产品上要贴1张RFID贴纸，贴纸由ZURU提供，贴纸位置请严格按照我们签回的签板； 2. 外箱印刷带条码的RFID箱唛：RFID紫色色带+WM Dept.图标+RFID图标+ITF-14条码+粉色艾利贴纸（不干胶打印），四面右下角印刷ZURU logo, ITFF条码只印刷在 正唛一面，在加印的时候确保条形码能扫描出来，1张粉红色贴纸贴在正唛对角线，外箱侧面任一角落加印："MADE IN CHINA" 字样； 3. 在产品上和包装上要有日期码、以及要有MADE IN CHINA和ZURU字样； 4. 产品如有扎带口要剪平，不能刮手。 5. 此单需要验货，请多备料 6. 此单以loose carton出货，4pcs/PDQ/CTN | X24: Maggie Xie | Y24: 5 | Z24: =Y24*I24 -> 16720 | AB24: 77673TQ1-S001 | AC24: 已入 | AE24: 已完成 | AG24: 3344 | AH24: =AG24-I24 -> 0 | AL24: =I24 -> 3344 | AP24: =I24 -> 3344 | AR24: =I24 -> 3344 | AT24: =I24 -> 3344 | BD24: =I24/4 -> 836
A25: 45755 | B25: ZURU Denmark ApS | C25: 丹麦 | D25: 4500162820 | E25: 5200006528 | F25: 4500162820-20 | G25: 77673TQ1-S001-MTS | H25: 迷你冰箱4pcs/箱 | I25: 2444 | J25: 0 | K25: 4 | L25: =I25/K25 -> 611 | M25: 45789 | N25: 45785 | P25: PASS | R25: 45757 | S25: 无 | T25: 45764 | W25: 日期码格式：ZURU INC(BVI) 标准格式 日期：按实际生产日期 Packaging Info: 77673 MA3L EAN 版本收缩膜+1*多语警告语贴纸+MA 5L 收藏指南+ MA 23L 电池UV 警告语+MA PDQ （语言不限） Remark: 1.北欧内销单，需要通过ZURU 验货结果后才能出货 (工厂需要主动提前同ZURU QC预约验货避免延期出货造成不必要麻烦)； 2. 产品如含有化学品，需要无硼无香， 3.包装不能含有PVC，使用PET 4. date code: 外箱日期码要晚于产品日期码 5. 装柜时需要按照款式号码从小到大一款款依次装,避免终端仓库卸货混乱.若一个柜子涉及到几个不同国家内销单,装柜时需要一个国家装完后再装另一个国家的 产品,依次装柜,避免终端仓库因不同国家不同库位位置卸货混乱. (此点需要同工厂装柜人员强调)" 6.若有特定款有特殊外箱条码要求时,需要明确列出产品款对应的具体外箱条码号码/条码类型 (若无,可以忽略此需求) 7.所有出口欧洲的产品, 法规规定禁止在包装和共公众用的印刷品中使用矿物油中含有的物质, 包装印刷油墨中含有的MOAH/MOSH的质量浓度不能超过1%, 否则出货 到法国被抽检出现问题, 供应商需要对此负责; 8.带电池出货的产品所用到的电池需要符合欧洲电池新规(EU) 2023-1542。 9.ratio 同MA | X25: SD04 | Y25: 5.03 | Z25: =Y25*I25 -> 12293.32 | AB25: 77673TQ1-S001-MTS | AC25: 已入 | AE25: 已完成 | AG25: 2444 | AH25: =AG25-I25 -> 0 | AL25: =I25 -> 2444 | AQ25: =I25 -> 2444 | AR25: =I25 -> 2444 | AT25: =I25 -> 2444 | BE25: =I25/4 -> 611
A26: 45773 | D26: ZMPO250350 | G26: 77673-S001 | H26: 迷你冰箱 | I26: 108 | J26: 0 | K26: 12 | L26: =I26/K26 -> 9 | M26: 45789 | N26: 45785 | P26: PASS | R26: 45773 | S26: 无 | T26: 无 | W26: Remark:大货最新版本/大货标准箱装箱/箱唛请参照邮件附件;备注：收到样品订单后尽快安排 ，注意样板品质质量要求要高于大货品质要求 ，送货时必须要附带送货单(没有送货单和QC检验合格报告的仓库一律拒绝收货)，请知悉，谢谢！ | X26: Angus | AB26: 77673-S001 | AC26: 已入 | AE26: 已完成 | AG26: 108 | AH26: =AG26-I26 -> 0 | AL26: =I26 -> 108 | AP26: =I26 -> 108 | AR26: =I26 -> 108 | AT26: =I26 -> 108
A27: 45741 | B27: MEIJER DISTRIBUTION, INC. | C27: 美国 | D27: 4500161407 | E27: 216951853 | F27: 4500161407-20 | G27: 77673-S004 | H27: 迷你冰箱4pcs/箱 | I27: 800 | J27: 0 | K27: 4 | L27: =I27/K27 -> 200 | M27: 45790 | N27: 45786 | P27: PASS | R27: 45771 | S27: 无 | T27: 无 | W27: 日期码格式：ZURU INC(BVI) 标准格式 日期： Packaging Info: 1. MA 1L 包装 2. 客人指定箱唛排版 Remark: 出货前 Zuru QC 验货 | X27: Cherie Li | Y27: 4.1 | Z27: =Y27*I27 -> 3280 | AB27: 77673-S004 | AC27: 已入 | AE27: 已完成 | AG27: 800 | AH27: =AG27-I27 -> 0 | AL27: =I27 -> 800 | AP27: =I27 -> 800 | AR27: =I27 -> 800 | AT27: =I27 -> 800
A28: 45741 | B28: MEIJER DISTRIBUTION, INC. | C28: 美国 | D28: 4500161408 | E28: 216951858 | F28: 4500161408-20 | G28: 77673-S004 | H28: 迷你冰箱4pcs/箱 | I28: 600 | J28: 0 | K28: 4 | L28: =I28/K28 -> 150 | M28: 45790 | N28: 45786 | P28: PASS | R28: 45771 | S28: 无 | T28: 无 | W28: 日期码格式：ZURU INC(BVI) 标准格式 日期： Packaging Info: 1. MA 1L 包装 2. 客人指定箱唛排版 Remark: 出货前 Zuru QC 验货 | X28: Cherie Li | Y28: 4.19 | Z28: =Y28*I28 -> 2514 | AB28: 77673-S004 | AC28: 已入 | AE28: 已完成 | AG28: 600 | AH28: =AG28-I28 -> 0 | AL28: =I28 -> 600 | AP28: =I28 -> 600 | AR28: =I28 -> 600 | AT28: =I28 -> 600
A29: 45737 | B29: ASIA GOAL LIMITED | C29: 香港 | D29: 4500160943 | E29: AG240427-HK | F29: 4500160943-20 | G29: 77673TQ1-S001 | H29: 迷你冰箱4pcs/箱 | I29: 608 | J29: 0 | K29: 4 | L29: =I29/K29 -> 152 | M29: 45792 | N29: 45789 | P29: PASS | R29: 45737 | S29: 无 | T29: 45755 | U29: 客供警告语贴纸 | W29: 日期码格式：ZURU INC(BVI) 标准格式 日期：按实际生产日期 Packaging Info: 77711GQ1 （INT): MA 3L 收缩膜+1张UPC 条码贴纸+ MA 3L PDQ+MA 5L 收藏指南+客供警语贴纸 （1张贴球底部，1张贴说明书，1张贴收藏指南） 77673TQ1:MA 1L 收缩膜+MA 1L PDQ+MA 5L 收藏指南+MA 说明书+1张客供警语贴纸+1张客供电池警语贴纸+1张客供中文警告说明书） Remark: 此单出香港 | X29: Doris Shou | Y29: 5 | Z29: =Y29*I29 -> 3040 | AB29: 77673TQ1-S001 | AC29: 已入 | AE29: 已完成 | AG29: 608 | AH29: =AG29-I29 -> 0 | AL29: =I29 -> 608 | AQ29: =I29 -> 608 | AR29: =I29 -> 608 | AT29: =I29 -> 608 | BE29: =I29/4 -> 152
A30: 45742 | B30: ASIA GOAL LIMITED TAIWAN BRANCH (H. | C30: 台湾 | D30: 4500161426 | E30: AG240431-TW | F30: 4500161426-20 | G30: 77673TQ1-S001 | H30: 迷你冰箱4pcs/箱 | I30: 240 | J30: 0 | K30: 4 | L30: =I30/K30 -> 60 | M30: 45792 | N30: 45789 | P30: PASS | R30: 45742 | S30: 无 | T30: 45755 | W30: 日期码格式：ZURU INC(BVI) 标准格式 日期：按实际生产日期 Packaging Info: 77673TQ1：MA 1L 收缩膜+MA 1L PDQ+MA 5L 收藏指南+MA 说明书+1张警语贴纸 Remark: 此单出TW | X30: Doris Shou | Y30: 5 | Z30: =Y30*I30 -> 1200 | AB30: 77673TQ1-S001 | AC30: 已入 | AE30: 已完成 | AG30: 240 | AH30: =AG30-I30 -> 0 | AL30: =I30 -> 240 | AP30: =I30 -> 240 | AR30: =I30 -> 240 | AT30: =I30 -> 240 | BE30: =I30/4 -> 60
A31: 45757 | B31: PPTOYS PTE LTD (SG) | C31: 新加坡 | D31: 4500163177 | E31: ZU25032701SG | F31: 4500163177-20 | G31: 77673-S001 | H31: 迷你冰箱 | I31: 720 | J31: 0 | K31: 12 | L31: =I31/K31 -> 60 | M31: 45792 | N31: 45789 | P31: PASS | R31: 45758 | S31: 无 | T31: 45762 | W31: 日期码格式：ZURU INC(BVI) 标准格式 日期：按实际生产日期 Packaging Info: 1. 77673因系统问题，暂时开40GP，待系统维护后会改成20GP发过来。 2. 77673-MA UPC包装（优先1L)+1张进口商贴纸 77673进口商贴纸资料待提供。 Remark: 77673-Filxed Collection， 3PCS AG13 BATTERIES(INCLUDED) | X31: Emma Wu | Y31: 4.18 | Z31: =Y31*I31 -> 3009.6 | AB31: 77673-S001 | AC31: 已入 | AE31: 已完成 | AG31: 东莞安排 | AH31: =AG31-I31 -> #VALUE! | AL31: =I31 -> 720 | AP31: =I31 -> 720 | AR31: =I31 -> 720 | AT31: =I31 -> 720
A32: 45733 | B32: WAL-MART CANADA CORP. | C32: 加拿大 | D32: 4500160504 | E32: 9900923472 | F32: 4500160504-50 | G32: 77673-S002 | H32: 迷你冰箱 | I32: 10 | J32: 0 | K32: 2 | L32: =I32/K32 -> 5 | M32: 45793 | N32: 45789 | O32: 5/19 第三方验货，77673需于2025/4/18安排签版, 签样数量：空PDQ2PCS, 大货样各4PCS+齐套散件3套; 9. #77673 需于2025/4/28安排抽办测试, 抽办数量：大货4 pcs+齐套散件4SETS; | P32: PASS | R32: 45748 | S32: 无 | T32: 45734 | W32: 日期码格式：ZURU INC(BVI) 标准格式 日期：按实际生产日期 Packaging Info: #77673： MA3L收缩膜+UPC贴纸(UPC:193052079404)+MA23L说明书+MA5L收藏指南+MA5L,UV胶瓶身贴 产品配比： 7 Assortment, Polar bear: Penguin: Walrus: Mammoth: Owl: Seal: Snow man=10:10:10:10:10:8:2. Snow man is the rare item. Remark: 1. 此单有箱唛； 2. 9900923472单为ECOM订单，外箱四面须加一张黄色贴纸； 3. 此单有第三方验货，烦请多备包装物料； 5. #77673需于2025/4/18安排签版, 签样数量：空PDQ2PCS, 大货样各4PCS+齐套散件3套; 9. #77673 需于2025/4/28安排抽办测试, 抽办数量：大货4 pcs+齐套散件4SETS; 11. UPC贴纸：必须在原来错误的条码上用黑色粗头笔涂黑直至不能扫描，再贴上正确的UPC; ********************* a. 请确保产品符合1999年版本的加拿大环境保护法(CEPA)和2012年禁止某些有毒物质法规的要求。该产品不含任何在加拿大禁用的化学物质，包括但不限于有毒物 质清单中列出的化学物质，并且在为加拿大沃尔玛生产产品期间没有使用任何禁用化学物质。 Supplier certify that the products comply with the requirements of Canadian Environmental Protection Act, 1999 (CEPA), Prohibition of Certain To xic Substances Regulations, 2012. The products do not contain any chemicals that are banned in Canada, including but not limited to those listed in the Toxic Substances List and no banned chemicals were used during the manufacturing of product for Walmart Canada. 附件列表： (1) Letter of Guarantee for Canada banned chemicals - (1-5CA) b. 请确保产品在均质材料中的汞浓度不超过0.1%（按重量计）。 Supplier certify that the WAL-MART vendor products does not have a mercury concentration of more than 0.1% by weight in homogeneous material. 附件列表： (1) Letter of Guarantee for Mercury COC c. 请确保产品的塑料材料不含以下物质（SOR 2011-17 27B): Supplier certify that the plastic materials do not contain the following substances(SOR 2011-17 27B): (a) carbon tetrachloride or any substance that contains it; (b) methyl alcohol or any substance thay contains >1.0%; (c) petroleum distillates or any substance that contains >10% weight to volume of petroleum distillates; (d) benzene; (e) turpentine or any substance that contains >10% weight to volume of turpentine; (f) boric acid or salts of boric acid; or (g) ethyl ether. 附件列表： (1) Letter of Guarantee for WM CA-Other prohibited substances in plastic(less than 3 years) | X32: Monica Zhou | Y32: 4.1 | Z32: =Y32*I32 -> 41 | AB32: 77673-S002 | AC32: 已入 | AE32: 已完成 | AG32: 10 | AH32: =AG32-I32 -> 0 | AL32: =I32 -> 10 | AQ32: =I32 -> 10 | AR32: =I32 -> 10 | AT32: =I32 -> 10
A33: 45733 | B33: WAL-MART CANADA CORP. | C33: 加拿大 | D33: 4500160504 | E33: 9900924260 | F33: 4500160504-60 | G33: 77673-S002 | H33: 迷你冰箱 | I33: 1996 | J33: 0 | K33: 2 | L33: =I33/K33 -> 998 | M33: 45793 | N33: 45789 | O33: 5/19 第三方验货，77673需于2025/4/18安排签版, 签样数量：空PDQ2PCS, 大货样各4PCS+齐套散件3套; 9. #77673 需于2025/4/28安排抽办测试, 抽办数量：大货4 pcs+齐套散件4SETS; | P33: PASS | R33: 45748 | S33: 无 | T33: 45734 | W33: 日期码格式：ZURU INC(BVI) 标准格式 日期：按实际生产日期 Packaging Info: #77673： MA3L收缩膜+UPC贴纸(UPC:193052079404)+MA23L说明书+MA5L收藏指南+MA5L,UV胶瓶身贴 产品配比： 7 Assortment, Polar bear: Penguin: Walrus: Mammoth: Owl: Seal: Snow man=10:10:10:10:10:8:2. Snow man is the rare item. Remark: 1. 此单有箱唛； 3. 此单有第三方验货，烦请多备包装物料； 5. #77673需于2025/4/18安排签版, 签样数量：空PDQ2PCS, 大货样各4PCS+齐套散件3套; 9. #77673 需于2025/4/28安排抽办测试, 抽办数量：大货4 pcs+齐套散件4SETS; 11. UPC贴纸：必须在原来错误的条码上用黑色粗头笔涂黑直至不能扫描，再贴上正确的UPC; ********************* a. 请确保产品符合1999年版本的加拿大环境保护法(CEPA)和2012年禁止某些有毒物质法规的要求。该产品不含任何在加拿大禁用的化学物质，包括但不限于有毒物 质清单中列出的化学物质，并且在为加拿大沃尔玛生产产品期间没有使用任何禁用化学物质。 Supplier certify that the products comply with the requirements of Canadian Environmental Protection Act, 1999 (CEPA), Prohibition of Certain To xic Substances Regulations, 2012. The products do not contain any chemicals that are banned in Canada, including but not limited to those listed in the Toxic Substances List and no banned chemicals were used during the manufacturing of product for Walmart Canada. 附件列表： (1) Letter of Guarantee for Canada banned chemicals - (1-5CA) b. 请确保产品在均质材料中的汞浓度不超过0.1%（按重量计）。 Supplier certify that the WAL-MART vendor products does not have a mercury concentration of more than 0.1% by weight in homogeneous material. 附件列表： (1) Letter of Guarantee for Mercury COC c. 请确保产品的塑料材料不含以下物质（SOR 2011-17 27B): Supplier certify that the plastic materials do not contain the following substances(SOR 2011-17 27B): (a) carbon tetrachloride or any substance that contains it; (b) methyl alcohol or any substance thay contains >1.0%; (c) petroleum distillates or any substance that contains >10% weight to volume of petroleum distillates; (d) benzene; (e) turpentine or any substance that contains >10% weight to volume of turpentine; (f) boric acid or salts of boric acid; or (g) ethyl ether. 附件列表： (1) Letter of Guarantee for WM CA-Other prohibited substances in plastic(less than 3 years) | X33: Monica Zhou | Y33: 4.1 | Z33: =Y33*I33 -> 8183.6 | AB33: 77673-S002 | AC33: 已入 | AE33: 已完成 | AG33: =1968+28 -> 1996 | AH33: =AG33-I33 -> 0 | AL33: =I33 -> 1996 | AQ33: =I33 -> 1996 | AR33: =I33 -> 1996 | AT33: =I33 -> 1996
A34: 45744 | B34: WALMART INC. | C34: 美国 | D34: 4500161761 | E34: 0904512278 | F34: 4500161761-10 | G34: 77673TQ1-S001 | H34: 迷你冰箱4pcs/箱 | I34: 912 | J34: 0 | K34: 4 | L34: =I34/K34 -> 228 | M34: 45793 | N34: 45789 | O34: 5/19 第三方验货 | P34: PASS | R34: 外箱印刷带条码的RFID箱唛：RFID紫色色带+WM Dept.图标+RFID图标+ITF-14条码，四面右下角印刷ZURU logo, ITFF条码只印刷在正唛一面，在加印的时候确保 条形码能扫描出来，外箱侧面任一角落加印："MADE IN CHINA" 字样； | S34: 无 | T34: RFID贴纸 | U34: RFID贴纸 | W34: 日期码格式：ZURU DGYYYYMMDD CHINA(日期避开周末和法定节假日即可） 日期：按实际生产日期 Packaging Info: 77673TQ1-S001 1.包装要求： MA 1L A版收缩膜+MA 5L 收藏指南+MA 说明书+MA playset，翻单：4500159641 每pcs产品上要贴1张RFID贴纸，贴纸由ZURU提供，贴纸位置请严格按照我们签回的签板； Remark: 77673TQ1-S001 1.包装要求： MA 1L A版收缩膜+MA 5L 收藏指南+MA 说明书+MA playset，翻单：4500159641 每pcs产品上要贴1张RFID贴纸，贴纸由ZURU提供，贴纸位置请严格按照我们签回的签板； 2. 外箱印刷带条码的RFID箱唛：RFID紫色色带+WM Dept.图标+RFID图标+ITF-14条码，四面右下角印刷ZURU logo, ITFF条码只印刷在正唛一面，在加印的时候确保 条形码能扫描出来，外箱侧面任一角落加印："MADE IN CHINA" 字样； 3. 在产品上和包装上要有日期码、以及要有MADE IN CHINA和ZURU字样； 4. 产品如有扎带口要剪平，不能刮手。 5. 此单需要验货，请多备料 6. 此单以loose carton出货，4pcs/PDQ/CTN | X34: Maggie Xie | Y34: 5 | Z34: =Y34*I34 -> 4560 | AB34: 77673TQ1-S001 | AC34: 已入 | AE34: 已完成 | AG34: 912 | AH34: =AG34-I34 -> 0 | AL34: =I34 -> 912 | AP34: =I34 -> 912 | AR34: =I34 -> 912 | AT34: =I34 -> 912 | BD34: =I34/4 -> 228
A35: 45742 | B35: TAS IMPORT AS(Lekekassen) | C35: 挪威 | D35: 4500160993 | E35: 11098 | F35: 4500160993-30 | G35: 77673-S001 | H35: 迷你冰箱 | I35: 240 | J35: 0 | K35: 12 | L35: =I35/K35 -> 20 | M35: 45793 | N35: 45789 | P35: PASS | R35: 45758 | S35: 无 | T35: 45762 | W35: 日期码格式：ZURU INC(BVI) 标准格式 日期：按实际生产日期 Packaging Info: 3. 77673: MA 3L EAN版收缩膜+挪威/瑞典/丹麦语警告语/客人进口商地址贴纸做成一张贴纸+MA 5L收藏指南+MA 电池+UV胶警告语-23L + WEEE__带电池走货北欧六 语通用黑白说明书 4. 配比跟MA Remark: 1. 包装如含PVC,请改为PET并第一时间通知跟单 2. 产品/包装要求无硼无香，出欧洲，微塑料需合规。 3.带电池出货的产品所用到的电池需要符合欧洲电池新规(EU) 2023-1542 4.有胶袋的产品：要求产品的胶袋厚度要大于等于0.05mm 5.关于贴纸，如果贴纸位置图的包装版本与大货不一致，请工厂第一时间提前提出。跟单会重新调整确认是否更新贴纸或调整位置图 6.产品/包装不含PFAS成分 7.产品条码如下: 请先检查条码是否正确再安排做货，如有问题请告知 ZURU ITEM#<(>&<)>EAN 77673:4894680042773 | X35: Sheba | Y35: 4.1 | Z35: =Y35*I35 -> 984 | AB35: 77673-S001-3L | AC35: 已入 | AE35: 已完成 | AG35: 240 | AH35: =AG35-I35 -> 0 | AL35: =I35 -> 240 | AQ35: =I35 -> 240 | AR35: =I35 -> 240 | AT35: =I35 -> 240
A36: 45727 | B36: TARGET US | C36: 美国 | D36: 4500159604 | E36: 10001232749-3890 | F36: 4500159604-10 | G36: 77673TQ1-S001-CC | H36: 迷你冰箱 4pcs/箱（客版配件） | I36: 4704 | J36: 0 | K36: 4 | L36: =I36/K36 -> 1176 | M36: 45777 | N36: 45789 | P36: PASS | R36: 45743 | S36: 有 | T36: 45749 | W36: 日期码格式：ZURU INC(BVI) 标准格式 日期：按实际生产日期 Packaging Info: 77673TQ1：产品包装 客版收缩膜+客版收藏指南+MA说明书+ MA 1L PDQ；客版收缩膜+客版收藏指南翻单4500158149 Remark: 77673TQ1: 1. 77673TQ1-S001-CC-MINI BRANDS-FILL THE FRIDGE PLAYSET-SERIES 1-SHRINK WRAP,4PCS/PDQ,4PCS/PDQ/CTN 2. 产品包装 客版收缩膜+客版收藏指南+MA说明书+ MA 1L PDQ；客版收缩膜上的UPC显示193052079404；客版收缩膜+客版收藏指南翻单4500158149 3. 外箱正唛左上角位置粘贴条码箱贴纸，每箱只贴一张，由ZURU订购。来料贴纸上显示的客户DPCI# 086-02-3468， UPC显示10193052079401; 此订单所有item： 1. 产品和包装上印刷 tracking code信息，格式为ZURU常规格式; 2. 出货方式：货代自提 | X36: Holly Zheng | Y36: 5.53 | Z36: =Y36*I36 -> 26013.12 | AB36: 77673TQ1-S001-CC | AC36: 已入 | AE36: 已完成 | AG36: 东莞安排 | AH36: =AG36-I36 -> #VALUE! | AN36: =I36 -> 4704 | AT36: =I36 -> 4704 | BB36: =I36 -> 4704 | BC36: =I36 -> 4704 | BD36: =I36/4 -> 1176
A37: 45709 | B37: TARGET US | C37: 美国 | D37: 4500158149 | E37: 10001245308-3890 | F37: 4500158149-10 | G37: 77673TQ1-S001-CC | H37: 迷你冰箱 4pcs/箱（客版配件） | I37: 3416 | J37: 0 | K37: 4 | L37: =I37/K37 -> 854 | M37: 45775 | N37: 45789 | O37: 5/9 第三方验货 | P37: PASS | R37: 45748 | S37: 有 | T37: 45749 | W37: 日期码格式：ZURU INC(BVI) 标准格式 日期：按实际生产日期 Packaging Info: 77673TQ1：产品包装 客版收缩膜+客版收藏指南+MA说明书+ MA 1L PDQ； Remark: 77673TQ1: 1. 77673TQ1-S001-CC-MINI BRANDS-FILL THE FRIDGE PLAYSET-SERIES 1-SHRINK WRAP,4PCS/PDQ,4PCS/PDQ/CTN 2. 产品包装 客版收缩膜+客版收藏指南+MA说明书+ MA 1L PDQ；客版收缩膜上的UPC显示193052079404； 3. 外箱正唛左上角位置粘贴条码箱贴纸，每箱只贴一张，由ZURU订购。来料贴纸上显示的客户DPCI# 086-02-3468， UPC显示10193052079401; 4. 外箱正唛箱唛内容右侧需贴一张Event label，内容显示Toys Set Date：7/20/2025，工厂自行订购； 此订单所有item： 1. 产品和包装上印刷 tracking code信息，格式为ZURU常规格式; 2. 出货方式：货代自提 | X37: Holly Zheng | Y37: 5.53 | Z37: =Y37*I37 -> 18890.48 | AB37: 77673TQ1-S001-CC | AC37: 已入 | AE37: 已完成 | AG37: 东莞安排 | AH37: =AG37-I37 -> #VALUE! | AN37: =I37 -> 3416 | AT37: =I37 -> 3416 | BB37: =I37 -> 3416 | BC37: =I37 -> 3416 | BD37: =I37/4 -> 854
A38: 45670 | B38: Smyths Toys HQ UC UK | C38: 爱尔兰 | D38: 4500155602 | E38: PO4400460300 | F38: 4500155602-10 | G38: 77673TQ1-S003 | H38: 迷你冰箱 | I38: 3008 | J38: 0 | K38: 8 | L38: =I38/K38 -> 376 | M38: 45796 | N38: 45792 | P38: PASS | R38: 45670 | S38: 无 | T38: WEEE声明(带电池)走货欧洲通用30L-B版说明书 | W38: 日期码格式：ZURU INC(BVI) 标准格式 日期：按实际生产日期 Packaging Info: 77673TQ1：最新MA PDQ(优先3L )+客版收缩膜+23L说明书+客版收藏指南+客版WEEE声明通用说明书(带电池) （所有资料翻#4500155594） 客户PO号码请参考remark Remark: 1）包装日期码按ZURU格式即可，请确保不迟于外箱日期码，可等于或者早于外箱日期码，必须为法定工作日，印刷前请先检查外箱日期码。 2）订单出英国，请注意检查产品及包装应带UKCA图标（14+产品除外），包装显示ZURU UK LTD/ZURU France地址信息，QC部门请查核，如有问题与跟单确认 3) 需要完全符合欧洲标准(符合微塑料法规)，否则不合法规会有客诉产生 | X38: Ula Zhao | Y38: 5 | Z38: =Y38*I38 -> 15040 | AB38: 77673TQ1-S003 | AC38: 已入 | AE38: 已完成 | AG38: =3000+8 -> 3008 | AH38: =AG38-I38 -> 0 | AL38: =I38 -> 3008 | AT38: =I38 -> 3008 | AZ38: =I38 -> 3008 | BA38: =I38 -> 3008 | BE38: =I38/4 -> 752
A39: 45670 | B39: Smyths Toys HQ UC UK | C39: 爱尔兰 | D39: 4500155602 | E39: PO4400460306 | F39: 4500155602-20 | G39: 77673TQ1-S003 | H39: 迷你冰箱 | I39: 1504 | J39: 0 | K39: 8 | L39: =I39/K39 -> 188 | M39: 45796 | N39: 45792 | P39: PASS | R39: 45670 | S39: 无 | T39: WEEE声明(带电池)走货欧洲通用30L-B版说明书 | W39: 日期码格式：ZURU INC(BVI) 标准格式 日期：按实际生产日期 Packaging Info: 77673TQ1：最新MA PDQ(优先3L )+客版收缩膜+23L说明书+客版收藏指南+客版WEEE声明通用说明书(带电池) （所有资料翻#4500155594） 客户PO号码请参考remark Remark: 1）包装日期码按ZURU格式即可，请确保不迟于外箱日期码，可等于或者早于外箱日期码，必须为法定工作日，印刷前请先检查外箱日期码。 2）订单出英国，请注意检查产品及包装应带UKCA图标（14+产品除外），包装显示ZURU UK LTD/ZURU France地址信息，QC部门请查核，如有问题与跟单确认 3) 需要完全符合欧洲标准(符合微塑料法规)，否则不合法规会有客诉产生 | X39: Ula Zhao | Y39: 5 | Z39: =Y39*I39 -> 7520 | AB39: 77673TQ1-S003 | AC39: 已入 | AE39: 已完成 | AG39: 1504 | AH39: =AG39-I39 -> 0 | AL39: =I39 -> 1504 | AT39: =I39 -> 1504 | AZ39: =I39 -> 1504 | BA39: =I39 -> 1504 | BE39: =I39/4 -> 376
A40: 45758 | B40: TOYS "R" US (CANADA) LTD. | C40: 加拿大 | D40: 4500163438 | E40: 3501527805 | F40: 4500163438-10 | G40: 77673-S001 | H40: 迷你冰箱 | I40: 1104 | J40: 0 | K40: 12 | L40: =I40/K40 -> 92 | M40: 45796 | N40: 45792 | O40: 需要第三方SGS验货，验货时间2025/05/19，每款每色请备1PC完整带包装样品供验货人员参考。用完后若无损坏可以放回大货里。 | P40: PASS | R40: 45764 | S40: 无 | T40: 45764 | W40: 日期码格式：ZURU INC(BVI) 标准格式 日期：按实际生产日期 Packaging Info: 1. 出口加拿大市场，MA UPC版本包装。 #77673: MA 3L EAN版本 +UPC贴纸；UPC#193052079404; 3PCS AG13 BATTERIES(INCLUDED) 2. 产品、包装、外箱上面tracking code的时间格式需要一致 Remark: 3. 需要第三方SGS验货，验货时间2025/05/19，每款每色请备1PC完整带包装样品供验货人员参考。用完后若无损坏可以放回大货里。 | X40: Abby Mai,Lluvia Zeng | Y40: 4.1 | Z40: =Y40*I40 -> 4526.4 | AB40: 77673-S001-3L | AC40: 已入 | AE40: 已完成 | AG40: 1104 | AH40: =AG40-I40 -> 0 | AL40: =I40 -> 1104 | AQ40: =I40 -> 1104 | AR40: =I40 -> 1104 | AT40: =I40 -> 1104
...

Sheet 77711
A1: 香港接单日期 | B1: 第三方客户名称 | C1: 走货国家 | D1: ZURU PO NO# | E1: 第三方客户 PO NO# | F1: SKU | G1: ITEM# | H1: 货品名称 | I1: PO数量(只) | J1: 内箱装箱数量(只) | K1: 外箱装箱数量(只) | L1: 总箱数 | M1: 计划出货期 | N1: 计划验货期 | O1: 第三方客户公证行验货 | P1: 验货结果 | Q1: S/O(截仓期) | R1: 箱唛 (收到日期) | S1: 外箱贴纸 | T1: 贴纸资料 (收到日期及订购日期) | U1: 其他物料 | V1: 备注 | W1: ZURU跟单组员 | X1: 单价USD | Y1: 金额USD | Z1: 发票号 | AA1: 系统货号 | AB1: 是否入系统 | AC1: 下单情况 | AD1: 生产情况 | AE1: 采购单 | AF1: 已回数量 | AG1: 欠数 | AH1: HN回复完成时间 | AI1: 贴纸 | AJ1: 纸箱 | AK1: 77711 NA 球数 | AL1: 77711 INT 球数 | AM1: MA 1L A收缩膜 | AN1: MA 2L 收缩膜 无条码 | AO1: MA 3L 收缩膜 无条码 | AP1: MA 2L 收缩膜 | AQ1: MA 3L 收缩膜 | AR1: MA 2L 收藏指南（NA） | AS1: MA 5L 收藏指南（INT） | AT1: 中文单专用客版收缩膜 | AU1: 中文吊牌/收藏指南 | AV1: 77803收缩膜 | AW1: 77803客版收藏指南 | AX1: 中文黑白说明书 | AY1: UV胶黑白说明书 | AZ1: 客版收缩膜 | BA1: BJ'S WHOLESALE CLUB, INC.客版收缩膜及收藏指南 | BB1: Smyths 客版收缩膜 | BC1: COSTCO 客版收缩膜 | BD1: COSTCO 客版收藏指南 | BE1: COSTCO 客版彩盒 | BF1: COSTCO 客版PDQ | BG1: GQ1 1L 13pcs | BH1: GQ1 2L 13PCS | BI1: GQ1 3L 13PCS | BJ1: GQ2 1L 25pcs | BK1: GQ2 2L 25pcs | BL1: GQ2 3L 25pcs | BM1: 1L 16PCS GQ4 | BN1: 3L 16PCS GQ4 | BO1: 客版 8PCS GQ5 | BP1: 客版 6PCS GQ6 | BQ1: 77782收缩膜 | BR1: 77782收藏指南 | BS1: 77782 PDQ | BT1: 77785 1L 彩盒 | BU1: 77785 3L INT彩盒 | BV1: 77785 3L NA彩盒 | BW1: 77758彩盒 | BX1: 77758托盘 | BY1: MEC356 | BZ1: MEC305 | CA1: 1L SK-S002 含底座 60pcs | CB1: 2L SK-S002 含底座 60pcs | CC1: 3L SK-S002 含底座 60pcs | CD1: 2L SK-S001 无底座 60pcs | CE1: 2L SK1-S001 30pcs | CF1: 3L SK1-S002 30pcs | CG1: 客版 77803SK1-S002 30pcs | CH1: 77731圆筒 | CI1: 77731彩纸 | CJ1: 77731贴纸 | CK1: GQ2/4展示小产品 | CL1: SK展示小产品 | CM1: MEC305展示小产品
A2: 45651 | C2: 库有 | D2: ZMPO24991 | G2: 77711-S001-NA | H2: 冰箱迷你球24pcs/箱 | I2: 500 | J2: 0 | K2: 24 | L2: =I2/K2 -> 20.833333 | R2: 周转箱 | S2: 无 | T2: 无 | V2: Remark：跟PP单一起安排 备注： 此板单为TVC 拍摄样板单，PM 有提供让工厂备料，请与PP一起交货，谢谢 | W2: Angus | AA2: N/A | AB2: N/A | AD2: 已完成 | AG2: =AF2-I2 -> -500 | AK2: =I2 -> 500 | CK2: =BM2+BL2+BK2+BJ2+BS2 -> 0 | CL2: =CA2+CB2+CC2+CD2+CE2+CG2+CF2 -> 0 | CM2: =BY2+BZ2 -> 0
A3: 45651 | C3: 库有 | D3: ZMPO24991 | G3: 77711-S001-NA | H3: 冰箱迷你球24pcs/箱 | I3: 25套散件 | J3: 0 | K3: 24 | R3: 周转箱 | S3: 无 | T3: 无 | V3: Remark：跟PP单一起安排/只需要齐套散件/麻烦用胶袋分装好一套为一袋 备注： 此板单为TVC 拍摄样板单，PM 有提供让工厂备料，请与PP一起交货，谢谢 | W3: Angus | AA3: N/A | AB3: N/A | AD3: 已完成 | CK3: =BM3+BL3+BK3+BJ3+BS3 -> 0 | CL3: =CA3+CB3+CC3+CD3+CE3+CG3+CF3 -> 0 | CM3: =BY3+BZ3 -> 0
A4: 45651 | C4: 库有 | D4: ZMPO24991 | G4: 77711-S001-INT | H4: 冰箱迷你球pcs24/箱 | I4: 200 | J4: 0 | K4: 24 | L4: =I4/K4 -> 8.3333333 | R4: 周转箱 | S4: 无 | T4: 无 | V4: Remark：跟PP单一起安排 备注： 此板单为TVC 拍摄样板单，PM 有提供让工厂备料，请与PP一起交货，谢谢 | W4: Angus | AA4: N/A | AB4: N/A | AD4: 已完成 | AG4: =AF4-I4 -> -200 | AL4: =I4 -> 200 | CK4: =BM4+BL4+BK4+BJ4+BS4 -> 0 | CL4: =CA4+CB4+CC4+CD4+CE4+CG4+CF4 -> 0 | CM4: =BY4+BZ4 -> 0
A5: 45651 | C5: 库有 | D5: ZMPO24991 | G5: 77711-S001-INT | H5: 冰箱迷你球pcs24/箱 | I5: 25套散件 | J5: 0 | K5: 24 | R5: 周转箱 | S5: 无 | T5: 无 | V5: Remark：跟PP单一起安排/只需要齐套散件/麻烦用胶袋分装好一套为一袋 备注： 此板单为TVC 拍摄样板单，PM 有提供让工厂备料，请与PP一起交货，谢谢 | W5: Angus | AA5: N/A | AB5: N/A | AD5: 已完成 | CK5: =BM5+BL5+BK5+BJ5+BS5 -> 0 | CL5: =CA5+CB5+CC5+CD5+CE5+CG5+CF5 -> 0 | CM5: =BY5+BZ5 -> 0
A6: 45652 | C6: 库有 | D6: ZMPO24995 | G6: 77711-S001-NA | H6: 冰箱迷你球24pcs/箱 | I6: 504 | J6: 0 | K6: 24 | L6: =I6/K6 -> 21 | R6: 周转箱 | S6: 无 | T6: 无 | V6: Remark：跟PP单一起安排/大货标准箱装箱/箱唛参照邮件附件 备注： 请跟PP订单一起安排，谢谢 | W6: Angus | AA6: N/A | AB6: N/A | AD6: 已完成 | AK6: =I6 -> 504 | CK6: =BM6+BL6+BK6+BJ6+BS6 -> 0 | CL6: =CA6+CB6+CC6+CD6+CE6+CG6+CF6 -> 0 | CM6: =BY6+BZ6 -> 0
A7: 45652 | C7: 库有 | D7: ZMPO24995 | G7: 77711-S001-NA | H7: 冰箱迷你球24pcs/箱 | I7: 5套散件 | J7: 0 | K7: 24 | R7: 周转箱 | S7: 无 | T7: 无 | V7: Remark：跟PP单一起安排/只需要齐套散件/麻烦用胶袋分装好一套为一袋 备注： 请跟PP订单一起安排，谢谢 | W7: Angus | AA7: N/A | AB7: N/A | AD7: 已完成 | CK7: =BM7+BL7+BK7+BJ7+BS7 -> 0 | CL7: =CA7+CB7+CC7+CD7+CE7+CG7+CF7 -> 0 | CM7: =BY7+BZ7 -> 0
A8: 45652 | C8: 库有 | D8: ZMPO24995 | G8: 77711GQ1-S001-NA | H8: 冰箱迷你球 | I8: 20个空PDQ | R8: 周转箱 | S8: 无 | T8: 无 | V8: Remark：跟PP单一起安排/只需要空PDQ/请配齐PDQ上应有的物料如展示公仔/吸塑等 备注： 请跟PP订单一起安排，谢谢 | W8: Angus | AA8: N/A | AB8: N/A | AD8: 已完成 | BH8: 20 | CK8: =BM8+BL8+BK8+BJ8+BS8 -> 0 | CL8: =CA8+CB8+CC8+CD8+CE8+CG8+CF8 -> 0 | CM8: =BY8+BZ8 -> 0
A9: 45652 | C9: 库有 | D9: ZMPO24995 | G9: 77711GQ2-S001-NA | H9: 冰箱迷你球 | I9: 20个空PDQ | R9: 周转箱 | S9: 无 | T9: 无 | V9: Remark：跟PP单一起安排/只需要空PDQ/请配齐PDQ上应有的物料如展示公仔/吸塑等 备注： 请跟PP订单一起安排，谢谢 | W9: Angus | AA9: N/A | AB9: N/A | AD9: 已完成 | BJ9: 20 | CK9: =BM9+BL9+BK9+BJ9+BS9 -> 20 | CL9: =CA9+CB9+CC9+CD9+CE9+CG9+CF9 -> 0 | CM9: =BY9+BZ9 -> 0
A10: 45652 | C10: 库有 | D10: ZMPO24995 | G10: 77711-S001-INT | H10: 冰箱迷你球pcs24/箱 | I10: 504 | J10: 0 | K10: 24 | L10: =I10/K10 -> 21 | R10: 周转箱 | S10: 无 | T10: 无 | V10: Remark：跟PP单一起安排/大货标准箱装箱/箱唛参照邮件附件 备注：请跟PP订单一起安排，谢谢 | W10: Angus | AA10: N/A | AB10: N/A | AD10: 已完成 | AG10: =AF10-I10 -> -504 | AL10: =I10 -> 504 | CK10: =BM10+BL10+BK10+BJ10+BS10 -> 0 | CL10: =CA10+CB10+CC10+CD10+CE10+CG10+CF10 -> 0 | CM10: =BY10+BZ10 -> 0
A11: 45652 | C11: 库有 | D11: ZMPO24995 | G11: 77711-S001-INT | H11: 冰箱迷你球pcs24/箱 | I11: 5套散件 | J11: 0 | K11: 24 | R11: 周转箱 | S11: 无 | T11: 无 | V11: Remark：跟PP单一起安排/只需要齐套散件/麻烦用胶袋分装好一套为一袋 备注： 请跟PP订单一起安排，谢谢 | W11: Angus | AA11: N/A | AB11: N/A | AD11: 已完成 | CK11: =BM11+BL11+BK11+BJ11+BS11 -> 0 | CL11: =CA11+CB11+CC11+CD11+CE11+CG11+CF11 -> 0 | CM11: =BY11+BZ11 -> 0
A12: 45652 | C12: 库有 | D12: ZMPO24995 | G12: 77711GQ1-S001-INT | H12: 冰箱迷你球pcs52/箱 | I12: 20个空PDQ | R12: 周转箱 | S12: 无 | T12: 无 | V12: Remark：跟PP单一起安排/只需要空PDQ/请配齐PDQ上应有的物料如展示公仔/吸塑等 备注： 请跟PP订单一起安排，谢谢 | W12: Angus | AA12: N/A | AB12: N/A | AD12: 已完成 | BI12: 20 | CK12: =BM12+BL12+BK12+BJ12+BS12 -> 0 | CL12: =CA12+CB12+CC12+CD12+CE12+CG12+CF12 -> 0 | CM12: =BY12+BZ12 -> 0
A13: 45652 | C13: 库有 | D13: ZMPO24995 | G13: 77711GQ2-S001-INT | H13: 冰箱迷你球 | I13: 20个空PDQ | R13: 周转箱 | S13: 无 | T13: 无 | V13: Remark：跟PP单一起安排/只需要空PDQ/请配齐PDQ上应有的物料如展示公仔/吸塑等 备注： 请跟PP订单一起安排，谢谢 | W13: Angus | AA13: N/A | AB13: N/A | AD13: 已完成 | BL13: 20 | CK13: =BM13+BL13+BK13+BJ13+BS13 -> 20 | CL13: =CA13+CB13+CC13+CD13+CE13+CG13+CF13 -> 0 | CM13: =BY13+BZ13 -> 0
A14: 45650 | C14: PP | D14: ZPO2412010 | G14: 77711-S001-NA | H14: 冰箱迷你球24pcs/箱 | I14: 570 | J14: 0 | K14: 24 | L14: =I14/K14 -> 23.75 | R14: 周转箱 | S14: 无 | T14: 无 | W14: Alison Chen | AA14: N/A | AB14: N/A | AD14: 已完成 | CK14: =BM14+BL14+BK14+BJ14+BS14 -> 0 | CL14: =CA14+CB14+CC14+CD14+CE14+CG14+CF14 -> 0 | CM14: =BY14+BZ14 -> 0
A15: 45650 | C15: PP | D15: ZPO2412010 | G15: 77711-S001-INT | H15: 冰箱迷你球pcs24/箱 | I15: 670 | J15: 0 | K15: 24 | L15: =I15/K15 -> 27.916667 | R15: 周转箱 | S15: 无 | T15: 无 | W15: Alison Chen | AA15: N/A | AB15: N/A | AD15: 已完成 | CK15: =BM15+BL15+BK15+BJ15+BS15 -> 0 | CL15: =CA15+CB15+CC15+CD15+CE15+CG15+CF15 -> 0 | CM15: =BY15+BZ15 -> 0
A16: 45701 | B16: THE WAREHOUSE LIMITED | C16: 新西兰 | D16: 4500157534 | F16: 4500157534-40 | G16: 77711GQ2-S002-INT | H16: 冰箱迷你球pcs25/箱 | I16: 200 | J16: 0 | K16: 25 | L16: =I16/K16 -> 8 | M16: 45731 | N16: 45727 | R16: 45804 | S16: 无 | T16: 45804 | V16: 日期码格式：ZURU INC(BVI) 标准格式 日期：按实际生产日期 Packaging Info: MA UPC 英语包装（优先1L英语版本，或者3L/5L含英语都可） 此客人不接受易掉落或者剥落或者可直接触碰的闪粉，可降解也不行，但可以接受符合欧洲微塑料标准的珠光粉或者闪片。 所有外箱上都要贴一张大黄贴："ZURU Product for NZ test " Remark: | W16: Abby Liang | X16: 0.95 | Y16: =X16*I16 -> 190 | AA16: 77711GQ2-S002-INT | AB16: 已入 | AD16: 已完成 | AG16: =AF16-I16+200 -> 0 | AL16: =I16 -> 200 | AQ16: =I16 -> 200 | AS16: =I16 -> 200 | AY16: =I16/24 -> 8.3333333 | BL16: =I16/25 -> 8 | CK16: =BM16+BL16+BK16+BJ16+BS16 -> 8 | CL16: =CA16+CB16+CC16+CD16+CE16+CG16+CF16 -> 0 | CM16: =BY16+BZ16 -> 0
A17: 45722 | D17: ZMPO250187 | G17: 77711-S001-NA | H17: 冰箱迷你球24pcs/箱 | I17: 1584 | J17: 0 | K17: 24 | L17: =I17/K17 -> 66 | M17: 45736 | N17: 45733 | P17: PASS | R17: 45722 | S17: 无 | T17: 无 | V17: Remark：大货最新版本包装/大货标准箱装箱/箱唛请参照邮件附件；备注：收到样品订单后尽快安排 ，注意样板品质质量要求要高于大货品质要求 ，送货时必须要附带送货单(没有送货单和QC检验合格报告的仓库一律拒绝收货)，请知悉，谢谢！ | W17: Angus | AA17: 77711-S001（北美） | AB17: 已入 | AD17: 已完成 | AF17: 1584 | AG17: =AF17-I17 -> 0 | AK17: =I17 -> 1584 | AM17: =I17 -> 1584 | AR17: =I17 -> 1584 | AY17: =I17/48 -> 33 | CK17: =BM17+BL17+BK17+BJ17+BS17 -> 0 | CL17: =CA17+CB17+CC17+CD17+CE17+CG17+CF17 -> 0 | CM17: =BY17+BZ17 -> 0
A18: 45737 | D18: ZMPO250244 | G18: 77711-S001-NA | H18: 冰箱迷你球24pcs/箱 | I18: 20套散件 | J18: 0 | K18: 20 | L18: 1 | M18: 45740 | N18: 45736 | R18: 45737 | S18: 无 | T18: 无 | V18: Remark：大货版本/只需要左图中3款散件每款各20PCS,共60PCS；备注： 收到订单后请尽快安排，谢谢 | W18: Angus | AA18: N/A | AB18: N/A | AD18: 已完成 | AF18: 20 | AG18: =AF18-K18 -> 0 | CK18: =BM18+BL18+BK18+BJ18+BS18 -> 0 | CL18: =CA18+CB18+CC18+CD18+CE18+CG18+CF18 -> 0 | CM18: =BY18+BZ18 -> 0
A19: 45737 | D19: ZMPO250244 | G19: 77711-S001-INT | H19: 冰箱迷你球pcs24/箱 | I19: 1100套散件 | J19: 0 | K19: 550 | L19: 2 | M19: 45740 | N19: 45736 | R19: 45737 | S19: 无 | T19: 无 | V19: Remark：大货版本/只需要左图中2款散件每款各1100PCS,共2200PCS；备注： 收到订单后请尽快安排，谢谢 | W19: Angus | AA19: N/A | AB19: N/A | AD19: 已完成 | AF19: 1100 | AG19: =AF19-1100 -> 0 | CK19: =BM19+BL19+BK19+BJ19+BS19 -> 0 | CL19: =CA19+CB19+CC19+CD19+CE19+CG19+CF19 -> 0 | CM19: =BY19+BZ19 -> 0
A20: 45749 | D20: ZMPO250283 | G20: 77711-S001-NA | H20: 冰箱迷你球24pcs/箱 | I20: 80套散件 | J20: 0 | K20: 20 | L20: 1 | M20: 45757 | N20: 45754 | R20: 45749 | S20: 无 | T20: 无 | V20: Remark:大货最新版本/只需要齐套散件/麻烦用胶袋分装好一套为一袋/箱唛参照邮件附件;备注： 收到订单后请尽快安排，谢谢 | W20: Angus | AA20: N/A | AB20: N/A | AD20: 已完成 | CK20: =BM20+BL20+BK20+BJ20+BS20 -> 0 | CL20: =CA20+CB20+CC20+CD20+CE20+CG20+CF20 -> 0 | CM20: =BY20+BZ20 -> 0
A21: 45749 | D21: ZMPO250283 | G21: 77711-S001-INT | H21: 冰箱迷你球pcs24/箱 | I21: 30套散件 | J21: 0 | K21: 550 | L21: 2 | M21: 45757 | N21: 45754 | R21: 45749 | S21: 无 | T21: 无 | V21: Remark:大货最新版本/只需要齐套散件/麻烦用胶袋分装好一套为一袋/箱唛参照邮件附件;备注： 收到订单后请尽快安排，谢谢 | W21: Angus | AA21: N/A | AB21: N/A | AD21: 已完成 | CK21: =BM21+BL21+BK21+BJ21+BS21 -> 0 | CL21: =CA21+CB21+CC21+CD21+CE21+CG21+CF21 -> 0 | CM21: =BY21+BZ21 -> 0
A22: 45740 | D22: ZMPO250247 | G22: 77711-S001-NA | H22: 冰箱迷你球24pcs/箱 | I22: 600 | J22: 0 | K22: 24 | L22: =I22/K22 -> 25 | M22: 45759 | N22: 45755 | P22: PASS | R22: 45740 | S22: 无 | T22: 无 | V22: Remark：大货最新版本/大货标准箱装箱/箱唛参照邮件附件；备注： 收到订单后请尽快安排，谢谢 | W22: Angus | AA22: 77711-S001（北美） | AB22: 已入 | AD22: 已完成 | AF22: 600 | AG22: =AF22-I22 -> 0 | AK22: =I22 -> 600 | AM22: =I22 -> 600 | AR22: =I22 -> 600 | AY22: =I22/48 -> 12.5 | CK22: =BM22+BL22+BK22+BJ22+BS22 -> 0 | CL22: =CA22+CB22+CC22+CD22+CE22+CG22+CF22 -> 0 | CM22: =BY22+BZ22 -> 0
A23: 45740 | D23: ZMPO250247 | G23: 77711-S001-NA | H23: 冰箱迷你球24pcs/箱 | I23: 30套散件 | J23: 0 | K23: 24 | L23: 1 | M23: 45759 | N23: 45755 | R23: 45740 | S23: 无 | T23: 无 | V23: Remark：大货最新版本/只需要齐套散件/麻烦用胶袋分装好一套为一袋；备注： 收到订单后请尽快安排，谢谢 | W23: Angus | AA23: N/A | AB23: N/A | AD23: 已完成 | AF23: 30 | AG23: 0 | CK23: =BM23+BL23+BK23+BJ23+BS23 -> 0 | CL23: =CA23+CB23+CC23+CD23+CE23+CG23+CF23 -> 0 | CM23: =BY23+BZ23 -> 0
A24: 45740 | D24: ZMPO250247 | G24: 77711-S001-INT | H24: 冰箱迷你球pcs24/箱 | I24: 400 | J24: 0 | K24: 24 | L24: =I24/K24 -> 16.666667 | M24: 45759 | N24: 45755 | R24: 45740 | S24: 无 | T24: 无 | V24: Remark：大货最新版本/大货标准箱装箱/箱唛参照邮件附件；备注： 收到订单后请尽快安排，谢谢 | W24: Angus | AA24: 77711-S001-INT | AB24: 已入 | AD24: 已完成 | AF24: 400 | AG24: =AF24-I24 -> 0 | AL24: =I24 -> 400 | AQ24: =I24 -> 400 | AS24: =I24 -> 400 | AY24: =I24/24 -> 16.666667 | CK24: =BM24+BL24+BK24+BJ24+BS24 -> 0 | CL24: =CA24+CB24+CC24+CD24+CE24+CG24+CF24 -> 0 | CM24: =BY24+BZ24 -> 0
A25: 45740 | D25: ZMPO250247 | G25: 77711-S001-INT | H25: 冰箱迷你球pcs24/箱 | I25: 30套散件 | J25: 0 | K25: 24 | L25: 2 | M25: 45759 | N25: 45755 | R25: 45740 | S25: 无 | T25: 无 | V25: Remark：大货最新版本/只需要齐套散件/麻烦用胶袋分装好一套为一袋；备注： 收到订单后请尽快安排，谢谢 | W25: Angus | AA25: N/A | AB25: N/A | AD25: 已完成 | AF25: 30 | AG25: 0 | CK25: =BM25+BL25+BK25+BJ25+BS25 -> 0 | CL25: =CA25+CB25+CC25+CD25+CE25+CG25+CF25 -> 0 | CM25: =BY25+BZ25 -> 0
A26: 45726 | B26: WAL-MART STORES INC. USA | C26: 美国 | D26: 4500159672 | E26: 0902763064 | F26: 4500159672-10 | G26: 77711GQ4-S001-NA | H26: 冰箱迷你球16pcs/箱 | I26: 3136 | J26: 0 | K26: 16 | L26: =I26/K26 -> 196 | M26: 45770 | N26: 45766 | O26: 4/25 第三方抽办 | R26: 45727 | S26: 无 | T26: RFID贴纸 | V26: 日期码格式：ZURU DGYYYYMMDD CHINA(日期避开周末和法定节假日即可） 日期：按实际生产日期 Packaging Info: 77711GQ4-S001-NA 1.包装要求： MA 1L A版收缩膜+MA 5L A版收藏指南+MA 说明书+客版1L PDQ 每pcs产品上要贴1张RFID贴纸，贴纸由ZURU提供，贴纸位置请严格按照我们签回的签板； Remark: 77711GQ4-S001-NA 1.包装要求： MA 1L A版收缩膜+MA 5L A版收藏指南+MA 说明书+客版1L PDQ 每pcs产品上要贴1张RFID贴纸，贴纸由ZURU提供，贴纸位置请严格按照我们签回的签板； 2. 外箱印刷带条码的RFID箱唛：RFID紫色色带+WM Dept.图标+RFID图标+ITF-14条码，四面右下角印刷ZURU logo, ITFF条码只印刷在正唛一面，在加印的时候确保 条形码能扫描出来，外箱侧面任一角落加印："MADE IN CHINA" 字样； 3. 在产品上和包装上要有日期码、以及要有MADE IN CHINA和ZURU字样； 4. 产品如有扎带口要剪平，不能刮手。 5. 此单需要抽板和验货，抽板时间预计4/23，请多备料 6. 此单以loose carton出货，16pcs/PDQ/CTN | W26: Maggie Xie | X26: 1.68 | Y26: =X26*I26 -> 5268.48 | AA26: 77711GQ4-S001-NA | AB26: 已入 | AD26: 已完成 | AF26: =504+2632 -> 3136 | AG26: =AF26-I26 -> 0 | AK26: =I26 -> 3136 | AM26: =I26 -> 3136 | AR26: =I26 -> 3136 | AY26: =I26/48 -> 65.333333 | BM26: =I26/16 -> 196 | CK26: =BM26+BL26+BK26+BJ26+BS26 -> 196 | CL26: =CA26+CB26+CC26+CD26+CE26+CG26+CF26 -> 0 | CM26: =BY26+BZ26 -> 0
A27: 45761 | D27: ZMPO250315 | G27: 77711-S001-NA | H27: 冰箱迷你球24pcs/箱 | I27: 816 | J27: 0 | K27: 24 | L27: =I27/K27 -> 34 | M27: 45771 | N27: 45768 | P27: PASS | R27: 45761 | S27: 无 | T27: 无 | V27: Remark:大货最新版本包装/大货标准箱装箱/箱唛请参照邮件附件;备注： 收到样品订单后尽快安排 ，此订单麻烦在外箱上备注是海运订单/注意样板品质质量要求要高于大货品质质量 ，送货时必须要附带送货单(没有送货单和QC检验合格报告的仓库一律拒绝收货)，请知悉，谢谢！ | W27: Angus | AA27: 77711-S001（北美） | AB27: 已入 | AD27: 已完成 | AF27: 816 | AG27: =AF27-I27 -> 0 | AK27: =I27 -> 816 | AM27: =I27 -> 816 | AR27: =I27 -> 816 | AY27: =I27/48 -> 17 | CK27: =BM27+BL27+BK27+BJ27+BS27 -> 0 | CL27: =CA27+CB27+CC27+CD27+CE27+CG27+CF27 -> 0 | CM27: =BY27+BZ27 -> 0
A28: 45761 | D28: ZMPO250315 | G28: 77711-S001-INT | H28: 冰箱迷你球pcs24/箱 | I28: 504 | J28: 0 | K28: 24 | L28: 2 | M28: 45771 | N28: 45768 | P28: PASS | R28: 45761 | S28: 无 | T28: 无 | V28: Remark:大货最新版本包装/大货标准箱装箱/箱唛请参照邮件附件;备注： 收到样品订单后尽快安排 ，此订单麻烦在外箱上备注是海运订单/注意样板品质质量要求要高于大货品质质量 ，送货时必须要附带送货单(没有送货单和QC检验合格报告的仓库一律拒绝收货)，请知悉，谢谢！ | W28: Angus | AA28: N/A | AB28: N/A | AD28: 已完成 | AF28: 504 | AG28: =AF28-I28 -> 0 | AL28: =I28 -> 504 | AM28: =I28 -> 504 | AS28: =I28 -> 504 | AY28: =I28/24 -> 21 | CK28: =BM28+BL28+BK28+BJ28+BS28 -> 0 | CL28: =CA28+CB28+CC28+CD28+CE28+CG28+CF28 -> 0 | CM28: =BY28+BZ28 -> 0
A29: 45670 | B29: Smyths Toys HQ UC UK | C29: 爱尔兰 | D29: 4500155601 | E29: PO4400460299 | F29: 4500155601-10 | G29: 77711GQ2-S002-INT | H29: 冰箱迷你球pcs25/箱 | I29: 9000 | J29: 0 | K29: 25 | L29: =I29/K29 -> 360 | M29: 45772 | N29: 45768 | P29: PASS | R29: 45670 | S29: 无 | T29: 所有资料翻#4500155592 | V29: 日期码格式：ZURU INC(BVI) 标准格式 日期：按实际生产日期 Packaging Info: 77711GQ2：最新MA PDQ(优先3L)+客版收缩膜+23L说明书+5-23L警语收藏指南+MA 5L creative说明书+creative说明书荷兰语贴纸（所有资料翻#4500155592） 客户PO号码请参考remark Remark: 1）包装日期码按ZURU格式即可，请确保不迟于外箱日期码，可等于或者早于外箱日期码，必须为法定工作日，印刷前请先检查外箱日期码。 2）订单出英国，请注意检查产品及包装应带UKCA图标（14+产品除外），包装显示ZURU UK LTD/ZURU France地址信息，QC部门请查核，如有问题与跟单确认 3) 需要完全符合欧洲标准(符合微塑料法规)，否则不合法规会有客诉产生 | W29: Ula Zhao | X29: 1.24 | Y29: =X29*I29 -> 11160 | AA29: 77711GQ2-S002-INT-客版Smyths | AB29: 已入 | AD29: 已完成 | AF29: 9000 | AG29: =AF29-I29 -> 0 | AL29: =I29 -> 9000 | AS29: =I29 -> 9000 | AY29: =I29/48 -> 187.5 | BB29: =I29 -> 9000 | BL29: =I29/25 -> 360 | CK29: =BM29+BL29+BK29+BJ29+BS29 -> 360 | CL29: =CA29+CB29+CC29+CD29+CE29+CG29+CF29 -> 0 | CM29: =BY29+BZ29 -> 0
A30: 45670 | B30: Smyths Toys HQ UC UK | C30: 爱尔兰 | D30: 4500155601 | E30: PO4400460305 | F30: 4500155601-20 | G30: 77711GQ2-S002-INT | H30: 冰箱迷你球pcs25/箱 | I30: 3000 | J30: 0 | K30: 25 | L30: =I30/K30 -> 120 | M30: 45772 | N30: 45768 | P30: PASS | Q30: 4/28 出货 | R30: 45670 | S30: 无 | T30: 所有资料翻#4500155592 | V30: 日期码格式：ZURU INC(BVI) 标准格式 日期：按实际生产日期 Packaging Info: 77711GQ2：最新MA PDQ(优先3L)+客版收缩膜+23L说明书+5-23L警语收藏指南+MA 5L creative说明书+creative说明书荷兰语贴纸（所有资料翻#4500155592） 客户PO号码请参考remark Remark: 1）包装日期码按ZURU格式即可，请确保不迟于外箱日期码，可等于或者早于外箱日期码，必须为法定工作日，印刷前请先检查外箱日期码。 2）订单出英国，请注意检查产品及包装应带UKCA图标（14+产品除外），包装显示ZURU UK LTD/ZURU France地址信息，QC部门请查核，如有问题与跟单确认 3) 需要完全符合欧洲标准(符合微塑料法规)，否则不合法规会有客诉产生 | W30: Ula Zhao | X30: 1.24 | Y30: =X30*I30 -> 3720 | AA30: 77711GQ2-S002-INT-客版Smyths | AB30: 已入 | AD30: 已完成 | AF30: 3000 | AG30: =AF30-I30 -> 0 | AL30: =I30 -> 3000 | AS30: =I30 -> 3000 | AY30: =I30/48 -> 62.5 | BB30: =I30 -> 3000 | BL30: =I30/25 -> 120 | CK30: =BM30+BL30+BK30+BJ30+BS30 -> 120 | CL30: =CA30+CB30+CC30+CD30+CE30+CG30+CF30 -> 0 | CM30: =BY30+BZ30 -> 0
A31: 45728 | B31: THE WAREHOUSE LIMITED | C31: 新西兰 | D31: 4500159882 | F31: 4500159882-10 | G31: 77711SK-S002-INT | H31: 冰箱迷你球展示架（带底座） | I31: 2280 | J31: 0 | K31: 60 | L31: =I31/K31 -> 38 | M31: 45772 | N31: 45768 | P31: PASS | Q31: 4/25 出货 | R31: 45735 | S31: 无 | T31: 45735 | V31: 日期码格式：ZURU INC(BVI) 标准格式 日期：按实际生产日期 Packaging Info: #77673TQ1: 1.3PCS AG13 BATTERIES(INCLUDED)，有纽扣电池，包装正面和说明书都需要加电池警告语贴纸（法规要求） 2.Filxed Collection #77711需要加UPC贴纸 Remark: 1.MA UPC 英语包装（优先1L英语版本，或者3L/5L含英语都可） 2.此客人不接受易掉落或者剥落或者可直接触碰的闪粉，可降解也不行，但可以接受符合欧洲微塑料标准的珠光粉或者闪片。 | W31: Abby Liang | X31: 63.7 | Y31: =X31*L31 -> 2420.6 | AA31: 77711SK-S002-INT | AB31: 已入 | AD31: 已完成 | AF31: 2280 | AG31: =AF31-I31 -> 0 | AL31: =I31 -> 2280 | AQ31: =I31 -> 2280 | AS31: =I31 -> 2280 | AY31: =I31/24 -> 95 | CC31: =I31/60 -> 38 | CK31: =BM31+BL31+BK31+BJ31+BS31 -> 0 | CL31: =CA31+CB31+CC31+CD31+CE31+CG31+CF31 -> 38 | CM31: =BY31+BZ31 -> 0
A32: 45728 | B32: THE WAREHOUSE LIMITED | C32: 新西兰 | D32: 4500159886 | F32: 4500159886-10 | G32: 77711SK-S002-INT | H32: 冰箱迷你球展示架（带底座） | I32: 720 | J32: 0 | K32: 60 | L32: =I32/K32 -> 12 | M32: 45772 | N32: 45768 | P32: PASS | R32: 45735 | S32: 无 | T32: 45735 | V32: 日期码格式：ZURU INC(BVI) 标准格式 日期：按实际生产日期 Packaging Info: #77673TQ1: 1.3PCS AG13 BATTERIES(INCLUDED)，有纽扣电池，包装正面和说明书都需要加电池警告语贴纸（法规要求） 2.Filxed Collection #77711需要加UPC贴纸 Remark: 1.MA UPC 英语包装（优先1L英语版本，或者3L/5L含英语都可） 2.此客人不接受易掉落或者剥落或者可直接触碰的闪粉，可降解也不行，但可以接受符合欧洲微塑料标准的珠光粉或者闪片。 | W32: Abby Liang | X32: 63.7 | Y32: =X32*L32 -> 764.4 | AA32: 77711SK-S002-INT | AB32: 已入 | AD32: 已完成 | AF32: 720 | AG32: =AF32-I32 -> 0 | AL32: =I32 -> 720 | AQ32: =I32 -> 720 | AS32: =I32 -> 720 | AY32: =I32/24 -> 30 | CC32: =I32/60 -> 12 | CK32: =BM32+BL32+BK32+BJ32+BS32 -> 0 | CL32: =CA32+CB32+CC32+CD32+CE32+CG32+CF32 -> 12 | CM32: =BY32+BZ32 -> 0
