Workbook

Sheet 鴨子、鱷魚、金魚排期
A1: ZURU 游水动物生产排期表
A2: 44982 | AH2: 訂單數量 | AK2: 說明書 | AN2: MA A版本彩盒2000set | AQ2: MA B版本彩盒 | AT2: MA C/D版本彩盒 | AW2: MA E版本彩盒 | AZ2: 客版包装 | BA2: 客版包装
A3: 香港接单日期 | B3: 第三方客户名称 | C3: 走货国家 | D3: ZURU PO NO# | E3: 第三方客户 PO NO# | F3: SUK号 | G3: 系统货号 | H3: ITEM# | I3: 中文名 | J3: PO数量 (pcs) | K3: 外箱装箱数量(pcs) | L3: 外箱装箱数量(pcs) | M3: 总箱数 | N3: 计划出货期 | O3: 计划验货期 | P3: 第三方客户公证行验货 | Q3: 驗貨結果 | R3: ZURU确认走货日期 | S3: 箱唛资料(收到日期) | T3: 外箱贴纸 | U3: 客供贴纸AI(收到日期) | V3: 包装 | W3: 备注 | X3: ZURU 跟单 | Y3: 单价USD | Z3: 金额USD | AA3: 發票號 | AB3: 送货情况 | AC3: 欠数 | AD3: 贴纸 | AE3: 是否入系统 | AF3: 系统出单 | AG3: 纸箱 | AH3: #25251鴨子 | AI3: #25252鱷魚 | AJ3: #25253金魚 | AK3: MA说明书 | AL3: MA说明书D版本 | AM3: 客版說明書 | AN3: #25251鴨子 | AO3: #25252鱷魚 | AP3: #25253金魚 | AQ3: #25251鴨子 | AR3: #25252鱷魚 | AS3: #25253金魚 | AT3: #25251鴨子 | AU3: #25252鱷魚 | AV3: #25253金魚 | AW3: #25251鴨子 | AX3: #25252鱷魚 | AY3: #25253金魚 | BA3: #25251鴨子 | BB3: #25252鱷魚 | BC3: #25253金魚 | BD3: 总数 | BE3: 相差
A4: 45625 | B4: ZURU | C4: 库有 | D4: ZMPO24898 | G4: 25251-S001 | H4: 25251-S001 | I4: 鸭子 | J4: 96 | K4: 0 | L4: 12 | M4: =J4/L4 -> 8 | N4: 45642 | O4: 45638 | Q4: Pass | S4: 周转箱 | U4: 无 | V4: 大货最新版本 | W4: Remark:大货最新版本/请用大货标准箱装箱/箱唛请参照邮件附件 备注：收到样品订单后尽快安排 ，注意样板品质质量要求要高于大货品质要求 ，送货时必须要附带送货单(没有送货单和QC检验合格报告的仓库一律拒绝收货)，请知悉，谢谢！ | X4: Angus | AA4: 94395-2.27 | AB4: 96 | AC4: =AB4-J4 -> 0 | AD4: 无 | AE4: 已入 | AF4: 系统出单 | AH4: =J4 -> 96 | AL4: =J4 -> 96 | AW4: =J4 -> 96 | BD4: =SUM(AH4:AJ4) -> 96 | BE4: =BD4-J4 -> 0
A5: 45625 | B5: ZURU | C5: 库有 | D5: ZMPO24898 | G5: 25252-S001 | H5: 25252-S001 | I5: 鱷魚 | J5: 96 | K5: 0 | L5: 12 | M5: =J5/L5 -> 8 | N5: 45642 | O5: 45638 | Q5: Pass | S5: 周转箱 | U5: 无 | V5: 大货最新版本 | W5: Remark:大货最新版本/请用大货标准箱装箱/箱唛请参照邮件附件 备注：收到样品订单后尽快安排 ，注意样板品质质量要求要高于大货品质要求 ，送货时必须要附带送货单(没有送货单和QC检验合格报告的仓库一律拒绝收货)，请知悉，谢谢！ | X5: Angus | AA5: 94395-2.27 | AB5: 96 | AC5: =AB5-J5 -> 0 | AD5: 无 | AE5: 已入 | AF5: 系统出单 | AI5: =J5 -> 96 | AL5: =J5 -> 96 | AX5: =J5 -> 96 | BD5: =SUM(AH5:AJ5) -> 96 | BE5: =BD5-J5 -> 0
A6: 45625 | B6: ZURU | C6: 库有 | D6: ZMPO24898 | G6: 25253-S001 | H6: 25253-S001 | I6: 金魚 | J6: 96 | K6: 0 | L6: 12 | M6: =J6/L6 -> 8 | N6: 45642 | O6: 45638 | Q6: Pass | S6: 周转箱 | U6: 无 | V6: 大货最新版本 | W6: Remark:大货最新版本/请用大货标准箱装箱/箱唛请参照邮件附件 备注：收到样品订单后尽快安排 ，注意样板品质质量要求要高于大货品质要求 ，送货时必须要附带送货单(没有送货单和QC检验合格报告的仓库一律拒绝收货)，请知悉，谢谢！ | X6: Angus | AA6: 94395-2.27 | AB6: 96 | AC6: =AB6-J6 -> 0 | AD6: 无 | AE6: 已入 | AF6: 系统出单 | AJ6: =J6 -> 96 | AL6: =J6 -> 96 | AY6: =J6 -> 96 | BD6: =SUM(AH6:AJ6) -> 96 | BE6: =BD6-J6 -> 0
A7: 45575 | B7: CARREFOUR CORA | C7: 法国 | D7: 4500147031 | E7: 48STY25CORA0091 | F7: 4500147031-10 | G7: 25251-S001-6 | H7: 25251-S001 | I7: 鸭子 | J7: 240 | K7: 0 | L7: 12 | M7: =J7/L7 -> 20 | N7: 45643 | O7: 45639 | P7: PET吸塑 | Q7: Pass | R7: 1/3出 | S7: 空白纸箱+双坑纸箱 | T7: 45616 | U7: EAN条码贴纸翻4500144921 | V7: 25251: MA E_1L-23L彩卡+客版说明书(EN/FR/RO), -翻PO#4500144921 | W7: 日期码格式：ZURU INC(BVI) 标准格式 日期：按实际生产日期 Packaging Info: 25251: MA E_1L-23L彩卡+EAN条码贴纸+法国环保logo+客版说明书(EN/FR/RO), -翻PO#4500144921 Remark: 1.大货样品2套，请多备料。 2. 出口欧洲，所有产品微塑料需符合法规。 3. 产品、包装、外箱日期码需一致。 4. 空白纸箱: 在正唛（只1面）加多虚线15 x 10.5 cm ( 高x 宽) 距箱左边2cm， 距箱底 3cm，虚线内1张外箱贴纸（在checkpoint网站上订）Custeomer Service: Erica Lun Tel.+852 2995 8399/erica.lun@checkpt.com 5. 所有包装材料禁止使用PVC，需改用PET材料。 6. 要求使用双坑纸箱，外箱尺寸超出7%有350USD的罚款，请注意外箱尺寸变更不能超出7%。 7. 客人系统外箱尺寸: 25251: 42*39.5*45.5CM | X7: Ula Zhao | Y7: 3.9118 | Z7: =Y7*J7 -> 938.832 | AA7: 88833-1.2 | AB7: 240 | AC7: =AB7-J7 -> 0 | AD7: ok | AE7: 已入 | AF7: 系统出单 | AH7: =J7 -> 240 | AM7: =J7 -> 240 | AW7: =J7 -> 240 | BD7: =SUM(AH7:AJ7) -> 240 | BE7: =BD7-J7 -> 0
A8: 45575 | B8: CARREFOUR CORA | C8: 法国 | D8: 4500147031 | E8: 48STY25CORA0091 | F8: 4500147031-20 | G8: 25252-S001-3 | H8: 25252-S001 | I8: 鱷魚 | J8: 240 | K8: 0 | L8: 12 | M8: =J8/L8 -> 20 | N8: 45643 | O8: 45639 | P8: PET吸塑 | Q8: Pass | R8: 1/3出 | S8: 空白纸箱+双坑纸箱 | T8: 45616 | U8: EAN条码贴纸翻4500144921 | V8: 25252: MA E_1L-23L彩卡+客版说明书(EN/FR/RO), -翻PO#4500144921 | W8: 日期码格式：ZURU INC(BVI) 标准格式 日期：按实际生产日期 Packaging Info: 25252: MA E_1L-23L彩卡+EAN条码贴纸+法国环保logo+客版说明书(EN/FR/RO), -翻PO#4500144921 Remark: 1.大货样品2套，请多备料。 2. 出口欧洲，所有产品微塑料需符合法规。 3. 产品、包装、外箱日期码需一致。 4. 空白纸箱: 在正唛（只1面）加多虚线15 x 10.5 cm ( 高x 宽) 距箱左边2cm， 距箱底 3cm，虚线内1张外箱贴纸（在checkpoint网站上订）Custeomer Service: Erica Lun Tel.+852 2995 8399/erica.lun@checkpt.com 5. 所有包装材料禁止使用PVC，需改用PET材料。 6. 要求使用双坑纸箱，外箱尺寸超出7%有350USD的罚款，请注意外箱尺寸变更不能超出7%。 7. 客人系统外箱尺寸: 25252: 42*39.5*45.5CM | X8: Ula Zhao | Y8: 4.0344 | Z8: =Y8*J8 -> 968.256 | AA8: 88833-1.2 | AB8: 240 | AC8: =AB8-J8 -> 0 | AD8: ok | AE8: 已入 | AF8: 系统出单 | AI8: =J8 -> 240 | AM8: =J8 -> 240 | AX8: =J8 -> 240 | BD8: =SUM(AH8:AJ8) -> 240 | BE8: =BD8-J8 -> 0
A9: 45575 | B9: CARREFOUR CORA | C9: 法国 | D9: 4500147031 | E9: 48STY25CORA0091 | F9: 4500147031-30 | G9: 25253-S001-3 | H9: 25253-S001 | I9: 金魚 | J9: 240 | K9: 0 | L9: 12 | M9: =J9/L9 -> 20 | N9: 45643 | O9: 45639 | P9: PET吸塑 | Q9: Pass | R9: 1/3出 | S9: 空白纸箱+双坑纸箱 | T9: 45616 | U9: EAN条码贴纸翻4500144921 | V9: 25253: MA E_1L-23L彩卡+客版说明书(EN/FR/RO), -翻PO#4500144921 | W9: 日期码格式：ZURU INC(BVI) 标准格式 日期：按实际生产日期 Packaging Info: 25253: MA E_1L-23L彩卡+EAN条码贴纸+法国环保logo+客版说明书(EN/FR/RO), 翻PO#4500144921 Remark: 1.大货样品2套，请多备料。 2. 出口欧洲，所有产品微塑料需符合法规。 3. 产品、包装、外箱日期码需一致。 4. 空白纸箱: 在正唛（只1面）加多虚线15 x 10.5 cm ( 高x 宽) 距箱左边2cm， 距箱底 3cm，虚线内1张外箱贴纸（在checkpoint网站上订）Custeomer Service: Erica Lun Tel.+852 2995 8399/erica.lun@checkpt.com 5. 所有包装材料禁止使用PVC，需改用PET材料。 6. 要求使用双坑纸箱，外箱尺寸超出7%有350USD的罚款，请注意外箱尺寸变更不能超出7%。 7. 客人系统外箱尺寸: 25253: 42*39.5*45.5CM | X9: Ula Zhao | Y9: 3.7168 | Z9: =Y9*J9 -> 892.032 | AA9: 88833-1.2 | AB9: 240 | AC9: =AB9-J9 -> 0 | AD9: ok | AE9: 已入 | AF9: 系统出单 | AJ9: =J9 -> 240 | AM9: =J9 -> 240 | AY9: =J9 -> 240 | BD9: =SUM(AH9:AJ9) -> 240 | BE9: =BD9-J9 -> 0
A10: 45590 | B10: WAL-MART STORES INC. USA | C10: 美国 | D10: 4500148810 | E10: 0870169770 | F10: 4500148810-10 | G10: 25251-S002 | H10: 25251-S002 | I10: 鸭子 | J10: 3740 | K10: 0 | L10: 2 | M10: =J10/L10 -> 1870 | N10: 45646 | O10: 45642 | P10: 12/20 BV（自检） | Q10: Pass | R10: 1/6出 | S10: 外箱四面印刷RFID箱唛 + 顶部ZURU logo黑色色带。主唛右下角加印 MADE IN CHINA | U10: 11/29-RFID贴纸 | V10: 最新扶正ZURU LOGO客版彩盒 | W10: 日期码格式：DGYYYYMMDD(日期避开周末和法定节假日) 日期：按实际生产日期 Packaging Info: 翻单：4500147361 1.包装方式： 25251：最新扶正ZURU LOGO客版彩盒（客版UPC）1L+23L警告语 + MA D版1L说明书 Remark: 2. 外箱四面印刷青色RFID箱唛 + 顶部ZURU logo黑色色带。 主唛左前下角印刷艾利贴纸替代标箱唛(ITF-14格式)，条码只印刷一面。 主唛右下角加印 MADE IN CHINA 3. WM#25251 NEW UPC：193052056092 4. Include 3pcs AAA carbon batteries; 5.此单需要验货，请自行多备包装物料。 6.在产品上和包装上要有日期码、MADE IN CHINA和ZURU字样。 7.此批单都为散箱出货 8.每PCS要加RFID 贴纸，严格按照我们提供的位置图，不可擅自调整位置，贴纸也不可有任何破损或折坏，不可淋湿!!（如缺数请及时告知） | X10: Nikki Mo | Y10: 3.514 | Z10: =Y10*J10 -> 13142.36 | AA10: 88868-1.4 | AB10: 3740 | AC10: =AB10-J10 -> 0 | AD10: ok | AE10: 已入 | AF10: 系统出单 | AH10: =J10 -> 3740 | AL10: =J10 -> 3740 | BA10: =J10 -> 3740 | BD10: =SUM(AH10:AJ10) -> 3740 | BE10: =BD10-J10 -> 0
A11: 45590 | B11: WAL-MART STORES INC. USA | C11: 美国 | D11: 4500148811 | E11: 0870169797 | F11: 4500148811-10 | G11: 25251-S002 | H11: 25251-S002 | I11: 鸭子 | J11: 4108 | K11: 0 | L11: 2 | M11: =J11/L11 -> 2054 | N11: 45646 | O11: 45642 | P11: 12/20 BV（自检） | Q11: Pass | R11: 1/21出 | S11: 外箱四面印刷RFID箱唛 + 顶部ZURU logo黑色色带。主唛右下角加印 MADE IN CHINA | U11: 11/29-RFID贴纸 | V11: 最新扶正ZURU LOGO客版彩盒 | W11: 日期码格式：DGYYYYMMDD(日期避开周末和法定节假日) 日期：按实际生产日期 Packaging Info: 翻单：4500147361 1.包装方式： 25251：最新扶正ZURU LOGO客版彩盒（客版UPC）1L+23L警告语 + MA D版1L说明书 Remark: 2. 外箱四面印刷青色RFID箱唛 + 顶部ZURU logo黑色色带。 主唛左前下角印刷艾利贴纸替代标箱唛(ITF-14格式)，条码只印刷一面。 主唛右下角加印 MADE IN CHINA 3. WM#25251 NEW UPC：193052056092 4. Include 3pcs AAA carbon batteries; 5.此单需要验货，请自行多备包装物料。 6.在产品上和包装上要有日期码、MADE IN CHINA和ZURU字样。 7.此批单都为散箱出货 8.每PCS要加RFID 贴纸，严格按照我们提供的位置图，不可擅自调整位置，贴纸也不可有任何破损或折坏，不可淋湿!!（如缺数请及时告知） | X11: Nikki Mo | Y11: 3.514 | Z11: =Y11*J11 -> 14435.512 | AA11: 94185-2.8 | AB11: 4108 | AC11: =AB11-J11 -> 0 | AD11: ok | AE11: 已入 | AF11: 系统出单 | AH11: =J11 -> 4108 | AL11: =J11 -> 4108 | BA11: =J11 -> 4108 | BD11: =SUM(AH11:AJ11) -> 4108 | BE11: =BD11-J11 -> 0
A12: 45590 | B12: WAL-MART STORES INC. USA | C12: 美国 | D12: 4500148812 | E12: 0870169800 | F12: 4500148812-10 | G12: 25251-S002 | H12: 25251-S002 | I12: 鸭子 | J12: 2922 | K12: 0 | L12: 2 | M12: =J12/L12 -> 1461 | N12: 45646 | O12: 45642 | P12: 12/20 BV（自检） | Q12: Pass | R12: 1/14出 | S12: 外箱四面印刷RFID箱唛 + 顶部ZURU logo黑色色带。主唛右下角加印 MADE IN CHINA | U12: 11/29-RFID贴纸 | V12: 最新扶正ZURU LOGO客版彩盒 | W12: 日期码格式：DGYYYYMMDD(日期避开周末和法定节假日) 日期：按实际生产日期 Packaging Info: 翻单：4500147361 1.包装方式： 25251：最新扶正ZURU LOGO客版彩盒（客版UPC）1L+23L警告语 + MA D版1L说明书 Remark: 2. 外箱四面印刷青色RFID箱唛 + 顶部ZURU logo黑色色带。 主唛左前下角印刷艾利贴纸替代标箱唛(ITF-14格式)，条码只印刷一面。 主唛右下角加印 MADE IN CHINA 3. WM#25251 NEW UPC：193052056092 4. Include 3pcs AAA carbon batteries; 5.此单需要验货，请自行多备包装物料。 6.在产品上和包装上要有日期码、MADE IN CHINA和ZURU字样。 7.此批单都为散箱出货 8.每PCS要加RFID 贴纸，严格按照我们提供的位置图，不可擅自调整位置，贴纸也不可有任何破损或折坏，不可淋湿!!（如缺数请及时告知） | X12: Nikki Mo | Y12: 3.5075 | Z12: =Y12*J12 -> 10248.915 | AA12: 94041-1.15 | AB12: =1422+1500 -> 2922 | AC12: =AB12-J12 -> 0 | AD12: ok | AE12: 已入 | AF12: 系统出单 | AH12: =J12 -> 2922 | AL12: =J12 -> 2922 | BA12: =J12 -> 2922 | BD12: =SUM(AH12:AJ12) -> 2922 | BE12: =BD12-J12 -> 0
A13: 45602 | B13: DM LLC | C13: 俄罗斯联邦 | D13: 4500150264 | E13: 出Bekasovo 2 | F13: 4500150264-10 | G13: 25252-S001 | H13: 25252-S001 | I13: 鱷魚 | J13: 756 | K13: 0 | L13: 12 | M13: =J13/L13 -> 63 | N13: 45652 | O13: 45649 | Q13: Pass | R13: 12/28出 | S13: 11/14收到 | U13: 11/22收到进口商贴纸+ EAN条码贴纸 | V13: 日期码格式：外包装/外箱不要打ZURU标准日期码 | W13: 日期码格式：外包装/外箱不要打ZURU标准日期码 日期： Packaging Info: 注意 ：外包装 (指: 收缩膜/彩卡/铝箔袋/挂卡/PDQ) /外箱不要打ZURU标准日期码！胶件可以打日期码 . 25252 ： MA 彩卡+ 进口商贴纸+ EAN条码贴纸， MA 说明书 ： Remark: 标准配比 ； 请按期完货， 会有罚金。 出港口Bekasovo 2. | X13: Ann Zhang | Y13: 4.0344 | Z13: =Y13*J13 -> 3050.0064 | AA13: 94035-1.15 | AB13: 756 | AC13: =AB13-J13 -> 0 | AD13: ok | AE13: 已入 | AF13: 系统出单 | AI13: =J13 -> 756 | AL13: =J13 -> 756 | AX13: =J13 -> 756 | BD13: =SUM(AH13:AJ13) -> 756 | BE13: =BD13-J13 -> 0
A14: 45596 | B14: Smyths Toys HQ UC UK | C14: 英国 | D14: 4500149773 | E14: 4400444865 | F14: 4500149773-10 | G14: 25251-S001-5 | H14: 25251-S001 | I14: 鸭子 | J14: 3000 | K14: 0 | L14: 12 | M14: =J14/L14 -> 250 | N14: 45653 | O14: 45649 | Q14: Pass | R14: 1/15出 | S14: 11/25收到 | U14: 德语<(>&<)>法语callout贴纸和位置图翻4500138425 | V14: 客版说明书都翻PO#4500138425 | W14: 日期码格式：ZURU INC(BVI) 标准格式 日期：按实际生产日期 Packaging Info: 1.25251: MA 1L-23L Warning+德语<(>&<)>法语callout贴纸+客版说明书（英法德意荷语言) 贴纸和位置图/客版说明书都翻PO#4500138425 Remark: 1）包装日期码按ZURU格式即可，请确保不迟于外箱日期码，可等于或者早于外箱日期码，必须为法定工作日，印刷前请先检查外箱日期码。 2）订单出英国，请注意检查产品及包装应带UKCA图标（14+产品除外），包装显示ZURU UK LTD/ZURU France地址信息，QC部门请查核，如有问题与跟单确认 3）订单必须经过ZURU QC验货并且通过后方可出货 4) 需要符合欧洲标准不能含有闪粉和微塑料，否则不和法规会有客诉产生 | X14: Amy Ding | Y14: 3.4606 | Z14: =Y14*J14 -> 10381.8 | AA14: 88975-1.10 | AB14: =2208+792 -> 3000 | AC14: =AB14-J14 -> 0 | AD14: ok | AE14: 已入 | AF14: 系统出单 | AH14: =J14 -> 3000 | AM14: =J14 -> 3000 | AW14: =J14 -> 3000 | BD14: =SUM(AH14:AJ14) -> 3000 | BE14: =BD14-J14 -> 0
A15: 45623 | B15: TJX COMPANIES, INC | C15: 美国 | D15: 4500152570 | E15: Marshalls DC#881-168PCS , DC#884-132PCS , DC#886-180PCS , DC#887-156PCS , DC#888-168PCS | F15: 4500152570-20 | G15: 25251-S001 | H15: 25251-S001 | I15: 鸭子 | J15: 804 | K15: 0 | L15: 12 | M15: =J15/L15 -> 67 | N15: 45651 | O15: 45647 | Q15: Pass | S15: 45623 | U15: 12/6-客供价格贴纸 | V15: MA UPC包装 | W15: 日期码格式：ZURU INC(BVI) 标准格式 日期：按实际生产日期 Packaging Info: MA UPC包装+价格贴纸，价格贴纸客供。 Remark: 1. 产品和包装上印刷tracking code信息，格式为ZURU常规格式。 2. 分5个DC出货，每款产品每个DC的箱唛资料不同。具体分DC数量，请参考后面行项目备注。 3. ZURU QC验货。 Order | X15: Emily Wu | Y15: 3.9118 | Z15: =Y15*J15 -> 3145.0872 | AA15: 94168-1.23 | AB15: 804 | AC15: =AB15-J15 -> 0 | AD15: ok | AE15: 已入 | AF15: 系统出单 | AH15: =J15 -> 804 | AL15: =J15 -> 804 | AW15: =J15 -> 804 | BD15: =SUM(AH15:AJ15) -> 804 | BE15: =BD15-J15 -> 0
A16: 45590 | B16: WAL-MART STORES INC. USA | C16: 美国 | D16: 4500148814 | E16: 0870169764 | F16: 4500148814-10 | G16: 25251-S002 | H16: 25251-S002 | I16: 鸭子 | J16: 2888 | K16: 0 | L16: 2 | M16: =J16/L16 -> 1444 | N16: 45653 | O16: 45649 | P16: 12/27 BV（自检） | Q16: Pass | R16: 1/14出 | S16: 外箱四面印刷RFID箱唛 + 顶部ZURU logo黑色色带。主唛右下角加印 MADE IN CHINA | U16: 12/10-RFID贴纸 | V16: 最新扶正ZURU LOGO客版彩盒 | W16: 日期码格式：DGYYYYMMDD(日期避开周末和法定节假日) 日期：按实际生产日期 Packaging Info: 翻单：4500147361 1.包装方式： 25251：最新扶正ZURU LOGO客版彩盒（客版UPC）1L+23L警告语 + MA D版1L说明书 Remark: 2. 外箱四面印刷青色RFID箱唛 + 顶部ZURU logo黑色色带。 主唛左前下角印刷艾利贴纸替代标箱唛(ITF-14格式)，条码只印刷一面。 主唛右下角加印 MADE IN CHINA 3. WM#25251 NEW UPC：193052056092 4. Include 3pcs AAA carbon batteries; 5.此单需要验货，请自行多备包装物料。 6.在产品上和包装上要有日期码、MADE IN CHINA和ZURU字样。 7.此批单都为散箱出货 8.每PCS要加RFID 贴纸，严格按照我们提供的位置图，不可擅自调整位置，贴纸也不可有任何破损或折坏，不可淋湿!!（如缺数请及时告知） | X16: Nikki Mo | Y16: 3.6259 | Z16: =Y16*J16 -> 10471.599 | AA16: 94028-1.14 | AB16: 2888 | AC16: =AB16-J16 -> 0 | AD16: ok | AE16: 已入 | AF16: 系统出单 | AH16: =J16 -> 2888 | AL16: =J16 -> 2888 | BA16: =J16 -> 2888 | BD16: =SUM(AH16:AJ16) -> 2888 | BE16: =BD16-J16 -> 0
A17: 45623 | B17: TJX COMPANIES, INC | C17: 美国 | D17: 4500152572 | E17: Marshalls DC#881-216PCS , DC#884-156PCS , DC#886-228PCS , DC#887-192PCS , DC#888-204PCS | F17: 4500152572-10 | G17: 25251-S001 | H17: 25251-S001 | I17: 鸭子 | J17: 996 | K17: 0 | L17: 12 | M17: =J17/L17 -> 83 | N17: 45657 | O17: 45653 | Q17: Pass | R17: 1/8出 | S17: 45623 | U17: 12/6-客供价格贴纸 | V17: MA UPC包装 | W17: 日期码格式：ZURU INC(BVI) 标准格式 日期：按实际生产日期 Packaging Info: MA UPC包装+价格贴纸，价格贴纸客供。 Remark: 1. 产品和包装上印刷tracking code信息，格式为ZURU常规格式。 2. 分5个DC出货，每款产品每个DC的箱唛资料不同。具体分DC数量，请参考后面行项目备注。 3. ZURU QC验货。 | X17: Emily Wu | Y17: 3.8242 | Z17: =Y17*J17 -> 3808.9032 | AA17: 94165-1.23 | AB17: 996 | AC17: =AB17-J17 -> 0 | AD17: ok | AE17: 已入 | AF17: 系统出单 | AH17: =J17 -> 996 | AL17: =J17 -> 996 | AW17: =J17 -> 996 | BD17: =SUM(AH17:AJ17) -> 996 | BE17: =BD17-J17 -> 0
A18: 45623 | B18: TJX COMPANIES, INC | C18: 美国 | D18: 4500152573 | E18: TJ MAXX DC#891-240PCS , DC#894-204PCS , DC#896-192PCS , DC#897-372PCS , DC#898-192PCS | F18: 4500152573-10 | G18: 25251-S001 | H18: 25251-S001 | I18: 鸭子 | J18: 1200 | K18: 0 | L18: 12 | M18: =J18/L18 -> 100 | N18: 45657 | O18: 45653 | Q18: Pass | R18: 1/8出 | S18: 45623 | U18: 12/6-客供价格贴纸 | V18: MA UPC包装 | W18: 日期码格式：ZURU INC(BVI) 标准格式 日期：按实际生产日期 Packaging Info: MA UPC包装+价格贴纸，价格贴纸客供。 Remark: 1. 产品和包装上印刷tracking code信息，格式为ZURU常规格式。 2. 分5个DC出货，每款产品每个DC的箱唛资料不同。具体分DC数量，请参考后面行项目备注。 3. ZURU QC验货。 | X18: Emily Wu | Y18: 3.4616 | Z18: =Y18*J18 -> 4153.92 | AA18: 94173-1.23 | AB18: 1200 | AC18: =AB18-J18 -> 0 | AD18: ok | AE18: 已入 | AF18: 系统出单 | AH18: =J18 -> 1200 | AL18: =J18 -> 1200 | AW18: =J18 -> 1200 | BD18: =SUM(AH18:AJ18) -> 1200 | BE18: =BD18-J18 -> 0
A19: 45623 | B19: TJX COMPANIES, INC | C19: 美国 | D19: 4500152575 | E19: TJ MAXX DC#891-240PCS , DC#894-204PCS , DC#896-192PCS , DC#897-372PCS , DC#898-192PCS | F19: 4500152575-20 | G19: 25251-S001 | H19: 25251-S001 | I19: 鸭子 | J19: 1200 | K19: 0 | L19: 12 | M19: =J19/L19 -> 100 | N19: 45657 | O19: 45653 | Q19: Pass | R19: 1/8出 | S19: 45623 | U19: 12/6-客供价格贴纸 | V19: MA UPC包装 | W19: 日期码格式：ZURU INC(BVI) 标准格式 日期：按实际生产日期 Packaging Info: MA UPC包装+价格贴纸，价格贴纸客供。 Remark: 1. 产品和包装上印刷tracking code信息，格式为ZURU常规格式。 2. 分5个DC出货，每款产品每个DC的箱唛资料不同。具体分DC数量，请参考后面行项目备注。 3. ZURU QC验货。 | X19: Emily Wu | Y19: 3.5492 | Z19: =Y19*J19 -> 4259.04 | AA19: 94172-1.23 | AB19: 1200 | AC19: =AB19-J19 -> 0 | AD19: ok | AE19: 已入 | AF19: 系统出单 | AH19: =J19 -> 1200 | AL19: =J19 -> 1200 | AW19: =J19 -> 1200 | BD19: =SUM(AH19:AJ19) -> 1200 | BE19: =BD19-J19 -> 0
A20: 45623 | B20: TJX COMPANIES, INC | C20: 美国 | D20: 4500152574 | E20: Marshalls DC#881-216PCS , DC#884-156PCS , DC#886-228PCS , DC#887-192PCS , DC#888-204PCS | F20: 4500152574-20 | G20: 25251-S001 | H20: 25251-S001 | I20: 鸭子 | J20: 996 | K20: 0 | L20: 12 | M20: =J20/L20 -> 83 | N20: 45657 | O20: 45653 | Q20: Pass | R20: 1/8出 | S20: 45623 | U20: 12/6-客供价格贴纸 | V20: MA UPC包装 | W20: 日期码格式：ZURU INC(BVI) 标准格式 日期：按实际生产日期 Packaging Info: MA UPC包装+价格贴纸，价格贴纸客供。 Remark: 1. 产品和包装上印刷tracking code信息，格式为ZURU常规格式。 2. 分5个DC出货，每款产品每个DC的箱唛资料不同。具体分DC数量，请参考后面行项目备注。 3. ZURU QC验货。 | X20: Emily Wu | Y20: 3.8242 | Z20: =Y20*J20 -> 3808.9032 | AA20: 94167-1.23 | AB20: 996 | AC20: =AB20-J20 -> 0 | AD20: ok | AE20: 已入 | AF20: 系统出单 | AH20: =J20 -> 996 | AL20: =J20 -> 996 | AW20: =J20 -> 996 | BD20: =SUM(AH20:AJ20) -> 996 | BE20: =BD20-J20 -> 0
A21: 45590 | B21: WAL-MART STORES INC. USA | C21: 美国 | D21: 4500149172 | E21: 0870169815 | F21: 4500149172-10 | G21: 25251-S002 | H21: 25251-S002 | I21: 鸭子 | J21: 4712 | K21: 0 | L21: 2 | M21: =J21/L21 -> 2356 | N21: 45659 | O21: 45656 | P21: 1/3 BV（自检） | Q21: Pass | R21: 1/13出 | S21: 外箱四面印刷RFID箱唛 + 顶部ZURU logo黑色色带。主唛右下角加印 MADE IN CHINA | U21: 12/10-RFID贴纸 | V21: 最新扶正ZURU LOGO客版彩盒 | W21: 日期码格式：DGYYYYMMDD(日期避开周末和法定节假日) 日期：按实际生产日期 Packaging Info: 翻单：4500147361 1.包装方式： 25251：最新扶正ZURU LOGO客版彩盒（客版UPC）1L+23L警告语 + MA D版1L说明书 Remark: 2. 外箱四面印刷青色RFID箱唛 + 顶部ZURU logo黑色色带。 主唛左前下角印刷艾利贴纸替代标箱唛(ITF-14格式)，条码只印刷一面。 主唛右下角加印 MADE IN CHINA 3. WM#25251 NEW UPC：193052056092 4. Include 3pcs AAA carbon batteries; 5.此单需要验货，请自行多备包装物料。 6.在产品上和包装上要有日期码、MADE IN CHINA和ZURU字样。 7.此批单都为散箱出货 8.每PCS要加RFID 贴纸，严格按照我们提供的位置图，不可擅自调整位置，贴纸也不可有任何破损或折坏，不可淋湿!!（如缺数请及时告知） | X21: Nikki Mo | Y21: 3.514 | Z21: =Y21*J21 -> 16557.968 | AA21: 94186-2.8 | AB21: 4712 | AC21: =AB21-J21 -> 0 | AD21: ok | AE21: 已入 | AF21: 系统出单 | AH21: =J21 -> 4712 | AL21: =J21 -> 4712 | BA21: =J21 -> 4712 | BD21: =SUM(AH21:AJ21) -> 4712 | BE21: =BD21-J21 -> 0
A22: 45624 | B22: WAL-MART STORES INC. USA | C22: 美国 | D22: 4500152364 | E22: 0869333766 | F22: 4500152364-10 | G22: 25251-S002 | H22: 25251-S002 | I22: 鸭子 | J22: 980 | K22: 0 | L22: 2 | M22: =J22/L22 -> 490 | N22: 45659 | O22: 45656 | P22: 1/3 BV（自检） | Q22: Pass | R22: 1/16出 | S22: 外箱四面印刷RFID箱唛 + 顶部ZURU logo黑色色带。主唛右下角加印 MADE IN CHINA | U22: 12/10-RFID贴纸 | V22: 最新扶正ZURU LOGO客版彩盒 | W22: 日期码格式：DGYYYYMMDD(日期避开周末和法定节假日) 日期：按实际生产日期 Packaging Info: 翻单：4500147361 1.包装方式： 25251：最新扶正ZURU LOGO客版彩盒（客版UPC）1L+23L警告语 + MA D版1L说明书 Remark: 2. 外箱四面印刷青色RFID箱唛 + 顶部ZURU logo黑色色带 主唛左前下角印刷艾利贴纸替代标箱唛(ITF-14格式)，条码只印刷一面 主唛右下角加印 MADE IN CHINA，对角线位置加贴一张粉色MOD艾利贴纸（工厂自行打印或订购） 3. WM#25251 NEW UPC：193052056092 4. Include 3pcs AAA carbon batteries; 5.此单需要验货，请自行多备包装物料。 6.在产品上和包装上要有日期码、MADE IN CHINA和ZURU字样。 7.此批单都为散箱出货 8.每PCS要加RFID 贴纸，严格按照我们提供的位置图，不可擅自调整位置，贴纸也不可有任何破损或折坏，不可淋湿!!（如缺数请及时告知） | X22: Nikki Mo | Y22: 4.0771 | Z22: =Y22*J22 -> 3995.558 | AA22: 94073-1.17 | AB22: 980 | AC22: =AB22-J22 -> 0 | AD22: ok | AE22: 已入 | AF22: 系统出单 | AH22: =J22 -> 980 | AL22: =J22 -> 980 | BA22: =J22 -> 980 | BD22: =SUM(AH22:AJ22) -> 980 | BE22: =BD22-J22 -> 0
A23: 45624 | B23: WAL-MART STORES INC. USA | C23: 美国 | D23: 4500152363 | E23: 0869333777 | F23: 4500152363-10 | G23: 25251-S002 | H23: 25251-S002 | I23: 鸭子 | J23: 1182 | K23: 0 | L23: 2 | M23: =J23/L23 -> 591 | N23: 45659 | O23: 45656 | P23: 1/3 BV（自检） | Q23: Pass | R23: 1/18出 | S23: 外箱四面印刷RFID箱唛 + 顶部ZURU logo黑色色带。主唛右下角加印 MADE IN CHINA | U23: 12/10-RFID贴纸 | V23: 最新扶正ZURU LOGO客版彩盒 | W23: 日期码格式：DGYYYYMMDD(日期避开周末和法定节假日) 日期：按实际生产日期 Packaging Info: 翻单：4500147361 1.包装方式： 25251：最新扶正ZURU LOGO客版彩盒（客版UPC）1L+23L警告语 + MA D版1L说明书 Remark: 2. 外箱四面印刷青色RFID箱唛 + 顶部ZURU logo黑色色带 主唛左前下角印刷艾利贴纸替代标箱唛(ITF-14格式)，条码只印刷一面 主唛右下角加印 MADE IN CHINA，对角线位置加贴一张粉色MOD艾利贴纸（工厂自行打印或订购） 3. WM#25251 NEW UPC：193052056092 4. Include 3pcs AAA carbon batteries; 5.此单需要验货，请自行多备包装物料。 6.在产品上和包装上要有日期码、MADE IN CHINA和ZURU字样。 7.此批单都为散箱出货 8.每PCS要加RFID 贴纸，严格按照我们提供的位置图，不可擅自调整位置，贴纸也不可有任何破损或折坏，不可淋湿!!（如缺数请及时告知） | X23: Nikki Mo | Y23: 3.7145 | Z23: =Y23*J23 -> 4390.539 | AA23: 94074-1.17 | AB23: 1182 | AC23: =AB23-J23 -> 0 | AD23: ok | AE23: 已入 | AF23: 系统出单 | AH23: =J23 -> 1182 | AL23: =J23 -> 1182 | BA23: =J23 -> 1182 | BD23: =SUM(AH23:AJ23) -> 1182 | BE23: =BD23-J23 -> 0
A24: 45624 | B24: WAL-MART STORES INC. USA | C24: 美国 | D24: 4500152365 | E24: 0869333761 | F24: 4500152365-10 | G24: 25251-S002 | H24: 25251-S002 | I24: 鸭子 | J24: 1352 | K24: 0 | L24: 2 | M24: =J24/L24 -> 676 | N24: 45659 | O24: 45656 | P24: 1/3 BV（自检） | Q24: Pass | R24: 1/20出 | S24: 外箱四面印刷RFID箱唛 + 顶部ZURU logo黑色色带。主唛右下角加印 MADE IN CHINA | U24: 12/10-RFID贴纸 | V24: 最新扶正ZURU LOGO客版彩盒 | W24: 日期码格式：DGYYYYMMDD(日期避开周末和法定节假日) 日期：按实际生产日期 Packaging Info: 翻单：4500147361 1.包装方式： 25251：最新扶正ZURU LOGO客版彩盒（客版UPC）1L+23L警告语 + MA D版1L说明书 Remark: 2. 外箱四面印刷青色RFID箱唛 + 顶部ZURU logo黑色色带 主唛左前下角印刷艾利贴纸替代标箱唛(ITF-14格式)，条码只印刷一面 主唛右下角加印 MADE IN CHINA，对角线位置加贴一张粉色MOD艾利贴纸（工厂自行打印或订购） 3. WM#25251 NEW UPC：193052056092 4. Include 3pcs AAA carbon batteries; 5.此单需要验货，请自行多备包装物料。 6.在产品上和包装上要有日期码、MADE IN CHINA和ZURU字样。 7.此批单都为散箱出货 8.每PCS要加RFID 贴纸，严格按照我们提供的位置图，不可擅自调整位置，贴纸也不可有任何破损或折坏，不可淋湿!!（如缺数请及时告知） | X24: Nikki Mo | Y24: 3.7145 | Z24: =Y24*J24 -> 5022.004 | AA24: 94056-1.16 | AB24: 1352 | AC24: =AB24-J24 -> 0 | AD24: ok | AE24: 已入 | AF24: 系统出单 | AH24: =J24 -> 1352 | AL24: =J24 -> 1352 | BA24: =J24 -> 1352 | BD24: =SUM(AH24:AJ24) -> 1352 | BE24: =BD24-J24 -> 0
A25: 45625 | B25: Smyths Toys HQ UC IE | C25: 爱尔兰 | D25: 4500153056 | E25: 4400452589 | F25: 4500153056-20 | G25: 25253-S001-7 | H25: 25253-S001 | I25: 金魚 | J25: 708 | K25: 0 | L25: 12 | M25: =J25/L25 -> 59 | N25: 45659 | O25: 45656 | Q25: Pass | R25: 1/6出 | S25: 12/3收到 | U25: 12/10-德语<(>&<)>法语callout贴纸 | V25: 25253:MA 1L-23L Warning+客版说明书翻4500138425 | W25: 日期码格式：ZURU INC(BVI) 标准格式 日期：按实际生产日期 Packaging Info: 2.25253:MA 1L-23L Warning+德语<(>&<)>法语callout贴纸+客版说明书（英法德意荷语言),客版说明书翻PO#4500138425 Remark: 1）包装日期码按ZURU格式即可，请确保不迟于外箱日期码，可等于或者早于外箱日期码，必须为法定工作日，印刷前请先检查外箱日期码。 2）订单出英国，请注意检查产品及包装应带UKCA图标（14+产品除外），包装显示ZURU UK LTD/ZURU France地址信息，QC部门请查核，如有问题与跟单确认 3) 需要符合欧洲标准不能含有闪粉和微塑料，否则不和法规会有客诉产生 | X25: Amy Ding | Y25: 3.7168 | Z25: =Y25*J25 -> 2631.4944 | AA25: 88855-1.3 | AB25: 708 | AC25: =AB25-J25 -> 0 | AD25: ok | AE25: 已入 | AF25: 系统出单 | AJ25: =J25 -> 708 | AM25: =J25 -> 708 | AY25: =J25 -> 708 | BD25: =SUM(AH25:AJ25) -> 708 | BE25: =BD25-J25 -> 0
A26: 45590 | B26: WAL-MART STORES INC. USA | C26: 美国 | D26: 4500149173 | E26: 870169769 | F26: 4500149173-10 | G26: 25251-S002 | H26: 25251-S002 | I26: 鸭子 | J26: 3530 | K26: 0 | L26: 2 | M26: =J26/L26 -> 1765 | N26: 45663 | O26: 45659 | P26: 1/7 BV（自检） | Q26: Pass | R26: 1/20出 | S26: 外箱四面印刷RFID箱唛 + 顶部ZURU logo黑色色带。主唛右下角加印 MADE IN CHINA | U26: 12/10-RFID贴纸 | V26: 最新扶正ZURU LOGO客版彩盒 | W26: 日期码格式：DGYYYYMMDD(日期避开周末和法定节假日) 日期：按实际生产日期 Packaging Info: 翻单：4500147361 1.包装方式： 25251：最新扶正ZURU LOGO客版彩盒（客版UPC）1L+23L警告语 + MA D版1L说明书 Remark: 2. 外箱四面印刷青色RFID箱唛 + 顶部ZURU logo黑色色带。 主唛左前下角印刷艾利贴纸替代标箱唛(ITF-14格式)，条码只印刷一面。 主唛右下角加印 MADE IN CHINA 3. WM#25251 NEW UPC：193052056092 4. Include 3pcs AAA carbon batteries; 5.此单需要验货，请自行多备包装物料。 6.在产品上和包装上要有日期码、MADE IN CHINA和ZURU字样。 7.此批单都为散箱出货 8.每PCS要加RFID 贴纸，严格按照我们提供的位置图，不可擅自调整位置，贴纸也不可有任何破损或折坏，不可淋湿!!（如缺数请及时告知） | X26: Nikki Mo | Y26: 3.514 | Z26: =Y26*J26 -> 12404.42 | AA26: 94058-1.16 | AB26: =3526+4 -> 3530 | AC26: =AB26-J26 -> 0 | AD26: ok | AE26: 已入 | AF26: 系统出单 | AH26: =J26 -> 3530 | AL26: =J26 -> 3530 | BA26: =J26 -> 3530 | BD26: =SUM(AH26:AJ26) -> 3530 | BE26: =BD26-J26 -> 0
A27: 45590 | B27: WAL-MART STORES INC. USA | C27: 美国 | D27: 4500149174 | E27: 0870169775 | F27: 4500149174-10 | G27: 25251-S002 | H27: 25251-S002 | I27: 鸭子 | J27: 1630 | K27: 0 | L27: 2 | M27: =J27/L27 -> 815 | N27: 45663 | O27: 45659 | P27: 1/7 BV（自检） | Q27: Pass | R27: 1/27出 | S27: 外箱四面印刷RFID箱唛 + 顶部ZURU logo黑色色带。主唛右下角加印 MADE IN CHINA | U27: 12/10-RFID贴纸 | V27: 最新扶正ZURU LOGO客版彩盒 | W27: 日期码格式：DGYYYYMMDD(日期避开周末和法定节假日) 日期：按实际生产日期 Packaging Info: 翻单：4500147361 1.包装方式： 25251：最新扶正ZURU LOGO客版彩盒（客版UPC）1L+23L警告语 + MA D版1L说明书 Remark: 2. 外箱四面印刷青色RFID箱唛 + 顶部ZURU logo黑色色带。 主唛左前下角印刷艾利贴纸替代标箱唛(ITF-14格式)，条码只印刷一面。 主唛右下角加印 MADE IN CHINA 3. WM#25251 NEW UPC：193052056092 4. Include 3pcs AAA carbon batteries; 5.此单需要验货，请自行多备包装物料。 6.在产品上和包装上要有日期码、MADE IN CHINA和ZURU字样。 7.此批单都为散箱出货 8.每PCS要加RFID 贴纸，严格按照我们提供的位置图，不可擅自调整位置，贴纸也不可有任何破损或折坏，不可淋湿!!（如缺数请及时告知） | X27: Nikki Mo | Y27: 3.7145 | Z27: =Y27*J27 -> 6054.635 | AA27: 94096-1.18 | AB27: 1630 | AC27: =AB27-J27 -> 0 | AD27: ok | AE27: 已入 | AF27: 系统出单 | AH27: =J27 -> 1630 | AL27: =J27 -> 1630 | BA27: =J27 -> 1630 | BD27: =SUM(AH27:AJ27) -> 1630 | BE27: =BD27-J27 -> 0
A28: 45590 | B28: WAL-MART STORES INC. USA | C28: 美国 | D28: 4500149176 | E28: 0870169805 | F28: 4500149176-10 | G28: 25251-S002 | H28: 25251-S002 | I28: 鸭子 | J28: 5496 | K28: 0 | L28: 2 | M28: =J28/L28 -> 2748 | N28: 45663 | O28: 45659 | P28: 1/7 BV（自检） | Q28: Pass | R28: 1/20出 | S28: 外箱四面印刷RFID箱唛 + 顶部ZURU logo黑色色带。主唛右下角加印 MADE IN CHINA | U28: 12/10-RFID贴纸 | V28: 最新扶正ZURU LOGO客版彩盒 | W28: 日期码格式：DGYYYYMMDD(日期避开周末和法定节假日) 日期：按实际生产日期 Packaging Info: 翻单：4500147361 1.包装方式： 25251：最新扶正ZURU LOGO客版彩盒（客版UPC）1L+23L警告语 + MA D版1L说明书 Remark: 2. 外箱四面印刷青色RFID箱唛 + 顶部ZURU logo黑色色带。 主唛左前下角印刷艾利贴纸替代标箱唛(ITF-14格式)，条码只印刷一面。 主唛右下角加印 MADE IN CHINA 3. WM#25251 NEW UPC：193052056092 4. Include 3pcs AAA carbon batteries; 5.此单需要验货，请自行多备包装物料。 6.在产品上和包装上要有日期码、MADE IN CHINA和ZURU字样。 7.此批单都为散箱出货 8.每PCS要加RFID 贴纸，严格按照我们提供的位置图，不可擅自调整位置，贴纸也不可有任何破损或折坏，不可淋湿!!（如缺数请及时告知） | X28: Nikki Mo | Y28: 3.4312 | Z28: =Y28*J28 -> 18857.875 | AA28: 94125-1.20 | AB28: 5496 | AC28: =AB28-J28 -> 0 | AD28: ok | AE28: 已入 | AF28: 系统出单 | AH28: =J28 -> 5496 | AL28: =J28 -> 5496 | BA28: =J28 -> 5496 | BD28: =SUM(AH28:AJ28) -> 5496 | BE28: =BD28-J28 -> 0
A29: 45590 | B29: WAL-MART STORES INC. USA | C29: 美国 | D29: 4500149177 | E29: 0870169847 | F29: 4500149177-10 | G29: 25251-S002 | H29: 25251-S002 | I29: 鸭子 | J29: 3370 | K29: 0 | L29: 2 | M29: =J29/L29 -> 1685 | N29: 45663 | O29: 45659 | P29: 1/7 BV（自检） | Q29: Pass | R29: 1/20出 | S29: 外箱四面印刷RFID箱唛 + 顶部ZURU logo黑色色带。主唛右下角加印 MADE IN CHINA | U29: 12/10-RFID贴纸 | V29: 最新扶正ZURU LOGO客版彩盒 | W29: 日期码格式：DGYYYYMMDD(日期避开周末和法定节假日) 日期：按实际生产日期 Packaging Info: 翻单：4500147361 1.包装方式： 25251：最新扶正ZURU LOGO客版彩盒（客版UPC）1L+23L警告语 + MA D版1L说明书 Remark: 2. 外箱四面印刷青色RFID箱唛 + 顶部ZURU logo黑色色带。 主唛左前下角印刷艾利贴纸替代标箱唛(ITF-14格式)，条码只印刷一面。 主唛右下角加印 MADE IN CHINA 3. WM#25251 NEW UPC：193052056092 4. Include 3pcs AAA carbon batteries; 5.此单需要验货，请自行多备包装物料。 6.在产品上和包装上要有日期码、MADE IN CHINA和ZURU字样。 7.此批单都为散箱出货 8.每PCS要加RFID 贴纸，严格按照我们提供的位置图，不可擅自调整位置，贴纸也不可有任何破损或折坏，不可淋湿!!（如缺数请及时告知） | X29: Nikki Mo | Y29: 3.514 | Z29: =Y29*J29 -> 11842.18 | AA29: 94072-1.17 | AB29: =2970+400 -> 3370 | AC29: =AB29-J29 -> 0 | AD29: ok | AE29: 已入 | AF29: 系统出单 | AH29: =J29 -> 3370 | AL29: =J29 -> 3370 | BA29: =J29 -> 3370 | BD29: =SUM(AH29:AJ29) -> 3370 | BE29: =BD29-J29 -> 0
A30: 45590 | B30: WAL-MART STORES INC. USA | C30: 美国 | D30: 4500149178 | E30: 0870169798 | F30: 4500149178-10 | G30: 25251-S002 | H30: 25251-S002 | I30: 鸭子 | J30: 4364 | K30: 0 | L30: 2 | M30: =J30/L30 -> 2182 | N30: 45663 | O30: 45659 | P30: 1/7 BV（自检） | Q30: Pass | R30: 1/20出 | S30: 外箱四面印刷RFID箱唛 + 顶部ZURU logo黑色色带。主唛右下角加印 MADE IN CHINA | U30: 12/10-RFID贴纸 | V30: 最新扶正ZURU LOGO客版彩盒 | W30: 日期码格式：DGYYYYMMDD(日期避开周末和法定节假日) 日期：按实际生产日期 Packaging Info: 翻单：4500147361 1.包装方式： 25251：最新扶正ZURU LOGO客版彩盒（客版UPC）1L+23L警告语 + MA D版1L说明书 Remark: 2. 外箱四面印刷青色RFID箱唛 + 顶部ZURU logo黑色色带。 主唛左前下角印刷艾利贴纸替代标箱唛(ITF-14格式)，条码只印刷一面。 主唛右下角加印 MADE IN CHINA 3. WM#25251 NEW UPC：193052056092 4. Include 3pcs AAA carbon batteries; 5.此单需要验货，请自行多备包装物料。 6.在产品上和包装上要有日期码、MADE IN CHINA和ZURU字样。 7.此批单都为散箱出货 8.每PCS要加RFID 贴纸，严格按照我们提供的位置图，不可擅自调整位置，贴纸也不可有任何破损或折坏，不可淋湿!!（如缺数请及时告知） | X30: Nikki Mo | Y30: 3.514 | Z30: =Y30*J30 -> 15335.096 | AA30: 94057-1.16 | AB30: 4364 | AC30: =AB30-J30 -> 0 | AD30: ok | AE30: 已入 | AF30: 系统出单 | AH30: =J30 -> 4364 | AL30: =J30 -> 4364 | BA30: =J30 -> 4364 | BD30: =SUM(AH30:AJ30) -> 4364 | BE30: =BD30-J30 -> 0
A31: 45590 | B31: WAL-MART STORES INC. USA | C31: 美国 | D31: 4500149179 | E31: 0870169788 | F31: 4500149179-10 | G31: 25251-S002 | H31: 25251-S002 | I31: 鸭子 | J31: 4792 | K31: 0 | L31: 2 | M31: =J31/L31 -> 2396 | N31: 45663 | O31: 45659 | P31: 1/7 BV（自检） | Q31: Pass | R31: 1/16出 | S31: 外箱四面印刷RFID箱唛 + 顶部ZURU logo黑色色带。主唛右下角加印 MADE IN CHINA | U31: 12/10-RFID贴纸 | V31: 最新扶正ZURU LOGO客版彩盒 | W31: 日期码格式：DGYYYYMMDD(日期避开周末和法定节假日) 日期：按实际生产日期 Packaging Info: 翻单：4500147361 1.包装方式： 25251：最新扶正ZURU LOGO客版彩盒（客版UPC）1L+23L警告语 + MA D版1L说明书 Remark: 2. 外箱四面印刷青色RFID箱唛 + 顶部ZURU logo黑色色带。 主唛左前下角印刷艾利贴纸替代标箱唛(ITF-14格式)，条码只印刷一面。 主唛右下角加印 MADE IN CHINA 3. WM#25251 NEW UPC：193052056092 4. Include 3pcs AAA carbon batteries; 5.此单需要验货，请自行多备包装物料。 6.在产品上和包装上要有日期码、MADE IN CHINA和ZURU字样。 7.此批单都为散箱出货 8.每PCS要加RFID 贴纸，严格按照我们提供的位置图，不可擅自调整位置，贴纸也不可有任何破损或折坏，不可淋湿!!（如缺数请及时告知） | X31: Nikki Mo | Y31: 3.514 | Z31: =Y31*J31 -> 16839.088 | AA31: 94140-1.21 | AB31: 4792 | AC31: =AB31-J31 -> 0 | AD31: ok | AE31: 已入 | AF31: 系统出单 | AH31: =J31 -> 4792 | AL31: =J31 -> 4792 | BA31: =J31 -> 4792 | BD31: =SUM(AH31:AJ31) -> 4792 | BE31: =BD31-J31 -> 0
A32: 45590 | B32: WAL-MART STORES INC. USA | C32: 美国 | D32: 4500149180 | E32: 0870169784 | F32: 4500149180-10 | G32: 25251-S002 | H32: 25251-S002 | I32: 鸭子 | J32: 3408 | K32: 0 | L32: 2 | M32: =J32/L32 -> 1704 | N32: 45663 | O32: 45659 | P32: 1/7 BV（自检） | Q32: Pass | R32: 1/7出 | S32: 外箱四面印刷RFID箱唛 + 顶部ZURU logo黑色色带。主唛右下角加印 MADE IN CHINA | U32: 12/10-RFID贴纸 | V32: 最新扶正ZURU LOGO客版彩盒 | W32: 日期码格式：DGYYYYMMDD(日期避开周末和法定节假日) 日期：按实际生产日期 Packaging Info: 翻单：4500147361 1.包装方式： 25251：最新扶正ZURU LOGO客版彩盒（客版UPC）1L+23L警告语 + MA D版1L说明书 Remark: 2. 外箱四面印刷青色RFID箱唛 + 顶部ZURU logo黑色色带。 主唛左前下角印刷艾利贴纸替代标箱唛(ITF-14格式)，条码只印刷一面。 主唛右下角加印 MADE IN CHINA 3. WM#25251 NEW UPC：193052056092 4. Include 3pcs AAA carbon batteries; 5.此单需要验货，请自行多备包装物料。 6.在产品上和包装上要有日期码、MADE IN CHINA和ZURU字样。 7.此批单都为散箱出货 8.每PCS要加RFID 贴纸，严格按照我们提供的位置图，不可擅自调整位置，贴纸也不可有任何破损或折坏，不可淋湿!!（如缺数请及时告知） | X32: Nikki Mo | Y32: 3.514 | Z32: =Y32*J32 -> 11975.712 | AA32: 94055-1.16 | AB32: 3408 | AC32: =AB32-J32 -> 0 | AD32: ok | AE32: 已入 | AF32: 系统出单 | AH32: =J32 -> 3408 | AL32: =J32 -> 3408 | BA32: =J32 -> 3408 | BD32: =SUM(AH32:AJ32) -> 3408 | BE32: =BD32-J32 -> 0
A33: 45623 | B33: AMAZON.COM.DEDC,LLC | C33: 美国 | D33: 4500152379 | E33: 2AIAHAQL | F33: 4500152379-110 | G33: 25253-S003-MTS | H33: 25253-S003 | I33: 金魚（邮包盒新稿） | J33: 160 | K33: 0 | L33: 4 | M33: =J33/L33 -> 40 | N33: 45664 | O33: 45660 | Q33: pass | R33: 2/7出 | U33: 12/20-外箱贴纸 | V33: 邮包盒图稿翻单4500131106-ZURU MA 1L | W33: 日期码格式： 标准格式 日期：按实际生产日期 Packaging Info: 25253：MA入邮包盒，邮包盒图稿翻单4500131106. Remark: 1. Amazon FOB订单，出口US。 2. 日期码使用ZURU标准版本。 3. 如果大货有要求入邮包盒，则对应的邮包盒上面要打上日期码。 4. 箱尺寸要求：外箱最长边不能超过25" （超过了，case pack只能为1），不符合要求的大货，一律不接受。 5. 外箱箱唛要求： ①外箱正面印ZURU Logo+SSCC Label（客供贴纸，由跟单订购)。关于 SSCC Label 请注意： SSCC Label 显示的是客人自己的item#。每一张SSCC label 都是唯一且有不同流水及条码的，没有损耗，绝对不可贴错 。如果贴错或损坏任何一张，都会导致全 部都错，千万要注意！ SSCC Label 必须贴在外箱正面的正中间位置（贴一面即可），并且贴纸离外箱边距必须至少3cm(可以覆盖Logo<(>&<)>箱唛)，否则会影响到客户那边仓库的扫描识 别。 ②外箱侧面印item#（订单上显示的SKU#)+carton size(以工厂实际尺寸为准,单位: inch) +MADE IN CHINA,日期使用ZURU 标准版本。 6. 装柜要求：按照客户PO# 装柜/箱号顺序装柜，跟单会提前给到装柜计划。 在大货生产/仓库存放时，请留意该装柜要求，以便装柜时不混乱（避免装错/装漏/找不到货号等）。 | X33: Kelly Shen | Y33: 4.0861 | Z33: =Y33*J33 -> 653.776 | AA33: 94201-2.10 | AB33: 160 | AC33: =AB33-J33 -> 0 | AD33: ok | AE33: 已入 | AF33: 系统出单 | AJ33: =J33 -> 160 | AL33: =J33 -> 160 | AY33: =J33 -> 160 | BD33: =SUM(AH33:AJ33) -> 160 | BE33: =BD33-J33 -> 0
A34: 45623 | B34: AMAZON.COM.DEDC,LLC | C34: 美国 | D34: 4500152379 | E34: 2ASXTO3R | F34: 4500152379-120 | G34: 25253-S003-MTS | H34: 25253-S003 | I34: 金魚（邮包盒新稿） | J34: 48 | K34: 0 | L34: 4 | M34: =J34/L34 -> 12 | N34: 45664 | O34: 45660 | Q34: pass | R34: 2/7出 | U34: 12/20-外箱贴纸 | V34: 邮包盒图稿翻单4500131106-ZURU MA 1L | W34: 日期码格式： 标准格式 日期：按实际生产日期 Packaging Info: 25253：MA入邮包盒，邮包盒图稿翻单4500131106. Remark: 1. Amazon FOB订单，出口US。 2. 日期码使用ZURU标准版本。 3. 如果大货有要求入邮包盒，则对应的邮包盒上面要打上日期码。 4. 箱尺寸要求：外箱最长边不能超过25" （超过了，case pack只能为1），不符合要求的大货，一律不接受。 5. 外箱箱唛要求： ①外箱正面印ZURU Logo+SSCC Label（客供贴纸，由跟单订购)。关于 SSCC Label 请注意： SSCC Label 显示的是客人自己的item#。每一张SSCC label 都是唯一且有不同流水及条码的，没有损耗，绝对不可贴错 。如果贴错或损坏任何一张，都会导致全 部都错，千万要注意！ SSCC Label 必须贴在外箱正面的正中间位置（贴一面即可），并且贴纸离外箱边距必须至少3cm(可以覆盖Logo<(>&<)>箱唛)，否则会影响到客户那边仓库的扫描识 别。 ②外箱侧面印item#（订单上显示的SKU#)+carton size(以工厂实际尺寸为准,单位: inch) +MADE IN CHINA,日期使用ZURU 标准版本。 6. 装柜要求：按照客户PO# 装柜/箱号顺序装柜，跟单会提前给到装柜计划。 在大货生产/仓库存放时，请留意该装柜要求，以便装柜时不混乱（避免装错/装漏/找不到货号等）。 | X34: Kelly Shen | Y34: 4.0861 | Z34: =Y34*J34 -> 196.1328 | AA34: 94201-2.10 | AB34: 48 | AC34: =AB34-J34 -> 0 | AD34: ok | AE34: 已入 | AF34: 系统出单 | AJ34: =J34 -> 48 | AL34: =J34 -> 48 | AY34: =J34 -> 48 | BD34: =SUM(AH34:AJ34) -> 48 | BE34: =BD34-J34 -> 0
A35: 45623 | B35: AMAZON.COM.DEDC,LLC | C35: 美国 | D35: 4500152379 | E35: 2KTUDAOR | F35: 4500152379-130 | G35: 25253-S003-MTS | H35: 25253-S003 | I35: 金魚（邮包盒新稿） | J35: 208 | K35: 0 | L35: 4 | M35: =J35/L35 -> 52 | N35: 45664 | O35: 45660 | Q35: pass | R35: 2/7出 | U35: 12/20-外箱贴纸 | V35: 邮包盒图稿翻单4500131106-ZURU MA 1L | W35: 日期码格式： 标准格式 日期：按实际生产日期 Packaging Info: 25253：MA入邮包盒，邮包盒图稿翻单4500131106. Remark: 1. Amazon FOB订单，出口US。 2. 日期码使用ZURU标准版本。 3. 如果大货有要求入邮包盒，则对应的邮包盒上面要打上日期码。 4. 箱尺寸要求：外箱最长边不能超过25" （超过了，case pack只能为1），不符合要求的大货，一律不接受。 5. 外箱箱唛要求： ①外箱正面印ZURU Logo+SSCC Label（客供贴纸，由跟单订购)。关于 SSCC Label 请注意： SSCC Label 显示的是客人自己的item#。每一张SSCC label 都是唯一且有不同流水及条码的，没有损耗，绝对不可贴错 。如果贴错或损坏任何一张，都会导致全 部都错，千万要注意！ SSCC Label 必须贴在外箱正面的正中间位置（贴一面即可），并且贴纸离外箱边距必须至少3cm(可以覆盖Logo<(>&<)>箱唛)，否则会影响到客户那边仓库的扫描识 别。 ②外箱侧面印item#（订单上显示的SKU#)+carton size(以工厂实际尺寸为准,单位: inch) +MADE IN CHINA,日期使用ZURU 标准版本。 6. 装柜要求：按照客户PO# 装柜/箱号顺序装柜，跟单会提前给到装柜计划。 在大货生产/仓库存放时，请留意该装柜要求，以便装柜时不混乱（避免装错/装漏/找不到货号等）。 | X35: Kelly Shen | Y35: 4.0861 | Z35: =Y35*J35 -> 849.9088 | AA35: 94201-2.10 | AB35: 208 | AC35: =AB35-J35 -> 0 | AD35: ok | AE35: 已入 | AF35: 系统出单 | AJ35: =J35 -> 208 | AL35: =J35 -> 208 | AY35: =J35 -> 208 | BD35: =SUM(AH35:AJ35) -> 208 | BE35: =BD35-J35 -> 0
A36: 45623 | B36: AMAZON.COM.DEDC,LLC | C36: 美国 | D36: 4500152657 | E36: 5M78WMIT | F36: 4500152657-10 | G36: 25253-S003-MTS | H36: 25253-S003 | I36: 金魚（邮包盒新稿） | J36: 512 | K36: 0 | L36: 4 | M36: =J36/L36 -> 128 | N36: 45664 | O36: 45660 | Q36: pass | R36: 2/13出 | U36: 12/20-外箱贴纸 | V36: 邮包盒图稿翻单4500131106-ZURU MA 1L | W36: 日期码格式： 标准格式 日期：按实际生产日期 Packaging Info: 25253：MA入邮包盒，邮包盒图稿翻单4500131106. Remark: 1. Amazon FOB订单，出口US。 2. 日期码使用ZURU标准版本。 3. 如果大货有要求入邮包盒，则对应的邮包盒上面要打上日期码。 4. 箱尺寸要求：外箱最长边不能超过25" （超过了，case pack只能为1），不符合要求的大货，一律不接受。 5. 外箱箱唛要求： ①外箱正面印ZURU Logo+SSCC Label（客供贴纸，由跟单订购)。关于 SSCC Label 请注意： SSCC Label 显示的是客人自己的item#。每一张SSCC label 都是唯一且有不同流水及条码的，没有损耗，绝对不可贴错 。如果贴错或损坏任何一张，都会导致全 部都错，千万要注意！ SSCC Label 必须贴在外箱正面的正中间位置（贴一面即可），并且贴纸离外箱边距必须至少3cm(可以覆盖Logo<(>&<)>箱唛)，否则会影响到客户那边仓库的扫描识 别。 ②外箱侧面印item#（订单上显示的SKU#)+carton size(以工厂实际尺寸为准,单位: inch) +MADE IN CHINA,日期使用ZURU 标准版本。 6. 装柜要求：按照客户PO# 装柜/箱号顺序装柜，跟单会提前给到装柜计划。 在大货生产/仓库存放时，请留意该装柜要求，以便装柜时不混乱（避免装错/装漏/找不到货号等）。 | X36: Kelly Shen | Y36: 3.9511 | Z36: =Y36*J36 -> 2022.9632 | AA36: 94229-2.12 | AB36: 512 | AC36: =AB36-J36 -> 0 | AD36: ok | AE36: 已入 | AF36: 系统出单 | AJ36: =J36 -> 512 | AL36: =J36 -> 512 | AY36: =J36 -> 512 | BD36: =SUM(AH36:AJ36) -> 512 | BE36: =BD36-J36 -> 0
A37: 45603 | B37: ROSS PROCUREMENT.INC | C37: 美国 | D37: 4500150300 | E37: 60188336 | F37: 4500150300-20 | G37: 25251-S001 | H37: 25251-S001 | I37: 鸭子 | J37: 4992 | K37: 0 | L37: 12 | M37: =J37/L37 -> 416 | N37: 45664 | O37: 45660 | Q37: Pass | R37: 1/17出 | S37: 2024/11/14收到 | U37: 12/2-客供价格贴纸 | V37: ZURU MA UPC 现有版本包装 | W37: 日期码格式： 标准格式 日期：按实际生产日期 Packaging Info: 1.ZURU MA UPC 现有版本包装 + 客供价格贴纸，出口美国 , 优先使用MA 1L 最新版本 。 Remark: 1.ZURU MA UPC 现有版本包装 + 客供价格贴纸，出口美国 , 优先使用MA 1L 最新版本 。 2.价格贴纸位于包装正面右下角，不挡住重要信息即可，可适当调整 ，价格贴纸由跟单提供。 3.标准日期码格式，产品和包装必须有日期码 。 4.同个产品同个货期不可出现不同的包装。 5. 跟单提供ROSS通用的箱唛模版，工厂按实际45 PO上客户PO/Item号/装箱数 提供箱唛排版来确认 6.#25251 和 #25253用英法包装，翻单4500132627 | X37: Taylor Liao | Y37: 3.3487 | Z37: =Y37*J37 -> 16716.71 | AA37: 94097-1.18 | AB37: =540+408+2472+1212+360 -> 4992 | AC37: =AB37-J37 -> 0 | AD37: ok | AE37: 已入 | AF37: 系统出单 | AH37: =J37 -> 4992 | AL37: =J37 -> 4992 | AW37: =J37 -> 4992 | BD37: =SUM(AH37:AJ37) -> 4992 | BE37: =BD37-J37 -> 0
A38: 45603 | B38: ROSS PROCUREMENT.INC | C38: 美国 | D38: 4500150300 | E38: 60188336 | F38: 4500150300-30 | G38: 25253-S001 | H38: 25253-S001 | I38: 金魚 | J38: 2496 | K38: 0 | L38: 12 | M38: =J38/L38 -> 208 | N38: 45664 | O38: 45660 | Q38: Pass | R38: 1/17出 | S38: 11/14收到 | U38: 12/2-客供价格贴纸 | V38: ZURU MA UPC 现有版本包装 | W38: 日期码格式： 标准格式 日期：按实际生产日期 Packaging Info: 1.ZURU MA UPC 现有版本包装 + 客供价格贴纸，出口美国 , 优先使用MA 1L 最新版本 。 Remark: 1.ZURU MA UPC 现有版本包装 + 客供价格贴纸，出口美国 , 优先使用MA 1L 最新版本 。 2.价格贴纸位于包装正面右下角，不挡住重要信息即可，可适当调整 ，价格贴纸由跟单提供。 3.标准日期码格式，产品和包装必须有日期码 。 4.同个产品同个货期不可出现不同的包装。 5. 跟单提供ROSS通用的箱唛模版，工厂按实际45 PO上客户PO/Item号/装箱数 提供箱唛排版来确认 6.#25251 和 #25253用英法包装，翻单4500132627 | X38: Taylor Liao | Y38: 3.0492 | Z38: =Y38*J38 -> 7610.8032 | AA38: 94097-1.18 | AB38: 2496 | AC38: =AB38-J38 -> 0 | AD38: ok | AE38: 已入 | AF38: 系统出单 | AJ38: =J38 -> 2496 | AL38: =J38 -> 2496 | AY38: =J38 -> 2496 | BD38: =SUM(AH38:AJ38) -> 2496 | BE38: =BD38-J38 -> 0
A39: 45625 | B39: Smyths Toys HQ UC UK | C39: 英国 | D39: 4500153057 | E39: 4400452592 | F39: 4500153057-10 | G39: 25253-S001-7 | H39: 25253-S001 | I39: 金魚 | J39: 3000 | K39: 0 | L39: 12 | M39: =J39/L39 -> 250 | N39: 45666 | O39: 45663 | Q39: Pass | R39: 1/13出 | S39: 12/4收到 | U39: 德语<(>&<)>法语callout贴纸翻4500153056 | V39: 25253:MA 1L-23L Warning+客版说明书翻4500138425 | W39: 日期码格式：ZURU INC(BVI) 标准格式 日期：按实际生产日期 Packaging Info: 2.25253:MA 1L-23L Warning+德语<(>&<)>法语callout贴纸(贴纸及位置图翻PO#4500153056)+客版说明书（英法德意荷语言),客版说明书翻PO#4500138425 UPC#845218016432请先检查条码是否正确再安排做货如有问题请告知 | X39: Amy Ding | Y39: 3.1368 | Z39: =Y39*J39 -> 9410.4 | AA39: 94098-1.18 | AB39: =1380+1620 -> 3000 | AC39: =AB39-J39 -> 0 | AD39: ok | AE39: 已入 | AF39: 系统出单 | AJ39: =J39 -> 3000 | AM39: =J39 -> 3000 | AY39: =J39 -> 3000 | BD39: =SUM(AH39:AJ39) -> 3000 | BE39: =BD39-J39 -> 0
A40: 45590 | B40: WAL-MART STORES INC. USA | C40: 美国 | D40: 4500149181 | E40: 0870169836 | F40: 4500149181-10 | G40: 25251-S002 | H40: 25251-S002 | I40: 鸭子 | J40: 1902 | K40: 0 | L40: 2 | M40: =J40/L40 -> 951 | N40: 45681 | O40: 45677 | P40: 1/22 BV（自检） | Q40: Pass | R40: 2/18出 | S40: 外箱四面印刷RFID箱唛 + 顶部ZURU logo黑色色带。主唛右下角加印 MADE IN CHINA | U40: 12/10-RFID贴纸 | V40: 最新扶正ZURU LOGO客版彩盒 | W40: 日期码格式：DGYYYYMMDD(日期避开周末和法定节假日) 日期：按实际生产日期 Packaging Info: 翻单：4500147361 1.包装方式： 25251：最新扶正ZURU LOGO客版彩盒（客版UPC）1L+23L警告语 + MA D版1L说明书 Remark: 2. 外箱四面印刷青色RFID箱唛 + 顶部ZURU logo黑色色带。 主唛左前下角印刷艾利贴纸替代标箱唛(ITF-14格式)，条码只印刷一面。 主唛右下角加印 MADE IN CHINA 3. WM#25251 NEW UPC：193052056092 4. Include 3pcs AAA carbon batteries; 5.此单需要验货，请自行多备包装物料。 6.在产品上和包装上要有日期码、MADE IN CHINA和ZURU字样。 7.此批单都为散箱出货 8.每PCS要加RFID 贴纸，严格按照我们提供的位置图，不可擅自调整位置，贴纸也不可有任何破损或折坏，不可淋湿!!（如缺数请及时告知） | X40: Nikki Mo | Y40: 3.7145 | Z40: =Y40*J40 -> 7064.979 | AA40: 94270-2.18 | AB40: 1902 | AC40: =AB40-J40 -> 0 | AD40: ok | AE40: 已入 | AF40: 系统出单 | AH40: =J40 -> 1902 | AL40: =J40 -> 1902 | BA40: =J40 -> 1902 | BD40: =SUM(AH40:AJ40) -> 1902 | BE40: =BD40-J40 -> 0
...

Sheet 7163-66
A1: ZURU Baby shark playset 滑道鲨鱼生产排期表 #25291
A2: =鴨子、鱷魚、金魚排期!A2 -> 44982 | AJ2: 7163 | AR2: 7175A | AS2: 7175B | AT2: 7166
A3: 香港接单日期 | B3: 第三方客户名称 | C3: 走货国家 | D3: ZURU PO NO# | E3: 第三方客户 PO NO# | F3: SKU | G3: 系统货号 | H3: ITEM# | I3: 中文名 | J3: PO数量 (pcs) | K3: 外箱装箱数量(pcs) | L3: 外箱装箱数量(pcs) | M3: 总箱数 | N3: 计划出货期 | O3: 计划验货期 | P3: 第三方客户公证行验货 | Q3: 驗貨結果 | R3: ZURU确认走货日期 | S3: 箱唛资料(收到日期) | T3: 外箱贴纸 | U3: 客供贴纸AI(收到日期) | V3: 包装 | W3: 备注 | X3: ZURU 跟单 | Y3: 单价USD | Z3: 金额USD | AA3: 發票號 | AB3: 送货情况 | AC3: 欠数 | AD3: 贴纸情况 | AE3: 是否入系统 | AF3: 系统出单 | AG3: 黄色小鲨鱼 | AH3: 蓝色小鲨鱼 | AI3: 粉色小鲨鱼 | AJ3: 2023-MA-1L彩盒 | AK3: 2023-MA-3L彩盒 | AL3: 2023-MA-9L说明书(7163/7175/7166)共用 | AM3: MA 1L-3L (共用PDQ）（2023新） | AN3: MA 1L-3L (共用PDQ）（2025新） | AO3: 客版彩盒 | AP3: 客版说明书 | AQ3: 客版PDQ | AR3: WM客版彩盒 | AS3: WM客版彩盒 | AT3: MA 1语彩盒 B版本 | AU3: MA 3语彩盒 B版本 | AV3: PDQ-7175/7166共用
A4: 45608 | B4: CMS FAMOUS TOYS | C4: 加拿大 | D4: 4500151018 | E4: PO0000475 | F4: 4500151018-50 | G4: 7163-2023-S003-3L-V1 | H4: 7163-2023-S003 | I4: 小鲨鱼 | J4: 240 | K4: 0 | L4: 24 | M4: =J4/L4 -> 10 | N4: 45651 | O4: 45647 | Q4: PASS | S4: 11/25收到 | U4: 11/25-UPC 贴纸 | V4: 7163 MA 多语版包装 | W4: 日期码格式： 标准格式 日期：按实际生产日期 Packaging Info: 7163 MA 多语版包装+UPC 贴纸。UPC号码193052062604 Remark: 出加拿大 每款产品都需要加进口商贴纸 Zuru验货.日期跟踪码：产品外包装及产品本身都必须有日期跟踪码，ZURU标准格式日期码 | X4: Summer Mo | Y4: 1.4655 | Z4: =Y4*J4 -> 351.72 | AA4: 88842-1.2 | AB4: 240 | AC4: =AB4-J4 -> 0 | AD4: OK | AE4: 已入 | AF4: 系统出单 | AG4: =J4/3 -> 80 | AH4: =J4/3 -> 80 | AI4: =J4/3 -> 80 | AK4: =J4 -> 240 | AL4: =J4 -> 240
A5: 45608 | B5: Amazon CA (Vendor Center) | C5: 加拿大 | D5: 4500150978 | E5: 222PB6UC | F5: 4500150978-160 | G5: 7166-2023-S002-V1-3L | H5: 7166-2023-S002 | I5: 小鲨鱼3PK | J5: 18 | K5: 0 | L5: 18 | M5: =J5/L5 -> 1 | N5: 45653 | O5: 45649 | Q5: PASS | R5: 1/1-1/7出 | S5: 11/12收到 | U5: 2024/11/25+UPC贴纸+外箱贴 | V5: 7166 MA 3L UPC版本 | W5: 日期码格式：ZURU INC(BVI) 标准格式 日期：按实际生产日期 Packaging Info: 出口加拿大，包装需要至少2/3L UPC版，无硼版本 #7166 MA 3L 加UPC贴纸，UPC贴纸资料翻单4500148503.。需要加一张客供防伪帖纸，贴纸跟单提供。与Amazon US 合并订料。 Remark: 1. Amazon FOB订单，出口CA。外箱最长边不能超过25" （超过了，case pack只能为1），不符合要求的大货，一律不接受。 2. 外箱正面印ZURU Logo + SSCC LABEL（客供贴纸)，侧面印item#（订单上显示的SKU#) + carton size(以工厂实际尺寸为准，单位: inch) + MADE IN CHINA， 日期使用ZURU 标准版本 SSCC Label 显示的是客人自己的item#，SSCC Label 贴在外箱正面的正中间，贴一面即可，跟单订购，贴纸离外箱距必须至少3cm，每一 张SSCC label 都是唯一且有不同流水及条码的，没有损耗，绝对不可贴错 ，否则贴错或损坏一张会导致全部都错，千万要注意: SSCC 贴纸务必要在正中间(可以覆 盖Logo <(>&<)> 箱唛)，否则会影响到仓库扫描识别。 3. 日期码使用ZURU标准版本。 4. 如果大货有要求入邮包盒，则对应的邮包盒上面要打上日期码。 5. 按照客户PO# 装柜/箱号顺序装柜，跟单会提前给到装柜计划。在大货生产/仓库存放时，请留意该装柜要求，以便装柜时不混乱（避免装错/装漏/找不到货号等 ）。 6. 出口加拿大，包装需要至少2/3L UPC版，无硼版本。 7.邮包盒上要印刷日期码 | X5: Kelly/Mia | Y5: 3.5384 | Z5: =Y5*J5 -> 63.6912 | AA5: 88919-1.7 | AB5: 18 | AC5: =AB5-J5 -> 0 | AD5: ok | AE5: 已入 | AF5: 系统出单 | AG5: =J5 -> 18 | AH5: =J5 -> 18 | AI5: =J5 -> 18 | AL5: =J5 -> 18 | AU5: =J5 -> 18
A6: 45623 | B6: AMAZON.COM.DEDC,LLC | C6: 美国 | D6: 4500152379 | E6: 3HLAV7WC | F6: 4500152379-130 | G6: 7166-2023-S002-V1-3L | H6: 7166-2023-S002 | I6: 小鲨鱼3PK | J6: 216 | K6: 0 | L6: 18 | M6: =J6/L6 -> 12 | N6: 45664 | O6: 45660 | Q6: PASS | S6: 45623 | U6: 12/20-客供防伪帖纸+12/20外箱贴+UPC贴纸翻4500148503 | V6: 7166 MA 3L UPC版本 | W6: 日期码格式： 标准格式 日期：按实际生产日期 Packaging Info:#7166 MA 3L 加UPC贴纸，UPC贴纸资料翻单4500148503.。需要加一张客供防伪帖纸，贴纸跟单提供。 Remark: 1. Amazon FOB订单，出口US。 2. 日期码使用ZURU标准版本。 3. 如果大货有要求入邮包盒，则对应的邮包盒上面要打上日期码。 4. 箱尺寸要求：外箱最长边不能超过25"（超过了，case pack只能为1），不符合要求的大货，一律不接受。 5. 外箱箱唛要求： ①外箱正面印ZURU Logo+SSCC Label（客供贴纸，由跟单订购)。关于 SSCC Label 请注意： SSCC Label 显示的是客人自己的item#。每一张SSCC label 都是唯一且有不同流水及条码的，没有损耗，绝对不可贴错 。如果贴错或损坏任何一张，都会导致全部都错，千万要注意！ SSCC Label 必须贴在外箱正面的正中间位置（贴一面即可），并且贴纸离外箱边距必须至少3cm(可以覆盖Logo<(>&<)>箱唛)，否则会影响到客户那边仓库的扫描识别。 ②外箱侧面印item#（订单上显示的SKU#)+carton size(以工厂实际尺寸为准,单位: inch) +MADE IN CHINA,日期使用ZURU 标准版本。 6. 装柜要求：按照客户PO# 装柜/箱号顺序装柜，跟单会提前给到装柜计划。 在大货生产/仓库存放时，请留意该装柜要求，以便装柜时不混乱（避免装错/装漏/找不到货号等）。 | X6: Kelly Shen | Y6: 3.5711 | Z6: =Y6*J6 -> 771.3576 | AA6: 94201-2.10 | AB6: 216 | AC6: =AB6-J6 -> 0 | AD6: ok | AE6: 已入 | AF6: 系统出单 | AG6: =J6 -> 216 | AH6: =J6 -> 216 | AI6: =J6 -> 216 | AL6: =J6 -> 216 | AU6: =J6 -> 216
A7: 45623 | B7: AMAZON.COM.DEDC,LLC | C7: 美国 | D7: 4500152657 | E7: 6JHFI1AV | F7: 4500152657-20 | G7: 7166-2023-S002-V1-3L | H7: 7166-2023-S002 | I7: 小鲨鱼3PK | J7: 180 | K7: 0 | L7: 18 | M7: =J7/L7 -> 10 | N7: 45664 | O7: 45660 | Q7: PASS | S7: 45623 | U7: 12/20-客供防伪帖纸+12/20外箱贴+UPC贴纸翻4500148503 | V7: 7166 MA 3L UPC版本 | W7: 日期码格式： 标准格式 日期：按实际生产日期 Packaging Info:#7166 MA 3L 加UPC贴纸，UPC贴纸资料翻单4500148503.。需要加一张客供防伪帖纸，贴纸跟单提供。 Remark: 1. Amazon FOB订单，出口US。 2. 日期码使用ZURU标准版本。 3. 如果大货有要求入邮包盒，则对应的邮包盒上面要打上日期码。 4. 箱尺寸要求：外箱最长边不能超过25"（超过了，case pack只能为1），不符合要求的大货，一律不接受。 5. 外箱箱唛要求： ①外箱正面印ZURU Logo+SSCC Label（客供贴纸，由跟单订购)。关于 SSCC Label 请注意： SSCC Label 显示的是客人自己的item#。每一张SSCC label 都是唯一且有不同流水及条码的，没有损耗，绝对不可贴错 。如果贴错或损坏任何一张，都会导致全部都错，千万要注意！ SSCC Label 必须贴在外箱正面的正中间位置（贴一面即可），并且贴纸离外箱边距必须至少3cm(可以覆盖Logo<(>&<)>箱唛)，否则会影响到客户那边仓库的扫描识别。 ②外箱侧面印item#（订单上显示的SKU#)+carton size(以工厂实际尺寸为准,单位: inch) +MADE IN CHINA,日期使用ZURU 标准版本。 6. 装柜要求：按照客户PO# 装柜/箱号顺序装柜，跟单会提前给到装柜计划。 在大货生产/仓库存放时，请留意该装柜要求，以便装柜时不混乱（避免装错/装漏/找不到货号等）。 | X7: Kelly Shen | Y7: 3.5711 | Z7: =Y7*J7 -> 642.798 | AA7: 94229-2.12 | AB7: 180 | AC7: =AB7-J7 -> 0 | AD7: ok | AE7: 已入 | AF7: 系统出单 | AG7: =J7 -> 180 | AH7: =J7 -> 180 | AI7: =J7 -> 180 | AL7: =J7 -> 180 | AU7: =J7 -> 180
A8: 45623 | B8: AMAZON.COM.DEDC,LLC | C8: 美国 | D8: 4500152439 | E8: 3OLDBHZT | F8: 4500152439-20 | G8: 7166-2023-S002-V1-3L | H8: 7166-2023-S002 | I8: 小鲨鱼3PK | J8: 792 | K8: 0 | L8: 18 | M8: =J8/L8 -> 44 | N8: 45666 | O8: 45663 | Q8: PASS | S8: 45623 | U8: 12/20-客供防伪帖纸+12/20外箱贴+UPC贴纸翻4500148503 | V8: 7166 MA 3L UPC版本 | W8: 日期码格式： 标准格式 日期：按实际生产日期 Packaging Info: #7166：MA 3L 加UPC贴纸，UPC贴纸资料翻单4500148503.。需要加一张客供防伪帖纸，贴纸跟单提供。 Remark: 1. Amazon FOB订单，出口US。 2. 日期码使用ZURU标准版本。 3. 如果大货有要求入邮包盒，则对应的邮包盒上面要打上日期码。 4. 箱尺寸要求：外箱最长边不能超过25"(超过了，case pack只能为1)，不符合要求的大货，一律不接受。 5. 外箱箱唛要求： ①外箱正面印ZURU Logo+SSCC Label(客供贴纸，由跟单订购)。关于 SSCC Label 请注意： SSCC Label显示的是客人自己的item#。每一张SSCC label都是唯一且有不同流水及条码的，没有损耗，绝对不可贴错。如果贴错或损坏任何一张，都会导致全部都 错，千万要注意！SSCC Label必须贴在外箱正面的正中间位置(贴一面即可)，并且贴纸离外箱边距必须至少3cm(可以覆盖Logo<(>&<)>箱唛)，否则会影响到客户那边 仓库的扫描识别。 ②外箱侧面印item#(订单上显示的SKU#)+carton size(以工厂实际尺寸为准，单位: inch)+MADE IN CHINA，日期使用ZURU 标准版本。 6. 装柜要求：按照客户PO#装柜/箱号顺序装柜，跟单会提前给到装柜计划。 在大货生产/仓库存放时，请留意该装柜要求，以便装柜时不混乱(避免装错/装漏/找不到货号等)。 | X8: Kelly Shen | Y8: 3.5384 | Z8: =Y8*J8 -> 2802.4128 | AA8: 94019-1.13 | AB8: 792 | AC8: =AB8-J8 -> 0 | AD8: ok | AE8: 已入 | AF8: 系统出单 | AG8: =J8 -> 792 | AH8: =J8 -> 792 | AI8: =J8 -> 792 | AL8: =J8 -> 792 | AU8: =J8 -> 792
A9: 45623 | B9: Amazon CA (Vendor Center) | C9: 加拿大 | D9: 4500152544 | E9: 2SEV5TYK | F9: 4500152544-50 | G9: 7166-2023-S002-V1-3L | H9: 7166-2023-S002 | I9: 小鲨鱼3PK | J9: 18 | K9: 0 | L9: 18 | M9: =J9/L9 -> 1 | N9: 45670 | O9: 45666 | Q9: PASS | R9: 1/16-1/21出 | S9: 45623 | U9: 12/20-客供防伪帖纸+12/20外箱贴+UPC贴纸翻4500148503 | V9: 7166 MA 3L UPC版本 | W9: 日期码格式：ZURU INC(BVI) 标准格式 日期：按实际生产日期 Packaging Info: 出口加拿大，包装需要至少2/3L UPC版，无硼版本。 #7166 MA 3L 加UPC贴纸，UPC贴纸资料翻单4500148503。需要加一张客供防伪帖纸，贴纸跟单提供。与Amazon US 合并订料。 Remark: 1. Amazon FOB订单，出口CA。外箱最长边不能超过25" （超过了，case pack只能为1），不符合要求的大货，一律不接受。 2. 外箱正面印ZURU Logo + SSCC LABEL（客供贴纸)，侧面印item#（订单上显示的SKU#) + carton size(以工厂实际尺寸为准，单位: inch) + MADE IN CHINA， 日期使用ZURU 标准版本 SSCC Label 显示的是客人自己的item#，SSCC Label 贴在外箱正面的正中间，贴一面即可，跟单订购，贴纸离外箱距必须至少3cm，每一 张SSCC label 都是唯一且有不同流水及条码的，没有损耗，绝对不可贴错 ，否则贴错或损坏一张会导致全部都错，千万要注意: SSCC 贴纸务必要在正中间(可以覆 盖Logo <(>&<)> 箱唛)，否则会影响到仓库扫描识别。 3. 日期码使用ZURU标准版本。 4. 如果大货有要求入邮包盒，则对应的邮包盒上面要打上日期码。 5. 按照客户PO# 装柜/箱号顺序装柜，跟单会提前给到装柜计划。在大货生产/仓库存放时，请留意该装柜要求，以便装柜时不混乱（避免装错/装漏/找不到货号等 ）。 6. 出口加拿大，包装需要至少2/3L UPC版，无硼版本。 7.邮包盒上要印刷日期码 | X9: Kelly/Mia | Y9: 3.5384 | Z9: =Y9*J9 -> 63.6912 | AA9: 94134-1.21 | AB9: 18 | AC9: =AB9-J9 -> 0 | AD9: ok | AE9: 已入 | AF9: 系统出单 | AG9: =J9 -> 18 | AH9: =J9 -> 18 | AI9: =J9 -> 18 | AL9: =J9 -> 18 | AU9: =J9 -> 18
A10: 45623 | B10: Amazon CA (Vendor Center) | C10: 加拿大 | D10: 4500152544 | E10: 5E1J4Q8W | F10: 4500152544-100 | G10: 7166-2023-S002-V1-3L | H10: 7166-2023-S002 | I10: 小鲨鱼3PK | J10: 18 | K10: 0 | L10: 18 | M10: =J10/L10 -> 1 | N10: 45670 | O10: 45666 | Q10: PASS | R10: 1/16-1/21出 | S10: 45623 | U10: 12/20-客供防伪帖纸+12/20外箱贴+UPC贴纸翻4500148503 | V10: 7166 MA 3L UPC版本 | W10: 日期码格式：ZURU INC(BVI) 标准格式 日期：按实际生产日期 Packaging Info: 出口加拿大，包装需要至少2/3L UPC版，无硼版本。 #7166 MA 3L 加UPC贴纸，UPC贴纸资料翻单4500148503。需要加一张客供防伪帖纸，贴纸跟单提供。与Amazon US 合并订料。 Remark: 1. Amazon FOB订单，出口CA。外箱最长边不能超过25" （超过了，case pack只能为1），不符合要求的大货，一律不接受。 2. 外箱正面印ZURU Logo + SSCC LABEL（客供贴纸)，侧面印item#（订单上显示的SKU#) + carton size(以工厂实际尺寸为准，单位: inch) + MADE IN CHINA， 日期使用ZURU 标准版本 SSCC Label 显示的是客人自己的item#，SSCC Label 贴在外箱正面的正中间，贴一面即可，跟单订购，贴纸离外箱距必须至少3cm，每一 张SSCC label 都是唯一且有不同流水及条码的，没有损耗，绝对不可贴错 ，否则贴错或损坏一张会导致全部都错，千万要注意: SSCC 贴纸务必要在正中间(可以覆 盖Logo <(>&<)> 箱唛)，否则会影响到仓库扫描识别。 3. 日期码使用ZURU标准版本。 4. 如果大货有要求入邮包盒，则对应的邮包盒上面要打上日期码。 5. 按照客户PO# 装柜/箱号顺序装柜，跟单会提前给到装柜计划。在大货生产/仓库存放时，请留意该装柜要求，以便装柜时不混乱（避免装错/装漏/找不到货号等 ）。 6. 出口加拿大，包装需要至少2/3L UPC版，无硼版本。 7.邮包盒上要印刷日期码 | X10: Kelly/Mia | Y10: 3.5384 | Z10: =Y10*J10 -> 63.6912 | AA10: 94134-1.21 | AB10: 18 | AC10: =AB10-J10 -> 0 | AD10: ok | AE10: 已入 | AF10: 系统出单 | AG10: =J10 -> 18 | AH10: =J10 -> 18 | AI10: =J10 -> 18 | AL10: =J10 -> 18 | AU10: =J10 -> 18
A11: 45558 | B11: ACADEMY LTD | C11: 美国 | D11: 4500145922 | E11: 10858892 | F11: 4500145922-20 | G11: 7163TQ1-2023-S001-V1 | H11: 7163TQ1-2023-S001 | I11: 小鲨鱼 | J11: 510 | K11: 0 | L11: 6 | M11: =J11/L11 -> 85 | N11: 45693 | O11: 45689 | Q11: PASS | R11: 2/13出 | S11: 12/25收到 | U11: 12/25-UCC外箱贴纸 | V11: MA UPC 版本包装 | W11: 日期码格式：ZURU INC(BVI) 标准格式 日期：按实际生产日期 Packaging Info:#7163TQ1: MA UPC 版本包装; UPC#193052062604; 3PCS LR44 batteries;(included); 3 assortment Remark: 2 .外箱正唛的右下角需贴一个UCC贴纸（4x6inch,距离右边和底边2inch,UCC贴纸为流水号的，每一箱都不一样。 3. 请按期完货，延期有罚金。 4. 我司验货即可。 5. 产品和包装上有tracking code信息，格式为ZURU常规。 | X11: Abby Mai, Lluviazeng | Y11: 1.6244 | Z11: =Y11*J11 -> 828.444 | AA11: 94236-2.13 | AB11: 510 | AC11: =AB11-J11 -> 0 | AD11: OK | AE11: 已入 | AF11: 系统出单 | AG11: =J11/3 -> 170 | AH11: =J11/3 -> 170 | AI11: =J11/3 -> 170 | AJ11: =J11 -> 510 | AL11: =J11 -> 510 | AM11: =J11/6 -> 85
A12: 45558 | B12: ACADEMY LTD | C12: 美国 | D12: 4500145919 | E12: 10858893 | F12: 4500145919-20 | G12: 7163TQ1-2023-S001-V1 | H12: 7163TQ1-2023-S001 | I12: 小鲨鱼 | J12: 570 | K12: 0 | L12: 6 | M12: =J12/L12 -> 95 | N12: 45693 | O12: 45689 | Q12: PASS | R12: 2/13-2/15出 | S12: 12/25收到 | U12: 12/25-UCC外箱贴纸 | V12: MA UPC 版本包装 | W12: 日期码格式：ZURU INC(BVI) 标准格式 日期：按实际生产日期 Packaging Info:#7163TQ1: MA UPC 版本包装; UPC#193052062604; 3PCS LR44 batteries;(included); 3 assortment Remark: 2 .外箱正唛的右下角需贴一个UCC贴纸（4x6inch,距离右边和底边2inch,UCC贴纸为流水号的，每一箱都不一样。 3. 请按期完货，延期有罚金。 4. 我司验货即可。 5. 产品和包装上有tracking code信息，格式为ZURU常规。 | X12: Abby Mai, Lluviazeng | Y12: 1.6244 | Z12: =Y12*J12 -> 925.908 | AA12: 94241-2.14 | AB12: 570 | AC12: =AB12-J12 -> 0 | AD12: OK | AE12: 已入 | AF12: 系统出单 | AG12: =J12/3 -> 190 | AH12: =J12/3 -> 190 | AI12: =J12/3 -> 190 | AJ12: =J12 -> 570 | AL12: =J12 -> 570 | AM12: =J12/6 -> 95
A13: 45558 | B13: ACADEMY LTD | C13: 美国 | D13: 4500145925 | E13: 10858891 | F13: 4500145925-20 | G13: 7163TQ1-2023-S001-V1 | H13: 7163TQ1-2023-S001 | I13: 小鲨鱼 | J13: 1134 | K13: 0 | L13: 6 | M13: =J13/L13 -> 189 | N13: 45699 | O13: 45695 | Q13: PASS | R13: 2/18出 | S13: 12/25收到 | U13: 12/25-UCC外箱贴纸 | V13: MA UPC 版本包装 | W13: 日期码格式：ZURU INC(BVI) 标准格式 日期：按实际生产日期 Packaging Info:#7163TQ1: MA UPC 版本包装; UPC#193052062604; 3PCS LR44 batteries;(included); 3 assortment Remark: 2 .外箱正唛的右下角需贴一个UCC贴纸（4x6inch,距离右边和底边2inch,UCC贴纸为流水号的，每一箱都不一样。 3. 请按期完货，延期有罚金。 4. 我司验货即可。 5. 产品和包装上有tracking code信息，格式为ZURU常规。 | X13: Abby Mai, Lluviazeng | Y13: 1.6189 | Z13: =Y13*J13 -> 1835.8326 | AA13: 94264-2.17 | AB13: 1134 | AC13: =AB13-J13 -> 0 | AD13: OK | AE13: 已入 | AF13: 系统出单 | AG13: =J13/3 -> 378 | AH13: =J13/3 -> 378 | AI13: =J13/3 -> 378 | AJ13: =J13 -> 1134 | AL13: =J13 -> 1134 | AM13: =J13/6 -> 189
A14: 45643 | B14: Dirk Rossmann GmbH | C14: 德国 | D14: 4500153297 | E14: 30241062 | F14: 4500153297-10 | G14: 7163-2023-S003-V1-1 | H14: 7163-2023-S003 | I14: 小鲨鱼 | J14: 5016 | K14: 0 | L14: 24 | M14: =J14/L14 -> 209 | N14: 45709 | O14: 45705 | P14: 2/21第三方 | Q14: PASS | R14: 2/24出 | S14: 12/26收到 | U14: 产品电池盖需要添加ZURU FRANCE地址字唛+1/15收到文档 | V14: 客版彩盒+产品电池盖需要添加ZURU FRANCE地址字唛+客版说明书 | W14: 日期码格式：ZURU INC(BVI) 标准格式 日期：按实际生产日期 Packaging Info: 客版彩盒+产品电池盖需要添加ZURU FRANCE地址字唛+客版说明书 Remark: 1. 出口欧洲，微塑料需符合法规 2. 所有包装材料都需要用PET材质。 3. 外箱上下需加保护卡，以防开箱时产品被划破。（保护卡需要时整面） 4. 此单在出货前4周提供完整的3套大货样品给Rossmann德国客人.请备额外物料。 5. 此单需要第三方验货，验货时间为完货后第二天，验货OK待客人放货后才能安排走货。 6. 此单出德国走散货，请知悉。 7. 每箱需要放一包干燥剂（不能是silicon) 。品牌SUPER DRY，规格：10g/pc 。 8. 外箱需要是5层瓦楞纸，厚度在5-9mm" | X14: Shirley Zhou | Y14: 1.2898 | Z14: =Y14*J14 -> 6469.6368 | AA14: 94339-2.25 | AB14: 5016 | AC14: =AB14-J14 -> 0 | AD14: 无 | AE14: 已入 | AF14: 系统出单 | AG14: =J14/3 -> 1672 | AH14: =J14/3 -> 1672 | AI14: =J14/3 -> 1672 | AO14: =J14 -> 5016 | AP14: =J14 -> 5016
A15: 45558 | B15: ACADEMY LTD | C15: 美国 | D15: 4500145932 | E15: 10858931 | F15: 4500145932-20 | G15: 7163TQ1-2023-S001-V1 | H15: 7163TQ1-2023-S001 | I15: 小鲨鱼 | J15: 516 | K15: 0 | L15: 6 | M15: =J15/L15 -> 86 | N15: 45712 | O15: 45708 | Q15: PASS | R15: 3/3出 | S15: 12/25收到 | U15: 12/25-UCC外箱贴纸 | V15: MA UPC 版本包装 | W15: 日期码格式：ZURU INC(BVI) 标准格式 日期：按实际生产日期 Packaging Info:#7163TQ1: MA UPC 版本包装; UPC#193052062604; 3PCS LR44 batteries;(included); 3 assortment Remark: 2 .外箱正唛的右下角需贴一个UCC贴纸（4x6inch,距离右边和底边2inch,UCC贴纸为流水号的，每一箱都不一样。 3. 请按期完货，延期有罚金。 4. 我司验货即可。 5. 产品和包装上有tracking code信息，格式为ZURU常规。 | X15: Abby Mai, Lluviazeng | Y15: 1.6244 | Z15: =Y15*J15 -> 838.1904 | AA15: 94417-3.3 | AB15: 516 | AC15: =AB15-J15 -> 0 | AD15: OK | AE15: 已入 | AF15: 系统出单 | AG15: =J15/3 -> 172 | AH15: =J15/3 -> 172 | AI15: =J15/3 -> 172 | AJ15: =J15 -> 516 | AL15: =J15 -> 516 | AM15: =J15/6 -> 86
A16: 45558 | B16: ACADEMY LTD | C16: 美国 | D16: 4500145929 | E16: 10858932 | F16: 4500145929-20 | G16: 7163TQ1-2023-S001-V1 | H16: 7163TQ1-2023-S001 | I16: 小鲨鱼 | J16: 564 | K16: 0 | L16: 6 | M16: =J16/L16 -> 94 | N16: 45712 | O16: 45708 | Q16: PASS | S16: 12/25收到 | U16: 12/25-UCC外箱贴纸 | V16: MA UPC 版本包装 | W16: 日期码格式：ZURU INC(BVI) 标准格式 日期：按实际生产日期 Packaging Info:#7163TQ1: MA UPC 版本包装; UPC#193052062604; 3PCS LR44 batteries;(included); 3 assortment Remark: 2 .外箱正唛的右下角需贴一个UCC贴纸（4x6inch,距离右边和底边2inch,UCC贴纸为流水号的，每一箱都不一样。 3. 请按期完货，延期有罚金。 4. 我司验货即可。 5. 产品和包装上有tracking code信息，格式为ZURU常规。 | X16: Abby Mai, Lluviazeng | Y16: 1.6244 | Z16: =Y16*J16 -> 916.1616 | AA16: 94416-3.3 | AB16: 564 | AC16: =AB16-J16 -> 0 | AD16: OK | AE16: 已入 | AF16: 系统出单 | AG16: =J16/3 -> 188 | AH16: =J16/3 -> 188 | AI16: =J16/3 -> 188 | AJ16: =J16 -> 564 | AL16: =J16 -> 564 | AM16: =J16/6 -> 94
A17: 45631 | B17: TOYS "R" US (CANADA) LTD. | C17: 加拿大 | D17: 4500153261 | E17: 3501527611 | F17: 4500153261-20 | G17: 7163TQ1-2023-S001-V1-3L | H17: 7163TQ1-2023-S001 | I17: 小鲨鱼 | J17: 1002 | K17: 0 | L17: 6 | M17: =J17/L17 -> 167 | N17: 45714 | O17: 45710 | P17: 2/27第三方 | Q17: PASS | R17: 3/5-3/11出 | S17: 1/6收到 | U17: 2/10收到 UPC 贴纸 | V17: 彩盒MA 3L | W17: 日期码格式：ZURU INC(BVI) 标准格式 日期：按实际生产日期 Packaging Info: 1. 出口加拿大市场 #7163TQ1: 彩盒MA 3L + UPC 贴纸，PDQ MA 版本; UPC#193052062604; 3PCS LR44 batteries;(included) Remark: 2. 需要第三方SGS验货，验货时间暂定2025/02/26，每款每色请备1PC完整带包装样品供验货人员参考。用完后若无损坏可以放回大货里。 | X17: Abby Mai, Lluviazeng | Y17: 1.6189 | Z17: =Y17*J17 -> 1622.1378 | AA17: 94517-3.11 | AB17: 1002 | AC17: =AB17-J17 -> 0 | AD17: ok | AE17: 已入 | AF17: 系统出单 | AG17: =J17/3 -> 334 | AH17: =J17/3 -> 334 | AI17: =J17/3 -> 334 | AK17: =J17 -> 1002 | AL17: =J17 -> 1002 | AM17: =J17/6 -> 167
A18: 45657 | B18: AMAZON.COM.DEDC,LLC | C18: 美国 | D18: 4500155048 | E18: 5EURH4TO | F18: 4500155048-10 | G18: 7166-2023-S002-V1-3L | H18: 7166-2023-S002 | I18: 小鲨鱼3PK | J18: 36 | K18: 0 | L18: 18 | M18: =J18/L18 -> 2 | N18: 45715 | O18: 45712 | Q18: PASS | R18: 收到SO | S18: 12/31收到 | U18: 1/13客供防伪帖纸+外箱贴纸 | V18: 7166 MA 3L UPC版本 | W18: 日期码格式：ZURU INC(BVI) 标准格式 日期：按实际生产日期 Packaging Info: #7166 MA 3L UPC版本。需要加一张客供防伪帖纸，贴纸跟单提供。 Remark: 1. Amazon FOB订单，出口US。 2. 日期码使用ZURU标准版本。 3. 如果大货有要求入邮包盒，则对应的邮包盒上面要打上日期码。 4. 箱尺寸要求：外箱最长边不能超过25" （超过了，case pack只能为1），不符合要求的大货，一律不接受。 5. 外箱箱唛要求： ①外箱正面印ZURU Logo+SSCC Label（客供贴纸，由跟单订购)。关于 SSCC Label 请注意： SSCC Label 显示的是客人自己的item#。每一张SSCC label 都是唯一且有不同流水及条码的，没有损耗，绝对不可贴错 。如果贴错或损坏任何一张，都会导致全 部都错，千万要注意！ SSCC Label 必须贴在外箱正面的正中间位置（贴一面即可），并且贴纸离外箱边距必须至少3cm(可以覆盖Logo<(>&<)>箱唛)，否则会影响到客户那边仓库的扫描识 别。 ②外箱侧面印item#（订单上显示的SKU#)+carton size(以工厂实际尺寸为准,单位: inch) +MADE IN CHINA,日期使用ZURU 标准版本。 6. 装柜要求：按照客户PO# 装柜/箱号顺序装柜，跟单会提前给到装柜计划。 在大货生产/仓库存放时，请留意该装柜要求，以便装柜时不混乱（避免装错/装漏/找不到货号等）。 | X18: Kelly Shen/Mia Pan | Y18: 3.5711 | Z18: =Y18*J18 -> 128.5596 | AA18: 94483-3.7 | AB18: 36 | AC18: =AB18-J18 -> 0 | AD18: OK | AE18: 已入 | AF18: 系统出单 | AG18: =J18 -> 36 | AH18: =J18 -> 36 | AI18: =J18 -> 36 | AL18: =J18 -> 36 | AU18: =J18 -> 36
A19: 45657 | B19: AMAZON.COM.DEDC,LLC | C19: 美国 | D19: 4500155020 | E19: 5MKL1CPZ | F19: 4500155020-20 | G19: 7166-2023-S002-V1-3L | H19: 7166-2023-S002 | I19: 小鲨鱼3PK | J19: 342 | K19: 0 | L19: 18 | M19: =J19/L19 -> 19 | N19: 45715 | O19: 45712 | Q19: PASS | R19: 收到SO | S19: 12/31收到 | U19: 1/13客供防伪帖纸+外箱贴纸+UPC贴纸翻4500148503 | V19: 7166 MA 3L UPC版本 | W19: 日期码格式：ZURU INC(BVI) 标准格式 日期：按实际生产日期 Packaging Info: #7166 MA 3L UPC版本。需要加一张客供防伪帖纸，贴纸跟单提供。 Remark: 1. Amazon FOB订单，出口US。 2. 日期码使用ZURU标准版本。 3. 如果大货有要求入邮包盒，则对应的邮包盒上面要打上日期码。 4. 箱尺寸要求：外箱最长边不能超过25" （超过了，case pack只能为1），不符合要求的大货，一律不接受。 5. 外箱箱唛要求： ①外箱正面印ZURU Logo+SSCC Label（客供贴纸，由跟单订购)。关于 SSCC Label 请注意： SSCC Label 显示的是客人自己的item#。每一张SSCC label 都是唯一且有不同流水及条码的，没有损耗，绝对不可贴错 。如果贴错或损坏任何一张，都会导致全 部都错，千万要注意！ SSCC Label 必须贴在外箱正面的正中间位置（贴一面即可），并且贴纸离外箱边距必须至少3cm(可以覆盖Logo<(>&<)>箱唛)，否则会影响到客户那边仓库的扫描识 别。 ②外箱侧面印item#（订单上显示的SKU#)+carton size(以工厂实际尺寸为准,单位: inch) +MADE IN CHINA,日期使用ZURU 标准版本。 6. 装柜要求：按照客户PO# 装柜/箱号顺序装柜，跟单会提前给到装柜计划。 在大货生产/仓库存放时，请留意该装柜要求，以便装柜时不混乱（避免装错/装漏/找不到货号等）。 | X19: Kelly Shen/Mia Pan | Y19: 3.5711 | Z19: =Y19*J19 -> 1221.3162 | AA19: 94452-3.5 | AB19: 342 | AC19: =AB19-J19 -> 0 | AD19: ok | AE19: 已入 | AF19: 系统出单 | AG19: =J19 -> 342 | AH19: =J19 -> 342 | AI19: =J19 -> 342 | AL19: =J19 -> 342 | AU19: =J19 -> 342
A20: 45558 | B20: ACADEMY LTD | C20: 美国 | D20: 4500145933 | E20: 10858930 | F20: 4500145933-20 | G20: 7163TQ1-2023-S001-V1 | H20: 7163TQ1-2023-S001 | I20: 小鲨鱼 | J20: 1092 | K20: 0 | L20: 6 | M20: =J20/L20 -> 182 | N20: 45728 | O20: 45724 | Q20: PASS | R20: 3/17-3/19出 | S20: 12/25收到 | U20: 12/25-UCC外箱贴纸 | V20: MA UPC 版本包装 | W20: 日期码格式：ZURU INC(BVI) 标准格式 日期：按实际生产日期 Packaging Info:#7163TQ1: MA UPC 版本包装; UPC#193052062604; 3PCS LR44 batteries;(included); 3 assortment Remark: 2 .外箱正唛的右下角需贴一个UCC贴纸（4x6inch,距离右边和底边2inch,UCC贴纸为流水号的，每一箱都不一样。 3. 请按期完货，延期有罚金。 4. 我司验货即可。 5. 产品和包装上有tracking code信息，格式为ZURU常规。 | X20: Abby Mai, Lluviazeng | Y20: 1.6189 | Z20: =Y20*J20 -> 1767.8388 | AA20: ZB00070-3.28 | AB20: 1092 | AC20: =AB20-J20 -> 0 | AD20: OK | AE20: 已入 | AF20: 系统出单 | AG20: =J20/3 -> 364 | AH20: =J20/3 -> 364 | AI20: =J20/3 -> 364 | AJ20: =J20 -> 1092 | AL20: =J20 -> 1092 | AM20: =J20/6 -> 182
A21: 45723 | B21: Miniso Depot CA Inc. | C21: 美国 | D21: 4500159501 | E21: Customer PO# 4341950649 | F21: 4500159501-20 | G21: 7163TQ1-2023-S002-V1 | H21: 7163TQ1-2023-S002 | I21: 小鲨鱼 | J21: 1824 | K21: 0 | L21: 24 | M21: =J21/L21 -> 76 | N21: 45798 | O21: 45794 | Q21: PASS | R21: 5/21出 | S21: 4/25收到 | U21: 4/29-UPC 条码贴纸+外箱贴纸 | V21: MA UPC 优先1L 最新包装 | W21: 日期码格式：ZURU INC(BVI) 标准格式 日期：按实际生产日期 Packaging Info: 1. 包装方式：MA UPC 优先1L 最新包装，出口美国； 2. 产品和包装上印刷tracking code信息，格式为ZURU常规. Remark: 4. 外箱加贴一张外箱贴纸，贴纸箱正唛一面，位置不限，不遮挡箱唛内容即可，贴纸AW跟单提供，工厂自行采购。 | X21: Iris Yuan | Y21: 0.9444 | Z21: =Y21*J21 -> 1722.5856 | AB21: 1824 | AC21: =AB21-J21 -> 0 | AD21: ok | AE21: 已入 | AF21: 系统出单 | AG21: =J21/3 -> 608 | AH21: =J21/3 -> 608 | AI21: =J21/3 -> 608 | AJ21: =J21 -> 1824 | AL21: =J21 -> 1824 | AM21: =J21/6 -> 304
A22: 45723 | B22: Miniso Depot CA Inc. | C22: 美国 | D22: 4500165182 | E22: CUSTOMER PO# 4341950650 | F22: 4500159501-20 | G22: 7163TQ1-2023-S002-V1 | H22: 7163TQ1-2023-S002 | I22: 小鲨鱼 | J22: 1536 | K22: 0 | L22: 24 | M22: =J22/L22 -> 64 | N22: 45798 | O22: 45794 | Q22: PASS | R22: 5/21出 | S22: 4/25收到 | U22: 4/29-UPC 条码贴纸 | V22: MA UPC 优先1L 最新包装 | W22: 日期码格式：ZURU INC(BVI) 标准格式 日期：按实际生产日期 Packaging Info: 1. 包装方式：MA UPC 优先1L 最新包装，出口美国； 2. 产品和包装上印刷tracking code信息，格式为ZURU常规. Remark: 3. #7163TQ1-2023-S002的PDQ上需要贴一张UPC 条码贴纸,UPC显示：193052062604；贴纸AW和位置图跟单提供，工厂自行采购。 4. 外箱加贴一张外箱贴纸，贴纸箱正唛一面，位置不限，不遮挡箱唛内容即可，贴纸AW跟单提供，工厂自行采购。 | X22: Iris Yuan | Y22: 0.9444 | Z22: =Y22*J22 -> 1450.5984 | AB22: 1536 | AC22: =AB22-J22 -> 0 | AD22: ok | AE22: 已入 | AF22: 系统出单 | AG22: =J22/3 -> 512 | AH22: =J22/3 -> 512 | AI22: =J22/3 -> 512 | AJ22: =J22 -> 1536 | AL22: =J22 -> 1536 | AM22: =J22/6 -> 256
A23: 45750 | B23: 360 SALES SOLUTIONS INC | C23: 加拿大 | D23: 4500162525 | E23: 2025ZURU16 | F23: 4500162525-20 | G23: 7163TQ1-2023-S001-V1-3L | H23: 7163TQ1-2023-S001 | I23: 小鲨鱼 | J23: 3402 | K23: 0 | L23: 6 | M23: =J23/L23 -> 567 | N23: 45800 | O23: 45796 | Q23: Pass | R23: 5/26出 | S23: 4/3收到 | U23: 4/3-UPC贴纸 | V23: 7163TQ1 MA 多语EAN | W23: 日期码格式：ZURU INC(BVI) 标准格式 日期：按实际生产日期 Packaging Info: 7163TQ1 MA 多语EAN+UPC贴纸， UPC号码193052062604 Remark: 出加拿大 Zuru验货.日期跟踪码：产品外包装及产品本身都必须有日期跟踪码，ZURU标准格式日期码。（箱唛日期码按跟单提供格式） | X23: Summer Mo | Y23: 1.4338 | Z23: =Y23*J23 -> 4877.7876 | AB23: 3402 | AC23: =AB23-J23 -> 0 | AD23: ok | AE23: 已入 | AF23: 系统出单 | AG23: =J23/3 -> 1134 | AH23: =J23/3 -> 1134 | AI23: =J23/3 -> 1134 | AK23: =J23 -> 3402 | AL23: =J23 -> 3402 | AM23: =J23/6 -> 567
A24: 45770 | B24: Planet of Toys Ltd | C24: 吉尔吉斯斯坦 | D24: 4500164616 | F24: 4500164616-110 | G24: 7163TQ1-2023-S002-V1 | H24: 7163TQ1-2023-S002 | I24: 小鲨鱼 | J24: 120 | K24: 0 | L24: 24 | M24: =J24/L24 -> 5 | N24: 45810 | O24: =N24-4 -> 45806 | Q24: Pass | R24: 收到SO | S24: 4/23收到 | U24: 4/30-通用贴纸 | V24: 1L MA UPC 包装 | W24: 日期码格式：ZURU INC(BVI) 标准格式 日期：按实际生产日期 Packaging Info: 1L MA UPC 包装 + 通用贴纸 ， MA 说明书/指南/PDQ （如有）； Remark: 标准配比 | X24: Ann | Y24: 1.5793 | Z24: =Y24*J24 -> 189.516 | AB24: 120 | AC24: =AB24-J24 -> 0 | AD24: ok | AE24: 已入 | AF24: 系统出单 | AG24: =J24/3 -> 40 | AH24: =J24/3 -> 40 | AI24: =J24/3 -> 40 | AJ24: =J24 -> 120 | AL24: =J24 -> 120 | AM24: =J24/6 -> 20
