Workbook
Name cavity: '[1]Form-003'!#REF!
Name Code: '[2]CQS Code(rev 38)'!$B$7:$E$1000
Name cycle.time: '[1]Form-003'!#REF!
Name GDE: [3]基础表!#REF!
Name mold.color: '[1]Form-003'!#REF!
Name mold.cost: '[1]Form-003'!#REF!
Name mold.height: '[1]Form-003'!#REF!
Name mold.length: '[1]Form-003'!#REF!
Name mold.material: '[1]Form-003'!#REF!
Name mold.name: '[1]Form-003'!#REF!
Name mold.number: '[1]Form-003'!#REF!
Name mold.partweight: '[1]Form-003'!#REF!
Name mold.usage: '[1]Form-003'!#REF!
Name mold.width: '[1]Form-003'!#REF!
Name new_sum: #REF!
Name part.list: '[1]Form-003'!#REF!
Name PI_IN: #REF!
Name PI_SUM: #REF!
Name PI_SUM_SALES: #REF!
Name Prepared.By: '[1]Form-003'!#REF!
Name Ref.Number: '[1]Form-003'!#REF!
Name Revised.By: '[1]Form-003'!#REF!
Name sd: [3]基础表!#REF!
Name tool.plan: '[1]Form-003'!#REF!
Name up: '[1]Form-003'!#REF!
Name Vendor: '[1]Form-003'!#REF!
Name 类别: [3]基础表!#REF!
Name 类别1: [3]基础表!#REF!
Name 领料单: [3]基础表!#REF!
Name 收料单: [3]基础表!#REF!
Name 一部: [3]基础表!#REF!

Sheet 77555旧排期
A1: ZURU （77555 迷你房子）生产排期表 | F1: 变更原因:根据市场要求，Mini Home出货需取消UV胶→ 根据美国市场要求，Mini Home出货需取消UV胶 更后内容: 3款稀有款出货不带UV胶- 3款稀有款出美国市场不带UV胶 目前美国市场的订单需要移除UV胶水出货，需要采用新版本的收缩膜和收藏指南，待10月底客人通知切换 | AG1: 第一张MA是订购A版本，第二张MA订购B版本，A和B版本区别在于德语的警语不一样，A版本不能出德国
AJ2: 收縮膜 | AQ2: 134013 | AS2: 收藏指南 | AY2: GQ6 | AZ2: GQ6 | BA2: GQ4 | BB2: FD GQ7 | BC2: GQ1 | BF2: GQ2 | BI2: GQ3 | BJ2: SQ1 | BK2: 不带底座 | BL2: 3L | BM2: 1L | BN2: 3L | BO2: 77556 圆筒 | BR2: 77584 圆筒
A3: 香港接单日期 | B3: 第三方客户名称 | C3: 走货国家 | D3: ZURU PO NO# | E3: 第三方客户 PO NO# | F3: SKU | G3: ITEM# | H3: 中文名 | I3: PO数量 (pcs) | J3: 内箱装箱数量(pcs) | K3: 外箱装箱数量(pcs) | L3: 总箱数 | M3: 客PO期 | N3: 验货期 | O3: 第三方验货期 | P3: 驗貨結果 | Q3: S/0船期 | R3: 箱唛资料(收到日期) | S3: 外箱贴纸 | T3: 客供贴纸AI(收到日期) | U3: 备注 | V3: ZURU 跟单 | W3: 单价USD | X3: 金额USD | Y3: 發票號 | Z3: 系统货号 | AA3: 是否入系统 | AB3: 系统出单 | AC3: 送货情况 | AD3: 欠数 | AE3: 贴纸 | AF3: 错误印刷内容3L内收缩膜 | AG3: 纸袋A/B | AH3: 球数 | AI3: 散件/空PDQ | AJ3: MA 1语 | AK3: MA 3语 | AL3: 1L-B版本 | AM3: 无UPC版本 | AN3: DG 客版 | AO3: TG客版 | AP3: WMCA客版 | AQ3: MGS客版 | AR3: GP 客版 | AS3: MA 5L语 | AT3: 5L-B版本 | AU3: 外挂收藏指南+中文说明书（每一款都不同，请做好区分） | AV3: wm us客版 | AW3: ESAL 客版 | AX3: GP 客版 | AY3: WMM 客版 | AZ3: 取消UV胶版本 | BA3: 1L | BB3: 客版 | BC3: 1L | BD3: 1L-B版本 | BE3: 3L | BF3: 1L | BG3: 1L-B版本 | BH3: 3L | BI3: 客版 | BJ3: 客版 | BK3: 77555SK-S001 | BL3: SK-S002 60PCS | BM3: SK1-S002 30PCS | BN3: SK1-S002 30PCS | BO3: 圆筒 | BP3: 铜板纸 | BQ3: 贴纸 | BR3: 圆筒 | BS3: 铜板纸 | BT3: 贴纸
A4: 45293 | B4: ZURU | C4: 库有 | D4: ZPO2401001 | E4: PP订单 | G4: 77555GQ2-S001 | H4: 迷你房子 | I4: 630 | K4: 50 | L4: =I4/K4 -> 12.6 | M4: 45315 | N4: 45315 | P4: PASS | R4: 周转箱 | S4: 无 | T4: 无 | U4: 请留意PP当天需要至少有2箱成品完成，如有必要请提前准备好半成品，谢谢！ | V4: Lynn | Y4: 84832-5.20 | Z4: # | AH4: =I4 -> 630 | BH4: =I4/25 -> 25.2
A5: 45293 | B5: ZURU | C5: 库有 | D5: ZMPO24010 | E5: PP | G5: 77555-S001 | H5: 迷你房子 | I5: 1000 | K5: 50 | L5: =I5/K5 -> 20 | M5: 45293 | P5: PASS | R5: 周转箱 | S5: 无 | T5: 无 | U5: 跟PP订单一起安排/麻烦按款号装箱 | V5: sally li | Y5: 84831-5.20 | Z5: # | AG5: A | AH5: =I5 -> 1000
A6: 45293 | B6: ZURU | C6: 库有 | D6: ZMPO24010 | E6: PP | G6: 77555-S001 | H6: 30套散件 | I6: 30 | K6: 50 | L6: =I6/K6 -> 0.6 | M6: 45293 | P6: PASS | R6: 周转箱 | S6: 无 | T6: 无 | U6: 跟PP订单一起安排/只需要全套散件，麻烦用胶袋分装好一套为一袋 | V6: sally li | Y6: 84831-5.20 | Z6: # | AC6: 30 | AI6: =I6 -> 30
A7: 45293 | B7: ZURU | C7: 库有 | D7: ZMPO24010 | E7: PP | G7: 77555GQ2-S001 | H7: 10个空PDQ | I7: 10 | K7: 50 | L7: =I7/K7 -> 0.2 | M7: 45293 | P7: PASS | R7: 周转箱 | S7: 无 | T7: 无 | U7: 跟PP订单一起安排/只需空PDQ+吸塑+展示公仔 | V7: sally li | Y7: 84831-5.20 | Z7: # | AI7: =I7 -> 10
A8: 45348 | B8: ZURU | C8: 库有 | D8: ZMPO24128 | G8: 77555GQ2-S001 | H8: 30套 | I8: 30 | K8: 50 | L8: =I8/K8 -> 0.6 | M8: 45357 | N8: 45353 | R8: 周转箱 | S8: 无 | T8: 无 | U8: 左图中4款小散件需要组装好+配套吸塑 | V8: sally li | Y8: 84848-5.21 | Z8: # | AC8: 30 | AI8: =I8 -> 30
A9: 45350 | B9: ZURU | C9: 库有 | D9: ZMPO24135 | G9: 77555-S001 | H9: 50套散件 | I9: 50 | J9: 0 | K9: 24 | L9: =I9/K9 -> 2.0833333 | M9: 45371 | N9: 45367 | R9: 周转箱 | S9: 无 | T9: 无 | U9: 大货最新版本/只需要齐全套散件，麻烦用胶袋分装好一套为一袋 | V9: sally li | Y9: 84849-5.21 | Z9: # | AC9: 30 | AI9: =I9 -> 50
A10: 45350 | B10: ZURU | C10: 库有 | D10: ZMPO24135 | G10: 77555-S001 | H10: 迷你房子 | I10: 1000 | J10: 0 | K10: 24 | L10: =I10/K10 -> 41.666667 | M10: 45371 | N10: 45367 | P10: pass | R10: 周转箱 | S10: 无 | T10: 无 | U10: 大货最新版本/款号数量平均/麻烦按款号装箱/并在外箱上注明款号/请用大货/箱唛请参照邮件附件 | V10: sally li | Y10: 84849-5.21 | Z10: 77555-S001 | AA10: 已入 | AB10: 系统出单 | AC10: 1000 | AG10: A | AH10: =I10 -> 1000 | AJ10: =I10 -> 1000 | AS10: =I10 -> 1000
A11: 45350 | B11: ZURU | C11: 库有 | D11: ZMPO24135 | G11: 77555GQ1-S001 | H11: 迷你房子 | I11: 650 | J11: 0 | K11: 13 | L11: =I11/K11 -> 50 | M11: 45371 | N11: 45367 | P11: pass | R11: 周转箱 | S11: 无 | T11: 无 | U11: 大货最新版本/PDQ里面的产品按大货比例入PDQ/大货标准箱装箱/箱唛参照邮件附件 | V11: sally li | Y11: 84849-5.21 | Z11: # | AC11: 650 | AG11: A | AH11: =I11 -> 650 | AJ11: =I11 -> 650 | AS11: =I11 -> 650 | BC11: =I11/13 -> 50
A12: 45350 | B12: ZURU | C12: 库有 | D12: ZMPO24135 | G12: 77555GQ2-S001 | H12: 迷你房子25pcsGQ2*2/箱 | I12: 2000 | K12: 50 | L12: =I12/K12 -> 40 | M12: 45371 | N12: 45367 | P12: pass | R12: 周转箱 | S12: 无 | T12: 无 | U12: 大货最新版本/PDQ里面的产品按大货比例入PDQ/大货标准箱装箱/箱唛参照邮件附件 | V12: sally li | Y12: 84849-5.21 | Z12: 77555GQ2-S001 | AA12: 已入 | AB12: 系统出单 | AC12: 2000 | AG12: A | AH12: =I12 -> 2000 | AJ12: =I12 -> 2000 | AS12: =I12 -> 2000 | BF12: =I12/25 -> 80
A13: 45363 | B13: ZURU | C13: 库有 | D13: ZMPO24189 | G13: 77555SK-S002 | H13: 迷你房子展示架 | I13: 480 | J13: 0 | K13: 60 | L13: =I13/K13 -> 8 | M13: 45381 | N13: 45377 | P13: pass | R13: 周转箱 | S13: 无 | T13: 无 | U13: 大货最新版本/产品按大货比例入展示架/箱唛请参照邮件附件 | V13: sally li | Y13: 85334-6.13 | Z13: # | AC13: 480 | AG13: A | AH13: =I13 -> 480 | AJ13: =I13 -> 480 | AS13: =I13 -> 480 | BL13: =I13/60 -> 8
A14: 45341 | B14: COLES SUPERMARKETS | C14: 澳大利亚 | D14: 4500124295 | E14: 43092050 SYD | F14: 4500124295-10 | G14: 77555GQ4-S001 | H14: 迷你房子GQ4/6pcs/箱 | I14: 768 | J14: 0 | K14: 6 | L14: =I14/K14 -> 128 | M14: 45392 | N14: 45388 | P14: pass | Q14: 4/15 交仓 | R14: 45328 | S14: 无 | T14: 无 | U14: 日期码格式：ZURU INC(BVI) 标准格式 日期：按实际生产日期 Packaging Info: 1. 包装 MA UPC PACKAGING Remark: 1.此单出口澳大利亚，请按相应的澳新标准生产； 2.产品和包装上生产批号请按我司标准 | V14: Lillian Li | W14: 1.6 | X14: =W14*I14 -> 1228.8 | Y14: 84798-5.17 | Z14: 77555GQ4-S001 | AA14: 已入 | AB14: 系统出单 | AC14: 768 | AD14: =AC14-I14 -> 0 | AE14: 无 | AG14: A | AH14: =I14 -> 768 | AJ14: =I14 -> 768 | AS14: =I14 -> 768 | BA14: =I14/6 -> 128
A15: 45341 | B15: COLES SUPERMARKETS | C15: 澳大利亚 | D15: 4500124295 | E15: 43092054 MEL | F15: 4500124295-30 | G15: 77555GQ4-S001 | H15: 迷你房子GQ4/6pcs/箱 | I15: 1578 | J15: 0 | K15: 6 | L15: =I15/K15 -> 263 | M15: 45392 | N15: 45388 | P15: pass | Q15: 4/15 交仓 | R15: 45328 | S15: 无 | T15: 无 | U15: 日期码格式：ZURU INC(BVI) 标准格式 日期：按实际生产日期 Packaging Info: 1. 包装 MA UPC PACKAGING Remark: 1.此单出口澳大利亚，请按相应的澳新标准生产； 2.产品和包装上生产批号请按我司标准 | V15: Lillian Li | W15: 1.6 | X15: =W15*I15 -> 2524.8 | Y15: 84798-5.17 | Z15: 77555GQ4-S001 | AA15: 已入 | AB15: 系统出单 | AC15: 1578 | AD15: =AC15-I15 -> 0 | AE15: 无 | AG15: A | AH15: =I15 -> 1578 | AJ15: =I15 -> 1578 | AS15: =I15 -> 1578 | BA15: =I15/6 -> 263
A16: 45341 | B16: COLES SUPERMARKETS | C16: 澳大利亚 | D16: 4500124295 | E16: 43102295 BNE | F16: 4500124295-50 | G16: 77555GQ4-S001 | H16: 迷你房子GQ4/6pcs/箱 | I16: 1098 | J16: 0 | K16: 6 | L16: =I16/K16 -> 183 | M16: 45392 | N16: 45388 | P16: pass | Q16: 4/15 交仓 | R16: 45328 | S16: 无 | T16: 无 | U16: 日期码格式：ZURU INC(BVI) 标准格式 日期：按实际生产日期 Packaging Info: 1. 包装 MA UPC PACKAGING Remark: 1.此单出口澳大利亚，请按相应的澳新标准生产； 2.产品和包装上生产批号请按我司标准 | V16: Lillian Li | W16: 1.6 | X16: =W16*I16 -> 1756.8 | Y16: 84798-5.17 | Z16: 77555GQ4-S001 | AA16: 已入 | AB16: 系统出单 | AC16: 1098 | AD16: =AC16-I16 -> 0 | AE16: 无 | AG16: A | AH16: =I16 -> 1098 | AJ16: =I16 -> 1098 | AS16: =I16 -> 1098 | BA16: =I16/6 -> 183
A17: 45355 | B17: KMART AUSTRALIA LTD(NEW ZEALAND) | C17: 新西兰 | D17: 4500125859 | E17: 19946678 | F17: 4500125859-10 | G17: 77555GQ1-S002 | H17: 迷你房子GQ1/13PCS/箱 | I17: 702 | J17: 0 | K17: 13 | L17: =I17/K17 -> 54 | M17: 45392 | N17: 45388 | P17: pass | R17: 45365 | S17: 有 | T17: 3/19箱唛贴纸 防盗贴纸翻单125858 | U17: 日期码格式：ZURU INC(BVI) 标准格式 日期：按实际生产日期 Packaging Info: 1.77555GQ1:MA英语UPC版本包装（首选1LUPC，如果无1L可用多语含英语UPC版本）+防盗贴纸+箱唛+箱唛贴纸(1PCS/CTN).防盗贴纸及其位置图请跟回PO#4500125858; Remark: 1,请务必按时完货，验货并请按期送货入货代指定仓库，如果晚了导致船期Delay将会有罚金产生或者客户要求空运，所产生的罚金和空运费由工厂承担。 2.SSCC 外箱贴纸请同纸箱瓦楞纸方向（竖纹向）垂直，即外箱贴纸横着贴(注意条码不要被胶带粘住），贴1pc，贴1面正唛，封箱胶纸不能挡住贴纸内容。每pcs外 箱贴纸都是唯一的，不可重复粘贴，否则会有罚款产生。 3.外箱材质为ZURU标准； 4.此单需使用KMART封箱胶上下工字型封箱;从2019年6月开始，要用KMART 新版封箱胶带，此单要用"ANKO"封箱胶带 5.此单出口新西兰，请按相应的澳新标准生产； 6.产品和包装上生产批号的显示格式ZURU标准日期码格式 7.RATIO: | V17: Sara Wang | W17: 1.55 | X17: =W17*I17 -> 1088.1 | Y17: 84792-5.17 | Z17: 77555GQ1-S002 | AA17: 已入 | AB17: 系统出单 | AC17: 702 | AD17: =AC17-I17 -> 0 | AE17: OK | AG17: A | AH17: =I17 -> 702 | AJ17: =I17 -> 702 | AS17: =I17 -> 702 | BC17: =I17/13 -> 54
A18: 45355 | B18: KMART AUSTRALIA LTD | C18: 澳大利亚 | D18: 4500125858 | E18: 19946677 | F18: 4500125858-10 | G18: 77555GQ1-S002 | H18: 迷你房子GQ1/13PCS/箱 | I18: 4914 | J18: 0 | K18: 13 | L18: =I18/K18 -> 378 | M18: 45392 | N18: 45388 | P18: pass | R18: 45365 | S18: 有 | T18: 3/19箱唛贴纸 防盗贴纸自行订购 | U18: 日期码格式：ZURU INC(BVI) 标准格式 日期：按实际生产日期 Packaging Info: 1.77555GQ1:MA英语UPC版本包装（首选1LUPC，如果无1L可用多语含英语UPC版本）+防盗贴纸+箱唛+箱唛贴纸(1PCS/CTN).防盗贴纸贴在球顶部空白处，大货生产前请返回位置图确认; Remark: 1,请务必按时完货，验货并请按期送货入货代指定仓库，如果晚了导致船期Delay将会有罚金产生或者客户要求空运，所产生的罚金和空运费由工厂承担。 2.SSCC 外箱贴纸请同纸箱瓦楞纸方向（竖纹向）垂直，即外箱贴纸横着贴(注意条码不要被胶带粘住），贴1pc，贴1面正唛，封箱胶纸不能挡住贴纸内容。每pcs外 箱贴纸都是唯一的，不可重复粘贴，否则会有罚款产生。 3.外箱材质为ZURU标准； 4.此单需使用KMART封箱胶上下工字型封箱;从2019年6月开始，要用KMART 新版封箱胶带，此单要用"ANKO"封箱胶带 5.此单出口澳大利亚，请按相应的澳新标准生产； 6.产品和包装上生产批号的显示格式ZURU标准日期码格式 7.RATIO: | V18: Sara Wang | W18: 1.55 | X18: =W18*I18 -> 7616.7 | Y18: 84784-5.17 | Z18: 77555GQ1-S002 | AA18: 已入 | AB18: 系统出单 | AC18: 4914 | AD18: =AC18-I18 -> 0 | AE18: OK | AG18: A | AH18: =I18 -> 4914 | AJ18: =I18 -> 4914 | AS18: =I18 -> 4914 | BC18: =I18/13 -> 378
A19: 45355 | B19: KMART AUSTRALIA LTD | C19: 澳大利亚 | D19: 4500125858 | E19: 19949062 | F19: 4500125858-20 | G19: 77555GQ1-S002 | H19: 迷你房子GQ1/13PCS/箱 | I19: 4914 | J19: 0 | K19: 13 | L19: =I19/K19 -> 378 | M19: 45392 | N19: 45388 | P19: pass | R19: 45365 | S19: 有 | T19: 3/19箱唛贴纸 防盗贴纸自行订购 | U19: 日期码格式：ZURU INC(BVI) 标准格式 日期：按实际生产日期 Packaging Info: 1.77555GQ1:MA英语UPC版本包装（首选1LUPC，如果无1L可用多语含英语UPC版本）+防盗贴纸+箱唛+箱唛贴纸(1PCS/CTN).防盗贴纸贴在球顶部空白处，大货生产前请返回位置图确认; Remark: 1,请务必按时完货，验货并请按期送货入货代指定仓库，如果晚了导致船期Delay将会有罚金产生或者客户要求空运，所产生的罚金和空运费由工厂承担。 2.SSCC 外箱贴纸请同纸箱瓦楞纸方向（竖纹向）垂直，即外箱贴纸横着贴(注意条码不要被胶带粘住），贴1pc，贴1面正唛，封箱胶纸不能挡住贴纸内容。每pcs外 箱贴纸都是唯一的，不可重复粘贴，否则会有罚款产生。 3.外箱材质为ZURU标准； 4.此单需使用KMART封箱胶上下工字型封箱;从2019年6月开始，要用KMART 新版封箱胶带，此单要用"ANKO"封箱胶带 5.此单出口澳大利亚，请按相应的澳新标准生产； 6.产品和包装上生产批号的显示格式ZURU标准日期码格式 7.RATIO: | V19: Sara Wang | W19: 1.55 | X19: =W19*I19 -> 7616.7 | Y19: 84784-5.17 | Z19: 77555GQ1-S002 | AA19: 已入 | AB19: 系统出单 | AC19: 4914 | AD19: =AC19-I19 -> 0 | AE19: OK | AG19: A | AH19: =I19 -> 4914 | AJ19: =I19 -> 4914 | AS19: =I19 -> 4914 | BC19: =I19/13 -> 378
A20: 45358 | B20: THE ENTERTAINER | C20: 英国 | D20: 4500126251 | F20: 4500126251-20 | G20: 77555GQ1-S002 | H20: 迷你房子GQ1/13PCS/箱 | I20: 21489 | J20: 0 | K20: 13 | L20: =I20/K20 -> 1653 | M20: 45394 | N20: 45390 | P20: pass | Q20: 4/19 截SI | R20: 45370 | S20: 无 | T20: 3/19条码贴 | U20: 日期码格式：ZURU INC(BVI) 标准格式 日期：按实际生产日期 Packaging Info: MA-3L 配套包装 ，额外加一张条码贴覆盖ZURU条码 按ZURU标准比例 Remark: *包装日期码按ZURU格式即可，请确保不迟于外箱日期码，可等于或者早于外箱日期码，必须为法定工作日。 *订单必须经过ZURU QC验货并且通过后方可出货。 *MA版本按工厂现有最新库存即可，请注意检查产品及包装应带UKCA图标，包装显示ZURU UK LTD信息，QC同事请查核，如有问题与跟单确认。 *条码以订单为准，请做货前先核对再安排生产 。 *所有产品按符合欧洲标准走货，不能出带闪粉版本 ，需要是不含微塑料版本 。 *订单出英国和西班牙市场 ，外包装必须要有英文和西班牙文警告语。 | V20: Sherry Lu | W20: 1.55 | X20: =W20*I20 -> 33307.95 | Y20: 84791-5.17 | Z20: 77555GQ2-S001-3L | AA20: 已入 | AB20: 系统出单 | AC20: 21489 | AD20: =AC20-I20 -> 0 | AE20: ok | AF20: 可接受 | AG20: A | AH20: =I20 -> 21489 | AK20: =I20 -> 21489 | AS20: =I20 -> 21489 | BE20: =I20/13 -> 1653
A21: 45351 | B21: Smyths Toys HQ UC UK | C21: 英国 | D21: 4500125676 | E21: 4400386226 | F21: 4500125676-10 | G21: 77555GQ2-S001 | H21: 迷你房子25pcsGQ2*2/箱 | I21: 8500 | J21: 0 | K21: 50 | L21: =I21/K21 -> 170 | M21: 45394 | N21: 45390 | P21: pass | Q21: 4/15 截SI | R21: 45356 | S21: 无 | T21: 贴纸以及位置图翻#450012567 | U21: 日期码格式：ZURU INC(BVI) 标准格式 日期：按实际生产日期 Packaging Info: 1.77555GQ2:MA 3L最新收缩膜+德国callout贴纸/荷兰警告语+MA 5L收藏指南+MA3LPDQ，贴纸以及位置图翻#4500125672 EAN#4894680033429 Remark: 1）包装日期码按ZURU格式即可，请确保不迟于外箱日期码，可等于或者早于外箱日期码，必须为法定工作日，印刷前请先检查外箱日期码。 2）订单出英国，请注意检查产品及包装应带UKCA图标（14+产品除外），包装显示ZURU UK LTD/ZURU France地址信息，QC部门请查核，如有问题与跟单确认 3）订单必须经过ZURU QC验货并且通过后方可出货 4) 需要符合欧洲标准不能含有闪粉和微塑料，否则不和法规会有客诉产生 | V21: Sheba Ye | W21: 1.54 | X21: =W21*I21 -> 13090 | Y21: 84789-5.17 | Z21: 77555GQ2-S001-3L | AA21: 已入 | AB21: 系统出单 | AC21: 8500 | AD21: =AC21-I21 -> 0 | AE21: ok | AF21: 可接受 | AG21: A | AH21: =I21 -> 8500 | AK21: =I21 -> 8500 | AS21: =I21 -> 8500 | BH21: =I21/25 -> 340
A22: 45351 | B22: Smyths Toys HQ UC IE | C22: 爱尔兰 | D22: 4500125672 | E22: 4400386225 | F22: 4500125672-10 | G22: 77555GQ2-S001 | H22: 迷你房子25pcsGQ2*2/箱 | I22: 2500 | J22: 0 | K22: 50 | L22: =I22/K22 -> 50 | M22: 45394 | N22: 45390 | P22: pass | R22: 45356 | S22: 无 | T22: 贴纸以及位置图翻#450012567 | U22: 日期码格式：ZURU INC(BVI) 标准格式 日期：按实际生产日期 Packaging Info: 1.77555GQ2:MA 3L最新收缩膜+德国callout贴纸/荷兰警告语+MA 5L收藏指南+MA3LPDQ UPC:4894680033429 Remark: 1）包装日期码按ZURU格式即可，请确保不迟于外箱日期码，可等于或者早于外箱日期码，必须为法定工作日，印刷前请先检查外箱日期码。 2）订单出英国，请注意检查产品及包装应带UKCA图标（14+产品除外），包装显示ZURU UK LTD/ZURU France地址信息，QC部门请查核，如有问题与跟单确认 3）订单必须经过ZURU QC验货并且通过后方可出货 4) 需要符合欧洲标准不能含有闪粉和微塑料，否则不和法规会有客诉产生 | V22: Sheba Ye | W22: 1.54 | X22: =W22*I22 -> 3850 | Y22: 84788-5.17 | Z22: 77555GQ2-S001-3L | AA22: 已入 | AB22: 系统出单 | AC22: 2500 | AD22: =AC22-I22 -> 0 | AE22: ok | AF22: 可接受 | AG22: A | AH22: =I22 -> 2500 | AK22: =I22 -> 2500 | AS22: =I22 -> 2500 | BH22: =I22/25 -> 100
A23: 45358 | B23: KMART AUSTRALIA LTD(NEW ZEALAND) | C23: 新西兰 | D23: 4500126301 | E23: 19961307 | F23: 4500126301-10 | G23: 77555GQ1-S002 | H23: 迷你房子GQ1/13PCS/箱 | I23: 1001 | J23: 0 | K23: 13 | L23: =I23/K23 -> 77 | M23: 45397 | N23: 45393 | P23: pass | R23: 45369 | S23: 有 | T23: 3/25箱唛贴纸 防盗贴纸翻单125858 | U23: 日期码格式：ZURU INC(BVI) 标准格式 日期：按实际生产日期 Packaging Info: 77555GQ1:MA英语UPC版本包装（首选1LUPC，如果无1L可用多语含英语UPC版本）+防盗贴纸+箱唛+箱唛贴纸(1PCS/CTN).防盗贴纸及其位置图请跟回PO#4500125858; Remark: 1,请务必按时完货，验货并请按期送货入货代指定仓库，如果晚了导致船期Delay将会有罚金产生或者客户要求空运，所产生的罚金和空运费由工厂承担。 2.SSCC 外箱贴纸请同纸箱瓦楞纸方向（竖纹向）垂直，即外箱贴纸横着贴(注意条码不要被胶带粘住），贴1pc，贴1面正唛，封箱胶纸不能挡住贴纸内容。每pcs外 箱贴纸都是唯一的，不可重复粘贴，否则会有罚款产生。 3.外箱材质为ZURU标准； 4.此单需使用KMART封箱胶上下工字型封箱;从2019年6月开始，要用KMART 新版封箱胶带，此单要用"ANKO"封箱胶带 5.此单出口新西兰，请按相应的澳新标准生产； 6.产品和包装上生产批号的显示格式ZURU标准日期码格式 7.77555GQ1先以FCL下单，实际出货方式为LCL | V23: Sara Wang | W23: 1.55 | X23: =W23*I23 -> 1551.55 | Y23: 84794-5.17 | Z23: 77555GQ1-S002 | AA23: 已入 | AB23: 系统出单 | AC23: 1001 | AD23: =AC23-I23 -> 0 | AE23: ok | AG23: A | AH23: =I23 -> 1001 | AJ23: =I23 -> 1001 | AS23: =I23 -> 1001 | BC23: =I23/13 -> 77
A24: 45358 | B24: KMART AUSTRALIA LTD | C24: 澳大利亚 | D24: 4500126300 | E24: 19949063 | F24: 4500126300-10 | G24: 77555GQ1-S002 | H24: 迷你房子GQ1/13PCS/箱 | I24: 2574 | J24: 0 | K24: 13 | L24: =I24/K24 -> 198 | M24: 45397 | N24: 45393 | P24: pass | R24: 45369 | S24: 有 | T24: 3/25箱唛贴纸 防盗贴纸翻单125858 | U24: 日期码格式：ZURU INC(BVI) 标准格式 日期：按实际生产日期 Packaging Info: 77555GQ1:MA英语UPC版本包装（首选1LUPC，如果无1L可用多语含英语UPC版本）+防盗贴纸+箱唛+箱唛贴纸(1PCS/CTN).防盗贴纸及其位置图请跟回PO#4500125858; Remark: 1,请务必按时完货，验货并请按期送货入货代指定仓库，如果晚了导致船期Delay将会有罚金产生或者客户要求空运，所产生的罚金和空运费由工厂承担。 2.SSCC 外箱贴纸请同纸箱瓦楞纸方向（竖纹向）垂直，即外箱贴纸横着贴(注意条码不要被胶带粘住），贴1pc，贴1面正唛，封箱胶纸不能挡住贴纸内容。每pcs外 箱贴纸都是唯一的，不可重复粘贴，否则会有罚款产生。 3.外箱材质为ZURU标准； 4.此单需使用KMART封箱胶上下工字型封箱;从2019年6月开始，要用KMART 新版封箱胶带，此单要用"ANKO"封箱胶带 5.此单出口澳大利亚，请按相应的澳新标准生产； 6.产品和包装上生产批号的显示格式ZURU标准日期码格式 7.77555GQ1先以FCL下单，实际出货方式为LCL | V24: Sara Wang | W24: 1.55 | X24: =W24*I24 -> 3989.7 | Y24: 84793-5.17 | Z24: 77555GQ1-S002 | AA24: 已入 | AB24: 系统出单 | AC24: 2574 | AD24: =AC24-I24 -> 0 | AE24: ok | AG24: A | AH24: =I24 -> 2574 | AJ24: =I24 -> 2574 | AS24: =I24 -> 2574 | BC24: =I24/13 -> 198
A25: 45358 | B25: KMART AUSTRALIA LTD | C25: 澳大利亚 | D25: 4500126300 | E25: 19961306 | F25: 4500126300-20 | G25: 77555GQ1-S002 | H25: 迷你房子GQ1/13PCS/箱 | I25: 3679 | J25: 0 | K25: 13 | L25: =I25/K25 -> 283 | M25: 45397 | N25: 45393 | P25: pass | R25: 45369 | S25: 有 | T25: 3/25箱唛贴纸 防盗贴纸翻单125858 | U25: 日期码格式：ZURU INC(BVI) 标准格式 日期：按实际生产日期 Packaging Info: 77555GQ1:MA英语UPC版本包装（首选1LUPC，如果无1L可用多语含英语UPC版本）+防盗贴纸+箱唛+箱唛贴纸(1PCS/CTN).防盗贴纸及其位置图请跟回PO#4500125858; Remark: 1,请务必按时完货，验货并请按期送货入货代指定仓库，如果晚了导致船期Delay将会有罚金产生或者客户要求空运，所产生的罚金和空运费由工厂承担。 2.SSCC 外箱贴纸请同纸箱瓦楞纸方向（竖纹向）垂直，即外箱贴纸横着贴(注意条码不要被胶带粘住），贴1pc，贴1面正唛，封箱胶纸不能挡住贴纸内容。每pcs外 箱贴纸都是唯一的，不可重复粘贴，否则会有罚款产生。 3.外箱材质为ZURU标准； 4.此单需使用KMART封箱胶上下工字型封箱;从2019年6月开始，要用KMART 新版封箱胶带，此单要用"ANKO"封箱胶带 5.此单出口澳大利亚，请按相应的澳新标准生产； 6.产品和包装上生产批号的显示格式ZURU标准日期码格式 7.77555GQ1先以FCL下单，实际出货方式为LCL | V25: Sara Wang | W25: 1.55 | X25: =W25*I25 -> 5702.45 | Y25: 84793-5.17 | Z25: 77555GQ1-S002 | AA25: 已入 | AB25: 系统出单 | AC25: 3679 | AD25: =AC25-I25 -> 0 | AE25: ok | AG25: A | AH25: =I25 -> 3679 | AJ25: =I25 -> 3679 | AS25: =I25 -> 3679 | BC25: =I25/13 -> 283
A26: 45356 | B26: Zuru Germany GMBH | C26: 德国 | D26: 4500126061 | E26: 5200004188 | F26: 4500126061-60 | G26: 77555GQ1-S002-MTS | H26: 迷你房子GQ1/13PCS/箱 | I26: 4810 | J26: 0 | K26: 13 | L26: =I26/K26 -> 370 | M26: 45398 | N26: 45394 | P26: pass | Q26: 4/28 交仓 | R26: 45358 | S26: 无 | T26: 3/12环保标贴纸 | U26: 日期码格式：ZURU INC(BVI) 标准格式 日期：按实际生产日期 Packaging Info: 6.77555GQ1：MA 3L EAN版本收缩膜+一张法国和意大利环保标贴纸+MA 5L A版收藏指南； Remark: 1.德国内销单，ZURU 验货后即可出货； 2.外箱EAN 14 条码参考： 6.77555GQ1：30193052064265 3.所有出口欧洲的产品, 法规规定禁止在包装和共公众用的印刷品中使用矿物油中含有的物质, 包装印刷油墨中含有的MOAH/MOSH的质量浓度不能超过1%, 否则出货 到法国被抽检出现问题, 供应商需要对此负责; 4. date code: 外箱/产品/包装 保持一致，完货后提供date code 信息以便我们保存记录做批次管理； | V26: SD45 | W26: 1.55 | X26: =W26*I26 -> 7455.5 | Y26: 84902-5.25 | Z26: 77555GQ1-S002-3L | AA26: 已入 | AB26: 系统出单 | AC26: 4810 | AD26: =AC26-I26 -> 0 | AE26: ok | AF26: 可接受 | AG26: 跟单同意用A版本 | AH26: =I26 -> 4810 | AK26: =I26 -> 4810 | AS26: =I26 -> 4810 | BE26: =I26/13 -> 370
A27: 45364 | B27: Multihexa Sdn Bhd | C27: 马来西亚 | D27: 4500126802 | F27: 4500126802-80 | G27: 77555GQ2-S001 | H27: 迷你房子25pcsGQ2*2/箱 | I27: 3000 | J27: 0 | K27: 50 | L27: =I27/K27 -> 60 | M27: 45401 | N27: 45397 | P27: pass | Q27: 4/25 截SI | R27: 45371 | S27: 无 | T27: 45373 | U27: 日期码格式：ZURU INC(BVI) 标准格式 日期：按实际生产日期 Packaging Info: 1.MA UPC包装（优先1L)+1张进口商贴纸 77555GQ2-贴纸AW、位置图待提供 Remark: 77555GQ2-Contains UV Glue | V27: Emma Wu | W27: 1.54 | X27: =W27*I27 -> 4620 | Y27: 84876-2-5.22 | Z27: 77555GQ2-S001 | AA27: 已入 | AB27: 系统出单 | AC27: 3000 | AD27: =AC27-I27 -> 0 | AE27: OK | AG27: A | AH27: =I27 -> 3000 | AJ27: =I27 -> 3000 | AS27: =I27 -> 3000 | BF27: =I27/25 -> 120
A28: 45362 | B28: TARGET AUSTRALIA PTY LTD | C28: 澳大利亚 | D28: 4500125613 | E28: 2342413 | F28: 4500125613-50 | G28: 77555GQ1-S002 | H28: 迷你房子GQ1/13PCS/箱 | I28: 3211 | J28: 0 | K28: 13 | L28: =I28/K28 -> 247 | M28: 45404 | N28: 45400 | P28: PASS | Q28: 4/25入仓 | R28: 45376 | S28: 有 | T28: 4/3外箱贴纸 | U28: 日期码格式：ZURU INC(BVI) 标准格式 日期：按实际生产日期 Packaging Info: 1.77555GQ1:MA英语UPC 版本包装 (优先1L，如无1L，可用3L),箱唛+外箱贴纸 Remark: 1.客人要求箱唛不可出现手写内容（流水号除外），箱唛印的重量和实际差异不超3%，且不可手写; 2.此单去澳大利亚，请按相应澳新标准生产; 3.使用TARGET客版封箱胶封顶，顶部两侧以及底部均用普通封箱胶，工字型封箱 4.外箱需要贴客户的SSCC LABEL，SSCC LABEL 由ZURU在货期前两周提供文档,由工厂订购，请贴在正唛右下角（封箱胶纸不能挡住贴纸内容。）； 5.产品和包装上要有tracking label信息：格式为Zuru标准格式（可以自行调整具体年月日生产日期,避开节假期日） 6.请务必按时完货，验货PASS后请按时送货入货代指定仓库，如果晚了导致船期Delay将会有罚金产生或者客户要求空运，所产生的罚金和空运费由工厂承担 7.Ratio： 77555GQ1先以FCL下单，实际出货方式为LCL | V28: Sara Wang | W28: 1.55 | X28: =W28*L28 -> 382.85 | Y28: 84922-5.25 | Z28: 77555GQ1-S002 | AA28: 已入 | AB28: 系统出单 | AC28: 3211 | AD28: =AC28-I28 -> 0 | AE28: ok | AG28: A | AH28: =I28 -> 3211 | AJ28: =I28 -> 3211 | AS28: =I28 -> 3211 | BC28: =I28/13 -> 247
A29: 45363 | B29: KMART AUSTRALIA LTD | C29: 澳大利亚 | D29: 4500126567 | E29: 19949064 | F29: 4500126567-40 | G29: 77555GQ1-S002 | H29: 迷你房子GQ1/13PCS/箱 | I29: 3432 | J29: 0 | K29: 13 | L29: =I29/K29 -> 264 | M29: 45404 | N29: 45400 | P29: PASS | Q29: 4月23日-4月26日交仓 | R29: 45377 | S29: 有 | T29: 4/3箱唛贴纸 防盗贴纸翻单125858 | U29: 日期码格式：ZURU INC(BVI) 标准格式 日期：按实际生产日期 Packaging Info: 1.77555GQ1:MA英语UPC版本包装（首选1LUPC，如果无1L可用多语含英语UPC版本）+防盗贴纸+箱唛+箱唛贴纸(1PCS /CTN).77555GQ1防盗贴纸及其位置图请跟回PO#4500125858; Remark: 1,请务必按时完货，验货并请按期送货入货代指定仓库，如果晚了导致船期Delay将会有罚金产生或者客户要求空运，所产生的罚金和空运费由工厂承担。 2.SSCC 外箱贴纸请同纸箱瓦楞纸方向（竖纹向）垂直，即外箱贴纸横着贴(注意条码不要被胶带粘住），贴1pc，贴1面正唛，封箱胶纸不能挡住贴纸内容。每pcs外 箱贴纸都是唯一的，不可重复粘贴，否则会有罚款产生。 3.外箱材质为ZURU标准； 4.此单需使用KMART封箱胶上下工字型封箱;从2019年6月开始，要用KMART 新版封箱胶带，此单要用"ANKO"封箱胶带 5.此单出口澳大利亚，请按相应的澳新标准生产； 6.产品和包装上生产批号的显示格式ZURU标准日期码格式 7.RATIO: 8.77555GQ1:先以FCL下单，实际出货方式为LCL | V29: Sara Wang | W29: 1.55 | X29: =W29*I29 -> 5319.6 | Y29: 84919-5.25 | Z29: 77555GQ1-S002 | AA29: 已入 | AB29: 系统出单 | AC29: 3432 | AD29: =AC29-I29 -> 0 | AE29: ok | AG29: A | AH29: =I29 -> 3432 | AJ29: =I29 -> 3432 | AS29: =I29 -> 3432 | BC29: =I29/13 -> 264
A30: 45351 | B30: THE FARMERS' TRADING COMPANY LIMITE | C30: 新西兰 | D30: 4500125725 | F30: 4500125725-10 | G30: 77555GQ1-S002 | H30: 迷你房子GQ1/13PCS/箱 | I30: 1950 | J30: 0 | K30: 13 | L30: =I30/K30 -> 150 | M30: 45405 | N30: 45401 | P30: PASS | R30: 45359 | S30: 无 | T30: 3/19价格贴纸 | U30: 日期码格式：ZURU INC(BVI) 标准格式 日期：按实际生产日期 Packaging Info: 1.MA PKG，优先1 L+可移材质价格贴纸 Remark: Contains UV Glue | V30: Coral Wu | W30: 1.55 | X30: =W30*I30 -> 3022.5 | Y30: 84790-5.17 | Z30: 77555GQ1-S002 | AA30: 已入 | AB30: 系统出单 | AC30: 1950 | AD30: =AC30-I30 -> 0 | AE30: ok | AG30: A | AH30: =I30 -> 1950 | AJ30: =I30 -> 1950 | AS30: =I30 -> 1950 | BC30: =I30/13 -> 150
A31: 45322 | B31: MTA Trade | C31: 哈萨克斯坦 | D31: 4500124111 | F31: 4500124111-10 | G31: 77555GQ1-S001 | H31: 迷你房子 | I31: 13104 | J31: 0 | K31: 52 | L31: =I31/K31 -> 252 | M31: 45405 | N31: =M31-4 -> 45401 | P31: PASS | Q31: 4/24走货 | R31: 45327 | S31: 无 | T31: 45327 | U31: 日期码格式：ZURU INC(BVI) 标准格式 日期：按实际生产日期 Packaging Info: 1. 1L MA 最新收缩膜+ 进口商贴纸， MA 指南。 Remark: | V31: Ann Zhang | W31: 1.5 | X31: =W31*I31 -> 19656 | Y31: 84743-5.14 | Z31: 77555GQ1-S001 | AA31: 已入 | AB31: 系统出单 | AC31: 13104 | AD31: =AC31-I31 -> 0 | AE31: ok | AG31: A | AH31: =I31 -> 13104 | AJ31: =I31 -> 13104 | AS31: =I31 -> 13104 | BC31: =I31/13 -> 1008
A32: 45364 | B32: SMYTHS TOYS HQ UC | C32: 法国 | D32: 4500126738 | E32: 236396 | F32: 4500126738-10 | G32: 77555GQ2-S001 | H32: 迷你房子25pcsGQ2*2/箱 | I32: 3500 | J32: 0 | K32: 50 | L32: =I32/K32 -> 70 | M32: 45405 | N32: =M32-4 -> 45401 | P32: pass | Q32: 4/23截SI | R32: 45365 | S32: 无 | T32: 贴纸翻单125672 | U32: 日期码格式：ZURU INC(BVI) 标准格式 日期：按实际生产日期 Packaging Info: 1.77555GQ2:MA 3L 收缩膜+1张德国CALLOUT<(>&<)>荷兰警告语贴纸(含法国回收logo)翻4500125672+MA 3L PDQ Remark: 1、此单出法国，所有包装都需要含有法语<(>&<)>法国回收logo, 需要满足Zuru Standard欧洲标准测试要求； 2、请准时出货，推期会有罚款； 3、出法国的产品需不含微塑料； 4、有出口法国的产品, 法规规定禁止在包装和公众用的印刷品中使用含有矿物油的物质，包装印刷油墨中含有的MOAH/MOSH的质量浓度不能超过1%, 否则出货到法 国被抽检出现问题, 供应商需要对此负责。 | V32: Ula Zhao | W32: 1.54 | X32: =W32*I32 -> 5390 | Y32: 84964-5.28 | Z32: 77555GQ2-S001-3L | AA32: 已入 | AB32: 系统出单 | AC32: 3500 | AD32: =AC32-I32 -> 0 | AE32: ok | AF32: 可接受 | AG32: A | AH32: =I32 -> 3500 | AK32: =I32 -> 3500 | AS32: =I32 -> 3500 | BH32: =I32/25 -> 140
A33: 45365 | B33: KMART AUSTRALIA LTD(NEW ZEALAND) | C33: 新西兰 | D33: 4500126643 | E33: 19972864 | F33: 4500126643-20 | G33: 77555GQ1-S002 | H33: 迷你房子GQ1/13PCS/箱 | I33: 754 | J33: 0 | K33: 13 | L33: =I33/K33 -> 58 | M33: 45406 | N33: 45402 | P33: pass | Q33: 4/29交仓 | R33: 45377 | S33: 有 | T33: 4/3箱唛贴纸 防盗贴纸翻单125858 | U33: 日期码格式：ZURU INC(BVI) 标准格式 日期：按实际生产日期 Packaging Info: 2.77555GQ1:MA英语UPC版本包装（首选1LUPC，如果无1L可用多语含英语UPC版本）+防盗贴纸+箱唛+箱唛贴纸(1PCS/CTN);77555GQ1防盗贴纸及位置图跟 回PO#4500125858; Remark: 1,请务必按时完货，验货并请按期送货入货代指定仓库，如果晚了导致船期Delay将会有罚金产生或者客户要求空运，所产生的罚金和空运费由工厂承担。 2.SSCC 外箱贴纸请同纸箱瓦楞纸方向（竖纹向）垂直，即外箱贴纸横着贴(注意条码不要被胶带粘住），贴1pc，贴1面正唛，封箱胶纸不能挡住贴纸内容。每pcs外 箱贴纸都是唯一的，不可重复粘贴，否则会有罚款产生。 3.外箱材质为ZURU标准； 4.此单需使用KMART封箱胶上下工字型封箱;从2019年6月开始，要用KMART 新版封箱胶带，此单要用"ANKO"封箱胶带 5.此单出口新西兰，请按相应的澳新标准生产； 6.产品和包装上生产批号的显示格式ZURU标准日期码格式 7.RATIO: 77515GQ1-S003:3PCS AG13 Batteries(Included); | V33: Sara Wang | W33: 1.55 | X33: =W33*I33 -> 1168.7 | Y33: 84785-5.17 | Z33: 77555GQ1-S002 | AA33: 已入 | AB33: 系统出单 | AC33: 754 | AD33: =AC33-I33 -> 0 | AE33: ok | AG33: A | AH33: =I33 -> 754 | AJ33: =I33 -> 754 | AS33: =I33 -> 754 | BC33: =I33/13 -> 58
A34: 45362 | B34: WAL-MART CANADA CORP. | C34: 加拿大 | D34: 4500126515 | E34: 2300874228 | F34: 4500126515-30 | G34: 77555GQ2-S002 | H34: 迷你房子 | I34: 15050 | J34: 0 | K34: 25 | L34: =I34/K34 -> 602 | M34: 45406 | N34: 45402 | O34: 4/24抽办10% | P34: pass | Q34: 5/24 截SI | R34: 45366 | S34: 无 | T34: 无 | U34: 日期码格式：ZURU INC(BVI) 标准格式 日期：按实际生产日期 Packaging Info: #77555GQ2: MA3L,PDQ(25装)+客版3L,UPC条码收缩膜(UPC: 193052064264)+MA5L收藏指南 Remark: 2. 带电池的产品需使用英法双语电池(纽扣电池除外)； 3. 此单有箱唛; 4. 此单需要第三方验货，烦请多备包装物; 5. 此单需安排大货样进行签办，样品数量见下： - #77555GQ2: 2pcsPDQ+3pcs大货球+2套光身办； 6. 此单##77555,2024/4/24需安排抽办进行产中测试；抽办数量：#77555: 各4pcs大货球+4套光身办； ********************* a. 请确保产品符合1999年版本的加拿大环境保护法(CEPA)和2012年禁止某些有毒物质法规的要求。该产品不含任何在加拿大禁用的化学物质，包括但不限于有毒物 质清单中列出的化学物质，并且在为加拿大沃尔玛生产产品期间没有使用任何禁用化学物质。 Supplier certify that the products comply with the requirements of Canadian Environmental Protection Act, 1999 (CEPA), Prohibition of Certain To xic Substances Regulations, 2012. The products do not contain any chemicals that are banned in Canada, including but not limited to those listed in the Toxic Substances List and no banned chemicals were used during the manufacturing of product for Walmart Canada. 附件列表： (1) Letter of Guarantee for Canada banned chemicals - (1-5CA) b. 请确保产品在均质材料中的汞浓度不超过0.1%（按重量计）。 Supplier certify that the WAL-MART vendor products does not have a mercury concentration of more than 0.1% by weight in homogeneous material. 附件列表： (1) Letter of Guarantee for Mercury COC c. 请确保产品的塑料材料不含以下物质（SOR 2011-17 27B): Supplier certify that the plastic materials do not contain the following substances(SOR 2011-17 27B): (a) carbon tetrachloride or any substance that contains it; (b) methyl alcohol or any substance thay contains >1.0%; (c) petroleum distillates or any substance that contains >10% weight to volume of petroleum distillates; (d) benzene; (e) turpentine or any substance that contains >10% weight to volume of turpentine; (f) boric acid or salts of boric acid; or (g) ethyl ether. 附件列表： (1) Letter of Guarantee for WM CA-Other prohibited substances in plastic(less than 3 years) | V34: Monica Zhou | W34: 1.59 | X34: =W34*I34 -> 23929.5 | Y34: 84951-5.27 | Z34: 77555GQ2-S002-3L-CA | AA34: 已入 | AB34: 系统出单 | AC34: 15050 | AD34: =AC34-I34 -> 0 | AE34: 无 | AF34: NO | AG34: A | AH34: =I34 -> 15050 | AP34: =I34 -> 15050 | AS34: =I34 -> 15050 | BH34: =I34/25 -> 602
A35: 45365 | B35: KMART AUSTRALIA LTD | C35: 澳大利亚 | D35: 4500126609 | E35: 19972863 | F35: 4500126609-40 | G35: 77555GQ1-S002 | H35: 迷你房子GQ1/13PCS/箱 | I35: 8346 | J35: 0 | K35: 13 | L35: =I35/K35 -> 642 | M35: 45406 | N35: 45402 | P35: pass | Q35: 4/29交仓 | R35: 45377 | S35: 有 | T35: 4/3箱唛贴纸 防盗贴纸翻单125858 | U35: 日期码格式：ZURU INC(BVI) 标准格式 日期：按实际生产日期 Packaging Info: 1.77555GQ1:MA英语UPC版本包装（首选1LUPC，如果无1L可用多语含英语UPC版本）+防盗贴纸+箱唛+箱唛贴纸(1PCS /CTN);77555GQ1防盗贴纸及位置图跟回PO#4500125858; Remark: 1,请务必按时完货，验货并请按期送货入货代指定仓库，如果晚了导致船期Delay将会有罚金产生或者客户要求空运，所产生的罚金和空运费由工厂承担。 2.SSCC 外箱贴纸请同纸箱瓦楞纸方向（竖纹向）垂直，即外箱贴纸横着贴(注意条码不要被胶带粘住），贴1pc，贴1面正唛，封箱胶纸不能挡住贴纸内容。每pcs外 箱贴纸都是唯一的，不可重复粘贴，否则会有罚款产生。 3.外箱材质为ZURU标准； 4.此单需使用KMART封箱胶上下工字型封箱;从2019年6月开始，要用KMART 新版封箱胶带，此单要用"ANKO"封箱胶带 5.此单出口澳大利亚，请按相应的澳新标准生产； 6.产品和包装上生产批号的显示格式ZURU标准日期码格式 7.RATIO: | V35: Sara Wang | W35: 1.55 | X35: =W35*I35 -> 12936.3 | Y35: 84783-2-5.17 | Z35: 77555GQ1-S002 | AA35: 已入 | AB35: 系统出单 | AC35: 8346 | AD35: =AC35-I35 -> 0 | AE35: ok | AG35: A | AH35: =I35 -> 8346 | AJ35: =I35 -> 8346 | AS35: =I35 -> 8346 | BC35: =I35/13 -> 642
A36: 45343 | B36: UPD, INC. | C36: 美国 | D36: 4500124932 | E36: 32275 | F36: 4500124932-20 | G36: 77555GQ2-S001 | H36: 迷你房子25pcsGQ2*2/箱 | I36: 4500 | J36: 0 | K36: 50 | L36: =I36/K36 -> 90 | M36: 45408 | N36: 45404 | P36: pass | Q36: 4/30 截SI | R36: 45345 | S36: 无 | T36: 无 | U36: 日期码格式：ZURU INC(BVI) 标准格式 日期：按实际生产日期 Packaging Info: 1. 包装方式：MA UPC 优先1L 最新包装，出口美国 Remark: 2. 外箱箱唛红色和黑色双色印刷 3. 产品和包装上印刷tracking code信息，格式为ZURU常规 | V36: Iris.yuan | W36: 1.54 | X36: =W36*I36 -> 6930 | Y36: 84787-5.17 | Z36: 77555GQ2-S001 | AA36: 已入 | AB36: 系统出单 | AC36: 4500 | AD36: =AC36-I36 -> 0 | AE36: 无 | AG36: A | AH36: =I36 -> 4500 | AJ36: =I36 -> 4500 | AS36: =I36 -> 4500 | BF36: =I36/25 -> 180
A37: 45366 | B37: Zuru Germany GMBH | C37: 德国 | D37: 4500126972 | E37: 5200004262 | F37: 4500126972-10 | G37: 77555SK1-S002-MTS | H37: 迷你房子展示架 | I37: 3000 | J37: 0 | K37: 30 | L37: =I37/K37 -> 100 | M37: 45402 | N37: 45407 | P37: pass | Q37: 4/26 截SI | R37: 45366 | S37: 无 | T37: 贴纸翻单 | U37: 日期码格式：ZURU INC(BVI) 标准格式 日期：按实际生产日期 Packaging Info: 1.77555SK1：MA 3L 展示架+MA 3L+5L Warnign-A 版EAN 收缩膜+一张意大利环保标贴纸（翻单4500126061）+MA 5L收藏指南； Remark: "1.德国内销单，ZURU 验货后即可出货； 2.外箱EAN 14 条码参考： 77555SK1：40193052064262 3.所有出口欧洲的产品, 法规规定禁止在包装和共公众用的印刷品中使用矿物油中含有的物质, 包装印刷油墨中含有的MOAH/MOSH的质量浓度不能超过1%, 否则出货 到法国被抽检出现问题, 供应商需要对此负责; 4. date code: 外箱/产品/包装 保持一致，完货后提供date code 信息以便我们保存记录做批次管理；" | V37: SD45 | W37: 56.598 | X37: =W37*L37 -> 5659.8 | Y37: 85032-5.31 | Z37: 77555SK1-S002-3L | AA37: 已入 | AB37: 系统出单 | AC37: 3000 | AD37: =AC37-I37 -> 0 | AE37: ok | AF37: 可接受 | AG37: 跟单同意用A版本 | AH37: =I37 -> 3000 | AK37: =I37 -> 3000 | AS37: =I37 -> 3000 | BN37: =I37/30 -> 100
A38: 45342 | B38: AMAZON UK | C38: 英国 | D38: 4500124874 | E38: 15NB9NCZ | F38: 4500124874-280 | G38: 77555-S001 | H38: 迷你房子 | I38: 888 | J38: 0 | K38: 24 | L38: =I38/K38 -> 37 | M38: 45412 | N38: 45408 | P38: pass | Q38: 5/12 截SI | R38: 空白外箱（加印带Zuru字样的最新logo | S38: 有 | T38: 3/28 SSCC | U38: 日期码格式：ZURU INC(BVI) 标准格式 日期：按实际生产日期 Packaging Info: Amazon UK: 4. 77555: 24 PCS/CTN; MA 1L A收缩膜+1张贴纸(含IT/FR sorting label+法德意西警告语)+MA 其他最新包装； 13. 验货时间不迟于2024/5/6； Remark: "1.空白外箱（加印带Zuru字样的最新logo，除了邮包盒直接做外箱的产品） + SSCC LABEL一张, 无箱唛. (SSCC LABEL贴在外箱正面的正中间，贴一面即可,贴纸离外箱边距必须至少3CM),SSCC贴纸由工厂直接跟勤得采购或者工厂自行采购，每一张SSCC Label都是唯一且 有不同流水及条码，且需要检查条码是否能正常扫描，另外，此贴纸印刷不可出现模糊，溢出及粘胶不牢易脱落等现象，如工厂不按此要求导致贴纸有任何问题产生 的罚款将由工厂承担一切责任 。’MADE IN CHINA 外箱只印一正一侧。 2. 出往UK的产品+包装务必打上UKCA logo ，否则客人会退货且当地会有罚款。 3.订单必须经过ZURU QC验货并且通过后方可出货。 4.法国订单要求包装不使用矿物油，请按要求提供以下其中一份文件再出货 ，产品出到法国被相关部门抽检出现包装不符合此要求的，供应商需要为此承担责任， 故此请严格把关 。 -油墨物质""由1 ~ 7个芳香环组成的MOAH""的包装检测报告，要求限值≤1.0%; -包装材料清单，包括包装油墨或物质的信息 -油墨制造商的证书。 5 . 每一批次出货只能有一个生产日期，不可多个生产日期混在同一批次出货； 6. 涉及到相关款式会有闪粉的或者微塑料的，请统一默认出无闪粉或者不含微塑料版本;" | V38: Crystal Chen | W38: 1.18 | X38: =W38*I38 -> 1047.84 | Y38: 84893-3-5.23 | Z38: 77555-S001 | AA38: 已入 | AB38: 系统出单 | AC38: 888 | AD38: =AC38-I38 -> 0 | AE38: OK | AG38: A | AH38: =I38 -> 888 | AJ38: =I38 -> 888 | AS38: =I38 -> 888
A39: 45356 | B39: Amazon EU SARL, Ndl Deutschland | C39: 德国 | D39: 4500125765 | E39: 86OS76HQ | F39: 4500125765-20 | G39: 77555-S001 | H39: 迷你房子 | I39: 648 | J39: 0 | K39: 24 | L39: =I39/K39 -> 27 | M39: 45412 | N39: 45408 | P39: pass | Q39: 5/12走货 | R39: 空白外箱（加印带Zuru字样的最新logo | S39: 有 | T39: 3/28 SSCC | U39: 日期码格式：ZURU INC(BVI) 标准格式 日期：按实际生产日期 Packaging Info: Amazon DE 2. 77555: 24 PCS/CTN; MA 1L A收缩膜+1张贴纸(含IT/FR sorting label+法德意西警告语)+MA 其他最新包装；参考翻单PO#4500124874; 15. 验货日期不得晚于2024/5/6 Remark: "1.空白外箱（加印带Zuru字样的最新logo，除了邮包盒直接做外箱的产品） + SSCC LABEL一张, 无箱唛. (SSCC LABEL贴在外箱正面的正中间，贴一面即可,贴纸离外箱边距必须至少3CM),SSCC贴纸由工厂直接跟勤得采购或者工厂自行采购，每一张SSCC Label都是唯一且 有不同流水及条码，且需要检查条码是否能正常扫描，另外，此贴纸印刷不可出现模糊，溢出及粘胶不牢易脱落等现象，如工厂不按此要求导致贴纸有任何问题产生 的罚款将由工厂承担一切责任 。’MADE IN CHINA 外箱只印一正一侧。 2. 出往UK的产品+包装务必打上UKCA logo ，否则客人会退货且当地会有罚款。 3.订单必须经过ZURU QC验货并且通过后方可出货。 4.法国订单要求包装不使用矿物油，请按要求提供以下其中一份文件再出货 ，产品出到法国被相关部门抽检出现包装不符合此要求的，供应商需要为此承担责任， 故此请严格把关 。 -油墨物质""由1 ~ 7个芳香环组成的MOAH""的包装检测报告，要求限值≤1.0%; -包装材料清单，包括包装油墨或物质的信息 -油墨制造商的证书。 5 . 每一批次出货只能有一个生产日期，不可多个生产日期混在同一批次出货； 6. 涉及到相关款式会有闪粉的或者微塑料的，请统一默认出无闪粉或者不含微塑料版本;" | V39: Crystal Chen | W39: 1.18 | X39: =W39*I39 -> 764.64 | Y39: 84892-5.23 | Z39: 77555-S001 | AA39: 已入 | AB39: 系统出单 | AC39: 648 | AD39: =AC39-I39 -> 0 | AE39: ok | AG39: B | AH39: =I39 -> 648 | AJ39: =I39 -> 648 | AS39: =I39 -> 648
A40: 45356 | B40: AMAZON FR | C40: 法国 | D40: 4500125756 | E40: 7DWFS9RB | F40: 4500125756-130 | G40: 77555-S001 | H40: 迷你房子 | I40: 624 | J40: 0 | K40: 24 | L40: =I40/K40 -> 26 | M40: 45412 | N40: 45408 | P40: pass | Q40: 5/12 截SI | R40: 空白外箱（加印带Zuru字样的最新logo | S40: 有 | T40: 3/28 SSCC | U40: 日期码格式： ZURU INC(BVI) 标准格式 日期：按实际生产日期 Packaging Info: Amazon FR: 13. 77555 2pcs/pvc tube, 12tubes/ctn; MA 1L A收缩膜+MA 其他最新包装+客版3L(5L warning)PVC tube彩卡+1张贴纸(含IT sorting label)；参考翻 单PO#4500124874; 14. 验货日期不得晚于2024/5/6 Remark: "1.空白外箱（加印带Zuru字样的最新logo，除了邮包盒直接做外箱的产品） + SSCC LABEL一张, 无箱唛. (SSCC LABEL贴在外箱正面的正中间，贴一面即可,贴纸离外箱边距必须至少3CM),SSCC贴纸由工厂直接跟勤得采购或者工厂自行采购，每一张SSCC Label都是唯一且 有不同流水及条码，且需要检查条码是否能正常扫描，另外，此贴纸印刷不可出现模糊，溢出及粘胶不牢易脱落等现象，如工厂不按此要求导致贴纸有任何问题产生 的罚款将由工厂承担一切责任 。’MADE IN CHINA 外箱只印一正一侧。 2. 出往UK的产品+包装务必打上UKCA logo ，否则客人会退货且当地会有罚款。 3.订单必须经过ZURU QC验货并且通过后方可出货。 4.法国订单要求包装不使用矿物油，请按要求提供以下其中一份文件再出货 ，产品出到法国被相关部门抽检出现包装不符合此要求的，供应商需要为此承担责任， 故此请严格把关 。 -油墨物质""由1 ~ 7个芳香环组成的MOAH""的包装检测报告，要求限值≤1.0%; -包装材料清单，包括包装油墨或物质的信息 -油墨制造商的证书。 5 . 每一批次出货只能有一个生产日期，不可多个生产日期混在同一批次出货； 6. 涉及到相关款式会有闪粉的或者微塑料的，请统一默认出无闪粉或者不含微塑料版本;" | V40: Crystal Chen | W40: 1.18 | X40: =W40*I40 -> 736.32 | Y40: 84996-2-5.29 | Z40: 77555-S001 | AA40: 已入 | AB40: 系统出单 | AC40: 624 | AD40: =AC40-I40 -> 0 | AE40: ok | AG40: A | AH40: =I40 -> 624 | AJ40: =I40 -> 624 | AS40: =I40 -> 624
...

Sheet 77555 迷你房子 旧排期
A1: ZURU （77555 迷你房子）生产排期表 | F1: 77555 MA 3LB版收缩膜，收藏指南，纸袋，GQ1，GQ2，小产品上的贴纸更新B版本，6.1号之后出加拿大的3L都需要双语logo，目前SK没有单就还没有更新 | AE1: 第一张MA是订购A版本，第二张MA订购B版本，A和B版本区别在于德语的警语不一样，A版本不能出德国
AI2: 收縮膜 | AX2: 134013 | AZ2: 收藏指南 | BG2: GQ6 | BH2: GQ6 | BI2: GQ4 | BJ2: FD GQ7 | BK2: GQ1 | BP2: GQ2 | BS2: GQ3 | BT2: SQ1 | BU2: 不带底座 | BV2: 3L | BW2: 1L | BX2: 3L | BY2: 77556 圆筒 | CC2: 77584 圆筒 | CL2: 总MA | CM2: ='生产MA '!S4 -> 5380000
A3: 香港接单日期 | B3: 第三方客户名称 | C3: 走货国家 | D3: ZURU PO NO# | E3: 第三方客户 PO NO# | F3: SKU | G3: ITEM# | H3: 中文名 | I3: PO数量 (pcs) | J3: 内箱装箱数量(pcs) | K3: 外箱装箱数量(pcs) | L3: 总箱数 | M3: 客PO期 | N3: 验货期 | O3: 第三方验货期 | P3: 驗貨結果 | Q3: S/0船期 | R3: 箱唛资料(收到日期) | S3: 外箱贴纸 | T3: 客供贴纸AI(收到日期) | U3: 备注 | V3: ZURU 跟单 | W3: 单价USD | X3: 金额USD | Y3: 發票號 | Z3: 系统货号 | AA3: 是否入系统 | AB3: 系统出单 | AC3: 送货情况 | AD3: 欠数 | AE3: 贴纸 | AG3: 球数 | AH3: 散件/空PDQ/空球壳 | AI3: MA 1语 | AJ3: MA 3语 | AK3: 1L-B版本 | AL3: 3L-B版本 | AM3: 无UPC版本 | AN3: DG 客版 | AO3: DG 新客版 | AP3: DG 更新客版 | AQ3: DG 更新-1客版 | AR3: DG 更新-2客版 | AS3: DG 更新-3客版 | AT3: DG 更新-4客版 | AU3: DG 更新-5客版 | AV3: TG客版 | AW3: WMCA客版 | AX3: MGS客版 | AY3: GP 客版 | AZ3: MA 5L语 | BA3: 5L-B版本 | BB3: 外挂收藏指南+中文说明书（每一款都不同，请做好区分） | BC3: wm us客版 | BD3: 韩语客版 | BE3: ESAL 客版 | BF3: GP 客版 | BG3: WMM 客版 | BH3: 取消UV胶版本 | BI3: 1L | BJ3: 客版 | BK3: 1L | BL3: 韩语客版 | BM3: 3L | BN3: 1L-B版本 | BO3: 3L-B版本 | BP3: 1L | BQ3: 1L-B版本 | BR3: 3L | BS3: 客版 | BT3: 客版 | BU3: 77555SK-S001 | BV3: SK-S002 60PCS | BW3: SK1-S002 30PCS | BX3: SK1-S002 30PCS | BY3: 圆筒 | BZ3: 铜板纸 | CA3: 新版铜版纸 | CB3: 贴纸 | CC3: 圆筒 | CD3: 铜板纸 | CE3: 新铜版纸 | CF3: 贴纸 | CL3: 已删减实单 | CM3: 2616809 | CN3: MA剩余 | CO3: =CM2-CM3 -> 2763191
A4: 45377 | B4: ZURU | C4: 库有 | D4: ZMPO24230 | G4: 77584-S001 | H4: 迷你房子*2 | I4: 6 | J4: 0 | K4: 12 | L4: =I4/K4 -> 0.5 | M4: 45392 | N4: 45388 | R4: 45377 | S4: 无 | T4: 无 | U4: 大货最新版本/UPC-193052066497 | V4: sally li | Z4: # | AA4: # | AC4: 6 | AD4: =AC4-I4 -> 0 | AI4: =I4*2 -> 12 | AZ4: =I4*2 -> 12 | CC4: =I4 -> 6 | CD4: =I4 -> 6 | CF4: =I4 -> 6 | CH4: 按单 | CO4: =CO3-AG4 -> 2763191
A5: 45428 | B5: ZURU | C5: 库有 | D5: ZMPO24385 | G5: 77555-S001 | H5: 迷你房子 | I5: 1000 | J5: 0 | K5: 24 | L5: =I5/K5 -> 41.666667 | M5: 45449 | N5: 45467 | P5: PASS | R5: 45428 | S5: 无 | T5: 无 | U5: 大货最新版本/款号数量平均/麻烦按款号装箱/并在外箱上注明款号/请用大货/箱唛请参照邮件附件；备注： 收到样品订单后尽快安排 ，注意样板品质质量要求要高于大货品质质量 ，送货时必须要附带送货单(没有送货单和QC检验合格报告的仓库一律拒绝收货)，请知悉，谢谢！ | Y5: 94391-2.27 | Z5: 77555-S001 | AA5: 已入 | AB5: 系统出单 | AC5: 1000 | AD5: =AC5-I5 -> 0 | AG5: =I5 -> 1000 | AI5: =I5 -> 1000 | AZ5: =I5 -> 1000 | CO5: =CO4-AG5 -> 2762191
A6: 45428 | B6: ZURU | C6: 库有 | D6: ZMPO24385 | G6: 77555-S001 | H6: 迷你房子 | I6: 100套散件 | J6: 0 | K6: 24 | L6: =I6/K6 -> #VALUE! | M6: 45449 | N6: 45467 | P6: 已送库有 | R6: 45428 | S6: 无 | T6: 无 | U6: 大货最新版本/只需要齐全套散件，麻烦用胶袋分装好一套为一袋；大货最新版本/只需要齐全套散件，麻烦用胶袋分装好一套为一袋 | Y6: 94391-2.27 | Z6: # | AA6: # | AC6: 100 | CO6: =CO5-AG6 -> 2762191
A7: 45491 | D7: ZMPO24559 | G7: 77555-S001 | H7: 迷你房子 | I7: 80套散件 | J7: 0 | K7: 24 | L7: =I7/K7 -> #VALUE! | M7: 45514 | N7: 45510 | P7: 已送库有 | R7: 7、18 | S7: 无 | T7: 无 | U7: 大货最新版本/只需要齐全套散件，麻烦用胶袋分装好一套为一袋；备注：收到样品订单后尽快安排 ，注意样板品质质量要求要高于大货品质要求 ，送货时必须要附带送货单(没有送货单和QC检验合格报告的仓库一律拒绝收货)，请知悉，谢谢！ | Y7: 94390-2.27 | Z7: # | AA7: # | AC7: 80 | AE7: 无 | CO7: =CO6-AG7 -> 2762191
A8: 45528 | B8: ZURU | C8: 库有 | D8: ZMPO24659 | G8: 77555-S001 | H8: 迷你房子 | I8: 60 | J8: 0 | K8: 24 | L8: =I8/K8 -> 2.5 | M8: 45559 | N8: 45555 | P8: 已送库有 | R8: 8、24 | S8: 无 | T8: 无 | U8: 大货最新版本/只需要齐全套散件，麻烦用胶袋分装好一套为一袋；备注： 收到样品订单后尽快安排 ，注意样板品质质量要求要高于大货品质质量 ，送货时必须要附带送货单(没有送货单和QC检验合格报告的仓库一律拒绝收货)，请知悉，谢谢！ | Y8: 94392-2.27 | Z8: # | AA8: # | AC8: 60 | AE8: 无 | CO8: =CO7-AG8 -> 2762191
A9: 45604 | B9: WAL-MART CANADA CORP. | C9: 加拿大 | D9: MPO03008 | E9: PO #4500150686 | G9: 77555-S001-MSLD118 | H9: 迷你房子-此款展示架Demo与展示架 MSLD96相同 配套387pcs | I9: 18144 | J9: 0 | K9: 24 | L9: =I9/K9 -> 756 | M9: 45632 | N9: 45628 | P9: PASS | Q9: 12/19 送库有 | R9: 周转箱 | S9: 无 | T9: 无 | U9: Remark: 1.#77555: 客版3L收缩膜(UPC: 193052064264)+MA5L收藏指南+MA配件袋+MA5L,UV胶水贴纸+MA23L说明书——客版收缩膜翻单PO: 4500126515； 2.Demo: 按照每款387pcs数量配套组装好交货 | V9: Willow Xu/Monica Zhou | W9: 0.8173 | X9: =W9*I9 -> 14829.091 | Y9: 94205-2.10 | Z9: 77555-S001-MSLD118 | AA9: 已入 | AB9: 系统出单 | AC9: =9720+8424 -> 18144 | AD9: =AC9-I9 -> 0 | AE9: 无 | AG9: =I9 -> 18144 | AW9: =I9 -> 18144 | AZ9: =I9 -> 18144 | CO9: =CO8-AG9 -> 2744047
A10: 45629 | D10: ZMPO24903 | G10: 77555SK1-S002 | H10: 迷你房子展示架 | I10: 1套空展示架 | J10: 0 | K10: 30 | L10: =I10/K10 -> #VALUE! | M10: 45632 | N10: 45628 | P10: 已寄出 | R10: 无 | S10: 无 | T10: 无 | U10: Remark：大货最新版本/麻烦配齐展示架上应有的物料（如展示架Demo+吸塑等物料） 备注： 收到样品订单后尽快安排 ，注意样板品质质量要求要高于大货品质质量 ，送货时必须要附带送货单(没有送货单和QC检验合格报告的仓库一律拒绝收货)，请知悉，谢谢！ | V10: Angus | Y10: 七 | Z10: # | AA10: # | CO10: =CO9-AG10 -> 2744047
A11: 45593 | B11: Miniso Depot CA Inc. | C11: 美国 | D11: 4500149149 | E11: 4333541366 | F11: 4500149149-20 | G11: 77555GQ2-S002 | H11: 迷你房子 | I11: 7100 | J11: 0 | K11: 25 | L11: =I11/K11 -> 284 | M11: 45645 | N11: 45642 | P11: pass | Q11: 1/3 截SI | R11: 45614 | S11: 无 | T11: UPC 条码贴纸翻单4500140602 | U11: 日期码格式：ZURU INC(BVI) 标准格式 日期：按实际生产日期 Packaging Info: 1. 包装方式：MA UPC 优先1L 最新包装，出口美国； 2. 产品和包装上印刷tracking code信息，格式为ZURU常规. Remark: 1.#77555GQ2-S002 PDQ上需要贴一张UPC 条码贴纸, UPC显示：193052064264；翻单4500140602，工厂自行采购； | V11: Iris Yuan | W11: 0.9082 | X11: =W11*I11 -> 6448.22 | Y11: 94158-1.23 | Z11: 77555GQ2-S002 | AA11: 已入 | AB11: 系统出单 | AC11: 7100 | AD11: =AC11-I11 -> 0 | AE11: ok | AG11: =I11 -> 7100 | AI11: =I11 -> 7100 | AZ11: =I11 -> 7100 | BP11: =I11/25 -> 284 | CO11: =CO10-AG11 -> 2736947
A12: 45593 | B12: Miniso Depot CA Inc. | C12: 美国 | D12: 4500149149 | E12: 4333541367 | F12: 4500149149-40 | G12: 77555GQ2-S002 | H12: 迷你房子 | I12: 6550 | J12: 0 | K12: 25 | L12: =I12/K12 -> 262 | M12: 45645 | N12: 45642 | P12: pass | Q12: 1/6 截SI | R12: 45614 | S12: 无 | T12: UPC 条码贴纸翻单4500140602 | U12: 日期码格式：ZURU INC(BVI) 标准格式 日期：按实际生产日期 Packaging Info: 1. 包装方式：MA UPC 优先1L 最新包装，出口美国； 2. 产品和包装上印刷tracking code信息，格式为ZURU常规. Remark: 1.#77555GQ2-S002 PDQ上需要贴一张UPC 条码贴纸, UPC显示：193052064264；翻单4500140602，工厂自行采购； | V12: Iris Yuan | W12: 0.9265 | X12: =W12*I12 -> 6068.575 | Y12: 94158-1.23 | Z12: 77555GQ2-S002 | AA12: 已入 | AB12: 系统出单 | AC12: 6550 | AD12: =AC12-I12 -> 0 | AE12: ok | AG12: =I12 -> 6550 | AI12: =I12 -> 6550 | AZ12: =I12 -> 6550 | BP12: =I12/25 -> 262 | CO12: =CO11-AG12 -> 2730397
A13: 45604 | B13: AMAZON.COM.DEDC,LLC | C13: 美国 | D13: 4500150761 | E13: 2R58Q8TS | F13: 4500150761-40 | G13: 77555-S001 | H13: 迷你房子 | I13: 1104 | J13: 0 | K13: 24 | L13: =I13/K13 -> 46 | M13: 45650 | N13: 45646 | P13: pass | Q13: 1/2 截SI | R13: 45604 | S13: 有 | T13: 12/2 SSCC Label | U13: 日期码格式：ZURU INC(BVI) 标准格式 日期：按实际生产日期 Packaging Info: #77555：MA1L 收缩膜+5L收藏指南。 Remark: 1. Amazon FOB订单，出口US。 2. 日期码使用ZURU标准版本。 3. 如果大货有要求入邮包盒，则对应的邮包盒上面要打上日期码。 4. 箱尺寸要求：外箱最长边不能超过25" （超过了，case pack只能为1），不符合要求的大货，一律不接受。 5. 外箱箱唛要求： ①外箱正面印ZURU Logo+SSCC Label（客供贴纸，由跟单订购)。关于 SSCC Label 请注意： SSCC Label 显示的是客人自己的item#。每一张SSCC label 都是唯一且有不同流水及条码的，没有损耗，绝对不可贴错 。如果贴错或损坏任何一张，都会导致全 部都错，千万要注意！ SSCC Label 必须贴在外箱正面的正中间位置（贴一面即可），并且贴纸离外箱边距必须至少3cm(可以覆盖Logo<(>&<)>箱唛)，否则会影响到客户那边仓库的扫描识 别。 ②外箱侧面印item#（订单上显示的SKU#)+carton size(以工厂实际尺寸为准,单位: inch) +MADE IN CHINA,日期使用ZURU 标准版本。 6. 装柜要求：按照客户PO# 装柜/箱号顺序装柜，跟单会提前给到装柜计划。 在大货生产/仓库存放时，请留意该装柜要求，以便装柜时不混乱（避免装错/装漏/找不到货号等）。 | V13: Kelly Shen | W13: 0.8484 | X13: =W13*I13 -> 936.6336 | Y13: 七 88846-1.2 | Z13: 77555-S001 | AA13: 已入 | AB13: 系统出单 | AC13: 1104 | AD13: =AC13-I13 -> 0 | AE13: ok | AG13: =I13 -> 1104 | AI13: =I13 -> 1104 | AZ13: =I13 -> 1104 | CO13: =CO12-AG13 -> 2729293
A14: 45604 | B14: AMAZON.COM.DEDC,LLC | C14: 美国 | D14: 4500150761 | E14: 3NQCKGVA | F14: 4500150761-50 | G14: 77555-S001 | H14: 迷你房子 | I14: 336 | J14: 0 | K14: 24 | L14: =I14/K14 -> 14 | M14: 45650 | N14: 45646 | P14: pass | Q14: 1/2 截SI | R14: 45604 | S14: 有 | T14: 12/2 SSCC Label | U14: 日期码格式：ZURU INC(BVI) 标准格式 日期：按实际生产日期 Packaging Info: #77555：MA1L 收缩膜+5L收藏指南。 Remark: 1. Amazon FOB订单，出口US。 2. 日期码使用ZURU标准版本。 3. 如果大货有要求入邮包盒，则对应的邮包盒上面要打上日期码。 4. 箱尺寸要求：外箱最长边不能超过25" （超过了，case pack只能为1），不符合要求的大货，一律不接受。 5. 外箱箱唛要求： ①外箱正面印ZURU Logo+SSCC Label（客供贴纸，由跟单订购)。关于 SSCC Label 请注意： SSCC Label 显示的是客人自己的item#。每一张SSCC label 都是唯一且有不同流水及条码的，没有损耗，绝对不可贴错 。如果贴错或损坏任何一张，都会导致全 部都错，千万要注意！ SSCC Label 必须贴在外箱正面的正中间位置（贴一面即可），并且贴纸离外箱边距必须至少3cm(可以覆盖Logo<(>&<)>箱唛)，否则会影响到客户那边仓库的扫描识 别。 ②外箱侧面印item#（订单上显示的SKU#)+carton size(以工厂实际尺寸为准,单位: inch) +MADE IN CHINA,日期使用ZURU 标准版本。 6. 装柜要求：按照客户PO# 装柜/箱号顺序装柜，跟单会提前给到装柜计划。 在大货生产/仓库存放时，请留意该装柜要求，以便装柜时不混乱（避免装错/装漏/找不到货号等）。 | V14: Kelly Shen | W14: 0.8484 | X14: =W14*I14 -> 285.0624 | Y14: 七 88846-1.2 | Z14: 77555-S001 | AA14: 已入 | AB14: 系统出单 | AC14: 336 | AD14: =AC14-I14 -> 0 | AE14: ok | AG14: =I14 -> 336 | AI14: =I14 -> 336 | AZ14: =I14 -> 336 | CO14: =CO13-AG14 -> 2728957
A15: 45604 | B15: AMAZON.COM.DEDC,LLC | C15: 美国 | D15: 4500150761 | E15: 36RPZOPS | F15: 4500150761-60 | G15: 77555-S001 | H15: 迷你房子 | I15: 384 | J15: 0 | K15: 24 | L15: =I15/K15 -> 16 | M15: 45650 | N15: 45646 | P15: pass | Q15: 1/2 截SI | R15: 45604 | S15: 有 | T15: 12/2 SSCC Label | U15: 日期码格式：ZURU INC(BVI) 标准格式 日期：按实际生产日期 Packaging Info: #77555：MA1L 收缩膜+5L收藏指南。 Remark: 1. Amazon FOB订单，出口US。 2. 日期码使用ZURU标准版本。 3. 如果大货有要求入邮包盒，则对应的邮包盒上面要打上日期码。 4. 箱尺寸要求：外箱最长边不能超过25" （超过了，case pack只能为1），不符合要求的大货，一律不接受。 5. 外箱箱唛要求： ①外箱正面印ZURU Logo+SSCC Label（客供贴纸，由跟单订购)。关于 SSCC Label 请注意： SSCC Label 显示的是客人自己的item#。每一张SSCC label 都是唯一且有不同流水及条码的，没有损耗，绝对不可贴错 。如果贴错或损坏任何一张，都会导致全 部都错，千万要注意！ SSCC Label 必须贴在外箱正面的正中间位置（贴一面即可），并且贴纸离外箱边距必须至少3cm(可以覆盖Logo<(>&<)>箱唛)，否则会影响到客户那边仓库的扫描识 别。 ②外箱侧面印item#（订单上显示的SKU#)+carton size(以工厂实际尺寸为准,单位: inch) +MADE IN CHINA,日期使用ZURU 标准版本。 6. 装柜要求：按照客户PO# 装柜/箱号顺序装柜，跟单会提前给到装柜计划。 在大货生产/仓库存放时，请留意该装柜要求，以便装柜时不混乱（避免装错/装漏/找不到货号等）。 | V15: Kelly Shen | W15: 0.8484 | X15: =W15*I15 -> 325.7856 | Y15: 七 88846-1.2 | Z15: 77555-S001 | AA15: 已入 | AB15: 系统出单 | AC15: 384 | AD15: =AC15-I15 -> 0 | AE15: ok | AG15: =I15 -> 384 | AI15: =I15 -> 384 | AZ15: =I15 -> 384 | CO15: =CO14-AG15 -> 2728573
A16: 45604 | B16: AMAZON.COM.DEDC,LLC | C16: 美国 | D16: 4500150745 | E16: 2MCXNKGF | F16: 4500150745-10 | G16: 77555-S001 | H16: 迷你房子 | I16: 72 | J16: 0 | K16: 24 | L16: =I16/K16 -> 3 | M16: 45650 | N16: 45646 | P16: pass | Q16: 12、28 交仓 | R16: 45604 | S16: 有 | T16: 12/2 SSCC Label | U16: 日期码格式：ZURU INC(BVI) 标准格式 日期：按实际生产日期 Packaging Info: #77555：MA1L 收缩膜+5L收藏指南。 Remark: 1. Amazon FOB订单，出口US。 2. 日期码使用ZURU标准版本。 3. 如果大货有要求入邮包盒，则对应的邮包盒上面要打上日期码。 4. 箱尺寸要求：外箱最长边不能超过25" （超过了，case pack只能为1），不符合要求的大货，一律不接受。 5. 外箱箱唛要求： ①外箱正面印ZURU Logo+SSCC Label（客供贴纸，由跟单订购)。关于 SSCC Label 请注意： SSCC Label 显示的是客人自己的item#。每一张SSCC label 都是唯一且有不同流水及条码的，没有损耗，绝对不可贴错 。如果贴错或损坏任何一张，都会导致全 部都错，千万要注意！ SSCC Label 必须贴在外箱正面的正中间位置（贴一面即可），并且贴纸离外箱边距必须至少3cm(可以覆盖Logo<(>&<)>箱唛)，否则会影响到客户那边仓库的扫描识 别。 ②外箱侧面印item#（订单上显示的SKU#)+carton size(以工厂实际尺寸为准,单位: inch) +MADE IN CHINA,日期使用ZURU 标准版本。 6. 装柜要求：按照客户PO# 装柜/箱号顺序装柜，跟单会提前给到装柜计划。 在大货生产/仓库存放时，请留意该装柜要求，以便装柜时不混乱（避免装错/装漏/找不到货号等）。 | V16: Kelly Shen | W16: 0.8778 | X16: =W16*I16 -> 63.2016 | Y16: 七 88838-1.2 | Z16: 77555-S001 | AA16: 已入 | AB16: 系统出单 | AC16: 72 | AD16: =AC16-I16 -> 0 | AE16: ok | AG16: =I16 -> 72 | AI16: =I16 -> 72 | AZ16: =I16 -> 72 | CO16: =CO15-AG16 -> 2728501
A17: 45621 | B17: WAL-MART STORES INC. USA | C17: 美国 | D17: 4500152241 | E17: 0877286357 ELWOOD | F17: 4500152241-30 | G17: 77555SLB-S002 | H17: 迷你房子 | I17: 1152 | J17: 0 | K17: 1152 | L17: =I17/K17 -> 1 | M17: 45649 | N17: 45645 | O17: 12/23 BV | P17: pass | Q17: 1/7 截SI | R17: 翻单 | S17: 有 | T17: 12/6 RFID贴纸 | U17: 日期码格式：ZURU DGYYYYMMDD CHINA(日期避开周末和法定节假日即可） 日期：按实际生产日期 Tracking Code: Packaging Info: 77555SLB-S002 1.包装要求： MA 1L收缩膜+ 客版 收藏指南+客版 1L PDQ，翻单：4500129394 每pcs产品上要贴1张RFID贴纸，贴纸由ZURU提供，贴纸位置请严格按照我们签回的签板； Remark: 77555SLB-S002 1.包装要求： MA 1L收缩膜+ 客版 收藏指南+客版 1L PDQ，翻单：4500129394 每pcs产品上要贴1张RFID贴纸，贴纸由ZURU提供，贴纸位置请严格按照我们签回的签板； 2. 外箱印刷带条码的RFID箱唛：RFID紫色色带+WM Dept.图标+RFID图标+ITF-14条码，四面右下角印刷ZURU logo, ITFF条码只印刷在正唛一面，在加印的时候确保 条形码能扫描出来，外箱侧面任一角落加印："MADE IN CHINA" 字样； 3. 每个slip sheet上面贴一张艾利贴纸（不干胶贴纸）和一张普通贴纸（A4纸），slip sheet打印的普通贴纸的尺寸不能比艾利贴纸小，普通贴纸内容见附件； 4. 在产品上和包装上要有日期码、以及要有MADE IN CHINA和ZURU字样； 5. 产品如有扎带口要剪平，不能刮手。 6. 此单需要验货，请多备料 7. 以slip sheet出货， 77555SLB-S002:1152pcs/96CTN/Slip Sheet | V17: Maggie Xie | W17: 1011.5343 | X17: =W17*L17 -> 1011.5343 | Y17: 七 88860-1.3 | Z17: 77555SLB-S002 | AA17: 已入 | AB17: 系统出单 | AC17: 1152 | AD17: =AC17-I17 -> 0 | AE17: OK | AG17: =I17 -> 1152 | AI17: =I17 -> 1152 | BC17: =I17 -> 1152 | BG17: =I17/12 -> 96 | CG17: 11/25 已放 | CI17: 0 | CO17: =CO16-AG17 -> 2727349
A18: 45621 | B18: WAL-MART STORES INC. USA | C18: 美国 | D18: 4500152241 | E18: 0877286383 STATESBORO | F18: 4500152241-40 | G18: 77555SLB-S002 | H18: 迷你房子 | I18: 2304 | J18: 0 | K18: 1152 | L18: =I18/K18 -> 2 | M18: 45649 | N18: 45645 | O18: 12/23 BV | P18: pass | Q18: 1/10 截SI | R18: 翻单 | S18: 有 | T18: 12/6 RFID贴纸 | U18: 日期码格式：ZURU DGYYYYMMDD CHINA(日期避开周末和法定节假日即可） 日期：按实际生产日期 Tracking Code: Packaging Info: 77555SLB-S002 1.包装要求： MA 1L收缩膜+ 客版 收藏指南+客版 1L PDQ，翻单：4500129394 每pcs产品上要贴1张RFID贴纸，贴纸由ZURU提供，贴纸位置请严格按照我们签回的签板； Remark: 77555SLB-S002 1.包装要求： MA 1L收缩膜+ 客版 收藏指南+客版 1L PDQ，翻单：4500129394 每pcs产品上要贴1张RFID贴纸，贴纸由ZURU提供，贴纸位置请严格按照我们签回的签板； 2. 外箱印刷带条码的RFID箱唛：RFID紫色色带+WM Dept.图标+RFID图标+ITF-14条码，四面右下角印刷ZURU logo, ITFF条码只印刷在正唛一面，在加印的时候确保 条形码能扫描出来，外箱侧面任一角落加印："MADE IN CHINA" 字样； 3. 每个slip sheet上面贴一张艾利贴纸（不干胶贴纸）和一张普通贴纸（A4纸），slip sheet打印的普通贴纸的尺寸不能比艾利贴纸小，普通贴纸内容见附件； 4. 在产品上和包装上要有日期码、以及要有MADE IN CHINA和ZURU字样； 5. 产品如有扎带口要剪平，不能刮手。 6. 此单需要验货，请多备料 7. 以slip sheet出货， 77555SLB-S002:1152pcs/96CTN/Slip Sheet | V18: Maggie Xie | W18: 1011.5343 | X18: =W18*L18 -> 2023.0686 | Y18: 七 88945-1.8 | Z18: 77555SLB-S002 | AA18: 已入 | AB18: 系统出单 | AC18: 2304 | AD18: =AC18-I18 -> 0 | AE18: OK | AG18: =I18 -> 2304 | AI18: =I18 -> 2304 | BC18: =I18 -> 2304 | BG18: =I18/12 -> 192 | CG18: 11/25 已放 | CI18: 0 | CO18: =CO17-AG18 -> 2725045
A19: 45621 | B19: WAL-MART STORES INC. USA | C19: 美国 | D19: 4500152241 | E19: 0877286397 EASTVALE | F19: 4500152241-50 | G19: 77555SLB-S002 | H19: 迷你房子 | I19: 3456 | J19: 0 | K19: 1152 | L19: =I19/K19 -> 3 | M19: 45649 | N19: 45645 | O19: 12/23 BV | P19: pass | Q19: 1/4 截仓 | R19: 翻单 | S19: 有 | T19: 12/6 RFID贴纸 | U19: 日期码格式：ZURU DGYYYYMMDD CHINA(日期避开周末和法定节假日即可） 日期：按实际生产日期 Tracking Code: Packaging Info: 77555SLB-S002 1.包装要求： MA 1L收缩膜+ 客版 收藏指南+客版 1L PDQ，翻单：4500129394 每pcs产品上要贴1张RFID贴纸，贴纸由ZURU提供，贴纸位置请严格按照我们签回的签板； Remark: 77555SLB-S002 1.包装要求： MA 1L收缩膜+ 客版 收藏指南+客版 1L PDQ，翻单：4500129394 每pcs产品上要贴1张RFID贴纸，贴纸由ZURU提供，贴纸位置请严格按照我们签回的签板； 2. 外箱印刷带条码的RFID箱唛：RFID紫色色带+WM Dept.图标+RFID图标+ITF-14条码，四面右下角印刷ZURU logo, ITFF条码只印刷在正唛一面，在加印的时候确保 条形码能扫描出来，外箱侧面任一角落加印："MADE IN CHINA" 字样； 3. 每个slip sheet上面贴一张艾利贴纸（不干胶贴纸）和一张普通贴纸（A4纸），slip sheet打印的普通贴纸的尺寸不能比艾利贴纸小，普通贴纸内容见附件； 4. 在产品上和包装上要有日期码、以及要有MADE IN CHINA和ZURU字样； 5. 产品如有扎带口要剪平，不能刮手。 6. 此单需要验货，请多备料 7. 以slip sheet出货， 77555SLB-S002:1152pcs/96CTN/Slip Sheet | V19: Maggie Xie | W19: 1011.5343 | X19: =W19*L19 -> 3034.6029 | Y19: 七 88875-1.4 | Z19: 77555SLB-S002 | AA19: 已入 | AB19: 系统出单 | AC19: 3456 | AD19: =AC19-I19 -> 0 | AE19: OK | AG19: =I19 -> 3456 | AI19: =I19 -> 3456 | BC19: =I19 -> 3456 | BG19: =I19/12 -> 288 | CG19: 11/25 已放 | CI19: 0 | CO19: =CO18-AG19 -> 2721589
A20: 45621 | B20: WAL-MART STORES INC. USA | C20: 美国 | D20: 4500152241 | E20: 0877286399 HOUSTON | F20: 4500152241-60 | G20: 77555SLB-S002 | H20: 迷你房子 | I20: 5760 | J20: 0 | K20: 1152 | L20: =I20/K20 -> 5 | M20: 45649 | N20: 45645 | O20: 12/23 BV | P20: pass | Q20: 12/30 截SI | R20: 翻单 | S20: 有 | T20: 12/6 RFID贴纸 | U20: 日期码格式：ZURU DGYYYYMMDD CHINA(日期避开周末和法定节假日即可） 日期：按实际生产日期 Tracking Code: Packaging Info: 77555SLB-S002 1.包装要求： MA 1L收缩膜+ 客版 收藏指南+客版 1L PDQ，翻单：4500129394 每pcs产品上要贴1张RFID贴纸，贴纸由ZURU提供，贴纸位置请严格按照我们签回的签板； Remark: 77555SLB-S002 1.包装要求： MA 1L收缩膜+ 客版 收藏指南+客版 1L PDQ，翻单：4500129394 每pcs产品上要贴1张RFID贴纸，贴纸由ZURU提供，贴纸位置请严格按照我们签回的签板； 2. 外箱印刷带条码的RFID箱唛：RFID紫色色带+WM Dept.图标+RFID图标+ITF-14条码，四面右下角印刷ZURU logo, ITFF条码只印刷在正唛一面，在加印的时候确保 条形码能扫描出来，外箱侧面任一角落加印："MADE IN CHINA" 字样； 3. 每个slip sheet上面贴一张艾利贴纸（不干胶贴纸）和一张普通贴纸（A4纸），slip sheet打印的普通贴纸的尺寸不能比艾利贴纸小，普通贴纸内容见附件； 4. 在产品上和包装上要有日期码、以及要有MADE IN CHINA和ZURU字样； 5. 产品如有扎带口要剪平，不能刮手。 6. 此单需要验货，请多备料 7. 以slip sheet出货， 77555SLB-S002:1152pcs/96CTN/Slip Sheet | V20: Maggie Xie | W20: 1011.5343 | X20: =W20*L20 -> 5057.6715 | Y20: 七 88875-1.4 | Z20: 77555SLB-S002 | AA20: 已入 | AB20: 系统出单 | AC20: 5760 | AD20: =AC20-I20 -> 0 | AE20: OK | AG20: =I20 -> 5760 | AI20: =I20 -> 5760 | BC20: =I20 -> 5760 | BG20: =I20/12 -> 480 | CG20: 11/25 已放 | CI20: 0 | CO20: =CO19-AG20 -> 2715829
A21: 45621 | B21: WAL-MART STORES INC. USA | C21: 美国 | D21: 4500152241 | E21: 0877286420 SUFFOLK | F21: 4500152241-70 | G21: 77555SLB-S002 | H21: 迷你房子 | I21: 10368 | J21: 0 | K21: 1152 | L21: =I21/K21 -> 9 | M21: 45649 | N21: 45645 | O21: 12/23 BV | P21: pass | R21: 翻单 | S21: 有 | T21: 12/6 RFID贴纸 | U21: 日期码格式：ZURU DGYYYYMMDD CHINA(日期避开周末和法定节假日即可） 日期：按实际生产日期 Tracking Code: Packaging Info: 77555SLB-S002 1.包装要求： MA 1L收缩膜+ 客版 收藏指南+客版 1L PDQ，翻单：4500129394 每pcs产品上要贴1张RFID贴纸，贴纸由ZURU提供，贴纸位置请严格按照我们签回的签板； Remark: 77555SLB-S002 1.包装要求： MA 1L收缩膜+ 客版 收藏指南+客版 1L PDQ，翻单：4500129394 每pcs产品上要贴1张RFID贴纸，贴纸由ZURU提供，贴纸位置请严格按照我们签回的签板； 2. 外箱印刷带条码的RFID箱唛：RFID紫色色带+WM Dept.图标+RFID图标+ITF-14条码，四面右下角印刷ZURU logo, ITFF条码只印刷在正唛一面，在加印的时候确保 条形码能扫描出来，外箱侧面任一角落加印："MADE IN CHINA" 字样； 3. 每个slip sheet上面贴一张艾利贴纸（不干胶贴纸）和一张普通贴纸（A4纸），slip sheet打印的普通贴纸的尺寸不能比艾利贴纸小，普通贴纸内容见附件； 4. 在产品上和包装上要有日期码、以及要有MADE IN CHINA和ZURU字样； 5. 产品如有扎带口要剪平，不能刮手。 6. 此单需要验货，请多备料 7. 以slip sheet出货， 77555SLB-S002:1152pcs/96CTN/Slip Sheet | V21: Maggie Xie | W21: 1011.5343 | X21: =W21*L21 -> 9103.8087 | Y21: 七 88840-1.2 | Z21: 77555SLB-S002 | AA21: 已入 | AB21: 系统出单 | AC21: 10368 | AD21: =AC21-I21 -> 0 | AE21: OK | AG21: =I21 -> 10368 | AI21: =I21 -> 10368 | BC21: =I21 -> 10368 | BG21: =I21/12 -> 864 | CG21: 11/25 已放 | CI21: 0 | CK21: 指南 | CL21: PDQ | CO21: =CO20-AG21 -> 2705461
A22: 45608 | B22: ZURU France | C22: 法国 | D22: 4500151007 | E22: 5200005637 | F22: 4500151007-10 | G22: 77555GQ1-S002-MTS | H22: 迷你房子GQ1/13PCS/箱 | I22: 1560 | J22: 0 | K22: 13 | L22: =I22/K22 -> 120 | M22: 45650 | N22: 45646 | P22: pass | Q22: 12/24 截SI | R22: 45618 | S22: 无 | T22: 11、13 环保标贴纸 | U22: 日期码格式：ZURU INC(BVI) 标准格式 日期：按实际生产日期 Packaging Info: 77555GQ1: MA 3L +5L warning EAN版本收缩膜+一张法国意大利西班牙环保标贴纸+MA 5L A版收藏指南； Remark: 1. 西班牙国家内销单，需要通过ZURU 验货结果后才能出货 (工厂需要主动提前同ZURU QC预约验货避免延期出货造成不必要麻烦)； 2. 本订单所有 具有 baby items / assorted items 的款式，零售包装上都要用 母 EAN; 3. 若有特定款有特殊外箱条码要求时,需要明确列出产品款对应的具体外箱条码号码/条码类型 (若无,可以忽略此需求) 4. 所有出口欧洲的产品, 法规规定禁止在包装和共公众用的印刷品中使用矿物油中含有的物质, 包装印刷油墨中含有的MOAH/MOSH的质量浓度不能超过1%, 否则出 货到法国被抽检出现问题, 供应商需要对此负责; 5. date code: 外箱/产品/包装 保持一致，完货后提供date code 信息以便我们保存记录做批次管理; 6. 装柜时需要按照款式号码从小到大一款款依次装,避免终端仓库卸货混乱.若一个柜子涉及到几个不同国家内销单,装柜时需要一个国家装完后再装另一个国家的 产品,依次装柜,避免终端仓库因不同国家不同库位位置卸货混乱. (此点需要同工厂装柜人员强调) | V22: SD83 | W22: 0.8797 | X22: =W22*I22 -> 1372.332 | Y22: 七 88839-1.2 | Z22: 77555GQ1-S002-3L | AA22: 已入 | AB22: 系统出单 | AC22: 1560 | AD22: =AC22-I22 -> 0 | AE22: OK | AG22: =I22 -> 1560 | AJ22: =I22 -> 1560 | AZ22: =I22 -> 1560 | BM22: =I22/13 -> 120 | CO22: =CO21-AG22 -> 2703901
A23: 45590 | B23: Amazon EU SARL, Ndl Deutschland | C23: 德国 | D23: 4500148999 | E23: 4WZA5DAX | F23: 4500148999-10 | G23: 77584-S001 | H23: 迷你房子 | I23: 504 | J23: 0 | K23: 12 | L23: =I23/K23 -> 42 | M23: 45651 | N23: 45647 | P23: 自检 | Q23: 1/4 入仓 | R23: 空白外箱（加印带Zuru字样的最新logo，除了邮包盒直接做外箱的产品） | S23: 有 | T23: 11/21SSCC LABEL+空白贴纸+IT sorting label翻单124874+ES回收标志1号翻单145205+12/2 ZURU邮箱贴 | U23: 日期码格式：ZURU INC(BVI) 标准格式 日期：按实际生产日期 Packaging Info: Amazon DE 77584 1.77584: 77555 2pcs/pvc tube, 12tubes/ctn; MA 3L (5L WARNING) 收缩膜（EAN#请用空白贴纸覆盖）+MA 其他最新包装+客版3L(5L warning)PVC tube彩卡(参 考翻单PO#4500131987)+3张贴纸(1张IT sorting label, 参考翻单PO#4500124874；1张ES回收标志1号，参考翻单PO#4500145205；1张ZURU邮箱)； 5. ZURU 验货最迟不得晚于2024/12/26 Remark: 1.空白外箱（加印带Zuru字样的最新logo，除了邮包盒直接做外箱的产品） + SSCC LABEL一张, 无箱唛. (SSCC LABEL贴在外箱正面的正中间，贴一面即可,贴纸离外箱边距必须至少3.2CM),SSCC贴纸由工厂直接跟勤得采购或者工厂自行采购，每一张SSCC Label都是唯一 且有不同流水及条码，且需要检查条码是否能正常扫描，另外，此贴纸印刷不可出现模糊，溢出及粘胶不牢易脱落等现象，如工厂不按此要求导致贴纸有任何问题产 生的罚款将由工厂承担一切责任 。’MADE IN CHINA 外箱只印一正一侧。 2. 出往UK的产品+包装务必打上UKCA logo ，否则客人会退货且当地会有罚款。 3.订单必须经过ZURU QC验货并且通过后方可出货。 4.法国订单要求包装不使用矿物油，请按要求提供以下其中一份文件再出货 ，产品出到法国被相关部门抽检出现包装不符合此要求的，供应商需要为此承担责任， 故此请严格把关 。 -油墨物质""由1 ~ 7个芳香环组成的MOAH""的包装检测报告，要求限值≤1.0%; -包装材料清单，包括包装油墨或物质的信息 -油墨制造商的证书。 5 . 每一批次出货只能有一个生产日期，不可多个生产日期混在同一批次出货；且邮包盒上必须统一加上日期码； 6. 涉及到相关款式会有闪粉的或 者微塑料的，请统一默认出无闪粉或者不含微塑料 版本; 7 .邮包盒及外箱封箱必须是工字型封箱方式； 8 . 5 Surprise or Mini Brands涉及包装是2个及2个以上的球入PVC桶包装时，单个球上若有UPC#或者EAN#，请用白色贴纸覆盖住； | V23: Zoe Chen | W23: 2.4352 | X23: =W23*I23 -> 1227.3408 | Y23: 七 88946-1.8 | Z23: 77584-S001-3L-1 | AA23: 已入 | AB23: 系统出单 | AC23: =492+12 -> 504 | AD23: =AC23-I23 -> 0 | AE23: ok | AG23: =I23*2 -> 1008 | AJ23: =AG23 -> 1008 | AZ23: =I23*2 -> 1008 | CC23: =I23 -> 504 | CD23: =I23 -> 504 | CF23: =I23 -> 504 | CH23: 10/25已放 | CI23: 5000 | CJ23: =CI23-I23 -> 4496 | CO23: =CO22-AG23 -> 2702893
A24: 45607 | B24: TARGET US | C24: 美国 | D24: 4500150929 | E24: 10001033427-3890 | F24: 4500150929-10 | G24: 77555GQ2-S002 | H24: 迷你房子 | I24: 37525 | J24: 0 | K24: 25 | L24: =I24/K24 -> 1501 | M24: 45651 | N24: 45647 | P24: pass | Q24: 1/6 客自提 | R24: 45621 | S24: 有 | T24: 12/6条码箱贴纸 | U24: 日期码格式：ZURU INC(BVI) 标准格式 日期：按实际生产日期 Tracking Code: Packaging Info: 产品MA包装 (UPC 版), MA 1L 收缩膜, MA 1L PDQ; Remark: 1. 77555GQ2-S002-MINI BRANDS-HOME MINI BRANDS-SERIES 1-CAPSULE,25PCS/Gravity PDQ, 25PCS/PDQ/CTN 2. 产品MA包装 (UPC 版), MA 1L 收缩膜，收缩膜上的UPC显示 193052064264, MA 1L PDQ; 3. 外箱正唛左上角位置粘贴条码箱贴纸，每箱只贴一张，由ZURU订购。来料贴纸上显示的客户DPCI# 086-02-1571， UPC显示10193052064261; 4. 产品和包装上印刷 tracking code信息，格式为ZU | V24: Holly Zheng | W24: 0.8967 | X24: =W24*I24 -> 33648.668 | Y24: 七 88894-1.6 | Z24: 77555GQ2-S002 | AA24: 已入 | AB24: 系统出单 | AC24: =7875+29650 -> 37525 | AD24: =AC24-I24 -> 0 | AE24: ok | AG24: =I24 -> 37525 | AI24: =I24 -> 37525 | AZ24: =I24 -> 37525 | BP24: =I24/25 -> 1501 | CO24: =CO23-AG24 -> 2665368
A25: 45644 | B25: WALGREEN CO. | C25: 美国 | D25: MPO03152 | E25: 此MPO订单替换原手工单MPOWAL034 | G25: 77555-S001 | H25: 迷你房子8个球按配比分隔开/箱 | I25: 42616 | J25: 0 | K25: 24 | L25: =I25/K25 -> 1775.6667 | M25: 45667 | N25: 45663 | P25: pass | Q25: 8504pcs 1/10 送库有 | R25: 周转箱 | S25: 无 | T25: 10/24 WIC贴纸 | U25: Remark:1.此MPO订单替换原手工单MPOWAL034 2.订单要求参考MPOWAL034 3.分三批送货 第-批 77485-8528pcs 77555-8528pcs(已送货)第二批77485-25584pcs77555-25584pcs(已送货)第三批 77485-8504pcs77555-8504pcs(待安排送货) | V25: Cara Li | W25: 0.8115 | X25: =W25*I25 -> 34582.884 | Y25: 94402-2.27 94410-2.28 | Z25: 77555-S001 | AA25: 已入 | AB25: 系统出单 | AC25: 11月份送回的 | AG25: =I25 -> 42616 | AI25: =I25 -> 42616 | AZ25: =I25 -> 42616 | CO25: =CO24-AG25 -> 2622752
A26: 45586 | B26: ROSS PROCUREMENT.INC | C26: 美国 | D26: 4500148421 | E26: 60190475 | F26: 4500148421-30 | G26: 77584-S001 | H26: 迷你房子 | I26: 6000 | J26: 0 | K26: 12 | L26: =I26/K26 -> 500 | M26: 45653 | N26: 45649 | P26: pass | Q26: 1/3 截SI | R26: 45588 | S26: 无 | T26: 11/20 客供价格贴纸 | U26: 日期码格式： 标准格式 日期：按实际生产日期 Packaging Info: URU MA UPC 收缩膜+客版铜版纸+PVC桶 + 客供价格贴纸，出口美国 , 优先使用MA 1L 最新版本 。 Remark: 1.ZURU MA UPC 收缩膜+客版铜版纸+PVC桶 + 客供价格贴纸，出口美国 , 优先使用MA 1L 最新版本 。 2.价格贴纸位于包装正面右下角，不挡住重要信息即可，可适当调整 ，价格贴纸由跟单提供。 3.标准日期码格式，产品和包装必须有日期码 。 4.同个产品同个货期不可出现不同的包装。 5. PVC 桶中球不能出现完全相同的ASSORTMENT ， 即同一个PVC 中球里的ASSORTMENT 需要不同。 以免消费者失望。 6.PVC 桶上加上 MINI BRANDS 的LOGO 贴纸 （ ZURU 统一要求的） 7.收缩膜可使用标版带UPC条码MA，无需白色贴纸覆盖。 | V26: Sophia Zhou | W26: 2.3775 | X26: =W26*I26 -> 14265 | Y26: 七 88928-1.7 | Z26: 77584-S001-3L | AA26: 已入 | AB26: 系统出单 | AC26: =5988+12 -> 6000 | AD26: =AC26-I26 -> 0 | AE26: ok | AG26: =I26*2 -> 12000 | AI26: =I26*2 -> 12000 | AZ26: =I26*2 -> 12000 | CC26: =I26 -> 6000 | CD26: =I26 -> 6000 | CF26: =I26 -> 6000 | CH26: 按实单 | CO26: =CO25-AG26 -> 2610752
A27: 45601 | B27: DD’S DISCOUNTS | C27: 美国 | D27: 4500150183 | E27: 70054027 | F27: 4500150183-10 | G27: 77584-S001 | H27: 迷你房子 | I27: 600 | J27: 0 | K27: 12 | L27: =I27/K27 -> 50 | M27: 45653 | N27: 45649 | P27: 自检 | Q27: 1/7交仓 | R27: 11、5 | S27: 无 | T27: 11/20 客供价格贴纸 | U27: 日期码格式：ZURU INC(BVI) 标准格式 日期：按实际生产日期 Packaging Info: 1.ZURU MA UPC 现有版本包装 + 客供价格贴纸，出口美国 , 优先使用MA 1L 最新版本 。 Remark: 1.ZURU MA UPC 现有版本包装 + 客供价格贴纸，出口美国 , 优先使用MA 1L 最新版本 。 2.价格贴纸位于包装正面右下角，不挡住重要信息即可，可适当调整 ，价格贴纸由跟单提供。 3.标准日期码格式，产品和包装必须有日期码 。 4.同个产品同个货期不可出现不同的包装。 5. 跟单提供ROSS通用的箱唛模版，工厂按实际45 PO上客户PO/Item号/装箱数 提供箱唛排版来确认。 6. PVC 桶中球不能出现完全相同的ASSORTMENT ， 即同一个PVC 中球里的ASSORTMENT 需要不同。 以免消费者失望。 7.PVC 桶上加上 5 surprise 的LOGO 贴纸 （ ZURU 统一要求的） 8.收缩膜可使用标版带UPC条码MA，无需白色贴纸覆盖。 | V27: Taylor Liao | W27: 2.4352 | X27: =W27*I27 -> 1461.12 | Y27: 七 88927-1.7 | Z27: 77584-S001-3L | AA27: 已入 | AB27: 系统出单 | AC27: 600 | AD27: =AC27-I27 -> 0 | AE27: ok | AG27: =I27*2 -> 1200 | AI27: =I27*2 -> 1200 | AZ27: =I27*2 -> 1200 | CC27: =I27 -> 600 | CD27: =I27 -> 600 | CF27: =I27 -> 600 | CH27: 10/25已放 | CJ27: =CJ23-I27 -> 3896 | CO27: =CO26-AG27 -> 2609552
A28: 45607 | B28: TARGET US | C28: 美国 | D28: 4500150926 | E28: 10001033543-3891 | F28: 4500150926-20 | G28: 77555GQ2-S002 | H28: 迷你房子 | I28: 19700 | J28: 0 | K28: 25 | L28: =I28/K28 -> 788 | M28: 45653 | N28: 45649 | P28: pass | R28: 45621 | S28: 有 | T28: 12/6条码箱贴纸 | U28: 日期码格式：ZURU INC(BVI) 标准格式 日期：按实际生产日期 Packaging Info: 77555GQ2：产品MA包装 (UPC 版), MA 1L 收缩膜，MA 1L PDQ; Remark: 77555GQ2: 1. 77555GQ2-S002-MINI BRANDS-HOME MINI BRANDS-SERIES 1-CAPSULE,25PCS/Gravity PDQ, 25PCS/PDQ/CTN 2. 产品MA包装 (UPC 版), MA 1L 收缩膜，收缩膜上的UPC显示 193052064264, MA 1L PDQ; 3. 外箱正唛左上角位置粘贴条码箱贴纸，每箱只贴一张，由ZURU订购。来料贴纸上显示的客户DPCI# 086-02-1571， UPC显示10193052064261; 此订单所有型号： 1. 产品和包装上印刷 tracking code信息，格式为ZURU常规格式; 2. 出货方式：货代自提 | V28: Holly Zheng | W28: 0.9024 | X28: =W28*I28 -> 17777.28 | Y28: 七 88960-1.9 | Z28: 77555GQ2-S002 | AA28: 已入 | AB28: 系统出单 | AC28: 19700 | AD28: =AC28-I28 -> 0 | AE28: ok | AG28: =I28 -> 19700 | AI28: =I28 -> 19700 | AZ28: =I28 -> 19700 | BP28: =I28/25 -> 788 | CO28: =CO27-AG28 -> 2589852
A29: 45638 | D29: ZMPO24948 | E29: MPO03008 | G29: 77555-S002 | H29: 迷你房子 | I29: 48 | J29: 0 | K29: 12 | L29: =I29/K29 -> 4 | M29: 45650 | N29: 45650 | P29: 已送库有 | R29: 空白箱 | S29: 无 | T29: 无 | U29: Remark：客版3L收缩膜(UPC: 193052064264)+MA5L收藏指南+MA配件袋+MA5L,UV胶水贴纸+MA23L说明书；----工厂PO:MPO03008- 备注：收到样品订单后尽快安排,注意样板品质质量要求要高于大货品质要求 ，送货时必须要附带送货单(没有送货单和QC检验合格报告的仓库一律拒绝收货)，请知悉，谢谢！ | V29: Angus | Z29: # | AA29: # | AC29: 48 | AD29: =AC29-I29 -> 0 | AE29: 无 | AG29: =I29 -> 48 | AW29: =I29 -> 48 | AZ29: =I29 -> 48 | CO29: =CO28-AG29 -> 2589804
A30: 45604 | B30: ASDA STORES LTD | C30: 英国 | D30: 4500150696 | E30: 2950866100 | F30: 4500150696-50 | G30: 77555SLB-S001 | H30: 迷你房子 | I30: 975 | J30: 0 | K30: 975 | L30: =I30/K30 -> 1 | M30: 45656 | N30: 45652 | P30: 自检 | Q30: 1/8 截SI | R30: 45625 | S30: 有 | T30: slip sheet贴纸 | U30: 日期码格式：ZURU INC(BVI) 标准格式 日期：按实际生产日期 Packaging Info: 77555GQ1-S002：MA最新1L UPC包装 UPC#193052064264, 请先检查条码是否正确再安排做货； Slip sheet:13pcs/PDQ/CTN 15*5H=75CTN/SLB=975pcs/Slip Sheet,一共需要1套slip sheet; Slip Sheet打包好后，需要在正唛、侧唛右下角各贴一张slip sheet贴纸，直接用A4纸打印出来即可，贴纸尺寸160mm width x 140mm high； Slip Sheet尺寸限制为100*115*130CM，一旦实际SLIP SHEET尺寸超过这个尺寸，请提前通知ZURU跟单，需同客人确认才能量产和出货; Remark: 1. 产品及包装需要印UKCA图标，包装需要有ZURU UK LTD/ZURU France地址信息，QC同事请核查，如有问题与跟单确认 2. 产品/包装/外箱都需要打ZURU格式日期码，日期必须为法定工作日。 3. 需要符合欧洲标准不能含有闪粉和微塑料，否则不合法规会有客诉产生 | V30: Amy Ding | W30: 877.958 | X30: =W30*I30 -> 856009.05 | Y30: 七 88944-1.8 | Z30: 77555SLB-S001 | AA30: 已入 | AB30: 系统出单 | AC30: 975 | AD30: =AC30-I30 -> 0 | AE30: 无 | AG30: =I30 -> 975 | AI30: =I30*2 -> 1950 | AZ30: =I30*2 -> 1950 | BK30: =I30/13 -> 75 | CO30: =CO29-AG30 -> 2588829
