Workbook

Sheet 77685旧排期 
A1: ZURU 5 surprise Dino （混搭恐龙）生产排期表 #77685 | H1: 3L及共用包材上的logo为英法2L，纸袋底纹为5S通用logo（为应对加拿大魁北克新规，3L及共用包材上的logo增加法语或改为5S logo以减少翻译）。口水胶、纸袋、说明书、收藏指南从1L Logo变更3L Logo，GQ21L/3L各库存2000PCS，后续切换B版本，注意走加拿大魁北克订单不能用A版本.同一个单不能出现两个版本 | AH1: 无硼 口水胶 | AK1: 收缩膜 | AN1: 收藏指南 | AP1: 外挂中文收藏指南+中文说明书 | AQ1: GQ2 | AT1: GQ1 | AV1: GQ4 | AW1: GQ5 | AX1: GQ7 | AZ1: SK展示架 | BC1: SK1展示架 | BF1: 2PK | BJ1: 腕龙 | BK1: 双脊龙 | BL1: 镰刀龙 | BM1: 甲龙 | BN1: 戟龙 | BO1: 棘龙 | BP1: 沧龙 | BQ1: 霸王龙 | BR1: 特殊款霸王龙 | BT1: =生产MA!G4 -> 腕龙 | BU1: =生产MA!H4 -> 双脊龙 | BV1: =生产MA!I4 -> 镰刀龙 | BW1: =生产MA!J4 -> 甲龙 | BX1: =生产MA!K4 -> 戟龙 | BY1: =生产MA!L4 -> 棘龙 | BZ1: =生产MA!M4 -> 沧龙 | CA1: =生产MA!N4 -> 霸王龙 | CB1: =生产MA!O4 -> 特殊款霸王龙
A2: 香港接单日期 | B2: 第三方客户名称 | C2: 走货国家 | D2: PO号 | E2: 第三方客户 PO NO# | F2: SKU | G2: ITEM# | H2: 中文名 | I2: PO数量 (pcs) | J2: 内箱装箱数量(pcs) | K2: 外箱装箱数量(pcs) | L2: 总箱数 | M2: 客PO期 | N2: 验货期 | O2: 第三方验货时间 | P2: 验货结果 | Q2: 船期 | R2: 箱唛资料(收到日期) | S2: 外箱贴纸 | T2: 客供贴纸AI(收到日期) | U2: 样板 | V2: 备注 | W2: ZURU 跟单 | X2: 单价USD | Y2: 金额USD | Z2: 发票号 | AA2: 送回数量 | AB2: 欠数 | AC2: 贴纸情况 | AD2: 下单情况 | AE2: 系统货号 | AF2: 是否入系统 | AG2: 球数 | AH2: MA | AI2: B MA | AJ2: 客版 | AK2: MA 1L | AL2: MA 3L | AM2: Smyths客版 | AN2: MA 5L | AO2: B MA 5L | AP2: 客版 | AQ2: MA 1L | AR2: MA 3L | AS2: MA B3L | AT2: MA 1L | AU2: MA 3L | AV2: WM 客版 | AW2: Big 客版 | AX2: WM M客版 | AY2: IMP 3L 客版 | AZ2: MA 1L | BA2: MA 3L | BB2: 3L底座 | BC2: MA 1L | BD2: MA 3L | BE2: 底座 | BF2: 圆筒 | BG2: logo英法语彩纸/贴纸 条码UPC | BJ2: 0.12239583 | BK2: 0.12239583 | BL2: 0.12239583 | BM2: 0.12239583 | BN2: 0.12239583 | BO2: 0.12239583 | BP2: 0.12239583 | BQ2: 0.12239583 | BR2: 0.020833333 | BS2: MA扣数 | BT2: =生产MA!G11 -> 113832 | BU2: =生产MA!H11 -> 113832 | BV2: =生产MA!I11 -> 113832 | BW2: =生产MA!J11 -> 113832 | BX2: =生产MA!K11 -> 113832 | BY2: =生产MA!L11 -> 113832 | BZ2: =生产MA!M11 -> 113832 | CA2: =生产MA!N11 -> 113832 | CB2: =生产MA!O11 -> 19377
A3: 45617 | B3: ZURU | C3: 深圳 | D3: ZPO2411012 | E3: PP订单 | G3: 77685GQ2-S001 | H3: 混搭恐龙27pcs/GQ2*2/箱 | I3: 1135 | J3: 0 | K3: 54 | L3: =I3/K3 -> 21.018519 | M3: 45639 | N3: 45635 | R3: 无 | S3: 无 | T3: 无 | V3: 如何同意以上交货期到ZURU但是最后由于供应商原因无法交货，ZURU保留以下的罚款条款 不按期出货罚款如下： 1-7（含第七天）天内延迟出货罚款为合同总金额的百分之五 7-14（含第十四天）天内延迟出货罚款为合同总金额的百分之七 如果超过14天将扣合同金额的百分之十或者由客人提出预计运费方案 如果因为质量不符合雨禾要求的标准，供应商必须改进产品并达到标准并支付返工费用和出货延迟费用 订单细节会不时进行修改，如果订单做了修改要及时通知供应商，修改和特殊指引在生产过程中要由邮件或者电话确认 | Z3: 年存 | BT3: =BT2-BJ3 -> 113832 | BU3: =BU2-BK3 -> 113832 | BV3: =BV2-BL3 -> 113832 | BW3: =BW2-BM3 -> 113832 | BX3: =BX2-BN3 -> 113832 | BY3: =BY2-BO3 -> 113832 | BZ3: =BZ2-BP3 -> 113832 | CA3: =CA2-BQ3 -> 113832 | CB3: =CB2-BR3 -> 19377
A4: 45618 | B4: ZURU | C4: 库有 | D4: ZMPO24875 | E4: 同PP单一起做 | G4: 77685-S001 | H4: 混搭恐龙 | I4: 1008 | J4: 0 | K4: 24 | L4: =I4/K4 -> 42 | M4: 45639 | N4: 45635 | R4: 无 | S4: 无 | T4: 无 | V4: Remark：跟PP订单一起安排/标准箱装箱/箱唛参照邮件附件 备注：收到样品订单后尽快安排 ，注意样板品质质量要求要高于大货品质要求 ，送货时必须要附带送货单(没有送货单和QC检验合格报告的仓库一律拒绝收货)，请知悉，谢谢！ | W4: Angus | Z4: 97427-12.31 | BT4: =BT3-BJ4 -> 113832 | BU4: =BU3-BK4 -> 113832 | BV4: =BV3-BL4 -> 113832 | BW4: =BW3-BM4 -> 113832 | BX4: =BX3-BN4 -> 113832 | BY4: =BY3-BO4 -> 113832 | BZ4: =BZ3-BP4 -> 113832 | CA4: =CA3-BQ4 -> 113832 | CB4: =CB3-BR4 -> 19377
A5: 45618 | B5: ZURU | C5: 库有 | D5: ZMPO24875 | E5: 同PP单一起做 | G5: 77685-S001 | H5: 10套散件 | I5: 10 | J5: 0 | K5: 10 | L5: =I5/K5 -> 1 | M5: 45639 | N5: 45635 | R5: 无 | S5: 无 | T5: 无 | V5: Remark：跟PP订单一起安排/只需要齐全套散件/麻烦用胶袋分装好一套为一袋/箱唛参照邮件附件 备注：收到样品订单后尽快安排 ，注意样板品质质量要求要高于大货品质要求 ，送货时必须要附带送货单(没有送货单和QC检验合格报告的仓库一律拒绝收货)，请知悉，谢谢！ | W5: Angus | Z5: 97427-12.31 | AE5: # | BT5: =BT4-BJ5 -> 113832 | BU5: =BU4-BK5 -> 113832 | BV5: =BV4-BL5 -> 113832 | BW5: =BW4-BM5 -> 113832 | BX5: =BX4-BN5 -> 113832 | BY5: =BY4-BO5 -> 113832 | BZ5: =BZ4-BP5 -> 113832 | CA5: =CA4-BQ5 -> 113832 | CB5: =CB4-BR5 -> 19377
A6: 45618 | B6: ZURU | C6: 库有 | D6: ZMPO24875 | E6: 同PP单一起做 | G6: 77685GQ1-S001 | H6: GQ1空PDQ搭配Demo零件 | I6: 20 | J6: 0 | K6: 20 | L6: =I6/K6 -> 1 | M6: 45639 | N6: 45635 | R6: 无 | S6: 无 | T6: 无 | V6: Remark：跟PP订单一起安排/只需要空PDQ(PDQ可打平包/需配齐PDQ上原有的配件（列如-Demo-吸塑) 备注：收到样品订单后尽快安排 ，注意样板品质质量要求要高于大货品质要求 ，送货时必须要附带送货单(没有送货单和QC检验合格报告的仓库一律拒绝收货)，请知悉，谢谢！ | W6: Angus | Z6: 97427-12.31 | AE6: # | BT6: =BT5-BJ6 -> 113832 | BU6: =BU5-BK6 -> 113832 | BV6: =BV5-BL6 -> 113832 | BW6: =BW5-BM6 -> 113832 | BX6: =BX5-BN6 -> 113832 | BY6: =BY5-BO6 -> 113832 | BZ6: =BZ5-BP6 -> 113832 | CA6: =CA5-BQ6 -> 113832 | CB6: =CB5-BR6 -> 19377
A7: 45618 | B7: ZURU | C7: 库有 | D7: ZMPO24875 | E7: 同PP单一起做 | G7: 77685GQ2-S001 | H7: GQ2空PDQ搭配Demo零件 | I7: 20 | J7: 0 | K7: 20 | L7: =I7/K7 -> 1 | M7: 45639 | N7: 45635 | R7: 无 | S7: 无 | T7: 无 | V7: Remark：跟PP订单一起安排/只需要空PDQ(PDQ可打平包/需配齐PDQ上原有的配件（列如-Demo-吸塑) 备注：收到样品订单后尽快安排 ，注意样板品质质量要求要高于大货品质要求 ，送货时必须要附带送货单(没有送货单和QC检验合格报告的仓库一律拒绝收货)，请知悉，谢谢！ | W7: Angus | Z7: 97427-12.31 | AE7: # | BT7: =BT6-BJ7 -> 113832 | BU7: =BU6-BK7 -> 113832 | BV7: =BV6-BL7 -> 113832 | BW7: =BW6-BM7 -> 113832 | BX7: =BX6-BN7 -> 113832 | BY7: =BY6-BO7 -> 113832 | BZ7: =BZ6-BP7 -> 113832 | CA7: =CA6-BQ7 -> 113832 | CB7: =CB6-BR7 -> 19377
A8: 45714 | D8: ZMPO250144 | G8: 77685GQ1-S001 | H8: 40个空PDQ | I8: 40 | J8: 0 | K8: 40 | L8: =I8/K8 -> 1 | M8: 45726 | N8: 45722 | R8: 45714 | S8: 无 | T8: 无 | V8: Remark:大货最新版本/只需要空PDQ(PDQ可打平包/需配齐PDQ上原有的配件（列如-Demo-吸塑);备注：收到样品订单后尽快安排 ，注意样板品质质量要求要高于大货品质要求 ，送货时必须要附带送货单(没有送货单和QC检验合格报告的仓库一律拒绝收货)，请知悉，谢谢！ | W8: Angus | Z8: 94917-4.30 | AA8: 40 | AB8: =AA8-I8 -> 0 | AE8: # | AT8: =I8 -> 40 | BT8: =BT7-BJ8 -> 113832 | BU8: =BU7-BK8 -> 113832 | BV8: =BV7-BL8 -> 113832 | BW8: =BW7-BM8 -> 113832 | BX8: =BX7-BN8 -> 113832 | BY8: =BY7-BO8 -> 113832 | BZ8: =BZ7-BP8 -> 113832 | CA8: =CA7-BQ8 -> 113832 | CB8: =CB7-BR8 -> 19377
A9: 45714 | D9: ZMPO250144 | G9: 77685GQ2-S001 | H9: 40个空PDQ | I9: 40 | J9: 0 | K9: 40 | L9: =I9/K9 -> 1 | M9: 45726 | N9: 45722 | R9: 45714 | S9: 无 | T9: 无 | V9: Remark:大货最新版本/只需要空PDQ(PDQ可打平包/需配齐PDQ上原有的配件（列如-Demo-吸塑);备注：收到样品订单后尽快安排 ，注意样板品质质量要求要高于大货品质要求 ，送货时必须要附带送货单(没有送货单和QC检验合格报告的仓库一律拒绝收货)，请知悉，谢谢！ | W9: Angus | Z9: 94917-4.30 | AA9: 40 | AB9: =AA9-I9 -> 0 | AE9: # | AQ9: =I9 -> 40 | BT9: =BT8-BJ9 -> 113832 | BU9: =BU8-BK9 -> 113832 | BV9: =BV8-BL9 -> 113832 | BW9: =BW8-BM9 -> 113832 | BX9: =BX8-BN9 -> 113832 | BY9: =BY8-BO9 -> 113832 | BZ9: =BZ8-BP9 -> 113832 | CA9: =CA8-BQ9 -> 113832 | CB9: =CB8-BR9 -> 19377
A10: 45680 | B10: ALL BRANDS TOYS PTY LTD | C10: 澳大利亚 | D10: 4500156526 | E10: 83574 | F10: 4500156526-20 | G10: 77685GQ2-S001 | H10: 混搭恐龙27pcs/GQ2*2/箱 | I10: 3618 | J10: 0 | K10: 54 | L10: =I10/K10 -> 67 | M10: 45730 | N10: 45726 | O10: 东莞生产 | P10: pass | Q10: 3/26 截SI | R10: 45680 | S10: 无 | T10: 2/20进口商贴纸 | V10: 日期码格式：ZURU INC(BVI) 标准格式 日期：按实际生产日期 Packaging Info: 77685GQ2：MA_UPC版本包装（收缩膜和说明书, MA首选1L，如无1L可用多语且含英语的配套多语UPC包装）+ 1张客人通用进口商贴纸 Remark: 1.按实际生产日期; 2.出澳大利亚，请按照相应标准生产; | W10: Lydia Wu | X10: 0.9779 | Y10: =X10*I10 -> 3538.0422 | Z10: 94636-3.25 | AA10: =3101+75 -> 3176 | AB10: =AA10-I10 -> -442 | AC10: OK | AD10: 系统出单 | AE10: 77685GQ2-S001 | AF10: 已入 | AG10: =I10 -> 3618 | AH10: =I10 -> 3618 | AK10: =I10 -> 3618 | AN10: =I10 -> 3618 | AQ10: =I10/27 -> 134 | BJ10: =$I10*BJ$2 -> 442.82812 | BK10: =$I10*BK$2 -> 442.82812 | BL10: =$I10*BL$2 -> 442.82812 | BM10: =$I10*BM$2 -> 442.82812 | BN10: =$I10*BN$2 -> 442.82812 | BO10: =$I10*BO$2 -> 442.82812 | BP10: =$I10*BP$2 -> 442.82812 | BQ10: =$I10*BQ$2 -> 442.82812 | BR10: =$I10*BR$2 -> 75.375 | BT10: =BT9-BJ10 -> 113389.17 | BU10: =BU9-BK10 -> 113389.17 | BV10: =BV9-BL10 -> 113389.17 | BW10: =BW9-BM10 -> 113389.17 | BX10: =BX9-BN10 -> 113389.17 | BY10: =BY9-BO10 -> 113389.17 | BZ10: =BZ9-BP10 -> 113389.17 | CA10: =CA9-BQ10 -> 113389.17 | CB10: =CB9-BR10 -> 19301.625
A11: 45701 | B11: ZURU LLC | C11: 美国 | D11: 4500157378 | E11: 5200006139 | F11: 4500157378-20 | G11: 77723-S001-MTS | H11: 混搭恐龙2PK圆筒装 | I11: 492 | J11: 0 | K11: 12 | L11: =I11/K11 -> 41 | M11: 45734 | N11: 45730 | P11: pass | Q11: 3/28 交仓 | R11: 2/13外箱最长边不能超过25" （超过了，case pack只能为1） | S11: 无 | T11: 2/21空白贴纸 | V11: 日期码格式：ZURU INC(BVI) 标准格式 日期：按实际生产日期 Packaging Info: #77723=2PK STD #77685 PVC Tube. #77685 收缩膜MA 1L+空白贴纸覆盖UPC，空白贴纸图稿跟单提供。2PK铜板纸，收藏指南，说明书均为MA 5L标版。（两个球的配 比不能重复）。 Remark: 1.Amazon domestic 订单。出口美国。外箱最长边不能超过25" （超过了，case pack只能为1），不符合要求的大货，一律不接受。 2.无第三方验货/测试要求。 3.日期码使用ZURU标准版本。 | W11: SD24 | X11: 2.09 | Y11: =X11*I11 -> 1028.28 | Z11: ZB00056 | AA11: 492 | AB11: =AA11-I11 -> 0 | AC11: OK | AD11: 系统出单 | AE11: 77723-S001-MTS | AF11: 已入 | AG11: =I11*2 -> 984 | AH11: =I11*2 -> 984 | AK11: =I11*2 -> 984 | AN11: =I11*2 -> 984 | BF11: =I11 -> 492 | BG11: =I11 -> 492 | BJ11: =$I11*BJ$2*2 -> 120.4375 | BK11: =$I11*BK$2*2 -> 120.4375 | BL11: =$I11*BL$2*2 -> 120.4375 | BM11: =$I11*BM$2*2 -> 120.4375 | BN11: =$I11*BN$2*2 -> 120.4375 | BO11: =$I11*BO$2*2 -> 120.4375 | BP11: =$I11*BP$2*2 -> 120.4375 | BQ11: =$I11*BQ$2*2 -> 120.4375 | BR11: =$I11*BR$2*2 -> 20.5 | BT11: =BT10-BJ11 -> 113268.73 | BU11: =BU10-BK11 -> 113268.73 | BV11: =BV10-BL11 -> 113268.73 | BW11: =BW10-BM11 -> 113268.73 | BX11: =BX10-BN11 -> 113268.73 | BY11: =BY10-BO11 -> 113268.73 | BZ11: =BZ10-BP11 -> 113268.73 | CA11: =CA10-BQ11 -> 113268.73 | CB11: =CB10-BR11 -> 19281.125 | CD11: 2/17 已放MA 圆筒/彩纸/贴纸 | CE11: 10000 | CF11: 5000 | CH11: =CE11-I11 -> 9508 | CI11: =CF11-I11 -> 4508
A12: 45674 | B12: Smyths Toys EU HQ UC | C12: 德国 | D12: 4500156119 | F12: 4500156119-10 | G12: 77685GQ2-S002 | H12: 混搭恐龙27pcs/GQ2/箱 | I12: 10017 | J12: 0 | K12: 27 | L12: =I12/K12 -> 371 | M12: 45741 | N12: 45737 | P12: pass | Q12: 3/31 截SI | R12: 45674 | S12: 无 | T12: 无 | V12: 日期码格式：ZURU INC(BVI) 标准格式 日期：按实际生产日期 Packaging Info: 客版收缩膜(英法德意荷)翻单#4500155619 +客版5L slime bag 翻单#4500155619+MA 3L PDQ+MA5L(23L Warning)收藏指南+MA23L说明书+MA内袋 EAN # 4894680042612 Remark: 1. 此单出德国，需要满足Zuru Standard欧洲标准测试要求； 2. 请准时出货，推期会有罚款； 3. 出口欧洲，微塑料需符合法规； 4. 所有电子产品身上需要加字唛，为ZURU FRANCE 地址 (如无电子产品，或者产品布标有此地址，可忽略此信息) ZURU France 1/3, Rue d'Argenteuil 95210 SAINT-GRATIEN, FRANCE 5. 标准配比 | W12: Shirley Zhou | X12: 0.89 | Y12: =I12*X12 -> 8915.13 | Z12: 94676-3.31 | AA12: 10017 | AB12: =AA12-I12 -> 0 | AC12: 无 | AD12: 系统出单 | AE12: 77685GQ2-S002-客 | AF12: 已入 | AG12: =I12 -> 10017 | AJ12: =I12 -> 10017 | AM12: =I12 -> 10017 | AN12: =I12 -> 10017 | AR12: =I12/27 -> 371 | BJ12: =$I12*BJ$2 -> 1226.0391 | BK12: =$I12*BK$2 -> 1226.0391 | BL12: =$I12*BL$2 -> 1226.0391 | BM12: =$I12*BM$2 -> 1226.0391 | BN12: =$I12*BN$2 -> 1226.0391 | BO12: =$I12*BO$2 -> 1226.0391 | BP12: =$I12*BP$2 -> 1226.0391 | BQ12: =$I12*BQ$2 -> 1226.0391 | BR12: =$I12*BR$2 -> 208.6875 | BT12: =BT11-BJ12 -> 112042.7 | BU12: =BU11-BK12 -> 112042.7 | BV12: =BV11-BL12 -> 112042.7 | BW12: =BW11-BM12 -> 112042.7 | BX12: =BX11-BN12 -> 112042.7 | BY12: =BY11-BO12 -> 112042.7 | BZ12: =BZ11-BP12 -> 112042.7 | CA12: =CA11-BQ12 -> 112042.7 | CB12: =CB11-BR12 -> 19072.438
A13: 45670 | B13: Smyths Toys HQ UC UK | C13: 爱尔兰 | D13: 4500155619 | E13: PO4400458973 | F13: 4500155619-10 | G13: 77685GQ2-S002 | H13: 混搭恐龙27pcs/GQ2/箱 | I13: 8046 | J13: 0 | K13: 27 | L13: 298 | M13: 45741 | N13: 45737 | P13: pass | Q13: 3/27 截SI | R13: 45670 | S13: 无 | T13: 无 | V13: 日期码格式：ZURU INC(BVI) 标准格式 日期：按实际生产日期 Packaging Info: 77685GQ2：客版收缩膜(英法德意荷)+客版5L slime bag+MA 3L PDQ+MA5L(23L Warning)收藏指南+MA23L说明书 客户PO号码请参考remark Remark: 1）包装日期码按ZURU格式即可，请确保不迟于外箱日期码，可等于或者早于外箱日期码，必须为法定工作日，印刷前请先检查外箱日期码。 2）订单出英国，请注意检查产品及包装应带UKCA图标（14+产品除外），包装显示ZURU UK LTD/ZURU France地址信息，QC部门请查核，如有问题与跟单确认 3) 需要完全符合欧洲标准(符合微塑料法规)，否则不合法规会有客诉产生 | W13: Ula Zhao | X13: 0.89 | Y13: =I13*X13 -> 7160.94 | Z13: 94640-3.26 | AA13: =7452+594 -> 8046 | AB13: =AA13-I13 -> 0 | AC13: 无 | AD13: 系统出单 | AE13: 77685GQ2-S002-客 | AF13: 已入 | AG13: =I13 -> 8046 | AJ13: =I13 -> 8046 | AM13: =I13 -> 8046 | AN13: =I13 -> 8046 | AR13: =I13/27 -> 298 | BJ13: =$I13*BJ$2 -> 984.79687 | BK13: =$I13*BK$2 -> 984.79687 | BL13: =$I13*BL$2 -> 984.79687 | BM13: =$I13*BM$2 -> 984.79687 | BN13: =$I13*BN$2 -> 984.79687 | BO13: =$I13*BO$2 -> 984.79687 | BP13: =$I13*BP$2 -> 984.79687 | BQ13: =$I13*BQ$2 -> 984.79687 | BR13: =$I13*BR$2 -> 167.625 | BT13: =BT12-BJ13 -> 111057.9 | BU13: =BU12-BK13 -> 111057.9 | BV13: =BV12-BL13 -> 111057.9 | BW13: =BW12-BM13 -> 111057.9 | BX13: =BX12-BN13 -> 111057.9 | BY13: =BY12-BO13 -> 111057.9 | BZ13: =BZ12-BP13 -> 111057.9 | CA13: =CA12-BQ13 -> 111057.9 | CB13: =CB12-BR13 -> 18904.812
A14: 45670 | B14: Smyths Toys HQ UC UK | C14: 爱尔兰 | D14: 4500155619 | E14: PO4400458974 | F14: 4500155619-20 | G14: 77685GQ2-S002 | H14: 混搭恐龙27pcs/GQ2/箱 | I14: 2052 | J14: 0 | K14: 27 | L14: =I14/K14 -> 76 | M14: 45741 | N14: 45737 | P14: pass | Q14: 3/31 截SI | R14: 45670 | S14: 无 | T14: 无 | V14: 日期码格式：ZURU INC(BVI) 标准格式 日期：按实际生产日期 Packaging Info: 77685GQ2：客版收缩膜(英法德意荷)+客版5L slime bag+MA 3L PDQ+MA5L(23L Warning)收藏指南+MA23L说明书 客户PO号码请参考remark Remark: 1）包装日期码按ZURU格式即可，请确保不迟于外箱日期码，可等于或者早于外箱日期码，必须为法定工作日，印刷前请先检查外箱日期码。 2）订单出英国，请注意检查产品及包装应带UKCA图标（14+产品除外），包装显示ZURU UK LTD/ZURU France地址信息，QC部门请查核，如有问题与跟单确认 3) 需要完全符合欧洲标准(符合微塑料法规)，否则不合法规会有客诉产生 | W14: Ula Zhao | X14: 0.89 | Y14: =I14*X14 -> 1826.28 | Z14: 94667-3.29 | AA14: 2052 | AB14: =AA14-I14 -> 0 | AC14: 无 | AD14: 系统出单 | AE14: 77685GQ2-S002-客 | AF14: 已入 | AG14: =I14 -> 2052 | AJ14: =I14 -> 2052 | AM14: =I14 -> 2052 | AN14: =I14 -> 2052 | AR14: =I14/27 -> 76 | BJ14: =$I14*BJ$2 -> 251.15625 | BK14: =$I14*BK$2 -> 251.15625 | BL14: =$I14*BL$2 -> 251.15625 | BM14: =$I14*BM$2 -> 251.15625 | BN14: =$I14*BN$2 -> 251.15625 | BO14: =$I14*BO$2 -> 251.15625 | BP14: =$I14*BP$2 -> 251.15625 | BQ14: =$I14*BQ$2 -> 251.15625 | BR14: =$I14*BR$2 -> 42.75 | BT14: =BT13-BJ14 -> 110806.74 | BU14: =BU13-BK14 -> 110806.74 | BV14: =BV13-BL14 -> 110806.74 | BW14: =BW13-BM14 -> 110806.74 | BX14: =BX13-BN14 -> 110806.74 | BY14: =BY13-BO14 -> 110806.74 | BZ14: =BZ13-BP14 -> 110806.74 | CA14: =CA13-BQ14 -> 110806.74 | CB14: =CB13-BR14 -> 18862.062
A15: 45705 | B15: TARGET US | C15: 美国 | D15: 4500157763 | E15: 10001232830-0581 | F15: 4500157763-10 | G15: 77685GQ1-S002 | H15: 混搭恐龙13pcs/GQ1/箱 | I15: 18720 | J15: 0 | K15: 13 | L15: =I15/K15 -> 1440 | M15: 45770 | N15: 45766 | P15: pass | Q15: 6/9 客上柜 | R15: 45705 | S15: 无 | T15: 2/26条码箱贴纸客供+2/17 Event label贴纸 | U15: 已出样板 | V15: 日期码格式：ZURU INC(BVI) 标准格式 日期：按实际生产日期 Packaging Info: MA 1L 收缩膜+说明书, MA PDQ Remark: 1.77685GQ1-S002-5 SURPRISE-DINO MIX AND MATCH-SERIES 1-CAPSULE,13PCS/Gravity PDQ, 13PCS/PDQ/CTN。MA 1L 收缩膜+说明书, MA PDQ，产品UPC19305207905 2. 外箱正唛左上角位置粘贴条码箱贴纸，每箱只贴一张由ZURU订购,来料显示DPCI-087-26-6460, UPC 10193052079050. 3. 产品和包装上均要印刷tracking code信息，格式为ZURU常规格式。 4 .外箱正唛右侧空白位置粘贴一张Event label贴纸，由工厂自己订购。 5. 出货方式：货代自提，兴信出货。 | W15: Holly Zheng | X15: 0.765 | Y15: =X15*I15 -> 14320.8 | Z15: ZB00436-6.9 | AA15: 18720 | AB15: =AA15-I15 -> 0 | AC15: OK | AD15: 系统出单 | AE15: 77685GQ1-S002 | AF15: 已入 | AG15: =I15 -> 18720 | AH15: =I15 -> 18720 | AK15: =I15 -> 18720 | AN15: =I15 -> 18720 | AT15: =I15/13 -> 1440 | BJ15: =$I15*BJ$2 -> 2291.25 | BK15: =$I15*BK$2 -> 2291.25 | BL15: =$I15*BL$2 -> 2291.25 | BM15: =$I15*BM$2 -> 2291.25 | BN15: =$I15*BN$2 -> 2291.25 | BO15: =$I15*BO$2 -> 2291.25 | BP15: =$I15*BP$2 -> 2291.25 | BQ15: =$I15*BQ$2 -> 2291.25 | BR15: =$I15*BR$2 -> 390 | BT15: =BT14-BJ15 -> 108515.49 | BU15: =BU14-BK15 -> 108515.49 | BV15: =BV14-BL15 -> 108515.49 | BW15: =BW14-BM15 -> 108515.49 | BX15: =BX14-BN15 -> 108515.49 | BY15: =BY14-BO15 -> 108515.49 | BZ15: =BZ14-BP15 -> 108515.49 | CA15: =CA14-BQ15 -> 108515.49 | CB15: =CB14-BR15 -> 18472.062
A16: 45713 | B16: Ramp-s Corporation | C16: 菲律宾 | D16: 4500158563 | E16: PO-25-0003 | F16: 4500158563-10 | G16: 77685GQ2-S001 | H16: 混搭恐龙27pcs/GQ2*2/箱 | I16: 2052 | J16: 0 | K16: 54 | L16: =I16/K16 -> 38 | M16: 45749 | N16: 45745 | P16: pass | Q16: 4/3 截SI | R16: 45719 | S16: 无 | T16: 3/5 进口商贴纸 | V16: 日期码格式：ZURU INC(BVI) 标准格式 日期：按实际生产日期 Packaging Info: MA UPC包装+进口商贴纸,贴纸资料待提供 Remark | W16: Emma Wu | X16: 0.8048 | Y16: =X16*I16 -> 1651.4496 | Z16: 94696-4.3 | AA16: 2052 | AB16: =AA16-I16 -> 0 | AC16: OK | AD16: 系统出单 | AE16: 77685GQ2-S001 | AF16: 已入 | AG16: =I16 -> 2052 | AH16: =I16 -> 2052 | AK16: =I16 -> 2052 | AN16: =I16 -> 2052 | AQ16: =I16/27 -> 76 | BJ16: =$I16*BJ$2 -> 251.15625 | BK16: =$I16*BK$2 -> 251.15625 | BL16: =$I16*BL$2 -> 251.15625 | BM16: =$I16*BM$2 -> 251.15625 | BN16: =$I16*BN$2 -> 251.15625 | BO16: =$I16*BO$2 -> 251.15625 | BP16: =$I16*BP$2 -> 251.15625 | BQ16: =$I16*BQ$2 -> 251.15625 | BR16: =$I16*BR$2 -> 42.75 | BT16: =BT15-BJ16 -> 108264.34 | BU16: =BU15-BK16 -> 108264.34 | BV16: =BV15-BL16 -> 108264.34 | BW16: =BW15-BM16 -> 108264.34 | BX16: =BX15-BN16 -> 108264.34 | BY16: =BY15-BO16 -> 108264.34 | BZ16: =BZ15-BP16 -> 108264.34 | CA16: =CA15-BQ16 -> 108264.34 | CB16: =CB15-BR16 -> 18429.312
A17: 45719 | B17: THE WAREHOUSE LIMITED | C17: 新西兰 | D17: 4500159004 | E17: 28854700/1 | F17: 4500159004-10 | G17: 77685SK-S002 | H17: 混搭恐龙展示架带底座 | I17: 2508 | J17: 0 | K17: 66 | L17: =I17/K17 -> 38 | M17: 45756 | N17: 45751 | P17: PASS | Q17: 4/16 截SI | R17: 45719 | S17: 无 | T17: 无 | V17: 日期码格式：ZURU INC(BVI) 标准格式 日期：按实际生产日期 Packaging Info: MA UPC 英语包装（优先1L英语版本，或者3L/5L含英语都可） 此客人不接受易掉落或者剥落或者可直接触碰的闪粉，可降解也不行，但可以接受符合欧洲微塑料标准的珠光粉或者闪片。 Remark: | W17: Abby Liang | X17: 59.55 | Y17: =X17*L17 -> 2262.9 | Z17: 94964-5.10 | AA17: 2508 | AB17: =AA17-I17 -> 0 | AC17: 无 | AD17: 系统出单 | AE17: 77685SK-S002 | AF17: 已入 | AG17: =I17 -> 2508 | AH17: =I17 -> 2508 | AK17: =I17 -> 2508 | AN17: =I17 -> 2508 | BA17: =I17/66 -> 38 | BB17: =BA17 -> 38 | BJ17: =$I17*BJ$2 -> 306.96875 | BK17: =$I17*BK$2 -> 306.96875 | BL17: =$I17*BL$2 -> 306.96875 | BM17: =$I17*BM$2 -> 306.96875 | BN17: =$I17*BN$2 -> 306.96875 | BO17: =$I17*BO$2 -> 306.96875 | BP17: =$I17*BP$2 -> 306.96875 | BQ17: =$I17*BQ$2 -> 306.96875 | BR17: =$I17*BR$2 -> 52.25 | BT17: =BT16-BJ17 -> 107957.37 | BU17: =BU16-BK17 -> 107957.37 | BV17: =BV16-BL17 -> 107957.37 | BW17: =BW16-BM17 -> 107957.37 | BX17: =BX16-BN17 -> 107957.37 | BY17: =BY16-BO17 -> 107957.37 | BZ17: =BZ16-BP17 -> 107957.37 | CA17: =CA16-BQ17 -> 107957.37 | CB17: =CB16-BR17 -> 18377.062
A18: 45719 | B18: THE WAREHOUSE LIMITED | C18: 新西兰 | D18: 4500159005 | E18: 28854701/1 | F18: 4500159005-10 | G18: 77685SK-S002 | H18: 混搭恐龙展示架带底座 | I18: 792 | J18: 0 | K18: 66 | L18: =I18/K18 -> 12 | M18: 45756 | N18: 45751 | P18: PASS | R18: 45719 | S18: 无 | T18: 无 | V18: 日期码格式：ZURU INC(BVI) 标准格式 日期：按实际生产日期 Packaging Info: MA UPC 英语包装（优先1L英语版本，或者3L/5L含英语都可） 此客人不接受易掉落或者剥落或者可直接触碰的闪粉，可降解也不行，但可以接受符合欧洲微塑料标准的珠光粉或者闪片。 Remark: | W18: Abby Liang | X18: 59.55 | Y18: =X18*L18 -> 714.6 | Z18: 94965-5.10 | AA18: 792 | AB18: =AA18-I18 -> 0 | AC18: 无 | AD18: 系统出单 | AE18: 77685SK-S002 | AF18: 已入 | AG18: =I18 -> 792 | AH18: =I18 -> 792 | AK18: =I18 -> 792 | AN18: =I18 -> 792 | BA18: =I18/66 -> 12 | BB18: =BA18 -> 12 | BJ18: =$I18*BJ$2 -> 96.9375 | BK18: =$I18*BK$2 -> 96.9375 | BL18: =$I18*BL$2 -> 96.9375 | BM18: =$I18*BM$2 -> 96.9375 | BN18: =$I18*BN$2 -> 96.9375 | BO18: =$I18*BO$2 -> 96.9375 | BP18: =$I18*BP$2 -> 96.9375 | BQ18: =$I18*BQ$2 -> 96.9375 | BR18: =$I18*BR$2 -> 16.5 | BT18: =BT17-BJ18 -> 107860.43 | BU18: =BU17-BK18 -> 107860.43 | BV18: =BV17-BL18 -> 107860.43 | BW18: =BW17-BM18 -> 107860.43 | BX18: =BX17-BN18 -> 107860.43 | BY18: =BY17-BO18 -> 107860.43 | BZ18: =BZ17-BP18 -> 107860.43 | CA18: =CA17-BQ18 -> 107860.43 | CB18: =CB17-BR18 -> 18360.562
A19: 45713 | B19: Amazon ES | C19: 西班牙 | D19: 4500158469 | E19: Amazon ES: 4EASJCSI | F19: 4500158469-10 | G19: 77723-S001 | H19: 混搭恐龙2PK圆筒装 | I19: 492 | J19: 0 | K19: 12 | L19: =I19/K19 -> 41 | M19: 45757 | N19: 45754 | P19: PASS | Q19: 4/21 截SI | R19: 空白外箱（加印带Zuru字样的最新logo，除了邮包盒直接做外箱的产品） | S19: 有 | T19: 3/21 SSCC贴纸+空白贴纸 | V19: 日期码格式：ZURU INC(BVI) 标准格式 日期：按实际生产日期 Packaging Info: Amazon ES(77723) 1. 77723：2pk 77685 into pvc tube, 12tubes/ctn; MA 3L(3L warning EAN)A收缩膜+MA 1L(23L warning)A说明书+MA 1L A内袋+MA 5L(23L warning)A收藏指南+M A 5L A Slime胶袋+客版3L（5L warning UPC)PVC筒彩卡(含英法德意西警告语+UPC#+邮箱地址+FR/ES/IT环保标) 2. 最迟验货不得晚于2025/4/11; Remark: 1.空白外箱（加印带Zuru字样的最新logo，除了邮包盒直接做外箱的产品） + SSCC LABEL一张, 无箱唛，MADE IN CHINA 外箱只印一正一侧。箱唛资料按照给定的 标准去做即可，无需发回我方再行审批(新标准将另行通知)。 (SSCC LABEL竖贴在外箱正面的正中间，贴一面即可,贴纸离外箱边距必须至少3.2CM。如竖贴无法满足要求，则横贴。如横贴也无法满足要求，则竖贴，遮到ZURU lo go无影响), SSCC贴纸由工厂直接跟勤得采购或者工厂自行采购，每一张SSCC Label都是唯一且有不同流水及条码，且需要检查条码是否能正常扫描，另外，此贴纸 印刷不可出现模糊，溢出及粘胶不牢易脱落等现象，如工厂不按此要求导致贴纸有任何问题产生的罚款将由工厂承担一切责任 。 2.出往UK的产品+包装务必打上UKCA logo ，否则客人会退货且当地会有罚款。 3.订单必须经过ZURU QC验货并且通过后方可出货。 4.法国订单要求包装不使用矿物油，请按要求提供以下其中一份文件再出货 ，产品出到法国被相关部门抽检出现包装不符合此要求的，供应商需要为此承担责任， 故此请严格把关。 -油墨物质""由1 ~ 7个芳香环组成的MOAH""的包装检测报告，要求限值≤1.0%； -包装材料清单，包括包装油墨或物质的信息； -油墨制造商的证书； 5.每一批次出货只能有一个生产日期，不可多个生产日期混在同一批次出货；且邮包盒上必须统一加上日期码；外箱对于日期码没有硬性规定； 6.涉及到相关款式会有闪粉的或者微塑料的，请统一默认出无闪粉或者不含微塑料版本； 7.邮包盒及外箱封箱必须是工字型封箱方式； 8.5 Surprise or Mini Brands涉及包装是2个及2个以上的球入PVC桶包装时，单个球上若有UPC#或者EAN#，请用白色贴纸覆盖住； | W19: Crystal Chen | X19: 1.8938 | Y19: =X19*I19 -> 931.7496 | Z19: 94786-4.17 | AA19: 492 | AB19: =AA19-I19 -> 0 | AC19: OK | AD19: 系统出单 | AE19: 77723-S001 | AF19: 已入 | AG19: =I19*2 -> 984 | AH19: =I19*2 -> 984 | AL19: =I19*2 -> 984 | AN19: =I19*2 -> 984 | BF19: =I19 -> 492 | BG19: =I19 -> 492 | BJ19: =$I19*BJ$2*2 -> 120.4375 | BK19: =$I19*BK$2*2 -> 120.4375 | BL19: =$I19*BL$2*2 -> 120.4375 | BM19: =$I19*BM$2*2 -> 120.4375 | BN19: =$I19*BN$2*2 -> 120.4375 | BO19: =$I19*BO$2*2 -> 120.4375 | BP19: =$I19*BP$2*2 -> 120.4375 | BQ19: =$I19*BQ$2*2 -> 120.4375 | BR19: =$I19*BR$2*2 -> 20.5 | BT19: =BT18-BJ19 -> 107739.99 | BU19: =BU18-BK19 -> 107739.99 | BV19: =BV18-BL19 -> 107739.99 | BW19: =BW18-BM19 -> 107739.99 | BX19: =BX18-BN19 -> 107739.99 | BY19: =BY18-BO19 -> 107739.99 | BZ19: =BZ18-BP19 -> 107739.99 | CA19: =CA18-BQ19 -> 107739.99 | CB19: =CB18-BR19 -> 18340.062 | CD19: 2/17 已放MA 圆筒/彩纸/贴纸 | CH19: =CH11-I19 -> 9016 | CI19: =CI11-I19 -> 4016
A20: 45720 | B20: AMAZON UK | C20: 德国 | D20: 4500158578 | E20: Amazon DE: 1WYS31BD | F20: 4500158578-160 | G20: 77723-S001 | H20: 混搭恐龙2PK圆筒装 | I20: 744 | J20: 0 | K20: 12 | L20: =I20/K20 -> 62 | M20: 45757 | N20: 45754 | P20: PASS | Q20: 4/27 截SI | R20: 空白外箱（加印带Zuru字样的最新logo，除了邮包盒直接做外箱的产品） | S20: 有 | T20: 3/18 SSCC贴纸+空白贴纸 | V20: 日期码格式：ZURU INC(BVI) 标准格式 日期：按实际生产日期 Packaging Info: Amazon UK(15726BEK/15728BEG/15762ABDE)/DE(15726EK/15728B/15762A/77723)/FR(77723) 4. 77723: 2pk 77685 into pvc tube, 12tubes/ctn; MA 3L(3L warning EAN)A收缩膜+MA 1L(23L warning)A说明书+MA 1L A内袋+MA 5L(23L warning)A收藏指南+M A 5L A Slime胶袋+客版PVC筒彩卡(含英法德意西5L警告语+UPC#+邮箱地址+FR/ES/IT环保标，参考翻单PO#4500158469)； 5. 验货时间不迟于2025/4/11. Remark: 1.空白外箱（加印带Zuru字样的最新logo，除了邮包盒直接做外箱的产品） + SSCC LABEL一张, 无箱唛，MADE IN CHINA 外箱只印一正一侧。箱唛资料按照给定的 标准去做即可，无需发回我方再行审批(新标准将另行通知)。 (SSCC LABEL竖贴在外箱正面的正中间，贴一面即可,贴纸离外箱边距必须至少3.2CM。如竖贴无法满足要求，则横贴。如横贴也无法满足要求，则竖贴，遮到ZURU lo go无影响), SSCC贴纸由工厂直接跟勤得采购或者工厂自行采购，每一张SSCC Label都是唯一且有不同流水及条码，且需要检查条码是否能正常扫描，另外，此贴纸 印刷不可出现模糊，溢出及粘胶不牢易脱落等现象，如工厂不按此要求导致贴纸有任何问题产生的罚款将由工厂承担一切责任 。 2.出往UK的产品+包装务必打上UKCA logo ，否则客人会退货且当地会有罚款。 3.订单必须经过ZURU QC验货并且通过后方可出货。 4.法国订单要求包装不使用矿物油，请按要求提供以下其中一份文件再出货 ，产品出到法国被相关部门抽检出现包装不符合此要求的，供应商需要为此承担责任， 故此请严格把关。 -油墨物质""由1 ~ 7个芳香环组成的MOAH""的包装检测报告，要求限值≤1.0%； -包装材料清单，包括包装油墨或物质的信息； -油墨制造商的证书； 5.每一批次出货只能有一个生产日期，不可多个生产日期混在同一批次出货；且邮包盒上必须统一加上日期码；外箱对于日期码没有硬性规定； 6.涉及到相关款式会有闪粉的或者微塑料的，请统一默认出无闪粉或者不含微塑料版本； 7.邮包盒及外箱封箱必须是工字型封箱方式； 8.5 Surprise or Mini Brands涉及包装是2个及2个以上的球入PVC桶包装时，单个球上若有UPC#或者EAN#，请用白色贴纸覆盖住 | W20: Crystal Chen | X20: 1.8626 | Y20: =X20*I20 -> 1385.7744 | Z20: 94813-4.22 | AA20: 744 | AB20: =AA20-I20 -> 0 | AC20: OK | AD20: 系统出单 | AE20: 77723-S001 | AF20: 已入 | AG20: =I20*2 -> 1488 | AH20: =I20*2 -> 1488 | AL20: =I20*2 -> 1488 | AN20: =I20*2 -> 1488 | BF20: =I20 -> 744 | BG20: =I20 -> 744 | BJ20: =$I20*BJ$2*2 -> 182.125 | BK20: =$I20*BK$2*2 -> 182.125 | BL20: =$I20*BL$2*2 -> 182.125 | BM20: =$I20*BM$2*2 -> 182.125 | BN20: =$I20*BN$2*2 -> 182.125 | BO20: =$I20*BO$2*2 -> 182.125 | BP20: =$I20*BP$2*2 -> 182.125 | BQ20: =$I20*BQ$2*2 -> 182.125 | BR20: =$I20*BR$2*2 -> 31 | BT20: =BT19-BJ20 -> 107557.87 | BU20: =BU19-BK20 -> 107557.87 | BV20: =BV19-BL20 -> 107557.87 | BW20: =BW19-BM20 -> 107557.87 | BX20: =BX19-BN20 -> 107557.87 | BY20: =BY19-BO20 -> 107557.87 | BZ20: =BZ19-BP20 -> 107557.87 | CA20: =CA19-BQ20 -> 107557.87 | CB20: =CB19-BR20 -> 18309.062 | CD20: 2/17 已放MA 圆筒/彩纸/贴纸 | CH20: =CH19-I20 -> 8272 | CI20: =CI19-I20 -> 3272
A21: 45720 | B21: AMAZON UK | C21: 法国 | D21: 4500158578 | E21: Amazon FR: 1YINQXLS | F21: 4500158578-180 | G21: 77723-S001 | H21: 混搭恐龙2PK圆筒装 | I21: 492 | J21: 0 | K21: 12 | L21: =I21/K21 -> 41 | M21: 45757 | N21: 45754 | P21: PASS | Q21: 4/27 截SI | R21: 空白外箱（加印带Zuru字样的最新logo，除了邮包盒直接做外箱的产品） | S21: 有 | T21: 3/18 SSCC贴纸+空白贴纸 | V21: 日期码格式：ZURU INC(BVI) 标准格式 日期：按实际生产日期 Packaging Info: Amazon UK(15726BEK/15728BEG/15762ABDE)/DE(15726EK/15728B/15762A/77723)/FR(77723) 4. 77723: 2pk 77685 into pvc tube, 12tubes/ctn; MA 3L(3L warning EAN)A收缩膜+MA 1L(23L warning)A说明书+MA 1L A内袋+MA 5L(23L warning)A收藏指南+M A 5L A Slime胶袋+客版PVC筒彩卡(含英法德意西5L警告语+UPC#+邮箱地址+FR/ES/IT环保标，参考翻单PO#4500158469)； 5. 验货时间不迟于2025/4/11. Remark: 1.空白外箱（加印带Zuru字样的最新logo，除了邮包盒直接做外箱的产品） + SSCC LABEL一张, 无箱唛，MADE IN CHINA 外箱只印一正一侧。箱唛资料按照给定的 标准去做即可，无需发回我方再行审批(新标准将另行通知)。 (SSCC LABEL竖贴在外箱正面的正中间，贴一面即可,贴纸离外箱边距必须至少3.2CM。如竖贴无法满足要求，则横贴。如横贴也无法满足要求，则竖贴，遮到ZURU lo go无影响), SSCC贴纸由工厂直接跟勤得采购或者工厂自行采购，每一张SSCC Label都是唯一且有不同流水及条码，且需要检查条码是否能正常扫描，另外，此贴纸 印刷不可出现模糊，溢出及粘胶不牢易脱落等现象，如工厂不按此要求导致贴纸有任何问题产生的罚款将由工厂承担一切责任 。 2.出往UK的产品+包装务必打上UKCA logo ，否则客人会退货且当地会有罚款。 3.订单必须经过ZURU QC验货并且通过后方可出货。 4.法国订单要求包装不使用矿物油，请按要求提供以下其中一份文件再出货 ，产品出到法国被相关部门抽检出现包装不符合此要求的，供应商需要为此承担责任， 故此请严格把关。 -油墨物质""由1 ~ 7个芳香环组成的MOAH""的包装检测报告，要求限值≤1.0%； -包装材料清单，包括包装油墨或物质的信息； -油墨制造商的证书； 5.每一批次出货只能有一个生产日期，不可多个生产日期混在同一批次出货；且邮包盒上必须统一加上日期码；外箱对于日期码没有硬性规定； 6.涉及到相关款式会有闪粉的或者微塑料的，请统一默认出无闪粉或者不含微塑料版本； 7.邮包盒及外箱封箱必须是工字型封箱方式； 8.5 Surprise or Mini Brands涉及包装是2个及2个以上的球入PVC桶包装时，单个球上若有UPC#或者EAN#，请用白色贴纸覆盖住 | W21: Crystal Chen | X21: 1.8626 | Y21: =X21*I21 -> 916.3992 | Z21: 94834-4.24 | AA21: 492 | AB21: =AA21-I21 -> 0 | AC21: OK | AD21: 系统出单 | AE21: 77723-S001 | AF21: 已入 | AG21: =I21*2 -> 984 | AH21: =I21*2 -> 984 | AL21: =I21*2 -> 984 | AN21: =I21*2 -> 984 | BF21: =I21 -> 492 | BG21: =I21 -> 492 | BJ21: =$I21*BJ$2*2 -> 120.4375 | BK21: =$I21*BK$2*2 -> 120.4375 | BL21: =$I21*BL$2*2 -> 120.4375 | BM21: =$I21*BM$2*2 -> 120.4375 | BN21: =$I21*BN$2*2 -> 120.4375 | BO21: =$I21*BO$2*2 -> 120.4375 | BP21: =$I21*BP$2*2 -> 120.4375 | BQ21: =$I21*BQ$2*2 -> 120.4375 | BR21: =$I21*BR$2*2 -> 20.5 | BT21: =BT20-BJ21 -> 107437.43 | BU21: =BU20-BK21 -> 107437.43 | BV21: =BV20-BL21 -> 107437.43 | BW21: =BW20-BM21 -> 107437.43 | BX21: =BX20-BN21 -> 107437.43 | BY21: =BY20-BO21 -> 107437.43 | BZ21: =BZ20-BP21 -> 107437.43 | CA21: =CA20-BQ21 -> 107437.43 | CB21: =CB20-BR21 -> 18288.562 | CD21: 2/17 已放MA 圆筒/彩纸/贴纸 | CH21: =CH20-I21 -> 7780 | CI21: =CI20-I21 -> 2780
A22: 45737 | B22: ASIA GOAL LIMITED | C22: 香港 | D22: 4500160929 | E22: AG240425-HK | F22: 4500160929-20 | G22: 77685GQ1-S001 | H22: 混搭恐龙13pcs/GQ1*4/箱 | I22: 780 | J22: 0 | K22: 52 | L22: =I22/K22 -> 15 | M22: 45761 | N22: 45757 | P22: pass | Q22: 4/16 截SI | R22: 45737 | S22: 无 | T22: 4/3客供警语贴纸 | V22: 日期码格式：ZURU INC(BVI) 标准格式 日期：按实际生产日期 Packaging Info: 71152：MA 1L PKG， MA 说明书+客供警语贴纸 77685GQ1：MA 1L PKG, MA PDQ, MA 收藏指南+4张客供警语贴纸 (1张贴球底部，1张贴收藏指南，1张贴说明书上，1张贴口水胶袋子上) Remark: 此单出香港 | W22: Doris Shou | X22: 0.8533 | Y22: =X22*I22 -> 665.574 | Z22: 94777-4.16 | AA22: 780 | AB22: =AA22-I22 -> 0 | AC22: OK | AD22: 系统出单 | AE22: 77685GQ1-S001 | AF22: 已入 | AG22: =I22 -> 780 | AH22: =I22 -> 780 | AK22: =I22 -> 780 | AN22: =I22 -> 780 | AT22: =I22/13 -> 60 | BJ22: =$I22*BJ$2 -> 95.46875 | BK22: =$I22*BK$2 -> 95.46875 | BL22: =$I22*BL$2 -> 95.46875 | BM22: =$I22*BM$2 -> 95.46875 | BN22: =$I22*BN$2 -> 95.46875 | BO22: =$I22*BO$2 -> 95.46875 | BP22: =$I22*BP$2 -> 95.46875 | BQ22: =$I22*BQ$2 -> 95.46875 | BR22: =$I22*BR$2 -> 16.25 | BT22: =BT21-BJ22 -> 107341.96 | BU22: =BU21-BK22 -> 107341.96 | BV22: =BV21-BL22 -> 107341.96 | BW22: =BW21-BM22 -> 107341.96 | BX22: =BX21-BN22 -> 107341.96 | BY22: =BY21-BO22 -> 107341.96 | BZ22: =BZ21-BP22 -> 107341.96 | CA22: =CA21-BQ22 -> 107341.96 | CB22: =CB21-BR22 -> 18272.312
A23: 45720 | B23: HARVEY WHOLESALE LTD | C23: 新西兰 | D23: 4500159074 | E23: 3002 | F23: 4500159074-10 | G23: 77685GQ2-S002 | H23: 混搭恐龙27pcs/GQ2/箱 | I23: 1350 | J23: 0 | K23: 27 | L23: =I23/K23 -> 50 | M23: 45763 | N23: 45758 | P23: pass | Q23: 4/17 截SI | R23: 45720 | S23: 无 | T23: 无 | V23: 日期码格式：ZURU INC(BVI) 标准格式 日期：按实际生产日期 Packaging Info: Remark: MA UPC 英语包装（优先1L英语版本,或者3L/L含英语即可 | W23: Abby Liang | X23: 0.89 | Y23: =X23*I23 -> 1201.5 | Z23: 94768-4.15 | AA23: 1350 | AB23: =AA23-I23 -> 0 | AC23: 无 | AD23: 系统出单 | AE23: 77685GQ2-S002 | AF23: 已入 | AG23: =I23 -> 1350 | AH23: =I23 -> 1350 | AK23: =I23 -> 1350 | AN23: =I23 -> 1350 | AQ23: =I23/27 -> 50 | BJ23: =$I23*BJ$2 -> 165.23438 | BK23: =$I23*BK$2 -> 165.23438 | BL23: =$I23*BL$2 -> 165.23438 | BM23: =$I23*BM$2 -> 165.23438 | BN23: =$I23*BN$2 -> 165.23438 | BO23: =$I23*BO$2 -> 165.23438 | BP23: =$I23*BP$2 -> 165.23438 | BQ23: =$I23*BQ$2 -> 165.23438 | BR23: =$I23*BR$2 -> 28.125 | BT23: =BT22-BJ23 -> 107176.73 | BU23: =BU22-BK23 -> 107176.73 | BV23: =BV22-BL23 -> 107176.73 | BW23: =BW22-BM23 -> 107176.73 | BX23: =BX22-BN23 -> 107176.73 | BY23: =BY22-BO23 -> 107176.73 | BZ23: =BZ22-BP23 -> 107176.73 | CA23: =CA22-BQ23 -> 107176.73 | CB23: =CB22-BR23 -> 18244.188
A24: 45733 | B24: Distruibuciones Universales, SA - D | C24: 洪都拉斯 | D24: 4500160421 | F24: 4500160421-120 | G24: 77685GQ2-S001 | H24: 混搭恐龙27pcs/GQ2*2/箱 | I24: 378 | J24: 0 | K24: 54 | L24: =I24/K24 -> 7 | M24: 45768 | N24: 45764 | P24: 自检 | Q24: 4/22 截SI | R24: 45736 | S24: 无 | T24: 3/25 UPC贴纸 | V24: 日期码格式：ZURU INC(BVI) 标准格式 日期：按实际生产日期 Packaging Info: 77685GQ2: MA多语EAN包装+UPC贴纸+MA多语收藏指南+MA多语PDQ+箱唛 Remark: | W24: Ava Liang | X24: 0.9779 | Y24: =X24*I24 -> 369.6462 | Z24: 94795-4.18 | AA24: 378 | AB24: =AA24-I24 -> 0 | AC24: OK | AD24: 系统出单 | AE24: 77685GQ2-S001-3L | AF24: 已入 | AG24: =I24 -> 378 | AH24: =I24 -> 378 | AL24: =I24 -> 378 | AN24: =I24 -> 378 | AR24: =I24/27 -> 14 | BJ24: =$I24*BJ$2 -> 46.265625 | BK24: =$I24*BK$2 -> 46.265625 | BL24: =$I24*BL$2 -> 46.265625 | BM24: =$I24*BM$2 -> 46.265625 | BN24: =$I24*BN$2 -> 46.265625 | BO24: =$I24*BO$2 -> 46.265625 | BP24: =$I24*BP$2 -> 46.265625 | BQ24: =$I24*BQ$2 -> 46.265625 | BR24: =$I24*BR$2 -> 7.875 | BT24: =BT23-BJ24 -> 107130.46 | BU24: =BU23-BK24 -> 107130.46 | BV24: =BV23-BL24 -> 107130.46 | BW24: =BW23-BM24 -> 107130.46 | BX24: =BX23-BN24 -> 107130.46 | BY24: =BY23-BO24 -> 107130.46 | BZ24: =BZ23-BP24 -> 107130.46 | CA24: =CA23-BQ24 -> 107130.46 | CB24: =CB23-BR24 -> 18236.312
A25: 45749 | D25: ZMPO250285 | G25: 77685-S001 | H25: 60套散件 | I25: 60 | J25: 0 | K25: 24 | L25: =I25/K25 -> 2.5 | M25: 45768 | N25: 45764 | P25: # | R25: 45749 | S25: 无 | T25: 无 | V25: Remark:大货最新版本/只需要齐全套散件/麻烦用胶袋分装好一套为一袋/箱唛参照邮件附件;备注：收到样品订单后尽快安排 ，注意样板品质质量要求要高于大货品质要求 ，送货时必须要附带送货单(没有送货单和QC检验合格报告的仓库一律拒绝收货)，请知悉，谢谢！ | W25: Angus | Z25: 94916-4.30 | AA25: 60 | AB25: =AA25-I25 -> 0 | AC25: 无 | AE25: # | BJ25: 60 | BK25: 60 | BL25: 60 | BM25: 60 | BN25: 60 | BO25: 60 | BP25: 60 | BQ25: 60 | BR25: 60 | BT25: =BT24-BJ25 -> 107070.46 | BU25: =BU24-BK25 -> 107070.46 | BV25: =BV24-BL25 -> 107070.46 | BW25: =BW24-BM25 -> 107070.46 | BX25: =BX24-BN25 -> 107070.46 | BY25: =BY24-BO25 -> 107070.46 | BZ25: =BZ24-BP25 -> 107070.46 | CA25: =CA24-BQ25 -> 107070.46 | CB25: =CB24-BR25 -> 18176.312
A26: 45749 | D26: ZMPO250285 | G26: 77685GQ1-S001 | H26: 50个满PDQ(650PCS) | I26: 650 | J26: 0 | K26: 52 | L26: =I26/K26 -> 12.5 | M26: 45768 | N26: 45764 | P26: pass | R26: 45749 | S26: 无 | T26: 无 | V26: Remark:大货最新版本/产品按大货比例/大货标准箱装箱/箱唛参照邮件附件;备注：收到样品订单后尽快安排 ，注意样板品质质量要求要高于大货品质要求 ，送货时必须要附带送货单(没有送货单和QC检验合格报告的仓库一律拒绝收货)，请知悉，谢谢！ | W26: Angus | Z26: 94916-4.30 | AA26: 650 | AB26: =AA26-I26 -> 0 | AC26: 无 | AD26: 系统出单 | AE26: 77685GQ1-S001 | AF26: 已入 | AG26: =I26 -> 650 | AH26: =I26 -> 650 | AK26: =I26 -> 650 | AN26: =I26 -> 650 | AT26: =I26/13 -> 50 | BJ26: =$I26*BJ$2 -> 79.557292 | BK26: =$I26*BK$2 -> 79.557292 | BL26: =$I26*BL$2 -> 79.557292 | BM26: =$I26*BM$2 -> 79.557292 | BN26: =$I26*BN$2 -> 79.557292 | BO26: =$I26*BO$2 -> 79.557292 | BP26: =$I26*BP$2 -> 79.557292 | BQ26: =$I26*BQ$2 -> 79.557292 | BR26: =$I26*BR$2 -> 13.541667 | BT26: =BT25-BJ26 -> 106990.9 | BU26: =BU25-BK26 -> 106990.9 | BV26: =BV25-BL26 -> 106990.9 | BW26: =BW25-BM26 -> 106990.9 | BX26: =BX25-BN26 -> 106990.9 | BY26: =BY25-BO26 -> 106990.9 | BZ26: =BZ25-BP26 -> 106990.9 | CA26: =CA25-BQ26 -> 106990.9 | CB26: =CB25-BR26 -> 18162.771
A27: 45749 | D27: ZMPO250285 | G27: 77685GQ2-S001 | H27: 50个满PDQ(1350PCS) | I27: 1350 | J27: 0 | K27: 54 | L27: =I27/K27 -> 25 | M27: 45768 | N27: 45764 | P27: pass | R27: 45749 | S27: 无 | T27: 无 | V27: Remark:大货最新版本/产品按大货比例/大货标准箱装箱/箱唛参照邮件附件;备注：收到样品订单后尽快安排 ，注意样板品质质量要求要高于大货品质要求 ，送货时必须要附带送货单(没有送货单和QC检验合格报告的仓库一律拒绝收货)，请知悉，谢谢！ | W27: Angus | Z27: 94916-4.30 | AA27: 1350 | AB27: =AA27-I27 -> 0 | AC27: 无 | AD27: 系统出单 | AE27: 77685GQ2-S001 | AF27: 已入 | AG27: =I27 -> 1350 | AH27: =I27 -> 1350 | AK27: =I27 -> 1350 | AN27: =I27 -> 1350 | AQ27: =I27/27 -> 50 | BJ27: =$I27*BJ$2 -> 165.23438 | BK27: =$I27*BK$2 -> 165.23438 | BL27: =$I27*BL$2 -> 165.23438 | BM27: =$I27*BM$2 -> 165.23438 | BN27: =$I27*BN$2 -> 165.23438 | BO27: =$I27*BO$2 -> 165.23438 | BP27: =$I27*BP$2 -> 165.23438 | BQ27: =$I27*BQ$2 -> 165.23438 | BR27: =$I27*BR$2 -> 28.125 | BT27: =BT26-BJ27 -> 106825.67 | BU27: =BU26-BK27 -> 106825.67 | BV27: =BV26-BL27 -> 106825.67 | BW27: =BW26-BM27 -> 106825.67 | BX27: =BX26-BN27 -> 106825.67 | BY27: =BY26-BO27 -> 106825.67 | BZ27: =BZ26-BP27 -> 106825.67 | CA27: =CA26-BQ27 -> 106825.67 | CB27: =CB26-BR27 -> 18134.646
A28: 45729 | B28: Babyhouse | C28: 乌兹别克斯坦 | D28: 4500159866 | F28: 4500159866-10 | G28: 77685GQ1-S001 | H28: 混搭恐龙13pcs/GQ1*4/箱 | I28: 208 | J28: 0 | K28: 52 | L28: =I28/K28 -> 4 | M28: 45769 | N28: 45765 | P28: 自检 | Q28: 4/22 客上柜 | R28: 45729 | S28: 无 | T28: 3/14 进口商贴纸 | V28: 日期码格式：ZURU INC(BVI) 标准格式 日期：按实际生产日期 Packaging Info: 77685: 1L MA 收缩膜 + 进口商贴纸 ; MA 说明书/指南（如有）; Remark: 标准配比 | W28: Ann Zhang | X28: 0.945 | Y28: =X28*I28 -> 196.56 | Z28: 94879-4.29 | AA28: 208 | AB28: =AA28-I28 -> 0 | AC28: OK | AD28: 系统出单 | AE28: 77685GQ1-S001 | AF28: 已入 | AG28: =I28 -> 208 | AH28: =I28 -> 208 | AK28: =I28 -> 208 | AN28: =I28 -> 208 | AT28: =I28/13 -> 16 | BJ28: =$I28*BJ$2 -> 25.458333 | BK28: =$I28*BK$2 -> 25.458333 | BL28: =$I28*BL$2 -> 25.458333 | BM28: =$I28*BM$2 -> 25.458333 | BN28: =$I28*BN$2 -> 25.458333 | BO28: =$I28*BO$2 -> 25.458333 | BP28: =$I28*BP$2 -> 25.458333 | BQ28: =$I28*BQ$2 -> 25.458333 | BR28: =$I28*BR$2 -> 4.3333333 | BT28: =BT27-BJ28 -> 106800.21 | BU28: =BU27-BK28 -> 106800.21 | BV28: =BV27-BL28 -> 106800.21 | BW28: =BW27-BM28 -> 106800.21 | BX28: =BX27-BN28 -> 106800.21 | BY28: =BY27-BO28 -> 106800.21 | BZ28: =BZ27-BP28 -> 106800.21 | CA28: =CA27-BQ28 -> 106800.21 | CB28: =CB27-BR28 -> 18130.312
A29: 45737 | B29: ASIA GOAL LIMITED TAIWAN BRANCH (H. | C29: 台湾 | D29: 4500160940 | E29: AG240426-TW | F29: 4500160940-10 | G29: 77685GQ1-S001 | H29: 混搭恐龙13pcs/GQ1*4/箱 | I29: 780 | J29: 0 | K29: 52 | L29: =I29/K29 -> 15 | M29: 45772 | N29: 45768 | P29: pass | Q29: 4/29 截SI | R29: 45737 | S29: 无 | T29: 3.28警语贴纸 | V29: 日期码格式：ZURU INC(BVI) 标准格式 日期：按实际生产日期 Packaging Info: MA 1L PKG, MA 1L PDQ +MA 收藏指南说明书+1张警语贴纸（贴球底部） Remark: 此单出台湾 | W29: Doris Shou | X29: 0.945 | Y29: =X29*I29 -> 737.1 | Z29: 94842-4.25 | AA29: 780 | AB29: =AA29-I29 -> 0 | AC29: OK | AD29: 系统出单 | AE29: 77685GQ1-S001 | AF29: 已入 | AG29: =I29 -> 780 | AH29: =I29 -> 780 | AK29: =I29 -> 780 | AN29: =I29 -> 780 | AT29: =I29/13 -> 60 | BJ29: =$I29*BJ$2 -> 95.46875 | BK29: =$I29*BK$2 -> 95.46875 | BL29: =$I29*BL$2 -> 95.46875 | BM29: =$I29*BM$2 -> 95.46875 | BN29: =$I29*BN$2 -> 95.46875 | BO29: =$I29*BO$2 -> 95.46875 | BP29: =$I29*BP$2 -> 95.46875 | BQ29: =$I29*BQ$2 -> 95.46875 | BR29: =$I29*BR$2 -> 16.25 | BT29: =BT28-BJ29 -> 106704.74 | BU29: =BU28-BK29 -> 106704.74 | BV29: =BV28-BL29 -> 106704.74 | BW29: =BW28-BM29 -> 106704.74 | BX29: =BX28-BN29 -> 106704.74 | BY29: =BY28-BO29 -> 106704.74 | BZ29: =BZ28-BP29 -> 106704.74 | CA29: =CA28-BQ29 -> 106704.74 | CB29: =CB28-BR29 -> 18114.062
A30: 45726 | B30: WAL-MART STORES INC. USA | C30: 美国 | D30: 4500159701 | E30: 0904512381 | F30: 4500159701-10 | G30: 77685SLB-S001 | H30: 混搭恐龙卡板装12pcs/GQ4/CTN**96/Slip Sheet | I30: 1152 | J30: 0 | K30: 1152 | L30: =I30/K30 -> 1 | M30: 45770 | N30: 45768 | O30: 4/23 第三方抽办+验货 | P30: pass | Q30: 5/15 截SI | R30: 首单，3/25 | S30: 有 | T30: 3/21 RFID+艾利贴纸（不干胶贴纸）和一张普通贴纸（A4纸） | V30: 日期码格式：ZURU DGYYYYMMDD CHINA(日期避开周末和法定节假日即可） 日期：按实际生产日期 Packaging Info: 77685SLB-S001： 1.包装要求： MA 1L A版收缩膜+MA A版纸袋+MA 5L A版收藏指南+MA A版slime bag+客版1L PDQ 每pcs产品上要贴1张RFID贴纸，贴纸由ZURU提供，贴纸位置请严格按照我们签回的签板； Remark: 77685SLB-S001： 1.包装要求： MA 1L A版收缩膜+MA A版纸袋+MA 5L A版收藏指南+MA A版slime bag+客版1L PDQ 每pcs产品上要贴1张RFID贴纸，贴纸由ZURU提供，贴纸位置请严格按照我们签回的签板； 2. 外箱印刷带条码的RFID箱唛：RFID紫色色带+WM Dept.图标+RFID图标+ITF-14条码，四面右下角印刷ZURU logo, ITFF条码只印刷在正唛一面，在加印的时候确保 条形码能扫描出来，外箱侧面任一角落加印："MADE IN CHINA" 字样； 3. 每个slip sheet上面贴一张艾利贴纸（不干胶贴纸）和一张普通贴纸（A4纸），slip sheet打印的普通贴纸的尺寸不能比艾利贴纸小，普通贴纸内容见附件； 4. 在产品上和包装上要有日期码、以及要有MADE IN CHINA和ZURU字样； 5. 产品如有扎带口要剪平，不能刮手。 6. 此单需要抽板和验货，抽板时间预计4/23，请多备料 7. 此单以slip sheet出货，77685：1152pcs/96CTN/Slip Sheet | W30: Maggie Xie | X30: 903.2128 | Y30: =X30*L30 -> 903.2128 | Z30: ZB00268-5.16 | AA30: 1152 | AB30: =AA30-I30 -> 0 | AD30: 系统出单 | AE30: 77685SLB-S001 | AF30: 已入 | AG30: =I30 -> 1152 | AH30: =I30 -> 1152 | AK30: =I30 -> 1152 | AN30: =I30 -> 1152 | AV30: =I30/12 -> 96 | BJ30: =$I30*BJ$2 -> 141 | BK30: =$I30*BK$2 -> 141 | BL30: =$I30*BL$2 -> 141 | BM30: =$I30*BM$2 -> 141 | BN30: =$I30*BN$2 -> 141 | BO30: =$I30*BO$2 -> 141 | BP30: =$I30*BP$2 -> 141 | BQ30: =$I30*BQ$2 -> 141 | BR30: =$I30*BR$2 -> 24 | BT30: =BT29-BJ30 -> 106563.74 | BU30: =BU29-BK30 -> 106563.74 | BV30: =BV29-BL30 -> 106563.74 | BW30: =BW29-BM30 -> 106563.74 | BX30: =BX29-BN30 -> 106563.74 | BY30: =BY29-BO30 -> 106563.74 | BZ30: =BZ29-BP30 -> 106563.74 | CA30: =CA29-BQ30 -> 106563.74 | CB30: =CB29-BR30 -> 18090.062
A31: 45735 | B31: MTA Trade | C31: 哈萨克斯坦 | D31: 4500160671 | F31: 4500160671-90 | G31: 77685GQ1-S001 | H31: 混搭恐龙13pcs/GQ1*4/箱 | I31: 312 | J31: 0 | K31: 52 | L31: =I31/K31 -> 6 | M31: 45772 | N31: 45768 | P31: 自检 | Q31: 4/25 客自提 | R31: 45735 | S31: 无 | T31: 3/28进口商贴纸 | V31: 日期码格式：ZURU INC(BVI) 标准格式 日期：按实际生产日期 Packaging Info: 77685GQ1:MA UPC 收缩膜（优先1L)+进口商贴纸;MA指南;MA PDQ(优先1L) Remark: 77685GQ1 Rare ratio:1/48 标准配比 | W31: Cora Zhou | X31: 0.7909 | Y31: =X31*I31 -> 246.7608 | Z31: 94843-4.25 | AA31: 312 | AB31: =AA31-I31 -> 0 | AC31: OK | AD31: 系统出单 | AE31: 77685GQ1-S001 | AF31: 已入 | AG31: =I31 -> 312 | AH31: =I31 -> 312 | AK31: =I31 -> 312 | AN31: =I31 -> 312 | AT31: =I31/13 -> 24 | BJ31: =$I31*BJ$2 -> 38.1875 | BK31: =$I31*BK$2 -> 38.1875 | BL31: =$I31*BL$2 -> 38.1875 | BM31: =$I31*BM$2 -> 38.1875 | BN31: =$I31*BN$2 -> 38.1875 | BO31: =$I31*BO$2 -> 38.1875 | BP31: =$I31*BP$2 -> 38.1875 | BQ31: =$I31*BQ$2 -> 38.1875 | BR31: =$I31*BR$2 -> 6.5 | BT31: =BT30-BJ31 -> 106525.55 | BU31: =BU30-BK31 -> 106525.55 | BV31: =BV30-BL31 -> 106525.55 | BW31: =BW30-BM31 -> 106525.55 | BX31: =BX30-BN31 -> 106525.55 | BY31: =BY30-BO31 -> 106525.55 | BZ31: =BZ30-BP31 -> 106525.55 | CA31: =CA30-BQ31 -> 106525.55 | CB31: =CB30-BR31 -> 18083.562
A32: 45695 | B32: SMYTHS TOYS HQ UC | C32: 法国 | D32: 4500156863 | E32: 4400463048 | F32: 4500156863-10 | G32: 77685GQ2-S002 | H32: 混搭恐龙27pcs/GQ2/箱 | I32: 4023 | J32: 0 | K32: 27 | L32: =I32/K32 -> 149 | M32: 45775 | N32: 45771 | P32: pass | Q32: 5/20 截SI | R32: 45696 | S32: 无 | T32: 无 | V32: 日期码格式：ZURU INC(BVI) 标准格式 日期：按实际生产日期 Packaging Info: 77685GQ2：客版收缩膜(英法德意荷)+客版5L slime bag+MA 3L PDQ+MA5L(23L Warning)收藏指南+MA23L说明书(客版翻4500155619) Remark: 1. 此单出法国，所有包装都需要含有法语，需要满足Zuru Standard欧洲标准测试要求； 2. 请准时出货，推期会有罚款； 3. 所有出口法国的产品, 法规规定禁止在包装和共公众用的印刷品中使用矿物油中含有的物质, 包装印刷油墨中含有的MOAH/MOSH的质量浓度不能超过1%, 否则出 货到法国被抽检出现问题, 供应商需要对此负责; | W32: Ula Zhao | X32: 0.89 | Y32: =X32*I32 -> 3580.47 | Z32: 94996-5.16 | AA32: 4023 | AB32: =AA32-I32 -> 0 | AC32: 无 | AD32: 系统出单 | AE32: 77685GQ2-S002-客 | AF32: 已入 | AG32: =I32 -> 4023 | AJ32: =I32 -> 4023 | AM32: =I32 -> 4023 | AN32: =I32 -> 4023 | AR32: =I32/27 -> 149 | BJ32: =$I32*BJ$2 -> 492.39844 | BK32: =$I32*BK$2 -> 492.39844 | BL32: =$I32*BL$2 -> 492.39844 | BM32: =$I32*BM$2 -> 492.39844 | BN32: =$I32*BN$2 -> 492.39844 | BO32: =$I32*BO$2 -> 492.39844 | BP32: =$I32*BP$2 -> 492.39844 | BQ32: =$I32*BQ$2 -> 492.39844 | BR32: =$I32*BR$2 -> 83.8125 | BT32: =BT31-BJ32 -> 106033.16 | BU32: =BU31-BK32 -> 106033.16 | BV32: =BV31-BL32 -> 106033.16 | BW32: =BW31-BM32 -> 106033.16 | BX32: =BX31-BN32 -> 106033.16 | BY32: =BY31-BO32 -> 106033.16 | BZ32: =BZ31-BP32 -> 106033.16 | CA32: =CA31-BQ32 -> 106033.16 | CB32: =CB31-BR32 -> 17999.75
A33: 45730 | B33: Andrés Dauhajre SA (LA NOVIA DE VIL | C33: 多米尼加共和国 | D33: 4500160345 | F33: 4500160345-90 | G33: 77685GQ2-S001 | H33: 混搭恐龙27pcs/GQ2*2/箱 | I33: 108 | J33: 0 | K33: 54 | L33: =I33/K33 -> 2 | M33: 45776 | N33: 45772 | P33: 自检 | R33: 45743 | S33: 无 | T33: 3/31 UPC贴纸 | V33: 日期码格式：ZURU INC(BVI) 标准格式 日期：按实际生产日期 Packaging Info: 77685GQ2: MA多语EAN包装+UPC贴纸+MA多语收藏指南+MA多语PDQ+箱唛 Remark: | W33: Ava Liang | X33: 0.7967 | Y33: =X33*I33 -> 86.0436 | Z33: 94881-4.29 | AA33: 108 | AB33: =AA33-I33 -> 0 | AC33: OK | AD33: 系统出单 | AE33: 77685GQ2-S001-3L | AF33: 已入 | AG33: =I33 -> 108 | AH33: =I33 -> 108 | AL33: =I33 -> 108 | AN33: =I33 -> 108 | AR33: =I33/27 -> 4 | BJ33: =$I33*BJ$2 -> 13.21875 | BK33: =$I33*BK$2 -> 13.21875 | BL33: =$I33*BL$2 -> 13.21875 | BM33: =$I33*BM$2 -> 13.21875 | BN33: =$I33*BN$2 -> 13.21875 | BO33: =$I33*BO$2 -> 13.21875 | BP33: =$I33*BP$2 -> 13.21875 | BQ33: =$I33*BQ$2 -> 13.21875 | BR33: =$I33*BR$2 -> 2.25 | BT33: =BT32-BJ33 -> 106019.94 | BU33: =BU32-BK33 -> 106019.94 | BV33: =BV32-BL33 -> 106019.94 | BW33: =BW32-BM33 -> 106019.94 | BX33: =BX32-BN33 -> 106019.94 | BY33: =BY32-BO33 -> 106019.94 | BZ33: =BZ32-BP33 -> 106019.94 | CA33: =CA32-BQ33 -> 106019.94 | CB33: =CB32-BR33 -> 17997.5
A34: 45734 | B34: ZURU LLC | C34: 美国 | D34: 4500160498 | E34: B0DS4YBF4S | F34: 4500160498-60 | G34: 77723-S001-MTS | H34: 混搭恐龙2PK圆筒装 | I34: 756 | J34: 0 | K34: 12 | L34: =I34/K34 -> 63 | M34: 45777 | N34: 45773 | P34: 自检 | Q34: 4/30 客上柜 | R34: 3/18 外箱最长边不能超过25" （超过了，case pack只能为1） | S34: 无 | T34: 2/21空白贴纸 | V34: 日期码格式：ZURU INC(BVI) 标准格式 日期：按实际生产日期 Packaging Info: #77723：2PK STD 77685 PVC Tube. MA 1L UPC版本+空白UPC贴纸，3L 铜版纸和空白贴纸跟翻单#4500157378。收藏指南，说明书均为MA 5L标版。（两个球的配比不 能重复）。 Remark: 1.Amazon domestic 订单。出口美国。外箱最长边不能超过25" （超过了，case pack只能为1），不符合要求的大货，一律不接受。 2.无第三方验货/测试要求。 3.日期码使用ZURU标准版本。 4.邮包盒要印刷日期码。 | W34: Kelly Shen/Mia Pan/P | X34: 2.09 | Y34: =X34*I34 -> 1580.04 | Z34: ZB00241-5.13 | AA34: 756 | AB34: =AA34-I34 -> 0 | AC34: OK | AD34: 系统出单 | AE34: 77723-S001-MTS | AF34: 已入 | AG34: =I34*2 -> 1512 | AH34: =I34*2 -> 1512 | AK34: =I34*2 -> 1512 | AN34: =I34*2 -> 1512 | BF34: =I34 -> 756 | BG34: =I34 -> 756 | BJ34: =$I34*BJ$2*2 -> 185.0625 | BK34: =$I34*BK$2*2 -> 185.0625 | BL34: =$I34*BL$2*2 -> 185.0625 | BM34: =$I34*BM$2*2 -> 185.0625 | BN34: =$I34*BN$2*2 -> 185.0625 | BO34: =$I34*BO$2*2 -> 185.0625 | BP34: =$I34*BP$2*2 -> 185.0625 | BQ34: =$I34*BQ$2*2 -> 185.0625 | BR34: =$I34*BR$2*2 -> 31.5 | BT34: =BT33-BJ34 -> 105834.88 | BU34: =BU33-BK34 -> 105834.88 | BV34: =BV33-BL34 -> 105834.88 | BW34: =BW33-BM34 -> 105834.88 | BX34: =BX33-BN34 -> 105834.88 | BY34: =BY33-BO34 -> 105834.88 | BZ34: =BZ33-BP34 -> 105834.88 | CA34: =CA33-BQ34 -> 105834.88 | CB34: =CB33-BR34 -> 17966 | CD34: 2/17 已放MA 圆筒/彩纸/贴纸 | CH34: =CH21-I34 -> 7024 | CI34: =CI21-I34 -> 2024
A35: 45735 | B35: MILLS FLEET FARM | C35: 美国 | D35: 4500160726 | E35: PO#4647602 | F35: 4500160726-190 | G35: 77685GQ1-S001 | H35: 混搭恐龙13pcs/GQ1*4/箱 | I35: 988 | J35: 0 | K35: 52 | L35: =I35/K35 -> 19 | M35: 45818 | N35: 45814 | P35: pass | Q35: 6/16 截SI | R35: 45742 | S35: 有 | T35: 3/26外箱贴纸 | V35: 日期码格式：ZURU INC(BVI) 标准格式 日期：按实际生产日期 Packaging Info: 1. 包材：ZURU 最新 MA 1L UPC 版本，出口美国;| Remark: 2.日期跟踪码：产品包装及产品本身都必须有日期跟踪码，并且确保两者的日期跟踪码要一致；ZURU标准格式日期码(请自行调整具体年月日生产期，但不能为末). 3. 此单不同客户PO对应不同交期，PO详情看侧边remark ，交期请看PO上面的delivery date； 4. 外箱贴纸(请务必先发箱唛排版给跟单确认后再做印刷) 5. 出货配比：ZURU 标版配比 | W35: Mila Yao | X35: 0.945 | Y35: =X35*I35 -> 933.66 | Z35: ZB00483-6.16 | AA35: 988 | AB35: =AA35-I35 -> 0 | AD35: 系统出单 | AE35: 77685GQ1-S001 | AF35: 已入 | AG35: =I35 -> 988 | AH35: =I35 -> 988 | AK35: =I35 -> 988 | AN35: =I35 -> 988 | AT35: =I35/13 -> 76 | BJ35: =$I35*BJ$2 -> 120.92708 | BK35: =$I35*BK$2 -> 120.92708 | BL35: =$I35*BL$2 -> 120.92708 | BM35: =$I35*BM$2 -> 120.92708 | BN35: =$I35*BN$2 -> 120.92708 | BO35: =$I35*BO$2 -> 120.92708 | BP35: =$I35*BP$2 -> 120.92708 | BQ35: =$I35*BQ$2 -> 120.92708 | BR35: =$I35*BR$2 -> 20.583333 | BT35: =BT34-BJ35 -> 105713.95 | BU35: =BU34-BK35 -> 105713.95 | BV35: =BV34-BL35 -> 105713.95 | BW35: =BW34-BM35 -> 105713.95 | BX35: =BX34-BN35 -> 105713.95 | BY35: =BY34-BO35 -> 105713.95 | BZ35: =BZ34-BP35 -> 105713.95 | CA35: =CA34-BQ35 -> 105713.95 | CB35: =CB34-BR35 -> 17945.417
A36: 45730 | B36: CORPORACION FAVORITA C.A. | C36: 厄多瓜尔 | D36: 4500160092 | E36: 25-2101100JEC | F36: 4500160092-240 | G36: 77685GQ2-S001 | H36: 混搭恐龙27pcs/GQ2*2/箱 | I36: 2700 | J36: 0 | K36: 54 | L36: =I36/K36 -> 50 | M36: 45775 | N36: 45775 | O36: 指定日期码：2025-05 外箱/产品/包装/进口商贴纸 日期码要一致 | P36: pass | Q36: 5/12 截SI | R36: 45740 | S36: 无 | T36: 4/15 UPC贴纸+进口商贴纸 | V36: 日期码格式：2025-05 日期： Packaging Info: 77685GQ2: MA多语EAN包装+UPC贴纸+MA多语收藏指南+MA多语PDQ+进口商贴纸+箱唛 Remark: 1.指定日期码：2025-05（外箱/产品/包装/进口商贴纸 日期码要一致。 如果部分半成品已打ZURU 标准日期码，满足不了指定日期码的要求，可以接受标准日期码，不用重复确认。) 2.所有item的包装上的条码必须是UPC，如果后续提供的贴纸资料已将进口商贴纸和UPC条码合并到一张， 则不需要额外再订购UPC贴纸资料，仅需要订购一张进口商贴纸 | W36: Ava Liang | X36: 0.9779 | Y36: =X36*I36 -> 2640.33 | Z36: 94973-5.12 | AA36: =2700 -> 2700 | AB36: =AA36-I36 -> 0 | AC36: OK | AD36: 系统出单 | AE36: 77685GQ2-S001-3L | AF36: 已入 | AG36: =I36 -> 2700 | AH36: =I36 -> 2700 | AL36: =I36 -> 2700 | AN36: =I36 -> 2700 | AR36: =I36/27 -> 100 | BJ36: =$I36*BJ$2 -> 330.46875 | BK36: =$I36*BK$2 -> 330.46875 | BL36: =$I36*BL$2 -> 330.46875 | BM36: =$I36*BM$2 -> 330.46875 | BN36: =$I36*BN$2 -> 330.46875 | BO36: =$I36*BO$2 -> 330.46875 | BP36: =$I36*BP$2 -> 330.46875 | BQ36: =$I36*BQ$2 -> 330.46875 | BR36: =$I36*BR$2 -> 56.25 | BT36: =BT35-BJ36 -> 105383.48 | BU36: =BU35-BK36 -> 105383.48 | BV36: =BV35-BL36 -> 105383.48 | BW36: =BW35-BM36 -> 105383.48 | BX36: =BX35-BN36 -> 105383.48 | BY36: =BY35-BO36 -> 105383.48 | BZ36: =BZ35-BP36 -> 105383.48 | CA36: =CA35-BQ36 -> 105383.48 | CB36: =CB35-BR36 -> 17889.167
A37: 45754 | B37: ZURU Denmark ApS | C37: 丹麦 | D37: 4500162346 | E37: 5200006527 | F37: 4500162346-10 | G37: 77685GQ1-S002-MTS | H37: 混搭恐龙13pcs/GQ1/箱 | I37: 3315 | J37: 0 | K37: 13 | L37: =I37/K37 -> 255 | M37: 45783 | N37: 45782 | P37: pass | Q37: 5/6截SI | R37: 45757 | S37: 无 | T37: 4/16警告语贴纸 | V37: 日期码格式：ZURU INC(BVI) 标准格式 日期：按实际生产日期 Packaging Info: 77685GQ1: MA 3L A版PDQ + 3L警语 EAN A版收缩膜 +1*多语折叠警告语贴纸+ 1L+23L警语说明书 + 5L+23L警语收藏指南 + 5L Slime袋子 + 北欧五语通用Slime黑 白说明书 Remark: 1.北欧内销单，需要通过ZURU 验货结果后才能出货 (工厂需要主动提前同ZURU QC预约验货避免延期出货造成不必要麻烦)； 2. 产品如含有化学品，需要无硼无香， 3.包装不能含有PVC，使用PET 4. date code: 外箱日期码要晚于产品日期码 5. 装柜时需要按照款式号码从小到大一款款依次装,避免终端仓库卸货混乱.若一个柜子涉及到几个不同国家内销单,装柜时需要一个国家装完后再装另一个国家的 产品,依次装柜,避免终端仓库因不同国家不同库位位置卸货混乱. (此点需要同工厂装柜人员强调)" 6.若有特定款有特殊外箱条码要求时,需要明确列出产品款对应的具体外箱条码号码/条码类型 (若无,可以忽略此需求) 7.所有出口欧洲的产品, 法规规定禁止在包装和共公众用的印刷品中使用矿物油中含有的物质, 包装印刷油墨中含有的MOAH/MOSH的质量浓度不能超过1%, 否则出货 到法国被抽检出现问题, 供应商需要对此负责; 8.带电池出货的产品所用到的电池需要符合欧洲电池新规(EU) 2023-1542。 9.ratio 同MA | W37: SD04 | X37: 0.7931 | Y37: =X37*I37 -> 2629.1265 | Z37: 94941-5.7 | AA37: 3315 | AB37: =AA37-I37 -> 0 | AC37: OK | AD37: 系统出单 | AE37: 77685GQ1-S002-3L | AF37: 已入 | AG37: =I37 -> 3315 | AH37: =I37 -> 3315 | AL37: =I37 -> 3315 | AN37: =I37 -> 3315 | AU37: =I37/13 -> 255 | BJ37: =$I37*BJ$2 -> 405.74219 | BK37: =$I37*BK$2 -> 405.74219 | BL37: =$I37*BL$2 -> 405.74219 | BM37: =$I37*BM$2 -> 405.74219 | BN37: =$I37*BN$2 -> 405.74219 | BO37: =$I37*BO$2 -> 405.74219 | BP37: =$I37*BP$2 -> 405.74219 | BQ37: =$I37*BQ$2 -> 405.74219 | BR37: =$I37*BR$2 -> 69.0625 | BT37: =BT36-BJ37 -> 104977.74 | BU37: =BU36-BK37 -> 104977.74 | BV37: =BV36-BL37 -> 104977.74 | BW37: =BW36-BM37 -> 104977.74 | BX37: =BX36-BN37 -> 104977.74 | BY37: =BY36-BO37 -> 104977.74 | BZ37: =BZ36-BP37 -> 104977.74 | CA37: =CA36-BQ37 -> 104977.74 | CB37: =CB36-BR37 -> 17820.104
A38: 45740 | B38: Signature Marketing N.Z Limited | C38: 新西兰 | D38: 4500161244 | E38: SMNZZU2503 | F38: 4500161244-10 | G38: 77685GQ1-S001 | H38: 混搭恐龙13pcs/GQ1*4/箱 | I38: 1456 | J38: 0 | K38: 52 | L38: =I38/K38 -> 28 | M38: 45784 | N38: 45782 | P38: pass | Q38: 待SO出货 | R38: 45747 | S38: 无 | T38: 无 | V38: 日期码格式：ZURU INC(BVI) 标准格式 日期：按实际生产日期 Packaging Info: 77685GQ1:Rare ratio:1/48 Remark: MA UPC 英语包装（优先1L英语版本,或者3L/L含英语即可） | W38: Abby Liang | X38: 0.945 | Y38: =X38*I38 -> 1375.92 | Z38: 94957-5.10 | AA38: 1456 | AB38: =AA38-I38 -> 0 | AC38: 无 | AD38: 系统出单 | AE38: 77685GQ1-S001 | AF38: 已入 | AG38: =I38 -> 1456 | AH38: =I38 -> 1456 | AK38: =I38 -> 1456 | AN38: =I38 -> 1456 | AT38: =I38/13 -> 112 | BJ38: =$I38*BJ$2 -> 178.20833 | BK38: =$I38*BK$2 -> 178.20833 | BL38: =$I38*BL$2 -> 178.20833 | BM38: =$I38*BM$2 -> 178.20833 | BN38: =$I38*BN$2 -> 178.20833 | BO38: =$I38*BO$2 -> 178.20833 | BP38: =$I38*BP$2 -> 178.20833 | BQ38: =$I38*BQ$2 -> 178.20833 | BR38: =$I38*BR$2 -> 30.333333 | BT38: =BT37-BJ38 -> 104799.53 | BU38: =BU37-BK38 -> 104799.53 | BV38: =BV37-BL38 -> 104799.53 | BW38: =BW37-BM38 -> 104799.53 | BX38: =BX37-BN38 -> 104799.53 | BY38: =BY37-BO38 -> 104799.53 | BZ38: =BZ37-BP38 -> 104799.53 | CA38: =CA37-BQ38 -> 104799.53 | CB38: =CB37-BR38 -> 17789.771
A39: 45744 | B39: WALMART INC. | C39: 美国 | D39: 4500161693 | E39: 0904512406 STATESBORO | F39: 4500161693-10 | G39: 77685SLB-S001 | H39: 混搭恐龙卡板装12pcs/GQ4/CTN**96/Slip Sheet | I39: 1152 | J39: 0 | K39: 1152 | L39: =I39/K39 -> 1 | M39: 45785 | N39: 45782 | O39: 5/9 BV | P39: pass | Q39: 5/15 交仓 | R39: 翻单 | S39: 有 | T39: 4/14 RFID | V39: 日期码格式：ZURU DGYYYYMMDD CHINA(日期避开周末和法定节假日即可） 日期：按实际生产日期 Packaging Info: 77685SLB-S001： 1.包装要求： MA 1L A版收缩膜+MA A版纸袋+MA 5L A版收藏指南+MA A版slime bag+客版1L PDQ,翻单：4500159701 每pcs产品上要贴1张RFID贴纸，贴纸由ZURU提供，贴纸位置请严格按照我们签回的签板； Remark: 77685SLB-S001： 1.包装要求： MA 1L A版收缩膜+MA A版纸袋+MA 5L A版收藏指南+MA A版slime bag+客版1L PDQ,翻单：4500159701 每pcs产品上要贴1张RFID贴纸，贴纸由ZURU提供，贴纸位置请严格按照我们签回的签板； 2. 外箱印刷带条码的RFID箱唛：RFID紫色色带+WM Dept.图标+RFID图标+ITF-14条码，四面右下角印刷ZURU logo, ITFF条码只印刷在正唛一面，在加印的时候确保 条形码能扫描出来，外箱侧面任一角落加印："MADE IN CHINA" 字样； 3. 每个slip sheet上面贴一张艾利贴纸（不干胶贴纸）和一张普通贴纸（A4纸），slip sheet打印的普通贴纸的尺寸不能比艾利贴纸小，普通贴纸内容见附件； 4. 在产品上和包装上要有日期码、以及要有MADE IN CHINA和ZURU字样； 5. 产品如有扎带口要剪平，不能刮手。 6. 此单需要验货，请多备料 7. 此单以slip sheet出货，77685：1152pcs/96CTN/Slip Sheet | W39: Maggie Xie | X39: 903.2128 | Y39: =X39*L39 -> 903.2128 | Z39: ZB00249-5.14 | AA39: 1152 | AB39: =AA39-I39 -> 0 | AD39: 系统出单 | AE39: 77685SLB-S001 | AF39: 已入 | AG39: =I39 -> 1152 | AH39: =I39 -> 1152 | AK39: =I39 -> 1152 | AN39: =I39 -> 1152 | AV39: =I39/12 -> 96 | BJ39: =$I39*BJ$2 -> 141 | BK39: =$I39*BK$2 -> 141 | BL39: =$I39*BL$2 -> 141 | BM39: =$I39*BM$2 -> 141 | BN39: =$I39*BN$2 -> 141 | BO39: =$I39*BO$2 -> 141 | BP39: =$I39*BP$2 -> 141 | BQ39: =$I39*BQ$2 -> 141 | BR39: =$I39*BR$2 -> 24 | BT39: =BT38-BJ39 -> 104658.53 | BU39: =BU38-BK39 -> 104658.53 | BV39: =BV38-BL39 -> 104658.53 | BW39: =BW38-BM39 -> 104658.53 | BX39: =BX38-BN39 -> 104658.53 | BY39: =BY38-BO39 -> 104658.53 | BZ39: =BZ38-BP39 -> 104658.53 | CA39: =CA38-BQ39 -> 104658.53 | CB39: =CB38-BR39 -> 17765.771
A40: 45744 | B40: WALMART INC. | C40: 美国 | D40: 4500161693 | E40: 0904512349 SUFFOLK | F40: 4500161693-20 | G40: 77685SLB-S001 | H40: 混搭恐龙卡板装12pcs/GQ4/CTN**96/Slip Sheet | I40: 1152 | J40: 0 | K40: 1152 | L40: =I40/K40 -> 1 | M40: 45785 | N40: 45782 | O40: 5/9 BV | P40: pass | Q40: 5/10 交仓 | R40: 翻单 | S40: 有 | T40: 4/14 RFID | V40: 日期码格式：ZURU DGYYYYMMDD CHINA(日期避开周末和法定节假日即可） 日期：按实际生产日期 Packaging Info: 77685SLB-S001： 1.包装要求： MA 1L A版收缩膜+MA A版纸袋+MA 5L A版收藏指南+MA A版slime bag+客版1L PDQ,翻单：4500159701 每pcs产品上要贴1张RFID贴纸，贴纸由ZURU提供，贴纸位置请严格按照我们签回的签板； Remark: 77685SLB-S001： 1.包装要求： MA 1L A版收缩膜+MA A版纸袋+MA 5L A版收藏指南+MA A版slime bag+客版1L PDQ,翻单：4500159701 每pcs产品上要贴1张RFID贴纸，贴纸由ZURU提供，贴纸位置请严格按照我们签回的签板； 2. 外箱印刷带条码的RFID箱唛：RFID紫色色带+WM Dept.图标+RFID图标+ITF-14条码，四面右下角印刷ZURU logo, ITFF条码只印刷在正唛一面，在加印的时候确保 条形码能扫描出来，外箱侧面任一角落加印："MADE IN CHINA" 字样； 3. 每个slip sheet上面贴一张艾利贴纸（不干胶贴纸）和一张普通贴纸（A4纸），slip sheet打印的普通贴纸的尺寸不能比艾利贴纸小，普通贴纸内容见附件； 4. 在产品上和包装上要有日期码、以及要有MADE IN CHINA和ZURU字样； 5. 产品如有扎带口要剪平，不能刮手。 6. 此单需要验货，请多备料 7. 此单以slip sheet出货，77685：1152pcs/96CTN/Slip Sheet | W40: Maggie Xie | X40: 903.2128 | Y40: =X40*L40 -> 903.2128 | Z40: ZB00240-5.13 | AA40: 1152 | AB40: =AA40-I40 -> 0 | AD40: 系统出单 | AE40: 77685SLB-S001 | AF40: 已入 | AG40: =I40 -> 1152 | AH40: =I40 -> 1152 | AK40: =I40 -> 1152 | AN40: =I40 -> 1152 | AV40: =I40/12 -> 96 | BJ40: =$I40*BJ$2 -> 141 | BK40: =$I40*BK$2 -> 141 | BL40: =$I40*BL$2 -> 141 | BM40: =$I40*BM$2 -> 141 | BN40: =$I40*BN$2 -> 141 | BO40: =$I40*BO$2 -> 141 | BP40: =$I40*BP$2 -> 141 | BQ40: =$I40*BQ$2 -> 141 | BR40: =$I40*BR$2 -> 24 | BT40: =BT39-BJ40 -> 104517.53 | BU40: =BU39-BK40 -> 104517.53 | BV40: =BV39-BL40 -> 104517.53 | BW40: =BW39-BM40 -> 104517.53 | BX40: =BX39-BN40 -> 104517.53 | BY40: =BY39-BO40 -> 104517.53 | BZ40: =BZ39-BP40 -> 104517.53 | CA40: =CA39-BQ40 -> 104517.53 | CB40: =CB39-BR40 -> 17741.771
...

Sheet 77685排期
A1: ZURU 5 surprise Dino （混搭恐龙）生产排期表 #77685 | H1: 3L及共用包材上的logo为英法2L，纸袋底纹为5S通用logo（为应对加拿大魁北克新规，3L及共用包材上的logo增加法语或改为5S logo以减少翻译）。口水胶、纸袋、说明书、收藏指南从1L Logo变更3L Logo，GQ21L/3L各库存2000PCS，后续切换B版本，注意走加拿大魁北克订单不能用A版本.同一个单不能出现两个版本 | AH1: 无硼 口水胶 | AK1: 收缩膜 | AN1: 收藏指南 | AP1: 外挂中文收藏指南+中文说明书 | AQ1: GQ2 | AT1: GQ1 | AV1: GQ4 | AW1: GQ5 | AX1: GQ7 | AZ1: SK展示架 | BC1: SK1展示架 | BF1: 2PK | BJ1: 腕龙 | BK1: 双脊龙 | BL1: 镰刀龙 | BM1: 甲龙 | BN1: 戟龙 | BO1: 棘龙 | BP1: 沧龙 | BQ1: 霸王龙 | BR1: 特殊款霸王龙 | BT1: =生产MA!G4 -> 腕龙 | BU1: =生产MA!H4 -> 双脊龙 | BV1: =生产MA!I4 -> 镰刀龙 | BW1: =生产MA!J4 -> 甲龙 | BX1: =生产MA!K4 -> 戟龙 | BY1: =生产MA!L4 -> 棘龙 | BZ1: =生产MA!M4 -> 沧龙 | CA1: =生产MA!N4 -> 霸王龙 | CB1: =生产MA!O4 -> 特殊款霸王龙
A2: 香港接单日期 | B2: 第三方客户名称 | C2: 走货国家 | D2: PO号 | E2: 第三方客户 PO NO# | F2: SKU | G2: ITEM# | H2: 中文名 | I2: PO数量 (pcs) | J2: 内箱装箱数量(pcs) | K2: 外箱装箱数量(pcs) | L2: 总箱数 | M2: 客PO期 | N2: 验货期 | O2: 第三方验货时间 | P2: 验货结果 | Q2: 船期 | R2: 箱唛资料(收到日期) | S2: 外箱贴纸 | T2: 客供贴纸AI(收到日期) | U2: 样板 | V2: 备注 | W2: ZURU 跟单 | X2: 单价USD | Y2: 金额USD | Z2: 发票号 | AA2: 送回数量 | AB2: 欠数 | AC2: 贴纸情况 | AD2: 下单情况 | AE2: 系统货号 | AF2: 是否入系统 | AG2: 球数 | AH2: MA | AI2: B MA | AJ2: 客版 | AK2: MA 1L | AL2: MA 3L | AM2: Smyths客版 | AN2: MA 5L | AO2: B MA 5L | AP2: 客版 | AQ2: MA 1L | AR2: MA 3L | AS2: MA B3L | AT2: MA 1L | AU2: MA 3L | AV2: WM 客版 | AW2: Big 客版 | AX2: WM M客版 | AY2: IMP 3L 客版 | AZ2: MA 1L | BA2: MA 3L | BB2: 3L底座 | BC2: MA 1L | BD2: MA 3L | BE2: 底座 | BF2: 圆筒 | BG2: logo英法语彩纸/贴纸 条码UPC | BJ2: 0.12239583 | BK2: 0.12239583 | BL2: 0.12239583 | BM2: 0.12239583 | BN2: 0.12239583 | BO2: 0.12239583 | BP2: 0.12239583 | BQ2: 0.12239583 | BR2: 0.020833333 | BS2: MA扣数 | BT2: =生产MA!G11 -> 113832 | BU2: =生产MA!H11 -> 113832 | BV2: =生产MA!I11 -> 113832 | BW2: =生产MA!J11 -> 113832 | BX2: =生产MA!K11 -> 113832 | BY2: =生产MA!L11 -> 113832 | BZ2: =生产MA!M11 -> 113832 | CA2: =生产MA!N11 -> 113832 | CB2: =生产MA!O11 -> 19377
A3: 45617 | B3: ZURU | C3: 深圳 | D3: ZPO2411012 | E3: PP订单 | G3: 77685GQ2-S001 | H3: 混搭恐龙27pcs/GQ2*2/箱 | I3: 1135 | J3: 0 | K3: 54 | L3: =I3/K3 -> 21.018519 | M3: 45639 | N3: 45635 | R3: 无 | S3: 无 | T3: 无 | V3: 如何同意以上交货期到ZURU但是最后由于供应商原因无法交货，ZURU保留以下的罚款条款 不按期出货罚款如下： 1-7（含第七天）天内延迟出货罚款为合同总金额的百分之五 7-14（含第十四天）天内延迟出货罚款为合同总金额的百分之七 如果超过14天将扣合同金额的百分之十或者由客人提出预计运费方案 如果因为质量不符合雨禾要求的标准，供应商必须改进产品并达到标准并支付返工费用和出货延迟费用 订单细节会不时进行修改，如果订单做了修改要及时通知供应商，修改和特殊指引在生产过程中要由邮件或者电话确认 | Z3: 年存 | BT3: =BT2-BJ3-BJ36 -> 25894.729 | BU3: =BU2-BK3-BK36 -> 25894.729 | BV3: =BV2-BL3-BL36 -> 25894.729 | BW3: =BW2-BM3-BM36 -> 25894.729 | BX3: =BX2-BN3-BN36 -> 25894.729 | BY3: =BY2-BO3-BO36 -> 25894.729 | BZ3: =BZ2-BP3-BP36 -> 25894.729 | CA3: =CA2-BQ3-BQ36 -> 25894.729 | CB3: =CB2-BR3-BR36 -> 4359.1667
A4: 45952 | B4: DISTRIBUIDORA LIVERPOOL S.A DE C.V. | C4: 墨西哥 | D4: 4500182578 | E4: 62050798 | F4: 4500182578-130 | G4: 77685GQ2-S001 | H4: 混搭恐龙27pcs/GQ2*2/箱 | I4: 972 | J4: 0 | K4: 54 | L4: =I4/K4 -> 18 | M4: 46006 | N4: 46004 | P4: 自检 | Q4: 1/15 截SI | R4: 45971 | S4: 无 | T4: 11/28 UPC贴纸+进口商贴纸+12/1价标贴纸 | V4: 日期码格式：ZURU INC(BVI) 标准格式 日期：按实际生产日期 Packaging Info:77685GQ2:MA 多语 EAN 包装+UPC贴纸+进口商贴纸+价标贴纸+箱唛 Remark: 1.此单价格贴纸（ZURU定购).-无位置图，价标贴纸贴于产品背面右上角空白处（不遮挡西班牙语处），如有特殊情况，请重新确认位置图。 2.此单有第三方监柜，不用额外准备备品，会在大货中每款拆1pc，拆了包装的产品会由监装员用客供胶带封好或在外箱上写上""opened by telescope” MOTHER UPC Barcode: | W4: Ava Liang | X4: 0.7795 | Y4: =X4*I4 -> 757.674 | Z4: 年存 | AA4: 972 | AB4: =AA4-I4 -> 0 | AD4: 系统出单 | AE4: 77685GQ2-S001-3L | AF4: 已入 | AG4: =I4 -> 972 | AI4: =I4 -> 972 | AL4: =I4 -> 972 | AO4: =I4 -> 972 | AS4: =I4/27 -> 36 | BJ4: =$I4*BJ$2 -> 118.96875 | BK4: =$I4*BK$2 -> 118.96875 | BL4: =$I4*BL$2 -> 118.96875 | BM4: =$I4*BM$2 -> 118.96875 | BN4: =$I4*BN$2 -> 118.96875 | BO4: =$I4*BO$2 -> 118.96875 | BP4: =$I4*BP$2 -> 118.96875 | BQ4: =$I4*BQ$2 -> 118.96875 | BR4: =$I4*BR$2 -> 20.25 | BT4: =BT3-BJ4 -> 25775.76 | BU4: =BU3-BK4 -> 25775.76 | BV4: =BV3-BL4 -> 25775.76 | BW4: =BW3-BM4 -> 25775.76 | BX4: =BX3-BN4 -> 25775.76 | BY4: =BY3-BO4 -> 25775.76 | BZ4: =BZ3-BP4 -> 25775.76 | CA4: =CA3-BQ4 -> 25775.76 | CB4: =CB3-BR4 -> 4338.9167
A5: 45964 | B5: ESAL TRADING L.L.C. | C5: 阿拉伯联合酋长国 | D5: 4500180717 | E5: UAE | F5: 4500180717-210 | G5: 77685GQ2-S001 | H5: 混搭恐龙27pcs/GQ2*2/箱 | I5: 2916 | J5: 0 | K5: 54 | L5: =I5/K5 -> 54 | M5: 46006 | N5: 46006 | P5: pass | R5: 45973 | S5: 无 | T5: 11/28进口商贴纸 | V5: 日期码格式：ZURU INC(BVI) 标准格式 日期：按实际生产日期 Packaging Info: 77685GQ2: MA 收缩膜+进口商贴纸 (含G Mark, QR code, 阿拉伯警语); 贴纸上的QR code需微信可扫，扫描结果另外通知; 收缩膜上UPC条码为193052079053；MA P DQ+进口商贴纸; 产品年龄3+； 客人箱唛排版，印4面，条码内容193052079053； Remark: | W5: Nora Pan | X5: 0.7913 | Y5: =X5*I5 -> 2307.4308 | Z5: 年存 | AA5: 2916 | AB5: =AA5-I5 -> 0 | AC5: OK | AD5: 系统出单 | AE5: 77685GQ2-S001 | AF5: 已入 | AG5: =I5 -> 2916 | AI5: =I5 -> 2916 | AK5: =I5 -> 2916 | AO5: =I5 -> 2916 | AQ5: =I5/27 -> 108 | BJ5: =$I5*BJ$2 -> 356.90625 | BK5: =$I5*BK$2 -> 356.90625 | BL5: =$I5*BL$2 -> 356.90625 | BM5: =$I5*BM$2 -> 356.90625 | BN5: =$I5*BN$2 -> 356.90625 | BO5: =$I5*BO$2 -> 356.90625 | BP5: =$I5*BP$2 -> 356.90625 | BQ5: =$I5*BQ$2 -> 356.90625 | BR5: =$I5*BR$2 -> 60.75 | BT5: =BT4-BJ5 -> 25418.854 | BU5: =BU4-BK5 -> 25418.854 | BV5: =BV4-BL5 -> 25418.854 | BW5: =BW4-BM5 -> 25418.854 | BX5: =BX4-BN5 -> 25418.854 | BY5: =BY4-BO5 -> 25418.854 | BZ5: =BZ4-BP5 -> 25418.854 | CA5: =CA4-BQ5 -> 25418.854 | CB5: =CB4-BR5 -> 4278.1667
A6: 45964 | B6: ESAL TRADING L.L.C. | C6: 阿拉伯联合酋长国 | D6: 4500180735 | E6: QAT | F6: 4500180735-190 | G6: 77685GQ2-S001 | H6: 混搭恐龙27pcs/GQ2*2/箱 | I6: 1080 | J6: 0 | K6: 54 | L6: =I6/K6 -> 20 | M6: 46006 | N6: 46006 | P6: pass | Q6: 1/12 截SI | R6: 45973 | S6: 无 | T6: 11/28进口商贴纸 | V6: 日期码格式：ZURU INC(BVI) 标准格式 日期：按实际生产日期 Packaging Info: 77685GQ2: MA 收缩膜+进口商贴纸 (含G Mark, QR code, 阿拉伯警语); 贴纸上的QR code需微信可扫，扫描结果另外通知; 收缩膜上UPC条码为193052079053；MA P DQ+进口商贴纸; 产品年龄3+； 客人箱唛排版，印4面，条码内容193052079053； Remark: | W6: Nora Pan | X6: 0.7913 | Y6: =X6*I6 -> 854.604 | Z6: 年存 | AA6: 1080 | AB6: =AA6-I6 -> 0 | AC6: OK | AD6: 系统出单 | AE6: 77685GQ2-S001 | AF6: 已入 | AG6: =I6 -> 1080 | AI6: =I6 -> 1080 | AK6: =I6 -> 1080 | AO6: =I6 -> 1080 | AQ6: =I6/27 -> 40 | BJ6: =$I6*BJ$2 -> 132.1875 | BK6: =$I6*BK$2 -> 132.1875 | BL6: =$I6*BL$2 -> 132.1875 | BM6: =$I6*BM$2 -> 132.1875 | BN6: =$I6*BN$2 -> 132.1875 | BO6: =$I6*BO$2 -> 132.1875 | BP6: =$I6*BP$2 -> 132.1875 | BQ6: =$I6*BQ$2 -> 132.1875 | BR6: =$I6*BR$2 -> 22.5 | BT6: =BT5-BJ6 -> 25286.667 | BU6: =BU5-BK6 -> 25286.667 | BV6: =BV5-BL6 -> 25286.667 | BW6: =BW5-BM6 -> 25286.667 | BX6: =BX5-BN6 -> 25286.667 | BY6: =BY5-BO6 -> 25286.667 | BZ6: =BZ5-BP6 -> 25286.667 | CA6: =CA5-BQ6 -> 25286.667 | CB6: =CB5-BR6 -> 4255.6667
