Workbook
Name cavity: '[1]Form-003'!#REF!
Name Code: '[2]CQS Code(rev 38)'!$B$7:$E$1000
Name cycle.time: '[1]Form-003'!#REF!
Name GDE: [3]基础表!#REF!
Name mold.color: '[1]Form-003'!#REF!
Name mold.cost: '[1]Form-003'!#REF!
Name mold.height: '[1]Form-003'!#REF!
Name mold.length: '[1]Form-003'!#REF!
Name mold.material: '[1]Form-003'!#REF!
Name mold.name: '[1]Form-003'!#REF!
Name mold.number: '[1]Form-003'!#REF!
Name mold.partweight: '[1]Form-003'!#REF!
Name mold.usage: '[1]Form-003'!#REF!
Name mold.width: '[1]Form-003'!#REF!
Name new_sum: #REF!
Name part.list: '[1]Form-003'!#REF!
Name PI_IN: #REF!
Name PI_SUM: #REF!
Name PI_SUM_SALES: #REF!
Name Prepared.By: '[1]Form-003'!#REF!
Name Ref.Number: '[1]Form-003'!#REF!
Name Revised.By: '[1]Form-003'!#REF!
Name sd: [3]基础表!#REF!
Name tool.plan: '[1]Form-003'!#REF!
Name up: '[1]Form-003'!#REF!
Name Vendor: '[1]Form-003'!#REF!
Name 类别: [3]基础表!#REF!
Name 类别1: [3]基础表!#REF!
Name 领料单: [3]基础表!#REF!
Name 收料单: [3]基础表!#REF!
Name 一部: [3]基础表!#REF!
Name GDE: [4]基础表!#REF!
Name new_sum: #REF!
Name PI_IN: #REF!
Name PI_SUM: #REF!
Name PI_SUM_SALES: #REF!
Name sd: [4]基础表!#REF!
Name 类别: [4]基础表!#REF!
Name 类别1: [4]基础表!#REF!
Name 领料单: [4]基础表!#REF!
Name 收料单: [4]基础表!#REF!
Name 一部: [4]基础表!#REF!
Name GDE: [4]基础表!#REF!
Name new_sum: #REF!
Name PI_IN: #REF!
Name PI_SUM: #REF!
Name PI_SUM_SALES: #REF!
Name sd: [4]基础表!#REF!
Name 类别: [4]基础表!#REF!
Name 类别1: [4]基础表!#REF!
Name 领料单: [4]基础表!#REF!
Name 收料单: [4]基础表!#REF!
Name 一部: [4]基础表!#REF!
Name GDE: [5]基础表!#REF!
Name new_sum: #REF!
Name PI_IN: #REF!
Name PI_SUM: #REF!
Name PI_SUM_SALES: #REF!
Name sd: [5]基础表!#REF!
Name 类别: [5]基础表!#REF!

Sheet 77515 旧排期
A1: ZURU （77515 Mini Brands 迷你球DIY厨艺系列）生产排期表 | H1: 77555SK1-S002这款是带底座 | L1: 走KM澳洲和出新西兰的说明书都要加纽扣电池警语贴纸
AG2: 77515 | AK2: 收縮膜 | AO2: 收藏指南 | AS2: PDQ盒 | BK2: 77516
A3: 香港接单日期 | B3: 第三方客户名称 | C3: 走货国家 | D3: ZURU PO NO# | E3: 第三方客户 PO NO# | F3: SKU | G3: ITEM# | H3: 中文名 | I3: PO数量 (pcs) | J3: 内箱装箱数量(pcs) | K3: 外箱装箱数量(pcs) | L3: 总箱数 | M3: 计划出货期 | N3: 计划验货期 | O3: 第三方客户公证行验货 | P3: 驗貨結果 | Q3: S/0船期 | R3: 箱唛资料(收到日期) | S3: 外箱贴纸 | T3: 客供贴纸AI(收到日期) | U3: 备注 | V3: ZURU 跟单 | W3: 单价USD | X3: 金额USD | Y3: 發票號 | Z3: 系统货号 | AA3: 是否入系统 | AB3: 已送情况 | AC3: 欠数 | AD3: 贴纸 | AE3: 生产地点 | AG3: 球数 | AH3: 无香味版本 | AI3: 删除组合10（猪肉） | AJ3: MA 3语 收缩膜 无条码 | AK3: MA 1语收缩膜 | AL3: MA 3语收缩膜 | AM3: 客版收缩膜 | AN3: 客版 3L 收缩膜 | AO3: MA 5L语收藏指南 | AP3: ESAL客版指南/说明书 | AQ3: WM客版 | AR3: 外挂中文收藏指南+中文收藏指南(每一款都不同) | AS3: GQ5-S001 21PCS 1L | AT3: GQ5-S001 21PCS 3L | AU3: WM 客版GQ5 | AV3: WM 客版GQ6 | AW3: GQ6-S001 12PCS 1L | AX3: GQ6-S001 12PCS 3L | AY3: GQ1-S001 13pcs 1L | AZ3: GQ1-S001 13pcs 3L | BA3: GQ2-S001 25pcs 1L | BB3: GQ2-S001 25pcs 3L | BC3: SK-S001 60PCS 1L 不含底座 配挂钩 | BD3: SK-S002 60PCS 1L 含底座 | BE3: SK-S002 60PCS 3L 含底座 | BF3: 77515SK1-S002 30pcs 1L 含底座 | BG3: 77515SK1-S001 30pcs 3L 不带底座 | BH3: SK1底座 | BI3: FD客 77515GQ3 | BJ3: 77515GQ3-S001 客版 8PCS | BK3: 圆筒 | BL3: 3L 彩纸 | BM3: 合计数量
A4: 45252 | B4: ZURU | C4: 库有 | D4: ZMPO23692 | G4: 77515-S001 | H4: DIY厨艺大师 | I4: 1000 | J4: 0 | K4: 24 | L4: =I4/K4 -> 41.666667 | M4: 45252 | N4: 45248 | P4: OK | R4: 周转箱 | S4: 无 | T4: 无 | U4: 跟PP订单一起安排 | Y4: 84014-2.19 | Z4: 无 | AE4: DG | AG4: =I4 -> 1000 | BM4: =AG4+AH4+AI4 -> 1000
A5: 45252 | B5: ZURU | C5: 库有 | D5: ZMPO23692 | G5: 77515-S001 | H5: DIY厨艺大师 | I5: 30套散件 | J5: 0 | K5: 24 | L5: 1 | M5: 45252 | N5: 45248 | P5: OK | R5: 周转箱 | S5: 无 | T5: 无 | U5: 跟PP订单一起安排/只需要全套散件，麻烦用胶袋分装好一套为一袋 | Y5: 84014-2.19 | Z5: 无 | AE5: DG | BM5: =AG5+AH5+AI5 -> 0
A6: 45252 | B6: ZURU | C6: 库有 | D6: ZPO2311001 | G6: 77515-S001 | H6: DIY厨艺大师 | I6: 510 | J6: 0 | K6: 24 | L6: =I6/K6 -> 21.25 | M6: 45272 | N6: 45268 | P6: OK | R6: 周转箱 | S6: 无 | T6: 无 | Z6: 无 | AE6: DG | AG6: =I6 -> 510 | BM6: =AG6+AH6+AI6 -> 510 | BN6: =BN5+BM6 -> 510 | BO6: =$BO$3-BN6 -> -510 | BQ6: =AS6+AT6+BA6+BB6 -> 0 | BR6: =BR5+BQ6 -> 0 | BS6: =$BS$3-BR6 -> 0
A7: 45279 | B7: ZURU | C7: 库有 | D7: ZMPO23783 | G7: 77515-S001 | H7: DIY厨艺大师 | I7: 5套 | J7: 0 | K7: 24 | L7: 1 | M7: 45288 | N7: 45285 | P7: OK | Q7: 3/14 寄深圳 | R7: 周转箱 | S7: 无 | T7: 无 | U7: 左图中散件每款各5PCS | Y7: 84562-4.17 | Z7: 无 | AE7: DG | BM7: =AG7+AH7+AI7 -> 0
A8: 45279 | B8: ZURU | C8: 库有 | D8: ZMPO23783 | G8: 77515-S001 | H8: DIY厨艺大师 | I8: 5套 | J8: 0 | K8: 24 | L8: 1 | M8: 45288 | N8: 45285 | P8: OK | Q8: 3/14 寄深圳 | R8: 周转箱 | S8: 无 | T8: 无 | U8: 左图中每款散件各5PCS | Z8: 无 | AE8: DG | BM8: =AG8+AH8+AI8 -> 0 | BN8: =BN7+BM8 -> 0 | BO8: =$BO$3-BN8 -> 0 | BQ8: =AS8+AT8+BA8+BB8 -> 0 | BR8: =BR7+BQ8 -> 0 | BS8: =$BS$3-BR8 -> 0
A9: 45275 | B9: ZURU | C9: 库有 | D9: ZMPO23775 | G9: 77515-S001 | H9: DIY厨艺大师 | I9: 2000 | J9: 0 | K9: 24 | L9: =I9/K9 -> 83.333333 | M9: 45300 | N9: 45296 | P9: pass | Q9: 3/6 已送500pcs | R9: 周转箱 | S9: 无 | T9: 无 | U9: 大货最新版本/款号平均/请按款号装箱，并在外箱上注明款号/请用大货标准箱装箱24PCS/箱共84箱/箱唛请参照邮件附件 | Y9: 84234-3.14 | Z9: 无 | AE9: DG | AG9: =I9 -> 2000 | AK9: =AG9 -> 2000 | AO9: =AG9 -> 2000 | BM9: =AG9+AH9+AI9 -> 2000
A10: 45275 | B10: ZURU | C10: 库有 | D10: ZMPO23775 | G10: 77515GQ2-S001 | H10: DIY厨艺大师 | I10: 2000 | J10: 0 | K10: 50 | L10: =2000/25 -> 80 | M10: 45300 | N10: 45296 | P10: pass | R10: 周转箱 | S10: 无 | T10: 无 | U10: 80个满PDQ 大货最新版本/大货标准箱装箱/箱唛请参照邮件附件 | Y10: 84234-3.14 | Z10: 无 | AE10: DG | AG10: =80*25 -> 2000 | AK10: =AG10 -> 2000 | AO10: =AG10 -> 2000 | BA10: 80 | BM10: =AG10+AH10+AI10 -> 2000
A11: 45293 | B11: ZURU | C11: 库有 | D11: ZMPO24005 | G11: 77515-S001 | H11: DIY厨艺大师 | I11: 150套散件 | J11: 0 | K11: 24 | L11: 1 | M11: 45307 | N11: 45303 | P11: OK | Q11: 3/14 寄深圳 | R11: 周转箱 | S11: 无 | T11: 无 | U11: 大货订单最新版本/只需要全套散件，麻烦用胶袋分装好一套为一袋 | Y11: 84561-4.17 | Z11: 无 | AE11: DG | AG11: 150 | BM11: =AG11+AH11+AI11 -> 150
A12: 45302 | B12: ZURU | C12: 库有 | D12: ZMPO24030 | G12: 77515-S001 | H12: DIY厨艺大师 | I12: 1400 | J12: 0 | K12: 24 | L12: =I12/K12 -> 58.333333 | M12: 45314 | N12: 45310 | P12: OK | R12: 周转箱 | S12: 无 | T12: 无 | U12: 左图中7款散件每款各200PCS/要做好的散件成品 | Y12: 84661-4.29 | Z12: 无 | AE12: DG | BM12: =AG12+AH12+AI12 -> 0
A13: 45302 | B13: ZURU | C13: 库有 | D13: ZMPO24030 | G13: 77515-S001 | H13: DIY厨艺大师 | I13: 800 | J13: 0 | K13: 24 | L13: =I13/K13 -> 33.333333 | M13: 45314 | N13: 45310 | P13: OK | R13: 周转箱 | S13: 无 | T13: 无 | U13: 左图中4款配件每款散件各200PCS | Y13: 84661-4.29 | Z13: 无 | AE13: DG | BM13: =AG13+AH13+AI13 -> 0
A14: 45315 | B14: ZURU | C14: 库有 | D14: ZMPO24071 | G14: 77515SK1-S002 | H14: DIY厨艺大师 | I14: 5套满展示架 | J14: 0 | K14: 30 | L14: =I14/K14 -> #VALUE! | M14: 45348 | N14: 20024/2/22 | Q14: 3/22 送库有 | R14: 周转箱 | S14: 无 | T14: 无 | U14: 大货订单最新版本/里面产品按大货配比/箱唛参照邮件附件 | Y14: 84558-4.17 | Z14: 无 | AE14: DG | AG14: =5*30 -> 150 | BF14: =5 -> 5 | BH14: =BF14 -> 5 | BM14: =AG14+AH14+AI14 -> 150
A15: 45317 | B15: ZURU | C15: 库有 | D15: ZMPO24079 | G15: 77515-S001 | H15: DIY厨艺大师 | I15: 200套散件 | J15: 0 | K15: 24 | L15: =I15/K15 -> #VALUE! | M15: 45351 | N15: 45348 | R15: 周转箱 | S15: 无 | T15: 无 | U15: 左图中14款酱每款200PCS/共2800PCS/麻烦用胶袋分装好14款一套为一袋 | Z15: 无 | AE15: DG | AG15: 200 | BM15: =AG15+AH15+AI15 -> 200 | BN15: =BN14+BM15 -> 200 | BO15: =$BO$3-BN15 -> -200 | BQ15: =AS15+AT15+BA15+BB15 -> 0 | BR15: =BR14+BQ15 -> 0 | BS15: =$BS$3-BR15 -> 0
A16: 45254 | B16: TARGET US | C16: 美国 | D16: 4500119549 | E16: 0086-7227519-0584 | F16: 4500119549-10 | G16: 77515GQ5-S002 | H16: DIY厨艺大师 | I16: 24465 | J16: 0 | K16: 21 | L16: =I16/K16 -> 1165 | M16: 45320 | N16: 45316 | P16: AOD | Q16: 1/29 客上柜 空运 | R16: 45654 | S16: 有 | T16: 1/9 寄出 | U16: 日期码格式：ZURU INC(BVI) 标准格式 日期：按实际生产日期 Packaging Info: MA PDQ Remark: 1. 77515GQ5-S002-MINI BRAND-MASTER CHEF MINI BRANDS-SERIES 1,21pcs/Gravity PDQ, 21pcs/CTN,No Inner,STD Color Assortment (White drop) 2. MA PDQ, 产品UPC 显示193052061034; 11 assortment have the same ratio； 3. 外箱正唛左上角位置粘贴条码箱贴纸，每箱只贴一张，由ZURU订购。来料贴纸上显示的客户DPCI# 086-02-9598， UPC显示10193052061031; 4. 外箱正唛箱唛内容右侧需贴一张Event label，内容显示 Toys Set Date：3/3/2024，工厂自行订购 5. 产品和包装上印刷 tracking code信息，格式为ZURU常规格式; 6. 出货方式：货代自提。 | V16: Holly Zheng | W16: 1.75 | X16: =I16*W16 -> 42813.75 | Y16: 78917-1.30 | Z16: 77515GQ5-S002 | AA16: 已入 | AE16: DG | AG16: =I16 -> 24465 | AK16: =AG16 -> 24465 | AO16: =AG16 -> 24465 | AS16: =I16/21 -> 1165 | BM16: =AG16+AH16+AI16 -> 24465
A17: 45254 | B17: TARGET US | C17: 美国 | D17: 4500119550 | E17: 0086-5971609-0581 | F17: 4500119550-10 | G17: 77515GQ5-S002 | H17: DIY厨艺大师 | I17: 35532 | J17: 0 | K17: 21 | L17: =I17/K17 -> 1692 | M17: 45320 | N17: 45316 | P17: pass | Q17: 1/29 客上柜 空运 | R17: 45654 | S17: 有 | T17: 1/9 寄出 | U17: 日期码格式：ZURU INC(BVI) 标准格式 日期：按实际生产日期 Packaging Info: MA PDQ Remark: 1. 77515GQ5-S002-MINI BRAND-MASTER CHEF MINI BRANDS-SERIES 1,21pcs/Gravity PDQ, 21pcs/CTN,No Inner,STD Color Assortment (White drop) 2. MA PDQ, 产品UPC 显示193052061034; 11 assortment have the same ratio； 3. 外箱正唛左上角位置粘贴条码箱贴纸，每箱只贴一张，由ZURU订购。来料贴纸上显示的客户DPCI# 086-02-9598， UPC显示10193052061031; 4. 外箱正唛箱唛内容右侧需贴一张Event label，内容显示 Toys Set Date：3/3/2024，工厂自行订购 5. 产品和包装上印刷 tracking code信息，格式为ZURU常规格式; 6. 出货方式：货代自提。 | V17: Holly Zheng | W17: 1.75 | X17: =I17*W17 -> 62181 | Y17: 78916-1.30 | Z17: 77515GQ5-S002 | AA17: 已入 | AE17: DG | AG17: =I17 -> 35532 | AK17: =AG17 -> 35532 | AO17: =AG17 -> 35532 | AS17: =I17/21 -> 1692 | BM17: =AG17+AH17+AI17 -> 35532
A18: 45254 | B18: TARGET US | C18: 美国 | D18: 4500119551 | E18: 0086-6266753-0581 | F18: 4500119551-10 | G18: 77515GQ5-S002 | H18: DIY厨艺大师 | I18: 38955 | J18: 0 | K18: 21 | L18: =I18/K18 -> 1855 | M18: 45320 | N18: 45316 | P18: pass | Q18: 1/30 客上柜 | R18: 45654 | S18: 有 | T18: 1/9 寄出 | U18: 日期码格式：ZURU INC(BVI) 标准格式 日期：按实际生产日期 Packaging Info: MA PDQ Remark: 1. 77515GQ5-S002-MINI BRAND-MASTER CHEF MINI BRANDS-SERIES 1,21pcs/Gravity PDQ, 21pcs/CTN,No Inner,STD Color Assortment (White drop) 2. MA PDQ, 产品UPC 显示193052061034; 11 assortment have the same ratio； 3. 外箱正唛左上角位置粘贴条码箱贴纸，每箱只贴一张，由ZURU订购。来料贴纸上显示的客户DPCI# 086-02-9598， UPC显示10193052061031; 4. 产品和包装上印刷 tracking code信息，格式为ZURU常规格式; 5. 出货方式：货代自提。 | V18: Holly Zheng | W18: 1.75 | X18: =I18*W18 -> 68171.25 | Y18: 78918-1.30 | Z18: 77515GQ5-S002 | AA18: 已入 | AE18: DG | AG18: =I18 -> 38955 | AK18: =AG18 -> 38955 | AO18: =AG18 -> 38955 | AS18: =I18/21 -> 1855 | BM18: =AG18+AH18+AI18 -> 38955
A19: 45254 | B19: TARGET US | C19: 美国 | D19: 4500119557 | E19: 0086-3900914-0581 | F19: 4500119557-10 | G19: 77515GQ5-S002 | H19: DIY厨艺大师 | I19: 45003 | J19: 0 | K19: 21 | L19: =I19/K19 -> 2143 | M19: 45321 | N19: 45317 | P19: pass | Q19: 1/30 客上柜 | R19: 45654 | S19: 有 | T19: 1/9 寄出 | U19: 日期码格式：ZURU INC(BVI) 标准格式 日期：按实际生产日期 Packaging Info: MA PDQ Remark: 1. 77515GQ5-S002-MINI BRAND-MASTER CHEF MINI BRANDS-SERIES 1,21pcs/Gravity PDQ, 21pcs/CTN,No Inner,STD Color Assortment (White drop) 2. MA PDQ, 产品UPC 显示193052061034; 11 assortment have the same ratio； 3. 外箱正唛左上角位置粘贴条码箱贴纸，每箱只贴一张，由ZURU订购。来料贴纸上显示的客户DPCI# 086-02-9598， UPC显示10193052061031; 4. 产品和包装上印刷 tracking code信息，格式为ZURU常规格式; 5. 出货方式：货代自提。 | V19: Holly Zheng | W19: 1.75 | X19: =I19*W19 -> 78755.25 | Y19: 78919-1.30 | Z19: 77515GQ5-S002 | AA19: 已入 | AE19: DG | AG19: =I19 -> 45003 | AK19: =AG19 -> 45003 | AO19: =AG19 -> 45003 | AS19: =I19/21 -> 2143 | BM19: =AG19+AH19+AI19 -> 45003
A20: 45254 | B20: TARGET US | C20: 美国 | D20: 4500119555 | E20: 0086-9221446-0584 | F20: 4500119555-10 | G20: 77515GQ5-S002 | H20: DIY厨艺大师 | I20: 20013 | J20: 0 | K20: 21 | L20: =I20/K20 -> 953 | M20: 45320 | N20: 45316 | P20: pass | Q20: 1/31 客上柜 | R20: 45654 | S20: 有 | T20: 1/9 寄出 | U20: 日期码格式：ZURU INC(BVI) 标准格式 日期：按实际生产日期 Packaging Info: MA PDQ Remark: 1. 77515GQ5-S002-MINI BRAND-MASTER CHEF MINI BRANDS-SERIES 1,21pcs/Gravity PDQ, 21pcs/CTN,No Inner,STD Color Assortment (White drop) 2. MA PDQ, 产品UPC 显示193052061034; 11 assortment have the same ratio； 3. 外箱正唛左上角位置粘贴条码箱贴纸，每箱只贴一张，由ZURU订购。来料贴纸上显示的客户DPCI# 086-02-9598， UPC显示10193052061031; 4. 产品和包装上印刷 tracking code信息，格式为ZURU常规格式; 5. 出货方式：货代自提。 | V20: Holly Zheng | W20: 1.75 | X20: =I20*W20 -> 35022.75 | Y20: 78951-1.31 | Z20: 77515GQ5-S002 | AA20: 已入 | AE20: DG | AG20: =I20 -> 20013 | AK20: =AG20 -> 20013 | AO20: =AG20 -> 20013 | AS20: =I20/21 -> 953 | BM20: =AG20+AH20+AI20 -> 20013
A21: 45254 | B21: TARGET US | C21: 美国 | D21: 4500119558 | E21: 0086-3865926-0581 | F21: 4500119558-10 | G21: 77515GQ5-S002 | H21: DIY厨艺大师 | I21: 29988 | J21: 0 | K21: 21 | L21: =I21/K21 -> 1428 | M21: 45320 | N21: 45316 | P21: pass | Q21: 1/31 客上柜 | R21: 45654 | S21: 有 | T21: 1/9 寄出 | U21: 日期码格式：ZURU INC(BVI) 标准格式 日期：按实际生产日期 Packaging Info: MA PDQ Remark: 1. 77515GQ5-S002-MINI BRAND-MASTER CHEF MINI BRANDS-SERIES 1,21pcs/Gravity PDQ, 21pcs/CTN,No Inner,STD Color Assortment (White drop) 2. MA PDQ, 产品UPC 显示193052061034; 11 assortment have the same ratio； 3. 外箱正唛左上角位置粘贴条码箱贴纸，每箱只贴一张，由ZURU订购。来料贴纸上显示的客户DPCI# 086-02-9598， UPC显示10193052061031; 4. 产品和包装上印刷 tracking code信息，格式为ZURU常规格式; 5. 出货方式：货代自提。 | V21: Holly Zheng | W21: 1.75 | X21: =I21*W21 -> 52479 | Y21: 84011-2.19 | Z21: 77515GQ5-S002 | AA21: 已入 | AE21: DG | AG21: =I21 -> 29988 | AK21: =AG21 -> 29988 | AO21: =AG21 -> 29988 | AS21: =I21/21 -> 1428 | BM21: =AG21+AH21+AI21 -> 29988
A22: 45254 | B22: TARGET US | C22: 美国 | D22: 4500119553 | E22: 0086-1598304-0584 | F22: 4500119553-10 | G22: 77515GQ5-S002 | H22: DIY厨艺大师 | I22: 26040 | J22: 0 | K22: 21 | L22: =I22/K22 -> 1240 | M22: 45320 | N22: 45316 | P22: pass | Q22: 2/2 客上柜 | R22: 45654 | S22: 有 | T22: 1/9 寄出 | U22: 日期码格式：ZURU INC(BVI) 标准格式 日期：按实际生产日期 Packaging Info: MA PDQ Remark: 1. 77515GQ5-S002-MINI BRAND-MASTER CHEF MINI BRANDS-SERIES 1,21pcs/Gravity PDQ, 21pcs/CTN,No Inner,STD Color Assortment (White drop) 2. MA PDQ, 产品UPC 显示193052061034; 11 assortment have the same ratio； 3. 外箱正唛左上角位置粘贴条码箱贴纸，每箱只贴一张，由ZURU订购。来料贴纸上显示的客户DPCI# 086-02-9598， UPC显示10193052061031; 4. 产品和包装上印刷 tracking code信息，格式为ZURU常规格式; 5. 出货方式：货代自提。 | V22: Holly Zheng | W22: 1.75 | X22: =I22*W22 -> 45570 | Y22: 84010-2.19 | Z22: 77515GQ5-S002 | AA22: 已入 | AE22: DG | AG22: =I22 -> 26040 | AK22: =AG22 -> 26040 | AO22: =AG22 -> 26040 | AS22: =I22/21 -> 1240 | BM22: =AG22+AH22+AI22 -> 26040
A23: 45285 | B23: AMAZON.COM.DEDC,LLC | C23: 美国 | D23: 4500122098 | F23: 4500122098-10 | G23: 77515-S001 | H23: DIY厨艺大师 | I23: 9264 | J23: 0 | K23: 24 | L23: =I23/K23 -> 386 | M23: 45321 | N23: 45317 | P23: AOD | Q23: 2/2 交仓 空运订单 | R23: 外箱正面印ZURU Logo+SSCC LABEL（客供贴纸), 侧面印item# | S23: 有 | T23: 45314 | U23: 日期码格式：ZURU INC(BVI) 标准格式 日期：按实际生产日期 Packaging Info: 77515：MA 1L. 加防伪贴纸， 跟单提供。 Remark: 1.Amazon FOB订单，出口US。外箱最长边不能超过25" （超过了，case pack只能为1），不符合要求的大货，一律不接受。 2. 外箱正面印ZURU Logo+SSCC LABEL（客供贴纸), 侧面印item#（订单上显示的SKU#)+carton size(以工厂实际尺寸为准,单位: inch) +MADE IN CHINA,日期使用Z URU 标准版本 SSCC Label 显示的是客人自己的item#, SSCC Label 贴在外箱正面的正中间，贴一面即可，跟单订购，贴纸离外箱距必须至少3cm, 每一张SSCC labe l 都是唯一且有不同流水及条码的，没有损耗，绝对不可贴错 ，否则贴错或损坏一张会导致全部都错，千万要注意. SSCC 贴纸务必要在正中间(可以覆盖Logo <(>&<)> 箱唛), 否则会影响到仓库扫描识别 3.日期码使用ZURU标准版本 邮包盒上要打日期码 4.按照客户PO# 装柜/箱号顺序装柜，跟单会提前给到装柜计划。请大货生产/仓库存放时留意，以便装柜时不混乱（装错/装漏/找不到货号） | V23: Agnes Zheng | W23: 1.19 | X23: =I23*W23 -> 11024.16 | Y23: 84009-2.19 | Z23: 77515-S001 | AA23: 已入 | AE23: DG | AG23: =I23 -> 9264 | AK23: =AG23 -> 9264 | AO23: =AG23 -> 9264 | BM23: =AG23+AH23+AI23 -> 9264
A24: 45271 | B24: MEIJER | C24: 美国 | D24: 4500120916 | E24: 215358810 | F24: 4500120916-10 | G24: 77515GQ1-S003 | H24: DIY厨艺大师 | I24: 416 | J24: 0 | K24: 13 | L24: =I24/K24 -> 32 | M24: 45321 | N24: 45317 | P24: pass | Q24: 2/19入仓 | R24: 45647 | S24: 无 | T24: 无 | U24: 日期码格式：ZURU INC(BVI) 标准格式 日期：按实际生产日期 Packaging Info: 1. MA 1L 包装 2. 客人指定箱唛排版 Remark: 出货前 Zuru QC 验货 | V24: Sophia Zhou | W24: 1.7 | X24: =I24*W24 -> 707.2 | Y24: 84028-2.20 | Z24: 77515GQ1-S003 | AA24: 已入 | AE24: DG | AG24: =I24 -> 416 | AK24: =AG24 -> 416 | AO24: =AG24 -> 416 | AY24: =I24/13 -> 32 | BM24: =AG24+AH24+AI24 -> 416
A25: 45271 | B25: MEIJER | C25: 美国 | D25: 4500120919 | E25: 215358821 | F25: 4500120919-10 | G25: 77515GQ1-S003 | H25: DIY厨艺大师 | I25: 806 | J25: 0 | K25: 13 | L25: =I25/K25 -> 62 | M25: 45321 | N25: 45317 | P25: pass | Q25: 2/19入仓 | R25: 45647 | S25: 无 | T25: 无 | U25: 日期码格式：ZURU INC(BVI) 标准格式 日期：按实际生产日期 Packaging Info: 1. MA 1L 包装 2. 客人指定箱唛排版 Remark: 出货前 Zuru QC 验货 | V25: Sophia Zhou | W25: 1.7 | X25: =I25*W25 -> 1370.2 | Y25: 84029-2.20 | Z25: 77515GQ1-S003 | AA25: 已入 | AE25: DG | AG25: =I25 -> 806 | AK25: =AG25 -> 806 | AO25: =AG25 -> 806 | AY25: =I25/13 -> 62 | BM25: =AG25+AH25+AI25 -> 806
A26: 45271 | B26: MEIJER | C26: 美国 | D26: 4500120905 | E26: 215358737 | F26: 4500120905-10 | G26: 77515GQ1-S003 | H26: DIY厨艺大师 | I26: 4017 | J26: 0 | K26: 13 | L26: =I26/K26 -> 309 | M26: 45321 | N26: 45317 | P26: pass | Q26: 2/19入仓 | R26: 45647 | S26: 无 | T26: 无 | U26: 日期码格式：ZURU INC(BVI) 标准格式 日期：按实际生产日期 Packaging Info: 1. MA 1L 包装 2. 客人指定箱唛排版 Remark: 出货前 Zuru QC 验货 | V26: Sophia Zhou | W26: 1.7 | X26: =I26*W26 -> 6828.9 | Y26: 84023-2.20 | Z26: 77515GQ1-S003 | AA26: 已入 | AE26: DG | AG26: =I26 -> 4017 | AK26: =AG26 -> 4017 | AO26: =AG26 -> 4017 | AY26: =I26/13 -> 309 | BM26: =AG26+AH26+AI26 -> 4017
A27: 45271 | B27: MEIJER | C27: 美国 | D27: 4500120910 | E27: 215358772 | F27: 4500120910-10 | G27: 77515GQ1-S003 | H27: DIY厨艺大师 | I27: 1612 | J27: 0 | K27: 13 | L27: =I27/K27 -> 124 | M27: 45321 | N27: 45317 | P27: pass | Q27: 2/19入仓 | R27: 45647 | S27: 无 | T27: 无 | U27: 日期码格式：ZURU INC(BVI) 标准格式 日期：按实际生产日期 Packaging Info: 1. MA 1L 包装 2. 客人指定箱唛排版 Remark: 出货前 Zuru QC 验货 | V27: Sophia Zhou | W27: 1.7 | X27: =I27*W27 -> 2740.4 | Y27: 84025-2.20 | Z27: 77515GQ1-S003 | AA27: 已入 | AE27: DG | AG27: =I27 -> 1612 | AK27: =AG27 -> 1612 | AO27: =AG27 -> 1612 | AY27: =I27/13 -> 124 | BM27: =AG27+AH27+AI27 -> 1612
A28: 45271 | B28: MEIJER | C28: 美国 | D28: 4500120915 | E28: 215358800 | F28: 4500120915-10 | G28: 77515GQ1-S003 | H28: DIY厨艺大师 | I28: 806 | J28: 0 | K28: 13 | L28: =I28/K28 -> 62 | M28: 45321 | N28: 45317 | P28: pass | Q28: 2/19入仓 | R28: 45647 | S28: 无 | T28: 无 | U28: 日期码格式：ZURU INC(BVI) 标准格式 日期：按实际生产日期 Packaging Info: 1. MA 1L 包装 2. 客人指定箱唛排版 Remark: 出货前 Zuru QC 验货 | V28: Sophia Zhou | W28: 1.7 | X28: =I28*W28 -> 1370.2 | Y28: 84027-2.20 | Z28: 77515GQ1-S003 | AA28: 已入 | AE28: DG | AG28: =I28 -> 806 | AK28: =AG28 -> 806 | AO28: =AG28 -> 806 | AY28: =I28/13 -> 62 | BM28: =AG28+AH28+AI28 -> 806
A29: 45271 | B29: MEIJER | C29: 美国 | D29: 4500120914 | E29: 215358783 | F29: 4500120914-10 | G29: 77515GQ1-S003 | H29: DIY厨艺大师 | I29: 806 | J29: 0 | K29: 13 | L29: =I29/K29 -> 62 | M29: 45321 | N29: 45317 | P29: pass | Q29: 2/19入仓 | R29: 45647 | S29: 无 | T29: 无 | U29: 日期码格式：ZURU INC(BVI) 标准格式 日期：按实际生产日期 Packaging Info: 1. MA 1L 包装 2. 客人指定箱唛排版 Remark: 出货前 Zuru QC 验货 | V29: Sophia Zhou | W29: 1.7 | X29: =I29*W29 -> 1370.2 | Y29: 84026-2.20 | Z29: 77515GQ1-S003 | AA29: 已入 | AE29: DG | AG29: =I29 -> 806 | AK29: =AG29 -> 806 | AO29: =AG29 -> 806 | AY29: =I29/13 -> 62 | BM29: =AG29+AH29+AI29 -> 806
A30: 45271 | B30: MEIJER | C30: 美国 | D30: 4500120920 | E30: 215358830 | F30: 4500120920-10 | G30: 77515GQ1-S003 | H30: DIY厨艺大师 | I30: 416 | J30: 0 | K30: 13 | L30: =I30/K30 -> 32 | M30: 45321 | N30: 45317 | P30: pass | Q30: 2/19入仓 | R30: 45647 | S30: 无 | T30: 无 | U30: 日期码格式：ZURU INC(BVI) 标准格式 日期：按实际生产日期 Packaging Info: 1. MA 1L 包装 2. 客人指定箱唛排版 Remark: 出货前 Zuru QC 验货 | V30: Sophia Zhou | W30: 1.7 | X30: =I30*W30 -> 707.2 | Y30: 84030-2.20 | Z30: 77515GQ1-S003 | AA30: 已入 | AE30: DG | AG30: =I30 -> 416 | AK30: =AG30 -> 416 | AO30: =AG30 -> 416 | AY30: =I30/13 -> 32 | BM30: =AG30+AH30+AI30 -> 416
A31: 45271 | B31: MEIJER | C31: 美国 | D31: 4500120909 | E31: 215358756 | F31: 4500120909-10 | G31: 77515GQ1-S003 | H31: DIY厨艺大师 | I31: 1989 | J31: 0 | K31: 13 | L31: =I31/K31 -> 153 | M31: 45321 | N31: 45317 | P31: pass | Q31: 2/19入仓 | R31: 45647 | S31: 无 | T31: 无 | U31: 日期码格式：ZURU INC(BVI) 标准格式 日期：按实际生产日期 Packaging Info: 1. MA 1L 包装 2. 客人指定箱唛排版 Remark: 出货前 Zuru QC 验货 | V31: Sophia Zhou | W31: 1.7 | X31: =I31*W31 -> 3381.3 | Y31: 84024-2.20 | Z31: 77515GQ1-S003 | AA31: 已入 | AE31: DG | AG31: =I31 -> 1989 | AK31: =AG31 -> 1989 | AO31: =AG31 -> 1989 | AY31: =I31/13 -> 153 | BM31: =AG31+AH31+AI31 -> 1989
A32: 45222 | B32: AMAZON FR | C32: 法国 | D32: 4500116508 | E32: 6MVKQO1E | F32: 4500116508-10 | G32: 77515-S001 | H32: DIY厨艺大师 | I32: 984 | J32: 0 | K32: 24 | L32: =I32/K32 -> 41 | M32: 45324 | N32: 45320 | P32: pass | Q32: 2/19入仓 | R32: 空白外箱（加印带Zuru字样的黑色色带，除了邮包盒直接做外箱的产品 | S32: 有 | T32: 12/5 订外箱贴纸 | U32: 日期码格式：ZURU INC(BVI) 标准格式 日期：按实际生产日期 Packaging Info: Amazon FR: 1. 77515: 24pcs/ctn, no inner; MA 3L A收缩膜包装+3张贴纸(含FR/DE/IT/ES警告语<(>&<)>IT sorting label 贴纸+FR sorting label贴纸+UPC#贴纸）; 2. 验货时间不迟于2024/2/5； Remark: "1.空白外箱（加印带Zuru字样的黑色色带，除了邮包盒直接做外箱的产品） + SSCC LABEL一张, 无箱唛. (SSCC LABEL贴在外箱正面的正中间，贴一面即可,贴纸离外箱边距必须至少3CM),SSCC贴纸由工厂直接跟勤得采购或者工厂自行采购，每一张SSCC Label都是唯一且 有不同流水及条码，且需要检查条码是否能正常扫描，如工厂不按此要求导致贴纸有任何问题产生的罚款将由工厂承担一切责任 。’MADE IN CHINA 外箱只印一正 一侧。 2. 出往UK的产品+包装务必打上UKCA logo ，否则客人会退货且当地会有罚款。 3.订单必须经过ZURU QC验货并且通过后方可出货。 4.法国订单要求包装不使用矿物油，请按要求提供以下其中一份文件再出货 ，产品出到法国被相关部门抽检出现包装不符合此要求的，供应商需要为此承担责任， 故此请严格把关 。 -油墨物质""由1 ~ 7个芳香环组成的MOAH""的包装检测报告，要求限值≤1.0%; 或 -包装材料清单，包括包装油墨或物质的信息 -油墨制造商的证书。 | V32: Crystal Chen | W32: 1.19 | X32: =I32*W32 -> 1170.96 | Y32: 84008-2.19 | Z32: 77515-S001-3L | AA32: 已入 | AE32: DG | AG32: =I32 -> 984 | AL32: =AG32 -> 984 | AO32: =AG32 -> 984 | BM32: =AG32+AH32+AI32 -> 984
A33: 45282 | B33: KMART AUSTRALIA LTD | C33: 澳大利亚 | D33: 4500121356 | E33: 19789620 | F33: 4500121356-70 | G33: 77515GQ1-S003 | H33: DIY厨艺大师 | I33: 5928 | J33: 0 | K33: 13 | L33: =I33/K33 -> 456 | M33: 45342 | N33: 45338 | P33: pass | Q33: 2/22入仓 | R33: 45655 | S33: 有 | T33: 45299 | U33: 日期码格式：ZURU INC(BVI) 标准格式 日期：按实际生产日期 Packaging Info: 3.77515GQ1:MA英语UPC版本包装（首选1LUPC，如果无1L可用多语含英语UPC版本）+防盗贴纸+箱唛+箱唛贴纸(1PCS/CTN),77515防盗贴纸请贴在顶部中央，大货生产前请返回1pcs确认.此外77515含纽扣电池，需要增加电池警告语贴纸，贴纸及其位置图后面提供 Remark: 1,请务必按时完货，验货并请按期送货入货代指定仓库，如果晚了导致船期Delay将会有罚金产生或者客户要求空运，所产生的罚金和空运费由工厂承担。 2.SSCC 外箱贴纸请同纸箱瓦楞纸方向（竖纹向）垂直，即外箱贴纸横着贴(注意条码不要被胶带粘住），贴1pc，贴1面正唛，封箱胶纸不能挡住贴纸内容。每pcs外 箱贴纸都是唯一的，不可重复粘贴，否则会有罚款产生。 3.外箱材质为ZURU标准； 4.此单需使用KMART封箱胶上下工字型封箱;从2019年6月开始，要用KMART 新版封箱胶带，此单要用"ANKO"封箱胶带 5.此单出口澳大利亚，请按相应的澳新标准生产； 6.产品和包装上生产批号的显示格式ZURU标准日期码格式 7. 77515GQ1-S003:3PCS AG13 Batteries(Included) | V33: Sara Wang | W33: 1.7 | X33: =I33*W33 -> 10077.6 | Y33: 84074-2.26 | Z33: 77515GQ1-S003 | AA33: 已入 | AE33: DG | AG33: =I33 -> 5928 | AK33: =AG33 -> 5928 | AO33: =AG33 -> 5928 | AY33: =I33/13 -> 456 | BM33: =AG33+AH33+AI33 -> 5928
A34: 45282 | B34: TARGET US | C34: 美国 | D34: 4500121729 | E34: 0086-1793817-0581 | F34: 4500121729-10 | G34: 77515GQ5-S002 | H34: DIY厨艺大师 | I34: 35007 | J34: 0 | K34: 21 | L34: =I34/K34 -> 1667 | M34: 45342 | N34: 45338 | P34: pass | Q34: 2/22 客上柜 | R34: 45296 | S34: 有 | T34: 1/11 寄出 | U34: 日期码格式：ZURU INC(BVI) 标准格式 日期：按实际生产日期 Packaging Info: 产品包装MA 1L, MA PDQ Remark: 1. 77515GQ5-S002-MINI BRAND-MASTER CHEF MINI BRANDS-SERIES 1,21pcs/Gravity PDQ, 21pcs/CTN,No Inner,STD Color Assortment (White drop) 2. 产品包装MA 1L, MA PDQ, 产品UPC 显示193052061034; 11 assortment have the same ratio； 3. 外箱正唛左上角位置粘贴条码箱贴纸，每箱只贴一张，由ZURU订购。来料贴纸上显示的客户DPCI# 086-02-9598， UPC显示10193052061031; 4. 产品和包装上印刷 tracking code信息，格式为ZURU常规格式; 5. 出货方式：货代自提。 | V34: Holly Zheng | W34: 1.75 | X34: =I34*W34 -> 61262.25 | Y34: 84048-2.22 | Z34: 77515GQ5-S002 | AA34: 已入 | AE34: DG | AG34: =I34 -> 35007 | AK34: =AG34 -> 35007 | AO34: =AG34 -> 35007 | AS34: =I34/21 -> 1667 | BM34: =AG34+AH34+AI34 -> 35007
A35: 45282 | B35: TARGET US | C35: 美国 | D35: 4500121728 | E35: 0086-1260120-0581 | F35: 4500121728-10 | G35: 77515GQ5-S002 | H35: DIY厨艺大师 | I35: 9996 | J35: 0 | K35: 21 | L35: =I35/K35 -> 476 | M35: 45342 | N35: 45338 | P35: pass | Q35: 2/24 客上柜 | R35: 45296 | S35: 有 | T35: 1/11 寄出 | U35: 日期码格式：ZURU INC(BVI) 标准格式 日期：按实际生产日期 Packaging Info: 产品包装MA 1L, MA PDQ Remark: 1. 77515GQ5-S002-MINI BRAND-MASTER CHEF MINI BRANDS-SERIES 1,21pcs/Gravity PDQ, 21pcs/CTN,No Inner,STD Color Assortment (White drop) 2. 产品包装MA 1L, MA PDQ, 产品UPC 显示193052061034; 11 assortment have the same ratio； 3. 外箱正唛左上角位置粘贴条码箱贴纸，每箱只贴一张，由ZURU订购。来料贴纸上显示的客户DPCI# 086-02-9598， UPC显示10193052061031; 4. 产品和包装上印刷 tracking code信息，格式为ZURU常规格式; 5. 出货方式：货代自提。 | V35: Holly Zheng | W35: 1.75 | X35: =I35*W35 -> 17493 | Y35: 84082-2.27 | Z35: 77515GQ5-S002 | AA35: 已入 | AE35: DG | AG35: =I35 -> 9996 | AK35: =AG35 -> 9996 | AO35: =AG35 -> 9996 | AS35: =I35/21 -> 476 | BM35: =AG35+AH35+AI35 -> 9996
A36: 45285 | B36: ZURU | C36: 库有 | D36: MPO02537 | G36: 77515GQ6-S001 | H36: DIY厨艺大师 | I36: 7200 | J36: 0 | K36: 36 | L36: =I36/K36 -> 200 | M36: 45345 | N36: 45341 | P36: pass | Q36: 2/29 送库有组装 | R36: 周转箱 | S36: 无 | T36: 45306 | U36: Remark: 1.77515GQ6: MA 1L收缩膜+1张防盗标贴纸贴在球的顶部（工厂自行订购此贴纸，此防盗贴纸产品款号:10111896/产品名称: 40R ECON YBL DE 8.2 1kr）+MA 1L PDQ+MA 23 L收藏指南/说明书+MA 5L ACCESSORY BAG; UPC#193052061034，请先检查条码是否正确再安排做货; 2. 产品及包装需要印UKCA图标，包装需要有ZURU UK LTD/ZURU France地址信息，QC同事请核查，如有问题与跟单确认 3.每座展示架放3个#77515GQ6 PDQ=12x3=36pcs，请务必按照每座展示架数量配好每个assortment的配比，方便组装厂直接组装展示架，配比跟MA标准款，如有不清楚 的请找客制部和跟单核查 4.外箱可以直接用周转箱或者其他，工厂自行安排即可，请在外箱上写好每箱装多少和总箱数方便点数； 5.送货到库有时请在送货单上备库有客供给TESCO UK PO#/#MSLD76组装展示架用 6.组装厂会安排最终验货，请准备好备品，验货后需要马上安排补货，届时请务必按时送货到库有厂 7.请确保交货数量准确，与收货方交收清楚，如收货方提出任何异常，请立即安排处理解决。 8.以上订单的任何生产要求与资料、要求备品数量等等，请以跟单发给贵司的邮件为准！ 9.子件工厂在交货到母件工厂时，将MPO（有注明45开头订单号）附在送货单上一起送货,或者送货单上备注45开头订单号。 | V36: Sheba | W36: 1.6 | X36: =I36*W36 -> 11520 | Y36: 86012R1-7.16 | Z36: 77515GQ6-S001 | AA36: 已入 | AE36: DG | AG36: =I36 -> 7200 | AK36: =AG36 -> 7200 | AO36: =AG36 -> 7200 | AW36: =I36/12 -> 600 | BM36: =AG36+AH36+AI36 -> 7200
A37: 45258 | B37: Smyths Toys HQ UC UK | C37: 英国 | D37: 4500119795 | E37: 4400364357 | F37: 4500119795-10 | G37: 77515GQ5-S001 | H37: DIY厨艺大师 | I37: 10038 | J37: 0 | K37: 42 | L37: =I37/K37 -> 239 | M37: 45349 | N37: 45345 | P37: pass | Q37: 2/28 出货 | R37: 45287 | S37: 无 | T37: 45299 | U37: 日期码格式：ZURU INC(BVI) 标准格式 日期：按实际生产日期 Packaging Info: 77515GQ5:MA 3L最新收缩膜+贴纸（德国CALLOUT 和荷兰警告语 ）+UPC贴纸（UPC#193052061034） +MA 5L收藏指南+MA3LPDQ Remark: 1）包装日期码按ZURU格式即可，请确保不迟于外箱日期码，可等于或者早于外箱日期码，必须为法定工作日，印刷前请先检查外箱日期码。 2）订单出英国，请注意检查产品及包装应带UKCA图标（14+产品除外），包装显示ZURU UK LTD/ZURU France地址信息，QC部门请查核，如有问题与跟单确认 3）订单必须经过ZURU QC验货并且通过后方可出货。 | V37: Sheba Ye | W37: 1.649 | X37: =I37*W37 -> 16552.662 | Y37: 84103-2.29 | Z37: 77515GQ5-S001-3L | AA37: 已入 | AE37: DG | AG37: =I37 -> 10038 | AL37: =I37 -> 10038 | AO37: =AG37 -> 10038 | AT37: =I37/21 -> 478 | BM37: =AG37+AH37+AI37 -> 10038
A38: 45258 | B38: Smyths Toys HQ UC UK | C38: 爱尔兰 | D38: 4500119796 | E38: 4400364358 | F38: 4500119796-10 | G38: 77515GQ5-S001 | H38: DIY厨艺大师 | I38: 3108 | J38: 0 | K38: 42 | L38: =I38/K38 -> 74 | M38: 45349 | N38: 45345 | P38: pass | Q38: 2/28 出货 | R38: 45287 | S38: 无 | T38: 45299 | U38: 日期码格式：ZURU INC(BVI) 标准格式 日期：按实际生产日期 Packaging Info: 77515GQ5:MA 3L最新收缩膜+贴纸（德国CALLOUT 和荷兰警告语 ）+UPC贴纸（UPC#193052061034） 全部贴纸翻#4500119795+MA 5L收藏指南+MA3LPDQ Remark: 1）包装日期码按ZURU格式即可，请确保不迟于外箱日期码，可等于或者早于外箱日期码，必须为法定工作日，印刷前请先检查外箱日期码。 2）订单出英国，请注意检查产品及包装应带UKCA图标（14+产品除外），包装显示ZURU UK LTD/ZURU France地址信息，QC部门请查核，如有问题与跟单确认 3）订单必须经过ZURU QC验货并且通过后方可出货。 | V38: Sheba Ye | W38: 1.649 | X38: =I38*W38 -> 5125.092 | Y38: 84104-2.29 | Z38: 77515GQ5-S001-3L | AA38: 已入 | AE38: DG | AG38: =I38 -> 3108 | AL38: =I38 -> 3108 | AO38: =AG38 -> 3108 | AT38: =I38/21 -> 148 | BM38: =AG38+AH38+AI38 -> 3108
A39: 45279 | B39: THE ENTERTAINER | C39: 英国 | D39: 4500121348 | E39: FB10932 | F39: 4500121348-30 | G39: 77515GQ5-S001 | H39: DIY厨艺大师 | I39: 14028 | J39: 0 | K39: 42 | L39: =I39/K39 -> 334 | M39: 45350 | N39: 45346 | P39: pass | Q39: 2/29 出货 | R39: 45651 | S39: 无 | T39: 45294 | U39: 日期码格式：ZURU INC(BVI) 标准格式 日期：按实际生产日期 Packaging Info: 77515GQ5-S001:MA-3L+5L warning 配套包装(必须为多语warning 版本，需要在西班牙售卖）+一张条码贴覆盖ZURU条码，另外产品内包装再加多一张9国语言电池说 明书（电池说明书和77489相同） ，即产品内含2张说明书 （ZURU标准说明书1张+9国语言电池说明书） 产品信息：11 assortment have the same ratio Remark: *包装日期码按ZURU格式即可，请确保不迟于外箱日期码，可等于或者早于外箱日期码，必须为法定工作日。 *订单必须经过ZURU QC验货并且通过后方可出货。 *MA版本按工厂现有最新库存即可，请注意检查产品及包装应带UKCA图标，包装显示ZURU UK LTD信息，QC同事请查核，如有问题与跟单确认。 *订单必须经过ZURU QC验货并且通过后方可出货。 *条码以订单为准，请做货前先核对再安排生产 。 *产品会同时在英国和西班牙市场售卖 ，注意按要求使用多语warning 包装版本。 | V39: Sherry Lu | W39: 1.649 | X39: =I39*W39 -> 23132.172 | Y39: 84125-3.2 | Z39: 77515GQ5-S001-3L | AA39: 已入 | AE39: DG | AG39: =I39 -> 14028 | AL39: =I39 -> 14028 | AO39: =AG39 -> 14028 | AT39: =I39/21 -> 668 | BM39: =AG39+AH39+AI39 -> 14028
A40: 45285 | B40: KMART AUSTRALIA LTD(NEW ZEALAND) | C40: 新西兰 | D40: 4500122071 | E40: 19631979 | F40: 4500122071-10 | G40: 77515GQ1-S003 | H40: DIY厨艺大师 | I40: 1495 | J40: 0 | K40: 13 | L40: =I40/K40 -> 115 | M40: 45348 | N40: 20024/2/22 | P40: AOD 漏说明书贴纸 | Q40: 3/1 交仓 | R40: 45294 | S40: 有 | T40: 45307 | U40: 日期码格式：ZURU INC(BVI) 标准格式 日期：按实际生产日期 Packaging Info: 77515GQ1:MA英语UPC版本包装（首选3LUPC，如果无1L可用多语含英语UPC版本）+防盗贴纸+箱唛+箱唛贴纸(1PCS/CTN).此外77515含纽扣电池，需要增加电池警告语 贴纸.防盗贴纸和警告语贴纸以及他们的位置图请跟回PO#4500121356 Remark: 1,请务必按时完货，验货并请按期送货入货代指定仓库，如果晚了导致船期Delay将会有罚金产生或者客户要求空运，所产生的罚金和空运费由工厂承担。 2.SSCC 外箱贴纸请同纸箱瓦楞纸方向（竖纹向）垂直，即外箱贴纸横着贴(注意条码不要被胶带粘住），贴1pc，贴1面正唛，封箱胶纸不能挡住贴纸内容。每pcs外 箱贴纸都是唯一的，不可重复粘贴，否则会有罚款产生。 3.外箱材质为ZURU标准； 4.此单需使用KMART封箱胶上下工字型封箱;从2019年6月开始，要用KMART 新版封箱胶带，此单要用"ANKO"封箱胶带 5.此单出口新西兰，请按相应的澳新标准生产； 6.产品和包装上生产批号的显示格式ZURU标准日期码格式 7.77515GQ1-S003:3PCS AG13 Batteries(Included) | V40: Sara Wang | W40: 1.7 | X40: =I40*W40 -> 2541.5 | Y40: 84124-3.2 | Z40: 77515GQ1-S003-3L | AA40: 已入 | AE40: DG | AG40: =I40 -> 1495 | AL40: =AG40 -> 1495 | AO40: =AG40 -> 1495 | AY40: =I40/13 -> 115 | BM40: =AG40+AH40+AI40 -> 1495
...

Sheet 77515 DIY厨艺大师 旧排期
A1: ZURU （77515 Mini Brands 迷你球DIY厨艺系列）生产排期表 | G1: 走KM澳洲和出新西兰的说明书都要加纽扣电池警语贴纸 | N1: 77515出加拿大的3L都需要双语logo，最新版本77515GQ1 GQ2 GQ5 GQ6 SK SK1 纸袋 收藏指南 收缩膜 | U1: 77555SK1-S002这款是带底座 | AH1: 77515 | AN1: 收縮膜 | AU1: 收藏指南 | BB1: PDQ盒 | BK1: GQ1 | BW1: 77516 | CB1: 总MA | CC1: ='生产MA Summary'!O4 -> 4670000
A2: 香港接单日期 | B2: 第三方客户名称 | C2: 走货国家 | D2: ZURU PO NO# | E2: 第三方客户 PO NO# | F2: SKU | G2: ITEM# | H2: 中文名 | I2: PO数量 (pcs) | J2: 内箱装箱数量(pcs) | K2: 外箱装箱数量(pcs) | L2: 总箱数 | M2: 计划出货期 | N2: 计划验货期 | O2: 第三方客户公证行验货 | P2: 驗貨結果 | Q2: S/0船期 | R2: 箱唛资料(收到日期) | S2: 外箱贴纸 | T2: 客供贴纸AI(收到日期) | U2: 备注 | V2: ZURU 跟单 | W2: 单价USD | X2: 金额USD | Y2: 發票號 | Z2: 系统货号 | AA2: 是否入系统 | AB2: 采购单 | AC2: 已送情况 | AD2: 欠数 | AE2: 贴纸 | AF2: 生产地点 | AH2: 球数 | AI2: 无香味版本 | AJ2: 删除组合10（猪肉） | AK2: MA 3语 收缩膜 无条码 | AL2: 无UPC版本 | AM2: 新无UPC版本-C | AN2: MA 1语收缩膜 | AO2: MA 3语收缩膜 | AP2: MA 1语C版收缩膜 | AQ2: MA 3语C版本收缩膜 | AR2: 客版收缩膜 | AS2: ACTION 客版1L收缩膜+客版15L吊牌+客版UV灯说明书 | AT2: 客版 3L 收缩膜 | AU2: MA 5L语收藏指南 | AV2: MA 5LB版语收藏指南 | AW2: ESAL客版指南/说明书 | AX2: WM客版 | AY2: 外挂中文收藏指南+中文收藏指南(每一款都不同) | AZ2: MA 23L_C_IFUD声明补充说明书 | BA2: WEE带电说明书 | BB2: GQ5-S001 21PCS 1L | BC2: GQ5-S001 21PCS 3L | BD2: GQ5 B3L | BE2: WM 客版GQ5 | BF2: WM 客版GQ6 | BG2: GQ6-S001 12PCS 1L | BH2: GQ6-S001 12PCS 3L | BI2: GQ1-S001 13pcs 1L | BJ2: GQ1-S001 13pcs 3L | BK2: B版 1L | BL2: B版 3L | BM2: GQ2-S001 25pcs 1L | BN2: GQ2-S001 25pcs 3L | BO2: SK-S001 60PCS 1L 不含底座 配挂钩 | BP2: SK-S002 60PCS 1L 含底座 | BQ2: SK-S002 60PCS 3L 含底座 | BR2: 77515SK1-S002 30pcs 1L 含底座 | BS2: 77515SK1-S001 30pcs 3L 不带底座 | BT2: SK1底座 | BU2: FD客 77515GQ3 | BV2: 77515GQ3-S001 客版 8PCS | BW2: 圆筒 | BX2: 3L 彩纸 | BY2: B版本 3L 彩纸 | BZ2: 合计数量 | CB2: 已删减实单 | CC2: 2862563 | CD2: MA剩余 | CE2: =CC1-CC2 -> 1807437
A3: 45252 | B3: ZURU | C3: 库有 | D3: ZPO2311001 | G3: 77515-S001 | H3: DIY厨艺大师 | I3: 510 | J3: 0 | K3: 24 | L3: =I3/K3 -> 21.25 | M3: 45272 | N3: 45268 | P3: OK | R3: 周转箱 | S3: 无 | T3: 无 | Z3: 无 | AF3: DG | AH3: =I3 -> 510 | BZ3: =AH3+AI3+AJ3 -> 510 | CE3: =CE2-AH3-AI3-AJ3 -> 1806927
A4: 45279 | B4: ZURU | C4: 库有 | D4: ZMPO23783 | G4: 77515-S001 | H4: DIY厨艺大师 | I4: 5套 | J4: 0 | K4: 24 | L4: 1 | M4: 45288 | N4: 45285 | P4: OK | Q4: 3/14 寄深圳 | R4: 周转箱 | S4: 无 | T4: 无 | U4: 左图中每款散件各5PCS | Z4: 无 | AF4: DG | BZ4: =AH4+AI4+AJ4 -> 0 | CE4: =CE3-AH4-AI4-AJ4 -> 1806927
A5: 45317 | B5: ZURU | C5: 库有 | D5: ZMPO24079 | G5: 77515-S001 | H5: DIY厨艺大师 | I5: 200套散件 | J5: 0 | K5: 24 | L5: =I5/K5 -> #VALUE! | M5: 45351 | N5: 45348 | R5: 周转箱 | S5: 无 | T5: 无 | U5: 左图中14款酱每款200PCS/共2800PCS/麻烦用胶袋分装好14款一套为一袋 | Z5: 无 | AF5: DG | AH5: 200 | BZ5: =AH5+AI5+AJ5 -> 200 | CE5: =CE4-AH5-AI5-AJ5 -> 1806727
A6: 45350 | B6: ZURU | C6: 库有 | D6: ZMPO24135 | G6: 77515GQ1-S001 | H6: DIY厨艺大师 | I6: 50个满PDQ | J6: 0 | K6: 52 | L6: =I6/K6 -> #VALUE! | M6: 45371 | N6: 45367 | P6: pass | R6: 周转箱 | S6: 无 | T6: 无 | U6: 大货最新版本/PDQ里面的产品按大货比例入PDQ/大货标准箱装箱/箱唛参照邮件附件 | Z6: 77515GQ1-S001 | AA6: 已入 | AC6: 676 | AD6: 0 | AF6: DG | AG6: 在仓库 | AN6: =50*13 -> 650 | AU6: =50*13 -> 650 | BI6: 50 | BZ6: =AH6+AI6+AJ6 -> 0 | CE6: =CE5-AH6-AI6-AJ6 -> 1806727
A7: 45411 | B7: ZURU | C7: 库有 | D7: ZMPO24312 | G7: 77515-S001 | H7: DIY厨艺大师 | I7: 120套 | J7: 0 | K7: 24 | L7: =I7/K7 -> #VALUE! | M7: 45426 | N7: 45422 | U7: 大货订单最新版本/只需要全套散件，麻烦用胶袋分装好一套为一袋；备注：收到样品订单后尽快安排 ，注意样板品质质量要求要高于大货品质要求 ，送货时必须要附带送货单(没有送货单和QC检验合格报告的仓库一律拒绝收货)，请知悉，谢谢！ | Z7: # | AC7: 120 | AD7: 0 | AF7: DG | AG7: 在仓库 | BZ7: =AH7+AI7+AJ7 -> 0 | CE7: =CE6-AH7-AI7-AJ7 -> 1806727
A8: 45491 | B8: ZURU | C8: 库有 | D8: ZMPO24559 | G8: 77515-S001 | H8: DIY厨艺大师 | I8: 80套散件 | J8: 0 | K8: 24 | L8: =I8/K8 -> #VALUE! | M8: 45514 | N8: 45510 | R8: 45491 | S8: 无 | T8: 无 | U8: 大货订单最新版本/只需要全套散件，麻烦用胶袋分装好一套为一袋；备注：收到样品订单后尽快安排 ，注意样板品质质量要求要高于大货品质要求 ，送货时必须要附带送货单(没有送货单和QC检验合格报告的仓库一律拒绝收货)，请知悉，谢谢！ | Z8: # | AC8: 80 | AD8: 0 | AF8: DG | AG8: 在仓库 | BZ8: =AH8+AI8+AJ8 -> 0 | CE8: =CE7-AH8-AI8-AJ8 -> 1806727
A9: 45593 | B9: ZURU | C9: 库有 | D9: ZMPO24801 | G9: 77515-S001 | H9: DIY厨艺大师 | I9: 3000 | J9: 0 | K9: 24 | L9: =I9/K9 -> 125 | M9: 45608 | N9: 45612 | R9: 45593 | S9: 无 | T9: 无 | U9: 只需77198的白色空球，只需用外面透明收缩膜压缩就好，不需要彩色收缩膜 | V9: Angus | Z9: 77515-S001-2 | AA9: 已入 | AC9: 3000 | AD9: =AC9-I9 -> 0 | BZ9: =AH9+AI9+AJ9 -> 0 | CE9: =CE8-AH9-AI9-AJ9 -> 1806727
A10: 45608 | B10: CMS FAMOUS TOYS | C10: 加拿大 | D10: 4500151018 | E10: PO0000475 | F10: 4500151018-40 | G10: 77515GQ1-S003 | H10: DIY厨艺大师 | I10: 1495 | J10: 0 | K10: 13 | L10: =I10/K10 -> 115 | M10: 45651 | N10: 45647 | P10: pass | Q10: 1/2 截SI | R10: 45621 | S10: 无 | T10: 11/25 UPC贴纸 | U10: 日期码格式： 标准格式 日期：按实际生产日期 Tracking Code: Packaging Info: 77515GQ1 MA 多语EAN+UPC贴纸。UPC号码193052061034 Remark: 出加拿大 每款产品都需要加进口商贴纸 Zuru验货.日期跟踪码：产品外包装及产品本身都必须有日期跟踪码，ZURU标准格式日期码 | V10: Summer Mo | W10: 1.4071 | X10: =I10*W10 -> 2103.6145 | Y10: 88842-1.2 | Z10: 77515GQ1-S003-3L | AA10: 已入 | AC10: 1495 | AD10: =AC10-I10 -> 0 | AG10: 在仓库 七 | AH10: =I10 -> 1495 | AO10: =I10 -> 1495 | AU10: =I10 -> 1495 | BJ10: =I10/13 -> 115 | BZ10: =AH10+AI10+AJ10 -> 1495 | CE10: =CE9-AH10-AI10-AJ10 -> 1805232
A11: 45586 | B11: ROSS PROCUREMENT.INC | C11: 美国 | D11: 4500148421 | E11: 60190475 | F11: 4500148421-10 | G11: 77516-S001 | H11: DIY厨艺大师*2 | I11: 6000 | J11: 0 | K11: 12 | L11: =I11/K11 -> 500 | M11: 45653 | N11: 45649 | P11: pass | Q11: 1/3 截SI | R11: 45588 | S11: 无 | T11: 11/20 客供价格贴纸+UPC贴纸 | U11: 日期码格式： 标准格式 日期：按实际生产日期 Packaging Info: URU MA UPC 收缩膜+客版铜版纸+PVC桶 + 客供价格贴纸，出口美国 , 优先使用MA 1L 最新版本 。 Remark: 1.ZURU MA UPC 收缩膜+客版铜版纸+PVC桶 + 客供价格贴纸，出口美国 , 优先使用MA 1L 最新版本 。 2.价格贴纸位于包装正面右下角，不挡住重要信息即可，可适当调整 ，价格贴纸由跟单提供。 3.标准日期码格式，产品和包装必须有日期码 。 4.同个产品同个货期不可出现不同的包装。 5. PVC 桶中球不能出现完全相同的ASSORTMENT ， 即同一个PVC 中球里的ASSORTMENT 需要不同。 以免消费者失望。 6.PVC 桶上加上 MINI BRANDS 的LOGO 贴纸 （ ZURU 统一要求的） 7.收缩膜可使用标版带UPC条码MA，无需白色贴纸覆盖。 8. #77516 可用MA 3L包装，用UPC 贴纸覆盖EAN 条码。 | V11: Sophia Zhou | W11: 3.0438 | X11: =I11*W11 -> 18262.8 | Y11: 88928-1.7 | Z11: 77516-S001-1L | AA11: 已入 | AC11: 6000 | AD11: =AC11-I11 -> 0 | AG11: 在仓库 七 | AH11: =I11*2 -> 12000 | AO11: =AH11 -> 12000 | AU11: =AH11 -> 12000 | BW11: =I11 -> 6000 | BX11: =I11 -> 6000 | BZ11: =AH11+AI11+AJ11 -> 12000 | CE11: =CE10-AH11-AI11-AJ11 -> 1793232
A12: 45614 | B12: Amazon Mexico, S. DE R.L. DE CV | C12: 墨西哥 | D12: 4500151559 | E12: 2YATGWVR | F12: 4500151559-10 | G12: 77515-S001 | H12: DIY厨艺大师 | I12: 24 | J12: 0 | K12: 24 | L12: =I12/K12 -> 1 | M12: 45649 | N12: 45645 | P12: 自检 | Q12: 1/3 交仓 | R12: 空白外箱加印ZURU Logo+MADE IN CHINA | S12: 有 | T12: 12/4UPC贴纸+进口商贴纸+12/6 SSCC贴纸 | U12: 日期码格式：ZURU INC(BVI) 标准格式 日期：按实际生产日期 Packaging Info: 77515: MA 3L+UPC贴纸+进口商贴纸+SSCC贴纸 Remark: Amazon FOB订单，出口Mexico，外箱最长边不能超过25" （超过了，case pack只能为1），不符合要求的大货，一律不接受。 1.空白外箱加印ZURU Logo+MADE IN CHINA+SSCC LABEL(客供贴纸），无shipping mark,日期使用ZURU 标准版本。SSCC Label显示的是客人自己的item#，SSCC Lab el 贴在外箱正面的正中间，贴一面即可，跟单订购，贴纸离外箱距必须至少3cm,每一张SSCC Label都是唯一且有不同流水及条码的，没有损耗，绝对不可贴错，否 则贴错或损坏一张会导致全部都错，千万要注意！ 2. 日期码使用ZURU标准版 3. 客户PO备注在remark处 4.77515: 3PCS AG13 Batteries(Included) | V12: Zoe Luo | W12: 1.3938 | X12: =I12*W12 -> 33.4512 | Y12: 88897-1.6 | Z12: 77515-S001-3L | AA12: 已入 | AC12: 240 | AD12: =AC12-I12 -> 216 | AG12: 在仓库 七 | AH12: =I12 -> 24 | AO12: =I12 -> 24 | AU12: =I12 -> 24 | BZ12: =AH12+AI12+AJ12 -> 24 | CE12: =CE11-AH12-AI12-AJ12 -> 1793208
A13: 45614 | B13: Amazon Mexico, S. DE R.L. DE CV | C13: 墨西哥 | D13: 4500151559 | E13: 64SP3ZYY | F13: 4500151559-100 | G13: 77515-S001 | H13: DIY厨艺大师 | I13: 384 | J13: 0 | K13: 24 | L13: =I13/K13 -> 16 | M13: 45649 | N13: 45645 | P13: 自检 | Q13: 1/3 交仓 | R13: 空白外箱加印ZURU Logo+MADE IN CHINA | S13: 有 | T13: 12/4UPC贴纸+进口商贴纸+12/6 SSCC贴纸 | U13: 日期码格式：ZURU INC(BVI) 标准格式 日期：按实际生产日期 Packaging Info: 77515: MA 3L+UPC贴纸+进口商贴纸+SSCC贴纸 Remark: Amazon FOB订单，出口Mexico，外箱最长边不能超过25" （超过了，case pack只能为1），不符合要求的大货，一律不接受。 1.空白外箱加印ZURU Logo+MADE IN CHINA+SSCC LABEL(客供贴纸），无shipping mark,日期使用ZURU 标准版本。SSCC Label显示的是客人自己的item#，SSCC Lab el 贴在外箱正面的正中间，贴一面即可，跟单订购，贴纸离外箱距必须至少3cm,每一张SSCC Label都是唯一且有不同流水及条码的，没有损耗，绝对不可贴错，否 则贴错或损坏一张会导致全部都错，千万要注意！ 2. 日期码使用ZURU标准版 3. 客户PO备注在remark处 4.77515: 3PCS AG13 Batteries(Included) | V13: Zoe Luo | W13: 1.3938 | X13: =I13*W13 -> 535.2192 | Y13: 88897-1.6 | Z13: 77515-S001-3L | AA13: 已入 | AC13: 384 | AD13: =AC13-I13 -> 0 | AG13: 在仓库 七 | AH13: =I13 -> 384 | AO13: =I13 -> 384 | AU13: =I13 -> 384 | BZ13: =AH13+AI13+AJ13 -> 384 | CE13: =CE12-AH13-AI13-AJ13 -> 1792824
A14: 45621 | B14: WAL-MART STORES INC. USA | C14: 美国 | D14: 4500152220 | E14: RIDGEVILLE SC0881401673 | F14: 4500152220-10 | G14: 77515GQ5-S002 | H14: DIY厨艺大师 | I14: 966 | J14: 0 | K14: 21 | L14: =I14/K14 -> 46 | M14: 45649 | N14: 45645 | O14: 12/23 BV | P14: pass | Q14: 1/6 截SI | R14: 45621 | S14: 有 | T14: 12/6RFID | U14: 日期码格式：ZURU DGYYYYMMDD CHINA(日期避开周末和法定节假日即可） 日期：按实际生产日期 Tracking Code: Packaging Info: 77515GQ5-S002 1.包装要求： MA B版 1L收缩膜+客版 A版 5L收藏指南+MA A版 5L纸袋+MA A版 23L说明书+客版 1L PDQ，翻单：4500142765 每pcs产品上要贴1张RFID贴纸，贴纸由ZURU提供，贴纸位置请严格按照我们签回的签板； Remark: 77515GQ5-S002 1.包装要求： MA B版 1L收缩膜+客版 A版 5L收藏指南+MA A版 5L纸袋+MA A版 23L说明书+客版 1L PDQ，翻单：4500142765 每pcs产品上要贴1张RFID贴纸，贴纸由ZURU提供，贴纸位置请严格按照我们签回的签板； 2. 外箱印刷带条码的RFID箱唛：RFID紫色色带+WM Dept.图标+RFID图标+ITF-14条码，四面右下角印刷ZURU logo, ITFF条码只印刷在正唛一面，在加印的时候确保 条形码能扫描出来，外箱侧面任一角落加印："MADE IN CHINA" 字样； 3. 在产品上和包装上要有日期码、以及要有MADE IN CHINA和ZURU字样； 4. 产品如有扎带口要剪平，不能刮手。 5. 此单需要验货，请多备料 6. 此单以loose carton出货，21pcs/PDQ/CTN | V14: Maggie Xie | W14: 1.4585 | X14: =I14*W14 -> 1408.911 | Z14: 77515GQ5-S002-WM | AA14: 已入 | AC14: 966 | AD14: =AC14-I14 -> 0 | AG14: 在仓库 七 | AH14: =I14 -> 966 | AN14: =I14 -> 966 | AX14: =I14 -> 966 | BE14: =I14/21 -> 46 | BZ14: =AH14+AI14+AJ14 -> 966 | CE14: =CE13-AH14-AI14-AJ14 -> 1791858
A15: 45621 | B15: WAL-MART STORES INC. USA | C15: 美国 | D15: 4500152220 | E15: EASTVALE08814 01675 | F15: 4500152220-20 | G15: 77515GQ5-S002 | H15: DIY厨艺大师 | I15: 1197 | J15: 0 | K15: 21 | L15: =I15/K15 -> 57 | M15: 45649 | N15: 45645 | O15: 12/23 BV | P15: pass | Q15: 1/4 截仓 | R15: 45621 | S15: 有 | T15: 12/6RFID | U15: 日期码格式：ZURU DGYYYYMMDD CHINA(日期避开周末和法定节假日即可） 日期：按实际生产日期 Tracking Code: Packaging Info: 77515GQ5-S002 1.包装要求： MA B版 1L收缩膜+客版 A版 5L收藏指南+MA A版 5L纸袋+MA A版 23L说明书+客版 1L PDQ，翻单：4500142765 每pcs产品上要贴1张RFID贴纸，贴纸由ZURU提供，贴纸位置请严格按照我们签回的签板； Remark: 77515GQ5-S002 1.包装要求： MA B版 1L收缩膜+客版 A版 5L收藏指南+MA A版 5L纸袋+MA A版 23L说明书+客版 1L PDQ，翻单：4500142765 每pcs产品上要贴1张RFID贴纸，贴纸由ZURU提供，贴纸位置请严格按照我们签回的签板； 2. 外箱印刷带条码的RFID箱唛：RFID紫色色带+WM Dept.图标+RFID图标+ITF-14条码，四面右下角印刷ZURU logo, ITFF条码只印刷在正唛一面，在加印的时候确保 条形码能扫描出来，外箱侧面任一角落加印："MADE IN CHINA" 字样； 3. 在产品上和包装上要有日期码、以及要有MADE IN CHINA和ZURU字样； 4. 产品如有扎带口要剪平，不能刮手。 5. 此单需要验货，请多备料 6. 此单以loose carton出货，21pcs/PDQ/CTN | V15: Maggie Xie | W15: 1.4585 | X15: =I15*W15 -> 1745.8245 | Z15: 77515GQ5-S002-WM | AA15: 已入 | AC15: 1197 | AD15: =AC15-I15 -> 0 | AG15: 在仓库 七 | AH15: =I15 -> 1197 | AN15: =I15 -> 1197 | AX15: =I15 -> 1197 | BE15: =I15/21 -> 57 | BZ15: =AH15+AI15+AJ15 -> 1197 | CE15: =CE14-AH15-AI15-AJ15 -> 1790661
A16: 45621 | B16: WAL-MART STORES INC. USA | C16: 美国 | D16: 4500152220 | E16: SUFFOLK088140 1672 | F16: 4500152220-30 | G16: 77515GQ5-S002 | H16: DIY厨艺大师 | I16: 987 | J16: 0 | K16: 21 | L16: =I16/K16 -> 47 | M16: 45649 | N16: 45645 | O16: 12/23 BV | P16: pass | Q16: 1/3 截仓 | R16: 45621 | S16: 有 | T16: 12/6RFID | U16: 日期码格式：ZURU DGYYYYMMDD CHINA(日期避开周末和法定节假日即可） 日期：按实际生产日期 Packaging Info: 77515GQ5-S002 1.包装要求： MA B版 1L收缩膜+客版 A版 5L收藏指南+MA A版 5L纸袋+MA A版 23L说明书+客版 1L PDQ，翻单：4500142765 每pcs产品上要贴1张RFID贴纸，贴纸由ZURU提供，贴纸位置请严格按照我们签回的签板； Remark: 77515GQ5-S002 1.包装要求： MA B版 1L收缩膜+客版 A版 5L收藏指南+MA A版 5L纸袋+MA A版 23L说明书+客版 1L PDQ，翻单：4500142765 每pcs产品上要贴1张RFID贴纸，贴纸由ZURU提供，贴纸位置请严格按照我们签回的签板； 2. 外箱印刷带条码的RFID箱唛：RFID紫色色带+WM Dept.图标+RFID图标+ITF-14条码，四面右下角印刷ZURU logo, ITFF条码只印刷在正唛一面，在加印的时候确保 条形码能扫描出来，外箱侧面任一角落加印："MADE IN CHINA" 字样； 3. 在产品上和包装上要有日期码、以及要有MADE IN CHINA和ZURU字样； 4. 产品如有扎带口要剪平，不能刮手。 5. 此单需要验货，请多备料 6. 此单以loose carton出货，21pcs/PDQ/CTN | V16: Maggie Xie | W16: 1.4585 | X16: =I16*W16 -> 1439.5395 | Y16: 88843-1.2 | Z16: 77515GQ5-S002-WM | AA16: 已入 | AC16: 987 | AD16: =AC16-I16 -> 0 | AG16: 在仓库 七 | AH16: =I16 -> 987 | AN16: =I16 -> 987 | AX16: =I16 -> 987 | BE16: =I16/21 -> 47 | BZ16: =AH16+AI16+AJ16 -> 987 | CE16: =CE15-AH16-AI16-AJ16 -> 1789674
A17: 45607 | B17: TARGET US | C17: 美国 | D17: 4500150926 | E17: 10001033543-3891 | F17: 4500150926-10 | G17: 77515GQ5-S002 | H17: DIY厨艺大师 | I17: 3675 | J17: 0 | K17: 21 | L17: =I17/K17 -> 175 | M17: 45653 | N17: 45649 | P17: pass | Q17: 1/9 客上柜 | R17: 45621 | S17: 有 | T17: 12/6 条码箱贴纸 | U17: 日期码格式：ZURU INC(BVI) 标准格式 日期：按实际生产日期 Packaging Info: 77515GQ5：MA包装, MA 1L 收缩膜, MA 1L PDQ； Remark: 77515GQ5: 1. 77515GQ5-S002-MINI BRAND-MASTER CHEF MINI BRANDS-SERIES 1,21pcs/Gravity PDQ, 21pcs/CTN,No Inner,STD Color Assortment 2. MA包装, MA 1L 收缩膜, MA 1L PDQ；收缩膜上的UPC显示193052061034; 3. 外箱正唛左上角位置粘贴条码箱贴纸，每箱只贴一张，由ZURU订购。来料贴纸上显示的客户DPCI# 086-02-9598， UPC显示10193052061031; 此订单所有型号： 1. 产品和包装上印刷 tracking code信息，格式为ZURU常规格式; 2. 出货方式：货代自提 | V17: Holly Zheng | W17: 1.4397 | X17: =W17*L17 -> 251.9475 | Y17: 88960-1.9 | Z17: 77515GQ5-S002 | AA17: 已入 | AC17: 3675 | AD17: =AC17-I17 -> 0 | AG17: 在仓库 七 | AH17: =I17 -> 3675 | AN17: =AH17 -> 3675 | AU17: =I17 -> 3675 | BB17: =I17/21 -> 175 | BZ17: =AH17+AI17+AJ17 -> 3675 | CE17: =CE16-AH17-AI17-AJ17 -> 1785999
A18: 45621 | B18: London Supply Group SA | C18: 乌拉圭 | D18: 4500152280 | F18: 4500152280-70 | G18: 77515GQ2-S001 | H18: DIY厨艺大师 | I18: 400 | J18: 0 | K18: 50 | L18: =I18/K18 -> 8 | M18: 45660 | N18: 45656 | P18: 自检 | Q18: 1/8 截SI | R18: 45623 | S18: 无 | T18: 无 | U18: 日期码格式：ZURU INC(BVI) 标准格式 日期：按实际生产日期 Tracking Code: Packaging Info: 77515GQ2:MA 1L包装+MA 多语说明（含西语）+箱唛，无进口商贴纸 Remark: | V18: Ava Liang | W18: 1.4395 | X18: =I18*W18 -> 575.8 | Y18: 88896-1.6 | Z18: 77515GQ2-S001 | AA18: 已入 | AC18: 400 | AD18: =AC18-I18 -> 0 | AG18: 在仓库 | AH18: =I18 -> 400 | AN18: =AH18 -> 400 | AU18: =I18 -> 400 | BM18: =I18/25 -> 16 | BZ18: =AH18+AI18+AJ18 -> 400 | CE18: =CE17-AH18-AI18-AJ18 -> 1785599
A19: 45643 | B19: WALGREEN CO. | C19: 北美 | D19: MPO03150 | F19: 实单代替MPOWAL034手工单 | G19: 77515-S001-MSLD109 | H19: DIY厨艺大师 | I19: 31962 | J19: 0 | K19: 24 | L19: =I19/K19 -> 1331.75 | M19: 45667 | N19: 45663 | O19: 指定日期码 | P19: pass | Q19: 1/10 送库有 | R19: 周转箱 | S19: 无 | T19: 10/24 WIC贴纸 | U19: Remark:1.取消手工单MPOWAL034 子件#77515，改下正式单MPO031502.订单要求参考MPOWAL034 3.分三批送货 第一批 77515 -6396pcs(已送货) 第二批 77515--19188pcs(已送货) 第三批 77515--6378pcs(待安排送货) | V19: Cara | W19: 1.3304 | X19: =I19*W19 -> 42522.245 | Y19: 94403-2.27 94411-2.28 | Z19: 77515-S001-3L | AA19: 已入 | AG19: 在仓库6396 | AH19: =I19 -> 31962 | AO19: =I19 -> 31962 | AU19: =I19 -> 31962 | BZ19: =AH19+AI19+AJ19 -> 31962 | CE19: =CE18-AH19-AI19-AJ19 -> 1753637
A20: 45604 | B20: ASDA STORES LTD | C20: 英国 | D20: 4500150696 | F20: 4500150696-40 | G20: 77515SLB-S003 | H20: DIY厨艺大师卡板装 | I20: 975 | K20: 975 | L20: =I20/K20 -> 1 | M20: 45656 | N20: 45652 | P20: pass | Q20: 1/8 截SI | R20: 45625 | S20: 有 | T20: UPC贴纸翻单145734+slip sheet贴纸 | U20: 日期码格式：ZURU INC(BVI) 标准格式 日期：按实际生产日期 Packaging Info: 7.77515SLB-S003 77515GQ1-S003: MA 3L A版PDQ+MA 3L B版收缩膜+1张UPC贴纸(贴纸翻PO#4500145734)+其他MA最新版包装 UPC#193052061034，请先检查条码是否正确再安排做货 Slip sheet：13PCS/PDQ/CTN(Carton SIZE:23*22*33CM),15*5H=75CTN=975PCS/SLIP SHEET;一共需要1套slip sheet； Slip Sheet打包好后，需要在正唛、侧唛右下角各贴一张slip sheet贴纸，直接用A4纸打印出来即可，贴纸尺寸160mm width x 140mm high；Slip Sheet尺寸限制为100*115*130CM，一旦实际SLIP SHEET尺寸超过这个尺寸，请提前通知ZURU跟单，需同客人确认才能量产和出货; Remark: 1. 产品及包装需要印UKCA图标，包装需要有ZURU UK LTD/ZURU France地址信息，QC同事请核查，如有问题与跟单确认 2. 产品/包装/外箱都需要打ZURU格式日期码，日期必须为法定工作日。 3. 需要符合欧洲标准不能含有闪粉和微塑料，否则不合法规会有客诉产生 | V20: Amy Ding | W20: 1294.836 | X20: =W20*L20 -> 1294.836 | Y20: 88944-1.8 | Z20: 77515SLB-S003 | AA20: 已入 | AC20: 975 | AD20: =AC20-I20 -> 0 | AG20: 在仓库 七 | AH20: =I20 -> 975 | AO20: =I20 -> 975 | AU20: =I20 -> 975 | BJ20: =I20/13 -> 75 | BZ20: =AH20+AI20+AJ20 -> 975 | CE20: =CE19-AH20-AI20-AJ20 -> 1752662
A21: 45604 | B21: THE ENTERTAINER | C21: 英国 | D21: 4500150141 | E21: 4500150141-2 | F21: 4500150141-70 | G21: 77515GQ1-S001 | H21: DIY厨艺大师 | I21: 2496 | J21: 0 | K21: 52 | L21: =I21/K21 -> 48 | M21: 45657 | N21: 45653 | O21: 加多一张2国语言电池说明书 | P21: pass | Q21: 1/4 截SI | R21: 45610 | S21: 无 | T21: 条码贴翻订单4500144795 | U21: 日期码格式：ZURU INC(BVI) 标准格式 日期：按实际生产日期 Packaging Info: 77515GQ1：MA最新1L配套包装+客户EAN条码贴一张覆盖ZURU 原条码，条码贴翻订单4500144795。 另外产品内包装再加多一张2国语言电池说明书 ，即产品内含2张说明书 （ZURU标准说明书1张+2国语言电池说明书），两国语言说明书翻订单4500148687 Remark: *MA版本按工厂现有最新库存即可，订单出英国，请注意检查产品及包装应带UKCA图标，包装显示ZURU UK LTD信息，QC同事请查核，如有问题与跟单确认。 *生产日期按实际（法定工作日），按ZURU标准格式即可 ，但是请知悉包装日期码需要早于或者等于外箱日期码 ，不能晚于外箱日期码 *请注意所有订单都需要经过ZURU QC验货并且通过后方可出货 *条码以订单显示为准 ，请安排生产前先核对 ，有问题请提出。 *所有产品按符合欧洲标准走货，需要是不含微塑料版本 。 *涉及到硼的，如可选择情况下应使用低硼版本 （slime 类别低硼一般低于300ppm)，无选择的应与跟单复核再安排 。 Order Modifiable Records Revision # Date: Comment: 1 11- | V21: Sherry Lu | W21: 1.4046 | X21: =I21*W21 -> 3505.8816 | Y21: 88877-1.4 | Z21: 77515GQ1-S001 | AA21: 已入 | AC21: 2496 | AD21: =AC21-I21 -> 0 | AG21: 在仓库 七 | AH21: =I21 -> 2496 | AN21: =AH21 -> 2496 | AU21: =AH21 -> 2496 | BI21: =AH21/13 -> 192 | BZ21: =AH21+AI21+AJ21 -> 2496 | CE21: =CE20-AH21-AI21-AJ21 -> 1750166
A22: 45618 | B22: CRG | C22: 哥斯达黎加 | D22: 4500152087 | E22: ZU01-25 | F22: 4500152087-110 | G22: 77515GQ2-S001 | H22: DIY厨艺大师 | I22: 3600 | J22: 0 | K22: 50 | L22: =I22/K22 -> 72 | M22: 45660 | N22: 45656 | P22: pass | Q22: 1/8 截SI | R22: 45623 | S22: 无 | T22: 12/10 进口商贴纸 | U22: 日期码格式：ZURU INC(BVI) 标准格式 日期：按实际生产日期 Packaging Info: 77515GQ2:MA 1L包装+进口商贴纸+箱唛 Remark: | V22: Ava Liang | W22: 1.4344 | X22: =I22*W22 -> 5163.84 | Y22: 88961-1.9 | Z22: 77515GQ2-S001 | AA22: 已入 | AC22: 3600 | AD22: =AC22-I22 -> 0 | AG22: 在仓库 | AH22: =I22 -> 3600 | AN22: =AH22 -> 3600 | AU22: =I22 -> 3600 | BM22: =I22/25 -> 144 | BZ22: =AH22+AI22+AJ22 -> 3600 | CE22: =CE21-AH22-AI22-AJ22 -> 1746566
A23: 45579 | B23: ASDA STORES LTD | C23: 英国 | D23: 4500147530 | E23: 2950866070 | F23: 4500147530-20 | G23: 77515SLB-S003 | H23: DIY厨艺大师卡板装 | I23: 1950 | J23: 0 | K23: 975 | L23: =I23/K23 -> 2 | M23: 45657 | N23: 45656 | P23: pass | Q23: 1/8 截SI | R23: 45636 | S23: 有 | T23: UPC贴纸翻单145734+slip sheet贴纸 | U23: 日期码格式：ZURU INC(BVI) 标准格式 日期：按实际生产日期 Packaging Info:77515SLB-S003 77515GQ1-S003: MA 3L A版PDQ+MA 3L B版收缩膜+1张UPC贴纸(贴纸翻PO#4500145734)+其他MA最新版包装 UPC#193052061034，请先检查条码是否正确再安排做货 Slip sheet：13PCS/PDQ/CTN(Carton SIZE:23*22*33CM),15*5H=75CTN=975PCS/SLIP SHEET;一共需要2套slip sheet； Slip Sheet打包好后，需要在正唛、侧唛右下角各贴一张slip sheet贴纸，直接用A4纸打印出来即可，贴纸尺寸160mm width x 140mm high；Slip Sheet尺寸限制为 100*115*130CM，一旦实际SLIP SHEET尺寸超过这个尺寸，请提前通知ZURU跟单，需同客人确认才能量产和出货; | V23: Sheba Ye | W23: 1289.8635 | X23: =W23*L23 -> 2579.727 | Y23: 88942-1.8 | Z23: 77515SLB-S003 | AA23: 已入 | AC23: =1924+26 -> 1950 | AD23: =AC23-I23 -> 0 | AG23: 在仓库 七 | AH23: =I23 -> 1950 | AO23: =I23 -> 1950 | AU23: =I23 -> 1950 | BJ23: =I23/13 -> 150 | BZ23: =AH23+AI23+AJ23 -> 1950 | CE23: =CE22-AH23-AI23-AJ23 -> 1744616
A24: 45555 | B24: ASDA STORES LTD | C24: 英国 | D24: 4500145734 | E24: 2950866059 | F24: 4500145734-10 | G24: 77515SLB-S003 | H24: DIY厨艺大师卡板装 | I24: 1950 | J24: 0 | K24: 975 | L24: =I24/K24 -> 2 | M24: 45657 | N24: 45656 | P24: pass | Q24: 1/8 截SI | R24: 45636 | S24: 有 | T24: 9/20 UPC贴纸+slip sheet贴纸 | U24: 日期码格式：ZURU INC(BVI) 标准格式 日期：按实际生产日期 Packaging Info: 77515SLB-S003 77515GQ1-S003: MA 3L A版PDQ+MA 3L B版收缩膜+1张UPC贴纸+其他MA最新版包装 UPC#193052061034，请先检查条码是否正确再安排做货 Slip sheet：13PCS/PDQ/CTN(Carton SIZE:23*22*33CM),15*5H=75CTN=975PCS/SLIP SHEET;一共需要2套slip sheet； Slip Sheet打包好后，需要在正唛、侧唛右下角各贴一张slip sheet贴纸，直接用A4纸打印出来即可，贴纸尺寸160mm width x 140mm high；Slip Sheet尺寸限制为 100*115*130CM，一旦实际SLIP SHEET尺寸超过这个尺寸，请提前通知ZURU跟单，需同客人确认才能量产和出货; Remark: 1. 产品及包装需要印UKCA图标，包装需要有ZURU UK LTD/ZURU France地址信息，QC同事请核查，如有问题与跟单确认 2. 产品/包装/外箱都需要打ZURU格式日期码，日期必须为法定工作日。 3. 需要符合欧洲标准不能含有闪粉和微塑料，否则不合法规会有客诉产生 | V24: Sheba Ye | W24: 1289.8635 | X24: =W24*L24 -> 2579.727 | Y24: 88943-1.8 | Z24: 77515SLB-S003 | AA24: 已入 | AC24: 1950 | AD24: =AC24-I24 -> 0 | AG24: 在仓库 七 | AH24: =I24 -> 1950 | AO24: =I24 -> 1950 | AU24: =I24 -> 1950 | BJ24: =I24/13 -> 150 | BZ24: =AH24+AI24+AJ24 -> 1950 | CE24: =CE23-AH24-AI24-AJ24 -> 1742666
A25: 45618 | B25: TARGET US | C25: 美国 | D25: 4500152133 | E25: 10001033542-3890 | F25: 4500152133-10 | G25: 77515GQ5-S002 | H25: DIY厨艺大师 | I25: 5061 | J25: 0 | K25: 21 | L25: =I25/K25 -> 241 | M25: 45657 | N25: 45657 | P25: pass | Q25: 1/6 客上柜 | R25: 45630 | S25: 有 | T25: 12/19条码箱贴纸 | U25: 日期码格式：ZURU INC(BVI) 标准格式 日期：按实际生产日期 Tracking Code: Packaging Info: 77515GQ5: MA包装, MA 1L 收缩膜, MA 1L PDQ； Remark: 77515GQ5: 1. 77515GQ5-S002-MINI BRAND-MASTER CHEF MINI BRANDS-SERIES 1,21pcs/Gravity PDQ, 21pcs/CTN,No Inner,STD Color Assortment 2. MA包装, MA 1L 收缩膜, MA 1L PDQ；收缩膜上的UPC显示193052061034; 3. 外箱正唛左上角位置粘贴条码箱贴纸，每箱只贴一张，由ZURU订购。来料贴纸上显示的客户DPCI# 086-02-9598， UPC显示10193052061031; 此订单所有型号： 1. 产品和包装上印刷 tracking code信息，格式为ZURU常规格式; 2. 出货方式：货代自提 | V25: Holly Zheng | W25: 1.4585 | X25: =I25*W25 -> 7381.4685 | Y25: 88895-1.6 | Z25: 77515GQ5-S002 | AA25: 已入 | AC25: 5061 | AD25: =AC25-I25 -> 0 | AG25: 在仓库 七 | AH25: =I25 -> 5061 | AN25: =I25 -> 5061 | AU25: =I25 -> 5061 | BB25: =I25/21 -> 241 | BZ25: =AH25+AI25+AJ25 -> 5061 | CE25: =CE24-AH25-AI25-AJ25 -> 1737605
A26: 45621 | B26: KMART AUSTRALIA LTD(NEW ZEALAND) | C26: 新西兰 | D26: 4500152293 | E26: 20478301 | F26: 4500152293-40 | G26: 77515GQ1-S003 | H26: DIY厨艺大师 | I26: 1313 | J26: 0 | K26: 13 | L26: =I26/K26 -> 101 | M26: 45663 | N26: 45663 | P26: pass | Q26: 1/8 交仓 | R26: 45629 | S26: 有 | T26: 12/16 SSCC LABEL（客供贴纸)+纽扣电池警告语贴纸/防盗贴纸翻单121356 | U26: 日期码格式：ZURU INC(BVI) 标准格式 日期：按实际生产日期 Tracking Code: Packaging Info: 77515GQ1:MA英语UPC版本包装（收缩膜和说明书, MA首选1L，如无1L可用多语且含英语的配套多语包装) + 1张说明书纽扣电池警告语贴纸（贴纸以及位置图翻单PO# 4500121356）+ 1张收缩膜纽扣电池警告语贴纸（贴纸以及位置图翻单PO#4500121356）+ 1张防盗贴纸 (贴纸以及位置图翻单PO#4500121356）+ 箱唛 + 外箱SSCC La bel Remark: 1.请务必按时完货，验货。并且按期送货入货代指定仓库，如果晚了导致船期Delay将会有罚金产生或者客户要求空运，所产生的罚金和空运费由工厂承担。 2.SSCC 外箱贴纸请同纸箱瓦楞纸方向（竖纹向）垂直，即外箱贴纸横着贴(注意条码不要被胶带粘住），贴1pc，贴1面正唛，封箱胶纸不能挡住贴纸内容。外箱贴纸 离外箱边距离不少于2cm。 3.外箱材质为ZURU标准； 4.此单需使用KMART封箱胶上下工字型封箱;从2019年6月开始，要用KMART 新版封箱胶带，此单要用"ANKO"封箱胶带 5.此单出口新西兰，请按相应的澳新标准生产； 6.产品和包装上生产批号的显示格式ZURU标准日期码格式 7.外箱信息不可手写，重量和体积需要与实际的一致(不可手写） 8. 每款item装箱后的G.W.超过10KG或者CBM超过0.13,(9.5KG或者以上，四舍五入后也属于10KG) 需在外箱上加印超 重或者Bulky LOGO，若发现我们资料没有，请 帮忙提醒 1)重量超过10kg但不超过16kg且CBM不超过0.13,10-16kg 超重logo 2）CBM超过0.13且重量少于17kg，bulky logo 3）不属于以上两种情况，需要使用相应重量范围内的超重logo 4）超重logo需要在外箱四面都印刷(箱唛右上角，两面侧唛超重logo需要尽量靠近毛重)，尺寸为:110mm height* 95mm width 9. 实际外箱重量跟印在箱唛上的数据差异不能超3%，尺寸按实际数据印刷 | V26: Lydia Wu | W26: 1.4432 | X26: =I26*W26 -> 1894.9216 | Y26: 88992-1.11 | Z26: 77515GQ1-S003 | AA26: 已入 | AC26: 1313 | AD26: =AC26-I26 -> 0 | AG26: 在仓库 | AH26: =I26 -> 1313 | AN26: =I26 -> 1313 | AU26: =I26 -> 1313 | BI26: =I26/13 -> 101 | BZ26: =AH26+AI26+AJ26 -> 1313 | CE26: =CE25-AH26-AI26-AJ26 -> 1736292
A27: 45621 | B27: KMART AUSTRALIA LTD | C27: 澳大利亚 | D27: 4500152292 | E27: 20357441 | F27: 4500152292-100 | G27: 77515GQ1-S003 | H27: DIY厨艺大师 | I27: 195 | J27: 0 | K27: 13 | L27: =I27/K27 -> 15 | M27: 45663 | N27: 45663 | P27: pass | R27: 45629 | S27: 有 | T27: 12/16 SSCC LABEL（客供贴纸)+纽扣电池警告语贴纸/防盗贴纸翻单121356 | U27: 日期码格式：ZURU INC(BVI) 标准格式 日期：按实际生产日期 Tracking Code: Packaging Info: 77515GQ1:MA英语UPC版本包装（收缩膜和说明书, MA首选1L，如无1L可用多语且含英语的配套多语包装) + 1张说明书纽扣电池警告语贴纸（贴纸以及位置图翻单PO# 4500121356）+ 1张收缩膜纽扣电池警告语贴纸（贴纸以及位置图翻单PO#4500121356）+ 1张防盗贴纸 (贴纸以及位置图翻单PO#4500121356）+ 箱唛 + 外箱SSCC La bel Remark: 1.请务必按时完货，验货。并且按期送货入货代指定仓库，如果晚了导致船期Delay将会有罚金产生或者客户要求空运，所产生的罚金和空运费由工厂承担。 2.SSCC 外箱贴纸请同纸箱瓦楞纸方向（竖纹向）垂直，即外箱贴纸横着贴(注意条码不要被胶带粘住），贴1pc，贴1面正唛，封箱胶纸不能挡住贴纸内容。外箱贴纸 离外箱边距离不少于2cm。 3.外箱材质为ZURU标准； 4.此单需使用KMART封箱胶上下工字型封箱;从2019年6月开始，要用KMART 新版封箱胶带，此单要用"ANKO"封箱胶带 5.此单出口澳大利亚，请按相应的澳新标准生产； 6.产品和包装上生产批号的显示格式ZURU标准日期码格式 7.外箱信息不可手写，重量和体积需要与实际的一致(不可手写） 8. 每款item装箱后的G.W.超过10KG或者CBM超过0.13,(9.5KG或者以上，四舍五入后也属于10KG) 需在外箱上加印超 重或者Bulky LOGO，若发现我们资料没有，请 帮忙提醒 1)重量超过10kg但不超过16kg且CBM不超过0.13,10-16kg 超重logo 2）CBM超过0.13且重量少于17kg，bulky logo 3）不属于以上两种情况，需要使用相应重量范围内的超重logo 4）超重logo需要在外箱四面都印刷(箱唛右上角，两面侧唛超重logo需要尽量靠近毛重)，尺寸为:110mm height* 95mm width 9. 实际外箱重量跟印在箱唛上的数据差异不能超3%，尺寸按实际数据印刷 | V27: Lydia Wu | W27: 1.4483 | X27: =I27*W27 -> 282.4185 | Y27: 88993-1.11 | Z27: 77515GQ1-S003 | AA27: 已入 | AC27: 195 | AD27: =AC27-I27 -> 0 | AG27: 在仓库 | AH27: =I27 -> 195 | AN27: =I27 -> 195 | AU27: =I27 -> 195 | BI27: =I27/13 -> 15 | BZ27: =AH27+AI27+AJ27 -> 195 | CE27: =CE26-AH27-AI27-AJ27 -> 1736097
A28: 45610 | B28: ZURU France | C28: 法国 | D28: 4500151118 | E28: 5200005699 | F28: 4500151118-10 | G28: 77515GQ2-S002-NS-MTS | H28: DIY厨艺大师-无香味版本 | I28: 2000 | J28: 0 | K28: 25 | L28: =I28/K28 -> 80 | M28: 45651 | N28: 45651 | O28: 外箱/产品/包装 保持一致 | P28: pass | Q28: 1/3 截SI | R28: 45618 | S28: 无 | T28: 11/22法意西回收贴纸+无香味贴纸 | U28: 日期码格式：ZURU INC(BVI) 标准格式 日期：按实际生产日期 Packaging Info: 1.77515GQ2:最新MA 3L EAN收缩膜+一张法意西回收贴纸+ MA 23L 说明书+MA PDQ+ MA收藏指南加无香贴纸（所有包装如有提示香味都做无香版） Remark: 1. 西班牙国家内销单，需要通过ZURU 验货结果后才能出货 (工厂需要主动提前同ZURU QC预约验货避免延期出货造成不必要麻烦)； 2. 本订单所有 具有 baby items / assorted items 的款式，零售包装上都要用 母 EAN; 3. 若有特定款有特殊外箱条码要求时,需要明确列出产品款对应的具体外箱条码号码/条码类型 (若无,可以忽略此需求) 4. 所有出口欧洲的产品, 法规规定禁止在包装和共公众用的印刷品中使用矿物油中含有的物质, 包装印刷油墨中含有的MOAH/MOSH的质量浓度不能超过1%, 否则出 货到法国被抽检出现问题, 供应商需要对此负责; 5. date code: 外箱/产品/包装 保持一致，完货后提供date code 信息以便我们保存记录做批次管理; 6. 装柜时需要按照款式号码从小到大一款款依次装,避免终端仓库卸货混乱.若一个柜子涉及到几个不同国家内销单,装柜时需要一个国家装完后再装另一个国家的 产品,依次装柜,避免终端仓库因不同国家不同库位位置卸货混乱. (此点需要同工厂装柜人员强调) | V28: Jade Wang | W28: 1.4171 | X28: =I28*W28 -> 2834.2 | Y28: 88841-1.2 | Z28: 77515GQ2-S002-NS | AA28: 已入 | AC28: 2000 | AD28: =AC28-I28 -> 0 | AG28: 在仓库 七 | AI28: =I28 -> 2000 | AO28: =I28 -> 2000 | AU28: =I28 -> 2000 | BN28: =I28/25 -> 80 | BZ28: =AH28+AI28+AJ28 -> 2000 | CE28: =CE27-AH28-AI28-AJ28 -> 1734097
A29: 45611 | B29: ToyChamp Belgium nv | C29: 比利时 | D29: 4500151401 | E29: 2024101316 | F29: 4500151401-10 | G29: 77515GQ5-S001 | H29: DIY厨艺大师 | I29: 2436 | J29: 0 | K29: 42 | L29: =I29/K29 -> 58 | M29: 45657 | N29: 45653 | O29: 说明书+配件袋都要贴贴纸 | P29: pass | Q29: 1/19 截SI | R29: 45617 | S29: 无 | T29: 警语贴纸/说明书贴纸/配件袋贴纸 翻单PO#4500140409 | U29: 日期码格式：ZURU INC(BVI) 标准格式 日期：按实际生产日期 Packaging Info: 77515GQ5: MA B 版3L(warning 5L) EAN 收缩膜+ 1张NL荷兰语警语贴纸 翻单PO#4500140409，MA 5L A版收藏指南，MA B版 23L 说明书+贴纸翻单4500140409，MA 5L B版配件袋+ 贴纸 翻单4500140409， MA 3L PDQ Remark: 1.外箱需要印条码，请确保条码可以清晰扫描，且条码内容正确 2.出欧洲，微塑料需合规（如item本身不含微塑料,则忽略此要求） 3.STD配比 4. 所有产品均需符合REACH 申明 | V29: Amber Zhang | W29: 1.4539 | X29: =I29*W29 -> 3541.7004 | Y29: 94107-118 | Z29: 77515GQ5-S001-3L | AA29: 已入 | AC29: 2436 | AD29: =AC29-I29 -> 0 | AG29: 七 | AH29: =I29 -> 2436 | AO29: =AH29 -> 2436 | AU29: =I29 -> 2436 | BC29: =I29/21 -> 116 | BZ29: =AH29+AI29+AJ29 -> 2436 | CE29: =CE28-AH29-AI29-AJ29 -> 1731661
A30: 45616 | B30: N.V. DREAMLAND | C30: 比利时 | D30: 4500151832 | E30: 4500054541 | F30: 4500151832-20 | G30: 77515GQ5-S001 | H30: DIY厨艺大师 | I30: 1932 | J30: 0 | K30: 42 | L30: =I30/K30 -> 46 | M30: 45657 | N30: 45653 | O30: 说明书+配件袋都要贴贴纸 | P30: 自检 | Q30: 1/6 截SI | R30: 45616 | S30: 无 | T30: 警语贴纸/说明书贴纸/配件袋贴纸 翻单PO#4500140409 | U30: 日期码格式：ZURU INC(BVI) 标准格式 日期：按实际生产日期 Packaging Info: 77515GQ5: MA B 版3L(warning 5L) EAN 收缩膜+ 1张NL荷兰语警语贴纸（翻PO#4500140409)，MA 5L A版收藏指南，MA B版 23L 说明书+贴纸翻单PO#4500140409， MA 5L B版配件袋+ 贴纸 翻单4500140409， MA 3L PDQ Remark: 1.外箱需要印条码，请确保条码可以清晰扫描，且条码内容正确 2.出欧洲，微塑料需合规（如item本身不含微塑料,则忽略此要求） 3.STD配比 4. 所有产品符合REACH申明 | V30: Amber Zhang | W30: 1.4539 | X30: =I30*W30 -> 2808.9348 | Y30: 88874-1.4 | Z30: 77515GQ5-S001-3L | AA30: 已入 | AC30: 1932 | AD30: =AC30-I30 -> 0 | AG30: 在仓库 七 | AH30: =I30 -> 1932 | AO30: =AH30 -> 1932 | AU30: =I30 -> 1932 | BC30: =AH30/21 -> 92 | BZ30: =AH30+AI30+AJ30 -> 1932 | CE30: =CE29-AH30-AI30-AJ30 -> 1729729
A31: 45615 | B31: Wonderland Toys Inc DBA The Zoofy G | C31: 美国 | D31: 4500151635 | E31: 4357 | F31: 4500151635-70 | G31: 77515GQ1-S003 | H31: DIY厨艺大师 | I31: 5369 | J31: 0 | K31: 13 | L31: =I31/K31 -> 413 | M31: 45665 | N31: 45663 | P31: pass | Q31: 1/11 截SI | R31: 45623 | S31: 有 | T31: 11/27价格贴纸+12/16 UCC贴纸 | U31: 日期码格式：ZURU INC(BVI) 标准格式 日期：按实际生产日期 Packaging Info: 1. 出口美国，MA UPC 版本包装，优先1L。 #77515GQ1: PRICER TICK-11.99; 3PCS AG13 Batteries(Included); 2. 产品需要价格贴纸， 贴纸资料后面提供。 3. 外箱需要UCC贴纸。贴纸资料后面提供。 Remark: 4. Zuru QC 验货即可。 | V31: Abby Mai, Lluviazeng | W31: 1.4021 | X31: =I31*W31 -> 7527.8749 | Y31: 94108-1.18 | Z31: 77515GQ1-S003 | AA31: 已入 | AC31: 5369 | AD31: =AC31-I31 -> 0 | AH31: =I31 -> 5369 | AN31: =I31 -> 5369 | AU31: =I31 -> 5369 | BI31: =I31/13 -> 413 | BZ31: =AH31+AI31+AJ31 -> 5369 | CE31: =CE30-AH31-AI31-AJ31 -> 1724360
A32: 45595 | B32: TIENDAS SORIANA, S.A. DE C.V. | C32: 墨西哥 | D32: 4500149669 | F32: 4500149669-50 | G32: 77515GQ2-S001 | H32: DIY厨艺大师 | I32: 4250 | J32: 0 | K32: 50 | L32: =I32/K32 -> 85 | M32: 45664 | N32: 45663 | O32: 另+保证书 | P32: pass | Q32: 1/14 截SI | R32: 45639 | S32: 无 | T32: 12/11 UPC贴纸+1个小的红色logo贴纸+进口商贴纸 | U32: 日期码格式：ZURU INC(BVI) 标准格式 日期：按实际生产日期 Packaging Info:5. 77515GQ2：MA 3L EAN包装+UPC贴纸+MA 多语说明书+MA 3L PDQ包装+1个小的红色logo贴纸+进口商贴纸+保证书+箱唛，3张不同的进口商贴纸分别是贴在彩卡/产 品电池盖/说明书上 Remark: 5. 77515GQ2：3PCS AG13 Batteries(Include) 6. 集装箱及装柜要求：集装箱不能有破洞；不能太脏 7.每个item需要放1整箱在每个集装箱门口 8.装柜的时候要前、中、后拍照 | V32: Ever Li | W32: 1.4344 | X32: =I32*W32 -> 6096.2 | Y32: 94030-1.14 | Z32: 77515GQ2-S001-3L | AA32: 已入 | AC32: 4250 | AD32: =AC32-I32 -> 0 | AG32: 七 | AH32: =I32 -> 4250 | AO32: =I32 -> 4250 | AU32: =I32 -> 4250 | BN32: =I32/25 -> 170 | BZ32: =AH32+AI32+AJ32 -> 4250 | CE32: =CE31-AH32-AI32-AJ32 -> 1720110
A33: 45623 | B33: Army & Air Force Exchange Service | C33: 美国 | D33: 4500152559 | E33: 0092242910 | F33: 4500152559-10 | G33: MEC251-77515-S001 | H33: 混装（77555+77515） | I33: 510 | J33: 0 | K33: 30 | L33: =I33/K33 -> 17 | M33: 45660 | N33: 45663 | P33: pass | Q33: 1/8 截SI | R33: 45630 | S33: 有 | T33: 12/5 UPC | U33: 日期码格式：ZURU INC(BVI) 标准格式 日期：按实际生产日期 Packaging Info: Remark: 1. MA UPC包装(优先1L），出口美国 2. 客户PO# 0092242911 0092242912 0092242913 这3个订单外箱需要贴4x6"UCC 贴纸，只需贴一面（UCC贴纸为客供贴纸）。PO#0092242910 0092242914，这2个 订单外箱不需要UCC贴纸。 3. ZURU QC 验货。 4. 产品和包裝上需印刷tracking code信息，格式为ZURU常规。 5. 展示架上需粘贴 mother UPC 贴纸 （Item# MEC251 的 mother UPC: 193052068019 ） | V33: Yilia | W33: 75.5207 | X33: =W33*L33 -> 1283.8519 | Y33: 88990-1.11 | Z33: MEC251-77515-S001 | AA33: 已入 | AC33: 510 | AD33: =AC33-I33 -> 0 | AH33: =I33 -> 510 | AN33: =AH33 -> 510 | AU33: =AH33 -> 510 | BZ33: =AH33+AI33+AJ33 -> 510 | CE33: =CE32-AH33-AI33-AJ33 -> 1719600
A34: 45623 | B34: Army & Air Force Exchange Service | C34: 美国 | D34: 4500152559 | E34: 0092242914 | F34: 4500152559-20 | G34: MEC251-77515-S001 | H34: 混装（77555+77515） | I34: 420 | J34: 0 | K34: 30 | L34: =I34/K34 -> 14 | M34: 45660 | N34: 45663 | P34: pass | Q34: 1/8 截SI | R34: 45630 | S34: 有 | T34: 12/5 UPC | U34: 日期码格式：ZURU INC(BVI) 标准格式 日期：按实际生产日期 Packaging Info: Remark: 1. MA UPC包装(优先1L），出口美国 2. 客户PO# 0092242911 0092242912 0092242913 这3个订单外箱需要贴4x6"UCC 贴纸，只需贴一面（UCC贴纸为客供贴纸）。PO#0092242910 0092242914，这2个 订单外箱不需要UCC贴纸。 3. ZURU QC 验货。 4. 产品和包裝上需印刷tracking code信息，格式为ZURU常规。 5. 展示架上需粘贴 mother UPC 贴纸 （Item# MEC251 的 mother UPC: 193052068019 ） | V34: Yilia | W34: 75.5207 | X34: =W34*L34 -> 1057.2898 | Y34: 88990-1.11 | Z34: MEC251-77515-S001 | AA34: 已入 | AC34: 420 | AD34: =AC34-I34 -> 0 | AH34: =I34 -> 420 | AN34: =AH34 -> 420 | AU34: =AH34 -> 420 | BZ34: =AH34+AI34+AJ34 -> 420 | CE34: =CE33-AH34-AI34-AJ34 -> 1719180
