Workbook

Sheet 77593旧排期
A1: ZURU 5 surprise Dino S6（恐龙系列）生产排期表 #77489 | I1: 1.球壳 转为95mm 2半球壳 ,材料：20%PCR PP +80%PP原料 2.因考虑到某些地区对微塑胶（闪粉，闪粉喷油等）的限制，内部产品会同步做以下变更：---Slime 取消闪粉 3.更改为95mm 球壳后款号更新，请参考以下款号 4.PDQ，SK 刀线均有变化（请留意部分会带有demo）GQ2/SK/SK1有demo | AJ1: 普通款暴龙+卡车 | AL1: 双刺龙 | AR1: 普通款暴龙
I2: 欧洲国家有: (共有43个国家组成) 。芬兰、瑞典、挪威、冰岛、丹麦 法罗群岛(丹)、爱沙尼亚、拉脱维亚、立陶宛、白俄罗斯、俄罗斯、乌克兰、摩尔多瓦、波兰、捷克、斯洛伐克、匈牙利、德国、奥地利、瑞士、列支敦士登、英国、爱尔兰、荷兰、比利时、卢森堡、法国、摩纳哥、罗马尼亚、保加利亚、塞尔维亚、马其顿、阿尔巴尼亚、希腊、斯洛文尼亚、克罗地亚、波斯尼亚和墨塞哥维那、意大利、梵蒂冈、圣马力诺、马耳他、西班牙、葡萄牙、安道尔。 | AG2: 95MM收縮膜 | AI2: 95MM收藏指南 | AJ2: SK展示架 | AK2: 带底座 | AL2: 77593GQ2 | AN2: 77593GQ1 | AP2: 77593GQ5 | AQ2: SK1展示架 | AT2: 77614 2PK圆筒 | AW2: WM GQ4 | AX2: 口水胶 | AZ2: MA比例 | BA2: 0.125 | BB2: 0.10416667 | BC2: 0.020833333 | BD2: 0.125 | BE2: 0.125 | BF2: 0.125 | BG2: 0.125 | BH2: 0.125 | BI2: 0.125 | BJ2: MA | BK2: ='77489 77593生产MA'!E15-BA51-BA53-'77489 77593生产MA'!I29 -> 12327.625 | BL2: ='77489 77593生产MA'!F15-BB51-BB53-'77489 77593生产MA'!I30-'77489 77593生产MA'!I31-'77489 77593生产MA'!J33-'77489 77593生产MA'!K33-'77489 77593生产MA'!J35-'77489 77593生产MA'!K35 -> 10449.521 | BM2: ='77489 77593生产MA'!G15-BD53-BD51 -> 12340.625 | BN2: ='77489 77593生产MA'!H15-BC53-BC51 -> 1965.1042 | BO2: ='77489 77593生产MA'!I15-BE51-BE53-'77489 77593生产MA'!J34-'77489 77593生产MA'!K34 -> 10462.625 | BP2: ='77489 77593生产MA'!J15-BF51-BF53 -> 12340.625 | BQ2: ='77489 77593生产MA'!K15-BG51-BG53 -> 12340.625 | BR2: ='77489 77593生产MA'!L15-BH51-BH53-'77489 77593生产MA'!K32-'77489 77593生产MA'!J32 -> 12740.625 | BS2: ='77489 77593生产MA'!M15-BI51-BI53 -> 12340.625
A3: 香港接单日期 | B3: 第三方客户名称 | C3: 走货国家 | D3: ZURU PO NO# | E3: 第三方客户 PO NO# | F3: SKU | G3: ITEM# | H3: 中文名 | I3: PO数量 (pcs) | J3: 内箱装箱数量(pcs) | K3: 外箱装箱数量(pcs) | L3: 总箱数 | M3: 客PO期 | N3: 验货期 | O3: 第三方验货期 | P3: 验货结果 | Q3: 船期 | R3: 箱唛资料(收到日期) | S3: 外箱贴纸 | T3: 客供贴纸AI(收到日期) | U3: 备注 | V3: ZURU 跟单 | W3: 单价USD | X3: 金额USD | Y3: 发票号 | Z3: 已送情况 | AA3: 欠数 | AB3: 贴纸 情况 | AC3: 是否入系统 | AD3: 系统货号 | AE3: 是否入系统 | AF3: 77593-95mm球壳 | AG3: MA 1L | AH3: MA 3L | AI3: MA 5L | AJ3: MA 1L | AL3: MA 1L | AM3: MA 3L | AN3: MA 1L | AO3: MA 3L | AP3: FD客版 | AQ3: MA 3L | AR3: MA 1L | AS3: 带底座 | AT3: 圆筒 | AU3: 彩纸 3L | AV3: 彩纸 1L | AW3: 客版 | AX3: 有硼无闪粉 | AY3: 无硼无闪粉 | BA3: Pterosaur 翼龙 | BB3: T-Rex 暴龙 | BC3: T-Rex (Rare) 暴龙（特别款） | BD3: Stegosaurus 剑龙 | BE3: Dilophosaurus 双棘龙 | BF3: Brontosaurus 雷龙 | BG3: Amargasaurus 阿玛加龙 | BH3: Truck 卡车 | BI3: Armed Helicoper 武装飞机 | BK3: Pterosaur 翼龙 | BL3: T-Rex 暴龙 | BM3: Stegosaurus 剑龙 | BN3: T-Rex (Rare) 暴龙（特别款） | BO3: Dilophosaurus 双棘龙 | BP3: Brontosaurus 雷龙 | BQ3: Amargasaurus 阿玛加龙 | BR3: Truck 卡车 | BS3: Armed Helicoper 武装飞机
A4: 45323 | B4: ZURU | C4: 库有 | D4: ZMPO24101 | G4: 77593SK-S002 | H4: S4迷你恐龙展示架带球 | I4: 480 | J4: 0 | K4: 60 | L4: =I4/K4 -> 8 | M4: 45359 | N4: 45355 | P4: 自检 | R4: 45323 | S4: 无 | T4: 无 | U4: 大货最新版本/产品请按大货比例入展架/箱唛参照邮件附件 | Y4: 97435-1.8 | Z4: 480 | AA4: =Z4-I4 -> 0 | AD4: 77593SK-S002 | AE4: 已入 | AF4: =I4 -> 480 | AG4: =AF4 -> 480 | AI4: =AG4 -> 480 | AJ4: =L4 -> 8 | AK4: =AJ4 -> 8 | AX4: =AF4 -> 480 | BA4: =I4*$BA$2 -> 60 | BB4: =I4*$BB$2 -> 50 | BC4: =I4*$BC$2 -> 10 | BD4: =I4*$BD$2 -> 60 | BE4: =I4*$BE$2 -> 60 | BF4: =I4*$BF$2 -> 60 | BG4: =I4*$BG$2 -> 60 | BH4: =I4*$BH$2 -> 60 | BI4: =I4*$BI$2 -> 60 | BK4: =BK2-BA4 -> 12267.625 | BL4: =BL2-BB4 -> 10399.521 | BM4: =BM2-BD4 -> 12280.625 | BN4: =BN2-BC4 -> 1955.1042 | BO4: =BO2-BE4 -> 10402.625 | BP4: =BP2-BF4 -> 12280.625 | BQ4: =BQ2-BG4 -> 12280.625 | BR4: =BR2-BH4 -> 12680.625 | BS4: =BS2-BI4 -> 12280.625
A5: 45323 | B5: ZURU | C5: 库有 | D5: ZMPO24101 | G5: 77593SK1-S002 | H5: S4迷你恐龙展示架带球 | I5: 240 | J5: 0 | K5: 30 | L5: =I5/K5 -> 8 | M5: 45359 | N5: 45355 | P5: 自检 | R5: 45323 | S5: 无 | T5: 无 | U5: 大货最新版本/产品请按大货比例入展架/箱唛参照邮件附件 | Y5: 97435-1.8 | Z5: 240 | AA5: =Z5-I5 -> 0 | AD5: 77593SK1-S002 | AE5: 已入 | AF5: =I5 -> 240 | AQ5: =L5 -> 8 | AS5: =AQ5 -> 8 | AX5: =AF5 -> 240 | BA5: =I5*$BA$2 -> 30 | BB5: =I5*$BB$2 -> 25 | BC5: =I5*$BC$2 -> 5 | BD5: =I5*$BD$2 -> 30 | BE5: =I5*$BE$2 -> 30 | BF5: =I5*$BF$2 -> 30 | BG5: =I5*$BG$2 -> 30 | BH5: =I5*$BH$2 -> 30 | BI5: =I5*$BI$2 -> 30 | BK5: =BK4-BA5 -> 12237.625 | BL5: =BL4-BB5 -> 10374.521 | BM5: =BM4-BD5 -> 12250.625 | BN5: =BN4-BC5 -> 1950.1042 | BO5: =BO4-BE5 -> 10372.625 | BP5: =BP4-BF5 -> 12250.625 | BQ5: =BQ4-BG5 -> 12250.625 | BR5: =BR4-BH5 -> 12650.625 | BS5: =BS4-BI5 -> 12250.625
A6: 45463 | B6: DM LLC | C6: 俄罗斯 | D6: 4500137881 | E6: Ural | F6: 4500137881-110 | G6: 77593GQ1-S001 | H6: S4迷你恐龙13PCS/GQ1*4 | I6: 312 | J6: 0 | K6: 52 | L6: =I6/K6 -> 6 | M6: 45498 | N6: 45502 | O6: 彩卡/收缩膜/PDQ/外箱不要打ZURU标准日期码！ | P6: 自检 | Q6: 已有计划船期等SO出货 | R6: 45469 | S6: 无 | T6: 7/8进口商贴纸+EAN条码贴纸 | U6: 日期码格式：彩卡/收缩膜/PDQ/外箱不要打ZURU标准日期码！ 日期： Packaging Info: 77593GQ1: 优先1L MA 收缩膜+进口商贴纸+EAN条码贴纸; MA PDQ/指南/说明书(如有); 注意 ：彩卡/收缩膜/PDQ/外箱不要打ZURU标准日期码！！ Remark: 1. 出 Bekasovo 2和Ural; | V6: Ann Zhang | W6: 0.9801 | X6: =W6*I6 -> 305.7912 | Y6: 88869-1.4 | Z6: 312 | AA6: =Z6-I6 -> 0 | AD6: 77593GQ1-S001 | AE6: 已入 | AF6: =I6 -> 312 | AG6: =AF6 -> 312 | AI6: =AG6 -> 312 | AN6: =I6/13 -> 24 | AX6: =I6 -> 312 | BA6: =I6*$BA$2 -> 39 | BB6: =I6*$BB$2 -> 32.5 | BC6: =I6*$BC$2 -> 6.5 | BD6: =I6*$BD$2 -> 39 | BE6: =I6*$BE$2 -> 39 | BF6: =I6*$BF$2 -> 39 | BG6: =I6*$BG$2 -> 39 | BH6: =I6*$BH$2 -> 39 | BI6: =I6*$BI$2 -> 39 | BK6: =BK5-BA6 -> 12198.625 | BL6: =BL5-BB6 -> 10342.021 | BM6: =BM5-BD6 -> 12211.625 | BN6: =BN5-BC6 -> 1943.6042 | BO6: =BO5-BE6 -> 10333.625 | BP6: =BP5-BF6 -> 12211.625 | BQ6: =BQ5-BG6 -> 12211.625 | BR6: =BR5-BH6 -> 12611.625 | BS6: =BS5-BI6 -> 12211.625
A7: 45564 | B7: DM LLC | C7: 俄罗斯 | D7: 4500163959 | E7: 包装要求参考4 500146630，出 Bekasovo 2 | F7: 4500146630-10 | G7: 77593GQ1-S001 | H7: S4迷你恐龙13PCS/GQ1*4 | I7: 676 | J7: 0 | K7: 52 | L7: =I7/K7 -> 13 | M7: 45667 | N7: 45663 | O7: 彩卡/收缩膜/PDQ/外箱不要打ZURU标准日期码！ | P7: pass | Q7: 4/28 截SI | R7: 45574 | S7: 无 | T7: 进口商贴纸+EAN条码贴纸翻单146595 | U7: 日期码格式：外包装/外箱不要打ZURU标准日期码 日期： Packaging Info: 取代4500150271/4500157991/4500146630/4500159461/4500158543中 对应的款 ; 包装要求参考4500150271/4500157991/4500146630/4500159461/4500158543 Remark: | V7: Ann Zhang | W7: 0.9638 | X7: =W7*I7 -> 651.5288 | Y7: 94862-4.28 | Z7: 676 | AA7: =Z7-I7 -> 0 | AD7: 77593GQ1-S001 | AE7: 已入 | AF7: =I7 -> 676 | AG7: =AF7 -> 676 | AI7: =AG7 -> 676 | AN7: =I7/13 -> 52 | AX7: =I7 -> 676 | BA7: =I7*$BA$2 -> 84.5 | BB7: =I7*$BB$2 -> 70.416667 | BC7: =I7*$BC$2 -> 14.083333 | BD7: =I7*$BD$2 -> 84.5 | BE7: =I7*$BE$2 -> 84.5 | BF7: =I7*$BF$2 -> 84.5 | BG7: =I7*$BG$2 -> 84.5 | BH7: =I7*$BH$2 -> 84.5 | BI7: =I7*$BI$2 -> 84.5 | BK7: =BK6-BA7 -> 12114.125 | BL7: =BL6-BB7 -> 10271.604 | BM7: =BM6-BD7 -> 12127.125 | BN7: =BN6-BC7 -> 1929.5208 | BO7: =BO6-BE7 -> 10249.125 | BP7: =BP6-BF7 -> 12127.125 | BQ7: =BQ6-BG7 -> 12127.125 | BR7: =BR6-BH7 -> 12527.125 | BS7: =BS6-BI7 -> 12127.125
A8: 45541 | B8: T.J.MORRIS LTD | C8: 英国 | D8: 4500144734 | E8: 11039548 | F8: 4500144734-20 | G8: 77593GQ2-S002 | H8: S4迷你恐龙24PCS入GQ2*2/箱 | I8: 9456 | J8: 0 | K8: 24 | L8: =I8/K8 -> 394 | M8: 45656 | N8: 45652 | P8: pass | Q8: 1/4 截单 | R8: 45614 | S8: 无 | T8: 无 | U8: 日期码格式：ZURU INC(BVI) 标准格式 日期：按实际生产日期 Packaging Info: 2.77593GQ2: MA 1L UPC包装，UPC#193052066206请先检查条码是否正确再安排做货，如有问题请告知 5.配比都跟MA配比 Remark: 1.产品及包装需要印UKCA图标，包装需要有ZURU UK LTD/ZURU France地址信息，QC同事请核查，如有问题与跟单确认。 2. 需要符合欧洲标准不能含有闪粉和微塑料，否则不和法规会有客诉产生 | V8: Sheba Ye | W8: 0.9854 | X8: =W8*I8 -> 9317.9424 | Y8: 88923-1.7 | Z8: =9432+24 -> 9456 | AA8: =Z8-I8 -> 0 | AD8: 77593GQ2-S002 | AE8: 已入 | AF8: =I8 -> 9456 | AG8: =I8 -> 9456 | AI8: =I8 -> 9456 | AL8: =I8/24 -> 394 | AX8: =I8 -> 9456 | BA8: =I8*$BA$2 -> 1182 | BB8: =I8*$BB$2 -> 985 | BC8: =I8*$BC$2 -> 197 | BD8: =I8*$BD$2 -> 1182 | BE8: =I8*$BE$2 -> 1182 | BF8: =I8*$BF$2 -> 1182 | BG8: =I8*$BG$2 -> 1182 | BH8: =I8*$BH$2 -> 1182 | BI8: =I8*$BI$2 -> 1182 | BK8: =BK7-BA8 -> 10932.125 | BL8: =BL7-BB8 -> 9286.6042 | BM8: =BM7-BD8 -> 10945.125 | BN8: =BN7-BC8 -> 1732.5208 | BO8: =BO7-BE8 -> 9067.125 | BP8: =BP7-BF8 -> 10945.125 | BQ8: =BQ7-BG8 -> 10945.125 | BR8: =BR7-BH8 -> 11345.125 | BS8: =BS7-BI8 -> 10945.125
A9: 45604 | B9: Inventive Toys | C9: 俄罗斯联邦 | D9: 4500150836 | F9: 4500150836-10 | G9: 77593GQ1-S001 | H9: S4迷你恐龙13PCS/GQ1*4 | I9: 2028 | J9: 0 | K9: 52 | L9: =I9/K9 -> 39 | M9: 45660 | N9: 45656 | O9: 外包装 (指: 收缩膜/彩卡/铝箔袋/挂卡/PDQ) /外箱不要打ZURU标准日期码 | P9: 自检 | Q9: 1/9 装柜 | R9: 11、26 | S9: 无 | T9: 12/9 进口商贴纸+ EAN条码贴纸 | U9: 日期码格式：外包装/外箱不要打ZURU标准日期码 日期： Packaging Info: 注意 ：外包装 (指: 收缩膜/彩卡/铝箔袋/挂卡/PDQ) /外箱不要打ZURU标准日期码！胶件可以打日期码。 外包装（包括收缩膜/彩卡/PDQ）都不能含Instagram and facebook logo等社交logo; 1L MA 收缩膜 或者彩卡+ 进口商贴纸； MA PDQ + EAN条码贴纸 ， MA指南/说明书（如有）; Remark: 标准配比 ；整单货期2025年1月3 | V9: Ann Zhang | W9: 0.963 | X9: =W9*I9 -> 1952.964 | Y9: 94071-1.16 | Z9: 2028 | AA9: =Z9-I9 -> 0 | AD9: 77593GQ1-S001 | AE9: 已入 | AF9: =I9 -> 2028 | AG9: =AF9 -> 2028 | AI9: =AG9 -> 2028 | AN9: =I9/13 -> 156 | AX9: =I9 -> 2028 | BA9: =I9*$BA$2 -> 253.5 | BB9: =I9*$BB$2 -> 211.25 | BC9: =I9*$BC$2 -> 42.25 | BD9: =I9*$BD$2 -> 253.5 | BE9: =I9*$BE$2 -> 253.5 | BF9: =I9*$BF$2 -> 253.5 | BG9: =I9*$BG$2 -> 253.5 | BH9: =I9*$BH$2 -> 253.5 | BI9: =I9*$BI$2 -> 253.5 | BK9: =BK8-BA9 -> 10678.625 | BL9: =BL8-BB9 -> 9075.3542 | BM9: =BM8-BD9 -> 10691.625 | BN9: =BN8-BC9 -> 1690.2708 | BO9: =BO8-BE9 -> 8813.625 | BP9: =BP8-BF9 -> 10691.625 | BQ9: =BQ8-BG9 -> 10691.625 | BR9: =BR8-BH9 -> 11091.625 | BS9: =BS8-BI9 -> 10691.625
A10: 45608 | B10: FAMILY DOLLAR SERVICES, INC, | C10: 美国 | D10: 4500151082 | E10: 30583154 | F10: 4500151082-10 | G10: 77593GQ5-S001 | H10: S4迷你恐龙8PCS/GQ5 | I10: 6056 | J10: 0 | K10: 8 | L10: =I10/K10 -> 757 | M10: 45660 | N10: 45656 | O10: 指定日期码:DG20241220 | P10: pass | Q10: 1/14 截SI | R10: 45609 | S10: 有 | T10: 外箱彩贴翻单PO#4500135943 | U10: 日期码格式：ZURU INC(BVI) 标准格式 日期：2024-12-20 Packaging Info: 1）客版PDQ(翻单PO#4500135943), 最新版ZURU MA UPC包装(去掉社交媒体标志，优先1L)，出口美国。如有说明书请使用ZURU MA说明书，优先放1L英语。8pcs/PDQ /CTN。 2）ZURU标准日期码格式：工厂城市缩写+生产年月日，此单指定日期码:DG20241220 3）外箱正侧唛两面都需粘贴产品彩色贴纸，外箱彩贴每箱两张，客版外箱彩贴翻单PO#4500135943。如侧唛位置放不下彩贴和唛头信息，可改为放两个正唛。无论 是正唛+侧唛或者是两个正唛，唛头信息和彩贴需放在同一个面。箱唛需排版给跟单确认。 4) 每个球贴一张客供防盗贴，贴在收缩膜上，防盗贴由跟单采购，供应商直接发货到工厂。防盗贴贴纸位置与PO#4500144246一致。 Remark: 客户PO#30583154 客户SKU#1003737 1）Item#77593GQ5- S001 2）此单无第三方验货+抽样测试，ZURU QC验货PASS后，跟单得到客户的approval之后方可安排出货 3）大货外箱材积绝对不可大于下述数据，材积只接受3%的变小；重量正负不得超过以下列出数据的5%，接受外箱以印章方式印上实际毛重。 大货外箱尺寸请保持：21.0 x 20.6 x 21.2 cm (即8.27 x8.11 x 8.35 inch)，材积必须不能大于0.3249CubeFeet（即0.0092SSCBM); 外箱毛重 2.6LBS（即1.20 KG S） 4）大货配比： #77593GQ5-S001 S001-5 SURPRISE-DINO STRIKE-SERIES 6-CAPSULE,2Facing8pcs/Gravity PDQ,8pcs/1PDQ/CTN。 UPC:193052066206 8pcs/PDQ/CTN,2W*2D*2H=8PCS/PDQ, Contain Slime,with borax; Capsule size: 3.74 inch x 3.74 inch x 3.74 inch 5）客户Family Dollar不允许少数出货，必须按照PO上的数量出货，也不允许延期，否则会有罚款。 6）客户要求:"产品和包装不能含有PFAS 物质以及1,4 dioxane" ，请确保产品可以过美国标准测试。 | V10: Jenny Liu/Andro | W10: 1.0363 | X10: =L10*W10 -> 784.4791 | Y10: 94042-1.15 | Z10: 6056 | AA10: =Z10-I10 -> 0 | AD10: 77593GQ5-S001 | AE10: 已入 | AF10: =I10 -> 6056 | AG10: =AF10 -> 6056 | AI10: =AG10 -> 6056 | AP10: =I10/8 -> 757 | AX10: =I10 -> 6056 | BA10: =I10*$BA$2 -> 757 | BB10: =I10*$BB$2 -> 630.83333 | BC10: =I10*$BC$2 -> 126.16667 | BD10: =I10*$BD$2 -> 757 | BE10: =I10*$BE$2 -> 757 | BF10: =I10*$BF$2 -> 757 | BG10: =I10*$BG$2 -> 757 | BH10: =I10*$BH$2 -> 757 | BI10: =I10*$BI$2 -> 757 | BK10: =BK9-BA10 -> 9921.625 | BL10: =BL9-BB10 -> 8444.5208 | BM10: =BM9-BD10 -> 9934.625 | BN10: =BN9-BC10 -> 1564.1042 | BO10: =BO9-BE10 -> 8056.625 | BP10: =BP9-BF10 -> 9934.625 | BQ10: =BQ9-BG10 -> 9934.625 | BR10: =BR9-BH10 -> 10334.625 | BS10: =BS9-BI10 -> 9934.625
A11: 45614 | B11: JSC 􀂫Grand-Trade􀂻 | C11: 俄罗斯联邦 | D11: 4500151353 | E11: PGT-658704 | F11: 4500151353-20 | G11: 77593GQ1-S002 | H11: S4迷你恐龙13PCS/GQ1*4 | I11: 1313 | J11: 0 | K11: 13 | L11: =I11/K11 -> 101 | M11: 45660 | N11: 45656 | P11: pass | Q11: 1/6 截SI | R11: 45614 | S11: 有 | T11: 12/2进口商贴纸+ EAN条码贴纸+背景贴纸+外箱贴纸+空白贴纸 | U11: 日期码格式：ZURU INC(BVI) 标准格式 日期：按实际生产日期 Packaging Info: 注意： 此客户不允许包装/产品/PDQ 上显示recycled material / plastic 字眼， 如有请告知跟单需要加贴纸覆盖； 1.77593GQ1 ： 1L MA 收缩膜+ 进口商贴纸(覆盖内膜上的recycled plastic)+ EAN 条码贴纸， 1L MA PDQ+ 背景贴纸覆盖recycled Plastic ， MA 指南 + 空白贴纸（覆盖指南上的recycled plastic信息） 2. 需要安排loading inspection (装柜现场监柜)； 3. 外箱侧唛右上角各一张贴纸（一共2张） ； Remark: 标准配比，整单货期2025年1月3 . | V11: Ann Zhang | W11: 0.9839 | X11: =W11*I11 -> 1291.8607 | Y11: 88957-1.9 | Z11: 1313 | AA11: =Z11-I11 -> 0 | AD11: 77593GQ1-S002 | AE11: 已入 | AF11: =I11 -> 1313 | AG11: =AF11 -> 1313 | AI11: =I11 -> 1313 | AN11: =I11/13 -> 101 | AX11: =I11 -> 1313 | BA11: =I11*$BA$2 -> 164.125 | BB11: =I11*$BB$2 -> 136.77083 | BC11: =I11*$BC$2 -> 27.354167 | BD11: =I11*$BD$2 -> 164.125 | BE11: =I11*$BE$2 -> 164.125 | BF11: =I11*$BF$2 -> 164.125 | BG11: =I11*$BG$2 -> 164.125 | BH11: =I11*$BH$2 -> 164.125 | BI11: =I11*$BI$2 -> 164.125 | BK11: =BK10-BA11 -> 9757.5 | BL11: =BL10-BB11 -> 8307.75 | BM11: =BM10-BD11 -> 9770.5 | BN11: =BN10-BC11 -> 1536.75 | BO11: =BO10-BE11 -> 7892.5 | BP11: =BP10-BF11 -> 9770.5 | BQ11: =BQ10-BG11 -> 9770.5 | BR11: =BR10-BH11 -> 10170.5 | BS11: =BS10-BI11 -> 9770.5
A12: 45617 | B12: Importadora Sudamericana & Generac | C12: 阿根廷 | D12: 4500151881 | E12: LEGAJO 4117 | F12: 4500151881-20 | G12: 77593GQ5-S001 | H12: S4迷你恐龙8PCS/GQ5 | I12: 6000 | J12: 0 | K12: 8 | L12: =I12/K12 -> 750 | M12: 45660 | N12: 45656 | P12: pass | Q12: 1/7 截SI | R12: 45629 | S12: 无 | T12: 12/12 进口商贴纸 | U12: 日期码格式：ZURU INC(BVI) 标准格式 日期：按实际生产日期 Packaging Info: MA 1L包装+进口商贴纸+箱唛 | V12: Ava Liang | W12: 0.9957 | X12: =L12*W12 -> 746.775 | Y12: 88870-1.4 | Z12: 6000 | AA12: =Z12-I12 -> 0 | AD12: 77593GQ5-S001 | AE12: 已入 | AF12: =I12 -> 6000 | AG12: =AF12 -> 6000 | AI12: =AG12 -> 6000 | AP12: =I12/8 -> 750 | AX12: =I12 -> 6000 | BA12: =I12*$BA$2 -> 750 | BB12: =I12*$BB$2 -> 625 | BC12: =I12*$BC$2 -> 125 | BD12: =I12*$BD$2 -> 750 | BE12: =I12*$BE$2 -> 750 | BF12: =I12*$BF$2 -> 750 | BG12: =I12*$BG$2 -> 750 | BH12: =I12*$BH$2 -> 750 | BI12: =I12*$BI$2 -> 750 | BK12: =BK11-BA12 -> 9007.5 | BL12: =BL11-BB12 -> 7682.75 | BM12: =BM11-BD12 -> 9020.5 | BN12: =BN11-BC12 -> 1411.75 | BO12: =BO11-BE12 -> 7142.5 | BP12: =BP11-BF12 -> 9020.5 | BQ12: =BQ11-BG12 -> 9020.5 | BR12: =BR11-BH12 -> 9420.5 | BS12: =BS11-BI12 -> 9020.5
A13: 45603 | B13: ROSS PROCUREMENT.INC | C13: 美国 | D13: 4500150464 | E13: 60190494 | F13: 4500150464-10 | G13: 77614-S001 | H13: S4迷你恐龙2PK圆筒*12/箱 | I13: 1008 | J13: 0 | K13: 12 | L13: =I13/K13 -> 84 | M13: 45672 | N13: 45667 | P13: 自检 | Q13: 3/7 截SI | R13: 45610 | S13: 无 | T13: 12/19 客供价格贴纸 | U13: 日期码格式：ZURU INC(BVI) 标准格式 日期：按实际生产日期 Packaging Info: 1.ZURU MA UPC 收缩膜+客版铜版纸+PVC桶 + 客供价格贴纸，出口美国 , 优先使用MA 1L 最新版本 。 Remark: 1.ZURU MA UPC 收缩膜+客版铜版纸+PVC桶 + 客供价格贴纸，出口美国 , 优先使用MA 1L 最新版本 。 2.价格贴纸位于包装正面右下角，不挡住重要信息即可，可适当调整 ，价格贴纸由跟单提供。 3.标准日期码格式，产品和包装必须有日期码 。 4.同个产品同个货期不可出现不同的包装。 5. PVC 桶中球不能出现完全相同的ASSORTMENT ， 即同一个PVC 中球里的ASSORTMENT 需要不同。 以免消费者失望。 6.PVC 桶上加上 MINI BRANDS 的LOGO 贴纸 （ ZURU 统一要求的） 7.收缩膜可使用标版带UPC条码MA，无需白色贴纸覆盖。 | V13: Sophia Zhou | W13: 2.2427 | X13: =W13*I13 -> 2260.6416 | Y13: 94486-3.7 | Z13: 1008 | AA13: =Z13-I13 -> 0 | AD13: 77614-S001-1 | AE13: 已入 | AF13: =I13*2 -> 2016 | AG13: =AF13 -> 2016 | AI13: =AF13 -> 2016 | AT13: =I13 -> 1008 | AU13: =AT13 -> 1008 | AX13: =I13*2 -> 2016 | BA13: =I13*$BA$2*2 -> 252 | BB13: =I13*$BB$2*2 -> 210 | BC13: =I13*$BC$2*2 -> 42 | BD13: =I13*$BD$2*2 -> 252 | BE13: =I13*$BE$2*2 -> 252 | BF13: =I13*$BF$2*2 -> 252 | BG13: =I13*$BG$2*2 -> 252 | BH13: =I13*$BH$2*2 -> 252 | BI13: =I13*$BI$2*2 -> 252 | BK13: =BK12-BA13 -> 8755.5 | BL13: =BL12-BB13 -> 7472.75 | BM13: =BM12-BD13 -> 8768.5 | BN13: =BN12-BC13 -> 1369.75 | BO13: =BO12-BE13 -> 6890.5 | BP13: =BP12-BF13 -> 8768.5 | BQ13: =BQ12-BG13 -> 8768.5 | BR13: =BR12-BH13 -> 9168.5 | BS13: =BS12-BI13 -> 8768.5
A14: 45651 | B14: TOYS "R" US – JAPAN, LTD | C14: 日本 | D14: 4500154748 | E14: 47:0003113610 | F14: 4500154748-10 | G14: 77593GQ2-S001 | H14: S4迷你恐龙24PCS入GQ2*2/箱-干燥剂 | I14: 4800 | J14: 0 | K14: 48 | L14: =I14/K14 -> 100 | M14: 45716 | N14: 45712 | P14: pass | Q14: 3/7 截SI | R14: 45652 | S14: 无 | T14: 1/21日语贴纸 | U14: 日期码格式：ZURU INC(BVI) 标准格式 日期：按实际生产日期 Packaging Info: MA 1L PKG+1张日语贴纸（新稿）， MA 1L PDQ， MA 5L收藏指南 Remark: 出日本首单需安排样板测试， 请按邮件要求先寄出MA包装的样板做测试。 大货的产品内容和MA包装版本以及产品品质需严格跟到寄出的测试版。 | V14: Doris Shou | W14: 0.9808 | X14: =W14*I14 -> 4707.84 | Y14: 94461-3.6 | Z14: 4800 | AA14: =Z14-I14 -> 0 | AD14: 77593GQ2-S001 | AE14: 已入 | AF14: =I14 -> 4800 | AG14: =I14 -> 4800 | AI14: =I14 -> 4800 | AL14: =I14/24 -> 200 | AX14: =I14 -> 4800 | BA14: =I14*$BA$2 -> 600 | BB14: =I14*$BB$2 -> 500 | BC14: =I14*$BC$2 -> 100 | BD14: =I14*$BD$2 -> 600 | BE14: =I14*$BE$2 -> 600 | BF14: =I14*$BF$2 -> 600 | BG14: =I14*$BG$2 -> 600 | BH14: =I14*$BH$2 -> 600 | BI14: =I14*$BI$2 -> 600 | BK14: =BK13-BA14 -> 8155.5 | BL14: =BL13-BB14 -> 6972.75 | BM14: =BM13-BD14 -> 8168.5 | BN14: =BN13-BC14 -> 1269.75 | BO14: =BO13-BE14 -> 6290.5 | BP14: =BP13-BF14 -> 8168.5 | BQ14: =BQ13-BG14 -> 8168.5 | BR14: =BR13-BH14 -> 8568.5 | BS14: =BS13-BI14 -> 8168.5
A15: 45696 | B15: Importadora Sudamericana & Generac | C15: 阿根廷 | D15: 4500156986 | F15: 4500156986-20 | G15: 77593GQ5-S001 | H15: S4迷你恐龙8PCS/GQ5 | I15: 9600 | J15: 0 | K15: 8 | L15: =I15/K15 -> 1200 | M15: 45736 | N15: 45733 | P15: PASS | Q15: 3/24 截SI | R15: 45707 | S15: 无 | T15: 3/3 进口商贴纸 | U15: 日期码格式：ZURU INC(BVI) 标准格式 日期：按实际生产日期 Packaging Info: MA 3LEAN包装+进口商贴纸+UPC贴纸+箱唛，进口商贴纸翻单PO4500151881 77593GQ5 PDQ 翻单PO 4500151082,77595GQ3 PDQ 翻单 PO 4500144251 Remark: | V15: Ava Liang | W15: 0.9957 | X15: =W15*I15 -> 9558.72 | Y15: 94631-3.25 | Z15: =4792+4800+8 -> 9600 | AA15: =Z15-I15 -> 0 | AD15: 77593GQ5-S001-3L | AE15: 已入 | AF15: =I15 -> 9600 | AH15: =I15 -> 9600 | AI15: =I15 -> 9600 | AP15: =I15/8 -> 1200 | AX15: =I15 -> 9600 | BA15: =I15*$BA$2 -> 1200 | BB15: =I15*$BB$2 -> 1000 | BC15: =I15*$BC$2 -> 200 | BD15: =I15*$BD$2 -> 1200 | BE15: =I15*$BE$2 -> 1200 | BF15: =I15*$BF$2 -> 1200 | BG15: =I15*$BG$2 -> 1200 | BH15: =I15*$BH$2 -> 1200 | BI15: =I15*$BI$2 -> 1200 | BK15: =BK14-BA15 -> 6955.5 | BL15: =BL14-BB15 -> 5972.75 | BM15: =BM14-BD15 -> 6968.5 | BN15: =BN14-BC15 -> 1069.75 | BO15: =BO14-BE15 -> 5090.5 | BP15: =BP14-BF15 -> 6968.5 | BQ15: =BQ14-BG15 -> 6968.5 | BR15: =BR14-BH15 -> 7368.5 | BS15: =BS14-BI15 -> 6968.5
A16: 45702 | B16: Hermanex Europe BV | C16: 新西兰 | D16: 4500157700 | F16: 4500157700-10 | G16: 77593SK1-S002 | H16: S4迷你恐龙展示架带球 | I16: 6570 | J16: 0 | K16: 30 | L16: =I16/K16 -> 219 | M16: 45741 | N16: 45737 | P16: pass | Q16: 3/27 截SI | R16: 45706 | S16: 无 | T16: 2/18 NL警语贴纸 | U16: 日期码格式：ZURU INC(BVI) 标准格式 日期：按实际生产日期 Packaging Info: 77593SK1: MA 3L A版本 EAN 收缩膜+NL警语贴纸(含FR, ES环保LOGO)，MA 5L Slime Poly Bag+NL警语贴纸，MA 5L收藏指南，MA说明书，MA 袋子，MA 3L A版展架( 消耗Slow Moving库存，With Base) Remark: | V16: Eddie Huang | W16: 36.2614 | X16: =W16*L16 -> 7941.2466 | Y16: 94652-3.27 | Z16: 6570 | AA16: =Z16-I16 -> 0 | AD16: 77593SK1-S002-3L | AE16: 已入 | AF16: =I16 -> 6570 | AH16: =I16 -> 6570 | AI16: =I16 -> 6570 | AQ16: =I16/30 -> 219 | AS16: =AQ16 -> 219 | AX16: =I16 -> 6570 | BA16: =I16*$BA$2 -> 821.25 | BB16: =I16*$BB$2 -> 684.375 | BC16: =I16*$BC$2 -> 136.875 | BD16: =I16*$BD$2 -> 821.25 | BE16: =I16*$BE$2 -> 821.25 | BF16: =I16*$BF$2 -> 821.25 | BG16: =I16*$BG$2 -> 821.25 | BH16: =I16*$BH$2 -> 821.25 | BI16: =I16*$BI$2 -> 821.25 | BK16: =BK15-BA16 -> 6134.25 | BL16: =BL15-BB16 -> 5288.375 | BM16: =BM15-BD16 -> 6147.25 | BN16: =BN15-BC16 -> 932.875 | BO16: =BO15-BE16 -> 4269.25 | BP16: =BP15-BF16 -> 6147.25 | BQ16: =BQ15-BG16 -> 6147.25 | BR16: =BR15-BH16 -> 6547.25 | BS16: =BS15-BI16 -> 6147.25
A17: 45705 | B17: Royal Foods LLC | C17: 阿塞拜疆 | D17: 4500157780 | F17: 4500157780-10 | G17: 77593GQ1-S001 | H17: S4迷你恐龙13PCS/GQ1*4 | I17: 156 | J17: 0 | K17: 52 | L17: =I17/K17 -> 3 | M17: 45741 | N17: 45737 | P17: 自检 | Q17: 4/7 截SI | R17: 45705 | S17: 无 | T17: 无 | U17: 日期码格式：ZURU INC(BVI) 标准格式 日期：按实际生产日期 Packaging Info: 1. 无进口商贴纸； 2. 77593GQ1 ： 1L MA UPC 包装， MA PDQ/说明书/指南（如有）； Remark: 标准配比 | V17: Ann Zhang | W17: 0.967 | X17: =W17*I17 -> 150.852 | Y17: 94710-4.7 | Z17: 156 | AA17: =Z17-I17 -> 0 | AD17: 77593GQ1-S001 | AE17: 已入 | AF17: =I17 -> 156 | AG17: =AF17 -> 156 | AI17: =I17 -> 156 | AN17: =I17/13 -> 12 | AX17: =I17 -> 156 | BA17: =I17*$BA$2 -> 19.5 | BB17: =I17*$BB$2 -> 16.25 | BC17: =I17*$BC$2 -> 3.25 | BD17: =I17*$BD$2 -> 19.5 | BE17: =I17*$BE$2 -> 19.5 | BF17: =I17*$BF$2 -> 19.5 | BG17: =I17*$BG$2 -> 19.5 | BH17: =I17*$BH$2 -> 19.5 | BI17: =I17*$BI$2 -> 19.5 | BK17: =BK16-BA17 -> 6114.75 | BL17: =BL16-BB17 -> 5272.125 | BM17: =BM16-BD17 -> 6127.75 | BN17: =BN16-BC17 -> 929.625 | BO17: =BO16-BE17 -> 4249.75 | BP17: =BP16-BF17 -> 6127.75 | BQ17: =BQ16-BG17 -> 6127.75 | BR17: =BR16-BH17 -> 6527.75 | BS17: =BS16-BI17 -> 6127.75
A18: 45740 | D18: ZMPO250257 | G18: 77593-S001 | I18: 11空球 | J18: 0 | K18: 24 | L18: =I18/K18 -> #VALUE! | M18: 45749 | N18: =M18-4 -> 45745 | R18: 空白箱 | S18: 无 | T18: 无 | U18: Remark：大货最新版本/11PCS空球要用大货收缩膜收缩好；备注： 收到样品订单后尽快安排 ，注意样板品质质量要求要高于大货品质质量 ，送货时必须要附带送货单(没有送货单和QC检验合格报告的仓库一律拒绝收货)，请知悉，谢谢！ | V18: Angus | Y18: 94918-4.30 | Z18: 11 | AD18: # | AE18: #
A19: 45740 | D19: ZMPO250257 | G19: 77593-S001 | I19: 18套散件 | J19: 0 | K19: 24 | L19: =I19/K19 -> #VALUE! | M19: 45749 | N19: =M19-4 -> 45745 | R19: 空白箱 | S19: 无 | T19: 无 | U19: Remark：大货最新版本/只需要齐全套散件，每款散件不要用纸袋子装，用透明塑胶袋装即可/麻烦用胶袋分装好一套为一袋；备注： 收到样品订单后尽快安排 ，注意样板品质质量要求要高于大货品质质量 ，送货时必须要附带送货单(没有送货单和QC检验合格报告的仓库一律拒绝收货)，请知悉，谢谢！ | V19: Angus | Y19: 94918-4.30 | Z19: 18 | AD19: # | AE19: #
A20: 45712 | B20: Walmart Central America | C20: 萨尔瓦多 | D20: 4500158302 | F20: 4500158302-10 | G20: 77593GQ2-S001 | H20: S4迷你恐龙24PCS入GQ2*2/箱 | I20: 576 | J20: 0 | K20: 48 | L20: =I20/K20 -> 12 | M20: 45763 | N20: 45758 | P20: pass | Q20: 4/28 截SI | R20: 3/24 双坑纸箱 | S20: 无 | T20: 3/21进口商贴纸+UPC贴纸 | U20: 日期码格式：ZURU INC(BVI) 标准格式 日期：按实际生产日期 Packaging Info: 1. 77593GQ2：MA 3L EAN包装+UPC贴纸+MA 3L PDQ包装+MA多语收藏指南+进口商贴纸+箱唛 Remark: 1.使用双坑外箱 2.请注意产品包装条形码必须是UPC 3.无第三方验货 | V20: Ever Li | W20: 0.9947 | X20: =W20*I20 -> 572.9472 | Y20: 94865-4.28 | Z20: 576 | AA20: =Z20-I20 -> 0 | AD20: 77593GQ2-S001-3L | AE20: 已入 | AF20: =I20 -> 576 | AH20: =I20 -> 576 | AI20: =I20 -> 576 | AM20: =I20/24 -> 24 | AX20: =I20 -> 576 | BA20: =I20*$BA$2 -> 72 | BB20: =I20*$BB$2 -> 60 | BC20: =I20*$BC$2 -> 12 | BD20: =I20*$BD$2 -> 72 | BE20: =I20*$BE$2 -> 72 | BF20: =I20*$BF$2 -> 72 | BG20: =I20*$BG$2 -> 72 | BH20: =I20*$BH$2 -> 72 | BI20: =I20*$BI$2 -> 72 | BK20: =BK17-BA20 -> 6042.75 | BL20: =BL17-BB20 -> 5212.125 | BM20: =BM17-BD20 -> 6055.75 | BN20: =BN17-BC20 -> 917.625 | BO20: =BO17-BE20 -> 4177.75 | BP20: =BP17-BF20 -> 6055.75 | BQ20: =BQ17-BG20 -> 6055.75 | BR20: =BR17-BH20 -> 6455.75 | BS20: =BS17-BI20 -> 6055.75
A21: 45712 | B21: Walmart Central America-NI | C21: 尼加拉瓜 | D21: 4500158358 | F21: 4500158358-10 | G21: 77593GQ2-S001 | H21: S4迷你恐龙24PCS入GQ2*2/箱 | I21: 192 | J21: 0 | K21: 48 | L21: =I21/K21 -> 4 | M21: 45763 | N21: 45758 | P21: pass | Q21: 4/28 截SI | R21: 3/24 双坑纸箱 | S21: 无 | T21: 进口商贴纸+UPC贴纸翻单158302 | U21: 日期码格式：ZURU INC(BVI) 标准格式 日期：按实际生产日期 Packaging Info: 1. 77593GQ2：MA 3L EAN包装+UPC贴纸+MA 3L PDQ包装+MA多语收藏指南+进口商贴纸+箱唛 所有贴纸翻单PO 4500158302 Remark: 1.使用双坑外箱 2.请注意产品包装条形码必须是UPC 3.无第三方验货 | V21: Ever Li | W21: 0.9947 | X21: =W21*I21 -> 190.9824 | Y21: 94934-5.6 | Z21: 192 | AA21: =Z21-I21 -> 0 | AD21: 77593GQ2-S001-3L | AE21: 已入 | AF21: =I21 -> 192 | AH21: =I21 -> 192 | AI21: =I21 -> 192 | AM21: =I21/24 -> 8 | AX21: =I21 -> 192 | BA21: =I21*$BA$2 -> 24 | BB21: =I21*$BB$2 -> 20 | BC21: =I21*$BC$2 -> 4 | BD21: =I21*$BD$2 -> 24 | BE21: =I21*$BE$2 -> 24 | BF21: =I21*$BF$2 -> 24 | BG21: =I21*$BG$2 -> 24 | BH21: =I21*$BH$2 -> 24 | BI21: =I21*$BI$2 -> 24 | BK21: =BK20-BA21 -> 6018.75 | BL21: =BL20-BB21 -> 5192.125 | BM21: =BM20-BD21 -> 6031.75 | BN21: =BN20-BC21 -> 913.625 | BO21: =BO20-BE21 -> 4153.75 | BP21: =BP20-BF21 -> 6031.75 | BQ21: =BQ20-BG21 -> 6031.75 | BR21: =BR20-BH21 -> 6431.75 | BS21: =BS20-BI21 -> 6031.75
A22: 45712 | B22: Walmart Central America-HN | C22: 洪都拉斯 | D22: 4500158415 | F22: 4500158415-10 | G22: 77593GQ2-S001 | H22: S4迷你恐龙24PCS入GQ2*2/箱 | I22: 384 | J22: 0 | K22: 48 | L22: =I22/K22 -> 8 | M22: 45763 | N22: 45758 | P22: pass | Q22: 4/29 截SI | R22: 3/24 双坑纸箱 | S22: 无 | T22: 进口商贴纸+UPC贴纸翻单158302 | U22: 日期码格式：ZURU INC(BVI) 标准格式 日期：按实际生产日期 Packaging Info: 1. 77593GQ2：MA 3L EAN包装+UPC贴纸+MA 3L PDQ包装+MA多语收藏指南+进口商贴纸+箱唛 以上所有贴纸翻单PO4500158302 Remark: 1.使用双坑外箱 2.请注意产品包装条形码必须是UPC 3.无第三方验货 | V22: Ever Li | W22: 0.9947 | X22: =W22*I22 -> 381.9648 | Y22: 94891-4.30 | Z22: 384 | AA22: =Z22-I22 -> 0 | AD22: 77593GQ2-S001-3L | AE22: 已入 | AF22: =I22 -> 384 | AH22: =I22 -> 384 | AI22: =I22 -> 384 | AM22: =I22/24 -> 16 | AX22: =I22 -> 384 | BA22: =I22*$BA$2 -> 48 | BB22: =I22*$BB$2 -> 40 | BC22: =I22*$BC$2 -> 8 | BD22: =I22*$BD$2 -> 48 | BE22: =I22*$BE$2 -> 48 | BF22: =I22*$BF$2 -> 48 | BG22: =I22*$BG$2 -> 48 | BH22: =I22*$BH$2 -> 48 | BI22: =I22*$BI$2 -> 48 | BK22: =BK21-BA22 -> 5970.75 | BL22: =BL21-BB22 -> 5152.125 | BM22: =BM21-BD22 -> 5983.75 | BN22: =BN21-BC22 -> 905.625 | BO22: =BO21-BE22 -> 4105.75 | BP22: =BP21-BF22 -> 5983.75 | BQ22: =BQ21-BG22 -> 5983.75 | BR22: =BR21-BH22 -> 6383.75 | BS22: =BS21-BI22 -> 5983.75
A23: 45714 | B23: Walmart Central America-CR | C23: 哥斯达黎加 | D23: 4500158535 | F23: 4500158535-10 | G23: 77593GQ2-S001 | H23: S4迷你恐龙24PCS入GQ2*2/箱 | I23: 1440 | J23: 0 | K23: 48 | L23: =I23/K23 -> 30 | M23: 45763 | N23: 45758 | P23: pass | Q23: 4/29 截SI | R23: 3/24 双坑纸箱 | S23: 无 | T23: 进口商贴纸+UPC贴纸翻单158302 | U23: 日期码格式：ZURU INC(BVI) 标准格式 日期：按实际生产日期 Packaging Info: 1. 77593GQ2：MA 3L EAN包装+UPC贴纸+MA 3L PDQ包装+MA多语收藏指南+进口商贴纸+箱唛 以上贴纸翻单PO 4500158302 Remark: 1.使用双坑外箱 2.请注意产品包装条形码必须是UPC 3.无第三方验货 | V23: Ever Li | W23: 0.9907 | X23: =W23*I23 -> 1426.608 | Y23: 94882-4.29 | Z23: 1440 | AA23: =Z23-I23 -> 0 | AD23: 77593GQ2-S001-3L | AE23: 已入 | AF23: =I23 -> 1440 | AH23: =I23 -> 1440 | AI23: =I23 -> 1440 | AM23: =I23/24 -> 60 | AX23: =I23 -> 1440 | BA23: =I23*$BA$2 -> 180 | BB23: =I23*$BB$2 -> 150 | BC23: =I23*$BC$2 -> 30 | BD23: =I23*$BD$2 -> 180 | BE23: =I23*$BE$2 -> 180 | BF23: =I23*$BF$2 -> 180 | BG23: =I23*$BG$2 -> 180 | BH23: =I23*$BH$2 -> 180 | BI23: =I23*$BI$2 -> 180 | BK23: =BK22-BA23 -> 5790.75 | BL23: =BL22-BB23 -> 5002.125 | BM23: =BM22-BD23 -> 5803.75 | BN23: =BN22-BC23 -> 875.625 | BO23: =BO22-BE23 -> 3925.75 | BP23: =BP22-BF23 -> 5803.75 | BQ23: =BQ22-BG23 -> 5803.75 | BR23: =BR22-BH23 -> 6203.75 | BS23: =BS22-BI23 -> 5803.75
A24: 45714 | B24: Walmart Central America-GT | C24: 危地马拉 | D24: 4500158447 | F24: 4500158447-10 | G24: 77593GQ2-S001 | H24: S4迷你恐龙24PCS入GQ2*2/箱 | I24: 1056 | J24: 0 | K24: 48 | L24: =I24/K24 -> 22 | M24: 45763 | N24: 45758 | P24: pass | Q24: 4/28 截SI | R24: 3/24 双坑纸箱 | S24: 无 | T24: 进口商贴纸+UPC贴纸翻单158302 | U24: 日期码格式：ZURU INC(BVI) 标准格式 日期：按实际生产日期 Packaging Info: 1. 77593GQ2：MA 3L EAN包装+UPC贴纸+MA 3L PDQ包装+MA多语收藏指南+进口商贴纸+箱唛 以上所有贴纸翻单PO4500158302 Remark: 1.使用双坑外箱 2.请注意产品包装条形码必须是UPC 3.无第三方验货 | V24: Ever Li | W24: 0.9907 | X24: =W24*I24 -> 1046.1792 | Y24: 94923-5.5 | Z24: =1008+48 -> 1056 | AA24: =Z24-I24 -> 0 | AD24: 77593GQ2-S001-3L | AE24: 已入 | AF24: =I24 -> 1056 | AH24: =I24 -> 1056 | AI24: =I24 -> 1056 | AM24: =I24/24 -> 44 | AX24: =I24 -> 1056 | BA24: =I24*$BA$2 -> 132 | BB24: =I24*$BB$2 -> 110 | BC24: =I24*$BC$2 -> 22 | BD24: =I24*$BD$2 -> 132 | BE24: =I24*$BE$2 -> 132 | BF24: =I24*$BF$2 -> 132 | BG24: =I24*$BG$2 -> 132 | BH24: =I24*$BH$2 -> 132 | BI24: =I24*$BI$2 -> 132 | BK24: =BK23-BA24 -> 5658.75 | BL24: =BL23-BB24 -> 4892.125 | BM24: =BM23-BD24 -> 5671.75 | BN24: =BN23-BC24 -> 853.625 | BO24: =BO23-BE24 -> 3793.75 | BP24: =BP23-BF24 -> 5671.75 | BQ24: =BQ23-BG24 -> 5671.75 | BR24: =BR23-BH24 -> 6071.75 | BS24: =BS23-BI24 -> 5671.75
A25: 45755 | B25: NUEVOS ALMACENES, S.A. | C25: 危地马拉 | D25: 4500162922 | E25: 4504192366 | F25: 4500162922-80 | G25: 77593GQ2-S001 | H25: S4迷你恐龙24PCS入GQ2*2/箱 | I25: 3168 | J25: 0 | K25: 48 | L25: =I25/K25 -> 66 | M25: 45792 | N25: 45789 | O25: 5/16 第三方 | P25: pass | Q25: 5/17 出货 | R25: 45762 | S25: 无 | T25: 4/8 UPC贴纸 | U25: 日期码格式：ZURU INC(BVI) 标准格式 日期：按实际生产日期 Packaging Info:77593GQ2:MA 3L EAN包装+UPC贴纸+箱唛，无进口商贴纸 Remark: 订单需第三方（QIMA)验货，无需签板，请多备料。 外箱上的箱唛资料会显示日期30-MAY-2025,产品/包装/外箱可以按ZURU 标准日期码打，也可以跟回外箱日期码，工厂自行选择,两者均可接受 | V25: Ava Liang | W25: 0.961 | X25: =W25*I25 -> 3044.448 | Y25: 95154-5.30 | Z25: 3168 | AA25: 0 | AD25: 77593GQ2-S001-3L | AE25: 已入 | AF25: =I25 -> 3168 | AH25: =I25 -> 3168 | AI25: =I25 -> 3168 | AM25: =I25/24 -> 132 | AX25: =I25 -> 3168 | BA25: =I25*$BA$2 -> 396 | BB25: =I25*$BB$2 -> 330 | BC25: =I25*$BC$2 -> 66 | BD25: =I25*$BD$2 -> 396 | BE25: =I25*$BE$2 -> 396 | BF25: =I25*$BF$2 -> 396 | BG25: =I25*$BG$2 -> 396 | BH25: =I25*$BH$2 -> 396 | BI25: =I25*$BI$2 -> 396 | BK25: =BK24-BA25 -> 5262.75 | BL25: =BL24-BB25 -> 4562.125 | BM25: =BM24-BD25 -> 5275.75 | BN25: =BN24-BC25 -> 787.625 | BO25: =BO24-BE25 -> 3397.75 | BP25: =BP24-BF25 -> 5275.75 | BQ25: =BQ24-BG25 -> 5275.75 | BR25: =BR24-BH25 -> 5675.75 | BS25: =BS24-BI25 -> 5275.75
A26: 45757 | B26: SUBURBIA S DE R. L. DE C. V. | C26: 墨西哥 | D26: 4500162850 | E26: 6000056637 | F26: 4500162850-50 | G26: 77593GQ2-S001 | H26: S4迷你恐龙24PCS入GQ2*2/箱 | I26: 480 | J26: 0 | K26: 48 | L26: =I26/K26 -> 10 | M26: 45821 | N26: 45818 | O26: 有监柜要求，需要每款多准备一套完整物料，用于监柜 | P26: 自检 | Q26: 6/13 截SI | R26: 外箱只需四面印Zuru logo | S26: 有 | T26: 5/9进口商贴纸+价标贴纸+说明书贴纸+5/26HU贴纸和ASN贴纸客供 | U26: 日期码格式：ZURU INC(BVI) 标准格式 日期：按实际生产日期 Packaging Info: 77593GQ2：MA 多语 EAN 包装+MA 多语PDQ+MA多语说明书+进口商贴纸+价标贴纸+说明书贴纸 1. 外箱只需四面印Zuru logo，再加2张贴纸，1张Hu贴纸（条码贴），1张ASN贴纸（尺寸6.5cm*6.3cm,潘通色号2597C），都贴于侧唛，只需贴1面(HU贴纸和ASN贴 纸客供） 2. 一个外箱对应一个HU’S(条形码),不可以混条码包装 3.含有说明书需要增加说明书贴纸 4.价格贴纸覆盖原有包装的条形码 Remark: 此单有监柜要求，需要每款多准备一套完整物料，用于监柜，不可以随大货走 | V26: Ever Li | W26: 0.9931 | X26: =W26*I26 -> 476.688 | Y26: 95265-6.11 | Z26: 480 | AA26: 0 | AD26: 77593GQ2-S001-3L | AE26: 已入 | AF26: =I26 -> 480 | AH26: =I26 -> 480 | AI26: =I26 -> 480 | AM26: =I26/24 -> 20 | AX26: =I26 -> 480 | BA26: =I26*$BA$2 -> 60 | BB26: =I26*$BB$2 -> 50 | BC26: =I26*$BC$2 -> 10 | BD26: =I26*$BD$2 -> 60 | BE26: =I26*$BE$2 -> 60 | BF26: =I26*$BF$2 -> 60 | BG26: =I26*$BG$2 -> 60 | BH26: =I26*$BH$2 -> 60 | BI26: =I26*$BI$2 -> 60 | BK26: =BK25-BA26 -> 5202.75 | BL26: =BL25-BB26 -> 4512.125 | BM26: =BM25-BD26 -> 5215.75 | BN26: =BN25-BC26 -> 777.625 | BO26: =BO25-BE26 -> 3337.75 | BP26: =BP25-BF26 -> 5215.75 | BQ26: =BQ25-BG26 -> 5215.75 | BR26: =BR25-BH26 -> 5615.75 | BS26: =BS25-BI26 -> 5215.75
A27: 45792 | B27: Sirius Sales (PTY) Ltd | C27: 南非 | D27: 4500166516 | F27: 4500166516-20 | G27: 77593GQ2-S001 | H27: S4迷你恐龙24PCS入GQ2*2/箱 | I27: 2400 | J27: 0 | K27: 48 | L27: =I27/K27 -> 50 | M27: 45838 | N27: 45834 | P27: pass | Q27: 7/1 入仓 | R27: 45796 | S27: 无 | T27: 无 | U27: 日期码格式：ZURU INC(BVI) 标准格式 日期：按实际生产日期 Packaging Info: 1. MA UPC PKG(优先1L) Remark: | V27: Doris Shou | W27: 0.9892 | X27: =W27*I27 -> 2374.08 | Y27: 95520-7.1 | Z27: =2352+48 -> 2400 | AA27: =Z27-I27 -> 0 | AD27: 77593GQ2-S001 | AE27: 已入 | AF27: =I27 -> 2400 | AG27: =I27 -> 2400 | AI27: =I27 -> 2400 | AL27: =I27/24 -> 100 | AX27: =I27 -> 2400 | BA27: =I27*$BA$2 -> 300 | BB27: =I27*$BB$2 -> 250 | BC27: =I27*$BC$2 -> 50 | BD27: =I27*$BD$2 -> 300 | BE27: =I27*$BE$2 -> 300 | BF27: =I27*$BF$2 -> 300 | BG27: =I27*$BG$2 -> 300 | BH27: =I27*$BH$2 -> 300 | BI27: =I27*$BI$2 -> 300 | BK27: =BK26-BA27 -> 4902.75 | BL27: =BL26-BB27 -> 4262.125 | BM27: =BM26-BD27 -> 4915.75 | BN27: =BN26-BC27 -> 727.625 | BO27: =BO26-BE27 -> 3037.75 | BP27: =BP26-BF27 -> 4915.75 | BQ27: =BQ26-BG27 -> 4915.75 | BR27: =BR26-BH27 -> 5315.75 | BS27: =BS26-BI27 -> 4915.75
A28: 45803 | B28: Hermanex Europe BV | C28: 荷兰 | D28: 4500167892 | E28: 91-21747 | F28: 4500167892-10 | G28: 77593SK-S002 | H28: S4迷你恐龙展示架带球 | I28: 7440 | J28: 0 | K28: 60 | L28: =I28/K28 -> 124 | M28: 45839 | N28: =M28-4 -> 45835 | P28: pass | Q28: 7/5 送外厂 | R28: 45803 | S28: 无 | T28: 6/4 NL警语贴纸 | U28: 日期码格式：ZURU INC(BVI) 标准格式 日期：按实际生产日期 Packaging Info: 77593SK-S002: MA A版3L EAN收缩膜+NL警语贴纸，MA A版 5L slime polybag+NL警语贴纸，MA A版 5L收藏指南，MA A版1L带Base展架（消耗slow moving库存） Remark: 1.出欧洲荷兰，须符合欧洲微塑料法规（如item本身不含微塑料，则忽略此要求） 2.条码 4894680034709 | V28: Nicole Ye | W28: 70.3426 | X28: =W28*L28 -> 8722.4824 | Y28: 95578-7.7 | Z28: 7440 | AA28: 0 | AD28: 77593SK-S002-3L | AE28: 已入 | AF28: =I28 -> 7440 | AH28: =I28 -> 7440 | AI28: =AH28 -> 7440 | AJ28: =L28 -> 124 | AK28: =AJ28 -> 124 | AX28: =I28 -> 7440 | BA28: =I28*$BA$2 -> 930 | BB28: =I28*$BB$2 -> 775 | BC28: =I28*$BC$2 -> 155 | BD28: =I28*$BD$2 -> 930 | BE28: =I28*$BE$2 -> 930 | BF28: =I28*$BF$2 -> 930 | BG28: =I28*$BG$2 -> 930 | BH28: =I28*$BH$2 -> 930 | BI28: =I28*$BI$2 -> 930 | BK28: =BK27-BA28 -> 3972.75 | BL28: =BL27-BB28 -> 3487.125 | BM28: =BM27-BD28 -> 3985.75 | BN28: =BN27-BC28 -> 572.625 | BO28: =BO27-BE28 -> 2107.75 | BP28: =BP27-BF28 -> 3985.75 | BQ28: =BQ27-BG28 -> 3985.75 | BR28: =BR27-BH28 -> 4385.75 | BS28: =BS27-BI28 -> 3985.75
A29: 45834 | B29: TJX CANADA | C29: 加拿大 | D29: 4500171335 | E29: 40276731 40276790 | F29: 4500171335-140 | G29: 77593GQ2-S002-NB | H29: S4迷你恐龙24PCS入GQ2*2/箱 | I29: 912 | J29: 0 | K29: 24 | L29: =I29/K29 -> 38 | M29: 45870 | N29: =M29-4 -> 45866 | P29: 自检 | Q29: 8/4 截SI | R29: 45835 | S29: 无 | T29: 6/26 UPC 贴纸+7/16客供价格贴 | U29: 日期码格式：ZURU INC(BVI) 标准格式 日期：按实际生产日期 Packaging Info: 77593GQ2 无硼版本， 标版多语包装/说明书+多语PDQ , 加UPC 贴纸， UPC 193052066206 Remark: 出加拿大 有客供价格贴 每行对应不同的客户PO，唛头要一一对应， 放唛头时跟单会提供清单 Zuru验货.日期跟踪码：产品外包装及产品本身都必须有日期跟踪码，ZURU标准格式 日期码 | V29: Summer Mo | W29: 0.9892 | X29: =W29*I29 -> 902.1504 | Y29: 95906-8.4 | Z29: =888+24 -> 912 | AA29: =Z29-I29 -> 0 | AD29: 77593GQ2-S002-NB | AE29: 已入 | AF29: =I29 -> 912 | AH29: =I29 -> 912 | AI29: =I29 -> 912 | AM29: =I29/24 -> 38 | AY29: =I29 -> 912 | BA29: =I29*$BA$2 -> 114 | BB29: =I29*$BB$2 -> 95 | BC29: =I29*$BC$2 -> 19 | BD29: =I29*$BD$2 -> 114 | BE29: =I29*$BE$2 -> 114 | BF29: =I29*$BF$2 -> 114 | BG29: =I29*$BG$2 -> 114 | BH29: =I29*$BH$2 -> 114 | BI29: =I29*$BI$2 -> 114 | BK29: =BK28-BA29 -> 3858.75 | BL29: =BL28-BB29 -> 3392.125 | BM29: =BM28-BD29 -> 3871.75 | BN29: =BN28-BC29 -> 553.625 | BO29: =BO28-BE29 -> 1993.75 | BP29: =BP28-BF29 -> 3871.75 | BQ29: =BQ28-BG29 -> 3871.75 | BR29: =BR28-BH29 -> 4271.75 | BS29: =BS28-BI29 -> 3871.75
A30: 45834 | B30: TJX CANADA | C30: 加拿大 | D30: 4500171335 | E30: 40276731 40276790 | F30: 4500171335-240 | G30: 77593GQ2-S002-NB | H30: S4迷你恐龙24PCS入GQ2*2/箱 | I30: 288 | J30: 0 | K30: 24 | L30: =I30/K30 -> 12 | M30: 45870 | N30: =M30-4 -> 45866 | P30: 自检 | Q30: 8/4 截SI | R30: 45835 | S30: 无 | T30: 6/26 UPC 贴纸+7/16客供价格贴 | U30: 日期码格式：ZURU INC(BVI) 标准格式 日期：按实际生产日期 Packaging Info: 77593GQ2 无硼版本， 标版多语包装/说明书+多语PDQ , 加UPC 贴纸， UPC 193052066206 Remark: 出加拿大 有客供价格贴 每行对应不同的客户PO，唛头要一一对应， 放唛头时跟单会提供清单 Zuru验货.日期跟踪码：产品外包装及产品本身都必须有日期跟踪码，ZURU标准格式 日期码 | V30: Summer Mo | W30: 0.9708 | X30: =W30*I30 -> 279.5904 | Y30: 95906-8.4 | Z30: =240+48 -> 288 | AA30: =Z30-I30 -> 0 | AD30: 77593GQ2-S002-NB | AE30: 已入 | AF30: =I30 -> 288 | AH30: =I30 -> 288 | AI30: =I30 -> 288 | AM30: =I30/24 -> 12 | AY30: =I30 -> 288 | BA30: =I30*$BA$2 -> 36 | BB30: =I30*$BB$2 -> 30 | BC30: =I30*$BC$2 -> 6 | BD30: =I30*$BD$2 -> 36 | BE30: =I30*$BE$2 -> 36 | BF30: =I30*$BF$2 -> 36 | BG30: =I30*$BG$2 -> 36 | BH30: =I30*$BH$2 -> 36 | BI30: =I30*$BI$2 -> 36 | BK30: =BK29-BA30 -> 3822.75 | BL30: =BL29-BB30 -> 3362.125 | BM30: =BM29-BD30 -> 3835.75 | BN30: =BN29-BC30 -> 547.625 | BO30: =BO29-BE30 -> 1957.75 | BP30: =BP29-BF30 -> 3835.75 | BQ30: =BQ29-BG30 -> 3835.75 | BR30: =BR29-BH30 -> 4235.75 | BS30: =BS29-BI30 -> 3835.75
A31: 45834 | B31: TJX CANADA | C31: 加拿大 | D31: 4500171335 | E31: 40276731 40276790 | F31: 4500171335-330 | G31: 77593GQ2-S002-NB | H31: S4迷你恐龙24PCS入GQ2*2/箱 | I31: 1080 | J31: 0 | K31: 24 | L31: =I31/K31 -> 45 | M31: 45870 | N31: =M31-4 -> 45866 | P31: 自检 | Q31: 8/4 截SI | R31: 45835 | S31: 无 | T31: 6/26 UPC 贴纸+7/16客供价格贴 | U31: 日期码格式：ZURU INC(BVI) 标准格式 日期：按实际生产日期 Packaging Info: 77593GQ2 无硼版本， 标版多语包装/说明书+多语PDQ , 加UPC 贴纸， UPC 193052066206 Remark: 出加拿大 有客供价格贴 每行对应不同的客户PO，唛头要一一对应， 放唛头时跟单会提供清单 Zuru验货.日期跟踪码：产品外包装及产品本身都必须有日期跟踪码，ZURU标准格式 日期码 | V31: Summer Mo | W31: 0.9708 | X31: =W31*I31 -> 1048.464 | Y31: 95906-8.4 | Z31: 1080 | AA31: =Z31-I31 -> 0 | AD31: 77593GQ2-S002-NB | AE31: 已入 | AF31: =I31 -> 1080 | AH31: =I31 -> 1080 | AI31: =I31 -> 1080 | AM31: =I31/24 -> 45 | AY31: =I31 -> 1080 | BA31: =I31*$BA$2 -> 135 | BB31: =I31*$BB$2 -> 112.5 | BC31: =I31*$BC$2 -> 22.5 | BD31: =I31*$BD$2 -> 135 | BE31: =I31*$BE$2 -> 135 | BF31: =I31*$BF$2 -> 135 | BG31: =I31*$BG$2 -> 135 | BH31: =I31*$BH$2 -> 135 | BI31: =I31*$BI$2 -> 135 | BK31: =BK30-BA31 -> 3687.75 | BL31: =BL30-BB31 -> 3249.625 | BM31: =BM30-BD31 -> 3700.75 | BN31: =BN30-BC31 -> 525.125 | BO31: =BO30-BE31 -> 1822.75 | BP31: =BP30-BF31 -> 3700.75 | BQ31: =BQ30-BG31 -> 3700.75 | BR31: =BR30-BH31 -> 4100.75 | BS31: =BS30-BI31 -> 3700.75
A32: 45834 | B32: TJX CANADA | C32: 加拿大 | D32: 4500171335 | E32: 40276731 40276790 | F32: 4500171335-420 | G32: 77593GQ2-S002-NB | H32: S4迷你恐龙24PCS入GQ2*2/箱 | I32: 384 | J32: 0 | K32: 24 | L32: =I32/K32 -> 16 | M32: 45870 | N32: =M32-4 -> 45866 | P32: 自检 | Q32: 8/4 截SI | R32: 45835 | S32: 无 | T32: 6/26 UPC 贴纸+7/16客供价格贴 | U32: 日期码格式：ZURU INC(BVI) 标准格式 日期：按实际生产日期 Packaging Info: 77593GQ2 无硼版本， 标版多语包装/说明书+多语PDQ , 加UPC 贴纸， UPC 193052066206 Remark: 出加拿大 有客供价格贴 每行对应不同的客户PO，唛头要一一对应， 放唛头时跟单会提供清单 Zuru验货.日期跟踪码：产品外包装及产品本身都必须有日期跟踪码，ZURU标准格式 日期码 | V32: Summer Mo | W32: 0.9892 | X32: =W32*I32 -> 379.8528 | Y32: 95906-8.4 | Z32: 384 | AA32: =Z32-I32 -> 0 | AD32: 77593GQ2-S002-NB | AE32: 已入 | AF32: =I32 -> 384 | AH32: =I32 -> 384 | AI32: =I32 -> 384 | AM32: =I32/24 -> 16 | AY32: =I32 -> 384 | BA32: =I32*$BA$2 -> 48 | BB32: =I32*$BB$2 -> 40 | BC32: =I32*$BC$2 -> 8 | BD32: =I32*$BD$2 -> 48 | BE32: =I32*$BE$2 -> 48 | BF32: =I32*$BF$2 -> 48 | BG32: =I32*$BG$2 -> 48 | BH32: =I32*$BH$2 -> 48 | BI32: =I32*$BI$2 -> 48 | BK32: =BK31-BA32 -> 3639.75 | BL32: =BL31-BB32 -> 3209.625 | BM32: =BM31-BD32 -> 3652.75 | BN32: =BN31-BC32 -> 517.125 | BO32: =BO31-BE32 -> 1774.75 | BP32: =BP31-BF32 -> 3652.75 | BQ32: =BQ31-BG32 -> 3652.75 | BR32: =BR31-BH32 -> 4052.75 | BS32: =BS31-BI32 -> 3652.75
A33: 45834 | B33: TJX CANADA | C33: 加拿大 | D33: 4500171335 | E33: 40276731 40276790 | F33: 4500171335-510 | G33: 77593GQ2-S002-NB | H33: S4迷你恐龙24PCS入GQ2*2/箱 | I33: 408 | J33: 0 | K33: 24 | L33: =I33/K33 -> 17 | M33: 45870 | N33: =M33-4 -> 45866 | P33: 自检 | Q33: 8/4 截SI | R33: 45835 | S33: 无 | T33: 6/26 UPC 贴纸+7/16客供价格贴 | U33: 日期码格式：ZURU INC(BVI) 标准格式 日期：按实际生产日期 Packaging Info: 77593GQ2 无硼版本， 标版多语包装/说明书+多语PDQ , 加UPC 贴纸， UPC 193052066206 Remark: 出加拿大 有客供价格贴 每行对应不同的客户PO，唛头要一一对应， 放唛头时跟单会提供清单 Zuru验货.日期跟踪码：产品外包装及产品本身都必须有日期跟踪码，ZURU标准格式 日期码 | V33: Summer Mo | W33: 0.9892 | X33: =W33*I33 -> 403.5936 | Y33: 95906-8.4 | Z33: 408 | AA33: =Z33-I33 -> 0 | AD33: 77593GQ2-S002-NB | AE33: 已入 | AF33: =I33 -> 408 | AH33: =I33 -> 408 | AI33: =I33 -> 408 | AM33: =I33/24 -> 17 | AY33: =I33 -> 408 | BA33: =I33*$BA$2 -> 51 | BB33: =I33*$BB$2 -> 42.5 | BC33: =I33*$BC$2 -> 8.5 | BD33: =I33*$BD$2 -> 51 | BE33: =I33*$BE$2 -> 51 | BF33: =I33*$BF$2 -> 51 | BG33: =I33*$BG$2 -> 51 | BH33: =I33*$BH$2 -> 51 | BI33: =I33*$BI$2 -> 51 | BK33: =BK32-BA33 -> 3588.75 | BL33: =BL32-BB33 -> 3167.125 | BM33: =BM32-BD33 -> 3601.75 | BN33: =BN32-BC33 -> 508.625 | BO33: =BO32-BE33 -> 1723.75 | BP33: =BP32-BF33 -> 3601.75 | BQ33: =BQ32-BG33 -> 3601.75 | BR33: =BR32-BH33 -> 4001.75 | BS33: =BS32-BI33 -> 3601.75
A34: 45834 | B34: TJX CANADA | C34: 加拿大 | D34: 4500171342 | E34: 40279125 45276449 | F34: 4500171342-70 | G34: 77593GQ2-S002-NB | H34: S4迷你恐龙24PCS入GQ2*2/箱 | I34: 144 | J34: 0 | K34: 24 | L34: =I34/K34 -> 6 | M34: 45870 | N34: =M34-4 -> 45866 | P34: 自检 | Q34: 8/4 截SI | R34: 45835 | S34: 无 | T34: 6/26 UPC 贴纸+7/16客供价格贴 | U34: 日期码格式：ZURU INC(BVI) 标准格式 日期：按实际生产日期 Packaging Info: 77593GQ2 无硼版本， 标版多语包装/说明书+多语PDQ , 加UPC 贴纸， UPC 193052066206 Remark: 出加拿大 有客供价格贴 每行对应不同的客户PO，唛头要一一对应， 放唛头时跟单会提供清单 Zuru验货.日期跟踪码：产品外包装及产品本身都必须有日期跟踪码，ZURU标准格式 日期码 | V34: Summer Mo | W34: 0.9931 | X34: =W34*I34 -> 143.0064 | Y34: 96596-8.4 | Z34: 144 | AA34: =Z34-I34 -> 0 | AD34: 77593GQ2-S002-NB | AE34: 已入 | AF34: =I34 -> 144 | AH34: =I34 -> 144 | AI34: =I34 -> 144 | AM34: =I34/24 -> 6 | AY34: =I34 -> 144 | BA34: =I34*$BA$2 -> 18 | BB34: =I34*$BB$2 -> 15 | BC34: =I34*$BC$2 -> 3 | BD34: =I34*$BD$2 -> 18 | BE34: =I34*$BE$2 -> 18 | BF34: =I34*$BF$2 -> 18 | BG34: =I34*$BG$2 -> 18 | BH34: =I34*$BH$2 -> 18 | BI34: =I34*$BI$2 -> 18 | BK34: =BK33-BA34 -> 3570.75 | BL34: =BL33-BB34 -> 3152.125 | BM34: =BM33-BD34 -> 3583.75 | BN34: =BN33-BC34 -> 505.625 | BO34: =BO33-BE34 -> 1705.75 | BP34: =BP33-BF34 -> 3583.75 | BQ34: =BQ33-BG34 -> 3583.75 | BR34: =BR33-BH34 -> 3983.75 | BS34: =BS33-BI34 -> 3583.75
A35: 45838 | B35: NASA PANAMA | C35: 巴拿马 | D35: 4500172103 | F35: 4500172103-160 | G35: 77593GQ2-S001 | H35: S4迷你恐龙24PCS入GQ2*2/箱 | I35: 528 | J35: 0 | K35: 48 | L35: =I35/K35 -> 11 | M35: 45874 | N35: 45870 | P35: 自检 | Q35: 8/14 截SI | R35: 45845 | S35: 无 | T35: 7/25 UPC | U35: 日期码格式：ZURU INC(BVI) 标准格式 日期：按实际生产日期 Packaging Info: 请确保包装上的条形码是UPC，如果是babyUPC，需要用mother UPC覆盖，如有不一致，请及时提出。谢谢! 77593GQ2: MA多语EAN 包装+MA 多语PDQ+UPC贴纸+ MA多语说明书+箱唛 Remark: | V35: Aimee Huang | W35: 0.9892 | X35: =W35*I35 -> 522.2976 | Y35: 96595-4-9.30 | Z35: 528 | AA35: =Z35-I35 -> 0 | AD35: 77593GQ2-S001-3L | AE35: 已入 | AF35: =I35 -> 528 | AH35: =I35 -> 528 | AI35: =I35 -> 528 | AM35: =I35/24 -> 22 | AX35: =I35 -> 528 | BA35: =I35*$BA$2 -> 66 | BB35: =I35*$BB$2 -> 55 | BC35: =I35*$BC$2 -> 11 | BD35: =I35*$BD$2 -> 66 | BE35: =I35*$BE$2 -> 66 | BF35: =I35*$BF$2 -> 66 | BG35: =I35*$BG$2 -> 66 | BH35: =I35*$BH$2 -> 66 | BI35: =I35*$BI$2 -> 66 | BK35: =BK34-BA35 -> 3504.75 | BL35: =BL34-BB35 -> 3097.125 | BM35: =BM34-BD35 -> 3517.75 | BN35: =BN34-BC35 -> 494.625 | BO35: =BO34-BE35 -> 1639.75 | BP35: =BP34-BF35 -> 3517.75 | BQ35: =BQ34-BG35 -> 3517.75 | BR35: =BR34-BH35 -> 3917.75 | BS35: =BS34-BI35 -> 3517.75
A36: 45841 | B36: HOBBY LOBBY STORES, INC. | C36: 美国 | D36: 4500171299 | E36: W0726956 | F36: 4500171299-20 | G36: 77593GQ1-S001 | H36: S4迷你恐龙13PCS/GQ1*4 | I36: 1820 | J36: 0 | K36: 52 | L36: =I36/K36 -> 35 | M36: 45882 | N36: 45882 | P36: pass | Q36: 8/20 截SI | R36: 45841 | S36: 有 | T36: 7/3价格贴纸+外箱条码贴纸 | U36: 日期码格式：ZURU INC(BVI) 标准格式 日期：按实际生产日期 Packaging Info: 1. MA UPC版包装，优先1L，需要加贴价格贴纸, 贴在产品包装正面右上角(价格贴纸文档跟单提供)，出美国。 2. 外箱正唛(2面)右下角贴条码贴纸各贴1张(即1面1张共2张),贴纸大小：2.75 x 1.5 inch。(跟单提供文档，工厂采购) Remark: 1. 产品外包装及产品本身都必须有日期跟踪码，格式为：ZURU 标准日期码。 2. ZURU QC验货，无测试。 3. 产品配比按照MA标准配比执行。 | V36: Yvonne Feng | W36: 0.5759 | X36: =W36*I36 -> 1048.138 | Y36: ZB01390-8.21 | Z36: 1820 | AA36: =Z36-I36 -> 0 | AD36: 77593GQ1-S001 | AE36: 已入 | AF36: =I36 -> 1820 | AG36: =AF36 -> 1820 | AI36: =I36 -> 1820 | AN36: =I36/13 -> 140 | AX36: =I36 -> 1820 | BA36: =I36*$BA$2 -> 227.5 | BB36: =I36*$BB$2 -> 189.58333 | BC36: =I36*$BC$2 -> 37.916667 | BD36: =I36*$BD$2 -> 227.5 | BE36: =I36*$BE$2 -> 227.5 | BF36: =I36*$BF$2 -> 227.5 | BG36: =I36*$BG$2 -> 227.5 | BH36: =I36*$BH$2 -> 227.5 | BI36: =I36*$BI$2 -> 227.5 | BK36: =BK35-BA36 -> 3277.25 | BL36: =BL35-BB36 -> 2907.5417 | BM36: =BM35-BD36 -> 3290.25 | BN36: =BN35-BC36 -> 456.70833 | BO36: =BO35-BE36 -> 1412.25 | BP36: =BP35-BF36 -> 3290.25 | BQ36: =BQ35-BG36 -> 3290.25 | BR36: =BR35-BH36 -> 3690.25 | BS36: =BS35-BI36 -> 3290.25
A37: 45825 | B37: DISTRIBUIDORA COMERCIAL DEL NORTE | C37: 厄瓜多尔 | D37: 4500170167 | E37: 2025-0893 | F37: 4500170167-90 | G37: 77593GQ2-S001 | H37: S4迷你恐龙24PCS入GQ2*2/箱 | I37: 2016 | J37: 0 | K37: 48 | L37: =I37/K37 -> 42 | M37: 45891 | N37: 45887 | P37: 自检 | Q37: 8/24 截SI | R37: 45827 | S37: 无 | T37: 7/23进口商贴纸+Mother UPC贴纸 | U37: 日期码格式：ZURU INC(BVI) 标准格式 日期：按实际生产日期 Packaging Info: 77593GQ2:MA 多语 EAN 包装+Mother UPC贴纸+MA 多语PDQ+MA多语说明书+进口商贴纸+箱唛 Mother UPC：193052074867 Remark: ; | V37: Ava Liang | W37: 0.9708 | X37: =W37*I37 -> 1957.1328 | Y37: 96147-2-8.25 | Z37: =1968+48 -> 2016 | AA37: =Z37-I37 -> 0 | AD37: 77593GQ2-S001-3L | AE37: 已入 | AF37: =I37 -> 2016 | AH37: =I37 -> 2016 | AI37: =I37 -> 2016 | AM37: =I37/24 -> 84 | AX37: =I37 -> 2016 | BA37: =I37*$BA$2 -> 252 | BB37: =I37*$BB$2 -> 210 | BC37: =I37*$BC$2 -> 42 | BD37: =I37*$BD$2 -> 252 | BE37: =I37*$BE$2 -> 252 | BF37: =I37*$BF$2 -> 252 | BG37: =I37*$BG$2 -> 252 | BH37: =I37*$BH$2 -> 252 | BI37: =I37*$BI$2 -> 252 | BK37: =BK36-BA37 -> 3025.25 | BL37: =BL36-BB37 -> 2697.5417 | BM37: =BM36-BD37 -> 3038.25 | BN37: =BN36-BC37 -> 414.70833 | BO37: =BO36-BE37 -> 1160.25 | BP37: =BP36-BF37 -> 3038.25 | BQ37: =BQ36-BG37 -> 3038.25 | BR37: =BR36-BH37 -> 3438.25 | BS37: =BS36-BI37 -> 3038.25
A38: 45889 | B38: HOBBY LOBBY STORES, INC. | C38: 美国 | D38: 4500176896 | E38: W0734381 | F38: 4500176896-20 | G38: 77593GQ1-S001 | H38: S4迷你恐龙13PCS/GQ1*4 | I38: 2860 | J38: 0 | K38: 52 | L38: =I38/K38 -> 55 | M38: 45923 | N38: 45919 | P38: pass | R38: 45889 | S38: 有 | T38: 8/20价格贴纸+外箱条码贴纸 | U38: 日期码格式：ZURU INC(BVI) 标准格式 日期：按实际生产日期 Packaging Info: 1. MA UPC版包装，优先1L，需要加贴价格贴纸, 贴在产品包装正面右上角(价格贴纸文档跟单提供)，出美国。 2. 外箱正唛(2面)右下角贴条码贴纸各贴1张(即1面1张共2张),贴纸大小：2.75 x 1.5 inch。(跟单提供文档，工厂采购) Remark: 1. 产品外包装及产品本身都必须有日期跟踪码，格式为：ZURU 标准日期码。 2. ZURU QC验货，无测试。 3. 产品配比按照MA标准配比执行。 | V38: Yvonne Feng | W38: 0.5759 | X38: =W38*I38 -> 1647.074 | Y38: ZB02550-10.22 | Z38: =2808+52 -> 2860 | AA38: =Z38-I38 -> 0 | AD38: 77593GQ1-S001 | AE38: 已入 | AF38: =I38 -> 2860 | AG38: =AF38 -> 2860 | AI38: =I38 -> 2860 | AN38: =I38/13 -> 220 | AX38: =I38 -> 2860 | BA38: =I38*$BA$2 -> 357.5 | BB38: =I38*$BB$2 -> 297.91667 | BC38: =I38*$BC$2 -> 59.583333 | BD38: =I38*$BD$2 -> 357.5 | BE38: =I38*$BE$2 -> 357.5 | BF38: =I38*$BF$2 -> 357.5 | BG38: =I38*$BG$2 -> 357.5 | BH38: =I38*$BH$2 -> 357.5 | BI38: =I38*$BI$2 -> 357.5 | BK38: =BK37-BA38 -> 2667.75 | BL38: =BL37-BB38 -> 2399.625 | BM38: =BM37-BD38 -> 2680.75 | BN38: =BN37-BC38 -> 355.125 | BO38: =BO37-BE38 -> 802.75 | BP38: =BP37-BF38 -> 2680.75 | BQ38: =BQ37-BG38 -> 2680.75 | BR38: =BR37-BH38 -> 3080.75 | BS38: =BS37-BI38 -> 2680.75
A39: 45918 | B39: HOBBY LOBBY STORES, INC. | C39: 美国 | D39: 4500179747 | E39: W0738938 | F39: 4500179747-20 | G39: 77593GQ1-S001 | H39: S4迷你恐龙13PCS/GQ1*4 | I39: 5200 | J39: 0 | K39: 52 | L39: =I39/K39 -> 100 | M39: 45958 | N39: 45954 | P39: pass | Q39: 11/6 截SI | R39: 45926 | S39: 有 | T39: 9/28价格贴纸+外箱条码贴纸 | U39: 日期码格式：ZURU INC(BVI) 标准格式 日期：按实际生产日期 Packaging Info: 1. MA UPC版包装，优先1L，需要加贴价格贴纸, 贴在产品包装正面右上角(价格贴纸文档跟单提供)，出美国。 2. 外箱正唛(2面)右下角贴条码贴纸各贴1张(即1面1张共2张),贴纸大小：2.75 x 1.5 inch。(跟单提供文档，工厂采购) Remark: 1. 产品外包装及产品本身都必须有日期跟踪码，格式为：ZURU 标准日期码。 2. ZURU QC验货，无测试。 3. 产品配比按照MA标准配比执行。 | V39: Yvonne Feng | W39: 0.5675 | X39: =W39*I39 -> 2951 | Y39: ZB03096-11.25 | Z39: =5096+104 -> 5200 | AA39: =Z39-I39 -> 0 | AD39: 77593GQ1-S001 | AE39: 已入 | AF39: =I39 -> 5200 | AG39: =AF39 -> 5200 | AI39: =I39 -> 5200 | AN39: =I39/13 -> 400 | AX39: =I39 -> 5200 | BA39: =I39*$BA$2 -> 650 | BB39: =I39*$BB$2 -> 541.66667 | BC39: =I39*$BC$2 -> 108.33333 | BD39: =I39*$BD$2 -> 650 | BE39: =I39*$BE$2 -> 650 | BF39: =I39*$BF$2 -> 650 | BG39: =I39*$BG$2 -> 650 | BH39: =I39*$BH$2 -> 650 | BI39: =I39*$BI$2 -> 650 | BK39: =BK38-BA39 -> 2017.75 | BL39: =BL38-BB39 -> 1857.9583 | BM39: =BM38-BD39 -> 2030.75 | BN39: =BN38-BC39 -> 246.79167 | BO39: =BO38-BE39 -> 152.75 | BP39: =BP38-BF39 -> 2030.75 | BQ39: =BQ38-BG39 -> 2030.75 | BR39: =BR38-BH39 -> 2430.75 | BS39: =BS38-BI39 -> 2030.75
A40: 45922 | B40: ROFU KINDERLAND SPIELWARENHANDELSGE | C40: 德国 | D40: 4500180040 | E40: 249680 | F40: 4500180040-10 | G40: 77593-S001-NB | H40: S4迷你恐龙24PCS入GQ2/箱 | I40: 5760 | J40: 0 | K40: 24 | L40: =I40/K40 -> 240 | M40: 45968 | N40: 45964 | P40: pass | Q40: 11/11 截SI | R40: 45940 | S40: 无 | T40: 11/17客供价格贴纸 | U40: 日期码格式：ZURU INC(BVI) 标准格式 日期：按实际生产日期 Packaging Info: 77593-S001(需更改无硼版本): 最新MA 3L+5LEAN包装+客供价格贴纸+5L警语收藏指南+5L Slime 袋 Remark: "1. 出口欧洲，微塑料需符合法规； 2. 所有电子产品身上需要加字唛，为ZURU FRANCE 地址 (如无电子产品/产品布标有此地址/产品太小无法增加，可忽略此信息) ZURU FRANCE 33 rue Paul Meurice 75020 Paris, France. 3. 所有出往德国订单的电子产品需增加一张客版WEEE声明说明书，区分带电池(WEEE 带电池走货 通用30L 说明书)和不带电池版本(WEEE 不带电池走货 通用30L 说 明书) 4. 此单需要在CRD前一天预约ZURU QC验货提供验货图片给客户确认才能出货 5. 需准时完成生产，推期出货会有罚款。 6. 此客户要求含布标的毛绒公仔，需要额外贴一张布标贴纸，区分电子产品（带电布标贴纸)和非电子产品(不带电布标贴纸)" | V40: Winnie zhong | W40: 0.9005 | X40: =W40*I40 -> 5186.88 | Y40: 96946-11.15 | Z40: 5760 | AA40: 0 | AD40: 77593-S001-NB | AE40: 已入 | AF40: =I40 -> 5760 | AH40: =I40 -> 5760 | AI40: =I40 -> 5760 | AO40: =I40/24 -> 240 | AY40: =I40 -> 5760 | BA40: =I40*$BA$2 -> 720 | BB40: =I40*$BB$2 -> 600 | BC40: =I40*$BC$2 -> 120 | BD40: =I40*$BD$2 -> 720 | BE40: =I40*$BE$2 -> 720 | BF40: =I40*$BF$2 -> 720 | BG40: =I40*$BG$2 -> 720 | BH40: =I40*$BH$2 -> 720 | BI40: =I40*$BI$2 -> 720 | BK40: =BK39-BA40 -> 1297.75 | BL40: =BL39-BB40 -> 1257.9583 | BM40: =BM39-BD40 -> 1310.75 | BN40: =BN39-BC40 -> 126.79167 | BO40: =BO39-BE40 -> -567.25 | BP40: =BP39-BF40 -> 1310.75 | BQ40: =BQ39-BG40 -> 1310.75 | BR40: =BR39-BH40 -> 1710.75 | BS40: =BS39-BI40 -> 1310.75
...

Sheet 77593 
A1: ZURU 5 surprise Dino S6（恐龙系列）生产排期表 #77489 | I1: 1.球壳 转为95mm 2半球壳 ,材料：20%PCR PP +80%PP原料 2.因考虑到某些地区对微塑胶（闪粉，闪粉喷油等）的限制，内部产品会同步做以下变更：---Slime 取消闪粉 3.更改为95mm 球壳后款号更新，请参考以下款号 4.PDQ，SK 刀线均有变化（请留意部分会带有demo）GQ2/SK/SK1有demo | AJ1: 普通款暴龙+卡车 | AL1: 双刺龙 | AR1: 普通款暴龙
I2: 欧洲国家有: (共有43个国家组成) 。芬兰、瑞典、挪威、冰岛、丹麦 法罗群岛(丹)、爱沙尼亚、拉脱维亚、立陶宛、白俄罗斯、俄罗斯、乌克兰、摩尔多瓦、波兰、捷克、斯洛伐克、匈牙利、德国、奥地利、瑞士、列支敦士登、英国、爱尔兰、荷兰、比利时、卢森堡、法国、摩纳哥、罗马尼亚、保加利亚、塞尔维亚、马其顿、阿尔巴尼亚、希腊、斯洛文尼亚、克罗地亚、波斯尼亚和墨塞哥维那、意大利、梵蒂冈、圣马力诺、马耳他、西班牙、葡萄牙、安道尔。 | AG2: 95MM收縮膜 | AI2: 95MM收藏指南 | AJ2: SK展示架 | AK2: 带底座 | AL2: 77593GQ2 | AN2: 77593GQ1 | AP2: 77593GQ5 | AQ2: SK1展示架 | AT2: 77614 2PK圆筒 | AW2: WM GQ4 | AX2: 口水胶 | AZ2: MA比例 | BA2: 0.125 | BB2: 0.10416667 | BC2: 0.020833333 | BD2: 0.125 | BE2: 0.125 | BF2: 0.125 | BG2: 0.125 | BH2: 0.125 | BI2: 0.125 | BJ2: MA | BK2: ='77489 77593生产MA'!E15-BA15-BA17-'77489 77593生产MA'!I29-BA19 -> 1297.75 | BL2: ='77489 77593生产MA'!F15-BB15-BB17-'77489 77593生产MA'!I30-'77489 77593生产MA'!I31-'77489 77593生产MA'!J33-'77489 77593生产MA'!K33-'77489 77593生产MA'!J35-'77489 77593生产MA'!K35-BB19 -> 1257.9583 | BM2: ='77489 77593生产MA'!G15-BD17-BD15-BD19 -> 1310.75 | BN2: ='77489 77593生产MA'!H15-BC17-BC15-BC19 -> 126.79167 | BO2: ='77489 77593生产MA'!I15-BE15-BE17-'77489 77593生产MA'!J34-'77489 77593生产MA'!K34-BE19 -> -567.25 | BP2: ='77489 77593生产MA'!J15-BF15-BF17-BF19 -> 1310.75 | BQ2: ='77489 77593生产MA'!K15-BG15-BG17-BG19 -> 1310.75 | BR2: ='77489 77593生产MA'!L15-BH15-BH17-'77489 77593生产MA'!K32-'77489 77593生产MA'!J32-BH19 -> 1710.75 | BS2: ='77489 77593生产MA'!M15-BI15-BI17-BI19 -> 1310.75
A3: 香港接单日期 | B3: 第三方客户名称 | C3: 走货国家 | D3: ZURU PO NO# | E3: 第三方客户 PO NO# | F3: SKU | G3: ITEM# | H3: 中文名 | I3: PO数量 (pcs) | J3: 内箱装箱数量(pcs) | K3: 外箱装箱数量(pcs) | L3: 总箱数 | M3: 客PO期 | N3: 验货期 | O3: 第三方验货期 | P3: 验货结果 | Q3: 船期 | R3: 箱唛资料(收到日期) | S3: 外箱贴纸 | T3: 客供贴纸AI(收到日期) | U3: 备注 | V3: ZURU 跟单 | W3: 单价USD | X3: 金额USD | Y3: 发票号 | Z3: 已送情况 | AA3: 欠数 | AB3: 贴纸 情况 | AC3: 是否入系统 | AD3: 系统货号 | AE3: 是否入系统 | AF3: 77593-95mm球壳 | AG3: MA 1L | AH3: MA 3L | AI3: MA 5L | AJ3: MA 1L | AL3: MA 1L | AM3: MA 3L | AN3: MA 1L | AO3: MA 3L | AP3: FD客版 | AQ3: MA 3L | AR3: MA 1L | AS3: 带底座 | AT3: 圆筒 | AU3: 彩纸 3L | AV3: 彩纸 1L | AW3: 客版 | AX3: 有硼无闪粉 | AY3: 无硼无闪粉 | BA3: Pterosaur 翼龙 | BB3: T-Rex 暴龙 | BC3: T-Rex (Rare) 暴龙（特别款） | BD3: Stegosaurus 剑龙 | BE3: Dilophosaurus 双棘龙 | BF3: Brontosaurus 雷龙 | BG3: Amargasaurus 阿玛加龙 | BH3: Truck 卡车 | BI3: Armed Helicoper 武装飞机 | BK3: Pterosaur 翼龙 | BL3: T-Rex 暴龙 | BM3: Stegosaurus 剑龙 | BN3: T-Rex (Rare) 暴龙（特别款） | BO3: Dilophosaurus 双棘龙 | BP3: Brontosaurus 雷龙 | BQ3: Amargasaurus 阿玛加龙 | BR3: Truck 卡车 | BS3: Armed Helicoper 武装飞机
A4: 46008 | B4: HOBBY LOBBY STORES, INC. | C4: 美国 | D4: 4500188454 | E4: W0750693 | F4: 4500188454-70 | G4: 77593GQ1-S001 | H4: S4迷你恐龙13PCS/GQ1*4 | I4: 1820 | J4: 0 | K4: 52 | L4: =I4/K4 -> 35 | M4: 46045 | N4: 46042 | P4: 自检 | Q4: 2/5 截SI | R4: 46008 | S4: 有 | T4: 12/17价格贴纸+外箱贴纸 | U4: 日期码格式：ZURU INC(BVI) 标准格式 日期：按实际生产日期 Packaging Info: 1. MA UPC版包装，优先1L，需要加贴价格贴纸, 贴在产品包装正面右上角(价格贴纸文档跟单提供)，出美国。 2. 外箱正唛(2面)右下角贴条码贴纸各贴1张(即1面1张共2张),贴纸大小：2.75 x 1.5 inch。(跟单提供文档，工厂采购) Remark: 1. 产品外包装及产品本身都必须有日期跟踪码，格式为：ZURU 标准日期码。 2. ZURU QC验货，无测试。 3. 产品配比按照MA标准配比执行。 | V4: Eleven Zhang | W4: 0.5759 | X4: =W4*I4 -> 1048.138 | Z4: 1820 | AB4: ok | AD4: 77593GQ1-S001 | AE4: 已入 | AF4: =I4 -> 1820 | AG4: =AF4 -> 1820 | AI4: =I4 -> 1820 | AN4: =I4/13 -> 140 | AX4: =I4 -> 1820 | BA4: =I4*$BA$2 -> 227.5 | BB4: =I4*$BB$2 -> 189.58333 | BC4: =I4*$BC$2 -> 37.916667 | BD4: =I4*$BD$2 -> 227.5 | BE4: =I4*$BE$2 -> 227.5 | BF4: =I4*$BF$2 -> 227.5 | BG4: =I4*$BG$2 -> 227.5 | BH4: =I4*$BH$2 -> 227.5 | BI4: =I4*$BI$2 -> 227.5 | BK4: =BK2-BA4 -> 1070.25 | BL4: =BL2-BB4 -> 1068.375 | BM4: =BM2-BD4 -> 1083.25 | BN4: =BN2-BC4 -> 88.875 | BO4: =BO2-BE4 -> -794.75 | BP4: =BP2-BF4 -> 1083.25 | BQ4: =BQ2-BG4 -> 1083.25 | BR4: =BR2-BH4 -> 1483.25 | BS4: =BS2-BI4 -> 1083.25
A5: 46008 | B5: NASA PANAMA | C5: 巴拿马 | D5: 4500189203 | F5: 4500189203-40 | G5: 77593GQ2-S001 | H5: S4迷你恐龙24PCS入GQ2*2/箱 | I5: 672 | J5: 0 | K5: 48 | L5: =I5/K5 -> 14 | M5: 46052 | N5: 46048 | P5: 自检 | Q5: 2/2 截SI | R5: 46028 | S5: 无 | T5: 1/6UPC贴纸 | U5: 日期码格式：ZURU INC(BVI) 标准格式 日期：按实际生产日期 Packaging Info: 请确保包装上的条形码是UPC，如果是babyUPC，需要用mother UPC覆盖，如有不一致，请及时提出。谢谢! 77593GQ2,,MA 多语EAN包装+UPC贴纸+MA多语收藏指南+MA PDQ+箱唛,, Remark: Common: Equal ratio | V5: Aimee Huang | W5: 0.9931 | X5: =W5*I5 -> 667.3632 | Z5: 672 | AB5: ok | AD5: 77593GQ2-S001-3L | AE5: 已入 | AF5: =I5 -> 672 | AH5: =I5 -> 672 | AI5: =I5 -> 672 | AM5: =I5/24 -> 28 | AX5: =I5 -> 672 | BA5: =I5*$BA$2 -> 84 | BB5: =I5*$BB$2 -> 70 | BC5: =I5*$BC$2 -> 14 | BD5: =I5*$BD$2 -> 84 | BE5: =I5*$BE$2 -> 84 | BF5: =I5*$BF$2 -> 84 | BG5: =I5*$BG$2 -> 84 | BH5: =I5*$BH$2 -> 84 | BI5: =I5*$BI$2 -> 84 | BK5: =BK4-BA5 -> 986.25 | BL5: =BL4-BB5 -> 998.375 | BM5: =BM4-BD5 -> 999.25 | BN5: =BN4-BC5 -> 74.875 | BO5: =BO4-BE5 -> -878.75 | BP5: =BP4-BF5 -> 999.25 | BQ5: =BQ4-BG5 -> 999.25 | BR5: =BR4-BH5 -> 1399.25 | BS5: =BS4-BI5 -> 999.25
A6: 46027 | B6: TOYZOONA LIMITED | C6: 肯尼亚 | D6: 4500190681 | F6: 4500190681-30 | G6: 77593GQ2-S001 | H6: S4迷你恐龙24PCS入GQ2*2/箱 | I6: 288 | J6: 0 | K6: 48 | L6: =I6/K6 -> 6 | M6: 46057 | N6: =M6-4 -> 46053 | P6: 自检 | Q6: 2/9 自提 | R6: 46027 | S6: 无 | T6: 无 | U6: 日期码格式：ZURU INC(BVI) 标准格式 日期：按实际生产日期 Packaging Info: MA PKG , 优先1L (需留意此单外箱上无客户名称） Remark: 此单按EXW +送货运费实报实销，需赶年前出货，请留意船务出货通知。 | V6: Chelsea Luo | W6: 0.9747 | X6: =W6*I6 -> 280.7136 | Z6: =240+48 -> 288 | AD6: 77593GQ2-S001 | AE6: 已入 | AF6: =I6 -> 288 | AG6: =AF6 -> 288 | AI6: =I6 -> 288 | AL6: =I6/24 -> 12 | AX6: =I6 -> 288 | BA6: =I6*$BA$2 -> 36 | BB6: =I6*$BB$2 -> 30 | BC6: =I6*$BC$2 -> 6 | BD6: =I6*$BD$2 -> 36 | BE6: =I6*$BE$2 -> 36 | BF6: =I6*$BF$2 -> 36 | BG6: =I6*$BG$2 -> 36 | BH6: =I6*$BH$2 -> 36 | BI6: =I6*$BI$2 -> 36 | BK6: =BK5-BA6 -> 950.25 | BL6: =BL5-BB6 -> 968.375 | BM6: =BM5-BD6 -> 963.25 | BN6: =BN5-BC6 -> 68.875 | BO6: =BO5-BE6 -> -914.75 | BP6: =BP5-BF6 -> 963.25 | BQ6: =BQ5-BG6 -> 963.25 | BR6: =BR5-BH6 -> 1363.25 | BS6: =BS5-BI6 -> 963.25
A7: 46055 | B7: HOBBY LOBBY STORES, INC. | C7: 美国 | D7: 4500192693 | E7: W0758454 | F7: 4500192693-60 | G7: 77593GQ1-S001 | H7: S4迷你恐龙13PCS/GQ1*4 | I7: 3380 | J7: 0 | K7: 52 | L7: =I7/K7 -> 65 | M7: 46115 | N7: 46111 | R7: 46059 | S7: 有 | T7: 2/6价格贴纸+外箱条码贴纸 | U7: 日期码格式：ZURU INC(BVI) 标准格式 日期：按实际生产日期 Packaging Info: 1. MA 优先1L UPC版包装,需要加贴价格贴纸, 贴在产品包装正面右上角(价格贴纸文档跟单提供)，出美国。 2. 外箱正唛(2面)右下角贴条码贴纸各贴1张(即1面1张共2张),贴纸大小：2.75 x 1.5 inch。(跟单提供文档，工厂采购) Remark: 1. 产品外包装及产品本身都必须有日期跟踪码，格式为：ZURU 标准日期码。 2. ZURU QC验货，无测试。 3. 产品配比按照MA标准配比执行。 | V7: Eleven Zhang | W7: 0.5701 | X7: =W7*I7 -> 1926.938 | AF7: =I7 -> 3380 | AG7: =AF7 -> 3380 | AI7: =I7 -> 3380 | AN7: =I7/13 -> 260 | AX7: =I7 -> 3380 | BA7: =I7*$BA$2 -> 422.5 | BB7: =I7*$BB$2 -> 352.08333 | BC7: =I7*$BC$2 -> 70.416667 | BD7: =I7*$BD$2 -> 422.5 | BE7: =I7*$BE$2 -> 422.5 | BF7: =I7*$BF$2 -> 422.5 | BG7: =I7*$BG$2 -> 422.5 | BH7: =I7*$BH$2 -> 422.5 | BI7: =I7*$BI$2 -> 422.5 | BK7: =BK6-BA7 -> 527.75 | BL7: =BL6-BB7 -> 616.29167 | BM7: =BM6-BD7 -> 540.75 | BN7: =BN6-BC7 -> -1.5416667 | BO7: =BO6-BE7 -> -1337.25 | BP7: =BP6-BF7 -> 540.75 | BQ7: =BQ6-BG7 -> 540.75 | BR7: =BR6-BH7 -> 940.75 | BS7: =BS6-BI7 -> 540.75
X13: =SUM(X4:X12)*7.75 -> 30404.434 | AF13: =SUM(AF4:AF12)+AF15+AF17+AF19 -> 652778 | AG13: =SUM(AG4:AG12)+AG15+AG17+AG19 -> 574657 | AH13: =SUM(AH4:AH12)+AH15+AH17+AH19 -> 77881 | AI13: =SUM(AI4:AI12)+AI15+AI17+AI19 -> 652538 | AJ13: =SUM(AJ4:AJ12)+AJ15+AJ17+AJ19 -> 500 | AK13: =SUM(AK4:AK12)+AK15+AK17+AK19 -> 500 | AL13: =SUM(AL4:AL12)+AL15+AL17+AL19 -> 6096 | AM13: =SUM(AM4:AM12)+AM15+AM17+AM19 -> 1494 | ... BI13: =SUM(BI4:BI12)+BI15+BI17+BI19 -> 144459.25
H14: 25年年存+26年实际 | BK14: =MIN(BK4:BK11) -> 527.75 | BL14: =MIN(BL4:BL11) -> 616.29167 | BM14: =MIN(BM4:BM11) -> 540.75 | BN14: =MIN(BN4:BN11) -> -1.5416667 | BO14: =MIN(BO4:BO11) -> -1337.25 | BP14: =MIN(BP4:BP11) -> 540.75 | BQ14: =MIN(BQ4:BQ11) -> 540.75 | BR14: =MIN(BR4:BR11) -> 940.75 | BS14: =MIN(BS4:BS11) -> 540.75
H15: =SUM(AF4:AF10) -> 6160 | AE15: 23年已删 | AX15: 0 | AY15: 4068 | BA15: 30159 | BB15: 25142.5 | BC15: 5076.5 | BD15: 30159 | BE15: 30159 | BF15: 30159 | BG15: 30159 | BH15: 30159 | BI15: 30159
X16: =SUM(#REF!)*7.75 -> #REF!
AE17: 24年已删 | AF17: 558379 | AG17: 523596 | AH17: 34783 | AI17: 558379 | AJ17: 368 | AK17: 368 | AL17: 5390 | AM17: 922 | AN17: 3615 | AO17: 485 | AP17: 23814 | AQ17: 73 | AR17: 0 | AS17: 73 | AT17: 8184 | AU17: 4752 | AV17: 3432 | AW17: 6233 | AX17: 779929 | AY17: 18278 | BA17: 102500.38 | BB17: 85425.313 | BC17: 17125.062 | BD17: 102500.38 | BE17: 102500.38 | BF17: 102500.38 | BG17: 102500.38 | BH17: 102500.38 | BI17: 102500.38 | BK17: =BK14-'77489 77593生产MA'!E17 -> -422.5 | BL17: =BL14-'77489 77593生产MA'!F17 -> -352.08333 | BM17: =BM14-'77489 77593生产MA'!G17 -> -422.5 | BN17: =BN14-'77489 77593生产MA'!H17 -> -70.416667 | BO17: =BO14-'77489 77593生产MA'!I17 -> -422.5 | BP17: =BP14-'77489 77593生产MA'!J17 -> -422.5 | BQ17: =BQ14-'77489 77593生产MA'!K17 -> -422.5 | BR17: =BR14-'77489 77593生产MA'!L17 -> -422.5 | BS17: =BS14-'77489 77593生产MA'!M17 -> -422.5
AE19: 25年已删 | AF19: 88239 | AG19: 45573 | AH19: 42426 | AI19: 87999 | AJ19: 132 | AK19: 132 | AL19: 694 | AM19: 544 | AN19: 1105 | AO19: 240 | AP19: 2707 | AQ19: 227 | AR19: 0 | AS19: 227 | AT19: 1008 | AU19: 1008 | AV19: 0 | AW19: 0 | AX19: 79263 | AY19: 8976 | AZ19: 0 | BA19: 11029.875 | BB19: 9191.5625 | BC19: 1838.3125 | BD19: 11029.875 | BE19: 11029.875 | BF19: 11029.875 | BG19: 11029.875 | BH19: 11029.875 | BI19: 11029.875
AJ20: =SUM(AJ4:AJ11) -> 0 | AL20: =SUM(AL4:AL11) -> 12 | AM20: =SUM(AM4:AM11) -> 28 | AQ20: =SUM(AQ4:AQ11) -> 0 | AR20: =SUM(AR4:AR11) -> 0 | BA20: =SUM(BA4:BA9) -> 770 | BB20: =SUM(BB4:BB9) -> 641.66667 | BC20: =SUM(BC4:BC9) -> 128.33333 | BD20: =SUM(BD4:BD9) -> 770 | BE20: =SUM(BE4:BE9) -> 770 | BF20: =SUM(BF4:BF9) -> 770 | BG20: =SUM(BG4:BG9) -> 770 | BH20: =SUM(BH4:BH9) -> 770 | BI20: =SUM(BI4:BI9) -> 770

Sheet 77489 77593生产MA
A1: ZURU 77489 Dino Strike S6 生产MA扣数
A2: MA訂單號 | B2: 日期 | C2: 85MM 球 | D2: 95MM 球 | E2: Pterosaur 翼龙 | F2: T-Rex 暴龙 | G2: Stegosaurus 剑龙 | H2: T-Rex (Rare) 暴龙（特别款） | I2: Dilophosaurus 双棘龙 | J2: Brontosaurus 雷龙 | K2: Amargasaurus 阿玛加龙 | L2: Truck 卡车 | M2: Armed Helicoper 武装飞机 | N2: 9款合計 | O2: Slime有硼 | P2: Slime无硼 | Q2: Slime无硼-无闪粉 | R2: Slime有硼-无闪粉 | S2: 要求完成时间 | T2: 口水胶原MOQ 5W，客人沟通确认最终可按2W接单
A3: MA-RR-907 | B3: 45095 | C3: 160000 | E3: 20000 | F3: 16666.667 | G3: 20000 | H3: 3333.3333 | I3: 20000 | J3: 20000 | K3: 20000 | L3: 20000 | M3: 20000 | N3: =SUM(E3:M3) -> 160000 | O3: 110000 | S3: 45145 | T3: 85MMM球壳
A4: MA-RR-907 | B4: 45095 | O4: 50000 | S4: 新增口水胶 | T4: 85MMM球壳
A5: MA-RR-980 | B5: 45196 | C5: 160000 | E5: 20000 | F5: 16666.667 | G5: 20000 | H5: 3333.3333 | I5: 20000 | J5: 20000 | K5: 20000 | L5: 20000 | M5: 20000 | N5: =SUM(E5:M5) -> 160000 | O5: 85000 | P5: 15000 | R5: 60000 | S5: 45246 | T5: 85MMM球壳
A6: MA-RR-1025 | B6: 45268 | C6: 100000 | E6: 25000 | F6: 20833.333 | G6: 25000 | H6: 4166.6667 | I6: 25000 | J6: 25000 | K6: 25000 | L6: 25000 | M6: 25000 | N6: =SUM(E6:M6) -> 200000 | Q6: 15000 | R6: 100000 | S6: 45304 | T6: 85MMM球壳
A7: MA-RR-1025 | D7: 50000 | E7: 103 | F7: 700 | I7: 2000 | L7: 500 | N7: =SUM(E7:M7) -> 3303 | S7: 45304 | T7: 增加95MM球壳50K，增加对应DEMO公仔数量
A8: MA-RR-1085 | B8: 45345 | C8: 100000 | D8: 110000 | E8: 20000 | F8: 16666.667 | G8: 20000 | H8: 3333.3333 | I8: 20000 | J8: 20000 | K8: 20000 | L8: 20000 | M8: 20000 | N8: =SUM(E8:M8) -> 160000 | Q8: 20000 | R8: =135000+70000 -> 205000 | S8: 45381
A9: MA-RR-1184 | B9: 45407 | D9: 160000 | E9: 20000 | F9: 16666.667 | G9: 20000 | H9: 3333.3333 | I9: 20000 | J9: 20000 | K9: 20000 | L9: 20000 | M9: 20000 | N9: =SUM(E9:M9) -> 160000 | R9: =60000+120000 -> 180000 | S9: 45448
